Workbook

Sheet 深度分析要求
A1: 深度分析维度
A2: 要点 | B2: 解决方案 | C2: 备注
A3: 1.补充swot分析 | B3: sheet1
A4: 补充：产品体验 | B4: 整个产品的重量是偏重的，噪音比其他的产品要大，在18KPA的吸力下，阻力会稍微大一些，比较难推动产品进行清洁；外观比较时尚，还有尘杯的拉环设计比较人性化
A5: 2.产品的定位 | B5: 定位的是年轻的白领一组（注重生活品质），以及家庭主妇（收入在中上的家庭）
A6: 补充：竞品分析 | B6: sheet2
A7: 3.核心关键词调研 | B7: sheet3
A8: 4.产品的五个亮点。 | B8: 1.尘杯拉环 2.过滤系统（待确认） 3.吸力（虚标）（要求说明书上面不要说） 4.地刷 5.配件（宠物毛刷，清洁刷，扁吸） 6.外观 7.灵活地刷 | C8: 人无我有，人有我优
A9: 5.产品：卡位多少？主关键词卡位？自然位，广告位 | B9: sheet4 | C9: 销量反推排名和卡位（市场情况、大盘、产品定位）
A10: 6.定价策略：LD价格，DOTD价格。 | B10: sheet5 | C10: 由于考虑到做LD，产品的售价不能时时调动，所以策略是固定住价格，再做利润空间的调整
A11: 7.推品的，达到卡位，投入多少？ | B11: sheet4 | C11: 新品期
A12: 8.测评比例，站内广告比例，站外广告比例 | B12: sheet6 | C12: 不考虑测评，做父子变体，重点是广告的投入
A13: 9.测评方案，各个阶段的测评方案 | B13: sheet6
A14: 10.流量方案：搜索流量，关联，店铺，站内，站外 | B14: sheet7 | C14: 20个流量入口
A15: 11.站外配合方案：渠道，时间点，作用，价格，数量 | B15: 产品状态：做父子变体，让listing有五个以上review 渠道： （1）红人这一块，初步的预订是 做一个youtube的开箱视频（提前准备好视频需求） （2）deal活动这一块，初步的预期是pep波兰， 和topmydeal，只是topmydeal要审核，不一定上 （3）其他的个别的小渠道也会发几个 时间点：开售第二周，持续时间一周 作用：推新品，冲销量，提升排名 价格：售价169.99，折扣空间35%，折后价格110.49欧 数量：15pcs/day | C15: 渠道 时间点 作用 价格 数量
A16: 12.备货计划：财务审核备货计划审核。 | B16: 开售第一个月，预计销量是350pcs，德国的发货到上架时间预留25天，备货则是一周两次调拨。 第一周调拨： 首批的数量是150pcs，第二波是200pcs（在预售前一个月开始调拨，保证在预定的开售时间做好所有的准备工作，包括商品上架、listing完善、测评需求已经提交等） 第四周调拨： 预计上一次调拨的刚入库，为下个月预留多一些库存，首批数量150pcs，第二波是150pcs（结合订单销量表以及后台的库存报表进行备货发货） | C16: 目标销量--反推发货计划
A17: 13.防御措施：异常处理方案。（变杀虫剂，变狗，被审核） | B17: 出现的问题，以及我们的应对方案： 1、找原因，找不出原因，开case； 2、用模板上传我们的listing信息，在上传的报错信息中，我们可以得知自己的哪个模块是有问题的，将信息进行修改，上传成功之后，listing也相应的恢复了； 3、listing回不来，则重新建一个链接

Sheet 1要点分析
A1: 要点分析
A2: 产品内部因素 VS 市场外部因素 | B2: S（strength） 1、21.6 V 高清锂电池 2、电动地刷上有指示灯，6个LED灯，LED灯更多，可扩大视野看到更广的视野 3、伸缩软管，伸缩比3:1 4、吸力7Kpa~~18Kpa 5、充电时间3-5H 6、功率200W 7、2.53kg（低于平均重量是2.8kg） | C2: W（weakness） 1、使用时间10~25min，时间比较短 2、82dB出风过滤网前有消音棉或者消音毡（竞品都在80以内）
A3: O（opportunity） 1、市场规模，德国市场的吸尘器小类目容量是5.7W左右， 2、新品占比2%，review数量只有100左右的，还是可以冲到best20以内（占比1%） 2、市场平均售价为179欧" 3、7月1号开始，亚马逊直接扣税，一些人没办法偷税漏税 4、经济在复苏，购买力增强 | B3: 优势S+机会O 亚马逊无偷税漏税的机会，让所有的卖家回到了同一个起跑线上，大家的成本有所提升。对手可能会提升售价来弥补成本，所以我们也有了更多的折扣空间。结合优势和机会，将内容展示在我们的五点和A+上 1、21.6 V 高清锂电池的电压高于竞品14.8V的，是一个优势 2、相对于市面上的竞品，电刷头前方LED只有3~4个，而我们的产品有6个 3、伸缩软管的伸缩比3:1，可以前后180度摆动，左右90度转动 4、功率目前是可以达到市面的最高200W 5、吸力有18KPA，处于中间阶段 | C3: 劣势W+机会O 我们的运行时间，在竞品中是算比较短的，而且噪音的水平高于行业的平均值。但我们可以把产品做高端，搭配各种附件，增加更多的附加价值。 思考： 如何取长补短，将这些劣势的参数表达的委婉一些。eg：可以描述我们的电机刷头出风过滤网前有消音棉或者消音毡，可以降噪，但是参数可以不罗列
A4: T（threats） 1、没有测评资源 2、广告预算受到控制 3、新品的价格区间在59.99~129.99，目前我们的定价是比这个区间高 | B4: 优势S+威胁T 目前的测评受限制，广告预算要控制，还有目前预计的定价169.99是高于新品价格的。 思考： 新品的定位是跑趋势，所以会注重把销量提升上去； 对于测评的话，可以用做父子变体来增加review数量； 对于广告的话，针对之前的吸尘器已有的精准小词或长尾词去打，而不是没有目标的乱花钱 | C4: 优势S+威胁T 思考： 对于自己的产品劣势，我们可以用自己的售后服务去加强，在文案中体现售后服务；在QA中以更专业的口吻去回复Q；不要害怕去暴露自己产品的缺点，因为过于掩饰或者夸大其词的话，会导致来差评的几率更高

Sheet 2竞品分析
A1: 市场情况 | B1: 图片
B2: 品牌 | C2: ORFELD | D2: Tineco | E2: Hoover | F2: Orfeld | G2: Orfeld | H2: AEG | I2: Philips | J2: VOSFEEL | K2: Tineco | L2: Aokin
B3: 型号 | C3: 3923 BLDC Motor | D3: Tineco A10 | E3: HF122RH | F3: EV679 | G3: EV660 | H3: CX7-2-I360 | I3: XC7042 | J3: Z10 | K3: A10 | L3: Rot1
B4: ASIN | D4: B07STYMV56 | E4: B07VJGQFJK | F4: B08GKRR67Q | G4: B0918P2K8D | H4: B0748MVY6S | I4: B07ZHV3XHD | J4: B08SBY23F1 | K4: B08CXKWS8T | L4: B07WCTN2VQ
B5: 价格 | D5: 199 | E5: 105.19 | F5: 135.98 | G5: 135.98 | H5: 259 | I5: 308.98 | J5: 89.99 | K5: 149.99 | L5: 99.99
B6: 排名 | D6: 大类11,792小类39 | F6: 大类445，小类2 | G6: 大类445，小类2 | I6: 大类825小类3 | J6: 大类1484小类9 | K6: 大类8202小类35
B7: 标题 | D7: Tineco Akku Staubsauger Akkustaubsauger A10 Hero Leichter 2 in 1 kabellos Handstaubsauger 17KPa Saugleistung beutellos, mit LED Elektrobürste Staubsauger, 24 Monate Garantie (Blau, A10 Hero) | E7: Hoover H-FREE 100 HOME Akku-Staubsauger, 2-in-1, großer Staubbehälter, integrierte Staubbürste, bis zu 40 Min. Laufzeit, motorisierte LED-Bodendüse, beutellos, kabellos, Modell: HF122RH | F7: ORFELD Akku Staubsauger, 18000Pa Staubsauger Kabellos 4 in 1, Superleichter Staubsauger, Bis zu 50 Minuten, mit doppeltem Digitalmotor für tief sauberes ganzes Haus [Energieklasse A+++] | G7: ORFELD Akku Staubsauger, Kabelloser Staubsauger 4 in 1 Kann Mehrere Oberflächen Reinigen, 40 Minuten Laufzeit, Niedriger Schwerpunkt, Stabstaubsauger Faltbarer für Harte Böden, Teppiche und Tierhaare | H7: AEG Ergorapido CX7-2-I360 2in1 Akku-Staubsauger / beutellos / Tierhaardüse und Zubehörset / bis zu 45 Min. Laufzeit / freistehend / 180° Drehgelenk / Bürstenreinigungsfunktion / LED-Lichter / blau | I7: Philips XC7042/01 SpeedPro Max kabelloser Staubsauger 7000 Series (Akkusauger, 360°-Saugdüse, 65 Min. Akkulaufzeit) rot mit Ersatzfilter FC5005/01 | J7: VOSFEEL Z10 Akku Staubsauger Kabellos 170W 18000Pa 4 in 1 LED-burste fur Hartboden Teppich Auto (170W) | K7: Tineco Akku Staubsauger Akkustaubsauger A10 Dash Leichter 2 in 1 kabellos Handstaubsauger 17KPa Saugleistung beutellos, mit LED Elektrobürste Staubsauger, 24 Monate Garantie (Violett, A10 Dash) | L7: Aokin Akku Staubsauger 18000Pa Handstaubsauger, staubsauger kabellos, 2200mAh Lithum-ion mit Second Gear Strong Suction LED-Frontlichter, Perfekt für Tierhaare Hartboden Teppich [Energieklasse A+++]
B8: 评论数
B9: Keepa分析 | D9: 1、一个月做一次LD，价格最低为139.30欧 2、没有大规模合并父子变体的趋势，但是在6月底的时候，review数量从3000掉到了2600 3、星级变化4.5-4.4-4.3-4.2（目前） | E9: 1、大规模的做过父子变体，第一次绑过500个，还经历了三次的父子变体“相聚”又“分离” 2、价格的调整比较频繁，最高价格239.最低价格99，做站内活动不频繁，今年以来没有做过 | F9: 1、6.22号做了LD活动，活动价格91.2欧 2、星级从43--4.2.，变体被拆从1957--1735个 | G9: 1、7.5号~7.12号做了BD活动，几天之后做了为期两天的LD，成交价84.39欧 2、7.16号变体被拆，review从429变成388，暂时页面在best上无法显示 | H9: 1、7天内在三个网站内推广过 2、5月中旬之后，把价格从195涨到了259欧，排名和星级都比较稳定 3、捆绑review接近1k个，掉了之后又重新被合并上了，之后的review涨速没有明显的断崖式变化 | I9: 1、价格变动比较频繁 2、最近半个月没有做站外推广活动 3、站内的deal活动最近三个月都没有申报 | J9: 1、价格调动比较频繁，范围在89.99~119.99 2、被拆分过变体，review之前掉了70个 | K9: 1、价格区间在119.2-199.99，6.20号做过deal活动，价格低至119.2 2、被拆分过变体，掉了2500个，最近两天合上了 3、星级从4.2到了4.1 | L9: 1、价格区间在89.99~92.99，6月25号做了deal，活动价格是79.99，基本一个月会做两次deal活动，持续时间为两天
A10: 产品参数 | B10: 电机功率 | C10: 200W | D10: 350W | E10: 22W | F10: 200W | G10: 120W | H10: 180W | I10: 600W | J10: 170W | K10: 300W | L10: 180W
B11: 吸力 | C11: 7~18KPA | D11: 17000pa | F11: 8 KPa / 18 kPa | G11: 7 KPa | J11: 18000 Pa | K11: 17000pa | L11: 18000Pa
B12: 噪音水平 | C12: 82 | D12: 70dB | E12: 77 | F12: 72dB | G12: 65dB | H12: 79dB | I12: 79dB | K12: 72 dB | L12: 70dB
B13: 充电时间 | C13: 3~5H | D13: 无 | E13: 6H（从买家评论得知） | F13: 3~5h | G13: 3~5h | H13: 3~5h | I13: 4h | J13: 3~5h | K13: 4h | L13: 4h
B14: 工作时间 | C14: 10~25MIN | D14: 25min | E14: 18~40min | F14: 50min | G14: 40min | H14: 16~45min | I14: 65min | J14: 40min | K14: 25min | L14: 15~30min
B15: 重量 | C15: 2.53kg | D15: 2.35 kg | E15: 2.6kg | F15: 1.98kg | G15: 2.5kg | H15: 2.5kg | I15: 3kg | J15: 1.05kg | K15: 1.3kg | L15: 2.3kg
B16: 尺寸 | C16: 111 x 25 x 22.8cm | D16: 1.10 Meter x 26.50 cm x 21.10 cm | E16: 26x23.4x11.2cm | F16: 109.2 x 24.5 x 27.8cm | G16: 26.1 x 20.7 x 118.2cm | H16: 26.50 x 14.50 x 114 cm | I16: 24 x 24 x 75cm | J16: 43.5 x 34 x 19 cm | K16: 23.60 x 11.0 x 21.1cm | L16: 11 x 23.00 x 20.00cm
B17: 包含的组件 | C17: 纸托、珍株棉袋、胶袋 | D17: 1 x 全尺寸多功能 LED 电动刷 1 x 迷你涡轮刷 1 x 二合一尘刷 1 x 缝隙喷嘴 1 x 预过滤器清洁工具 1 x 壁挂支架和用户手册 1 个适配器 1 x 用户手册 (DE / FR / ES / IT) 1 x 头发清洁工具 | E17: 带强力地板滚轮的电动 LED 地板吸嘴（适用于所有楼层）、拉出式家具刷和巧妙收纳在手柄中的缝隙吸嘴、壁挂支架 | F17: 吸嘴+毛刷 | G17: 吸嘴+毛刷 | H17: 1x CX7、电动吸尘刷、缝隙吸嘴、吸水软管、家具刷、充电站+一体式家具刷/迷你缝隙吸嘴、1个过滤器（在设备中）//推荐配件：扩展套件AKIT14、床垫吸嘴AZE128 , 过滤器组 AEF150 | I17: 吸尘器+过滤网套装 | J17: -包含2个HEPA过滤网、壁挂支架、3个不同使用场景的刷头和一个收纳袋 | K17: 无绳吸尘器、带 LED 照明的大型电动多功能刷、缝隙吸嘴、二合一尘刷、单电池充电器 + 壁挂支架和操作说明 | L17: 1 x 充电站 1 x 用户手册
B18: 各自的卖点/优势 | C18: 1、21.6 V 高清锂电池 2、电动地刷上有指示灯，4/6个LED灯，LED灯更多，可扩大视野看到更广的视野 3、伸缩软管伸缩比3:1，电动刷灵活 4、吸力7Kpa~~15Kpa（中间阶段） 5、充电时间3-5H 6、功率200W 7、2.53kg（低于平均重量是2.8kg） | D18: ♦ 2级吸力高达17KPa； ♦ 10-25 分钟运行时间； ♦ 21.6 伏 2000mAh 可拆卸锂离子电池； ♦ 70 分贝安静运行； ♦ 350W 令人印象深刻的电机功率； ♦ 无绳和无袋； ♦ 24 个月保修 | E18: 1、运行时间40min 2、尘杯器有0.9L，大于其他竞品 | F18: 1.续航时间长，充满电可以使用50min（EV-679) 2.吸力强劲，达到18Kpa以上(EV-679) 3.快充，4-5H即可充满电 4.多种配件，适用于多种场景，（吸嘴-吸牛奶，积水等液体；扁吸-集中吸力，吸砂石或细小的垃圾时使用；毛刷可用于家里缝隙等比较狭窄的地方） 5.噪音相对较小 6.679有LED显示灯，只有1.98kg（参数书上写）更加轻便 | G18: 1.续航时间长，充满电可以使用40min（EV-660) 2.低重心，运行稳定 3.折叠设计，不需要弯腰 4.多种配件，适用于多种场景，（吸嘴-吸牛奶，积水等液体；扁吸-集中吸力，吸砂石或细小的垃圾时使用；毛刷可用于家里缝隙等比较狭窄的地方） 5.噪音相对较小 6.660可以直立，不需要在墙上打孔挂住 | H18: 1、二合一功能 2、有高低两档不同的吸力模式，清洁时间分别为16min和45min 3、带 LED 前灯的电动电动吸刷可提供最佳视野 4、配件多，过滤组，吸嘴，尘刷，家居刷 | I18: 1、在经济模式下提供长达 65 分钟的工作时间，在正常模式下长达 30 分钟，在涡轮增压模式下工作时间长达 21 分钟。（多模式清洁） 2、二合一，手持式吸尘器和无线电池吸尘器同时使用 3、360度吸嘴，清洁每个角落 4、LED灯甚至显示隐藏的灰尘 | J18: 1、图片卖点 主图、清洁不同杂物、机器全长、过滤系统、使用场景 壁挂+充电、全家福 2、独特地刷 3、适用于短毛地毯 4、18KPA，两档 | K18: 卖点(除尘/尘螨/毛发) 配件使用场景 4级过滤拆解 全家福 1.3KG轻松托举 300W无刷电机\17KPA吸力 25分钟使用时长+低噪音72 dB LED前灯+轻便 配件详情 | L18: ➤无刷电机吸力高达18KPa； ➤2个吸力等级； ➤耐用的可拆卸电池； ➤改进的声学； ➤4级过滤系统； ➤LED电刷
B19: 总结 | C19: 对比了竞品，我们的产品噪音相对较高，吸力不是很突出，处于一般水平；重量是在平均水平2.8kg以下，但是不轻盈，没有突出优势；运行时间处于一般的水平；最大的优势是外观比较美观 | D19: 功率是目前已有产品中最大的，噪音相对比较低，可以替换的配件多 | E19: 该产品强调突出自己的0.9L大集尘杯，运行时间可以达到40min，避开了自己重量相对较重，以及一些吸力方面的参数描述（没有竞争优势的参数指标都会避开，取长补短） | F19: 续航时长是竞品中最长的，达到了50min，非常的轻1.23kg，加上噪音特别的小 | G19: 折叠设计，容易收纳；可以直立放置，不占地方 | H19: 续航时间较长45min，配件多，review是目前最多的一个产品，且差评绿较低 | I19: 比679的续航时间还要长，伸缩软管可以让吸尘器摆动360度 | J19: 好评点是安静轻巧易于操作，但是吸尘器必须将电缆插入电池才能充电、续航时间短、吸力很快下降、材质很廉价 | K19: 清洁效果好\电池拆解方便 安静轻巧 易于操作 有LED灯 配件丰富 一键开启持续模式 | L19: 带LED灯/二合一无线 18KPa/2级吸力 工作时间15-30分 旋风抽吸技术 低噪音设计
B20: 对比优点 | D20: 300W的大功率电机 | E20: 0.9L大集尘杯 | F20: 轻盈+噪音小 | G20: 折叠和直立设计 | H20: review在一万以上 | I20: 续航时间65min | J20: 只有1.05kg的重量 | K20: 功率达到了300W | L20: 价格优势

Sheet 3核心关键词
A1: 关键词分组 | B1: 关键词 | C1: 月点击量 | D1: 月搜索量 | E1: 搜索频率排名 | F1: 点击率 | G1: 精准度 | I1: 商品词 | J1: 上位/近义词 | K1: 修饰词 | L1: 品牌词 | N1: 单个商品词 | O1: 组装核心词
A2: 核心大词 | B2: staubsauger | E2: 27 | F2: 0.206978 | G2: 0.27272727 | I2: Akku-Staubsauger | J2: Staubsauger | K2: bis zu | L2: AEG | N2: Stabstaubsauger | O2: Akku Staubsauger
A3: 核心大词 | B3: akku staubsauger | C3: 382301 | D3: 888367 | E3: 209 | F3: 0.139652 | G3: 精准 | I3: Akkusauger | J3: Handstaubsauger | K3: kabelloser | L3: Bosch | N3: Akkustaubsauger | O3: Kabelloser Staubsauger
A4: 核心大词 | B4: staubsauger akku | C4: 75835 | D4: 83336 | E4: 7144 | F4: 0.184076 | G4: 精准 | I4: Akkustaubsauger | K4: beutellos | L4: Philips | N4: Akkusauger | O4: Staubsauger Kabellos
A5: 长尾词 | B5: staubsauger beutellos | E5: 771 | F5: 0.255498 | G5: 0.27 | I5: Stabstaubsauger | K5: Min. | L5: BISSELL | O5: Akku Staubsauger Kabellos
A6: 长尾词 | B6: staubsauger kabellos | C6: 212182 | D6: 347804 | E6: 901 | F6: 0.151894 | G6: 精准 | I6: Stielstaubsauger | K6: Laufzeit | L6: Tineco | O6: Kabelloser Akkusauger
A7: 长尾词 | B7: kabelloser staubsauger | C7: 140039 | D7: 119574 | E7: 5268 | F7: 0.140556 | G7: 精准 | I7: Saugwischer | K7: Akku-Staubsauger | L7: Shark | O7: Kabelloser Akkustaubsauger
A8: 长尾词 | B8: akku staubsauger testsieger 2020 | E8: 7537 | F8: 0.20721 | G8: 精准 | K8: Staubsauger | L8: JASHEN | O8: Kabelloser Stabstaubsauger
K9: freistehend | L9: ORFELD | O9: Akku Stabstaubsauger
K10: Akku | L10: ONEDAY | O10: Beutellos Staubsauger akku
K11: Saugleistung | L11: HONITURE | O11: Beutellos Stabstaubsauger Kabelloser
K12: LED-Frontlichter | L12: Hoover | O12: Beutellos Stabstaubsauger akku
K13: 2in1 | L13: INSE
K14: 180° | L14: MIC
K15: 45 | L15: Makita
K16: Drehgelenk | L16: Rowenta
K17: Bürstenreinigungsfunktion | L17: Anker
K18: Tierhaardüse | L18: eufy
K19: Hartböden | L19: Deerma
K20: hohe | L20: Proscenic
K21: alle | L21: VOSFEEL
K22: Teppiche | L22: Homtiky
K23: lange | L23: Aokin
K24: Tierhaare | L24: Dreame
K25: Fugendüse | L25: SWEETLF
K26: Bodenarten | L26: WOWGO
K27: Akkusauger | L27: Supkitdin
K28: 4 | L28: Grundig
K29: Zubehörset | L29: ANMO
K30: 22000 | L30: PWRHERO
K31: Abnehmbarer | L31: Deenkee
K32: 3-in-1 | L32: Dibea
K33: Starke | L33: WOVIDA
K34: Lithium | L34: Czemo
K35: Akkulaufzeit | L35: Greenote
K36: Multiflächen-Bodenreiniger | L36: ONSON
K37: Saugt | L37: Muzili
K38: wischt | L38: Casdon
K39: 360°-Saugdüse | L39: Dyson
K40: Akkustaubsauger | L40: Hosome
...

Sheet 4卡位
A1: 产品周期 | B1: 按照测评方案中的OKR表，预估一个月的销量是286pcs，每天出单15pcs
A2: 新品期 | B2: 投入广告 | C2: 以过去30天为一个维度，查看已有同类产品的广告数据情况： C10A： 曝光量232W，点击量0.87W，CPC为2.18欧，ACOS=16.47%，广告转化10% V20: 曝光量376W，点击量1.9W，CPC为1.96欧，ACOS=26.32%，广告转化6.9% 660： 曝光量14W，点击量675，CPC为1.18欧，ACOS=11.59%，广告转化11.9% 679： 曝光量668W，点击量3.12W，CPC为1.65欧，ACOS=20.21%，广告转化7% 每天80欧，前4天不开广告，先在测评单的推动下跑一个销量趋势，第五天开启广告，增加产品的曝光和点击，预计月度广告占比5.36%。 按照同类产品的表现情况，设3923的广告转化为7%，ACOS在20%，若单价在139.99~169.99之间，则依据 ACOS=CPC/(CR*单价），得到CPC=1.96~2.38，取CPC=2欧 预算=CPC*click，得出click=40, CR=order/click，得出order=3单
B3: 测评 | C3: 预估新品期三个月的销量是1000件，测评占比5%，测评数量50pcs 测评的节奏是从开售第一天开始：1-2-3-4-5-6-7-8-10-4-4 开售的前九天是测评出单； 开售第五天开启的广告，跑数据，同时关注自己跑出来的关键词是否精准，销量趋势和广告数据两手抓
B4: 站外 | C4: 德国站的站外效果不好，暂时不考虑站外的活动
B5: 做父子变体 | C5: 看德国是否有可用变体；或者将美国那边的转移到德国过来，做父子变体
B6: 卡位多少 | C6: 一个月销量300左右，预计可以到达大类11068，小类40
B7: 主关键词卡位 | C7: CPC=2欧广告位可以达到第一页，通过广告拉升，预计8月底自然页的在前两页
D9: 总结
A10: 投入以及产出 | B10: 广告花费 | C10: 投入广告费19096元，广告占比5.2%。 | D10: 测评增加review，计划回评+做父子变体将review涨到100个，星级在4.6以上。测评的另一个作用是前期拉升销量，跑销量趋势。以及看我们的产品是否存在什么质量问题，及时进行调整，减少差评和不必要的售后争端。 通过做一周的站外推广，提高站内的大类排名，大类排名3541，小类排名20，预计一天出单15~20pcs。 广告投入之后带来的直接效果是增加曝光和点击，提升转化率到10%，在开售一个月内提升自然排位到前两页。新品期第一个月，预计广告出单3pcs/day；第二个月，随着广告组的流量越来越精准，广告的花费会下降，转化提升，CPC能够降低到1.5左右（参考相似参数C10A） 设ACOS=15%，CPC=1.5，预算是80欧/day，转化率10% 预算=CPC*click，得出click=54 CR=order/click，得出order=5单 广告总出单5*30=150， 若第二个月平均每天出单15： 总单量15*30=450，广告单占比33% 若第三个月平均每天出单20： 总单量20*30=600，广告单占比25%
B11: 测评花费 | C11: 投入测评费用56128元，测评占比为15.83%。
B12: 站外花费 | C12: plan A：deal渠道的话估计100欧以内，折合人民币780元 备注：每个渠道预估花费35~50欧，建议同时发两三个 plan B：deal+红人视频营销2个，预估花费6000元 德国的红人是泛欧最贵的，一般三五千观看量的红人基本就三五百欧一个视频（当deal渠道带来的单量没有达到目标销量15pcs时候，可以考虑做红人营销）

Sheet 5定价策略
B1: DOTD | C1: LD | D1: 正常售价 | F1: asin | H1: B07STYMV56 | I1: B08CXKWS8T
B2: 3923 | C2: 3923 | D2: 3923 | F2: 竞品型号 | G2: 3923 | H2: Tineco A10 | I2: Tineco A10
A3: 成交价 | B3: 149 | C3: 139.99 | D3: 169.99 | F3: 价格 | G3: 139.99~169.99 | H3: 199 | I3: 149.99
A4: 数量 | B4: 1 | C4: 1 | D4: 1 | F4: 电机功率 | G4: 200W | H4: 350W | I4: 300W
A5: 汇率 | B5: 7.7 | C5: 7.7 | D5: 7.7 | F5: 吸力 | G5: 7~18KPA | H5: 17000pa | I5: 17000pa
A6: 营业收入 | B6: =B3*B4*B5 -> 1147.3 | C6: =C3*C4*C5 -> 1077.923 | D6: =D3*D4*D5 -> 1308.923 | F6: 噪音水平 | G6: 82 | H6: 70dB | I6: 72 dB
A7: 促销折扣费 | B7: =B3*0.3*B5 -> 344.19 | C7: =C3*0.15*C5 -> 161.68845 | D7: =D3*0.3*D5 -> 392.6769 | F7: 充电时间 | G7: 3~5H | H7: 无 | I7: 4h
A8: 促销比率 | B8: =B7/B6 -> 0.3 | C8: =C7/C6 -> 0.15 | D8: =D7/D6 -> 0.3 | F8: 工作时间 | G8: 10~25MIN | H8: 25min | I8: 25min
A9: 销售退款 | B9: =B10*B6 -> 86.0475 | C9: =C10*C6 -> 80.844225 | D9: =D10*D6 -> 98.169225 | F9: 重量 | G9: 2.53kg | H9: 2.35 kg | I9: 1.3kg
A10: 退款率 | B10: 0.075 | C10: 0.075 | D10: 0.075 | F10: 尺寸 | G10: 111 x 25 x 22.8cm | H10: 11.0 x 26.50 x 21.10 cm | I10: 23.60 x 11.0 x 21.1cm
A11: 其他收入汇总 | B11: 0 | C11: 0 | D11: 0 | F11: 总结 | G11: 从不同的参数上看，tineco的产品可以作为我们的对标竞品。 tineco的这两款自相对比，总体上的参数只是在功率上有50W的差距，其他参数差别不大，但是差价却是50欧，一个走高端路线，另一个走中端路线，从产品销量表现上看，两者是不分伯仲； tineco与我们的3923进行对比，从吸力上面分析，我们的18KPA更加有优势，劣势在于功率上面，我们的只有200W，其他的参数基本不存在太大的差距，我们的价格完全可以在149.99~199.99之间。
A12: 一、销售收入 | B12: =B6-B7-B9+B11 -> 717.0625 | C12: =C6-C7-C9+C11 -> 835.39032 | D12: =D6-D7-D9+D11 -> 818.07687
A13: 销收占比 | B13: =B12/B6 -> 0.625 | C13: =C12/C6 -> 0.775 | D13: =D12/D6 -> 0.625
A14: 采购成本 | B14: =B15*(1-B10) -> 333.925 | C14: =C15*(1-C10) -> 333.925 | D14: =D15*(1-D10) -> 333.925
A15: 采购单价RMB | B15: 361 | C15: 361 | D15: 361
A16: 采购占比 40% | B16: =B14/B12 -> 0.46568465 | C16: =C14/C12 -> 0.39972333 | D16: =D14/D12 -> 0.40818291
A17: 头程运费 | B17: =B18*B12 -> 16.420731 | C17: =C18*C12 -> 19.130438 | D17: =D18*D12 -> 18.73396
A18: 头程占比 6% | B18: 0.0229 | C18: 0.0229 | D18: 0.0229
A19: 二程运费 | B19: =B20*B12 -> 20.507987 | C19: =C20*C12 -> 23.892163 | D19: =D20*D12 -> 23.396999
A20: 二程占比 | B20: 0.0286 | C20: 0.0286 | D20: 0.0286
A21: 存货损耗 | B21: =B10*0.7*B15 -> 18.9525 | C21: =C10*0.7*C15 -> 18.9525 | D21: =D10*0.7*D15 -> 18.9525
A22: 损耗占比 | B22: 0.01 | C22: 0.024 | D22: 0.024
A23: 退回成本
A24: 退回成本3%
A25: 产品总成本 | B25: =B14+B17+B19+B21+B23 -> 389.80622 | C25: =C14+C17+C19+C21+C23 -> 395.9001 | D25: =D14+D17+D19+D21+D23 -> 395.00846
A26: 产品占比 49% | B26: =B25/B12 -> 0.5436154 | C26: =C25/C12 -> 0.47391033 | D26: =D25/D12 -> 0.48285005
A27: 二、销售毛利 | B27: =B12-B25 -> 327.25628 | C27: =C12-C25 -> 439.49022 | D27: =D12-D25 -> 423.06842
A28: 亚马逊佣金 | B28: =B12*B29 -> 107.55938 | C28: =C12*C29 -> 125.30855 | D28: =D12*D29 -> 122.71153
A29: 亚马逊佣金 15% | B29: 0.15 | C29: 0.15 | D29: 0.15
A30: FBA 配送费 10% | B30: 55.24 | C30: 55.24 | D30: 55.24
A31: 退回费用 | B31: 0 | C31: 0 | D31: 0
A32: 平台占比 25% | B32: =(B28+B30-B31)/B12 -> 0.22703652 | C32: =(C28+C30-C31)/C12 -> 0.21612478 | D32: =(D28+D30-D31)/D12 -> 0.21752422
A33: AMPS费/合仓费等 | B33: =B34*B12 -> 0 | C33: =C34*C12 -> 0 | D33: =D34*D12 -> 0
A34: AMPS费/合仓费等1% | B34: 0 | C34: 0 | D34: 0
A35: 服务费合计 | B35: =B28+B30-B31+B33 -> 162.79937 | C35: =C28+C30-C31+C33 -> 180.54855 | D35: =D28+D30-D31+D33 -> 177.95153
A36: 服务费占比 27% | B36: =B35/B12 -> 0.22703652 | C36: =C35/C12 -> 0.21612478 | D36: =D35/D12 -> 0.21752422
A37: 移除费用 | B37: 0.01 | C37: 0.01 | D37: 0.01
A38: fba仓储费
A39: fba仓占比 1%
A40: fba超量费
...

Sheet 6测评方案
A1: 科目 | B1: 字段 | C1: KPI | D1: 44409 | E1: 44410 | F1: 44411 | G1: 44412 | H1: 44413 | I1: 44414 | J1: 44415 | K1: 44416 | L1: 44417 | M1: 44418 | N1: 44419 | O1: 44420 | P1: 44421 | Q1: 44422 | R1: 44423 | S1: 44424 | T1: 44425 | U1: 44426 | V1: 44427 | W1: 44428 | X1: 44429 | Y1: 44430 | Z1: 44431 | AA1: 44432 | AB1: 44433 | AC1: 44434 | AD1: 44435 | AE1: 44436 | AF1: 44437 | AG1: 44438 | AH1: 44439 | AI1: 合计
A2: 基础值 | B2: 指标- | C2: 单价 | D2: 169.99 | E2: 169.99 | F2: 169.99 | G2: 169.99 | H2: 169.99 | I2: 169.99 | J2: 169.99 | K2: 169.99 | L2: 169.99 | M2: 169.99 | N2: 169.99 | O2: 169.99 | P2: 169.99 | Q2: 169.99 | R2: 169.99 | S2: 169.99 | T2: 169.99 | U2: 169.99 | V2: 169.99 | W2: 169.99 | X2: 169.99 | Y2: 169.99 | Z2: 169.99 | AA2: 169.99 | AB2: 169.99 | AC2: 169.99 | AD2: 169.99 | AE2: 169.99 | AF2: 169.99 | AG2: 169.99 | AH2: 169.99 | AI2: =AVERAGE(G2:AH2) -> 169.99
A3: 基础值 | B3: 指标- | C3: 数量 | D3: 1 | E3: 2 | F3: 3 | G3: 4 | H3: 5 | I3: 6 | J3: 7 | K3: 8 | L3: 9 | M3: 10 | N3: 11 | O3: 11 | P3: 11 | Q3: 11 | R3: 11 | S3: 15 | T3: 15 | U3: 15 | V3: 15 | W3: 15 | X3: 15 | Y3: 15 | Z3: 15 | AA3: 15 | AB3: 15 | AC3: 15 | AD3: 15 | AE3: 15 | AF3: 15 | AG3: 15 | AH3: 15 | AI3: =SUM(D3:AH3) -> 350
A4: 基础值 | B4: 指标- | C4: 参考销量指标 | D4: =[1]日均销量计算表!$B$20 -> 1.9642857 | E4: =[1]日均销量计算表!$B$20 -> 1.9642857 | F4: =[1]日均销量计算表!$B$20 -> 1.9642857 | G4: =[1]日均销量计算表!$B$20 -> 1.9642857 | H4: =[1]日均销量计算表!$B$20 -> 1.9642857 | I4: =[1]日均销量计算表!$B$20 -> 1.9642857 | J4: =[1]日均销量计算表!$B$20 -> 1.9642857 | K4: =[1]日均销量计算表!$B$20 -> 1.9642857 | ... AH4: =[1]日均销量计算表!$B$20 -> 1.9642857
A5: 基础值 | B5: 指标- | C5: 汇率 | D5: 7.7 | E5: 7.7 | F5: 7.7 | G5: 7.7 | H5: 7.7 | I5: 7.7 | J5: 7.7 | K5: 7.7 | L5: 7.7 | M5: 7.7 | N5: 7.7 | O5: 7.7 | P5: 7.7 | Q5: 7.7 | R5: 7.7 | S5: 7.7 | T5: 7.7 | U5: 7.7 | V5: 7.7 | W5: 7.7 | X5: 7.7 | Y5: 7.7 | Z5: 7.7 | AA5: 7.7 | AB5: 7.7 | AC5: 7.7 | AD5: 7.7 | AE5: 7.7 | AF5: 7.7 | AG5: 7.7 | AH5: 7.7
A6: 营收额 | B6: 指标 | C6: 营业收入 | D6: =D2*D3*D5 -> 1308.923 | E6: =E2*E3*E5 -> 2617.846 | F6: =F2*F3*F5 -> 3926.769 | G6: =G2*G3*G5 -> 5235.692 | H6: =H2*H3*H5 -> 6544.615 | I6: =I2*I3*I5 -> 7853.538 | J6: =J2*J3*J5 -> 9162.461 | K6: =K2*K3*K5 -> 10471.384 | ... AH6: =AH2*AH3*AH5 -> 19633.845 | AI6: =SUM(D6:AH6) -> 458123.05
A7: 营收额 | B7: 比率 | C7: 收入增长率 | D7: / | E7: / | F7: / | G7: / | H7: / | I7: / | J7: / | K7: / | L7: / | M7: / | N7: / | O7: / | P7: / | Q7: / | R7: / | S7: / | T7: / | U7: / | V7: / | W7: / | X7: / | Y7: / | Z7: / | AA7: / | AB7: =(AB6-AA6)/AA6 -> 0 | AC7: =(AC6-AB6)/AB6 -> 0 | AD7: =(AD6-AC6)/AC6 -> 0 | AE7: =(AE6-AD6)/AD6 -> 0 | AF7: =(AF6-AE6)/AE6 -> 0 | AG7: =(AG6-AE6)/AE6 -> 0 | AH7: =(AH6-AG6)/AG6 -> 0
A8: 营收额 | B8: 指标- | C8: 促销折扣费 | D8: =35*D5*D3*0.8 -> 215.6 | E8: =35*E5*E3*0.8 -> 431.2 | F8: =35*F5*F3*0.8 -> 646.8 | G8: =35*G5*G3*0.8 -> 862.4 | H8: =35*H5*H3*0.8 -> 1078 | I8: =35*I5*I3*0.8 -> 1293.6 | J8: =35*J5*J3*0.8 -> 1509.2 | K8: =35*K5*K3*0.8 -> 1724.8 | ... AH8: =35*AH5*AH3*0.8 -> 3234 | AI8: =SUM(D8:AH8) -> 75460
A9: 营收额 | B9: 比率 | C9: 促销比率 | D9: =D8/D6 -> 0.16471557 | E9: =E8/E6 -> 0.16471557 | F9: =F8/F6 -> 0.16471557 | G9: =G8/G6 -> 0.16471557 | H9: =H8/H6 -> 0.16471557 | I9: =I8/I6 -> 0.16471557 | J9: =J8/J6 -> 0.16471557 | K9: =K8/K6 -> 0.16471557 | ... AH9: =AH8/AH6 -> 0.16471557
A10: 营收额 | B10: 指标- | C10: 销售退款 | D10: =D11*(D6-D8) -> 0 | E10: =E11*(E6-E8) -> 0 | F10: =F11*(F6-F8) -> 0 | G10: =G11*(G6-G8) -> 0 | H10: =H11*(H6-H8) -> 0 | I10: =I11*(I6-I8) -> 0 | J10: =J11*(J6-J8) -> 0 | K10: =K11*(K6-K8) -> 699.72672 | ... AH10: =AH11*(AH6-AH8) -> 1311.9876 | AI10: =SUM(D10:AH10) -> 28164
A11: 营收额 | B11: 比率 | C11: 退款率 | D11: 0 | E11: 0 | F11: 0 | G11: 0 | H11: 0 | I11: 0 | J11: 0 | K11: 0.08 | L11: 0.08 | M11: 0.08 | N11: 0.08 | O11: 0.08 | P11: 0.08 | Q11: 0.08 | R11: 0.08 | S11: 0.08 | T11: 0.08 | U11: 0.08 | V11: 0.08 | W11: 0.08 | X11: 0.08 | Y11: 0.08 | Z11: 0.08 | AA11: 0.08 | AB11: 0.08 | AC11: 0.08 | AD11: 0.08 | AE11: 0.08 | AF11: 0.08 | AG11: 0.08 | AH11: 0.08 | AI11: =AVERAGE(H11:AH11) -> 0.071111111
A12: 营收额 | B12: 指标- | C12: 其他收入汇总
A13: 收益类 | B13: 指标 | C13: 一、销售收入 | D13: =D6-D8-D10+D12 -> 1093.323 | E13: =E6-E8-E10+E12 -> 2186.646 | F13: =F6-F8-F10+F12 -> 3279.969 | G13: =G6-G8-G10+G12 -> 4373.292 | H13: =H6-H8-H10+H12 -> 5466.615 | I13: =I6-I8-I10+I12 -> 6559.938 | J13: =J6-J8-J10+J12 -> 7653.261 | K13: =K6-K8-K10+K12 -> 8046.8573 | ... AH13: =AH6-AH8-AH10+AH12 -> 15087.857 | AI13: =SUM(D13:AH13) -> 354499.05 | AJ13: =AI10/AI13 -> 0.079447323
A14: 收益类 | B14: 比率 | C14: 销收占比 | D14: =D13/D6 -> 0.83528443 | E14: =E13/E6 -> 0.83528443 | F14: =F13/F6 -> 0.83528443 | G14: =G13/G6 -> 0.83528443 | H14: =H13/H6 -> 0.83528443 | I14: =I13/I6 -> 0.83528443 | J14: =J13/J6 -> 0.83528443 | K14: =K13/K6 -> 0.76846167 | ... AH14: =AH13/AH6 -> 0.76846167 | AI14: =AVERAGE(K14:AH14) -> 0.76846167
A15: 产品费 | B15: 指标 | C15: 采购成本 | D15: =D3*(1-D11)*D16 -> 361.2 | E15: =E3*(1-E11)*E16 -> 722.4 | F15: =F3*(1-F11)*F16 -> 1083.6 | G15: =G3*(1-G11)*G16 -> 1444.8 | H15: =H3*(1-H11)*H16 -> 1806 | I15: =I3*(1-I11)*I16 -> 2167.2 | J15: =J3*(1-J11)*J16 -> 2528.4 | K15: =K3*(1-K11)*K16 -> 2658.432 | ... AH15: =AH3*(1-AH11)*AH16 -> 4984.56 | AI15: =SUM(D15:AH15) -> 117115.49
A16: 产品费 | B16: 指标- | C16: 采购单价RMB | D16: =56*6.45 -> 361.2 | E16: =56*6.45 -> 361.2 | F16: =56*6.45 -> 361.2 | G16: =56*6.45 -> 361.2 | H16: =56*6.45 -> 361.2 | I16: =56*6.45 -> 361.2 | J16: =56*6.45 -> 361.2 | K16: =56*6.45 -> 361.2 | ... AH16: =56*6.45 -> 361.2
A17: 产品费 | B17: 比率 | C17: 采购占比 40% | D17: =D15/D13 -> 0.33036898 | E17: =E15/E13 -> 0.33036898 | F17: =F15/F13 -> 0.33036898 | G17: =G15/G13 -> 0.33036898 | H17: =H15/H13 -> 0.33036898 | I17: =I15/I13 -> 0.33036898 | J17: =J15/J13 -> 0.33036898 | K17: =K15/K13 -> 0.33036898 | ... AH17: =AH15/AH13 -> 0.33036898 | AI17: =AVERAGE(K17:AH17) -> 0.33036898
A18: 产品费 | B18: 指标- | C18: 头程运费 | D18: =70*D3 -> 70 | E18: =70*E3 -> 140 | F18: =70*F3 -> 210 | G18: =70*G3 -> 280 | H18: =70*H3 -> 350 | I18: =70*I3 -> 420 | J18: =70*J3 -> 490 | K18: =70*K3 -> 560 | ... AH18: =70*AH3 -> 1050 | AI18: =SUM(D18:AH18) -> 24500
A19: 产品费 | B19: 比率 | C19: 头程占比 6% | D19: =D18/D13 -> 0.064024995 | E19: =E18/E13 -> 0.064024995 | F19: =F18/F13 -> 0.064024995 | G19: =G18/G13 -> 0.064024995 | H19: =H18/H13 -> 0.064024995 | I19: =I18/I13 -> 0.064024995 | J19: =J18/J13 -> 0.064024995 | K19: =K18/K13 -> 0.069592386 | ... AH19: =AH18/AH13 -> 0.069592386 | AI19: =AVERAGE(H19:AH19) -> 0.068973787
A20: 产品费 | B20: 指标- | C20: 二程运费 | D20: =70*D3 -> 70 | E20: =70*E3 -> 140 | F20: =70*F3 -> 210 | G20: =70*G3 -> 280 | H20: =70*H3 -> 350 | I20: =70*I3 -> 420 | J20: =70*J3 -> 490 | K20: =70*K3 -> 560 | ... AH20: =70*AH3 -> 1050 | AI20: =SUM(D20:AH20) -> 24500
A21: 产品费 | B21: 比率 | C21: 二程占比 | D21: =D20/D13 -> 0.064024995 | E21: =E20/E13 -> 0.064024995 | F21: =F20/F13 -> 0.064024995 | G21: =G20/G13 -> 0.064024995 | H21: =H20/H13 -> 0.064024995 | I21: =I20/I13 -> 0.064024995 | J21: =J20/J13 -> 0.064024995 | K21: =K20/K13 -> 0.069592386 | ... AH21: =AH20/AH13 -> 0.069592386 | AI21: =AVERAGE(H21:AH21) -> 0.068973787
A22: 产品费 | B22: 指标- | C22: 存货损耗 | D22: 0 | E22: 0 | F22: 0 | G22: 0 | H22: 0 | I22: 0 | J22: 0 | K22: 0 | L22: 0 | M22: 0 | N22: 0 | O22: 0 | P22: 0 | Q22: 0 | R22: 0 | S22: 0 | T22: 0 | U22: 0 | V22: 0 | W22: 0 | X22: 0 | Y22: 0 | Z22: 0 | AA22: 0 | AB22: 0 | AC22: 0 | AD22: 0 | AE22: 0 | AF22: 0 | AG22: 0 | AH22: 0 | AI22: =SUM(D22:AH22) -> 0
A23: 产品费 | B23: 比率 | C23: 损耗占比 | D23: =D22/D13 -> 0 | E23: =E22/E13 -> 0 | F23: =F22/F13 -> 0 | G23: =G22/G13 -> 0 | H23: =H22/H13 -> 0 | I23: =I22/I13 -> 0 | J23: =J22/J13 -> 0 | K23: =K22/K13 -> 0 | ... AH23: =AH22/AH13 -> 0 | AI23: =AVERAGE(H23:AH23) -> 0
A24: 产品费 | B24: 指标 | C24: 退回成本 | D24: =D25*D13 -> 32.79969 | E24: =E25*E13 -> 65.59938 | F24: =F25*F13 -> 98.39907 | G24: =G25*G13 -> 131.19876 | H24: =H25*H13 -> 163.99845 | I24: =I25*I13 -> 196.79814 | J24: =J25*J13 -> 229.59783 | K24: =K25*K13 -> 241.40572 | ... AH24: =AH25*AH13 -> 452.63572 | AI24: =SUM(D24:AH24) -> 10634.971
A25: 产品费 | B25: 比率- | C25: 退回成本3% | D25: 0.03 | E25: 0.03 | F25: 0.03 | G25: 0.03 | H25: 0.03 | I25: 0.03 | J25: 0.03 | K25: 0.03 | L25: 0.03 | M25: 0.03 | N25: 0.03 | O25: 0.03 | P25: 0.03 | Q25: 0.03 | R25: 0.03 | S25: 0.03 | T25: 0.03 | U25: 0.03 | V25: 0.03 | W25: 0.03 | X25: 0.03 | Y25: 0.03 | Z25: 0.03 | AA25: 0.03 | AB25: 0.03 | AC25: 0.03 | AD25: 0.03 | AE25: 0.03 | AF25: 0.03 | AG25: 0.03 | AH25: 0.03 | AI25: =AVERAGE(H25:AH25) -> 0.03
A26: 1产品费 | B26: 指标 | C26: 产品总成本 | D26: =D15+D18+D20+D22+D24 -> 533.99969 | E26: =E15+E18+E20+E22+E24 -> 1067.9994 | F26: =F15+F18+F20+F22+F24 -> 1601.9991 | G26: =G15+G18+G20+G22+G24 -> 2135.9988 | H26: =H15+H18+H20+H22+H24 -> 2669.9985 | I26: =I15+I18+I20+I22+I24 -> 3203.9981 | J26: =J15+J18+J20+J22+J24 -> 3737.9978 | K26: =K15+K18+K20+K22+K24 -> 4019.8377 | ... AH26: =AH15+AH18+AH20+AH22+AH24 -> 7537.1957 | AI26: =SUM(D26:AH26) -> 176750.46
A27: 1产品费 | B27: 比率 | C27: 产品占比 49% | D27: =D26/D13 -> 0.48841897 | E27: =E26/E13 -> 0.48841897 | F27: =F26/F13 -> 0.48841897 | G27: =G26/G13 -> 0.48841897 | H27: =H26/H13 -> 0.48841897 | I27: =I26/I13 -> 0.48841897 | J27: =J26/J13 -> 0.48841897 | K27: =K26/K13 -> 0.49955375 | ... AH27: =AH26/AH13 -> 0.49955375 | AI27: =AVERAGE(K27:AH27) -> 0.49955375
A28: 收益类 | B28: 指标 | C28: 二、销售毛利 | D28: =D13-D26 -> 559.32331 | E28: =E13-E26 -> 1118.6466 | F28: =F13-F26 -> 1677.9699 | G28: =G13-G26 -> 2237.2932 | H28: =H13-H26 -> 2796.6166 | I28: =I13-I26 -> 3355.9399 | J28: =J13-J26 -> 3915.2632 | K28: =K13-K26 -> 4027.0196 | ... AH28: =AH13-AH26 -> 7550.6617 | AI28: =SUM(D28:AH28) -> 177748.59
A29: 服务费 | B29: 指标 | C29: 亚马逊佣金 | D29: =(D6-D8)*D30 -> 155.25187 | E29: =(E6-E8)*E30 -> 310.50373 | F29: =(F6-F8)*F30 -> 465.7556 | G29: =(G6-G8)*G30 -> 621.00746 | H29: =(H6-H8)*H30 -> 776.25933 | I29: =(I6-I8)*I30 -> 931.5112 | J29: =(J6-J8)*J30 -> 1086.7631 | K29: =(K6-K8)*K30 -> 1242.0149 | ... AH29: =(AH6-AH8)*AH30 -> 2328.778 | AI29: =SUM(D29:AH29) -> 54338.153
A30: 服务费 | B30: 比率- | C30: 亚马逊佣金 15% | D30: 0.142 | E30: 0.142 | F30: 0.142 | G30: 0.142 | H30: 0.142 | I30: 0.142 | J30: 0.142 | K30: 0.142 | L30: 0.142 | M30: 0.142 | N30: 0.142 | O30: 0.142 | P30: 0.142 | Q30: 0.142 | R30: 0.142 | S30: 0.142 | T30: 0.142 | U30: 0.142 | V30: 0.142 | W30: 0.142 | X30: 0.142 | Y30: 0.142 | Z30: 0.142 | AA30: 0.142 | AB30: 0.142 | AC30: 0.142 | AD30: 0.142 | AE30: 0.142 | AF30: 0.142 | AG30: 0.142 | AH30: 0.142 | AI30: =AVERAGE(H30:AH30) -> 0.142
A31: 服务费 | B31: 指标- | C31: FBA 配送费 10% | D31: =$D$67*D3 -> 54.678 | E31: =$D$67*E3 -> 109.356 | F31: =$D$67*F3 -> 164.034 | G31: =$D$67*G3 -> 218.712 | H31: =$D$67*H3 -> 273.39 | I31: =$D$67*I3 -> 328.068 | J31: =$D$67*J3 -> 382.746 | K31: =$D$67*K3 -> 437.424 | ... AH31: =$D$67*AH3 -> 820.17 | AI31: =SUM(D31:AH31) -> 19137.3
A32: 服务费 | B32: 指标 | C32: 退回费用 | D32: =D11*D29 -> 0 | E32: =E11*E29 -> 0 | F32: =F11*F29 -> 0 | G32: =G11*G29 -> 0 | H32: =H11*H29 -> 0 | I32: =I11*I29 -> 0 | J32: =J11*J29 -> 0 | K32: =K11*K29 -> 99.361194 | ... AH32: =AH11*AH29 -> 186.30224 | AI32: =SUM(D32:AH32) -> 3999.2881
A33: 服务费 | B33: 比率- | C33: 平台占比 25% | D33: =(D29+D31-D32)/D13 -> 0.19201084 | E33: =(E29+E31-E32)/E13 -> 0.19201084 | F33: =(F29+F31-F32)/F13 -> 0.19201084 | G33: =(G29+G31-G32)/G13 -> 0.19201084 | H33: =(H29+H31-H32)/H13 -> 0.19201084 | I33: =(I29+I31-I32)/I13 -> 0.19201084 | J33: =(J29+J31-J32)/J13 -> 0.19201084 | K33: =(K29+K31-K32)/K13 -> 0.19635961 | ... AH33: =(AH29+AH31-AH32)/AH13 -> 0.19635961 | AI33: =AVERAGE(K33:AH33) -> 0.19635961
A34: 服务费 | B34: 指标 | C34: AMPS费/合仓费等 | D34: =D35*D13 -> 0 | E34: =E35*E13 -> 0 | F34: =F35*F13 -> 0 | G34: =G35*G13 -> 0 | H34: =H35*H13 -> 0 | I34: =I35*I13 -> 0 | J34: =J35*J13 -> 0 | K34: =K35*K13 -> 0 | ... AH34: =AH35*AH13 -> 0 | AI34: =SUM(D34:AH34) -> 0
A35: 服务费 | B35: 比率- | C35: AMPS费/合仓费等1% | D35: 0 | E35: 0 | F35: 0 | G35: 0 | H35: 0 | I35: 0 | J35: 0 | K35: 0 | L35: 0 | M35: 0 | N35: 0 | O35: 0 | P35: 0 | Q35: 0 | R35: 0 | S35: 0 | T35: 0 | U35: 0 | V35: 0 | W35: 0 | X35: 0 | Y35: 0 | Z35: 0 | AA35: 0 | AB35: 0 | AC35: 0 | AD35: 0 | AE35: 0 | AF35: 0 | AG35: 0 | AH35: 0 | AI35: 0.01
A36: 服务费 | B36: 指标 | C36: 服务费合计 | D36: =D29+D31-D32+D34 -> 209.92987 | E36: =E29+E31-E32+E34 -> 419.85973 | F36: =F29+F31-F32+F34 -> 629.7896 | G36: =G29+G31-G32+G34 -> 839.71946 | H36: =H29+H31-H32+H34 -> 1049.6493 | I36: =I29+I31-I32+I34 -> 1259.5792 | J36: =J29+J31-J32+J34 -> 1469.5091 | K36: =K29+K31-K32+K34 -> 1580.0777 | ... AH36: =AH29+AH31-AH32+AH34 -> 2962.6458 | AI36: =SUM(D36:AH36) -> 69476.165
A37: 服务费 | B37: 比率 | C37: 服务费占比 27% | D37: =D36/D13 -> 0.19201084 | E37: =E36/E13 -> 0.19201084 | F37: =F36/F13 -> 0.19201084 | G37: =G36/G13 -> 0.19201084 | H37: =H36/H13 -> 0.19201084 | I37: =I36/I13 -> 0.19201084 | J37: =J36/J13 -> 0.19201084 | K37: =K36/K13 -> 0.19635961 | ... AH37: =AH36/AH13 -> 0.19635961 | AI37: =AVERAGE(K37:AH37) -> 0.19635961
A38: 仓储费 | B38: 比率- | C38: 移除费用 | D38: 0.01 | E38: 0.01 | F38: 0.01 | G38: 0.01 | H38: 0.01 | I38: 0.01 | J38: 0.01 | K38: 0.01 | L38: 0.01 | M38: 0.01 | N38: 0.01 | O38: 0.01 | P38: 0.01 | Q38: 0.01 | R38: 0.01 | S38: 0.01 | T38: 0.01 | U38: 0.01 | V38: 0.01 | W38: 0.01 | X38: 0.01 | Y38: 0.01 | Z38: 0.01 | AA38: 0.01 | AB38: 0.01 | AC38: 0.01 | AD38: 0.01 | AE38: 0.01 | AF38: 0.01 | AG38: 0.01 | AH38: 0.01 | AI38: =AVERAGE(H38:AH38) -> 0.01
A39: 仓储费 | B39: 比率- | C39: fba仓储费
A40: 仓储费 | B40: 比率- | C40: fba仓占比 1%
...

Sheet 7流量方案
A1: 流量入口 | B1: 流量来源 | C1: 方案
A2: 自然搜索流量 | B2: 关键词搜索 | C2: 在标题、五点、QA、A+文案中都要尽量去埋词，词的选择可以查看【3核心关键词】一栏；还有后台的ST入口，将精准的词埋在我们的产品中，让亚马逊的机器识别我们的产品，把词和产品进行关联
A3: 广告流量 | B3: SP | C3: 自动手动广告开启前，一定要否定无效流量；关键词要精准
B4: SB | C4: 最常用的该类型是SBV广告，视频要控制好长度1min内，表达出我们的卖点，结合“宣传片+卖点细节展示”，可以向玄天提交我们的新品视频需求，用于我们的详情页“宣传视频”，和QA里面的回复“操作视频”（视频的需求详情可以后期斟酌）
B5: SD | C5: 类目和商品投放，主要在商品的详情页中显示，有10个位置可以选择
A6: 站内推广流量 | B6: LD | C6: 付费活动，看后台有无申报资格
B7: BD | C7: 只能通过招商经理渠道去申请
B8: DOTD | C8: 很难申请，新品一般不考虑
B9: COUPON | C9: 定价定高一点，目前在新品期的预留折扣空间是35欧；上升期可以重点放在利润上，降低折扣空间为30欧
B10: OUTLET | C10: 针对冗余产品
A11: 类目节点流量 | C11: 要精准，(参考660和679的类目途径）Household Cleaning Tools & Vacuums<Vacuums<Stick Vacuums & Electric Brooms
A12: 各类榜单流量 | B12: best seller | C12: 工业类目可以节约2个点佣金，不抢其他节点bs；若不能到工业类目，可以尝试进中央吸尘器类目拿bs标。
B13: new release | C13: 德国吸尘器无
B14: most wished | C14: 可以提交心愿单，前期每天计划上30个看效果，有变化则加大需求量到50个
B15: gift idea | C15: 可以提交加购，时刻关注榜单情况，前期也是每天提交30个，一周提交两次，有效果之后可以加大需求量到50个
A16: 关联流量 | B16: 看了又看
B17: 买了又买 | C17: 一起购买的关联流量，把新品加到orfeld排名靠前的产品中，增加其曝光
B18: 品牌关联 | C18: 针对在orfeld热销款式 1、在A+页面引流 2、把新品加到其页面下的new model板块 3、在热销款式上做促销code，买一可以优惠新品5%~10%
B19: 广告关联 | C19: 自己品牌的流量闭环，投放orfeld在售的产品asin
B20: 相似产品关联 | C20: 打其他吸尘器的asin广告，尽可能形成一定的关联。
B21: 4星级及以上 | C21: 保持自己的产品在四星以上，同时打其他吸尘器的asin广告，尽可能形成一定的关联。让自己的产品出现在他们的下面。

Sheet 8推广计划表
A1: 序号 | B1: 类目 | C1: 指标名称 | D1: 工作内容&事项-O | E1: 结果呈现/输出载体-KR | F1: 时间节点 | G1: 具体动作-ACTION（Plan A) | H1: 具体动作-ACTION（Plan B) | I1: 时间起 | J1: 时间止 | K1: 结果偏差 | L1: 结果-RESULT | M1: 改善方案 | N1: 备注
A2: W1(8/2~8/8) | B2: 业务指标 | C2: 3923产品销收&利润 | D2: M8W1目标销售&利润 | E2: 3923预计产品销量 | F2: 44413 | G2: 在测评之前确认产品的详情信息都准备ok，包括listing内容还有产品已经上架；测评的节奏是从开售第一天开始：1-2-3-4-5-6-7-8 开售的前九天是测评出单；提升自然排名 | I2: 44410 | J2: 44416
E3: 3923产品预计成交价 | F3: 44413 | G3: 做35欧的coupon，预计成交价 是34.99欧 | I3: 44410 | J3: 44416
E4: 3923产品目标折扣占比 | F4: 44413 | G4: 35/169.99=20% | I4: 44410 | J4: 44416
E5: 3923产品目标广告占比 | F5: 44413 | G5: 开售第五天开启广告，广告预算前期可以用少一些，50欧以内，将这部分费用挪到其他的时间段 | I5: 44410 | J5: 44416
B6: 优化指标 | C6: 3923产品转化率 | D6: M8W1目标产品转化率 | E6: 参数+A+ | F6: 44413 | G6: listing 文案+A+更新 | I6: 44410 | J6: 44416
E7: DEAL | F7: 44413 | G7: 绑定C10G获得DEAL提报资格 | H7: 服务商操作报DEAL | I7: 44410 | J7: 44416
B8: 优化指标 | C8: 3923产品CTR | D8: M8W1目标产品CTR | E8: 首图 | F8: 44413 | G8: 图片更新 | I8: 44410 | J8: 44416
E9: 标题 | F9: 44413 | G9: 标题更新 | I9: 44410 | J9: 44416
A10: W2(8/9~8/15) | B10: 业务指标 | C10: 3923产品销收&利润 | D10: M8W2目标销售&利润 | E10: 3923预计产品销量 | F10: 44420 | G10: 测评：接着上一周-10-4-4，目的是提升关键词自然排名 | H10: 做new model 挂在CX11下面 | I10: 44417 | J10: 44423
E11: 3923产品预计成交价 | F11: 44420 | G11: 前期重点做节奏在节奏稳步上升的前提下降低coupon力度至30欧，成交价139.99欧 | H11: 销量不满足：维持30欧coupon | I11: 44417 | J11: 44423
E12: 3923产品目标折扣占比 | F12: 44420 | G12: 30欧coupon，折扣占比17.6% | I12: 44417 | J12: 44423
E13: 3923产品目标广告占比 | F13: 44420 | G13: 第一天9%，后逐渐降低广告花费 | I13: 44417 | J13: 44423
B14: 优化指标 | C14: 3923产品转化率 | D14: M8W2目标产品转化率 | E14: 评论 | F14: 44420 | G14: 找汤姆猫催评，回评 | H14: vine计划提交 | I14: 44417 | J14: 44423
E15: 流量 | F15: 44420 | G15: 申请加购+心愿榜各100个 | I15: 44417 | J15: 44423
E16: 闭环（精准流量） | F16: 44420 | G16: 将链接加进660、679、V20 VC818 CX11 C10A的A+对比 | I16: 44417 | J16: 44423
E17: QA | F17: 44420 | G17: QA-10对 | I17: 44417 | J17: 44423
B18: 优化指标 | C18: 3923产品CTR | D18: M8W2目标产品CTR 0.5% | E18: 评分 | F18: 44420 | G18: 绑定一条种子 | H18: 绑两条 | I18: 44417 | J18: 44423
E19: 标题 | F19: 44420 | G19: 无 | I19: 44417 | J19: 44423
A20: W3(8/16~8/22) | B20: 业务指标 | C20: 3923产品销收&利润 | D20: M8W3目标销售&利润 | E20: 3923预计产品销量 | F20: 44427 | G20: 目标销量是每天15单 | I20: 44424 | J20: 44430
E21: 3923产品预计成交价 | F21: 44427 | G21: coupon设置不高于30欧，LD期间不设置coupon，成交价139.99 | H21: 测试30欧力度拆分成coupon+外挂code观察转化变化情况 | I21: 44424 | J21: 44430
E22: 3923产品目标折扣占比 | F22: 44427 | G22: coupon设置力度：30欧，折扣占比17.6% | H22: 销量满足的情况：coupon设置力度减小到：25欧 | I22: 44424 | J22: 44430
E23: 3923产品目标广告占比 | F23: 44427 | G23: LD活动期间减少广告花费至10%，平时广告花费控制在15%以内 | H23: 调低转化低于5%的广告组的竞价至不花钱，广告倾斜转化好的 | I23: 44424 | J23: 44430
B24: 优化指标 | C24: 3923产品转化率 | D24: M8W3目标产品转化率 | E24: 流量（精准） | F24: 44427 | G24: 申请加购+心愿榜各100个 | H24: 广告否词（结合其他同类产品的无效流量数据操作） | I24: 44424 | J24: 44430
E25: 评论 | F25: 44427 | G25: 催评，前两页无差评 | H25: 出现异常：提交首页无差评需求+增加好评点赞 | I25: 44424 | J25: 44430
E26: 参数 | F26: 44427 | G26: 检查保持listing参数无误 | I26: 44424 | J26: 44430
E27: 站外推广 | F27: 44427 | G27: 预计每天出单是15pcs | H27: 站外推广的销量没有跟上，则考虑做PD单，推动 | I27: 44424 | J27: 44430
B28: 优化指标 | C28: 3923产品CTR | D28: M8W3目标产品CTR | E28: 评分 | F28: 44427 | G28: 开始催评稳住评分 | H28: 加绑种子评论1-2条 | I28: 44424 | J28: 44430
E29: 广告竞价 | F29: 44427 | G29: 1、对于曝光和点击都少的词或asin，采取加大5%竞价的方式，给它更多的表现机会 2、对于曝光多，点击少的词，可以保留，定位为增加产品曝光 3、对于曝光多，点击多，但是没有转化的词，降低10%的竞价，继续观察是否要关闭 4、对于转化好的词，要时刻跟进，查看我们的产品在这个词下面的坑位情况 （以上操作都会事先和青龙沟通） | H29: 调整之后发现流量异常，或者下降10%，要看是否自己调整的竞价幅度太大，降低竞价的调整幅度，把5%和10%改成3%和5% | I29: 44424 | J29: 44430
E30: 广告预算 | F30: 44427 | G30: 对于acos太高或者有点击多但是完全没有订单的广告组进行将预算，把更多的预算分配到转化好的广告组中 | H30: 无 | I30: 44424 | J30: 44430
E31: 广告否词 | F31: 44427 | G31: 每周两次否词，安排在周一和周四，否定无效流量（和我们的产品不相关） | H31: 调整之后发现曝光异常减少，那么要去看否定的词是否影响了原来的流量 | I31: 44424 | J31: 44430
A32: W4(8/23~8/29) | B32: 业务指标 | C32: 3923产品销收&利润 | D32: M8W4目标销售&利润 | E32: 3923预计产品销量 | F32: 44434 | G32: 目标销量是每天15单，BD活动 | H32: 设置10欧coupon,单量在计划基础上每天需多出4单 | I32: 44431 | J32: 44437
E33: 3923产品预计成交价 | F33: 44434 | G33: 用活动价销收不再额外设置优惠活动 | I33: 44431 | J33: 44437
E34: 3923产品目标折扣占比 | F34: 44434 | G34: 不设置coupon | I34: 44431 | J34: 44437
E35: 3923产品目标广告占比 | F35: 44434 | G35: 广告预算只放计划销收的5.6% | H35: 调低转化低于5%的广告组的竞价至不花钱，广告倾斜转化好的 | I35: 44431 | J35: 44437
B36: 优化指标 | C36: 3923产品转化率 | D36: M8W4目标产品转化率 | E36: 流量（精准） | F36: 44434 | G36: 申请加购+心愿榜各100个 | H36: 广告否词两次 | I36: 44431 | J36: 44437
E37: 评论 | F37: 44434 | G37: 前两页无差评 | H37: 若出现：首页无差评需求 | I37: 44431 | J37: 44437
E38: QA | F38: 44434 | G38: 首页无不利内容 上视频 | H38: 若出现不利内容：点赞将其他内容顶上来 | I38: 44431 | J38: 44437
B39: 优化指标 | C39: 3923产品CTR | D39: M8W4目标产品CTR | E39: 评分 | F39: 44434 | G39: 催评（测评单） 站内索评 | H39: 加绑种子评论1-2条 | I39: 44431 | J39: 44437
E40: 广告竞价 | F40: 44434 | G40: 日常操作（与第二周一样） | H40: 无 | I40: 44431 | J40: 44437
...
