Workbook

Sheet 使用说明
F2: 猫猫背带产品调研
F3: 英文关键词 | H3: Cat Harness | K3: 调研时间 | O3: 编号
G5: 使用需知
G12: 1.本表格只接受160条listing的数据，相当于亚马逊前十页的listing数量。
G17: 2.务必提供准确的数据，如果数据中包含不相干的产品数据，该表格将不能自动分辨，因此，在将数据粘贴到本表格前，请先将杂质清除。
G22: 3.本表格的数据最好是来源于Jungle Scout或米库插件软件下载的CSV文件，可将下载的文件直接粘贴于本表格，其他软件下载的数据需要事先整理。
G27: 4.本表格每页都有“注释”板块，用于讲解或提示本页面的数据及注意事项，使用前需提前了解。
G32: 5.本表格只有绿色区域可用于编辑，其他区域因有函数关系的原因，同时以防不小心修改了函数关系导致数据错乱，所以其他区域为不可选中，不可编辑修改。

Sheet 数据调研
A1: # | B1: Product Name | C1: Brand | D1: Price | E1: Category | F1: Rank | G1: Sales | H1: Revenue | I1: Reviews | J1: Rating | K1: Seller | L1: ASIN | M1: Link | N1: 上架天数 | P1: 市场份额
A2: 86 | B2: 骞垮憡-Small Dog Harness Cat Harness Escape Proof Cat and Dog Harness Adjustable Vest Harnesses with Reflective Strap Soft Mesh Back Metal Clip No Pull No Choke Training Walk for Small Pet Puppy Kitten | C2: Eagloo | D2: 13.99 | E2: Pet Supplies | F2: 764 | G2: 2550 | H2: 35674.5 | I2: 79 | J2: 4 | K2: FBA | L2: B07NQ35VDW | M2: https://www.amazon.com/dp/B07NQ35VDW?psc=1 | N2: 387 | O2: =IFERROR(VLOOKUP(L2,#REF!,5,0),"") | P2: =G2/SUM($G$2:$G$161) -> 0.098391017
A3: 29 | B3: Small Dog Harness Cat Harness Escape Proof Cat and Dog Harness Adjustable Vest Harnesses with Reflective Strap Soft Mesh Back Metal Clip No Pull No Choke Training Walk for Small Pet Puppy Kitten | C3: Eagloo | D3: 13.99 | E3: Pet Supplies | F3: 764 | G3: 2550 | H3: 35674.5 | I3: 79 | J3: 4 | K3: FBA | L3: B07NQ35VDW | M3: https://www.amazon.com/dp/B07NQ35VDW?psc=1 | N3: 387 | O3: =IFERROR(VLOOKUP(L3,#REF!,5,0),"") | P3: =G3/SUM($G$2:$G$161) -> 0.098391017 | R3: 注意： 该表格数据最好来自于JS,JS数据可直接粘贴使用，无需调整格式 此处的上架天数来源于表格“天数换算”的数据匹配，无需手动输入。 没有上架天数的必须手动输入，不然会影响分析结果。可用Keepa查询后补齐
A4: 111 | B4: 骞垮憡-Small Dog Harness Cat Harness Escape Proof Cat and Dog Harness Adjustable Vest Harnesses with Reflective Strap Soft Mesh Back Metal Clip No Pull No Choke Training Walk for Small Pet Puppy Kitten | C4: Eagloo | D4: 13.99 | E4: Pet Supplies | F4: 764 | G4: 2550 | H4: 35674.5 | I4: 79 | J4: 4 | K4: FBA | L4: B07NQ35VDW | M4: https://www.amazon.com/dp/B07NQ35VDW?psc=1 | N4: 387 | O4: =IFERROR(VLOOKUP(L4,#REF!,5,0),"") | P4: =G4/SUM($G$2:$G$161) -> 0.098391017
A5: 80 | B5: BWOGUE 2 Packs Dog Cat Safety Seat Belt Strap Car Headrest Restraint Adjustable Nylon Fabric Dog Restraints Vehicle Seatbelts Harness | C5: BWOGUE | D5: 10.49 | E5: Pet Supplies | F5: 921 | G5: 2220 | H5: 23287.8 | I5: 743 | J5: 4.7 | K5: FBA | L5: B078G6MKTN | M5: https://www.amazon.com/dp/B078G6MKTN?psc=1 | N5: 459 | O5: =IFERROR(VLOOKUP(L5,#REF!,5,0),"") | P5: =G5/SUM($G$2:$G$161) -> 0.085658062
A6: 117 | B6: PetSafe Nylon Dog Leash, Strong and Durable Traditional Style Leash with Easy to Use Collar Hook, Available in Multiple Widths and Colors | C6: PetSafe | D6: 4.79 | E6: Pet Supplies | F6: 1174 | G6: 1830 | H6: 8765.7 | I6: 1616 | J6: 4.4 | K6: AMZ | L6: B000OGRDK0 | M6: https://www.amazon.com/dp/B000OGRDK0?psc=1 | N6: 4374 | O6: =IFERROR(VLOOKUP(L6,#REF!,5,0),"") | P6: =G6/SUM($G$2:$G$161) -> 0.070610024
A7: 14 | B7: PUPTECK Cat Harness with Leash Set - Adjustable Soft Strap with Fashion Design | C7: PUPTECK | D7: 13.99 | E7: Pet Supplies | F7: 2511 | G7: 960 | H7: 13430.4 | I7: 13 | J7: 4.8 | K7: FBA | L7: B07MKQFJSP | M7: https://www.amazon.com/dp/B07MKQFJSP?psc=1 | N7: 96 | O7: =IFERROR(VLOOKUP(L7,#REF!,5,0),"") | P7: =G7/SUM($G$2:$G$161) -> 0.037041324
A8: 25 | B8: 骞垮憡-PUPTECK Cat Harness with Leash Set - Adjustable Soft Strap with Fashion Design | C8: PUPTECK | D8: 13.99 | E8: Pet Supplies | F8: 2921 | G8: 840 | H8: 11751.6 | I8: 13 | J8: 4.8 | K8: FBA | L8: B07MKQFJSP | M8: https://www.amazon.com/dp/B07MKQFJSP?psc=1 | N8: 96 | O8: =IFERROR(VLOOKUP(L8,#REF!,5,0),"") | P8: =G8/SUM($G$2:$G$161) -> 0.032411159
A9: 131 | B9: 骞垮憡-GAUTERF Dog and Cat Universal Harness with Leash Set, Escape Proof Cat Harnesses - Adjustable Reflective Soft Mesh Corduroy Dog Harnesses - Best Pet Supplies | C9: GAUTERF | D9: 10.99 | E9: Pet Supplies | F9: 6044 | G9: 420 | H9: 4615.8 | I9: 601 | J9: 4.2 | K9: FBA | L9: B07GFBW7JT | M9: https://www.amazon.com/dp/B07GFBW7JT?psc=1 | N9: 256 | O9: =IFERROR(VLOOKUP(L9,#REF!,5,0),"") | P9: =G9/SUM($G$2:$G$161) -> 0.016205579
A10: 53 | B10: Cat Harness Escape Proof Small Dogs Mesh Vest Harnesses Adjustable Puppy Kitten Walking Harness No Pull Design with Leash Clip & Reflective Strips for Best Comfort & Safety, Black Green Pink Red | C10: Rabbitgoo | D10: 12.98 | E10: Pet Supplies | F10: 6553 | G10: 390 | H10: 5062.2 | I10: 28 | J10: 3.7 | K10: FBA | L10: B07MZR3MDT | M10: https://www.amazon.com/dp/B07MZR3MDT?psc=1 | N10: 48 | O10: =IFERROR(VLOOKUP(L10,#REF!,5,0),"") | P10: =G10/SUM($G$2:$G$161) -> 0.015048038
A11: 3 | B11: 骞垮憡-Cat Harness Escape Proof Small Dogs Mesh Vest Harnesses Adjustable Puppy Kitten Walking Harness No Pull Design with Leash Clip & Reflective Strips for Best Comfort & Safety, Black Green Pink Red | C11: Rabbitgoo | D11: 12.98 | E11: Pet Supplies | F11: 6553 | G11: 390 | H11: 5062.2 | I11: 28 | J11: 3.7 | K11: FBA | L11: B07MZR3MDT | M11: https://www.amazon.com/dp/B07MZR3MDT?psc=1 | N11: 48 | O11: =IFERROR(VLOOKUP(L11,#REF!,5,0),"") | P11: =G11/SUM($G$2:$G$161) -> 0.015048038
A12: 68 | B12: Escape Proof Cat Harness with Leash Adjustable Soft Mesh - Best for Walking | C12: PUPTECK | D12: 12.99 | E12: Pet Supplies | F12: 6727 | G12: 360 | H12: 4676.4 | I12: 944 | J12: 3.6 | K12: FBA | L12: B074MWRZ5Y | M12: https://www.amazon.com/dp/B074MWRZ5Y?psc=1 | N12: 1080 | O12: =IFERROR(VLOOKUP(L12,#REF!,5,0),"") | P12: =G12/SUM($G$2:$G$161) -> 0.013890497
A13: 46 | B13: 骞垮憡-INVENHO Mesh Harness with Padded Vest for Puppy and Cats No Choke Design Ventilation Gift with One Leash & Seat Belt | C13: INVENHO | D13: 10.99 | E13: Pet Supplies | F13: 7043 | G13: 360 | H13: 3956.4 | I13: 124 | J13: 4.3 | K13: FBA | L13: B07MDLYQR7 | M13: https://www.amazon.com/dp/B07MDLYQR7?psc=1 | N13: 556 | O13: =IFERROR(VLOOKUP(L13,#REF!,5,0),"") | P13: =G13/SUM($G$2:$G$161) -> 0.013890497
A14: 45 | B14: 骞垮憡-INVENHO Mesh Harness with Padded Vest for Puppy and Cats No Choke Design Ventilation Gift with One Leash & Seat Belt | C14: INVENHO | D14: 10.99 | E14: Pet Supplies | F14: 7043 | G14: 360 | H14: 3956.4 | I14: 124 | J14: 4.3 | K14: FBA | L14: B07MDLYQR7 | M14: https://www.amazon.com/dp/B07MDLYQR7?psc=1 | N14: 556 | O14: =IFERROR(VLOOKUP(L14,#REF!,5,0),"") | P14: =G14/SUM($G$2:$G$161) -> 0.013890497
A15: 66 | B15: Voyager All Weather No Pull Step-in Mesh Dog Harness Padded Vest | C15: Best Pet Supplies, Inc. | D15: 12.99 | E15: Pet Supplies | F15: 7965 | G15: 300 | H15: 3897 | I15: 4515 | J15: 4.3 | K15: AMZ | L15: B00M0V7UVE | M15: https://www.amazon.com/dp/B00M0V7UVE?psc=1 | N15: 1921 | O15: =IFERROR(VLOOKUP(L15,#REF!,5,0),"") | P15: =G15/SUM($G$2:$G$161) -> 0.011575414
... A20: 147 | B20: SCENEREAL Escape Proof Cat Harness and Leash - Adjustable Soft Mesh Vest for Rabbits Puppy Kittens | C20: SCENEREAL | D20: 13.99 | E20: Pet Supplies | F20: 10702 | G20: 210 | H20: 2937.9 | I20: 67 | J20: 3.9 | K20: FBA | L20: B07F8RY3C6 | M20: https://www.amazon.com/dp/B07F8RY3C6?psc=1 | N20: 272 | O20: =IFERROR(VLOOKUP(L20,#REF!,5,0),"") | P20: =G20/SUM($G$2:$G$161) -> 0.0081027897
A21: 82 | B21: PetSafe Come with Me Kitty Harness and Bungee Leash, Harness for Cats | C21: PetSafe | D21: 14.95 | E21: Amazon Best Sellers Rank: | F21: N.A. | G21: 210 | H21: 3139.5 | I21: 2543 | J21: 3.9 | K21: AMZ | L21: B001OMD5ZA | M21: https://www.amazon.com/dp/B001OMD5ZA?psc=1 | N21: 4229 | O21: =IFERROR(VLOOKUP(L21,#REF!,5,0),"") | P21: =G21/SUM($G$2:$G$161) -> 0.0081027897
A22: 157 | B22: Escape Proof Cat Harness with Leash, Adjustable Cat Walking Jackets, Padded Cat Vest | C22: Yizhi Miaow | D22: 14.49 | E22: Pet Supplies | F22: 12619 | G22: 180 | H22: 2608.2 | I22: 263 | J22: 4 | K22: FBA | L22: B077XY1CBC | M22: https://www.amazon.com/dp/B077XY1CBC?psc=1 | N22: 533 | O22: =IFERROR(VLOOKUP(L22,#REF!,5,0),"") | P22: =G22/SUM($G$2:$G$161) -> 0.0069452483
A23: 47 | B23: OFPUPPY Adjustable Cat Harness and Leash Set Velvet and Nylon Lead for Kitty Kitten Walking | C23: OFPUPPY | D23: 9.99 | E23: Pet Supplies | F23: 98482 | G23: 180 | H23: 1798.2 | I23: 14 | J23: 3.9 | K23: FBA | L23: B07DWPTT9S | M23: https://www.amazon.com/dp/B07DWPTT9S?psc=1 | N23: 309 | O23: =IFERROR(VLOOKUP(L23,#REF!,5,0),"") | P23: =G23/SUM($G$2:$G$161) -> 0.0069452483
A24: 9 | B24: voopet Boho Soft Mesh Dog Harness, Cats Padded Front Vest Harness with Leash, Adjustable Pets No-Pull Walking Harness - Easy Control for Small Dogs & Puppy | C24: voopet | D24: 10.99 | E24: Pet Supplies | F24: 140925 | G24: 180 | H24: 1978.2 | I24: 2 | J24: 5 | K24: FBA | L24: B07MMHDWTC | M24: https://www.amazon.com/dp/B07MMHDWTC?psc=1 | N24: 1235 | O24: =IFERROR(VLOOKUP(L24,#REF!,5,0),"") | P24: =G24/SUM($G$2:$G$161) -> 0.0069452483
A25: 37 | B25: 骞垮憡-Mellow Shirt Dog Anxiety Calming Wrap | C25: Mellow Shirt | D25: 25.99 | E25: Pet Supplies | F25: 12670 | G25: 180 | H25: 4678.2 | I25: 1611 | J25: 3.5 | K25: FBA | L25: B018S3APEG | M25: https://www.amazon.com/dp/B018S3APEG?psc=1 | N25: 1235 | O25: =IFERROR(VLOOKUP(L25,#REF!,5,0),"") | P25: =G25/SUM($G$2:$G$161) -> 0.0069452483
A26: 158 | B26: Coastal Pet Poly Cat Tie Out with Nickel-Plated Swivel Snaps, Black, 1/8 Width by 15-Feet Long | C26: Coastal Pet | D26: 8.14 | E26: Pet Supplies | F26: 13278 | G26: 180 | H26: 1465.2 | I26: 106 | J26: 4.4 | K26: FBA | L26: B003WRG9O4 | M26: https://www.amazon.com/dp/B003WRG9O4?psc=1 | N26: 980 | O26: =IFERROR(VLOOKUP(L26,#REF!,5,0),"") | P26: =G26/SUM($G$2:$G$161) -> 0.0069452483
A27: 148 | B27: Dog and Cat Universal Harness with Traction Rope, Adjustable Vest-Type Reflective Corduroy Comfortable Pet Harness | C27: Rosestola | D27: 8.99 | E27: Pet Supplies | F27: 130055 | G27: 180 | H27: 1618.2 | I27: 5 | J27: 5 | K27: FBA | L27: B07P74ZSXS | M27: https://www.amazon.com/dp/B07P74ZSXS?psc=1 | N27: 980 | O27: =IFERROR(VLOOKUP(L27,#REF!,5,0),"") | P27: =G27/SUM($G$2:$G$161) -> 0.0069452483
A28: 135 | B28: EliteField Soft Sided Pet Carrier (3 Year Warranty, Airline Approved), Multiple Sizes and Colors Available | C28: EliteField | D28: 29.99 | E28: Pet Supplies | F28: 12784 | G28: 180 | H28: 5398.2 | I28: 534 | J28: 4.3 | K28: FBA | L28: B01CY48OIO | M28: https://www.amazon.com/dp/B01CY48OIO?psc=1 | N28: 1045 | O28: =IFERROR(VLOOKUP(L28,#REF!,5,0),"") | P28: =G28/SUM($G$2:$G$161) -> 0.0069452483
A29: 77 | B29: Best Pet Supplies Voyager Soft Harness for Pets - No Pull Vest | C29: Best Pet Supplies, Inc. | D29: 13.99 | E29: Pet Supplies | F29: 16620 | G29: 150 | H29: 2098.5 | I29: 1529 | J29: 4.4 | K29: AMZ | L29: B07J4W6KW2 | M29: https://www.amazon.com/dp/B07J4W6KW2?psc=1 | N29: 2186 | O29: =IFERROR(VLOOKUP(L29,#REF!,5,0),"") | P29: =G29/SUM($G$2:$G$161) -> 0.0057877069
A30: 81 | B30: 骞垮憡-Kamots Beauty Escape Proof Cat Harness and Leash for Walking Adjustable Soft Mesh Pet Vest with Lead for Kitten | C30: Kamots Beauty | D30: 11.48 | E30: Pet Supplies | F30: 17750 | G30: 120 | H30: 1377.6 | I30: 41 | J30: 3.9 | K30: FBA | L30: B07LGS8M36 | M30: https://www.amazon.com/dp/B07LGS8M36?psc=1 | N30: 159 | O30: =IFERROR(VLOOKUP(L30,#REF!,5,0),"") | P30: =G30/SUM($G$2:$G$161) -> 0.0046301655
A31: 102 | B31: BINGPET Escape Proof Cat Harness with Leash - Adjustable Soft Mesh Vest for Walking | C31: BINGPET | D31: 12.99 | E31: Pet Supplies | F31: 19836 | G31: 120 | H31: 1558.8 | I31: 12 | J31: 4.2 | K31: FBA | L31: B07PNFDG8P | M31: https://www.amazon.com/dp/B07PNFDG8P?psc=1 | N31: 150 | O31: =IFERROR(VLOOKUP(L31,#REF!,5,0),"") | P31: =G31/SUM($G$2:$G$161) -> 0.0046301655
A32: 56 | B32: Kamots Beauty Escape Proof Cat Harness and Leash for Walking Adjustable Soft Mesh Pet Vest with Lead for Kitten | C32: Kamots Beauty | D32: 11.48 | E32: Pet Supplies | F32: 17750 | G32: 120 | H32: 1377.6 | I32: 41 | J32: 3.9 | K32: FBA | L32: B07LGS8M36 | M32: https://www.amazon.com/dp/B07LGS8M36?psc=1 | N32: 159 | O32: =IFERROR(VLOOKUP(L32,#REF!,5,0),"") | P32: =G32/SUM($G$2:$G$161) -> 0.0046301655
A33: 121 | B33: Rella Home Cat Harness and Leash Adjustable Nylon Halter Harness Kitten Nylon Strap Belt Safety Rope Leads | C33: Rella Home | D33: 7.99 | E33: Pet Supplies | F33: 18783 | G33: 120 | H33: 958.8 | I33: 88 | J33: 4.1 | K33: FBA | L33: B0753J3RBC | M33: https://www.amazon.com/dp/B0753J3RBC?psc=1 | N33: 473 | O33: =IFERROR(VLOOKUP(L33,#REF!,5,0),"") | P33: =G33/SUM($G$2:$G$161) -> 0.0046301655
... A69: 92 | B69: TOMKAS Small Dog Cat Carrier Sling Hands Free Pet Puppy Outdoor Travel Bag Tote Reversible | C69: TOMKAS | D69: 19.99 | E69: Pet Supplies | F69: 1483 | G69: 74 | H69: 1479.26 | I69: 920 | J69: 4.3 | K69: FBA | L69: B01M5D90I0 | M69: https://www.amazon.com/dp/B01M5D90I0?psc=1 | N69: 241 | O69: =IFERROR(VLOOKUP(L69,#REF!,5,0),"") | P69: =G69/SUM($G$2:$G$161) -> 0.0028552687
A70: 128 | B70: XPangle No Pull Dog Harness Easy Walk, Adjustable Escape Proof Pet Harness Outdoor for Small Medium Large Dogs | C70: XPangle | D70: 12.99 | E70: Pet Supplies | F70: 150395 | G70: 74 | H70: 961.26 | I70: 0 | J70: N.A. | K70: FBA | L70: B07QM55LKZ | M70: https://www.amazon.com/dp/B07QM55LKZ?psc=1 | N70: 49 | O70: =IFERROR(VLOOKUP(L70,#REF!,5,0),"") | P70: =G70/SUM($G$2:$G$161) -> 0.0028552687
A71: 123 | B71: Hamilton 3/8-Inch Adjustable Reflective Figure 8 Pup-Cat Harness | C71: Hamilton | D71: 18.75 | E71: Pet Supplies | F71: 152809 | G71: 74 | H71: 1387.5 | I71: 18 | J71: 3.3 | K71: AMZ | L71: B00E1C2T3E | M71: https://www.amazon.com/dp/B00E1C2T3E?psc=1 | N71: 1811 | O71: =IFERROR(VLOOKUP(L71,#REF!,5,0),"") | P71: =G71/SUM($G$2:$G$161) -> 0.0028552687
A72: 153 | B72: SlowTon Dog Car Harness Plus Connector Strap, Multifunction Adjustable Vest Harness Double Breathable Mesh Fabric with Car Vehicle Safety Seat Belt | C72: SlowTon | D72: 14.99 | E72: Pet Supplies | F72: 45302 | G72: 69 | H72: 1034.31 | I72: 953 | J72: 4.5 | K72: FBA | L72: B07F75Q3ZW | M72: https://www.amazon.com/dp/B07F75Q3ZW?psc=1 | N72: 714 | O72: =IFERROR(VLOOKUP(L72,#REF!,5,0),"") | P72: =G72/SUM($G$2:$G$161) -> 0.0026623452
A73: 87 | B73: OFPUPPY Escape Proof Cat Harness and Leash Set Adjustable - Soft Mesh - for Kitty Kitten Walking Black | C73: OFPUPPY | D73: 10.99 | E73: Pet Supplies | F73: 91540 | G73: 68 | H73: 747.32 | I73: 22 | J73: 3.7 | K73: FBA | L73: B07FCDWH3Z | M73: https://www.amazon.com/dp/B07FCDWH3Z?psc=1 | N73: 241 | O73: =IFERROR(VLOOKUP(L73,#REF!,5,0),"") | P73: =G73/SUM($G$2:$G$161) -> 0.0026237605
A74: 38 | B74: 骞垮憡-Unihubys Cat Harness with Leash Set- Adjustable Embroidered Bee H Style Harness and Leash for Walking | C74: Unihubys | D74: 10.99 | E74: Pet Supplies | F74: 121441 | G74: 68 | H74: 747.32 | I74: 0 | J74: N.A. | K74: FBA | L74: B07RM3T9B6 | M74: https://www.amazon.com/dp/B07RM3T9B6?psc=1 | N74: 1099 | O74: =IFERROR(VLOOKUP(L74,#REF!,5,0),"") | P74: =G74/SUM($G$2:$G$161) -> 0.0026237605
A75: 90 | B75: Coastal Pet Products CCP7348NPK Nylon Right Adjustable Figure 8 Cat Harness, Neon Pink | C75: Coastal Pet | D75: 13.92 | E75: Pet Supplies | F75: 166174 | G75: 68 | H75: 946.56 | I75: 25 | J75: 4.1 | K75: FBA | L75: B004LO7M4S | M75: https://www.amazon.com/dp/B004LO7M4S?psc=1 | N75: 3396 | O75: =IFERROR(VLOOKUP(L75,#REF!,5,0),"") | P75: =G75/SUM($G$2:$G$161) -> 0.0026237605
A76: 130 | B76: Stock Show Pet Cat Harness with Lead Leash Set Cat Reflective Adjustable Mesh Paddded Chest Harness Escape Proof Harness for Outdoor Walking Jogging for Cat, 12-16, Mint Green | C76: Stock Show | D76: 9.99 | E76: Pet Supplies | F76: 48325 | G76: 63 | H76: 629.37 | I76: 5 | J76: 3.1 | K76: FBA | L76: B07GNDW9Y7 | M76: https://www.amazon.com/dp/B07GNDW9Y7?psc=1 | N76: 221 | O76: =IFERROR(VLOOKUP(L76,#REF!,5,0),"") | P76: =G76/SUM($G$2:$G$161) -> 0.0024308369
A77: 6 | B77: Didog Adjustable Pet Mesh Vest Harness and Leash Set with Cute Bell for Puppy Small Medium Dogs and Cats | C77: Didog | D77: 11.59 | E77: Pet Supplies | F77: 116053 | G77: 63 | H77: 730.17 | I77: 96 | J77: 3.9 | K77: FBA | L77: B0721MH5QH | M77: https://www.amazon.com/dp/B0721MH5QH?psc=1 | N77: 670 | O77: =IFERROR(VLOOKUP(L77,#REF!,5,0),"") | P77: =G77/SUM($G$2:$G$161) -> 0.0024308369
A78: 91 | B78: Smdoxi Dog Puppy Harness Leash Collar Cat Vest Strap with Angel Wings (Pink, XS) | C78: Smdoxi | D78: 2.99 | E78: N.A. | F78: N.A. | G78: 63 | H78: 188.37 | I78: 5 | J78: 4.5 | K78: FBA | L78: B079QVHVHT | M78: https://www.amazon.com/dp/B079QVHVHT?psc=1 | N78: 2517 | O78: =IFERROR(VLOOKUP(L78,#REF!,5,0),"") | P78: =G78/SUM($G$2:$G$161) -> 0.0024308369
A79: 33 | B79: Red Dingo Classic Cat Harness and Lead Combo | C79: Red Dingo | D79: 15.9 | E79: Pet Supplies | F79: 144485 | G79: 63 | H79: 1001.7 | I79: 17 | J79: 3.3 | K79: AMZ | L79: B0088VPH3S | M79: https://www.amazon.com/dp/B0088VPH3S?psc=1 | N79: 2193 | O79: =IFERROR(VLOOKUP(L79,#REF!,5,0),"") | P79: =G79/SUM($G$2:$G$161) -> 0.0024308369
...

Sheet 竞品分析
A1: ASIN | B1: Brand | C1: Price | D1: Category | E1: Rank | F1: Sales | G1: Revenue | H1: Reviews | I1: Rating | J1: Seller | K1: Link | L1: 上架时间 | M1: 竞品价格 | N1: 竞品数量 | O1: 最低价 | P1: 最高价 | Q1: 竞品销量 | R1: 销量数量 | S1: 最低量 | T1: 最高量 | U1: 价格 | V1: 销量 | X1: 竞品分析
A2: =数据调研!L2 -> B07NQ35VDW | B2: =数据调研!C2 -> Eagloo | C2: =数据调研!D2 -> 13.99 | D2: =数据调研!E2 -> Pet Supplies | E2: =数据调研!F2 -> 764 | F2: =数据调研!G2 -> 2550 | G2: =数据调研!H2 -> 35674.5 | H2: =数据调研!I2 -> 79 | I2: =数据调研!J2 -> 4 | J2: =数据调研!K2 -> FBA | K2: =数据调研!M2 -> https://www.amazon.com/dp/B07NQ35VDW?psc=1 | L2: =数据调研!N2 -> 387 | M2: =IF(AND(AC4<>0,AC4<>"N.A."),AC4,0) -> 13.99 | N2: =IF(M2<>0,1,0) -> 1 | O2: =IF(N2=1,M2,100000) -> 13.99 | P2: =IF(N2=1,M2,0) -> 13.99 | Q2: =IF(AND(AD4<>"N.A.",AD4<>"< 5"),AD4,0) -> 2550 | R2: =IF(Q2<>0,1,0) -> 1 | S2: =IF(R2=1,Q2,10000000) -> 2550 | T2: =IF(R2=1,S2,0) -> 2550 | U2: =M2 -> 13.99 | V2: =Q2 -> 2550
A3: =数据调研!L3 -> B07NQ35VDW | B3: =数据调研!C3 -> Eagloo | C3: =数据调研!D3 -> 13.99 | D3: =数据调研!E3 -> Pet Supplies | E3: =数据调研!F3 -> 764 | F3: =数据调研!G3 -> 2550 | G3: =数据调研!H3 -> 35674.5 | H3: =数据调研!I3 -> 79 | I3: =数据调研!J3 -> 4 | J3: =数据调研!K3 -> FBA | K3: =数据调研!M3 -> https://www.amazon.com/dp/B07NQ35VDW?psc=1 | L3: =数据调研!N3 -> 387 | M3: =IF(AND(AC5<>0,AC5<>"N.A."),AC5,0) -> 13.99 | N3: =IF(M3<>0,1,0) -> 1 | O3: =IF(N3=1,M3,100000) -> 13.99 | P3: =IF(N3=1,M3,0) -> 13.99 | Q3: =IF(AND(AD5<>"N.A.",AD5<>"< 5"),AD5,0) -> 960 | R3: =IF(Q3<>0,1,0) -> 1 | S3: =IF(R3=1,Q3,10000000) -> 960 | T3: =IF(R3=1,S3,0) -> 960 | U3: =M3 -> 13.99 | V3: =Q3 -> 960 | X3: 图片 | AA3: 站点 | AB3: ASIN | AC3: 价格 | AD3: 月销量 | AE3: 品牌 | AF3: 评论数 | AG3: 大类排名 | AH3: 星级 | AI3: 链接 | AJ3: 上架天数 | AK3: 店铺背景分析 | AM3: 产品特色 | AO3: 注意 1、该表格有自动填充功能，当你输入产品的ASIN码时会自动填充其他内容。但是除了图片。所以使用表格时先输入图片和ASIN码。如果输入ASIN码后不能自动填充，其他信息就需要手动输入。 2、请勿改动除图片、ASIN、优点以外的任何数据，不然被改动的单元格不再具备自动填充功能。
A4: =数据调研!L4 -> B07NQ35VDW | B4: =数据调研!C4 -> Eagloo | C4: =数据调研!D4 -> 13.99 | D4: =数据调研!E4 -> Pet Supplies | E4: =数据调研!F4 -> 764 | F4: =数据调研!G4 -> 2550 | G4: =数据调研!H4 -> 35674.5 | H4: =数据调研!I4 -> 79 | I4: =数据调研!J4 -> 4 | J4: =数据调研!K4 -> FBA | K4: =数据调研!M4 -> https://www.amazon.com/dp/B07NQ35VDW?psc=1 | L4: =数据调研!N4 -> 387 | M4: =IF(AND(AC6<>0,AC6<>"N.A."),AC6,0) -> 12.98 | N4: =IF(M4<>0,1,0) -> 1 | O4: =IF(N4=1,M4,100000) -> 12.98 | P4: =IF(N4=1,M4,0) -> 12.98 | Q4: =IF(AND(AD6<>"N.A.",AD6<>"< 5"),AD6,0) -> 390 | R4: =IF(Q4<>0,1,0) -> 1 | S4: =IF(R4=1,Q4,10000000) -> 390 | T4: =IF(R4=1,S4,0) -> 390 | U4: =M4 -> 12.98 | V4: =Q4 -> 390 | AA4: US | AB4: B07NQ35VDW | AC4: =VLOOKUP(AB4,A:C,3,0) -> 13.99 | AD4: =VLOOKUP(AB4,A:F,6,0) -> 2550 | AE4: =VLOOKUP(AB4,A:B,2,0) -> Eagloo | AF4: =VLOOKUP(AB4,A:H,8,0) -> 79 | AG4: =VLOOKUP(AB4,A:E,5,0) -> 764 | AH4: =VLOOKUP(AB4,A:I,9,0) -> 4 | AI4: =VLOOKUP(AB4,A:K,11,0) -> https://www.amazon.com/dp/B07NQ35VDW?psc=1 | AJ4: =VLOOKUP(AB4,A:L,12,0) -> 387 | AK4: 一两年的店铺，主营宠物类用品，该产品占据50%以上的销售份额 | AM4: 防逃生、可调、反光带、造型简约、13-18in
A5: =数据调研!L5 -> B078G6MKTN | B5: =数据调研!C5 -> BWOGUE | C5: =数据调研!D5 -> 10.49 | D5: =数据调研!E5 -> Pet Supplies | E5: =数据调研!F5 -> 921 | F5: =数据调研!G5 -> 2220 | G5: =数据调研!H5 -> 23287.8 | H5: =数据调研!I5 -> 743 | I5: =数据调研!J5 -> 4.7 | J5: =数据调研!K5 -> FBA | K5: =数据调研!M5 -> https://www.amazon.com/dp/B078G6MKTN?psc=1 | L5: =数据调研!N5 -> 459 | M5: =IF(AND(AC7<>0,AC7<>"N.A."),AC7,0) -> 10.99 | N5: =IF(M5<>0,1,0) -> 1 | O5: =IF(N5=1,M5,100000) -> 10.99 | P5: =IF(N5=1,M5,0) -> 10.99 | Q5: =IF(AND(AD7<>"N.A.",AD7<>"< 5"),AD7,0) -> 270 | R5: =IF(Q5<>0,1,0) -> 1 | S5: =IF(R5=1,Q5,10000000) -> 270 | T5: =IF(R5=1,S5,0) -> 270 | U5: =M5 -> 10.99 | V5: =Q5 -> 270 | AA5: US | AB5: B07MKQFJSP | AC5: =VLOOKUP(AB5,A:C,3,0) -> 13.99 | AD5: =VLOOKUP(AB5,A:F,6,0) -> 960 | AE5: =VLOOKUP(AB5,A:B,2,0) -> PUPTECK | AF5: =VLOOKUP(AB5,A:H,8,0) -> 13 | AG5: =VLOOKUP(AB5,A:E,5,0) -> 2511 | AH5: =VLOOKUP(AB5,A:I,9,0) -> 4.8 | AI5: =VLOOKUP(AB5,A:K,11,0) -> https://www.amazon.com/dp/B07MKQFJSP?psc=1 | AJ5: =VLOOKUP(AB5,A:L,12,0) -> 96 | AK5: 两年多的大店，专注宠物类用品 | AM5: 带子清新时尚、防逃生、造型简约、多颜色变体
A6: =数据调研!L6 -> B000OGRDK0 | B6: =数据调研!C6 -> PetSafe | C6: =数据调研!D6 -> 4.79 | D6: =数据调研!E6 -> Pet Supplies | E6: =数据调研!F6 -> 1174 | F6: =数据调研!G6 -> 1830 | G6: =数据调研!H6 -> 8765.7 | H6: =数据调研!I6 -> 1616 | I6: =数据调研!J6 -> 4.4 | J6: =数据调研!K6 -> AMZ | K6: =数据调研!M6 -> https://www.amazon.com/dp/B000OGRDK0?psc=1 | L6: =数据调研!N6 -> 4374 | M6: =IF(AND(AC8<>0,AC8<>"N.A."),AC8,0) -> 12.99 | N6: =IF(M6<>0,1,0) -> 1 | O6: =IF(N6=1,M6,100000) -> 12.99 | P6: =IF(N6=1,M6,0) -> 12.99 | Q6: =IF(AND(AD8<>"N.A.",AD8<>"< 5"),AD8,0) -> 360 | R6: =IF(Q6<>0,1,0) -> 1 | S6: =IF(R6=1,Q6,10000000) -> 360 | T6: =IF(R6=1,S6,0) -> 360 | U6: =M6 -> 12.99 | V6: =Q6 -> 360 | AA6: US | AB6: B07MZR3MDT | AC6: =VLOOKUP(AB6,A:C,3,0) -> 12.98 | AD6: =VLOOKUP(AB6,A:F,6,0) -> 390 | AE6: =VLOOKUP(AB6,A:B,2,0) -> Rabbitgoo | AF6: =VLOOKUP(AB6,A:H,8,0) -> 28 | AG6: =VLOOKUP(AB6,A:E,5,0) -> 6553 | AH6: =VLOOKUP(AB6,A:I,9,0) -> 3.7 | AI6: =VLOOKUP(AB6,A:K,11,0) -> https://www.amazon.com/dp/B07MZR3MDT?psc=1 | AJ6: =VLOOKUP(AB6,A:L,12,0) -> 48 | AK6: 大账号、卖家居宠物类产品 | AM6: 防逃生、可调、反光带、造型简约、13-18in、多色
A7: =数据调研!L7 -> B07MKQFJSP | B7: =数据调研!C7 -> PUPTECK | C7: =数据调研!D7 -> 13.99 | D7: =数据调研!E7 -> Pet Supplies | E7: =数据调研!F7 -> 2511 | F7: =数据调研!G7 -> 960 | G7: =数据调研!H7 -> 13430.4 | H7: =数据调研!I7 -> 13 | I7: =数据调研!J7 -> 4.8 | J7: =数据调研!K7 -> FBA | K7: =数据调研!M7 -> https://www.amazon.com/dp/B07MKQFJSP?psc=1 | L7: =数据调研!N7 -> 96 | M7: =IF(AND(AC9<>0,AC9<>"N.A."),AC9,0) -> 11.99 | N7: =IF(M7<>0,1,0) -> 1 | O7: =IF(N7=1,M7,100000) -> 11.99 | P7: =IF(N7=1,M7,0) -> 11.99 | Q7: =IF(AND(AD9<>"N.A.",AD9<>"< 5"),AD9,0) -> 514 | R7: =IF(Q7<>0,1,0) -> 1 | S7: =IF(R7=1,Q7,10000000) -> 514 | T7: =IF(R7=1,S7,0) -> 514 | U7: =M7 -> 11.99 | V7: =Q7 -> 514 | AA7: US | AB7: B07GFBQ4H6 | AC7: =VLOOKUP(AB7,A:C,3,0) -> 10.99 | AD7: =VLOOKUP(AB7,A:F,6,0) -> 270 | AE7: =VLOOKUP(AB7,A:B,2,0) -> GAUTERF | AF7: =VLOOKUP(AB7,A:H,8,0) -> 601 | AG7: =VLOOKUP(AB7,A:E,5,0) -> 9013 | AH7: =VLOOKUP(AB7,A:I,9,0) -> 4.2 | AI7: =VLOOKUP(AB7,A:K,11,0) -> https://www.amazon.com/dp/B07GFBQ4H6?psc=1 | AJ7: =VLOOKUP(AB7,A:L,12,0) -> 364 | AK7: 1年店铺，专卖宠物背带产品 | AM7: 防逃生、可调、反光带、造型简约、多色
A8: =数据调研!L8 -> B07MKQFJSP | B8: =数据调研!C8 -> PUPTECK | C8: =数据调研!D8 -> 13.99 | D8: =数据调研!E8 -> Pet Supplies | E8: =数据调研!F8 -> 2921 | F8: =数据调研!G8 -> 840 | G8: =数据调研!H8 -> 11751.6 | H8: =数据调研!I8 -> 13 | I8: =数据调研!J8 -> 4.8 | J8: =数据调研!K8 -> FBA | K8: =数据调研!M8 -> https://www.amazon.com/dp/B07MKQFJSP?psc=1 | L8: =数据调研!N8 -> 96 | M8: =IF(AND(AC10<>0,AC10<>"N.A."),AC10,0) -> 9.99 | N8: =IF(M8<>0,1,0) -> 1 | O8: =IF(N8=1,M8,100000) -> 9.99 | P8: =IF(N8=1,M8,0) -> 9.99 | Q8: =IF(AND(AD10<>"N.A.",AD10<>"< 5"),AD10,0) -> 102 | R8: =IF(Q8<>0,1,0) -> 1 | S8: =IF(R8=1,Q8,10000000) -> 102 | T8: =IF(R8=1,S8,0) -> 102 | U8: =M8 -> 9.99 | V8: =Q8 -> 102 | AA8: US | AB8: B074MWRZ5Y | AC8: =VLOOKUP(AB8,A:C,3,0) -> 12.99 | AD8: =VLOOKUP(AB8,A:F,6,0) -> 360 | AE8: =VLOOKUP(AB8,A:B,2,0) -> PUPTECK | AF8: =VLOOKUP(AB8,A:H,8,0) -> 944 | AG8: =VLOOKUP(AB8,A:E,5,0) -> 6727 | AH8: =VLOOKUP(AB8,A:I,9,0) -> 3.6 | AI8: =VLOOKUP(AB8,A:K,11,0) -> https://www.amazon.com/dp/B074MWRZ5Y?psc=1 | AJ8: =VLOOKUP(AB8,A:L,12,0) -> 1080 | AK8: 两年多的大店，专注宠物类用品 | AM8: 防逃生、可调、舒适
A9: =数据调研!L9 -> B07GFBW7JT | B9: =数据调研!C9 -> GAUTERF | C9: =数据调研!D9 -> 10.99 | D9: =数据调研!E9 -> Pet Supplies | E9: =数据调研!F9 -> 6044 | F9: =数据调研!G9 -> 420 | G9: =数据调研!H9 -> 4615.8 | H9: =数据调研!I9 -> 601 | I9: =数据调研!J9 -> 4.2 | J9: =数据调研!K9 -> FBA | K9: =数据调研!M9 -> https://www.amazon.com/dp/B07GFBW7JT?psc=1 | L9: =数据调研!N9 -> 256 | M9: =IF(AND(AC11<>0,AC11<>"N.A."),AC11,0) -> 9.99 | N9: =IF(M9<>0,1,0) -> 1 | O9: =IF(N9=1,M9,100000) -> 9.99 | P9: =IF(N9=1,M9,0) -> 9.99 | Q9: =IF(AND(AD11<>"N.A.",AD11<>"< 5"),AD11,0) -> 89 | R9: =IF(Q9<>0,1,0) -> 1 | S9: =IF(R9=1,Q9,10000000) -> 89 | T9: =IF(R9=1,S9,0) -> 89 | U9: =M9 -> 9.99 | V9: =Q9 -> 89 | AA9: UK | AB9: B07B49LNW9 | AC9: 11.99 | AD9: 514 | AE9: BINGPET | AF9: 228 | AG9: 821 | AH9: 4 | AI9: 点此 | AJ9: 715 | AK9: 宠物类店铺 | AM9: 防逃生、可调、舒适
A10: =数据调研!L10 -> B07MZR3MDT | B10: =数据调研!C10 -> Rabbitgoo | C10: =数据调研!D10 -> 12.98 | D10: =数据调研!E10 -> Pet Supplies | E10: =数据调研!F10 -> 6553 | F10: =数据调研!G10 -> 390 | G10: =数据调研!H10 -> 5062.2 | H10: =数据调研!I10 -> 28 | I10: =数据调研!J10 -> 3.7 | J10: =数据调研!K10 -> FBA | K10: =数据调研!M10 -> https://www.amazon.com/dp/B07MZR3MDT?psc=1 | L10: =数据调研!N10 -> 48 | M10: =IF(AND(AC12<>0,AC12<>"N.A."),AC12,0) -> 11.99 | N10: =IF(M10<>0,1,0) -> 1 | O10: =IF(N10=1,M10,100000) -> 11.99 | P10: =IF(N10=1,M10,0) -> 11.99 | Q10: =IF(AND(AD12<>"N.A.",AD12<>"< 5"),AD12,0) -> 124 | R10: =IF(Q10<>0,1,0) -> 1 | S10: =IF(R10=1,Q10,10000000) -> 124 | T10: =IF(R10=1,S10,0) -> 124 | U10: =M10 -> 11.99 | V10: =Q10 -> 124 | AA10: UK | AB10: B07GSJJ2X6 | AC10: 9.99 | AD10: 102 | AE10: SCENEREAL | AF10: 31 | AG10: 4821 | AH10: 4 | AI10: 点此 | AJ10: 16 | AK10: 宠物类店铺 | AM10: 防逃生、可调、舒适
A11: =数据调研!L11 -> B07MZR3MDT | B11: =数据调研!C11 -> Rabbitgoo | C11: =数据调研!D11 -> 12.98 | D11: =数据调研!E11 -> Pet Supplies | E11: =数据调研!F11 -> 6553 | F11: =数据调研!G11 -> 390 | G11: =数据调研!H11 -> 5062.2 | H11: =数据调研!I11 -> 28 | I11: =数据调研!J11 -> 3.7 | J11: =数据调研!K11 -> FBA | K11: =数据调研!M11 -> https://www.amazon.com/dp/B07MZR3MDT?psc=1 | L11: =数据调研!N11 -> 48 | M11: =IF(AND(AC13<>0,AC13<>"N.A."),AC13,0) -> 0 | N11: =IF(M11<>0,1,0) -> 0 | O11: =IF(N11=1,M11,100000) -> 100000 | P11: =IF(N11=1,M11,0) -> 0 | Q11: =IF(AND(AD13<>"N.A.",AD13<>"< 5"),AD13,0) -> 0 | R11: =IF(Q11<>0,1,0) -> 0 | S11: =IF(R11=1,Q11,10000000) -> 10000000 | T11: =IF(R11=1,S11,0) -> 0 | U11: =M11 -> 0 | V11: =Q11 -> 0 | AA11: UK | AB11: B07R8Y1DLY | AC11: 9.99 | AD11: 89 | AE11: EXPAWLORER | AF11: 10 | AG11: 9220 | AH11: 4.8 | AI11: 点此 | AJ11: 712 | AK11: 宠物类店铺，卖得好的产品是定制项圈 | AM11: 防逃生、可调、舒适，胸围: 29-35.6cm, 颈围:20.3-24.1cm
A12: =数据调研!L12 -> B074MWRZ5Y | B12: =数据调研!C12 -> PUPTECK | C12: =数据调研!D12 -> 12.99 | D12: =数据调研!E12 -> Pet Supplies | E12: =数据调研!F12 -> 6727 | F12: =数据调研!G12 -> 360 | G12: =数据调研!H12 -> 4676.4 | H12: =数据调研!I12 -> 944 | I12: =数据调研!J12 -> 3.6 | J12: =数据调研!K12 -> FBA | K12: =数据调研!M12 -> https://www.amazon.com/dp/B074MWRZ5Y?psc=1 | L12: =数据调研!N12 -> 1080 | M12: =IF(AND(#REF!<>0,#REF!<>"N.A."),#REF!,0) -> #REF! | N12: =IF(M12<>0,1,0) -> #REF! | O12: =IF(N12=1,M12,100000) -> #REF! | P12: =IF(N12=1,M12,0) -> #REF! | Q12: =IF(AND(#REF!<>"N.A.",#REF!<>"< 5"),#REF!,0) -> #REF! | R12: =IF(Q12<>0,1,0) -> #REF! | S12: =IF(R12=1,Q12,10000000) -> #REF! | T12: =IF(R12=1,S12,0) -> #REF! | U12: =M12 -> #REF! | V12: =Q12 -> #REF! | AA12: UK | AB12: B07G43RT89 | AC12: 11.99 | AD12: 124 | AE12: HOMIMP | AF12: 22 | AG12: 3730 | AH12: 4.1 | AI12: 点此 | AJ12: 407 | AK12: 一年左右的新店铺，主卖宠物类产品，值得借鉴 | AM12: 普通款，老款产品，双D型扣
A13: =数据调研!L13 -> B07MDLYQR7 | B13: =数据调研!C13 -> INVENHO | C13: =数据调研!D13 -> 10.99 | D13: =数据调研!E13 -> Pet Supplies | E13: =数据调研!F13 -> 7043 | F13: =数据调研!G13 -> 360 | G13: =数据调研!H13 -> 3956.4 | H13: =数据调研!I13 -> 124 | I13: =数据调研!J13 -> 4.3 | J13: =数据调研!K13 -> FBA | K13: =数据调研!M13 -> https://www.amazon.com/dp/B07MDLYQR7?psc=1 | L13: =数据调研!N13 -> 556 | M13: =IF(AND(#REF!<>0,#REF!<>"N.A."),#REF!,0) -> #REF! | N13: =IF(M13<>0,1,0) -> #REF! | O13: =IF(N13=1,M13,100000) -> #REF! | P13: =IF(N13=1,M13,0) -> #REF! | Q13: =IF(AND(#REF!<>"N.A.",#REF!<>"< 5"),#REF!,0) -> #REF! | R13: =IF(Q13<>0,1,0) -> #REF! | S13: =IF(R13=1,Q13,10000000) -> #REF! | T13: =IF(R13=1,S13,0) -> #REF! | U13: =M13 -> #REF! | V13: =Q13 -> #REF! | X13: 客户潜在需求分析 | AH13: 痛点分析
A14: =数据调研!L14 -> B07MDLYQR7 | B14: =数据调研!C14 -> INVENHO | C14: =数据调研!D14 -> 10.99 | D14: =数据调研!E14 -> Pet Supplies | E14: =数据调研!F14 -> 7043 | F14: =数据调研!G14 -> 360 | G14: =数据调研!H14 -> 3956.4 | H14: =数据调研!I14 -> 124 | I14: =数据调研!J14 -> 4.3 | J14: =数据调研!K14 -> FBA | K14: =数据调研!M14 -> https://www.amazon.com/dp/B07MDLYQR7?psc=1 | L14: =数据调研!N14 -> 556 | M14: =IF(AND(#REF!<>0,#REF!<>"N.A."),#REF!,0) -> #REF! | N14: =IF(M14<>0,1,0) -> #REF! | O14: =IF(N14=1,M14,100000) -> #REF! | P14: =IF(N14=1,M14,0) -> #REF! | Q14: =IF(AND(#REF!<>"N.A.",#REF!<>"< 5"),#REF!,0) -> #REF! | R14: =IF(Q14<>0,1,0) -> #REF! | S14: =IF(R14=1,Q14,10000000) -> #REF! | T14: =IF(R14=1,S14,0) -> #REF! | U14: =M14 -> #REF! | V14: =Q14 -> #REF!
A15: =数据调研!L15 -> B00M0V7UVE | B15: =数据调研!C15 -> Best Pet Supplies, Inc. | C15: =数据调研!D15 -> 12.99 | D15: =数据调研!E15 -> Pet Supplies | E15: =数据调研!F15 -> 7965 | F15: =数据调研!G15 -> 300 | G15: =数据调研!H15 -> 3897 | H15: =数据调研!I15 -> 4515 | I15: =数据调研!J15 -> 4.3 | J15: =数据调研!K15 -> AMZ | K15: =数据调研!M15 -> https://www.amazon.com/dp/B00M0V7UVE?psc=1 | L15: =数据调研!N15 -> 1921 | M15: =IF(AND(#REF!<>0,#REF!<>"N.A."),#REF!,0) -> #REF! | N15: =IF(M15<>0,1,0) -> #REF! | O15: =IF(N15=1,M15,100000) -> #REF! | P15: =IF(N15=1,M15,0) -> #REF! | Q15: =IF(AND(#REF!<>"N.A.",#REF!<>"< 5"),#REF!,0) -> #REF! | R15: =IF(Q15<>0,1,0) -> #REF! | S15: =IF(R15=1,Q15,10000000) -> #REF! | T15: =IF(R15=1,S15,0) -> #REF! | U15: =M15 -> #REF! | V15: =Q15 -> #REF! | X15: 序号 | Y15: 需求描述 | AC15: 次数 | AD15: 对策 | AH15: 序号 | AI15: 描述 | AL15: 比例 | AM15: 解决对策
A16: =数据调研!L16 -> B07GFBQ4H6 | B16: =数据调研!C16 -> GAUTERF | C16: =数据调研!D16 -> 10.99 | D16: =数据调研!E16 -> Pet Supplies | E16: =数据调研!F16 -> 9013 | F16: =数据调研!G16 -> 270 | G16: =数据调研!H16 -> 2967.3 | H16: =数据调研!I16 -> 601 | I16: =数据调研!J16 -> 4.2 | J16: =数据调研!K16 -> FBA | K16: =数据调研!M16 -> https://www.amazon.com/dp/B07GFBQ4H6?psc=1 | L16: =数据调研!N16 -> 364 | M16: =IF(AND(#REF!<>0,#REF!<>"N.A."),#REF!,0) -> #REF! | N16: =IF(M16<>0,1,0) -> #REF! | O16: =IF(N16=1,M16,100000) -> #REF! | P16: =IF(N16=1,M16,0) -> #REF! | Q16: =IF(AND(#REF!<>"N.A.",#REF!<>"< 5"),#REF!,0) -> #REF! | R16: =IF(Q16<>0,1,0) -> #REF! | S16: =IF(R16=1,Q16,10000000) -> #REF! | T16: =IF(R16=1,S16,0) -> #REF! | U16: =M16 -> #REF! | V16: =Q16 -> #REF! | X16: 1 | Y16: 需要能更好的调整背带长度 | AC16: 4 | AH16: 1 | AI16: 猫容易逃脱出去 | AL16: 0.56 | AM16: 改变穿戴方式
A17: =数据调研!L17 -> B01MY4O0CE | B17: =数据调研!C17 -> PUPTECK | C17: =数据调研!D17 -> 9.99 | D17: =数据调研!E17 -> Pet Supplies | E17: =数据调研!F17 -> 9685 | F17: =数据调研!G17 -> 240 | G17: =数据调研!H17 -> 2397.6 | H17: =数据调研!I17 -> 614 | I17: =数据调研!J17 -> 4.2 | J17: =数据调研!K17 -> FBA | K17: =数据调研!M17 -> https://www.amazon.com/dp/B01MY4O0CE?psc=1 | L17: =数据调研!N17 -> 795 | M17: =IF(AND(#REF!<>0,#REF!<>"N.A."),#REF!,0) -> #REF! | N17: =IF(M17<>0,1,0) -> #REF! | O17: =IF(N17=1,M17,100000) -> #REF! | P17: =IF(N17=1,M17,0) -> #REF! | Q17: =IF(AND(#REF!<>"N.A.",#REF!<>"< 5"),#REF!,0) -> #REF! | R17: =IF(Q17<>0,1,0) -> #REF! | S17: =IF(R17=1,Q17,10000000) -> #REF! | T17: =IF(R17=1,S17,0) -> #REF! | U17: =M17 -> #REF! | V17: =Q17 -> #REF! | X17: 2 | Y17: 希望更薄 | AC17: 2 | AH17: 2 | AI17: 尺寸不合适 | AL17: 0.17 | AM17: 改为尺寸可调节
A18: =数据调研!L18 -> B07MKTGM95 | B18: =数据调研!C18 -> INVENHO | C18: =数据调研!D18 -> 9.99 | D18: =数据调研!E18 -> Pet Supplies | E18: =数据调研!F18 -> 10023 | F18: =数据调研!G18 -> 240 | G18: =数据调研!H18 -> 2397.6 | H18: =数据调研!I18 -> 124 | I18: =数据调研!J18 -> 4.3 | J18: =数据调研!K18 -> FBA | K18: =数据调研!M18 -> https://www.amazon.com/dp/B07MKTGM95?psc=1 | L18: =数据调研!N18 -> 556 | M18: =IF(AND(#REF!<>0,#REF!<>"N.A."),#REF!,0) -> #REF! | N18: =IF(M18<>0,1,0) -> #REF! | O18: =IF(N18=1,M18,100000) -> #REF! | P18: =IF(N18=1,M18,0) -> #REF! | Q18: =IF(AND(#REF!<>"N.A.",#REF!<>"< 5"),#REF!,0) -> #REF! | R18: =IF(Q18<>0,1,0) -> #REF! | S18: =IF(R18=1,Q18,10000000) -> #REF! | T18: =IF(R18=1,S18,0) -> #REF! | U18: =M18 -> #REF! | V18: =Q18 -> #REF! | X18: 3 | Y18: 舒适度是首要的 | AC18: 1 | AH18: 3 | AI18: 背带太重 | AL18: 0.06 | AM18: 减轻背带重量
A19: =数据调研!L19 -> B007KAX8DO | B19: =数据调研!C19 -> Kitty Holster | C19: =数据调研!D19 -> 24.95 | D19: =数据调研!E19 -> Pet Supplies | E19: =数据调研!F19 -> 11080 | F19: =数据调研!G19 -> 210 | G19: =数据调研!H19 -> 5239.5 | H19: =数据调研!I19 -> 1428 | I19: =数据调研!J19 -> 4.3 | J19: =数据调研!K19 -> FBA | K19: =数据调研!M19 -> https://www.amazon.com/dp/B007KAX8DO?psc=1 | L19: =数据调研!N19 -> 2527 | M19: =IF(AND(#REF!<>0,#REF!<>"N.A."),#REF!,0) -> #REF! | N19: =IF(M19<>0,1,0) -> #REF! | O19: =IF(N19=1,M19,100000) -> #REF! | P19: =IF(N19=1,M19,0) -> #REF! | Q19: =IF(AND(#REF!<>"N.A.",#REF!<>"< 5"),#REF!,0) -> #REF! | R19: =IF(Q19<>0,1,0) -> #REF! | S19: =IF(R19=1,Q19,10000000) -> #REF! | T19: =IF(R19=1,S19,0) -> #REF! | U19: =M19 -> #REF! | V19: =Q19 -> #REF! | X19: 4 | AH19: 4 | AI19: 太厚、太热、不喜欢尼龙粘扣 | AL19: 0.07 | AM19: 减轻背带重量
A20: =数据调研!L20 -> B07F8RY3C6 | B20: =数据调研!C20 -> SCENEREAL | C20: =数据调研!D20 -> 13.99 | D20: =数据调研!E20 -> Pet Supplies | E20: =数据调研!F20 -> 10702 | F20: =数据调研!G20 -> 210 | G20: =数据调研!H20 -> 2937.9 | H20: =数据调研!I20 -> 67 | I20: =数据调研!J20 -> 3.9 | J20: =数据调研!K20 -> FBA | K20: =数据调研!M20 -> https://www.amazon.com/dp/B07F8RY3C6?psc=1 | L20: =数据调研!N20 -> 272 | M20: =IF(AND(AC21<>0,AC21<>"N.A."),AC21,0) -> 0 | N20: =IF(M20<>0,1,0) -> 0 | O20: =IF(N20=1,M20,100000) -> 100000 | P20: =IF(N20=1,M20,0) -> 0 | Q20: =IF(AND(#REF!<>"N.A.",#REF!<>"< 5"),#REF!,0) -> #REF! | R20: =IF(Q20<>0,1,0) -> #REF! | S20: =IF(R20=1,Q20,10000000) -> #REF! | T20: =IF(R20=1,S20,0) -> #REF! | U20: =M20 -> 0 | V20: =Q20 -> #REF! | X20: 5 | AH20: 5
A21: =数据调研!L21 -> B001OMD5ZA | B21: =数据调研!C21 -> PetSafe | C21: =数据调研!D21 -> 14.95 | D21: =数据调研!E21 -> Amazon Best Sellers Rank: | E21: =数据调研!F21 -> N.A. | F21: =数据调研!G21 -> 210 | G21: =数据调研!H21 -> 3139.5 | H21: =数据调研!I21 -> 2543 | I21: =数据调研!J21 -> 3.9 | J21: =数据调研!K21 -> AMZ | K21: =数据调研!M21 -> https://www.amazon.com/dp/B001OMD5ZA?psc=1 | L21: =数据调研!N21 -> 4229 | M21: =IF(AND(#REF!<>0,#REF!<>"N.A."),#REF!,0) -> #REF! | N21: =IF(M21<>0,1,0) -> #REF! | O21: =IF(N21=1,M21,100000) -> #REF! | P21: =IF(N21=1,M21,0) -> #REF! | Q21: =IF(AND(#REF!<>"N.A.",#REF!<>"< 5"),#REF!,0) -> #REF! | R21: =IF(Q21<>0,1,0) -> #REF! | S21: =IF(R21=1,Q21,10000000) -> #REF! | T21: =IF(R21=1,S21,0) -> #REF! | U21: =M21 -> #REF! | V21: =Q21 -> #REF! | X21: 6 | AH21: 6
A22: =数据调研!L22 -> B077XY1CBC | B22: =数据调研!C22 -> Yizhi Miaow | C22: =数据调研!D22 -> 14.49 | D22: =数据调研!E22 -> Pet Supplies | E22: =数据调研!F22 -> 12619 | F22: =数据调研!G22 -> 180 | G22: =数据调研!H22 -> 2608.2 | H22: =数据调研!I22 -> 263 | I22: =数据调研!J22 -> 4 | J22: =数据调研!K22 -> FBA | K22: =数据调研!M22 -> https://www.amazon.com/dp/B077XY1CBC?psc=1 | L22: =数据调研!N22 -> 533 | M22: =IF(AND(#REF!<>0,#REF!<>"N.A."),#REF!,0) -> #REF! | N22: =IF(M22<>0,1,0) -> #REF! | O22: =IF(N22=1,M22,100000) -> #REF! | P22: =IF(N22=1,M22,0) -> #REF! | Q22: =IF(AND(#REF!<>"N.A.",#REF!<>"< 5"),#REF!,0) -> #REF! | R22: =IF(Q22<>0,1,0) -> #REF! | S22: =IF(R22=1,Q22,10000000) -> #REF! | T22: =IF(R22=1,S22,0) -> #REF! | U22: =M22 -> #REF! | V22: =Q22 -> #REF! | Z22: 竞品总结
A23: =数据调研!L23 -> B07DWPTT9S | B23: =数据调研!C23 -> OFPUPPY | C23: =数据调研!D23 -> 9.99 | D23: =数据调研!E23 -> Pet Supplies | E23: =数据调研!F23 -> 98482 | F23: =数据调研!G23 -> 180 | G23: =数据调研!H23 -> 1798.2 | H23: =数据调研!I23 -> 14 | I23: =数据调研!J23 -> 3.9 | J23: =数据调研!K23 -> FBA | K23: =数据调研!M23 -> https://www.amazon.com/dp/B07DWPTT9S?psc=1 | L23: =数据调研!N23 -> 309 | M23: =IF(AND(#REF!<>0,#REF!<>"N.A."),#REF!,0) -> #REF! | N23: =IF(M23<>0,1,0) -> #REF! | O23: =IF(N23=1,M23,100000) -> #REF! | P23: =IF(N23=1,M23,0) -> #REF! | Q23: =IF(AND(#REF!<>"N.A.",#REF!<>"< 5"),#REF!,0) -> #REF! | R23: =IF(Q23<>0,1,0) -> #REF! | S23: =IF(R23=1,Q23,10000000) -> #REF! | T23: =IF(R23=1,S23,0) -> #REF! | U23: =M23 -> #REF! | V23: =Q23 -> #REF!
A24: =数据调研!L24 -> B07MMHDWTC | B24: =数据调研!C24 -> voopet | C24: =数据调研!D24 -> 10.99 | D24: =数据调研!E24 -> Pet Supplies | E24: =数据调研!F24 -> 140925 | F24: =数据调研!G24 -> 180 | G24: =数据调研!H24 -> 1978.2 | H24: =数据调研!I24 -> 2 | I24: =数据调研!J24 -> 5 | J24: =数据调研!K24 -> FBA | K24: =数据调研!M24 -> https://www.amazon.com/dp/B07MMHDWTC?psc=1 | L24: =数据调研!N24 -> 1235 | M24: =IF(AND(#REF!<>0,#REF!<>"N.A."),#REF!,0) -> #REF! | N24: =IF(M24<>0,1,0) -> #REF! | O24: =IF(N24=1,M24,100000) -> #REF! | P24: =IF(N24=1,M24,0) -> #REF! | Q24: =IF(AND(#REF!<>"N.A.",#REF!<>"< 5"),#REF!,0) -> #REF! | R24: =IF(Q24<>0,1,0) -> #REF! | S24: =IF(R24=1,Q24,10000000) -> #REF! | T24: =IF(R24=1,S24,0) -> #REF! | U24: =M24 -> #REF! | V24: =Q24 -> #REF! | Z24: 该款产品属于生命周期比较长的，目前市面上的产品存在严重的质量问题，如果能够想办法解决这些质量问题，那么会达到很高的销量。
A25: =数据调研!L25 -> B018S3APEG | B25: =数据调研!C25 -> Mellow Shirt | C25: =数据调研!D25 -> 25.99 | D25: =数据调研!E25 -> Pet Supplies | E25: =数据调研!F25 -> 12670 | F25: =数据调研!G25 -> 180 | G25: =数据调研!H25 -> 4678.2 | H25: =数据调研!I25 -> 1611 | I25: =数据调研!J25 -> 3.5 | J25: =数据调研!K25 -> FBA | K25: =数据调研!M25 -> https://www.amazon.com/dp/B018S3APEG?psc=1 | L25: =数据调研!N25 -> 1235 | M25: =IF(AND(#REF!<>0,#REF!<>"N.A."),#REF!,0) -> #REF! | N25: =IF(M25<>0,1,0) -> #REF! | O25: =IF(N25=1,M25,100000) -> #REF! | P25: =IF(N25=1,M25,0) -> #REF! | Q25: =IF(AND(#REF!<>"N.A.",#REF!<>"< 5"),#REF!,0) -> #REF! | R25: =IF(Q25<>0,1,0) -> #REF! | S25: =IF(R25=1,Q25,10000000) -> #REF! | T25: =IF(R25=1,S25,0) -> #REF! | U25: =M25 -> #REF! | V25: =Q25 -> #REF!
A26: =数据调研!L26 -> B003WRG9O4 | B26: =数据调研!C26 -> Coastal Pet | C26: =数据调研!D26 -> 8.14 | D26: =数据调研!E26 -> Pet Supplies | E26: =数据调研!F26 -> 13278 | F26: =数据调研!G26 -> 180 | G26: =数据调研!H26 -> 1465.2 | H26: =数据调研!I26 -> 106 | I26: =数据调研!J26 -> 4.4 | J26: =数据调研!K26 -> FBA | K26: =数据调研!M26 -> https://www.amazon.com/dp/B003WRG9O4?psc=1 | L26: =数据调研!N26 -> 980 | M26: =IF(AND(#REF!<>0,#REF!<>"N.A."),#REF!,0) -> #REF! | N26: =IF(M26<>0,1,0) -> #REF! | O26: =IF(N26=1,M26,100000) -> #REF! | P26: =IF(N26=1,M26,0) -> #REF! | Q26: =IF(AND(#REF!<>"N.A.",#REF!<>"< 5"),#REF!,0) -> #REF! | R26: =IF(Q26<>0,1,0) -> #REF! | S26: =IF(R26=1,Q26,10000000) -> #REF! | T26: =IF(R26=1,S26,0) -> #REF! | U26: =M26 -> #REF! | V26: =Q26 -> #REF!
A27: =数据调研!L27 -> B07P74ZSXS | B27: =数据调研!C27 -> Rosestola | C27: =数据调研!D27 -> 8.99 | D27: =数据调研!E27 -> Pet Supplies | E27: =数据调研!F27 -> 130055 | F27: =数据调研!G27 -> 180 | G27: =数据调研!H27 -> 1618.2 | H27: =数据调研!I27 -> 5 | I27: =数据调研!J27 -> 5 | J27: =数据调研!K27 -> FBA | K27: =数据调研!M27 -> https://www.amazon.com/dp/B07P74ZSXS?psc=1 | L27: =数据调研!N27 -> 980 | M27: =IF(AND(#REF!<>0,#REF!<>"N.A."),#REF!,0) -> #REF! | N27: =IF(M27<>0,1,0) -> #REF! | O27: =IF(N27=1,M27,100000) -> #REF! | P27: =IF(N27=1,M27,0) -> #REF! | Q27: =IF(AND(#REF!<>"N.A.",#REF!<>"< 5"),#REF!,0) -> #REF! | R27: =IF(Q27<>0,1,0) -> #REF! | S27: =IF(R27=1,Q27,10000000) -> #REF! | T27: =IF(R27=1,S27,0) -> #REF! | U27: =M27 -> #REF! | V27: =Q27 -> #REF!
A28: =数据调研!L28 -> B01CY48OIO | B28: =数据调研!C28 -> EliteField | C28: =数据调研!D28 -> 29.99 | D28: =数据调研!E28 -> Pet Supplies | E28: =数据调研!F28 -> 12784 | F28: =数据调研!G28 -> 180 | G28: =数据调研!H28 -> 5398.2 | H28: =数据调研!I28 -> 534 | I28: =数据调研!J28 -> 4.3 | J28: =数据调研!K28 -> FBA | K28: =数据调研!M28 -> https://www.amazon.com/dp/B01CY48OIO?psc=1 | L28: =数据调研!N28 -> 1045 | M28: =IF(AND(#REF!<>0,#REF!<>"N.A."),#REF!,0) -> #REF! | N28: =IF(M28<>0,1,0) -> #REF! | O28: =IF(N28=1,M28,100000) -> #REF! | P28: =IF(N28=1,M28,0) -> #REF! | Q28: =IF(AND(#REF!<>"N.A.",#REF!<>"< 5"),#REF!,0) -> #REF! | R28: =IF(Q28<>0,1,0) -> #REF! | S28: =IF(R28=1,Q28,10000000) -> #REF! | T28: =IF(R28=1,S28,0) -> #REF! | U28: =M28 -> #REF! | V28: =Q28 -> #REF!
A29: =数据调研!L29 -> B07J4W6KW2 | B29: =数据调研!C29 -> Best Pet Supplies, Inc. | C29: =数据调研!D29 -> 13.99 | D29: =数据调研!E29 -> Pet Supplies | E29: =数据调研!F29 -> 16620 | F29: =数据调研!G29 -> 150 | G29: =数据调研!H29 -> 2098.5 | H29: =数据调研!I29 -> 1529 | I29: =数据调研!J29 -> 4.4 | J29: =数据调研!K29 -> AMZ | K29: =数据调研!M29 -> https://www.amazon.com/dp/B07J4W6KW2?psc=1 | L29: =数据调研!N29 -> 2186 | M29: =IF(AND(#REF!<>0,#REF!<>"N.A."),#REF!,0) -> #REF! | N29: =IF(M29<>0,1,0) -> #REF! | O29: =IF(N29=1,M29,100000) -> #REF! | P29: =IF(N29=1,M29,0) -> #REF! | Q29: =IF(AND(#REF!<>"N.A.",#REF!<>"< 5"),#REF!,0) -> #REF! | R29: =IF(Q29<>0,1,0) -> #REF! | S29: =IF(R29=1,Q29,10000000) -> #REF! | T29: =IF(R29=1,S29,0) -> #REF! | U29: =M29 -> #REF! | V29: =Q29 -> #REF!
A30: =数据调研!L30 -> B07LGS8M36 | B30: =数据调研!C30 -> Kamots Beauty | C30: =数据调研!D30 -> 11.48 | D30: =数据调研!E30 -> Pet Supplies | E30: =数据调研!F30 -> 17750 | F30: =数据调研!G30 -> 120 | G30: =数据调研!H30 -> 1377.6 | H30: =数据调研!I30 -> 41 | I30: =数据调研!J30 -> 3.9 | J30: =数据调研!K30 -> FBA | K30: =数据调研!M30 -> https://www.amazon.com/dp/B07LGS8M36?psc=1 | L30: =数据调研!N30 -> 159 | M30: =IF(AND(AB23<>0,AB23<>"N.A."),AB23,0) -> 0 | N30: =IF(M30<>0,1,0) -> 0 | O30: =IF(N30=1,M30,100000) -> 100000 | P30: =IF(N30=1,M30,0) -> 0 | Q30: =IF(AND(AC23<>"N.A.",AC23<>"< 5"),AC23,0) -> 0 | R30: =IF(Q30<>0,1,0) -> 0 | S30: =IF(R30=1,Q30,10000000) -> 10000000 | T30: =IF(R30=1,S30,0) -> 0 | U30: =M30 -> 0 | V30: =Q30 -> 0
A31: =数据调研!L31 -> B07PNFDG8P | B31: =数据调研!C31 -> BINGPET | C31: =数据调研!D31 -> 12.99 | D31: =数据调研!E31 -> Pet Supplies | E31: =数据调研!F31 -> 19836 | F31: =数据调研!G31 -> 120 | G31: =数据调研!H31 -> 1558.8 | H31: =数据调研!I31 -> 12 | I31: =数据调研!J31 -> 4.2 | J31: =数据调研!K31 -> FBA | K31: =数据调研!M31 -> https://www.amazon.com/dp/B07PNFDG8P?psc=1 | L31: =数据调研!N31 -> 150 | M31: =IF(AND(AB24<>0,AB24<>"N.A."),AB24,0) -> 0 | N31: =IF(M31<>0,1,0) -> 0 | O31: =IF(N31=1,M31,100000) -> 100000 | P31: =IF(N31=1,M31,0) -> 0 | Q31: =IF(AND(AC24<>"N.A.",AC24<>"< 5"),AC24,0) -> 0 | R31: =IF(Q31<>0,1,0) -> 0 | S31: =IF(R31=1,Q31,10000000) -> 10000000 | T31: =IF(R31=1,S31,0) -> 0 | U31: =M31 -> 0 | V31: =Q31 -> 0
A32: =数据调研!L32 -> B07LGS8M36 | B32: =数据调研!C32 -> Kamots Beauty | C32: =数据调研!D32 -> 11.48 | D32: =数据调研!E32 -> Pet Supplies | E32: =数据调研!F32 -> 17750 | F32: =数据调研!G32 -> 120 | G32: =数据调研!H32 -> 1377.6 | H32: =数据调研!I32 -> 41 | I32: =数据调研!J32 -> 3.9 | J32: =数据调研!K32 -> FBA | K32: =数据调研!M32 -> https://www.amazon.com/dp/B07LGS8M36?psc=1 | L32: =数据调研!N32 -> 159 | M32: =IF(AND(AB25<>0,AB25<>"N.A."),AB25,0) -> 0 | N32: =IF(M32<>0,1,0) -> 0 | O32: =IF(N32=1,M32,100000) -> 100000 | P32: =IF(N32=1,M32,0) -> 0 | Q32: =IF(AND(AC25<>"N.A.",AC25<>"< 5"),AC25,0) -> 0 | R32: =IF(Q32<>0,1,0) -> 0 | S32: =IF(R32=1,Q32,10000000) -> 10000000 | T32: =IF(R32=1,S32,0) -> 0 | U32: =M32 -> 0 | V32: =Q32 -> 0
A33: =数据调研!L33 -> B0753J3RBC | B33: =数据调研!C33 -> Rella Home | C33: =数据调研!D33 -> 7.99 | D33: =数据调研!E33 -> Pet Supplies | E33: =数据调研!F33 -> 18783 | F33: =数据调研!G33 -> 120 | G33: =数据调研!H33 -> 958.8 | H33: =数据调研!I33 -> 88 | I33: =数据调研!J33 -> 4.1 | J33: =数据调研!K33 -> FBA | K33: =数据调研!M33 -> https://www.amazon.com/dp/B0753J3RBC?psc=1 | L33: =数据调研!N33 -> 473 | M33: =IF(AND(AB26<>0,AB26<>"N.A."),AB26,0) -> 0 | N33: =IF(M33<>0,1,0) -> 0 | O33: =IF(N33=1,M33,100000) -> 100000 | P33: =IF(N33=1,M33,0) -> 0 | Q33: =IF(AND(AC26<>"N.A.",AC26<>"< 5"),AC26,0) -> 0 | R33: =IF(Q33<>0,1,0) -> 0 | S33: =IF(R33=1,Q33,10000000) -> 10000000 | T33: =IF(R33=1,S33,0) -> 0 | U33: =M33 -> 0 | V33: =Q33 -> 0
A34: =数据调研!L34 -> B07NXCHNW8 | B34: =数据调研!C34 -> PUPTECK | C34: =数据调研!D34 -> 11.99 | D34: =数据调研!E34 -> Pet Supplies | E34: =数据调研!F34 -> 17359 | F34: =数据调研!G34 -> 120 | G34: =数据调研!H34 -> 1438.8 | H34: =数据调研!I34 -> 4 | I34: =数据调研!J34 -> 3.5 | J34: =数据调研!K34 -> FBA | K34: =数据调研!M34 -> https://www.amazon.com/dp/B07NXCHNW8?psc=1 | L34: =数据调研!N34 -> 674 | M34: =IF(AND(AB27<>0,AB27<>"N.A."),AB27,0) -> 0 | N34: =IF(M34<>0,1,0) -> 0 | O34: =IF(N34=1,M34,100000) -> 100000 | P34: =IF(N34=1,M34,0) -> 0 | Q34: =IF(AND(AC27<>"N.A.",AC27<>"< 5"),AC27,0) -> 0 | R34: =IF(Q34<>0,1,0) -> 0 | S34: =IF(R34=1,Q34,10000000) -> 10000000 | T34: =IF(R34=1,S34,0) -> 0 | U34: =M34 -> 0 | V34: =Q34 -> 0
A35: =数据调研!L35 -> B07QYYDH4T | B35: =数据调研!C35 -> NEEDOON | C35: =数据调研!D35 -> 10.99 | D35: =数据调研!E35 -> Beauty & Personal Care | E35: =数据调研!F35 -> 133666 | F35: =数据调研!G35 -> 120 | G35: =数据调研!H35 -> 1318.8 | H35: =数据调研!I35 -> 3 | I35: =数据调研!J35 -> 4 | J35: =数据调研!K35 -> FBA | K35: =数据调研!M35 -> https://www.amazon.com/dp/B07QYYDH4T?psc=1 | L35: =数据调研!N35 -> 27 | M35: =IF(AND(AB28<>0,AB28<>"N.A."),AB28,0) -> 0 | N35: =IF(M35<>0,1,0) -> 0 | O35: =IF(N35=1,M35,100000) -> 100000 | P35: =IF(N35=1,M35,0) -> 0 | Q35: =IF(AND(AC28<>"N.A.",AC28<>"< 5"),AC28,0) -> 0 | R35: =IF(Q35<>0,1,0) -> 0 | S35: =IF(R35=1,Q35,10000000) -> 10000000 | T35: =IF(R35=1,S35,0) -> 0 | U35: =M35 -> 0 | V35: =Q35 -> 0
A36: =数据调研!L36 -> B07CMQLWF4 | B36: =数据调研!C36 -> Stock Show | C36: =数据调研!D36 -> 16.99 | D36: =数据调研!E36 -> Pet Supplies | E36: =数据调研!F36 -> 211183 | F36: =数据调研!G36 -> 120 | G36: =数据调研!H36 -> 2038.8 | H36: =数据调研!I36 -> 31 | I36: =数据调研!J36 -> 4.2 | J36: =数据调研!K36 -> FBA | K36: =数据调研!M36 -> https://www.amazon.com/dp/B07CMQLWF4?psc=1 | L36: =数据调研!N36 -> 346 | M36: =IF(AND(AB29<>0,AB29<>"N.A."),AB29,0) -> 0 | N36: =IF(M36<>0,1,0) -> 0 | O36: =IF(N36=1,M36,100000) -> 100000 | P36: =IF(N36=1,M36,0) -> 0 | Q36: =IF(AND(AC29<>"N.A.",AC29<>"< 5"),AC29,0) -> 0 | R36: =IF(Q36<>0,1,0) -> 0 | S36: =IF(R36=1,Q36,10000000) -> 10000000 | T36: =IF(R36=1,S36,0) -> 0 | U36: =M36 -> 0 | V36: =Q36 -> 0
A37: =数据调研!L37 -> B07LGS8M36 | B37: =数据调研!C37 -> Kamots Beauty | C37: =数据调研!D37 -> 11.48 | D37: =数据调研!E37 -> Pet Supplies | E37: =数据调研!F37 -> 17750 | F37: =数据调研!G37 -> 120 | G37: =数据调研!H37 -> 1377.6 | H37: =数据调研!I37 -> 41 | I37: =数据调研!J37 -> 3.9 | J37: =数据调研!K37 -> FBA | K37: =数据调研!M37 -> https://www.amazon.com/dp/B07LGS8M36?psc=1 | L37: =数据调研!N37 -> 159 | M37: =IF(AND(AB30<>0,AB30<>"N.A."),AB30,0) -> 0 | N37: =IF(M37<>0,1,0) -> 0 | O37: =IF(N37=1,M37,100000) -> 100000 | P37: =IF(N37=1,M37,0) -> 0 | Q37: =IF(AND(AC30<>"N.A.",AC30<>"< 5"),AC30,0) -> 0 | R37: =IF(Q37<>0,1,0) -> 0 | S37: =IF(R37=1,Q37,10000000) -> 10000000 | T37: =IF(R37=1,S37,0) -> 0 | U37: =M37 -> 0 | V37: =Q37 -> 0
A38: =数据调研!L38 -> B018DDFJTM | B38: =数据调研!C38 -> EcoBark | C38: =数据调研!D38 -> 14.99 | D38: =数据调研!E38 -> Pet Supplies | E38: =数据调研!F38 -> 17257 | F38: =数据调研!G38 -> 120 | G38: =数据调研!H38 -> 1798.8 | H38: =数据调研!I38 -> 3544 | I38: =数据调研!J38 -> 4.4 | J38: =数据调研!K38 -> FBA | K38: =数据调研!M38 -> https://www.amazon.com/dp/B018DDFJTM?psc=1 | L38: =数据调研!N38 -> 1329 | M38: =IF(AND(AC40<>0,AC40<>"N.A."),AC40,0) -> 0 | N38: =IF(M38<>0,1,0) -> 0 | O38: =IF(N38=1,M38,100000) -> 100000 | P38: =IF(N38=1,M38,0) -> 0 | Q38: =IF(AND(AD40<>"N.A.",AD40<>"< 5"),AD40,0) -> 0 | R38: =IF(Q38<>0,1,0) -> 0 | S38: =IF(R38=1,Q38,10000000) -> 10000000 | T38: =IF(R38=1,S38,0) -> 0 | U38: =M38 -> 0 | V38: =Q38 -> 0
A39: =数据调研!L39 -> B07KP86PG5 | B39: =数据调研!C39 -> Kamots Beauty | C39: =数据调研!D39 -> 11.48 | D39: =数据调研!E39 -> Pet Supplies | E39: =数据调研!F39 -> 17345 | F39: =数据调研!G39 -> 120 | G39: =数据调研!H39 -> 1377.6 | H39: =数据调研!I39 -> 41 | I39: =数据调研!J39 -> 3.9 | J39: =数据调研!K39 -> FBA | K39: =数据调研!M39 -> https://www.amazon.com/dp/B07KP86PG5?psc=1 | L39: =数据调研!N39 -> 164 | M39: =IF(AND(AC41<>0,AC41<>"N.A."),AC41,0) -> 0 | N39: =IF(M39<>0,1,0) -> 0 | O39: =IF(N39=1,M39,100000) -> 100000 | P39: =IF(N39=1,M39,0) -> 0 | Q39: =IF(AND(AD41<>"N.A.",AD41<>"< 5"),AD41,0) -> 0 | R39: =IF(Q39<>0,1,0) -> 0 | S39: =IF(R39=1,Q39,10000000) -> 10000000 | T39: =IF(R39=1,S39,0) -> 0 | U39: =M39 -> 0 | V39: =Q39 -> 0
A40: =数据调研!L40 -> B01M0RBJNA | B40: =数据调研!C40 -> PUPTECK | C40: =数据调研!D40 -> 12.99 | D40: =数据调研!E40 -> Pet Supplies | E40: =数据调研!F40 -> 18486 | F40: =数据调研!G40 -> 120 | G40: =数据调研!H40 -> 1558.8 | H40: =数据调研!I40 -> 1030 | I40: =数据调研!J40 -> 3.9 | J40: =数据调研!K40 -> FBA | K40: =数据调研!M40 -> https://www.amazon.com/dp/B01M0RBJNA?psc=1 | L40: =数据调研!N40 -> 1079 | M40: =IF(AND(AC42<>0,AC42<>"N.A."),AC42,0) -> 0 | N40: =IF(M40<>0,1,0) -> 0 | O40: =IF(N40=1,M40,100000) -> 100000 | P40: =IF(N40=1,M40,0) -> 0 | Q40: =IF(AND(AD42<>"N.A.",AD42<>"< 5"),AD42,0) -> 0 | R40: =IF(Q40<>0,1,0) -> 0 | S40: =IF(R40=1,Q40,10000000) -> 10000000 | T40: =IF(R40=1,S40,0) -> 0 | U40: =M40 -> 0 | V40: =Q40 -> 0
...

Sheet 市场容量分析
A1: Rank | B1: 0-99 | C1: 100-499 | D1: 500-999 | E1: 1000-1999 | F1: 2000-3999 | G1: 4000-5999 | H1: 6000-7999 | I1: 8000-10000 | J1: >10001 | K1: 销量 | L1: 0-300 | M1: 300-500 | N1: 500-800 | O1: 800-1000 | P1: 1000-1500 | Q1: 1500-2000 | R1: 2000-3000 | S1: 3000-4500 | T1: 4500-6000 | U1: 6000-8000 | V1: >8000 | W1: Rank | X1: review | Y1: Re<30 | Z1: Re<30且 0-99 | AA1: Re<30且 100-499 | AB1: Re<30且 500-999 | AC1: Re<30且 1000-1999 | AD1: Re<30且 2000-3999 | AE1: Re<30且 4000-5999 | AF1: Re<30且 6000-7999 | AG1: Re<30且8000-10000 | AH1: Re<30且 10000+ | AI1: 30<review<100 | AJ1: 30<review<100且 0-99 | AK1: 30<review<100且 100-499 | AL1: 30<review<100且 500-999 | AM1: 30<review<100且 1000-1999 | AN1: 30<review<100且 2000-3999 | AO1: 30<review<100且 4000-5999 | AP1: 30<review<100且 6000-7999 | AQ1: 30<review<100且8000-10000 | AR1: 30<review<100且 10000+ | AS1: 100<review<500 | AT1: 100<review<500且 0-99 | AU1: 100<review<500且 100-499 | AV1: 100<review<500且 500-999 | AW1: 100<review<500且 1000-1999 | AX1: 100<review<500且 2000-3999 | AY1: 100<review<500且 4000-5999 | AZ1: 100<review<500且 6000-7999 | BA1: 100<review<500且8000-10000 | BB1: 100<review<500且 10000+ | BC1: 500<review<1000 | BD1: 500<review<1000且 0-99 | BE1: 500<review<1000且 100-499 | BF1: 500<review<1000且 500-999 | BG1: 500<review<1000且 1000-1999 | BH1: 500<review<1000且 2000-3999 | BI1: 500<review<1000且 4000-5999 | BJ1: 500<review<1000且 6000-7999 | BK1: 500<review<1000且8000-10000 | BL1: 500<review<1000且 10000+ | BM1: review>1000 | BN1: 500<review<1000且 0-99 | BO1: 500<review<1000且 100-499 | BP1: 500<review<1000且 500-999 | BQ1: 500<review<1000且 1000-1999 | BR1: 500<review<1000且 2000-3999 | BS1: 500<review<1000且 4000-5999 | BT1: 500<review<1000且 6000-7999 | BU1: 500<review<1000且8000-10000 | BV1: 500<review<1000且 10000+ | BW1: Seller | BX1: AMZ | BY1: AMZ且0-99 | BZ1: AMZ且100-499 | CA1: AMZ且500-999 | CB1: AMZ且1000-1999 | CC1: AMZ且2000-3999 | CD1: AMZ且4000-5999 | CE1: AMZ且6000-7999 | CF1: AMZ且8000-10000 | CG1: AMZ且>10000 | CH1: FBA | CI1: FBA且0-99 | CJ1: FBA且100-499 | CK1: FBA且500-999 | CL1: FBA且1000-1999 | CM1: FBA且2000-3999 | CN1: FBA且4000-5999 | CO1: FBA且6000-7999 | CP1: FBA且8000-10000 | CQ1: FBA且>10000 | CR1: 上架天数 | CS1: 天数<31 | CT1: 天数<31且0-99 | CU1: 天数<31且100-499 | CV1: 天数<31且500-999 | CW1: 天数<31且1000-1999 | CX1: 天数<31且2000-3999 | CY1: 天数<31且4000-5999 | CZ1: 天数<31且6000-7999 | DA1: 天数<31且8000-10000 | DB1: 天数<31且>10001 | DC1: 30<天数<61 | DD1: 30<天数<61且0-99 | DE1: 30<天数<61100-499 | DF1: 30<天数<61且500-999 | DG1: 30<天数<61且1000-1999 | DH1: 30<天数<61且2000-3999 | DI1: 30<天数<61且4000-5999 | DJ1: 30<天数<61且6000-7999 | DK1: 30<天数<61且8000-10000 | DL1: 30<天数<61且>10001 | DM1: 60<天数<91 | DN1: 60<天数<91且0-99 | DO1: 60<天数<91且100-499 | DP1: 60<天数<91且500-999 | DQ1: 60<天数<91且1000-1999 | DR1: 60<天数<91且2000-3999 | DS1: 60<天数<91且4000-5999 | DT1: 60<天数<91且6000-7999 | DU1: 60<天数<91且8000-10000 | DV1: 60<天数<91且>10001 | DW1: 90<天数<181 | DX1: 90<天数<181且0-99 | DY1: 90<天数<181且100-499 | DZ1: 90<天数<181且500-999 | EA1: 90<天数<181且1000-1999 | EB1: 90<天数<181且2000-3999 | EC1: 90<天数<181且4000-5999 | ED1: 90<天数<181且6000-7999 | EE1: 90<天数<181且8000-10000 | EF1: 90<天数<181且>10001 | EG1: 半年以上 | EH1: 半年以上且0-99 | EI1: 半年以上且100-499 | EJ1: 半年以上且500-999 | EK1: 半年以上且1000-1999 | EL1: 半年以上且2000-3999 | EM1: 半年以上且4000-5999 | EN1: 半年以上且6000-7999 | EO1: 半年以上且8000-10000 | EP1: 半年以上且>10001 | EQ1: 市场容量分析
A2: =数据调研!F2 -> 764 | B2: =IF(AND(A2>0,A2<100),1,0) -> 0 | C2: =IF(AND(A2>99,A2<500),1,0) -> 0 | D2: =IF(AND(A2>499,A2<1000),1,0) -> 1 | E2: =IF(AND(A2>999,A2<2000),1,0) -> 0 | F2: =IF(AND(A2>1999,A2<4000),1,0) -> 0 | G2: =IF(AND(A2>3999,A2<6000),1,0) -> 0 | H2: =IF(AND(A2>5999,A2<8000),1,0) -> 0 | I2: =IF(AND(A2>7999,A2<10001),1,0) -> 0 | J2: =IF(A2>10001,1,0) -> 0 | K2: =价格参考!K2 -> 2550 | L2: =IF(AND(K2>0,K2<301),1,0) -> 0 | M2: =IF(AND(K2>300,K2<501),1,0) -> 0 | N2: =IF(AND(K2>500,K2<801),1,0) -> 0 | O2: =IF(AND(K2>800,K2<1001),1,0) -> 0 | P2: =IF(AND(K2>1000,K2<1501),1,0) -> 0 | Q2: =IF(AND(K2>1500,K2<2001),1,0) -> 0 | R2: =IF(AND(K2>2000,K2<3001),1,0) -> 1 | S2: =IF(AND(K2>3000,K2<4501),1,0) -> 0 | T2: =IF(AND(K2>4500,K2<6001),1,0) -> 0 | U2: =IF(AND(K2>6000,K2<8001),1,0) -> 0 | V2: =IF(AND(K2>8000,K2<>"N.A.",K2<>"< 5"),1,0) -> 0 | W2: =IF(A2<>"N.A.",A2,1000000) -> 764 | X2: =数据调研!I2 -> 79 | Y2: =IF(X2<31,1,0) -> 0 | Z2: =IF(AND(Y2=1,B2=1),1,0) -> 0 | AA2: =IF(AND(Y2=1,C2=1),1,0) -> 0 | AB2: =IF(AND(Y2=1,D2=1),1,0) -> 0 | AC2: =IF(AND(Y2=1,E2=1),1,0) -> 0 | AD2: =IF(AND(Y2=1,F2=1),1,0) -> 0 | AE2: =IF(AND(Y2=1,G2=1),1,0) -> 0 | AF2: =IF(AND(Y2=1,H2=1),1,0) -> 0 | AG2: =IF(AND(Y2=1,I2=1),1,0) -> 0 | AH2: =IF(AND(Y2=1,J2=1),1,0) -> 0 | AI2: =IF(AND(X2>30,X2<101),1,0) -> 1 | AJ2: =IF(AND(AI2=1,B2=1),1,0) -> 0 | AK2: =IF(AND(AI2=1,C2=1),1,0) -> 0 | AL2: =IF(AND(AI2=1,D2=1),1,0) -> 1 | AM2: =IF(AND(AI2=1,E2=1),1,0) -> 0 | AN2: =IF(AND(AI2=1,F2=1),1,0) -> 0 | AO2: =IF(AND(AI2=1,G2=1),1,0) -> 0 | AP2: =IF(AND(AI2=1,H2=1),1,0) -> 0 | AQ2: =IF(AND(AI2=1,I2=1),1,0) -> 0 | AR2: =IF(AND(AI2=1,J2=1),1,0) -> 0 | AS2: =IF(AND(X2>100,X2<501),1,0) -> 0 | AT2: =IF(AND(B2=1,AS2=1),1,0) -> 0 | AU2: =IF(AND(C2=1,AS2=1),1,0) -> 0 | AV2: =IF(AND(D2=1,AS2=1),1,0) -> 0 | AW2: =IF(AND(E2=1,AS2=1),1,0) -> 0 | AX2: =IF(AND(F2=1,AS2=1),1,0) -> 0 | AY2: =IF(AND(G2=1,AS2=1),1,0) -> 0 | AZ2: =IF(AND(H2=1,AS2=1),1,0) -> 0 | BA2: =IF(AND(I2=1,AS2=1),1,0) -> 0 | BB2: =IF(AND(J2=1,AS2=1),1,0) -> 0 | BC2: =IF(AND(X2>500,X2<1001),1,0) -> 0 | BD2: =IF(AND(BC2=1,B2=1),1,0) -> 0 | BE2: =IF(AND(BC2=1,C2=1),1,0) -> 0 | BF2: =IF(AND(BC2=1,D2=1),1,0) -> 0 | BG2: =IF(AND(BC2=1,E2=1),1,0) -> 0 | BH2: =IF(AND(BC2=1,F2=1),1,0) -> 0 | BI2: =IF(AND(BC2=1,G2=1),1,0) -> 0 | BJ2: =IF(AND(BC2=1,H2=1),1,0) -> 0 | BK2: =IF(AND(BC2=1,I2=1),1,0) -> 0 | BL2: =IF(AND(BC2=1,J2=1),1,0) -> 0 | BM2: =IF(X2>1001,1,0) -> 0 | BN2: =IF(AND(B2=1,BM2=1),1,0) -> 0 | BO2: =IF(AND(C2=1,BM2=1),1,0) -> 0 | BP2: =IF(AND(D2=1,BM2=1),1,0) -> 0 | BQ2: =IF(AND(E2=1,BM2=1),1,0) -> 0 | BR2: =IF(AND(F2=1,BM2=1),1,0) -> 0 | BS2: =IF(AND(G2=1,BM2=1),1,0) -> 0 | BT2: =IF(AND(H2=1,BM2=1),1,0) -> 0 | BU2: =IF(AND(I2=1,BM2=1),1,0) -> 0 | BV2: =IF(AND(J2=1,BM2=1),1,0) -> 0 | BW2: =数据调研!K2 -> FBA | BX2: =IF(BW2="AMZ",1,0) -> 0 | BY2: =IF(AND(BX2=1,B2=1),1,0) -> 0 | BZ2: =IF(AND(BX2=1,C2=1),1,0) -> 0 | CA2: =IF(AND(BX2=1,D2=1),1,0) -> 0 | CB2: =IF(AND(BX2=1,E2=1),1,0) -> 0 | CC2: =IF(AND(BX2=1,F2=1),1,0) -> 0 | CD2: =IF(AND(BX2=1,G2=1),1,0) -> 0 | CE2: =IF(AND(BX2=1,H2=1),1,0) -> 0 | CF2: =IF(AND(BX2=1,I2=1),1,0) -> 0 | CG2: =IF(AND(BX2=1,J2=1),1,0) -> 0 | CH2: =IF(BW2="FBA",1,0) -> 1 | CI2: =IF(AND(CH2=1,B2=1),1,0) -> 0 | CJ2: =IF(AND(CH2=1,C2=1),1,0) -> 0 | CK2: =IF(AND(CH2=1,D2=1),1,0) -> 1 | CL2: =IF(AND(CH2=1,E2=1),1,0) -> 0 | CM2: =IF(AND(CH2=1,F2=1),1,0) -> 0 | CN2: =IF(AND(CH2=1,G2=1),1,0) -> 0 | CO2: =IF(AND(CH2=1,H2=1),1,0) -> 0 | CP2: =IF(AND(CH2=1,I2=1),1,0) -> 0 | CQ2: =IF(AND(CH2=1,J2=1),1,0) -> 0 | CR2: =数据调研!N2 -> 387 | CS2: =IF(AND(CR2<31,CR2<>0),1,0) -> 0 | CT2: =IF(AND(CS2=1,B2=1),1,0) -> 0 | CU2: =IF(AND(CS2=1,C2=1),1,0) -> 0 | CV2: =IF(AND(CS2=1,D2=1),1,0) -> 0 | CW2: =IF(AND(CS2=1,E2=1),1,0) -> 0 | CX2: =IF(AND(CS2=1,F2=1),1,0) -> 0 | CY2: =IF(AND(CS2=1,G2=1),1,0) -> 0 | CZ2: =IF(AND(CS2=1,H2=1),1,0) -> 0 | DA2: =IF(AND(CS2=1,I2=1),1,0) -> 0 | DB2: =IF(AND(CS2=1,J2=1),1,0) -> 0 | DC2: =IF(AND(CR2>30,CR2<61),1,0) -> 0 | DD2: =IF(AND(DC2=1,B2=1),1,0) -> 0 | DE2: =IF(AND(DC2=1,C2=1),1,0) -> 0 | DF2: =IF(AND(DC2=1,D2=1),1,0) -> 0 | DG2: =IF(AND(DC2=1,E2=1),1,0) -> 0 | DH2: =IF(AND(DC2=1,F2=1),1,0) -> 0 | DI2: =IF(AND(DC2=1,G2=1),1,0) -> 0 | DJ2: =IF(AND(DC2=1,H2=1),1,0) -> 0 | DK2: =IF(AND(DC2=1,I2=1),1,0) -> 0 | DL2: =IF(AND(DC2=1,J2=1),1,0) -> 0 | DM2: =IF(AND(CR2>60,CR2<91),1,0) -> 0 | DN2: =IF(AND(DM2=1,B2=1),1,0) -> 0 | DO2: =IF(AND(DM2=1,C2=1),1,0) -> 0 | DP2: =IF(AND(DM2=1,D2=1),1,0) -> 0 | DQ2: =IF(AND(DM2=1,E2=1),1,0) -> 0 | DR2: =IF(AND(DM2=1,F2=1),1,0) -> 0 | DS2: =IF(AND(DM2=1,G2=1),1,0) -> 0 | DT2: =IF(AND(DM2=1,H2=1),1,0) -> 0 | DU2: =IF(AND(DM2=1,I2=1),1,0) -> 0 | DV2: =IF(AND(DM2=1,J2=1),1,0) -> 0 | DW2: =IF(AND(CR2>90,CR2<181),1,0) -> 0 | DX2: =IF(AND(DW2=1,B2=1),1,0) -> 0 | DY2: =IF(AND(DW2=1,C2=1),1,0) -> 0 | DZ2: =IF(AND(DW2=1,D2=1),1,0) -> 0 | EA2: =IF(AND(DW2=1,E2=1),1,0) -> 0 | EB2: =IF(AND(DW2=1,F2=1),1,0) -> 0 | EC2: =IF(AND(DW2=1,G2=1),1,0) -> 0 | ED2: =IF(AND(DW2=1,H2=1),1,0) -> 0 | EE2: =IF(AND(DW2=1,I2=1),1,0) -> 0 | EF2: =IF(AND(DW2=1,J2=1),1,0) -> 0 | EG2: =IF(CR2>180,1,0) -> 1 | EH2: =IF(AND(EG2=1,B2=1),1,0) -> 0 | EI2: =IF(AND(EG2=1,C2=1),1,0) -> 0 | EJ2: =IF(AND(EG2=1,D2=1),1,0) -> 1 | EK2: =IF(AND(EG2=1,E2=1),1,0) -> 0 | EL2: =IF(AND(EG2=1,F2=1),1,0) -> 0 | EM2: =IF(AND(EG2=1,G2=1),1,0) -> 0 | EN2: =IF(AND(EG2=1,H2=1),1,0) -> 0 | EO2: =IF(AND(EG2=1,I2=1),1,0) -> 0 | EP2: =IF(AND(EG2=1,J2=1),1,0) -> 0
