Workbook

Sheet 搜索词报告

Sheet 总体数据一览
A1: 日期 | B1: 曝光量 | C1: 点击数 | D1: 点击率 | E1: 平均点击花费 | F1: 总花费 | G1: 销售额 | H1: ACOS
A2: 43770 | B2: =IF(SUMIF(搜索词报告!$A$2:$A$22222,总体数据一览!A2,搜索词报告!$I$2:$I$22222)=0,"",SUMIF(搜索词报告!$A$2:$A$22222,总体数据一览!A2,搜索词报告!$I$2:$I$22222)) | C2: =IF(SUMIF(搜索词报告!$A$2:$A$22222,总体数据一览!A2,搜索词报告!$J$2:$J$22222)=0,"",SUMIF(搜索词报告!$A$2:$A$22222,总体数据一览!A2,搜索词报告!$J$2:$J$22222)) | D2: =IFERROR(ROUND(C2/B2,4),"") | E2: =IFERROR(ROUND(F2/C2,2),"") | F2: =IF(SUMIF(搜索词报告!$A$2:$A$22222,总体数据一览!A2,搜索词报告!$M$2:$M$22222)=0,"",SUMIF(搜索词报告!$A$2:$A$22222,总体数据一览!A2,搜索词报告!$M$2:$M$22222)) | G2: =IFERROR(IF(B2="","",SUMIF(搜索词报告!$A$2:$A$22222,总体数据一览!A2,搜索词报告!$V$2:$V$22222))+IF(B2="","",SUMIF(搜索词报告!$A$2:$A$22222,总体数据一览!A2,搜索词报告!$W$2:$W$22222)),"") | H2: =IFERROR(ROUND(F2/G2,2),"")
A3: 43771 | B3: =IF(SUMIF(搜索词报告!$A$2:$A$22222,总体数据一览!A3,搜索词报告!$I$2:$I$22222)=0,"",SUMIF(搜索词报告!$A$2:$A$22222,总体数据一览!A3,搜索词报告!$I$2:$I$22222)) | C3: =IF(SUMIF(搜索词报告!$A$2:$A$22222,总体数据一览!A3,搜索词报告!$J$2:$J$22222)=0,"",SUMIF(搜索词报告!$A$2:$A$22222,总体数据一览!A3,搜索词报告!$J$2:$J$22222)) | D3: =IFERROR(ROUND(C3/B3,4),"") | E3: =IFERROR(ROUND(F3/C3,2),"") | F3: =IF(SUMIF(搜索词报告!$A$2:$A$22222,总体数据一览!A3,搜索词报告!$M$2:$M$22222)=0,"",SUMIF(搜索词报告!$A$2:$A$22222,总体数据一览!A3,搜索词报告!$M$2:$M$22222)) | G3: =IFERROR(IF(B3="","",SUMIF(搜索词报告!$A$2:$A$22222,总体数据一览!A3,搜索词报告!$V$2:$V$22222))+IF(B3="","",SUMIF(搜索词报告!$A$2:$A$22222,总体数据一览!A3,搜索词报告!$W$2:$W$22222)),"") | H3: =IFERROR(ROUND(F3/G3,2),"")
A4: 43772 | B4: =IF(SUMIF(搜索词报告!$A$2:$A$22222,总体数据一览!A4,搜索词报告!$I$2:$I$22222)=0,"",SUMIF(搜索词报告!$A$2:$A$22222,总体数据一览!A4,搜索词报告!$I$2:$I$22222)) | C4: =IF(SUMIF(搜索词报告!$A$2:$A$22222,总体数据一览!A4,搜索词报告!$J$2:$J$22222)=0,"",SUMIF(搜索词报告!$A$2:$A$22222,总体数据一览!A4,搜索词报告!$J$2:$J$22222)) | D4: =IFERROR(ROUND(C4/B4,4),"") | E4: =IFERROR(ROUND(F4/C4,2),"") | F4: =IF(SUMIF(搜索词报告!$A$2:$A$22222,总体数据一览!A4,搜索词报告!$M$2:$M$22222)=0,"",SUMIF(搜索词报告!$A$2:$A$22222,总体数据一览!A4,搜索词报告!$M$2:$M$22222)) | G4: =IFERROR(IF(B4="","",SUMIF(搜索词报告!$A$2:$A$22222,总体数据一览!A4,搜索词报告!$V$2:$V$22222))+IF(B4="","",SUMIF(搜索词报告!$A$2:$A$22222,总体数据一览!A4,搜索词报告!$W$2:$W$22222)),"") | H4: =IFERROR(ROUND(F4/G4,2),"")
A5: 43773 | B5: =IF(SUMIF(搜索词报告!$A$2:$A$22222,总体数据一览!A5,搜索词报告!$I$2:$I$22222)=0,"",SUMIF(搜索词报告!$A$2:$A$22222,总体数据一览!A5,搜索词报告!$I$2:$I$22222)) | C5: =IF(SUMIF(搜索词报告!$A$2:$A$22222,总体数据一览!A5,搜索词报告!$J$2:$J$22222)=0,"",SUMIF(搜索词报告!$A$2:$A$22222,总体数据一览!A5,搜索词报告!$J$2:$J$22222)) | D5: =IFERROR(ROUND(C5/B5,4),"") | E5: =IFERROR(ROUND(F5/C5,2),"") | F5: =IF(SUMIF(搜索词报告!$A$2:$A$22222,总体数据一览!A5,搜索词报告!$M$2:$M$22222)=0,"",SUMIF(搜索词报告!$A$2:$A$22222,总体数据一览!A5,搜索词报告!$M$2:$M$22222)) | G5: =IFERROR(IF(B5="","",SUMIF(搜索词报告!$A$2:$A$22222,总体数据一览!A5,搜索词报告!$V$2:$V$22222))+IF(B5="","",SUMIF(搜索词报告!$A$2:$A$22222,总体数据一览!A5,搜索词报告!$W$2:$W$22222)),"") | H5: =IFERROR(ROUND(F5/G5,2),"")
A6: 43774 | B6: =IF(SUMIF(搜索词报告!$A$2:$A$22222,总体数据一览!A6,搜索词报告!$I$2:$I$22222)=0,"",SUMIF(搜索词报告!$A$2:$A$22222,总体数据一览!A6,搜索词报告!$I$2:$I$22222)) | C6: =IF(SUMIF(搜索词报告!$A$2:$A$22222,总体数据一览!A6,搜索词报告!$J$2:$J$22222)=0,"",SUMIF(搜索词报告!$A$2:$A$22222,总体数据一览!A6,搜索词报告!$J$2:$J$22222)) | D6: =IFERROR(ROUND(C6/B6,4),"") | E6: =IFERROR(ROUND(F6/C6,2),"") | F6: =IF(SUMIF(搜索词报告!$A$2:$A$22222,总体数据一览!A6,搜索词报告!$M$2:$M$22222)=0,"",SUMIF(搜索词报告!$A$2:$A$22222,总体数据一览!A6,搜索词报告!$M$2:$M$22222)) | G6: =IFERROR(IF(B6="","",SUMIF(搜索词报告!$A$2:$A$22222,总体数据一览!A6,搜索词报告!$V$2:$V$22222))+IF(B6="","",SUMIF(搜索词报告!$A$2:$A$22222,总体数据一览!A6,搜索词报告!$W$2:$W$22222)),"") | H6: =IFERROR(ROUND(F6/G6,2),"")
A7: 43775 | B7: =IF(SUMIF(搜索词报告!$A$2:$A$22222,总体数据一览!A7,搜索词报告!$I$2:$I$22222)=0,"",SUMIF(搜索词报告!$A$2:$A$22222,总体数据一览!A7,搜索词报告!$I$2:$I$22222)) | C7: =IF(SUMIF(搜索词报告!$A$2:$A$22222,总体数据一览!A7,搜索词报告!$J$2:$J$22222)=0,"",SUMIF(搜索词报告!$A$2:$A$22222,总体数据一览!A7,搜索词报告!$J$2:$J$22222)) | D7: =IFERROR(ROUND(C7/B7,4),"") | E7: =IFERROR(ROUND(F7/C7,2),"") | F7: =IF(SUMIF(搜索词报告!$A$2:$A$22222,总体数据一览!A7,搜索词报告!$M$2:$M$22222)=0,"",SUMIF(搜索词报告!$A$2:$A$22222,总体数据一览!A7,搜索词报告!$M$2:$M$22222)) | G7: =IFERROR(IF(B7="","",SUMIF(搜索词报告!$A$2:$A$22222,总体数据一览!A7,搜索词报告!$V$2:$V$22222))+IF(B7="","",SUMIF(搜索词报告!$A$2:$A$22222,总体数据一览!A7,搜索词报告!$W$2:$W$22222)),"") | H7: =IFERROR(ROUND(F7/G7,2),"")
A8: 43776 | B8: =IF(SUMIF(搜索词报告!$A$2:$A$22222,总体数据一览!A8,搜索词报告!$I$2:$I$22222)=0,"",SUMIF(搜索词报告!$A$2:$A$22222,总体数据一览!A8,搜索词报告!$I$2:$I$22222)) | C8: =IF(SUMIF(搜索词报告!$A$2:$A$22222,总体数据一览!A8,搜索词报告!$J$2:$J$22222)=0,"",SUMIF(搜索词报告!$A$2:$A$22222,总体数据一览!A8,搜索词报告!$J$2:$J$22222)) | D8: =IFERROR(ROUND(C8/B8,4),"") | E8: =IFERROR(ROUND(F8/C8,2),"") | F8: =IF(SUMIF(搜索词报告!$A$2:$A$22222,总体数据一览!A8,搜索词报告!$M$2:$M$22222)=0,"",SUMIF(搜索词报告!$A$2:$A$22222,总体数据一览!A8,搜索词报告!$M$2:$M$22222)) | G8: =IFERROR(IF(B8="","",SUMIF(搜索词报告!$A$2:$A$22222,总体数据一览!A8,搜索词报告!$V$2:$V$22222))+IF(B8="","",SUMIF(搜索词报告!$A$2:$A$22222,总体数据一览!A8,搜索词报告!$W$2:$W$22222)),"") | H8: =IFERROR(ROUND(F8/G8,2),"")
A9: 43777 | B9: =IF(SUMIF(搜索词报告!$A$2:$A$22222,总体数据一览!A9,搜索词报告!$I$2:$I$22222)=0,"",SUMIF(搜索词报告!$A$2:$A$22222,总体数据一览!A9,搜索词报告!$I$2:$I$22222)) | C9: =IF(SUMIF(搜索词报告!$A$2:$A$22222,总体数据一览!A9,搜索词报告!$J$2:$J$22222)=0,"",SUMIF(搜索词报告!$A$2:$A$22222,总体数据一览!A9,搜索词报告!$J$2:$J$22222)) | D9: =IFERROR(ROUND(C9/B9,4),"") | E9: =IFERROR(ROUND(F9/C9,2),"") | F9: =IF(SUMIF(搜索词报告!$A$2:$A$22222,总体数据一览!A9,搜索词报告!$M$2:$M$22222)=0,"",SUMIF(搜索词报告!$A$2:$A$22222,总体数据一览!A9,搜索词报告!$M$2:$M$22222)) | G9: =IFERROR(IF(B9="","",SUMIF(搜索词报告!$A$2:$A$22222,总体数据一览!A9,搜索词报告!$V$2:$V$22222))+IF(B9="","",SUMIF(搜索词报告!$A$2:$A$22222,总体数据一览!A9,搜索词报告!$W$2:$W$22222)),"") | H9: =IFERROR(ROUND(F9/G9,2),"")
A10: 43778 | B10: =IF(SUMIF(搜索词报告!$A$2:$A$22222,总体数据一览!A10,搜索词报告!$I$2:$I$22222)=0,"",SUMIF(搜索词报告!$A$2:$A$22222,总体数据一览!A10,搜索词报告!$I$2:$I$22222)) | C10: =IF(SUMIF(搜索词报告!$A$2:$A$22222,总体数据一览!A10,搜索词报告!$J$2:$J$22222)=0,"",SUMIF(搜索词报告!$A$2:$A$22222,总体数据一览!A10,搜索词报告!$J$2:$J$22222)) | D10: =IFERROR(ROUND(C10/B10,4),"") | E10: =IFERROR(ROUND(F10/C10,2),"") | F10: =IF(SUMIF(搜索词报告!$A$2:$A$22222,总体数据一览!A10,搜索词报告!$M$2:$M$22222)=0,"",SUMIF(搜索词报告!$A$2:$A$22222,总体数据一览!A10,搜索词报告!$M$2:$M$22222)) | G10: =IFERROR(IF(B10="","",SUMIF(搜索词报告!$A$2:$A$22222,总体数据一览!A10,搜索词报告!$V$2:$V$22222))+IF(B10="","",SUMIF(搜索词报告!$A$2:$A$22222,总体数据一览!A10,搜索词报告!$W$2:$W$22222)),"") | H10: =IFERROR(ROUND(F10/G10,2),"")
A11: 43779 | B11: =IF(SUMIF(搜索词报告!$A$2:$A$22222,总体数据一览!A11,搜索词报告!$I$2:$I$22222)=0,"",SUMIF(搜索词报告!$A$2:$A$22222,总体数据一览!A11,搜索词报告!$I$2:$I$22222)) | C11: =IF(SUMIF(搜索词报告!$A$2:$A$22222,总体数据一览!A11,搜索词报告!$J$2:$J$22222)=0,"",SUMIF(搜索词报告!$A$2:$A$22222,总体数据一览!A11,搜索词报告!$J$2:$J$22222)) | D11: =IFERROR(ROUND(C11/B11,4),"") | E11: =IFERROR(ROUND(F11/C11,2),"") | F11: =IF(SUMIF(搜索词报告!$A$2:$A$22222,总体数据一览!A11,搜索词报告!$M$2:$M$22222)=0,"",SUMIF(搜索词报告!$A$2:$A$22222,总体数据一览!A11,搜索词报告!$M$2:$M$22222)) | G11: =IFERROR(IF(B11="","",SUMIF(搜索词报告!$A$2:$A$22222,总体数据一览!A11,搜索词报告!$V$2:$V$22222))+IF(B11="","",SUMIF(搜索词报告!$A$2:$A$22222,总体数据一览!A11,搜索词报告!$W$2:$W$22222)),"") | H11: =IFERROR(ROUND(F11/G11,2),"")
A12: 43780 | B12: =IF(SUMIF(搜索词报告!$A$2:$A$22222,总体数据一览!A12,搜索词报告!$I$2:$I$22222)=0,"",SUMIF(搜索词报告!$A$2:$A$22222,总体数据一览!A12,搜索词报告!$I$2:$I$22222)) | C12: =IF(SUMIF(搜索词报告!$A$2:$A$22222,总体数据一览!A12,搜索词报告!$J$2:$J$22222)=0,"",SUMIF(搜索词报告!$A$2:$A$22222,总体数据一览!A12,搜索词报告!$J$2:$J$22222)) | D12: =IFERROR(ROUND(C12/B12,4),"") | E12: =IFERROR(ROUND(F12/C12,2),"") | F12: =IF(SUMIF(搜索词报告!$A$2:$A$22222,总体数据一览!A12,搜索词报告!$M$2:$M$22222)=0,"",SUMIF(搜索词报告!$A$2:$A$22222,总体数据一览!A12,搜索词报告!$M$2:$M$22222)) | G12: =IFERROR(IF(B12="","",SUMIF(搜索词报告!$A$2:$A$22222,总体数据一览!A12,搜索词报告!$V$2:$V$22222))+IF(B12="","",SUMIF(搜索词报告!$A$2:$A$22222,总体数据一览!A12,搜索词报告!$W$2:$W$22222)),"") | H12: =IFERROR(ROUND(F12/G12,2),"")
A13: 43781 | B13: =IF(SUMIF(搜索词报告!$A$2:$A$22222,总体数据一览!A13,搜索词报告!$I$2:$I$22222)=0,"",SUMIF(搜索词报告!$A$2:$A$22222,总体数据一览!A13,搜索词报告!$I$2:$I$22222)) | C13: =IF(SUMIF(搜索词报告!$A$2:$A$22222,总体数据一览!A13,搜索词报告!$J$2:$J$22222)=0,"",SUMIF(搜索词报告!$A$2:$A$22222,总体数据一览!A13,搜索词报告!$J$2:$J$22222)) | D13: =IFERROR(ROUND(C13/B13,4),"") | E13: =IFERROR(ROUND(F13/C13,2),"") | F13: =IF(SUMIF(搜索词报告!$A$2:$A$22222,总体数据一览!A13,搜索词报告!$M$2:$M$22222)=0,"",SUMIF(搜索词报告!$A$2:$A$22222,总体数据一览!A13,搜索词报告!$M$2:$M$22222)) | G13: =IFERROR(IF(B13="","",SUMIF(搜索词报告!$A$2:$A$22222,总体数据一览!A13,搜索词报告!$V$2:$V$22222))+IF(B13="","",SUMIF(搜索词报告!$A$2:$A$22222,总体数据一览!A13,搜索词报告!$W$2:$W$22222)),"") | H13: =IFERROR(ROUND(F13/G13,2),"")
... A34: 43802 | B34: =IF(SUMIF(搜索词报告!$A$2:$A$22222,总体数据一览!A34,搜索词报告!$I$2:$I$22222)=0,"",SUMIF(搜索词报告!$A$2:$A$22222,总体数据一览!A34,搜索词报告!$I$2:$I$22222)) | C34: =IF(SUMIF(搜索词报告!$A$2:$A$22222,总体数据一览!A34,搜索词报告!$J$2:$J$22222)=0,"",SUMIF(搜索词报告!$A$2:$A$22222,总体数据一览!A34,搜索词报告!$J$2:$J$22222)) | D34: =IFERROR(ROUND(C34/B34,4),"") | E34: =IFERROR(ROUND(F34/C34,2),"") | F34: =IF(SUMIF(搜索词报告!$A$2:$A$22222,总体数据一览!A34,搜索词报告!$M$2:$M$22222)=0,"",SUMIF(搜索词报告!$A$2:$A$22222,总体数据一览!A34,搜索词报告!$M$2:$M$22222)) | G34: =IFERROR(IF(B34="","",SUMIF(搜索词报告!$A$2:$A$22222,总体数据一览!A34,搜索词报告!$V$2:$V$22222))+IF(B34="","",SUMIF(搜索词报告!$A$2:$A$22222,总体数据一览!A34,搜索词报告!$W$2:$W$22222)),"") | H34: =IFERROR(ROUND(F34/G34,2),"")
B35: =IF(SUMIF(搜索词报告!$A$2:$A$22222,总体数据一览!A35,搜索词报告!$I$2:$I$22222)=0,"",SUMIF(搜索词报告!$A$2:$A$22222,总体数据一览!A35,搜索词报告!$I$2:$I$22222)) | C35: =IF(SUMIF(搜索词报告!$A$2:$A$22222,总体数据一览!A35,搜索词报告!$J$2:$J$22222)=0,"",SUMIF(搜索词报告!$A$2:$A$22222,总体数据一览!A35,搜索词报告!$J$2:$J$22222)) | D35: =IFERROR(ROUND(C35/B35,4),"") | E35: =IFERROR(ROUND(F35/C35,2),"") | F35: =IF(SUMIF(搜索词报告!$A$2:$A$22222,总体数据一览!A35,搜索词报告!$M$2:$M$22222)=0,"",SUMIF(搜索词报告!$A$2:$A$22222,总体数据一览!A35,搜索词报告!$M$2:$M$22222)) | G35: =IFERROR(IF(B35="","",SUMIF(搜索词报告!$A$2:$A$22222,总体数据一览!A35,搜索词报告!$V$2:$V$22222))+IF(B35="","",SUMIF(搜索词报告!$A$2:$A$22222,总体数据一览!A35,搜索词报告!$W$2:$W$22222)),"") | H35: =IFERROR(ROUND(F35/G35,2),"")
B36: =IF(SUMIF(搜索词报告!$A$2:$A$22222,总体数据一览!A36,搜索词报告!$I$2:$I$22222)=0,"",SUMIF(搜索词报告!$A$2:$A$22222,总体数据一览!A36,搜索词报告!$I$2:$I$22222)) | C36: =IF(SUMIF(搜索词报告!$A$2:$A$22222,总体数据一览!A36,搜索词报告!$J$2:$J$22222)=0,"",SUMIF(搜索词报告!$A$2:$A$22222,总体数据一览!A36,搜索词报告!$J$2:$J$22222)) | D36: =IFERROR(ROUND(C36/B36,4),"") | E36: =IFERROR(ROUND(F36/C36,2),"") | F36: =IF(SUMIF(搜索词报告!$A$2:$A$22222,总体数据一览!A36,搜索词报告!$M$2:$M$22222)=0,"",SUMIF(搜索词报告!$A$2:$A$22222,总体数据一览!A36,搜索词报告!$M$2:$M$22222)) | G36: =IFERROR(IF(B36="","",SUMIF(搜索词报告!$A$2:$A$22222,总体数据一览!A36,搜索词报告!$V$2:$V$22222))+IF(B36="","",SUMIF(搜索词报告!$A$2:$A$22222,总体数据一览!A36,搜索词报告!$W$2:$W$22222)),"") | H36: =IFERROR(ROUND(F36/G36,2),"")
B37: =IF(SUMIF(搜索词报告!$A$2:$A$22222,总体数据一览!A37,搜索词报告!$I$2:$I$22222)=0,"",SUMIF(搜索词报告!$A$2:$A$22222,总体数据一览!A37,搜索词报告!$I$2:$I$22222)) | C37: =IF(SUMIF(搜索词报告!$A$2:$A$22222,总体数据一览!A37,搜索词报告!$J$2:$J$22222)=0,"",SUMIF(搜索词报告!$A$2:$A$22222,总体数据一览!A37,搜索词报告!$J$2:$J$22222)) | D37: =IFERROR(ROUND(C37/B37,4),"") | E37: =IFERROR(ROUND(F37/C37,2),"") | F37: =IF(SUMIF(搜索词报告!$A$2:$A$22222,总体数据一览!A37,搜索词报告!$M$2:$M$22222)=0,"",SUMIF(搜索词报告!$A$2:$A$22222,总体数据一览!A37,搜索词报告!$M$2:$M$22222)) | G37: =IFERROR(IF(B37="","",SUMIF(搜索词报告!$A$2:$A$22222,总体数据一览!A37,搜索词报告!$V$2:$V$22222))+IF(B37="","",SUMIF(搜索词报告!$A$2:$A$22222,总体数据一览!A37,搜索词报告!$W$2:$W$22222)),"") | H37: =IFERROR(ROUND(F37/G37,2),"")
B38: =IF(SUMIF(搜索词报告!$A$2:$A$22222,总体数据一览!A38,搜索词报告!$I$2:$I$22222)=0,"",SUMIF(搜索词报告!$A$2:$A$22222,总体数据一览!A38,搜索词报告!$I$2:$I$22222)) | C38: =IF(SUMIF(搜索词报告!$A$2:$A$22222,总体数据一览!A38,搜索词报告!$J$2:$J$22222)=0,"",SUMIF(搜索词报告!$A$2:$A$22222,总体数据一览!A38,搜索词报告!$J$2:$J$22222)) | D38: =IFERROR(ROUND(C38/B38,4),"") | E38: =IFERROR(ROUND(F38/C38,2),"") | F38: =IF(SUMIF(搜索词报告!$A$2:$A$22222,总体数据一览!A38,搜索词报告!$M$2:$M$22222)=0,"",SUMIF(搜索词报告!$A$2:$A$22222,总体数据一览!A38,搜索词报告!$M$2:$M$22222)) | G38: =IFERROR(IF(B38="","",SUMIF(搜索词报告!$A$2:$A$22222,总体数据一览!A38,搜索词报告!$V$2:$V$22222))+IF(B38="","",SUMIF(搜索词报告!$A$2:$A$22222,总体数据一览!A38,搜索词报告!$W$2:$W$22222)),"") | H38: =IFERROR(ROUND(F38/G38,2),"")
B39: =IF(SUMIF(搜索词报告!$A$2:$A$22222,总体数据一览!A39,搜索词报告!$I$2:$I$22222)=0,"",SUMIF(搜索词报告!$A$2:$A$22222,总体数据一览!A39,搜索词报告!$I$2:$I$22222)) | C39: =IF(SUMIF(搜索词报告!$A$2:$A$22222,总体数据一览!A39,搜索词报告!$J$2:$J$22222)=0,"",SUMIF(搜索词报告!$A$2:$A$22222,总体数据一览!A39,搜索词报告!$J$2:$J$22222)) | D39: =IFERROR(ROUND(C39/B39,4),"") | E39: =IFERROR(ROUND(F39/C39,2),"") | F39: =IF(SUMIF(搜索词报告!$A$2:$A$22222,总体数据一览!A39,搜索词报告!$M$2:$M$22222)=0,"",SUMIF(搜索词报告!$A$2:$A$22222,总体数据一览!A39,搜索词报告!$M$2:$M$22222)) | G39: =IFERROR(IF(B39="","",SUMIF(搜索词报告!$A$2:$A$22222,总体数据一览!A39,搜索词报告!$V$2:$V$22222))+IF(B39="","",SUMIF(搜索词报告!$A$2:$A$22222,总体数据一览!A39,搜索词报告!$W$2:$W$22222)),"") | H39: =IFERROR(ROUND(F39/G39,2),"")
B40: =IF(SUMIF(搜索词报告!$A$2:$A$22222,总体数据一览!A40,搜索词报告!$I$2:$I$22222)=0,"",SUMIF(搜索词报告!$A$2:$A$22222,总体数据一览!A40,搜索词报告!$I$2:$I$22222)) | C40: =IF(SUMIF(搜索词报告!$A$2:$A$22222,总体数据一览!A40,搜索词报告!$J$2:$J$22222)=0,"",SUMIF(搜索词报告!$A$2:$A$22222,总体数据一览!A40,搜索词报告!$J$2:$J$22222)) | D40: =IFERROR(ROUND(C40/B40,4),"") | E40: =IFERROR(ROUND(F40/C40,2),"") | F40: =IF(SUMIF(搜索词报告!$A$2:$A$22222,总体数据一览!A40,搜索词报告!$M$2:$M$22222)=0,"",SUMIF(搜索词报告!$A$2:$A$22222,总体数据一览!A40,搜索词报告!$M$2:$M$22222)) | G40: =IFERROR(IF(B40="","",SUMIF(搜索词报告!$A$2:$A$22222,总体数据一览!A40,搜索词报告!$V$2:$V$22222))+IF(B40="","",SUMIF(搜索词报告!$A$2:$A$22222,总体数据一览!A40,搜索词报告!$W$2:$W$22222)),"") | H40: =IFERROR(ROUND(F40/G40,2),"")
B41: =IF(SUMIF(搜索词报告!$A$2:$A$22222,总体数据一览!A41,搜索词报告!$I$2:$I$22222)=0,"",SUMIF(搜索词报告!$A$2:$A$22222,总体数据一览!A41,搜索词报告!$I$2:$I$22222)) | C41: =IF(SUMIF(搜索词报告!$A$2:$A$22222,总体数据一览!A41,搜索词报告!$J$2:$J$22222)=0,"",SUMIF(搜索词报告!$A$2:$A$22222,总体数据一览!A41,搜索词报告!$J$2:$J$22222)) | D41: =IFERROR(ROUND(C41/B41,4),"") | E41: =IFERROR(ROUND(F41/C41,2),"") | F41: =IF(SUMIF(搜索词报告!$A$2:$A$22222,总体数据一览!A41,搜索词报告!$M$2:$M$22222)=0,"",SUMIF(搜索词报告!$A$2:$A$22222,总体数据一览!A41,搜索词报告!$M$2:$M$22222)) | G41: =IFERROR(IF(B41="","",SUMIF(搜索词报告!$A$2:$A$22222,总体数据一览!A41,搜索词报告!$V$2:$V$22222))+IF(B41="","",SUMIF(搜索词报告!$A$2:$A$22222,总体数据一览!A41,搜索词报告!$W$2:$W$22222)),"") | H41: =IFERROR(ROUND(F41/G41,2),"")
B42: =IF(SUMIF(搜索词报告!$A$2:$A$22222,总体数据一览!A42,搜索词报告!$I$2:$I$22222)=0,"",SUMIF(搜索词报告!$A$2:$A$22222,总体数据一览!A42,搜索词报告!$I$2:$I$22222)) | C42: =IF(SUMIF(搜索词报告!$A$2:$A$22222,总体数据一览!A42,搜索词报告!$J$2:$J$22222)=0,"",SUMIF(搜索词报告!$A$2:$A$22222,总体数据一览!A42,搜索词报告!$J$2:$J$22222)) | D42: =IFERROR(ROUND(C42/B42,4),"") | E42: =IFERROR(ROUND(F42/C42,2),"") | F42: =IF(SUMIF(搜索词报告!$A$2:$A$22222,总体数据一览!A42,搜索词报告!$M$2:$M$22222)=0,"",SUMIF(搜索词报告!$A$2:$A$22222,总体数据一览!A42,搜索词报告!$M$2:$M$22222)) | G42: =IFERROR(IF(B42="","",SUMIF(搜索词报告!$A$2:$A$22222,总体数据一览!A42,搜索词报告!$V$2:$V$22222))+IF(B42="","",SUMIF(搜索词报告!$A$2:$A$22222,总体数据一览!A42,搜索词报告!$W$2:$W$22222)),"") | H42: =IFERROR(ROUND(F42/G42,2),"")
B43: =IF(SUMIF(搜索词报告!$A$2:$A$22222,总体数据一览!A43,搜索词报告!$I$2:$I$22222)=0,"",SUMIF(搜索词报告!$A$2:$A$22222,总体数据一览!A43,搜索词报告!$I$2:$I$22222)) | C43: =IF(SUMIF(搜索词报告!$A$2:$A$22222,总体数据一览!A43,搜索词报告!$J$2:$J$22222)=0,"",SUMIF(搜索词报告!$A$2:$A$22222,总体数据一览!A43,搜索词报告!$J$2:$J$22222)) | D43: =IFERROR(ROUND(C43/B43,4),"") | E43: =IFERROR(ROUND(F43/C43,2),"") | F43: =IF(SUMIF(搜索词报告!$A$2:$A$22222,总体数据一览!A43,搜索词报告!$M$2:$M$22222)=0,"",SUMIF(搜索词报告!$A$2:$A$22222,总体数据一览!A43,搜索词报告!$M$2:$M$22222)) | G43: =IFERROR(IF(B43="","",SUMIF(搜索词报告!$A$2:$A$22222,总体数据一览!A43,搜索词报告!$V$2:$V$22222))+IF(B43="","",SUMIF(搜索词报告!$A$2:$A$22222,总体数据一览!A43,搜索词报告!$W$2:$W$22222)),"") | H43: =IFERROR(ROUND(F43/G43,2),"")
B44: =IF(SUMIF(搜索词报告!$A$2:$A$22222,总体数据一览!A44,搜索词报告!$I$2:$I$22222)=0,"",SUMIF(搜索词报告!$A$2:$A$22222,总体数据一览!A44,搜索词报告!$I$2:$I$22222)) | C44: =IF(SUMIF(搜索词报告!$A$2:$A$22222,总体数据一览!A44,搜索词报告!$J$2:$J$22222)=0,"",SUMIF(搜索词报告!$A$2:$A$22222,总体数据一览!A44,搜索词报告!$J$2:$J$22222)) | D44: =IFERROR(ROUND(C44/B44,4),"") | E44: =IFERROR(ROUND(F44/C44,2),"") | F44: =IF(SUMIF(搜索词报告!$A$2:$A$22222,总体数据一览!A44,搜索词报告!$M$2:$M$22222)=0,"",SUMIF(搜索词报告!$A$2:$A$22222,总体数据一览!A44,搜索词报告!$M$2:$M$22222)) | G44: =IFERROR(IF(B44="","",SUMIF(搜索词报告!$A$2:$A$22222,总体数据一览!A44,搜索词报告!$V$2:$V$22222))+IF(B44="","",SUMIF(搜索词报告!$A$2:$A$22222,总体数据一览!A44,搜索词报告!$W$2:$W$22222)),"") | H44: =IFERROR(ROUND(F44/G44,2),"")
B45: =IF(SUMIF(搜索词报告!$A$2:$A$22222,总体数据一览!A45,搜索词报告!$I$2:$I$22222)=0,"",SUMIF(搜索词报告!$A$2:$A$22222,总体数据一览!A45,搜索词报告!$I$2:$I$22222)) | C45: =IF(SUMIF(搜索词报告!$A$2:$A$22222,总体数据一览!A45,搜索词报告!$J$2:$J$22222)=0,"",SUMIF(搜索词报告!$A$2:$A$22222,总体数据一览!A45,搜索词报告!$J$2:$J$22222)) | D45: =IFERROR(ROUND(C45/B45,4),"") | E45: =IFERROR(ROUND(F45/C45,2),"") | F45: =IF(SUMIF(搜索词报告!$A$2:$A$22222,总体数据一览!A45,搜索词报告!$M$2:$M$22222)=0,"",SUMIF(搜索词报告!$A$2:$A$22222,总体数据一览!A45,搜索词报告!$M$2:$M$22222)) | G45: =IFERROR(IF(B45="","",SUMIF(搜索词报告!$A$2:$A$22222,总体数据一览!A45,搜索词报告!$V$2:$V$22222))+IF(B45="","",SUMIF(搜索词报告!$A$2:$A$22222,总体数据一览!A45,搜索词报告!$W$2:$W$22222)),"") | H45: =IFERROR(ROUND(F45/G45,2),"")
B46: =IF(SUMIF(搜索词报告!$A$2:$A$22222,总体数据一览!A46,搜索词报告!$I$2:$I$22222)=0,"",SUMIF(搜索词报告!$A$2:$A$22222,总体数据一览!A46,搜索词报告!$I$2:$I$22222)) | C46: =IF(SUMIF(搜索词报告!$A$2:$A$22222,总体数据一览!A46,搜索词报告!$J$2:$J$22222)=0,"",SUMIF(搜索词报告!$A$2:$A$22222,总体数据一览!A46,搜索词报告!$J$2:$J$22222)) | D46: =IFERROR(ROUND(C46/B46,4),"") | E46: =IFERROR(ROUND(F46/C46,2),"") | F46: =IF(SUMIF(搜索词报告!$A$2:$A$22222,总体数据一览!A46,搜索词报告!$M$2:$M$22222)=0,"",SUMIF(搜索词报告!$A$2:$A$22222,总体数据一览!A46,搜索词报告!$M$2:$M$22222)) | G46: =IFERROR(IF(B46="","",SUMIF(搜索词报告!$A$2:$A$22222,总体数据一览!A46,搜索词报告!$V$2:$V$22222))+IF(B46="","",SUMIF(搜索词报告!$A$2:$A$22222,总体数据一览!A46,搜索词报告!$W$2:$W$22222)),"") | H46: =IFERROR(ROUND(F46/G46,2),"")
... B921: =IF(SUMIF(搜索词报告!$A$2:$A$22222,总体数据一览!A921,搜索词报告!$I$2:$I$22222)=0,"",SUMIF(搜索词报告!$A$2:$A$22222,总体数据一览!A921,搜索词报告!$I$2:$I$22222)) | C921: =IF(SUMIF(搜索词报告!$A$2:$A$22222,总体数据一览!A921,搜索词报告!$J$2:$J$22222)=0,"",SUMIF(搜索词报告!$A$2:$A$22222,总体数据一览!A921,搜索词报告!$J$2:$J$22222)) | D921: =IFERROR(ROUND(C921/B921,4),"") | E921: =IFERROR(ROUND(F921/C921,2),"") | F921: =IF(SUMIF(搜索词报告!$A$2:$A$22222,总体数据一览!A921,搜索词报告!$M$2:$M$22222)=0,"",SUMIF(搜索词报告!$A$2:$A$22222,总体数据一览!A921,搜索词报告!$M$2:$M$22222)) | G921: =IFERROR(IF(B921="","",SUMIF(搜索词报告!$A$2:$A$22222,总体数据一览!A921,搜索词报告!$V$2:$V$22222))+IF(B921="","",SUMIF(搜索词报告!$A$2:$A$22222,总体数据一览!A921,搜索词报告!$W$2:$W$22222)),"") | H921: =IFERROR(ROUND(F921/G921,2),"")

Sheet 关键词词频统计
A1: 开始时间 | L1: 开始时间
A2: 43770 | L2: 43770
A3: 结束时间 | L3: 结束时间
A4: 43802 | L4: 43802
A5: 客户搜索词 | B5: 曝光量 | C5: 点击次数 | D5: 点击率 | E5: 转化率 | F5: 订单数 | G5: 销售额 | H5: 花费 | I5: ACOS | J5: 评级 | K5: 所属广告组 | L5: 客户搜索词 | M5: 曝光量 | N5: 点击次数 | O5: 点击率 | P5: 转化率 | Q5: 订单数 | R5: 销售额 | S5: 花费 | T5: ACOS | U5: 评级 | V5: 所属广告组
B6: {=SUM(IF(搜索词报告!$H$2:$H$22222=A6,IF(搜索词报告!$A$2:$A$22222>=关键词词频统计!$A$2,IF(搜索词报告!$A$2:$A$22222<=关键词词频统计!$A$4,搜索词报告!$I$2:$I$22222,0),0),0))} -> 0 | C6: {=SUM(IF(搜索词报告!$H$2:$H$22222=A6,IF(搜索词报告!$A$2:$A$22222>=关键词词频统计!$A$2,IF(搜索词报告!$A$2:$A$22222<=关键词词频统计!$A$4,搜索词报告!$J$2:$J$22222,0),0),0))} -> 0 | D6: =IFERROR(C6/B6,0) -> 0 | E6: =IFERROR(F6/C6,0) -> 0 | F6: {=SUM(IF(搜索词报告!$H$2:$H$22222=A6,IF(搜索词报告!$A$2:$A$22222>=关键词词频统计!$A$2,IF(搜索词报告!$A$2:$A$22222<=关键词词频统计!$A$4,搜索词报告!$Q$2:$Q$22222,0),0),0))} -> 0 | G6: {=SUM(IF(搜索词报告!$H$2:$H$22222=A6,IF(搜索词报告!$A$2:$A$22222>=关键词词频统计!$A$2,IF(搜索词报告!$A$2:$A$22222<=关键词词频统计!$A$4,搜索词报告!$N$2:$N$22222,0),0),0))} -> 0 | H6: {=SUM(IF(搜索词报告!$H$2:$H$22222=A6,IF(搜索词报告!$A$2:$A$22222>=关键词词频统计!$A$2,IF(搜索词报告!$A$2:$A$22222<=关键词词频统计!$A$4,搜索词报告!$M$2:$M$22222,0),0),0))} -> 0 | I6: =IF(IFERROR(H6/G6,0)=0,"",IFERROR(H6/G6,0)) | J6: =IF(AND(C6>=10,E6<=0.05),"极差",IF(AND(C6>=10,0.05<E6,E6<=0.1),"差",IF(AND(C6>=10,0.1<E6,E6<=0.15),"良",IF(AND(C6>=10,E6>0.15),"优","点击次数少于10次没有参考性")))) -> 点击次数少于10次没有参考性 | K6: =IFERROR(INDEX(搜索词报告!$D$2:$D$22222,MATCH(关键词词频统计!A6,搜索词报告!$H$2:$H$22222,0)),"") | M6: {=SUM(IF(搜索词报告!$H$2:$H$22222=L6,IF(搜索词报告!$A$2:$A$22222>=$L$2,IF(搜索词报告!$A$2:$A$22222<=$L$4,搜索词报告!$I$2:$I$22222,0),0),0))} -> 0 | N6: {=SUM(IF(搜索词报告!$H$2:$H$22222=L6,IF(搜索词报告!$A$2:$A$22222>=$L$2,IF(搜索词报告!$A$2:$A$22222<=$L$4,搜索词报告!$J$2:$J$22222,0),0),0))} -> 0 | O6: =IFERROR(N6/M6,0) -> 0 | P6: =IFERROR(Q6/N6,0) -> 0 | Q6: {=SUM(IF(搜索词报告!$H$2:$H$22222=L6,IF(搜索词报告!$A$2:$A$22222>=$L$2,IF(搜索词报告!$A$2:$A$22222<=$L$4,搜索词报告!$Q$2:$Q$22222,0),0),0))} -> 0 | R6: {=SUM(IF(搜索词报告!$H$2:$H$22222=L6,IF(搜索词报告!$A$2:$A$22222>=$L$2,IF(搜索词报告!$A$2:$A$22222<=$L$4,搜索词报告!$N$2:$N$22222,0),0),0))} -> 0 | S6: {=SUM(IF(搜索词报告!$H$2:$H$22222=L6,IF(搜索词报告!$A$2:$A$22222>=$L$2,IF(搜索词报告!$A$2:$A$22222<=$L$4,搜索词报告!$M$2:$M$22222,0),0),0))} -> 0 | T6: =IF(IFERROR(S6/R6,0)=0,"",IFERROR(S6/R6,0)) | U6: =IF(AND(N6>=10,P6<=0.05),"极差",IF(AND(N6>=10,0.05<P6,P6<=0.1),"差",IF(AND(N6>=10,0.1<P6,P6<=0.15),"良",IF(AND(N6>=10,P6>0.15),"优","点击次数少于10次没有参考性")))) -> 点击次数少于10次没有参考性 | V6: =IFERROR(INDEX(搜索词报告!$D$2:$D$22222,MATCH(关键词词频统计!L6,搜索词报告!$H$2:$H$22222,0)),"")
B7: {=SUM(IF(搜索词报告!$H$2:$H$22222=A7,IF(搜索词报告!$A$2:$A$22222>=关键词词频统计!$A$2,IF(搜索词报告!$A$2:$A$22222<=关键词词频统计!$A$4,搜索词报告!$I$2:$I$22222,0),0),0))} -> 0 | C7: {=SUM(IF(搜索词报告!$H$2:$H$22222=A7,IF(搜索词报告!$A$2:$A$22222>=关键词词频统计!$A$2,IF(搜索词报告!$A$2:$A$22222<=关键词词频统计!$A$4,搜索词报告!$J$2:$J$22222,0),0),0))} -> 0 | D7: =IFERROR(C7/B7,0) -> 0 | E7: =IFERROR(F7/C7,0) -> 0 | F7: {=SUM(IF(搜索词报告!$H$2:$H$22222=A7,IF(搜索词报告!$A$2:$A$22222>=关键词词频统计!$A$2,IF(搜索词报告!$A$2:$A$22222<=关键词词频统计!$A$4,搜索词报告!$Q$2:$Q$22222,0),0),0))} -> 0 | G7: {=SUM(IF(搜索词报告!$H$2:$H$22222=A7,IF(搜索词报告!$A$2:$A$22222>=关键词词频统计!$A$2,IF(搜索词报告!$A$2:$A$22222<=关键词词频统计!$A$4,搜索词报告!$N$2:$N$22222,0),0),0))} -> 0 | H7: {=SUM(IF(搜索词报告!$H$2:$H$22222=A7,IF(搜索词报告!$A$2:$A$22222>=关键词词频统计!$A$2,IF(搜索词报告!$A$2:$A$22222<=关键词词频统计!$A$4,搜索词报告!$M$2:$M$22222,0),0),0))} -> 0 | I7: =IF(IFERROR(H7/G7,0)=0,"",IFERROR(H7/G7,0)) | J7: =IF(AND(C7>=10,E7<=0.05),"极差",IF(AND(C7>=10,0.05<E7,E7<=0.1),"差",IF(AND(C7>=10,0.1<E7,E7<=0.15),"良",IF(AND(C7>=10,E7>0.15),"优","点击次数少于10次没有参考性")))) -> 点击次数少于10次没有参考性 | K7: =IFERROR(INDEX(搜索词报告!$D$2:$D$22222,MATCH(关键词词频统计!A7,搜索词报告!$H$2:$H$22222,0)),"") | M7: {=SUM(IF(搜索词报告!$H$2:$H$22222=L7,IF(搜索词报告!$A$2:$A$22222>=$L$2,IF(搜索词报告!$A$2:$A$22222<=$L$4,搜索词报告!$I$2:$I$22222,0),0),0))} -> 0 | N7: {=SUM(IF(搜索词报告!$H$2:$H$22222=L7,IF(搜索词报告!$A$2:$A$22222>=$L$2,IF(搜索词报告!$A$2:$A$22222<=$L$4,搜索词报告!$J$2:$J$22222,0),0),0))} -> 0 | O7: =IFERROR(N7/M7,0) -> 0 | P7: =IFERROR(Q7/N7,0) -> 0 | Q7: {=SUM(IF(搜索词报告!$H$2:$H$22222=L7,IF(搜索词报告!$A$2:$A$22222>=$L$2,IF(搜索词报告!$A$2:$A$22222<=$L$4,搜索词报告!$Q$2:$Q$22222,0),0),0))} -> 0 | R7: {=SUM(IF(搜索词报告!$H$2:$H$22222=L7,IF(搜索词报告!$A$2:$A$22222>=$L$2,IF(搜索词报告!$A$2:$A$22222<=$L$4,搜索词报告!$N$2:$N$22222,0),0),0))} -> 0 | S7: {=SUM(IF(搜索词报告!$H$2:$H$22222=L7,IF(搜索词报告!$A$2:$A$22222>=$L$2,IF(搜索词报告!$A$2:$A$22222<=$L$4,搜索词报告!$M$2:$M$22222,0),0),0))} -> 0 | T7: =IF(IFERROR(S7/R7,0)=0,"",IFERROR(S7/R7,0)) | U7: =IF(AND(N7>=10,P7<=0.05),"极差",IF(AND(N7>=10,0.05<P7,P7<=0.1),"差",IF(AND(N7>=10,0.1<P7,P7<=0.15),"良",IF(AND(N7>=10,P7>0.15),"优","点击次数少于10次没有参考性")))) -> 点击次数少于10次没有参考性 | V7: =IFERROR(INDEX(搜索词报告!$D$2:$D$22222,MATCH(关键词词频统计!L7,搜索词报告!$H$2:$H$22222,0)),"")
B8: {=SUM(IF(搜索词报告!$H$2:$H$22222=A8,IF(搜索词报告!$A$2:$A$22222>=关键词词频统计!$A$2,IF(搜索词报告!$A$2:$A$22222<=关键词词频统计!$A$4,搜索词报告!$I$2:$I$22222,0),0),0))} -> 0 | C8: {=SUM(IF(搜索词报告!$H$2:$H$22222=A8,IF(搜索词报告!$A$2:$A$22222>=关键词词频统计!$A$2,IF(搜索词报告!$A$2:$A$22222<=关键词词频统计!$A$4,搜索词报告!$J$2:$J$22222,0),0),0))} -> 0 | D8: =IFERROR(C8/B8,0) -> 0 | E8: =IFERROR(F8/C8,0) -> 0 | F8: {=SUM(IF(搜索词报告!$H$2:$H$22222=A8,IF(搜索词报告!$A$2:$A$22222>=关键词词频统计!$A$2,IF(搜索词报告!$A$2:$A$22222<=关键词词频统计!$A$4,搜索词报告!$Q$2:$Q$22222,0),0),0))} -> 0 | G8: {=SUM(IF(搜索词报告!$H$2:$H$22222=A8,IF(搜索词报告!$A$2:$A$22222>=关键词词频统计!$A$2,IF(搜索词报告!$A$2:$A$22222<=关键词词频统计!$A$4,搜索词报告!$N$2:$N$22222,0),0),0))} -> 0 | H8: {=SUM(IF(搜索词报告!$H$2:$H$22222=A8,IF(搜索词报告!$A$2:$A$22222>=关键词词频统计!$A$2,IF(搜索词报告!$A$2:$A$22222<=关键词词频统计!$A$4,搜索词报告!$M$2:$M$22222,0),0),0))} -> 0 | I8: =IF(IFERROR(H8/G8,0)=0,"",IFERROR(H8/G8,0)) | J8: =IF(AND(C8>=10,E8<=0.05),"极差",IF(AND(C8>=10,0.05<E8,E8<=0.1),"差",IF(AND(C8>=10,0.1<E8,E8<=0.15),"良",IF(AND(C8>=10,E8>0.15),"优","点击次数少于10次没有参考性")))) -> 点击次数少于10次没有参考性 | K8: =IFERROR(INDEX(搜索词报告!$D$2:$D$22222,MATCH(关键词词频统计!A8,搜索词报告!$H$2:$H$22222,0)),"") | M8: {=SUM(IF(搜索词报告!$H$2:$H$22222=L8,IF(搜索词报告!$A$2:$A$22222>=$L$2,IF(搜索词报告!$A$2:$A$22222<=$L$4,搜索词报告!$I$2:$I$22222,0),0),0))} -> 0 | N8: {=SUM(IF(搜索词报告!$H$2:$H$22222=L8,IF(搜索词报告!$A$2:$A$22222>=$L$2,IF(搜索词报告!$A$2:$A$22222<=$L$4,搜索词报告!$J$2:$J$22222,0),0),0))} -> 0 | O8: =IFERROR(N8/M8,0) -> 0 | P8: =IFERROR(Q8/N8,0) -> 0 | Q8: {=SUM(IF(搜索词报告!$H$2:$H$22222=L8,IF(搜索词报告!$A$2:$A$22222>=$L$2,IF(搜索词报告!$A$2:$A$22222<=$L$4,搜索词报告!$Q$2:$Q$22222,0),0),0))} -> 0 | R8: {=SUM(IF(搜索词报告!$H$2:$H$22222=L8,IF(搜索词报告!$A$2:$A$22222>=$L$2,IF(搜索词报告!$A$2:$A$22222<=$L$4,搜索词报告!$N$2:$N$22222,0),0),0))} -> 0 | S8: {=SUM(IF(搜索词报告!$H$2:$H$22222=L8,IF(搜索词报告!$A$2:$A$22222>=$L$2,IF(搜索词报告!$A$2:$A$22222<=$L$4,搜索词报告!$M$2:$M$22222,0),0),0))} -> 0 | T8: =IF(IFERROR(S8/R8,0)=0,"",IFERROR(S8/R8,0)) | U8: =IF(AND(N8>=10,P8<=0.05),"极差",IF(AND(N8>=10,0.05<P8,P8<=0.1),"差",IF(AND(N8>=10,0.1<P8,P8<=0.15),"良",IF(AND(N8>=10,P8>0.15),"优","点击次数少于10次没有参考性")))) -> 点击次数少于10次没有参考性 | V8: =IFERROR(INDEX(搜索词报告!$D$2:$D$22222,MATCH(关键词词频统计!L8,搜索词报告!$H$2:$H$22222,0)),"")
B9: {=SUM(IF(搜索词报告!$H$2:$H$22222=A9,IF(搜索词报告!$A$2:$A$22222>=关键词词频统计!$A$2,IF(搜索词报告!$A$2:$A$22222<=关键词词频统计!$A$4,搜索词报告!$I$2:$I$22222,0),0),0))} -> 0 | C9: {=SUM(IF(搜索词报告!$H$2:$H$22222=A9,IF(搜索词报告!$A$2:$A$22222>=关键词词频统计!$A$2,IF(搜索词报告!$A$2:$A$22222<=关键词词频统计!$A$4,搜索词报告!$J$2:$J$22222,0),0),0))} -> 0 | D9: =IFERROR(C9/B9,0) -> 0 | E9: =IFERROR(F9/C9,0) -> 0 | F9: {=SUM(IF(搜索词报告!$H$2:$H$22222=A9,IF(搜索词报告!$A$2:$A$22222>=关键词词频统计!$A$2,IF(搜索词报告!$A$2:$A$22222<=关键词词频统计!$A$4,搜索词报告!$Q$2:$Q$22222,0),0),0))} -> 0 | G9: {=SUM(IF(搜索词报告!$H$2:$H$22222=A9,IF(搜索词报告!$A$2:$A$22222>=关键词词频统计!$A$2,IF(搜索词报告!$A$2:$A$22222<=关键词词频统计!$A$4,搜索词报告!$N$2:$N$22222,0),0),0))} -> 0 | H9: {=SUM(IF(搜索词报告!$H$2:$H$22222=A9,IF(搜索词报告!$A$2:$A$22222>=关键词词频统计!$A$2,IF(搜索词报告!$A$2:$A$22222<=关键词词频统计!$A$4,搜索词报告!$M$2:$M$22222,0),0),0))} -> 0 | I9: =IF(IFERROR(H9/G9,0)=0,"",IFERROR(H9/G9,0)) | J9: =IF(AND(C9>=10,E9<=0.05),"极差",IF(AND(C9>=10,0.05<E9,E9<=0.1),"差",IF(AND(C9>=10,0.1<E9,E9<=0.15),"良",IF(AND(C9>=10,E9>0.15),"优","点击次数少于10次没有参考性")))) -> 点击次数少于10次没有参考性 | K9: =IFERROR(INDEX(搜索词报告!$D$2:$D$22222,MATCH(关键词词频统计!A9,搜索词报告!$H$2:$H$22222,0)),"") | M9: {=SUM(IF(搜索词报告!$H$2:$H$22222=L9,IF(搜索词报告!$A$2:$A$22222>=$L$2,IF(搜索词报告!$A$2:$A$22222<=$L$4,搜索词报告!$I$2:$I$22222,0),0),0))} -> 0 | N9: {=SUM(IF(搜索词报告!$H$2:$H$22222=L9,IF(搜索词报告!$A$2:$A$22222>=$L$2,IF(搜索词报告!$A$2:$A$22222<=$L$4,搜索词报告!$J$2:$J$22222,0),0),0))} -> 0 | O9: =IFERROR(N9/M9,0) -> 0 | P9: =IFERROR(Q9/N9,0) -> 0 | Q9: {=SUM(IF(搜索词报告!$H$2:$H$22222=L9,IF(搜索词报告!$A$2:$A$22222>=$L$2,IF(搜索词报告!$A$2:$A$22222<=$L$4,搜索词报告!$Q$2:$Q$22222,0),0),0))} -> 0 | R9: {=SUM(IF(搜索词报告!$H$2:$H$22222=L9,IF(搜索词报告!$A$2:$A$22222>=$L$2,IF(搜索词报告!$A$2:$A$22222<=$L$4,搜索词报告!$N$2:$N$22222,0),0),0))} -> 0 | S9: {=SUM(IF(搜索词报告!$H$2:$H$22222=L9,IF(搜索词报告!$A$2:$A$22222>=$L$2,IF(搜索词报告!$A$2:$A$22222<=$L$4,搜索词报告!$M$2:$M$22222,0),0),0))} -> 0 | T9: =IF(IFERROR(S9/R9,0)=0,"",IFERROR(S9/R9,0)) | U9: =IF(AND(N9>=10,P9<=0.05),"极差",IF(AND(N9>=10,0.05<P9,P9<=0.1),"差",IF(AND(N9>=10,0.1<P9,P9<=0.15),"良",IF(AND(N9>=10,P9>0.15),"优","点击次数少于10次没有参考性")))) -> 点击次数少于10次没有参考性 | V9: =IFERROR(INDEX(搜索词报告!$D$2:$D$22222,MATCH(关键词词频统计!L9,搜索词报告!$H$2:$H$22222,0)),"")
B10: {=SUM(IF(搜索词报告!$H$2:$H$22222=A10,IF(搜索词报告!$A$2:$A$22222>=关键词词频统计!$A$2,IF(搜索词报告!$A$2:$A$22222<=关键词词频统计!$A$4,搜索词报告!$I$2:$I$22222,0),0),0))} -> 0 | C10: {=SUM(IF(搜索词报告!$H$2:$H$22222=A10,IF(搜索词报告!$A$2:$A$22222>=关键词词频统计!$A$2,IF(搜索词报告!$A$2:$A$22222<=关键词词频统计!$A$4,搜索词报告!$J$2:$J$22222,0),0),0))} -> 0 | D10: =IFERROR(C10/B10,0) -> 0 | E10: =IFERROR(F10/C10,0) -> 0 | F10: {=SUM(IF(搜索词报告!$H$2:$H$22222=A10,IF(搜索词报告!$A$2:$A$22222>=关键词词频统计!$A$2,IF(搜索词报告!$A$2:$A$22222<=关键词词频统计!$A$4,搜索词报告!$Q$2:$Q$22222,0),0),0))} -> 0 | G10: {=SUM(IF(搜索词报告!$H$2:$H$22222=A10,IF(搜索词报告!$A$2:$A$22222>=关键词词频统计!$A$2,IF(搜索词报告!$A$2:$A$22222<=关键词词频统计!$A$4,搜索词报告!$N$2:$N$22222,0),0),0))} -> 0 | H10: {=SUM(IF(搜索词报告!$H$2:$H$22222=A10,IF(搜索词报告!$A$2:$A$22222>=关键词词频统计!$A$2,IF(搜索词报告!$A$2:$A$22222<=关键词词频统计!$A$4,搜索词报告!$M$2:$M$22222,0),0),0))} -> 0 | I10: =IF(IFERROR(H10/G10,0)=0,"",IFERROR(H10/G10,0)) | J10: =IF(AND(C10>=10,E10<=0.05),"极差",IF(AND(C10>=10,0.05<E10,E10<=0.1),"差",IF(AND(C10>=10,0.1<E10,E10<=0.15),"良",IF(AND(C10>=10,E10>0.15),"优","点击次数少于10次没有参考性")))) -> 点击次数少于10次没有参考性 | K10: =IFERROR(INDEX(搜索词报告!$D$2:$D$22222,MATCH(关键词词频统计!A10,搜索词报告!$H$2:$H$22222,0)),"") | M10: {=SUM(IF(搜索词报告!$H$2:$H$22222=L10,IF(搜索词报告!$A$2:$A$22222>=$L$2,IF(搜索词报告!$A$2:$A$22222<=$L$4,搜索词报告!$I$2:$I$22222,0),0),0))} -> 0 | N10: {=SUM(IF(搜索词报告!$H$2:$H$22222=L10,IF(搜索词报告!$A$2:$A$22222>=$L$2,IF(搜索词报告!$A$2:$A$22222<=$L$4,搜索词报告!$J$2:$J$22222,0),0),0))} -> 0 | O10: =IFERROR(N10/M10,0) -> 0 | P10: =IFERROR(Q10/N10,0) -> 0 | Q10: {=SUM(IF(搜索词报告!$H$2:$H$22222=L10,IF(搜索词报告!$A$2:$A$22222>=$L$2,IF(搜索词报告!$A$2:$A$22222<=$L$4,搜索词报告!$Q$2:$Q$22222,0),0),0))} -> 0 | R10: {=SUM(IF(搜索词报告!$H$2:$H$22222=L10,IF(搜索词报告!$A$2:$A$22222>=$L$2,IF(搜索词报告!$A$2:$A$22222<=$L$4,搜索词报告!$N$2:$N$22222,0),0),0))} -> 0 | S10: {=SUM(IF(搜索词报告!$H$2:$H$22222=L10,IF(搜索词报告!$A$2:$A$22222>=$L$2,IF(搜索词报告!$A$2:$A$22222<=$L$4,搜索词报告!$M$2:$M$22222,0),0),0))} -> 0 | T10: =IF(IFERROR(S10/R10,0)=0,"",IFERROR(S10/R10,0)) | U10: =IF(AND(N10>=10,P10<=0.05),"极差",IF(AND(N10>=10,0.05<P10,P10<=0.1),"差",IF(AND(N10>=10,0.1<P10,P10<=0.15),"良",IF(AND(N10>=10,P10>0.15),"优","点击次数少于10次没有参考性")))) -> 点击次数少于10次没有参考性 | V10: =IFERROR(INDEX(搜索词报告!$D$2:$D$22222,MATCH(关键词词频统计!L10,搜索词报告!$H$2:$H$22222,0)),"")
B11: {=SUM(IF(搜索词报告!$H$2:$H$22222=A11,IF(搜索词报告!$A$2:$A$22222>=关键词词频统计!$A$2,IF(搜索词报告!$A$2:$A$22222<=关键词词频统计!$A$4,搜索词报告!$I$2:$I$22222,0),0),0))} -> 0 | C11: {=SUM(IF(搜索词报告!$H$2:$H$22222=A11,IF(搜索词报告!$A$2:$A$22222>=关键词词频统计!$A$2,IF(搜索词报告!$A$2:$A$22222<=关键词词频统计!$A$4,搜索词报告!$J$2:$J$22222,0),0),0))} -> 0 | D11: =IFERROR(C11/B11,0) -> 0 | E11: =IFERROR(F11/C11,0) -> 0 | F11: {=SUM(IF(搜索词报告!$H$2:$H$22222=A11,IF(搜索词报告!$A$2:$A$22222>=关键词词频统计!$A$2,IF(搜索词报告!$A$2:$A$22222<=关键词词频统计!$A$4,搜索词报告!$Q$2:$Q$22222,0),0),0))} -> 0 | G11: {=SUM(IF(搜索词报告!$H$2:$H$22222=A11,IF(搜索词报告!$A$2:$A$22222>=关键词词频统计!$A$2,IF(搜索词报告!$A$2:$A$22222<=关键词词频统计!$A$4,搜索词报告!$N$2:$N$22222,0),0),0))} -> 0 | H11: {=SUM(IF(搜索词报告!$H$2:$H$22222=A11,IF(搜索词报告!$A$2:$A$22222>=关键词词频统计!$A$2,IF(搜索词报告!$A$2:$A$22222<=关键词词频统计!$A$4,搜索词报告!$M$2:$M$22222,0),0),0))} -> 0 | I11: =IF(IFERROR(H11/G11,0)=0,"",IFERROR(H11/G11,0)) | J11: =IF(AND(C11>=10,E11<=0.05),"极差",IF(AND(C11>=10,0.05<E11,E11<=0.1),"差",IF(AND(C11>=10,0.1<E11,E11<=0.15),"良",IF(AND(C11>=10,E11>0.15),"优","点击次数少于10次没有参考性")))) -> 点击次数少于10次没有参考性 | K11: =IFERROR(INDEX(搜索词报告!$D$2:$D$22222,MATCH(关键词词频统计!A11,搜索词报告!$H$2:$H$22222,0)),"") | M11: {=SUM(IF(搜索词报告!$H$2:$H$22222=L11,IF(搜索词报告!$A$2:$A$22222>=$L$2,IF(搜索词报告!$A$2:$A$22222<=$L$4,搜索词报告!$I$2:$I$22222,0),0),0))} -> 0 | N11: {=SUM(IF(搜索词报告!$H$2:$H$22222=L11,IF(搜索词报告!$A$2:$A$22222>=$L$2,IF(搜索词报告!$A$2:$A$22222<=$L$4,搜索词报告!$J$2:$J$22222,0),0),0))} -> 0 | O11: =IFERROR(N11/M11,0) -> 0 | P11: =IFERROR(Q11/N11,0) -> 0 | Q11: {=SUM(IF(搜索词报告!$H$2:$H$22222=L11,IF(搜索词报告!$A$2:$A$22222>=$L$2,IF(搜索词报告!$A$2:$A$22222<=$L$4,搜索词报告!$Q$2:$Q$22222,0),0),0))} -> 0 | R11: {=SUM(IF(搜索词报告!$H$2:$H$22222=L11,IF(搜索词报告!$A$2:$A$22222>=$L$2,IF(搜索词报告!$A$2:$A$22222<=$L$4,搜索词报告!$N$2:$N$22222,0),0),0))} -> 0 | S11: {=SUM(IF(搜索词报告!$H$2:$H$22222=L11,IF(搜索词报告!$A$2:$A$22222>=$L$2,IF(搜索词报告!$A$2:$A$22222<=$L$4,搜索词报告!$M$2:$M$22222,0),0),0))} -> 0 | T11: =IF(IFERROR(S11/R11,0)=0,"",IFERROR(S11/R11,0)) | U11: =IF(AND(N11>=10,P11<=0.05),"极差",IF(AND(N11>=10,0.05<P11,P11<=0.1),"差",IF(AND(N11>=10,0.1<P11,P11<=0.15),"良",IF(AND(N11>=10,P11>0.15),"优","点击次数少于10次没有参考性")))) -> 点击次数少于10次没有参考性 | V11: =IFERROR(INDEX(搜索词报告!$D$2:$D$22222,MATCH(关键词词频统计!L11,搜索词报告!$H$2:$H$22222,0)),"")
B12: {=SUM(IF(搜索词报告!$H$2:$H$22222=A12,IF(搜索词报告!$A$2:$A$22222>=关键词词频统计!$A$2,IF(搜索词报告!$A$2:$A$22222<=关键词词频统计!$A$4,搜索词报告!$I$2:$I$22222,0),0),0))} -> 0 | C12: {=SUM(IF(搜索词报告!$H$2:$H$22222=A12,IF(搜索词报告!$A$2:$A$22222>=关键词词频统计!$A$2,IF(搜索词报告!$A$2:$A$22222<=关键词词频统计!$A$4,搜索词报告!$J$2:$J$22222,0),0),0))} -> 0 | D12: =IFERROR(C12/B12,0) -> 0 | E12: =IFERROR(F12/C12,0) -> 0 | F12: {=SUM(IF(搜索词报告!$H$2:$H$22222=A12,IF(搜索词报告!$A$2:$A$22222>=关键词词频统计!$A$2,IF(搜索词报告!$A$2:$A$22222<=关键词词频统计!$A$4,搜索词报告!$Q$2:$Q$22222,0),0),0))} -> 0 | G12: {=SUM(IF(搜索词报告!$H$2:$H$22222=A12,IF(搜索词报告!$A$2:$A$22222>=关键词词频统计!$A$2,IF(搜索词报告!$A$2:$A$22222<=关键词词频统计!$A$4,搜索词报告!$N$2:$N$22222,0),0),0))} -> 0 | H12: {=SUM(IF(搜索词报告!$H$2:$H$22222=A12,IF(搜索词报告!$A$2:$A$22222>=关键词词频统计!$A$2,IF(搜索词报告!$A$2:$A$22222<=关键词词频统计!$A$4,搜索词报告!$M$2:$M$22222,0),0),0))} -> 0 | I12: =IF(IFERROR(H12/G12,0)=0,"",IFERROR(H12/G12,0)) | J12: =IF(AND(C12>=10,E12<=0.05),"极差",IF(AND(C12>=10,0.05<E12,E12<=0.1),"差",IF(AND(C12>=10,0.1<E12,E12<=0.15),"良",IF(AND(C12>=10,E12>0.15),"优","点击次数少于10次没有参考性")))) -> 点击次数少于10次没有参考性 | K12: =IFERROR(INDEX(搜索词报告!$D$2:$D$22222,MATCH(关键词词频统计!A12,搜索词报告!$H$2:$H$22222,0)),"") | M12: {=SUM(IF(搜索词报告!$H$2:$H$22222=L12,IF(搜索词报告!$A$2:$A$22222>=$L$2,IF(搜索词报告!$A$2:$A$22222<=$L$4,搜索词报告!$I$2:$I$22222,0),0),0))} -> 0 | N12: {=SUM(IF(搜索词报告!$H$2:$H$22222=L12,IF(搜索词报告!$A$2:$A$22222>=$L$2,IF(搜索词报告!$A$2:$A$22222<=$L$4,搜索词报告!$J$2:$J$22222,0),0),0))} -> 0 | O12: =IFERROR(N12/M12,0) -> 0 | P12: =IFERROR(Q12/N12,0) -> 0 | Q12: {=SUM(IF(搜索词报告!$H$2:$H$22222=L12,IF(搜索词报告!$A$2:$A$22222>=$L$2,IF(搜索词报告!$A$2:$A$22222<=$L$4,搜索词报告!$Q$2:$Q$22222,0),0),0))} -> 0 | R12: {=SUM(IF(搜索词报告!$H$2:$H$22222=L12,IF(搜索词报告!$A$2:$A$22222>=$L$2,IF(搜索词报告!$A$2:$A$22222<=$L$4,搜索词报告!$N$2:$N$22222,0),0),0))} -> 0 | S12: {=SUM(IF(搜索词报告!$H$2:$H$22222=L12,IF(搜索词报告!$A$2:$A$22222>=$L$2,IF(搜索词报告!$A$2:$A$22222<=$L$4,搜索词报告!$M$2:$M$22222,0),0),0))} -> 0 | T12: =IF(IFERROR(S12/R12,0)=0,"",IFERROR(S12/R12,0)) | U12: =IF(AND(N12>=10,P12<=0.05),"极差",IF(AND(N12>=10,0.05<P12,P12<=0.1),"差",IF(AND(N12>=10,0.1<P12,P12<=0.15),"良",IF(AND(N12>=10,P12>0.15),"优","点击次数少于10次没有参考性")))) -> 点击次数少于10次没有参考性 | V12: =IFERROR(INDEX(搜索词报告!$D$2:$D$22222,MATCH(关键词词频统计!L12,搜索词报告!$H$2:$H$22222,0)),"")
B13: {=SUM(IF(搜索词报告!$H$2:$H$22222=A13,IF(搜索词报告!$A$2:$A$22222>=关键词词频统计!$A$2,IF(搜索词报告!$A$2:$A$22222<=关键词词频统计!$A$4,搜索词报告!$I$2:$I$22222,0),0),0))} -> 0 | C13: {=SUM(IF(搜索词报告!$H$2:$H$22222=A13,IF(搜索词报告!$A$2:$A$22222>=关键词词频统计!$A$2,IF(搜索词报告!$A$2:$A$22222<=关键词词频统计!$A$4,搜索词报告!$J$2:$J$22222,0),0),0))} -> 0 | D13: =IFERROR(C13/B13,0) -> 0 | E13: =IFERROR(F13/C13,0) -> 0 | F13: {=SUM(IF(搜索词报告!$H$2:$H$22222=A13,IF(搜索词报告!$A$2:$A$22222>=关键词词频统计!$A$2,IF(搜索词报告!$A$2:$A$22222<=关键词词频统计!$A$4,搜索词报告!$Q$2:$Q$22222,0),0),0))} -> 0 | G13: {=SUM(IF(搜索词报告!$H$2:$H$22222=A13,IF(搜索词报告!$A$2:$A$22222>=关键词词频统计!$A$2,IF(搜索词报告!$A$2:$A$22222<=关键词词频统计!$A$4,搜索词报告!$N$2:$N$22222,0),0),0))} -> 0 | H13: {=SUM(IF(搜索词报告!$H$2:$H$22222=A13,IF(搜索词报告!$A$2:$A$22222>=关键词词频统计!$A$2,IF(搜索词报告!$A$2:$A$22222<=关键词词频统计!$A$4,搜索词报告!$M$2:$M$22222,0),0),0))} -> 0 | I13: =IF(IFERROR(H13/G13,0)=0,"",IFERROR(H13/G13,0)) | J13: =IF(AND(C13>=10,E13<=0.05),"极差",IF(AND(C13>=10,0.05<E13,E13<=0.1),"差",IF(AND(C13>=10,0.1<E13,E13<=0.15),"良",IF(AND(C13>=10,E13>0.15),"优","点击次数少于10次没有参考性")))) -> 点击次数少于10次没有参考性 | K13: =IFERROR(INDEX(搜索词报告!$D$2:$D$22222,MATCH(关键词词频统计!A13,搜索词报告!$H$2:$H$22222,0)),"") | M13: {=SUM(IF(搜索词报告!$H$2:$H$22222=L13,IF(搜索词报告!$A$2:$A$22222>=$L$2,IF(搜索词报告!$A$2:$A$22222<=$L$4,搜索词报告!$I$2:$I$22222,0),0),0))} -> 0 | N13: {=SUM(IF(搜索词报告!$H$2:$H$22222=L13,IF(搜索词报告!$A$2:$A$22222>=$L$2,IF(搜索词报告!$A$2:$A$22222<=$L$4,搜索词报告!$J$2:$J$22222,0),0),0))} -> 0 | O13: =IFERROR(N13/M13,0) -> 0 | P13: =IFERROR(Q13/N13,0) -> 0 | Q13: {=SUM(IF(搜索词报告!$H$2:$H$22222=L13,IF(搜索词报告!$A$2:$A$22222>=$L$2,IF(搜索词报告!$A$2:$A$22222<=$L$4,搜索词报告!$Q$2:$Q$22222,0),0),0))} -> 0 | R13: {=SUM(IF(搜索词报告!$H$2:$H$22222=L13,IF(搜索词报告!$A$2:$A$22222>=$L$2,IF(搜索词报告!$A$2:$A$22222<=$L$4,搜索词报告!$N$2:$N$22222,0),0),0))} -> 0 | S13: {=SUM(IF(搜索词报告!$H$2:$H$22222=L13,IF(搜索词报告!$A$2:$A$22222>=$L$2,IF(搜索词报告!$A$2:$A$22222<=$L$4,搜索词报告!$M$2:$M$22222,0),0),0))} -> 0 | T13: =IF(IFERROR(S13/R13,0)=0,"",IFERROR(S13/R13,0)) | U13: =IF(AND(N13>=10,P13<=0.05),"极差",IF(AND(N13>=10,0.05<P13,P13<=0.1),"差",IF(AND(N13>=10,0.1<P13,P13<=0.15),"良",IF(AND(N13>=10,P13>0.15),"优","点击次数少于10次没有参考性")))) -> 点击次数少于10次没有参考性 | V13: =IFERROR(INDEX(搜索词报告!$D$2:$D$22222,MATCH(关键词词频统计!L13,搜索词报告!$H$2:$H$22222,0)),"")
B14: {=SUM(IF(搜索词报告!$H$2:$H$22222=A14,IF(搜索词报告!$A$2:$A$22222>=关键词词频统计!$A$2,IF(搜索词报告!$A$2:$A$22222<=关键词词频统计!$A$4,搜索词报告!$I$2:$I$22222,0),0),0))} -> 0 | C14: {=SUM(IF(搜索词报告!$H$2:$H$22222=A14,IF(搜索词报告!$A$2:$A$22222>=关键词词频统计!$A$2,IF(搜索词报告!$A$2:$A$22222<=关键词词频统计!$A$4,搜索词报告!$J$2:$J$22222,0),0),0))} -> 0 | D14: =IFERROR(C14/B14,0) -> 0 | E14: =IFERROR(F14/C14,0) -> 0 | F14: {=SUM(IF(搜索词报告!$H$2:$H$22222=A14,IF(搜索词报告!$A$2:$A$22222>=关键词词频统计!$A$2,IF(搜索词报告!$A$2:$A$22222<=关键词词频统计!$A$4,搜索词报告!$Q$2:$Q$22222,0),0),0))} -> 0 | G14: {=SUM(IF(搜索词报告!$H$2:$H$22222=A14,IF(搜索词报告!$A$2:$A$22222>=关键词词频统计!$A$2,IF(搜索词报告!$A$2:$A$22222<=关键词词频统计!$A$4,搜索词报告!$N$2:$N$22222,0),0),0))} -> 0 | H14: =SUM(IF(搜索词报告!$H$2:$H$22222=A14,IF(搜索词报告!$A$2:$A$22222>=关键词词频统计!$A$2,IF(搜索词报告!$A$2:$A$22222<=关键词词频统计!$A$4,搜索词报告!$M$2:$M$22222,0),0),0)) -> 0 | I14: =IF(IFERROR(H14/G14,0)=0,"",IFERROR(H14/G14,0)) | J14: =IF(AND(C14>=10,E14<=0.05),"极差",IF(AND(C14>=10,0.05<E14,E14<=0.1),"差",IF(AND(C14>=10,0.1<E14,E14<=0.15),"良",IF(AND(C14>=10,E14>0.15),"优","点击次数少于10次没有参考性")))) -> 点击次数少于10次没有参考性 | K14: =IFERROR(INDEX(搜索词报告!$D$2:$D$22222,MATCH(关键词词频统计!A14,搜索词报告!$H$2:$H$22222,0)),"") | M14: {=SUM(IF(搜索词报告!$H$2:$H$22222=L14,IF(搜索词报告!$A$2:$A$22222>=$L$2,IF(搜索词报告!$A$2:$A$22222<=$L$4,搜索词报告!$I$2:$I$22222,0),0),0))} -> 0 | N14: {=SUM(IF(搜索词报告!$H$2:$H$22222=L14,IF(搜索词报告!$A$2:$A$22222>=$L$2,IF(搜索词报告!$A$2:$A$22222<=$L$4,搜索词报告!$J$2:$J$22222,0),0),0))} -> 0 | O14: =IFERROR(N14/M14,0) -> 0 | P14: =IFERROR(Q14/N14,0) -> 0 | Q14: {=SUM(IF(搜索词报告!$H$2:$H$22222=L14,IF(搜索词报告!$A$2:$A$22222>=$L$2,IF(搜索词报告!$A$2:$A$22222<=$L$4,搜索词报告!$Q$2:$Q$22222,0),0),0))} -> 0 | R14: {=SUM(IF(搜索词报告!$H$2:$H$22222=L14,IF(搜索词报告!$A$2:$A$22222>=$L$2,IF(搜索词报告!$A$2:$A$22222<=$L$4,搜索词报告!$N$2:$N$22222,0),0),0))} -> 0 | S14: {=SUM(IF(搜索词报告!$H$2:$H$22222=L14,IF(搜索词报告!$A$2:$A$22222>=$L$2,IF(搜索词报告!$A$2:$A$22222<=$L$4,搜索词报告!$M$2:$M$22222,0),0),0))} -> 0 | T14: =IF(IFERROR(S14/R14,0)=0,"",IFERROR(S14/R14,0)) | U14: =IF(AND(N14>=10,P14<=0.05),"极差",IF(AND(N14>=10,0.05<P14,P14<=0.1),"差",IF(AND(N14>=10,0.1<P14,P14<=0.15),"良",IF(AND(N14>=10,P14>0.15),"优","点击次数少于10次没有参考性")))) -> 点击次数少于10次没有参考性 | V14: =IFERROR(INDEX(搜索词报告!$D$2:$D$22222,MATCH(关键词词频统计!L14,搜索词报告!$H$2:$H$22222,0)),"")
B15: {=SUM(IF(搜索词报告!$H$2:$H$22222=A15,IF(搜索词报告!$A$2:$A$22222>=关键词词频统计!$A$2,IF(搜索词报告!$A$2:$A$22222<=关键词词频统计!$A$4,搜索词报告!$I$2:$I$22222,0),0),0))} -> 0 | C15: {=SUM(IF(搜索词报告!$H$2:$H$22222=A15,IF(搜索词报告!$A$2:$A$22222>=关键词词频统计!$A$2,IF(搜索词报告!$A$2:$A$22222<=关键词词频统计!$A$4,搜索词报告!$J$2:$J$22222,0),0),0))} -> 0 | D15: =IFERROR(C15/B15,0) -> 0 | E15: =IFERROR(F15/C15,0) -> 0 | F15: {=SUM(IF(搜索词报告!$H$2:$H$22222=A15,IF(搜索词报告!$A$2:$A$22222>=关键词词频统计!$A$2,IF(搜索词报告!$A$2:$A$22222<=关键词词频统计!$A$4,搜索词报告!$Q$2:$Q$22222,0),0),0))} -> 0 | G15: {=SUM(IF(搜索词报告!$H$2:$H$22222=A15,IF(搜索词报告!$A$2:$A$22222>=关键词词频统计!$A$2,IF(搜索词报告!$A$2:$A$22222<=关键词词频统计!$A$4,搜索词报告!$N$2:$N$22222,0),0),0))} -> 0 | H15: {=SUM(IF(搜索词报告!$H$2:$H$22222=A15,IF(搜索词报告!$A$2:$A$22222>=关键词词频统计!$A$2,IF(搜索词报告!$A$2:$A$22222<=关键词词频统计!$A$4,搜索词报告!$M$2:$M$22222,0),0),0))} -> 0 | I15: =IF(IFERROR(H15/G15,0)=0,"",IFERROR(H15/G15,0)) | J15: =IF(AND(C15>=10,E15<=0.05),"极差",IF(AND(C15>=10,0.05<E15,E15<=0.1),"差",IF(AND(C15>=10,0.1<E15,E15<=0.15),"良",IF(AND(C15>=10,E15>0.15),"优","点击次数少于10次没有参考性")))) -> 点击次数少于10次没有参考性 | K15: =IFERROR(INDEX(搜索词报告!$D$2:$D$22222,MATCH(关键词词频统计!A15,搜索词报告!$H$2:$H$22222,0)),"") | M15: {=SUM(IF(搜索词报告!$H$2:$H$22222=L15,IF(搜索词报告!$A$2:$A$22222>=$L$2,IF(搜索词报告!$A$2:$A$22222<=$L$4,搜索词报告!$I$2:$I$22222,0),0),0))} -> 0 | N15: {=SUM(IF(搜索词报告!$H$2:$H$22222=L15,IF(搜索词报告!$A$2:$A$22222>=$L$2,IF(搜索词报告!$A$2:$A$22222<=$L$4,搜索词报告!$J$2:$J$22222,0),0),0))} -> 0 | O15: =IFERROR(N15/M15,0) -> 0 | P15: =IFERROR(Q15/N15,0) -> 0 | Q15: {=SUM(IF(搜索词报告!$H$2:$H$22222=L15,IF(搜索词报告!$A$2:$A$22222>=$L$2,IF(搜索词报告!$A$2:$A$22222<=$L$4,搜索词报告!$Q$2:$Q$22222,0),0),0))} -> 0 | R15: {=SUM(IF(搜索词报告!$H$2:$H$22222=L15,IF(搜索词报告!$A$2:$A$22222>=$L$2,IF(搜索词报告!$A$2:$A$22222<=$L$4,搜索词报告!$N$2:$N$22222,0),0),0))} -> 0 | S15: {=SUM(IF(搜索词报告!$H$2:$H$22222=L15,IF(搜索词报告!$A$2:$A$22222>=$L$2,IF(搜索词报告!$A$2:$A$22222<=$L$4,搜索词报告!$M$2:$M$22222,0),0),0))} -> 0 | T15: =IF(IFERROR(S15/R15,0)=0,"",IFERROR(S15/R15,0)) | U15: =IF(AND(N15>=10,P15<=0.05),"极差",IF(AND(N15>=10,0.05<P15,P15<=0.1),"差",IF(AND(N15>=10,0.1<P15,P15<=0.15),"良",IF(AND(N15>=10,P15>0.15),"优","点击次数少于10次没有参考性")))) -> 点击次数少于10次没有参考性 | V15: =IFERROR(INDEX(搜索词报告!$D$2:$D$22222,MATCH(关键词词频统计!L15,搜索词报告!$H$2:$H$22222,0)),"")
B16: {=SUM(IF(搜索词报告!$H$2:$H$22222=A16,IF(搜索词报告!$A$2:$A$22222>=关键词词频统计!$A$2,IF(搜索词报告!$A$2:$A$22222<=关键词词频统计!$A$4,搜索词报告!$I$2:$I$22222,0),0),0))} -> 0 | C16: {=SUM(IF(搜索词报告!$H$2:$H$22222=A16,IF(搜索词报告!$A$2:$A$22222>=关键词词频统计!$A$2,IF(搜索词报告!$A$2:$A$22222<=关键词词频统计!$A$4,搜索词报告!$J$2:$J$22222,0),0),0))} -> 0 | D16: =IFERROR(C16/B16,0) -> 0 | E16: =IFERROR(F16/C16,0) -> 0 | F16: {=SUM(IF(搜索词报告!$H$2:$H$22222=A16,IF(搜索词报告!$A$2:$A$22222>=关键词词频统计!$A$2,IF(搜索词报告!$A$2:$A$22222<=关键词词频统计!$A$4,搜索词报告!$Q$2:$Q$22222,0),0),0))} -> 0 | G16: {=SUM(IF(搜索词报告!$H$2:$H$22222=A16,IF(搜索词报告!$A$2:$A$22222>=关键词词频统计!$A$2,IF(搜索词报告!$A$2:$A$22222<=关键词词频统计!$A$4,搜索词报告!$N$2:$N$22222,0),0),0))} -> 0 | H16: {=SUM(IF(搜索词报告!$H$2:$H$22222=A16,IF(搜索词报告!$A$2:$A$22222>=关键词词频统计!$A$2,IF(搜索词报告!$A$2:$A$22222<=关键词词频统计!$A$4,搜索词报告!$M$2:$M$22222,0),0),0))} -> 0 | I16: =IF(IFERROR(H16/G16,0)=0,"",IFERROR(H16/G16,0)) | J16: =IF(AND(C16>=10,E16<=0.05),"极差",IF(AND(C16>=10,0.05<E16,E16<=0.1),"差",IF(AND(C16>=10,0.1<E16,E16<=0.15),"良",IF(AND(C16>=10,E16>0.15),"优","点击次数少于10次没有参考性")))) -> 点击次数少于10次没有参考性 | K16: =IFERROR(INDEX(搜索词报告!$D$2:$D$22222,MATCH(关键词词频统计!A16,搜索词报告!$H$2:$H$22222,0)),"") | M16: {=SUM(IF(搜索词报告!$H$2:$H$22222=L16,IF(搜索词报告!$A$2:$A$22222>=$L$2,IF(搜索词报告!$A$2:$A$22222<=$L$4,搜索词报告!$I$2:$I$22222,0),0),0))} -> 0 | N16: {=SUM(IF(搜索词报告!$H$2:$H$22222=L16,IF(搜索词报告!$A$2:$A$22222>=$L$2,IF(搜索词报告!$A$2:$A$22222<=$L$4,搜索词报告!$J$2:$J$22222,0),0),0))} -> 0 | O16: =IFERROR(N16/M16,0) -> 0 | P16: =IFERROR(Q16/N16,0) -> 0 | Q16: {=SUM(IF(搜索词报告!$H$2:$H$22222=L16,IF(搜索词报告!$A$2:$A$22222>=$L$2,IF(搜索词报告!$A$2:$A$22222<=$L$4,搜索词报告!$Q$2:$Q$22222,0),0),0))} -> 0 | R16: {=SUM(IF(搜索词报告!$H$2:$H$22222=L16,IF(搜索词报告!$A$2:$A$22222>=$L$2,IF(搜索词报告!$A$2:$A$22222<=$L$4,搜索词报告!$N$2:$N$22222,0),0),0))} -> 0 | S16: {=SUM(IF(搜索词报告!$H$2:$H$22222=L16,IF(搜索词报告!$A$2:$A$22222>=$L$2,IF(搜索词报告!$A$2:$A$22222<=$L$4,搜索词报告!$M$2:$M$22222,0),0),0))} -> 0 | T16: =IF(IFERROR(S16/R16,0)=0,"",IFERROR(S16/R16,0)) | U16: =IF(AND(N16>=10,P16<=0.05),"极差",IF(AND(N16>=10,0.05<P16,P16<=0.1),"差",IF(AND(N16>=10,0.1<P16,P16<=0.15),"良",IF(AND(N16>=10,P16>0.15),"优","点击次数少于10次没有参考性")))) -> 点击次数少于10次没有参考性 | V16: =IFERROR(INDEX(搜索词报告!$D$2:$D$22222,MATCH(关键词词频统计!L16,搜索词报告!$H$2:$H$22222,0)),"")
B17: {=SUM(IF(搜索词报告!$H$2:$H$22222=A17,IF(搜索词报告!$A$2:$A$22222>=关键词词频统计!$A$2,IF(搜索词报告!$A$2:$A$22222<=关键词词频统计!$A$4,搜索词报告!$I$2:$I$22222,0),0),0))} -> 0 | C17: {=SUM(IF(搜索词报告!$H$2:$H$22222=A17,IF(搜索词报告!$A$2:$A$22222>=关键词词频统计!$A$2,IF(搜索词报告!$A$2:$A$22222<=关键词词频统计!$A$4,搜索词报告!$J$2:$J$22222,0),0),0))} -> 0 | D17: =IFERROR(C17/B17,0) -> 0 | E17: =IFERROR(F17/C17,0) -> 0 | F17: {=SUM(IF(搜索词报告!$H$2:$H$22222=A17,IF(搜索词报告!$A$2:$A$22222>=关键词词频统计!$A$2,IF(搜索词报告!$A$2:$A$22222<=关键词词频统计!$A$4,搜索词报告!$Q$2:$Q$22222,0),0),0))} -> 0 | G17: {=SUM(IF(搜索词报告!$H$2:$H$22222=A17,IF(搜索词报告!$A$2:$A$22222>=关键词词频统计!$A$2,IF(搜索词报告!$A$2:$A$22222<=关键词词频统计!$A$4,搜索词报告!$N$2:$N$22222,0),0),0))} -> 0 | H17: {=SUM(IF(搜索词报告!$H$2:$H$22222=A17,IF(搜索词报告!$A$2:$A$22222>=关键词词频统计!$A$2,IF(搜索词报告!$A$2:$A$22222<=关键词词频统计!$A$4,搜索词报告!$M$2:$M$22222,0),0),0))} -> 0 | I17: =IF(IFERROR(H17/G17,0)=0,"",IFERROR(H17/G17,0)) | J17: =IF(AND(C17>=10,E17<=0.05),"极差",IF(AND(C17>=10,0.05<E17,E17<=0.1),"差",IF(AND(C17>=10,0.1<E17,E17<=0.15),"良",IF(AND(C17>=10,E17>0.15),"优","点击次数少于10次没有参考性")))) -> 点击次数少于10次没有参考性 | K17: =IFERROR(INDEX(搜索词报告!$D$2:$D$22222,MATCH(关键词词频统计!A17,搜索词报告!$H$2:$H$22222,0)),"") | M17: {=SUM(IF(搜索词报告!$H$2:$H$22222=L17,IF(搜索词报告!$A$2:$A$22222>=$L$2,IF(搜索词报告!$A$2:$A$22222<=$L$4,搜索词报告!$I$2:$I$22222,0),0),0))} -> 0 | N17: {=SUM(IF(搜索词报告!$H$2:$H$22222=L17,IF(搜索词报告!$A$2:$A$22222>=$L$2,IF(搜索词报告!$A$2:$A$22222<=$L$4,搜索词报告!$J$2:$J$22222,0),0),0))} -> 0 | O17: =IFERROR(N17/M17,0) -> 0 | P17: =IFERROR(Q17/N17,0) -> 0 | Q17: {=SUM(IF(搜索词报告!$H$2:$H$22222=L17,IF(搜索词报告!$A$2:$A$22222>=$L$2,IF(搜索词报告!$A$2:$A$22222<=$L$4,搜索词报告!$Q$2:$Q$22222,0),0),0))} -> 0 | R17: {=SUM(IF(搜索词报告!$H$2:$H$22222=L17,IF(搜索词报告!$A$2:$A$22222>=$L$2,IF(搜索词报告!$A$2:$A$22222<=$L$4,搜索词报告!$N$2:$N$22222,0),0),0))} -> 0 | S17: {=SUM(IF(搜索词报告!$H$2:$H$22222=L17,IF(搜索词报告!$A$2:$A$22222>=$L$2,IF(搜索词报告!$A$2:$A$22222<=$L$4,搜索词报告!$M$2:$M$22222,0),0),0))} -> 0 | T17: =IF(IFERROR(S17/R17,0)=0,"",IFERROR(S17/R17,0)) | U17: =IF(AND(N17>=10,P17<=0.05),"极差",IF(AND(N17>=10,0.05<P17,P17<=0.1),"差",IF(AND(N17>=10,0.1<P17,P17<=0.15),"良",IF(AND(N17>=10,P17>0.15),"优","点击次数少于10次没有参考性")))) -> 点击次数少于10次没有参考性 | V17: =IFERROR(INDEX(搜索词报告!$D$2:$D$22222,MATCH(关键词词频统计!L17,搜索词报告!$H$2:$H$22222,0)),"")
B18: {=SUM(IF(搜索词报告!$H$2:$H$22222=A18,IF(搜索词报告!$A$2:$A$22222>=关键词词频统计!$A$2,IF(搜索词报告!$A$2:$A$22222<=关键词词频统计!$A$4,搜索词报告!$I$2:$I$22222,0),0),0))} -> 0 | C18: {=SUM(IF(搜索词报告!$H$2:$H$22222=A18,IF(搜索词报告!$A$2:$A$22222>=关键词词频统计!$A$2,IF(搜索词报告!$A$2:$A$22222<=关键词词频统计!$A$4,搜索词报告!$J$2:$J$22222,0),0),0))} -> 0 | D18: =IFERROR(C18/B18,0) -> 0 | E18: =IFERROR(F18/C18,0) -> 0 | F18: {=SUM(IF(搜索词报告!$H$2:$H$22222=A18,IF(搜索词报告!$A$2:$A$22222>=关键词词频统计!$A$2,IF(搜索词报告!$A$2:$A$22222<=关键词词频统计!$A$4,搜索词报告!$Q$2:$Q$22222,0),0),0))} -> 0 | G18: {=SUM(IF(搜索词报告!$H$2:$H$22222=A18,IF(搜索词报告!$A$2:$A$22222>=关键词词频统计!$A$2,IF(搜索词报告!$A$2:$A$22222<=关键词词频统计!$A$4,搜索词报告!$N$2:$N$22222,0),0),0))} -> 0 | H18: {=SUM(IF(搜索词报告!$H$2:$H$22222=A18,IF(搜索词报告!$A$2:$A$22222>=关键词词频统计!$A$2,IF(搜索词报告!$A$2:$A$22222<=关键词词频统计!$A$4,搜索词报告!$M$2:$M$22222,0),0),0))} -> 0 | I18: =IF(IFERROR(H18/G18,0)=0,"",IFERROR(H18/G18,0)) | J18: =IF(AND(C18>=10,E18<=0.05),"极差",IF(AND(C18>=10,0.05<E18,E18<=0.1),"差",IF(AND(C18>=10,0.1<E18,E18<=0.15),"良",IF(AND(C18>=10,E18>0.15),"优","点击次数少于10次没有参考性")))) -> 点击次数少于10次没有参考性 | K18: =IFERROR(INDEX(搜索词报告!$D$2:$D$22222,MATCH(关键词词频统计!A18,搜索词报告!$H$2:$H$22222,0)),"") | M18: {=SUM(IF(搜索词报告!$H$2:$H$22222=L18,IF(搜索词报告!$A$2:$A$22222>=$L$2,IF(搜索词报告!$A$2:$A$22222<=$L$4,搜索词报告!$I$2:$I$22222,0),0),0))} -> 0 | N18: {=SUM(IF(搜索词报告!$H$2:$H$22222=L18,IF(搜索词报告!$A$2:$A$22222>=$L$2,IF(搜索词报告!$A$2:$A$22222<=$L$4,搜索词报告!$J$2:$J$22222,0),0),0))} -> 0 | O18: =IFERROR(N18/M18,0) -> 0 | P18: =IFERROR(Q18/N18,0) -> 0 | Q18: {=SUM(IF(搜索词报告!$H$2:$H$22222=L18,IF(搜索词报告!$A$2:$A$22222>=$L$2,IF(搜索词报告!$A$2:$A$22222<=$L$4,搜索词报告!$Q$2:$Q$22222,0),0),0))} -> 0 | R18: {=SUM(IF(搜索词报告!$H$2:$H$22222=L18,IF(搜索词报告!$A$2:$A$22222>=$L$2,IF(搜索词报告!$A$2:$A$22222<=$L$4,搜索词报告!$N$2:$N$22222,0),0),0))} -> 0 | S18: {=SUM(IF(搜索词报告!$H$2:$H$22222=L18,IF(搜索词报告!$A$2:$A$22222>=$L$2,IF(搜索词报告!$A$2:$A$22222<=$L$4,搜索词报告!$M$2:$M$22222,0),0),0))} -> 0 | T18: =IF(IFERROR(S18/R18,0)=0,"",IFERROR(S18/R18,0)) | U18: =IF(AND(N18>=10,P18<=0.05),"极差",IF(AND(N18>=10,0.05<P18,P18<=0.1),"差",IF(AND(N18>=10,0.1<P18,P18<=0.15),"良",IF(AND(N18>=10,P18>0.15),"优","点击次数少于10次没有参考性")))) -> 点击次数少于10次没有参考性 | V18: =IFERROR(INDEX(搜索词报告!$D$2:$D$22222,MATCH(关键词词频统计!L18,搜索词报告!$H$2:$H$22222,0)),"")
B19: {=SUM(IF(搜索词报告!$H$2:$H$22222=A19,IF(搜索词报告!$A$2:$A$22222>=关键词词频统计!$A$2,IF(搜索词报告!$A$2:$A$22222<=关键词词频统计!$A$4,搜索词报告!$I$2:$I$22222,0),0),0))} -> 0 | C19: {=SUM(IF(搜索词报告!$H$2:$H$22222=A19,IF(搜索词报告!$A$2:$A$22222>=关键词词频统计!$A$2,IF(搜索词报告!$A$2:$A$22222<=关键词词频统计!$A$4,搜索词报告!$J$2:$J$22222,0),0),0))} -> 0 | D19: =IFERROR(C19/B19,0) -> 0 | E19: =IFERROR(F19/C19,0) -> 0 | F19: {=SUM(IF(搜索词报告!$H$2:$H$22222=A19,IF(搜索词报告!$A$2:$A$22222>=关键词词频统计!$A$2,IF(搜索词报告!$A$2:$A$22222<=关键词词频统计!$A$4,搜索词报告!$Q$2:$Q$22222,0),0),0))} -> 0 | G19: {=SUM(IF(搜索词报告!$H$2:$H$22222=A19,IF(搜索词报告!$A$2:$A$22222>=关键词词频统计!$A$2,IF(搜索词报告!$A$2:$A$22222<=关键词词频统计!$A$4,搜索词报告!$N$2:$N$22222,0),0),0))} -> 0 | H19: {=SUM(IF(搜索词报告!$H$2:$H$22222=A19,IF(搜索词报告!$A$2:$A$22222>=关键词词频统计!$A$2,IF(搜索词报告!$A$2:$A$22222<=关键词词频统计!$A$4,搜索词报告!$M$2:$M$22222,0),0),0))} -> 0 | I19: =IF(IFERROR(H19/G19,0)=0,"",IFERROR(H19/G19,0)) | J19: =IF(AND(C19>=10,E19<=0.05),"极差",IF(AND(C19>=10,0.05<E19,E19<=0.1),"差",IF(AND(C19>=10,0.1<E19,E19<=0.15),"良",IF(AND(C19>=10,E19>0.15),"优","点击次数少于10次没有参考性")))) -> 点击次数少于10次没有参考性 | K19: =IFERROR(INDEX(搜索词报告!$D$2:$D$22222,MATCH(关键词词频统计!A19,搜索词报告!$H$2:$H$22222,0)),"") | M19: {=SUM(IF(搜索词报告!$H$2:$H$22222=L19,IF(搜索词报告!$A$2:$A$22222>=$L$2,IF(搜索词报告!$A$2:$A$22222<=$L$4,搜索词报告!$I$2:$I$22222,0),0),0))} -> 0 | N19: {=SUM(IF(搜索词报告!$H$2:$H$22222=L19,IF(搜索词报告!$A$2:$A$22222>=$L$2,IF(搜索词报告!$A$2:$A$22222<=$L$4,搜索词报告!$J$2:$J$22222,0),0),0))} -> 0 | O19: =IFERROR(N19/M19,0) -> 0 | P19: =IFERROR(Q19/N19,0) -> 0 | Q19: {=SUM(IF(搜索词报告!$H$2:$H$22222=L19,IF(搜索词报告!$A$2:$A$22222>=$L$2,IF(搜索词报告!$A$2:$A$22222<=$L$4,搜索词报告!$Q$2:$Q$22222,0),0),0))} -> 0 | R19: {=SUM(IF(搜索词报告!$H$2:$H$22222=L19,IF(搜索词报告!$A$2:$A$22222>=$L$2,IF(搜索词报告!$A$2:$A$22222<=$L$4,搜索词报告!$N$2:$N$22222,0),0),0))} -> 0 | S19: {=SUM(IF(搜索词报告!$H$2:$H$22222=L19,IF(搜索词报告!$A$2:$A$22222>=$L$2,IF(搜索词报告!$A$2:$A$22222<=$L$4,搜索词报告!$M$2:$M$22222,0),0),0))} -> 0 | T19: =IF(IFERROR(S19/R19,0)=0,"",IFERROR(S19/R19,0)) | U19: =IF(AND(N19>=10,P19<=0.05),"极差",IF(AND(N19>=10,0.05<P19,P19<=0.1),"差",IF(AND(N19>=10,0.1<P19,P19<=0.15),"良",IF(AND(N19>=10,P19>0.15),"优","点击次数少于10次没有参考性")))) -> 点击次数少于10次没有参考性 | V19: =IFERROR(INDEX(搜索词报告!$D$2:$D$22222,MATCH(关键词词频统计!L19,搜索词报告!$H$2:$H$22222,0)),"")
B20: {=SUM(IF(搜索词报告!$H$2:$H$22222=A20,IF(搜索词报告!$A$2:$A$22222>=关键词词频统计!$A$2,IF(搜索词报告!$A$2:$A$22222<=关键词词频统计!$A$4,搜索词报告!$I$2:$I$22222,0),0),0))} -> 0 | C20: {=SUM(IF(搜索词报告!$H$2:$H$22222=A20,IF(搜索词报告!$A$2:$A$22222>=关键词词频统计!$A$2,IF(搜索词报告!$A$2:$A$22222<=关键词词频统计!$A$4,搜索词报告!$J$2:$J$22222,0),0),0))} -> 0 | D20: =IFERROR(C20/B20,0) -> 0 | E20: =IFERROR(F20/C20,0) -> 0 | F20: {=SUM(IF(搜索词报告!$H$2:$H$22222=A20,IF(搜索词报告!$A$2:$A$22222>=关键词词频统计!$A$2,IF(搜索词报告!$A$2:$A$22222<=关键词词频统计!$A$4,搜索词报告!$Q$2:$Q$22222,0),0),0))} -> 0 | G20: {=SUM(IF(搜索词报告!$H$2:$H$22222=A20,IF(搜索词报告!$A$2:$A$22222>=关键词词频统计!$A$2,IF(搜索词报告!$A$2:$A$22222<=关键词词频统计!$A$4,搜索词报告!$N$2:$N$22222,0),0),0))} -> 0 | H20: {=SUM(IF(搜索词报告!$H$2:$H$22222=A20,IF(搜索词报告!$A$2:$A$22222>=关键词词频统计!$A$2,IF(搜索词报告!$A$2:$A$22222<=关键词词频统计!$A$4,搜索词报告!$M$2:$M$22222,0),0),0))} -> 0 | I20: =IF(IFERROR(H20/G20,0)=0,"",IFERROR(H20/G20,0)) | J20: =IF(AND(C20>=10,E20<=0.05),"极差",IF(AND(C20>=10,0.05<E20,E20<=0.1),"差",IF(AND(C20>=10,0.1<E20,E20<=0.15),"良",IF(AND(C20>=10,E20>0.15),"优","点击次数少于10次没有参考性")))) -> 点击次数少于10次没有参考性 | K20: =IFERROR(INDEX(搜索词报告!$D$2:$D$22222,MATCH(关键词词频统计!A20,搜索词报告!$H$2:$H$22222,0)),"") | M20: {=SUM(IF(搜索词报告!$H$2:$H$22222=L20,IF(搜索词报告!$A$2:$A$22222>=$L$2,IF(搜索词报告!$A$2:$A$22222<=$L$4,搜索词报告!$I$2:$I$22222,0),0),0))} -> 0 | N20: {=SUM(IF(搜索词报告!$H$2:$H$22222=L20,IF(搜索词报告!$A$2:$A$22222>=$L$2,IF(搜索词报告!$A$2:$A$22222<=$L$4,搜索词报告!$J$2:$J$22222,0),0),0))} -> 0 | O20: =IFERROR(N20/M20,0) -> 0 | P20: =IFERROR(Q20/N20,0) -> 0 | Q20: {=SUM(IF(搜索词报告!$H$2:$H$22222=L20,IF(搜索词报告!$A$2:$A$22222>=$L$2,IF(搜索词报告!$A$2:$A$22222<=$L$4,搜索词报告!$Q$2:$Q$22222,0),0),0))} -> 0 | R20: {=SUM(IF(搜索词报告!$H$2:$H$22222=L20,IF(搜索词报告!$A$2:$A$22222>=$L$2,IF(搜索词报告!$A$2:$A$22222<=$L$4,搜索词报告!$N$2:$N$22222,0),0),0))} -> 0 | S20: {=SUM(IF(搜索词报告!$H$2:$H$22222=L20,IF(搜索词报告!$A$2:$A$22222>=$L$2,IF(搜索词报告!$A$2:$A$22222<=$L$4,搜索词报告!$M$2:$M$22222,0),0),0))} -> 0 | T20: =IF(IFERROR(S20/R20,0)=0,"",IFERROR(S20/R20,0)) | U20: =IF(AND(N20>=10,P20<=0.05),"极差",IF(AND(N20>=10,0.05<P20,P20<=0.1),"差",IF(AND(N20>=10,0.1<P20,P20<=0.15),"良",IF(AND(N20>=10,P20>0.15),"优","点击次数少于10次没有参考性")))) -> 点击次数少于10次没有参考性 | V20: =IFERROR(INDEX(搜索词报告!$D$2:$D$22222,MATCH(关键词词频统计!L20,搜索词报告!$H$2:$H$22222,0)),"")
B21: {=SUM(IF(搜索词报告!$H$2:$H$22222=A21,IF(搜索词报告!$A$2:$A$22222>=关键词词频统计!$A$2,IF(搜索词报告!$A$2:$A$22222<=关键词词频统计!$A$4,搜索词报告!$I$2:$I$22222,0),0),0))} -> 0 | C21: {=SUM(IF(搜索词报告!$H$2:$H$22222=A21,IF(搜索词报告!$A$2:$A$22222>=关键词词频统计!$A$2,IF(搜索词报告!$A$2:$A$22222<=关键词词频统计!$A$4,搜索词报告!$J$2:$J$22222,0),0),0))} -> 0 | D21: =IFERROR(C21/B21,0) -> 0 | E21: =IFERROR(F21/C21,0) -> 0 | F21: {=SUM(IF(搜索词报告!$H$2:$H$22222=A21,IF(搜索词报告!$A$2:$A$22222>=关键词词频统计!$A$2,IF(搜索词报告!$A$2:$A$22222<=关键词词频统计!$A$4,搜索词报告!$Q$2:$Q$22222,0),0),0))} -> 0 | G21: {=SUM(IF(搜索词报告!$H$2:$H$22222=A21,IF(搜索词报告!$A$2:$A$22222>=关键词词频统计!$A$2,IF(搜索词报告!$A$2:$A$22222<=关键词词频统计!$A$4,搜索词报告!$N$2:$N$22222,0),0),0))} -> 0 | H21: {=SUM(IF(搜索词报告!$H$2:$H$22222=A21,IF(搜索词报告!$A$2:$A$22222>=关键词词频统计!$A$2,IF(搜索词报告!$A$2:$A$22222<=关键词词频统计!$A$4,搜索词报告!$M$2:$M$22222,0),0),0))} -> 0 | I21: =IF(IFERROR(H21/G21,0)=0,"",IFERROR(H21/G21,0)) | J21: =IF(AND(C21>=10,E21<=0.05),"极差",IF(AND(C21>=10,0.05<E21,E21<=0.1),"差",IF(AND(C21>=10,0.1<E21,E21<=0.15),"良",IF(AND(C21>=10,E21>0.15),"优","点击次数少于10次没有参考性")))) -> 点击次数少于10次没有参考性 | K21: =IFERROR(INDEX(搜索词报告!$D$2:$D$22222,MATCH(关键词词频统计!A21,搜索词报告!$H$2:$H$22222,0)),"") | M21: {=SUM(IF(搜索词报告!$H$2:$H$22222=L21,IF(搜索词报告!$A$2:$A$22222>=$L$2,IF(搜索词报告!$A$2:$A$22222<=$L$4,搜索词报告!$I$2:$I$22222,0),0),0))} -> 0 | N21: {=SUM(IF(搜索词报告!$H$2:$H$22222=L21,IF(搜索词报告!$A$2:$A$22222>=$L$2,IF(搜索词报告!$A$2:$A$22222<=$L$4,搜索词报告!$J$2:$J$22222,0),0),0))} -> 0 | O21: =IFERROR(N21/M21,0) -> 0 | P21: =IFERROR(Q21/N21,0) -> 0 | Q21: {=SUM(IF(搜索词报告!$H$2:$H$22222=L21,IF(搜索词报告!$A$2:$A$22222>=$L$2,IF(搜索词报告!$A$2:$A$22222<=$L$4,搜索词报告!$Q$2:$Q$22222,0),0),0))} -> 0 | R21: {=SUM(IF(搜索词报告!$H$2:$H$22222=L21,IF(搜索词报告!$A$2:$A$22222>=$L$2,IF(搜索词报告!$A$2:$A$22222<=$L$4,搜索词报告!$N$2:$N$22222,0),0),0))} -> 0 | S21: {=SUM(IF(搜索词报告!$H$2:$H$22222=L21,IF(搜索词报告!$A$2:$A$22222>=$L$2,IF(搜索词报告!$A$2:$A$22222<=$L$4,搜索词报告!$M$2:$M$22222,0),0),0))} -> 0 | T21: =IF(IFERROR(S21/R21,0)=0,"",IFERROR(S21/R21,0)) | U21: =IF(AND(N21>=10,P21<=0.05),"极差",IF(AND(N21>=10,0.05<P21,P21<=0.1),"差",IF(AND(N21>=10,0.1<P21,P21<=0.15),"良",IF(AND(N21>=10,P21>0.15),"优","点击次数少于10次没有参考性")))) -> 点击次数少于10次没有参考性 | V21: =IFERROR(INDEX(搜索词报告!$D$2:$D$22222,MATCH(关键词词频统计!L21,搜索词报告!$H$2:$H$22222,0)),"")
B22: {=SUM(IF(搜索词报告!$H$2:$H$22222=A22,IF(搜索词报告!$A$2:$A$22222>=关键词词频统计!$A$2,IF(搜索词报告!$A$2:$A$22222<=关键词词频统计!$A$4,搜索词报告!$I$2:$I$22222,0),0),0))} -> 0 | C22: {=SUM(IF(搜索词报告!$H$2:$H$22222=A22,IF(搜索词报告!$A$2:$A$22222>=关键词词频统计!$A$2,IF(搜索词报告!$A$2:$A$22222<=关键词词频统计!$A$4,搜索词报告!$J$2:$J$22222,0),0),0))} -> 0 | D22: =IFERROR(C22/B22,0) -> 0 | E22: =IFERROR(F22/C22,0) -> 0 | F22: {=SUM(IF(搜索词报告!$H$2:$H$22222=A22,IF(搜索词报告!$A$2:$A$22222>=关键词词频统计!$A$2,IF(搜索词报告!$A$2:$A$22222<=关键词词频统计!$A$4,搜索词报告!$Q$2:$Q$22222,0),0),0))} -> 0 | G22: {=SUM(IF(搜索词报告!$H$2:$H$22222=A22,IF(搜索词报告!$A$2:$A$22222>=关键词词频统计!$A$2,IF(搜索词报告!$A$2:$A$22222<=关键词词频统计!$A$4,搜索词报告!$N$2:$N$22222,0),0),0))} -> 0 | H22: {=SUM(IF(搜索词报告!$H$2:$H$22222=A22,IF(搜索词报告!$A$2:$A$22222>=关键词词频统计!$A$2,IF(搜索词报告!$A$2:$A$22222<=关键词词频统计!$A$4,搜索词报告!$M$2:$M$22222,0),0),0))} -> 0 | I22: =IF(IFERROR(H22/G22,0)=0,"",IFERROR(H22/G22,0)) | J22: =IF(AND(C22>=10,E22<=0.05),"极差",IF(AND(C22>=10,0.05<E22,E22<=0.1),"差",IF(AND(C22>=10,0.1<E22,E22<=0.15),"良",IF(AND(C22>=10,E22>0.15),"优","点击次数少于10次没有参考性")))) -> 点击次数少于10次没有参考性 | K22: =IFERROR(INDEX(搜索词报告!$D$2:$D$22222,MATCH(关键词词频统计!A22,搜索词报告!$H$2:$H$22222,0)),"") | M22: {=SUM(IF(搜索词报告!$H$2:$H$22222=L22,IF(搜索词报告!$A$2:$A$22222>=$L$2,IF(搜索词报告!$A$2:$A$22222<=$L$4,搜索词报告!$I$2:$I$22222,0),0),0))} -> 0 | N22: {=SUM(IF(搜索词报告!$H$2:$H$22222=L22,IF(搜索词报告!$A$2:$A$22222>=$L$2,IF(搜索词报告!$A$2:$A$22222<=$L$4,搜索词报告!$J$2:$J$22222,0),0),0))} -> 0 | O22: =IFERROR(N22/M22,0) -> 0 | P22: =IFERROR(Q22/N22,0) -> 0 | Q22: {=SUM(IF(搜索词报告!$H$2:$H$22222=L22,IF(搜索词报告!$A$2:$A$22222>=$L$2,IF(搜索词报告!$A$2:$A$22222<=$L$4,搜索词报告!$Q$2:$Q$22222,0),0),0))} -> 0 | R22: {=SUM(IF(搜索词报告!$H$2:$H$22222=L22,IF(搜索词报告!$A$2:$A$22222>=$L$2,IF(搜索词报告!$A$2:$A$22222<=$L$4,搜索词报告!$N$2:$N$22222,0),0),0))} -> 0 | S22: {=SUM(IF(搜索词报告!$H$2:$H$22222=L22,IF(搜索词报告!$A$2:$A$22222>=$L$2,IF(搜索词报告!$A$2:$A$22222<=$L$4,搜索词报告!$M$2:$M$22222,0),0),0))} -> 0 | T22: =IF(IFERROR(S22/R22,0)=0,"",IFERROR(S22/R22,0)) | U22: =IF(AND(N22>=10,P22<=0.05),"极差",IF(AND(N22>=10,0.05<P22,P22<=0.1),"差",IF(AND(N22>=10,0.1<P22,P22<=0.15),"良",IF(AND(N22>=10,P22>0.15),"优","点击次数少于10次没有参考性")))) -> 点击次数少于10次没有参考性 | V22: =IFERROR(INDEX(搜索词报告!$D$2:$D$22222,MATCH(关键词词频统计!L22,搜索词报告!$H$2:$H$22222,0)),"")
B23: {=SUM(IF(搜索词报告!$H$2:$H$22222=A23,IF(搜索词报告!$A$2:$A$22222>=关键词词频统计!$A$2,IF(搜索词报告!$A$2:$A$22222<=关键词词频统计!$A$4,搜索词报告!$I$2:$I$22222,0),0),0))} -> 0 | C23: {=SUM(IF(搜索词报告!$H$2:$H$22222=A23,IF(搜索词报告!$A$2:$A$22222>=关键词词频统计!$A$2,IF(搜索词报告!$A$2:$A$22222<=关键词词频统计!$A$4,搜索词报告!$J$2:$J$22222,0),0),0))} -> 0 | D23: =IFERROR(C23/B23,0) -> 0 | E23: =IFERROR(F23/C23,0) -> 0 | F23: {=SUM(IF(搜索词报告!$H$2:$H$22222=A23,IF(搜索词报告!$A$2:$A$22222>=关键词词频统计!$A$2,IF(搜索词报告!$A$2:$A$22222<=关键词词频统计!$A$4,搜索词报告!$Q$2:$Q$22222,0),0),0))} -> 0 | G23: {=SUM(IF(搜索词报告!$H$2:$H$22222=A23,IF(搜索词报告!$A$2:$A$22222>=关键词词频统计!$A$2,IF(搜索词报告!$A$2:$A$22222<=关键词词频统计!$A$4,搜索词报告!$N$2:$N$22222,0),0),0))} -> 0 | H23: {=SUM(IF(搜索词报告!$H$2:$H$22222=A23,IF(搜索词报告!$A$2:$A$22222>=关键词词频统计!$A$2,IF(搜索词报告!$A$2:$A$22222<=关键词词频统计!$A$4,搜索词报告!$M$2:$M$22222,0),0),0))} -> 0 | I23: =IF(IFERROR(H23/G23,0)=0,"",IFERROR(H23/G23,0)) | J23: =IF(AND(C23>=10,E23<=0.05),"极差",IF(AND(C23>=10,0.05<E23,E23<=0.1),"差",IF(AND(C23>=10,0.1<E23,E23<=0.15),"良",IF(AND(C23>=10,E23>0.15),"优","点击次数少于10次没有参考性")))) -> 点击次数少于10次没有参考性 | K23: =IFERROR(INDEX(搜索词报告!$D$2:$D$22222,MATCH(关键词词频统计!A23,搜索词报告!$H$2:$H$22222,0)),"") | M23: {=SUM(IF(搜索词报告!$H$2:$H$22222=L23,IF(搜索词报告!$A$2:$A$22222>=$L$2,IF(搜索词报告!$A$2:$A$22222<=$L$4,搜索词报告!$I$2:$I$22222,0),0),0))} -> 0 | N23: {=SUM(IF(搜索词报告!$H$2:$H$22222=L23,IF(搜索词报告!$A$2:$A$22222>=$L$2,IF(搜索词报告!$A$2:$A$22222<=$L$4,搜索词报告!$J$2:$J$22222,0),0),0))} -> 0 | O23: =IFERROR(N23/M23,0) -> 0 | P23: =IFERROR(Q23/N23,0) -> 0 | Q23: {=SUM(IF(搜索词报告!$H$2:$H$22222=L23,IF(搜索词报告!$A$2:$A$22222>=$L$2,IF(搜索词报告!$A$2:$A$22222<=$L$4,搜索词报告!$Q$2:$Q$22222,0),0),0))} -> 0 | R23: {=SUM(IF(搜索词报告!$H$2:$H$22222=L23,IF(搜索词报告!$A$2:$A$22222>=$L$2,IF(搜索词报告!$A$2:$A$22222<=$L$4,搜索词报告!$N$2:$N$22222,0),0),0))} -> 0 | S23: {=SUM(IF(搜索词报告!$H$2:$H$22222=L23,IF(搜索词报告!$A$2:$A$22222>=$L$2,IF(搜索词报告!$A$2:$A$22222<=$L$4,搜索词报告!$M$2:$M$22222,0),0),0))} -> 0 | T23: =IF(IFERROR(S23/R23,0)=0,"",IFERROR(S23/R23,0)) | U23: =IF(AND(N23>=10,P23<=0.05),"极差",IF(AND(N23>=10,0.05<P23,P23<=0.1),"差",IF(AND(N23>=10,0.1<P23,P23<=0.15),"良",IF(AND(N23>=10,P23>0.15),"优","点击次数少于10次没有参考性")))) -> 点击次数少于10次没有参考性 | V23: =IFERROR(INDEX(搜索词报告!$D$2:$D$22222,MATCH(关键词词频统计!L23,搜索词报告!$H$2:$H$22222,0)),"")
B24: {=SUM(IF(搜索词报告!$H$2:$H$22222=A24,IF(搜索词报告!$A$2:$A$22222>=关键词词频统计!$A$2,IF(搜索词报告!$A$2:$A$22222<=关键词词频统计!$A$4,搜索词报告!$I$2:$I$22222,0),0),0))} -> 0 | C24: {=SUM(IF(搜索词报告!$H$2:$H$22222=A24,IF(搜索词报告!$A$2:$A$22222>=关键词词频统计!$A$2,IF(搜索词报告!$A$2:$A$22222<=关键词词频统计!$A$4,搜索词报告!$J$2:$J$22222,0),0),0))} -> 0 | D24: =IFERROR(C24/B24,0) -> 0 | E24: =IFERROR(F24/C24,0) -> 0 | F24: {=SUM(IF(搜索词报告!$H$2:$H$22222=A24,IF(搜索词报告!$A$2:$A$22222>=关键词词频统计!$A$2,IF(搜索词报告!$A$2:$A$22222<=关键词词频统计!$A$4,搜索词报告!$Q$2:$Q$22222,0),0),0))} -> 0 | G24: {=SUM(IF(搜索词报告!$H$2:$H$22222=A24,IF(搜索词报告!$A$2:$A$22222>=关键词词频统计!$A$2,IF(搜索词报告!$A$2:$A$22222<=关键词词频统计!$A$4,搜索词报告!$N$2:$N$22222,0),0),0))} -> 0 | H24: {=SUM(IF(搜索词报告!$H$2:$H$22222=A24,IF(搜索词报告!$A$2:$A$22222>=关键词词频统计!$A$2,IF(搜索词报告!$A$2:$A$22222<=关键词词频统计!$A$4,搜索词报告!$M$2:$M$22222,0),0),0))} -> 0 | I24: =IF(IFERROR(H24/G24,0)=0,"",IFERROR(H24/G24,0)) | J24: =IF(AND(C24>=10,E24<=0.05),"极差",IF(AND(C24>=10,0.05<E24,E24<=0.1),"差",IF(AND(C24>=10,0.1<E24,E24<=0.15),"良",IF(AND(C24>=10,E24>0.15),"优","点击次数少于10次没有参考性")))) -> 点击次数少于10次没有参考性 | K24: =IFERROR(INDEX(搜索词报告!$D$2:$D$22222,MATCH(关键词词频统计!A24,搜索词报告!$H$2:$H$22222,0)),"") | M24: {=SUM(IF(搜索词报告!$H$2:$H$22222=L24,IF(搜索词报告!$A$2:$A$22222>=$L$2,IF(搜索词报告!$A$2:$A$22222<=$L$4,搜索词报告!$I$2:$I$22222,0),0),0))} -> 0 | N24: {=SUM(IF(搜索词报告!$H$2:$H$22222=L24,IF(搜索词报告!$A$2:$A$22222>=$L$2,IF(搜索词报告!$A$2:$A$22222<=$L$4,搜索词报告!$J$2:$J$22222,0),0),0))} -> 0 | O24: =IFERROR(N24/M24,0) -> 0 | P24: =IFERROR(Q24/N24,0) -> 0 | Q24: {=SUM(IF(搜索词报告!$H$2:$H$22222=L24,IF(搜索词报告!$A$2:$A$22222>=$L$2,IF(搜索词报告!$A$2:$A$22222<=$L$4,搜索词报告!$Q$2:$Q$22222,0),0),0))} -> 0 | R24: {=SUM(IF(搜索词报告!$H$2:$H$22222=L24,IF(搜索词报告!$A$2:$A$22222>=$L$2,IF(搜索词报告!$A$2:$A$22222<=$L$4,搜索词报告!$N$2:$N$22222,0),0),0))} -> 0 | S24: {=SUM(IF(搜索词报告!$H$2:$H$22222=L24,IF(搜索词报告!$A$2:$A$22222>=$L$2,IF(搜索词报告!$A$2:$A$22222<=$L$4,搜索词报告!$M$2:$M$22222,0),0),0))} -> 0 | T24: =IF(IFERROR(S24/R24,0)=0,"",IFERROR(S24/R24,0)) | U24: =IF(AND(N24>=10,P24<=0.05),"极差",IF(AND(N24>=10,0.05<P24,P24<=0.1),"差",IF(AND(N24>=10,0.1<P24,P24<=0.15),"良",IF(AND(N24>=10,P24>0.15),"优","点击次数少于10次没有参考性")))) -> 点击次数少于10次没有参考性 | V24: =IFERROR(INDEX(搜索词报告!$D$2:$D$22222,MATCH(关键词词频统计!L24,搜索词报告!$H$2:$H$22222,0)),"")
