Workbook

Sheet 1.1核心竞争对手调研
A1: 变体形式
A2: ASIN
A3: 品牌
A4: 图片
A5: 卖点提炼
A6: 销售价格
A7: 尺寸信息
A8: FBA配送费
A9: reviews星级
A10: reviews数量
A11: 类目
A12: review内容分析
... A14: 历史销售数据
A15: 产品总结 | B15: 1.尺寸对比-分析配送费，优化价格 2.对比五点，找出共同描述的点，找出自己产品的差异点 3.查看星级 -是否需要控评 4.review数量-预估上评数量 5.reviews布局- 图片review内容（室内or室外），文字review内容（尺寸，材质，颜色，款式，质量），是否中评卡位 6.对比售价，定位自家价格 7.对比排名情况，设定目标 8.关键词分析

Sheet 1.2 产品定价
A1: 产品采购信息
A2: 产品型号 | B2: 每箱毛重 | C2: 每箱体积 | D2: 每箱数量 | E2: 头程运费 | F2: 产品采购成本
A3: XXXX-111 | B3: 5 | C3: 1 | D3: 20 | E3: =C3*1500/D3 -> 75 | F3: 20
A4: XXXX-222 | B4: 5 | C4: 1 | D4: 20 | E4: =C4*1500/D4 -> 75 | F4: 20
A6: 产品信息 | E6: 亚马逊销售核算公式
A7: 货号/品名 | B7: 图片 | C7: 英文品名 | D7: 产品型号 Model No. | E7: 销售价格 | F7: 类目佣金 | G7: FBA配送费 | H7: 头程运费 | I7: 产品成本 | J7: 毛利润 | K7: 毛利润率
C8: XXXXX | D8: XXXX-111 | E8: 25 | F8: =E8*0.15 -> 3.75 | G8: 4.75 | H8: =E3/6.5 -> 11.538462 | I8: =F3/6.5 -> 3.0769231 | J8: =E8-F8-G8-H8-I8 -> 1.8846154 | K8: =J8/E8 -> 0.075384615
C9: XXXXX | D9: XXXX-222 | E9: 25 | F9: =E9*0.15 -> 3.75 | G9: 4.75 | H9: =E4/6.5 -> 11.538462 | I9: =F4/6.5 -> 3.0769231 | J9: =E9-F9-G9-H9-I9 -> 1.8846154 | K9: =J9/E9 -> 0.075384615

Sheet 2.1 销售和库存规划
A1: 图片 | B1: 产品型号 | H1: 退货 | I1: 0.05 | J1: 25 | K1: =J1*('1.2 产品定价'!I8+'1.2 产品定价'!H8+'1.2 产品定价'!G8*0.15) -> 383.19712
B2: XXXX-111 | H2: 广告 | I2: 30 | J2: 30天 | K2: 900
B3: 1000 | H3: 仓储成本 | I3: 30天 | J3: 500个 | K3: =(1000/'1.2 产品定价'!D4*'1.2 产品定价'!C4)*35*0.83 -> 1452.5
A4: 日期 | B4: 每日销量目标 | C4: 目标剩余库存 | D4: 实际每日销量 | E4: 实际剩余库存 | F4: 实际售价 | G4: 单个利润 | H4: 利润 | I4: 实际广告成本 | J4: 每日销量完成率 | K4: 实际利润
A5: 2022.8.23 | B5: 1 | C5: =B3-B5 -> 999 | D5: 2 | E5: =B3-D5 -> 998 | F5: 13.99 | G5: 3.528 | H5: =G5*D5 -> 7.056 | I5: 20.95 | J5: =D5/B5 -> 2 | K5: =H5-I5 -> -13.894
A6: 2022.8.24 | B6: 1 | C6: =C5-B6 -> 998 | D6: 1 | E6: =E5-D6 -> 997 | F6: 13.99 | G6: 3.528 | H6: =G6*D6 -> 3.528 | I6: 18.32 | J6: =D6/B6 -> 1 | K6: =H6-I6 -> -14.792
A7: 2022.8.25 | B7: 1 | C7: =C6-B7 -> 997 | D7: 0 | E7: =E6-D7 -> 997 | F7: 13.99 | G7: 3.528 | H7: =G7*D7 -> 0 | I7: 4.72 | J7: =D7/B7 -> 0 | K7: =H7-I7 -> -4.72
A8: 2022.8.26 | B8: 1 | C8: =C7-B8 -> 996 | D8: 1 | E8: =E7-D8 -> 996 | F8: 13.99 | G8: 3.528 | H8: =G8*D8 -> 3.528 | I8: 20.26 | J8: =D8/B8 -> 1 | K8: =H8-I8 -> -16.732
A9: 2022.8.27 | B9: 1 | C9: =C8-B9 -> 995 | D9: 3 | E9: =E8-D9 -> 993 | F9: 13.99 | G9: 3.528 | H9: =G9*D9 -> 10.584 | I9: 26 | J9: =D9/B9 -> 3 | K9: =H9-I9 -> -15.416
A10: 2022.8.28 | B10: 1 | C10: =C9-B10 -> 994 | D10: 3 | E10: =E9-D10 -> 990 | F10: 13.99 | G10: 3.528 | H10: =G10*D10 -> 10.584 | I10: 23.48 | J10: =D10/B10 -> 3 | K10: =H10-I10 -> -12.896
A11: 2022.8.29 | B11: 1 | C11: =C10-B11 -> 993 | D11: 9 | E11: =E10-D11 -> 981 | F11: 13.99 | G11: 3.528 | H11: =G11*D11 -> 31.752 | I11: 20.61 | J11: =D11/B11 -> 9 | K11: =H11-I11 -> 11.142
A12: 2022.8.30 | B12: 1 | C12: =C11-B12 -> 992 | D12: 5 | E12: =E11-D12 -> 976 | F12: 13.99 | G12: 3.528 | H12: =G12*D12 -> 17.64 | I12: 19.58 | J12: =D12/B12 -> 5 | K12: =H12-I12 -> -1.94
A13: 2022.8.31 | B13: 2 | C13: =C12-B13 -> 990 | D13: 9 | E13: =E12-D13 -> 967 | F13: 13.99 | G13: 3.528 | H13: =G13*D13 -> 31.752 | I13: 20.38 | J13: =D13/B13 -> 4.5 | K13: =H13-I13 -> 11.372
A14: 2022.9.1 | B14: 5 | C14: =C13-B14 -> 985 | D14: 4 | E14: =E13-D14 -> 963 | F14: 13.99 | G14: 3.528 | H14: =G14*D14 -> 14.112 | I14: 20.3 | J14: =D14/B14 -> 0.8 | K14: =H14-I14 -> -6.188
A15: 2022.9.2 | B15: 5 | C15: =C14-B15 -> 980 | D15: 9 | E15: =E14-D15 -> 954 | F15: 13.99 | G15: 3.528 | H15: =G15*D15 -> 31.752 | I15: 20.22 | J15: =D15/B15 -> 1.8 | K15: =H15-I15 -> 11.532
A16: 2022.9.3 | B16: 5 | C16: =C15-B16 -> 975 | D16: 9 | E16: =E15-D16 -> 945 | F16: 13.99 | G16: 3.528 | H16: =G16*D16 -> 31.752 | I16: 19.49 | J16: =D16/B16 -> 1.8 | K16: =H16-I16 -> 12.262
A17: 2022.9.4 | B17: 5 | C17: =C16-B17 -> 970 | D17: 8 | E17: =E16-D17 -> 937 | F17: 13.99 | G17: 3.528 | H17: =G17*D17 -> 28.224 | I17: 19.53 | J17: =D17/B17 -> 1.6 | K17: =H17-I17 -> 8.694
... A49: 2022.10.6 | B49: 25 | C49: =C48-B49 -> 500 | D49: 18 | E49: =E48-D49 -> 127 | F49: 21.99 | G49: 10.328 | H49: =G49*D49 -> 185.904 | I49: 0 | J49: =D49/B49 -> 0.72 | K49: =H49-I49 -> 185.904
A50: 2022.10.7 | B50: 25 | C50: =C49-B50 -> 475
A51: 2022.10.8 | B51: 25 | C51: =C50-B51 -> 450
A52: 2022.10.9 | B52: 25 | C52: =C51-B52 -> 425
A53: 2022.10.10 | B53: 25 | C53: =C52-B53 -> 400
A54: 2022.10.11 | B54: 25 | C54: =C53-B54 -> 375
A55: 2022.10.12 | B55: 30 | C55: =C54-B55 -> 345
A56: 2022.10.13 | B56: 30 | C56: =C55-B56 -> 315
A57: 2022.10.14 | B57: 30 | C57: =C56-B57 -> 285
A58: 2022.10.15 | B58: 30 | C58: =C57-B58 -> 255
A59: 2022.10.16 | B59: 30 | C59: =C58-B59 -> 225
A60: 2022.10.17 | B60: 30 | C60: =C59-B60 -> 195
A61: 2022.10.18 | B61: 30 | C61: =C60-B61 -> 165
... A74: 2022.10.31 | B74: 5 | C74: =C73-B74 -> 0

Sheet 2.2 运营策略
A1: 变体合并策略 | C1: 执行细节及实际情况 | D1: 整体推广策略 | F1: 使用指南
A2: XXXX-111和XXXX-222合并 使用颜色进行合并 XXXXX等细节 | C2: 记录情况:8.18号 变体合并成功 | D2: 1、XXXX-111和XXXX-222 先开自动广告测款定主推款 3、推广节奏 第一阶段：Listing校验----自动广告 第二阶段：变体策略验证， 提升关键词排序---手动广告， 站外 第三阶段：提升订单量和关键词排序 | F2: 1、根据实际运营情况，每周对整体推广策略进行调整 2、基于上周运营表现，对下一周的核心目标、运营措施等进行更新调整并执行 3、记录运营数据到板块3
A3: 主推款运营框架 | C3: 执行细节及实际情况 | D3: 次推款运营框架 | F3: 执行细节及实际情况
A4: 【时间节点】 | B4: 第一阶段：9月第一周 | D4: 【时间节点】 | E4: 第一阶段：9月第一周
A5: 【核心目标】 | B5: 1.校正Listing的准确性， 完成LISTING基础收录，积累基础权重 2. 测词， 测款 | C5: 【执行细节】 1. 8.23号， 开自动广告， 预算$20， Bid $1.2 【核心指标情况】 1. 预算$20 能花完，展示量正常，整体点击率0.17%，偏低， 每日访客数在30-40，呈递增趋势，转化率7.88%正常 2. 广告展示量主要在商品页面， 预算花费在商品页面最多， 结合投放来看， 花费主要分布在紧密匹配和宽泛匹配， 说明目前市场上的竞品还不多 3. 从用户搜索词看， 目前主要也是跑的关键词，ASIN少。 关键词与我们Listing定位的关键词非常匹配， 主要是XXXXXXXXXXXX等相关词 ，与我们Listing的定位一致 4. 虽然看不到广告展示位， 但是关键词自然排序位置靠前， 可以继续按照现在的自动广告跑。 【遇到问题及后续计划】 问题： 1. 进一步提升关键词自然排序和订单量 2. 预算花费很分散， 现在没有特别热销的ASIN 计划： 1. 预算增加到$30 2. 自动广告中关掉同类商品和关联商品。 | D5: 【核心目标】 | E5: 1.校正Listing的准确性， 完成LISTING基础收录，积累基础权重 2. 测词， 测款 | F5: 【执行细节】 1. 8.23号， 开自动广告， 预算$20， Bid $1.2 【核心指标情况】 1. 预算$20能花完， 展示量偏低， 点击率正常， 转化率正常 2. 广告位来看， 广告主要展示在商品页面，预算主要花费在搜索结果其余位置， 从投放来看， 预算主要分配在紧密匹配和宽泛匹配， 说明现在竞品还不多。 3.看不到广告位 4. 用户搜索词： 主要是跑的一些跟xxxx相关的关键词，，与我们Listing的定位一致 5. 从关键词排序上看， XXXX-111主要在XXXXXX下有排序， 跟XXXX-222关键词排序形成互补， 所以目前XXXX-111和XXXX-222的自然广告都可以开。 【遇到问题及后续计划】 问题： 1. 进一步提升关键词自然排序和订单量 2. 预算花费很分散， 现在没有特别热销的ASIN，跑了很多长尾词 计划： 1. 预算增加到$30， Bid提高到$1.5 2. 自动广告中关掉同类商品和关联商品。
A6: 【本阶段运营措施】 | B6: 广告策略： 开自动广告 价格策略： 站外策略: | D6: 【本阶段运营措施】 | E6: 广告策略： 开自动广告 价格策略： 站外策略:
A7: 【重点跟进关注指标】 | B7: 1.Listing资料定位准确 2. 跑出的关键词与我们定位的关键词一致 3.广告曝光量正常 4. 关注核心关键词的排序， 广告位置展示 | D7: 【重点跟进关注指标】 | E7: 1.Listing资料定位准确 2. 跑出的关键词与我们定位的关键词一致 3.广告曝光量正常 4. 关注核心关键词的排序， 广告位置展示
A8: 【指标变动后的应对策略】 | B8: 1. 关键词排序提升， 订单量增长， 广告继续这也跑， 直到每日订单量20， 逐渐减少广告预算， 靠关键词自然位出单 2. 关键词排序和订单量没有增长， 那我们集中预算主要跑核心关键词，关闭同类商品和关联商品 | D8: 【指标变动后的应对策略】 | E8: 1. 关键词排序提升， 订单量增长， 广告继续这也跑， 直到每日订单量20， 逐渐减少广告预算， 靠关键词自然位出单 2. 关键词排序和订单量没有增长， 那我们集中预算主要跑核心关键词，关闭同类商品和关联商品
A9: 【时间节点】 | B9: 第二阶段：9月第二周 | D9: 【时间节点】 | E9: 第二阶段：9月第二周
A10: 【核心目标】 | B10: 提升关键词排序占据流量坑位 | C10: 【执行细节】 1. 9.7号 优化listing 【核心指标情况】 1. 订单量增长明显 2. 关键词XXXXXXXXXX P3， XXXXXXXX P1， 关键词位置提升明显 【遇到问题及后续计划】 问题： 1.出现了一个3星rating， 影响订单量 计划： 1. 与其他链接合并，解决评论的问题 | D10: 【核心目标】 | E10: 提升关键词排序占据流量坑位 | F10: 【执行细节】 1. 9.6号 关闭自动广告 2. 9.7号 优化listing 【核心指标情况】 1. 订单量增长明显， 关闭自动广告后 ， 订单量有下降 2. 关键词XXXXXXXX 排序在P3-P4， 变化不大 【遇到问题及后续计划】
A11: 【本阶段运营措施】 | B11: 1. 优化Listing标题， 资料文案， 让关键词跑出 XXXXXXXXXXXXX | D11: 【本阶段运营措施】 | E11: 1. 优化Listing标题， 资料文案， 让关键词跑出 XXXXXXXX 2. 关闭自动广告
A12: 【重点关注指标】 | B12: 1. 订单量的增长 2. 关键词排序的变化 | D12: 【重点关注指标】 | E12: 1. 订单量的增长 2. 关键词排序的变化
A13: 【指标变动后的应对策略】 | D13: 【指标变动后的应对策略】
A14: 【时间节点】 | B14: 第三阶段：9月第三周 | D14: 【时间节点】 | E14: 第三阶段：9月第三周
A15: 【核心目标】 | B15: 推动关键词排序进一步增长，抢占更靠前位置 | C15: 【执行细节】 9.13号 关闭自动广告 【核心指标情况】 1.订单量能够稳住， 并有增长 2. 关键词自然排序XXXXXXX 在P2， XXXXXXX在P1 能够稳住 3. 访客数也在增长 【遇到问题及后续计划】 计划： XXXX-111 涨价 | D15: 【核心目标】 | F15: 【执行细节】 【核心指标情况】 XXX 【遇到问题及后续计划】 XXX。
A16: 【本阶段运营措施】 | B16: 广告策略： 关闭自动广告， 靠自然出单 | D16: 【本阶段运营措施】
A17: 【重点关注指标】 | B17: 1. 订单量的变化 2. 关键词排序的变化 | D17: 【重点关注指标】
A18: 【指标变动后的应对策略】 | D18: 【指标变动后的应对策略】
A19: 【时间节点】 | B19: 第四阶段：9月第四周 | D19: 【时间节点】 | E19: 第四阶段：9月第四周
A20: 【核心目标】 | B20: 保证每日单量 整个链接40+， 提价做利润 | C20: 【执行细节】 9.17 号 XXXX-111 涨价 $13.99--$15.99 9.19号 XXXX-111 涨价 $15.99-$16.99 XXXX-222 涨价 $13.99-$14.99 【核心指标情况】 1.订单量能够稳住， 并有增长 2. 关键词自然排序XXXXXXXXX 在P2， XXXXXXXX在P1 能够稳住 3. 访客数也在增长 【遇到问题及后续计划】 | D20: 【核心目标】 | E20: 例：保持库存动销，避免库存积压 | F20: 【执行细节】 【核心指标情况】 XXX 【遇到问题及后续计划】 XXXX
A21: 【本阶段运营措施】 | B21: 价格策略：9.17 号 XXXX-111 涨价 $13.99--$15.99 9.19号 XXXX-111 涨价 $15.99-$16.99 XXXX-222 涨价 $13.99-$14.99 | D21: 【本阶段运营措施】
A22: 【重点关注指标】 | D22: 【重点关注指标】
A23: 【指标变动后的应对策略】 | D23: 【指标变动后的应对策略】
A25: 【时间节点】 | B25: 第五阶段：10月第一周 | D25: 【时间节点】 | E25: 第五阶段：10月第一周
A26: 【核心目标】 | B26: 例：保持每日XX销量，视情况提价释放利润 | C26: 【执行细节】 【核心指标情况】 【遇到问题及后续计划】 XXX | D26: 【核心目标】 | E26: 例：转化主推款流量，保持动销 | F26: 【执行细节】 【核心指标情况】 XXX 【遇到问题及后续计划】 XXX。
A27: 【本阶段运营措施】 | D27: 【本阶段运营措施】
A28: 【重点关注指标】 | D28: 【重点关注指标】
A29: 【指标变动后的应对策略】 | D29: 【指标变动后的应对策略】
A30: 【时间节点】 | B30: 第六阶段：10月第二周 | D30: 【时间节点】 | E30: 第六阶段：10月第二周
A31: 【核心目标】 | B31: 例：保持每日XX销量，视情况提价释放利润 | C31: 【执行细节】 【核心指标情况】 XXX 【遇到问题及后续计划】 XXX | D31: 【核心目标】 | E31: 例：保持库存动销，避免库存积压 | F31: 【执行细节】 【核心指标情况】 XXX 【遇到问题及后续计划】 XXXX
A32: 【本阶段运营措施】 | D32: 【本阶段运营措施】
A33: 【重点关注指标】 | D33: 【重点关注指标】
A34: 【指标变动后的应对策略】 | D34: 【指标变动后的应对策略】

Sheet  3.1 ASIN数据
A1: 分析指南 | B1: 1、关注数据重点：整个链接的整体数据规模到了什么程度？哪些指标需要重点分析？ 2、关注产品重点：主推款与次推款之间的数据占比如何？变体之间是否出现任何异常情况？ 3、关注工作重点：下阶段的工作重点是什么？如何帮助我们更好完成目标？后续需要重点关注哪些指标？
A2: 主推款SKU | B2: XXXX-111 | C2: ASIN | D2: ASIN1 | E2: 主图 | H2: 次推款SKU | I2: XXXX-222 | J2: ASIN | K2: ASIN2 | L2: 主图
A3: 日期 | B3: 销量 | C3: SESSION | D3: 销量转化率 | E3: 价格变动 | F3: 运营细节备注 | H3: 日期 | I3: 销量 | J3: 总SESSION | K3: 销量转化率 | L3: 运营细节备注
A4: 2022-08-23 | B4: =VLOOKUP($A4&$B$2,'4.2 产品详情原始数据'!$A:$BG,10,FALSE) -> 2 | C4: =VLOOKUP($A4&$B$2,'4.2 产品详情原始数据'!$A:$BG,37,FALSE) -> 29 | D4: =VLOOKUP($A4&$B$2,'4.2 产品详情原始数据'!$A:$BG,43,FALSE) -> 0.069 | E4: =VLOOKUP($A4&$B$2,'4.2 产品详情原始数据'!$A:$BG,7,FALSE) -> 13.99 | H4: 2022-08-23 | I4: =VLOOKUP(H4&$I$2,'4.2 产品详情原始数据'!$A:$BG,10,FALSE) -> 1 | J4: =VLOOKUP($H4&$I$2,'4.2 产品详情原始数据'!$A:$BG,37,FALSE) -> 25 | K4: =VLOOKUP($H4&$I$2,'4.2 产品详情原始数据'!$A:$BG,43,FALSE) -> 0.04
A5: 2022-08-24 | B5: =VLOOKUP($A5&$B$2,'4.2 产品详情原始数据'!$A:$BG,10,FALSE) -> 1 | C5: =VLOOKUP($A5&$B$2,'4.2 产品详情原始数据'!$A:$BG,37,FALSE) -> 25 | D5: =VLOOKUP($A5&$B$2,'4.2 产品详情原始数据'!$A:$BG,43,FALSE) -> 0.04 | E5: =VLOOKUP($A5&$B$2,'4.2 产品详情原始数据'!$A:$BG,7,FALSE) -> 13.99 | H5: 2022-08-24 | I5: =VLOOKUP(H5&$I$2,'4.2 产品详情原始数据'!$A:$BG,10,FALSE) -> 0 | J5: =VLOOKUP($H5&$I$2,'4.2 产品详情原始数据'!$A:$BG,37,FALSE) -> 16 | K5: =VLOOKUP($H5&$I$2,'4.2 产品详情原始数据'!$A:$BG,43,FALSE) -> 0
A6: 2022-08-25 | B6: =VLOOKUP($A6&$B$2,'4.2 产品详情原始数据'!$A:$BG,10,FALSE) -> 0 | C6: =VLOOKUP($A6&$B$2,'4.2 产品详情原始数据'!$A:$BG,37,FALSE) -> 17 | D6: =VLOOKUP($A6&$B$2,'4.2 产品详情原始数据'!$A:$BG,43,FALSE) -> 0 | E6: =VLOOKUP($A6&$B$2,'4.2 产品详情原始数据'!$A:$BG,7,FALSE) -> 13.99 | H6: 2022-08-25 | I6: =VLOOKUP(H6&$I$2,'4.2 产品详情原始数据'!$A:$BG,10,FALSE) -> 1 | J6: =VLOOKUP($H6&$I$2,'4.2 产品详情原始数据'!$A:$BG,37,FALSE) -> 28 | K6: =VLOOKUP($H6&$I$2,'4.2 产品详情原始数据'!$A:$BG,43,FALSE) -> 0.0357
A7: 2022-08-26 | B7: =VLOOKUP($A7&$B$2,'4.2 产品详情原始数据'!$A:$BG,10,FALSE) -> 1 | C7: =VLOOKUP($A7&$B$2,'4.2 产品详情原始数据'!$A:$BG,37,FALSE) -> 32 | D7: =VLOOKUP($A7&$B$2,'4.2 产品详情原始数据'!$A:$BG,43,FALSE) -> 0.0312 | E7: =VLOOKUP($A7&$B$2,'4.2 产品详情原始数据'!$A:$BG,7,FALSE) -> 13.99 | H7: 2022-08-26 | I7: =VLOOKUP(H7&$I$2,'4.2 产品详情原始数据'!$A:$BG,10,FALSE) -> 5 | J7: =VLOOKUP($H7&$I$2,'4.2 产品详情原始数据'!$A:$BG,37,FALSE) -> 37 | K7: =VLOOKUP($H7&$I$2,'4.2 产品详情原始数据'!$A:$BG,43,FALSE) -> 0.1351
A8: 2022-08-27 | B8: =VLOOKUP($A8&$B$2,'4.2 产品详情原始数据'!$A:$BG,10,FALSE) -> 3 | C8: =VLOOKUP($A8&$B$2,'4.2 产品详情原始数据'!$A:$BG,37,FALSE) -> 40 | D8: =VLOOKUP($A8&$B$2,'4.2 产品详情原始数据'!$A:$BG,43,FALSE) -> 0.075 | E8: =VLOOKUP($A8&$B$2,'4.2 产品详情原始数据'!$A:$BG,7,FALSE) -> 13.99 | H8: 2022-08-27 | I8: =VLOOKUP(H8&$I$2,'4.2 产品详情原始数据'!$A:$BG,10,FALSE) -> 2 | J8: =VLOOKUP($H8&$I$2,'4.2 产品详情原始数据'!$A:$BG,37,FALSE) -> 47 | K8: =VLOOKUP($H8&$I$2,'4.2 产品详情原始数据'!$A:$BG,43,FALSE) -> 0.0426
A9: 2022-08-28 | B9: =VLOOKUP($A9&$B$2,'4.2 产品详情原始数据'!$A:$BG,10,FALSE) -> 3 | C9: =VLOOKUP($A9&$B$2,'4.2 产品详情原始数据'!$A:$BG,37,FALSE) -> 54 | D9: =VLOOKUP($A9&$B$2,'4.2 产品详情原始数据'!$A:$BG,43,FALSE) -> 0.0556 | E9: =VLOOKUP($A9&$B$2,'4.2 产品详情原始数据'!$A:$BG,7,FALSE) -> 13.99 | H9: 2022-08-28 | I9: =VLOOKUP(H9&$I$2,'4.2 产品详情原始数据'!$A:$BG,10,FALSE) -> 1 | J9: =VLOOKUP($H9&$I$2,'4.2 产品详情原始数据'!$A:$BG,37,FALSE) -> 50 | K9: =VLOOKUP($H9&$I$2,'4.2 产品详情原始数据'!$A:$BG,43,FALSE) -> 0.02
A10: 2022-08-29 | B10: =VLOOKUP($A10&$B$2,'4.2 产品详情原始数据'!$A:$BG,10,FALSE) -> 9 | C10: =VLOOKUP($A10&$B$2,'4.2 产品详情原始数据'!$A:$BG,37,FALSE) -> 46 | D10: =VLOOKUP($A10&$B$2,'4.2 产品详情原始数据'!$A:$BG,43,FALSE) -> 0.1957 | E10: =VLOOKUP($A10&$B$2,'4.2 产品详情原始数据'!$A:$BG,7,FALSE) -> 13.99 | H10: 2022-08-29 | I10: =VLOOKUP(H10&$I$2,'4.2 产品详情原始数据'!$A:$BG,10,FALSE) -> 1 | J10: =VLOOKUP($H10&$I$2,'4.2 产品详情原始数据'!$A:$BG,37,FALSE) -> 34 | K10: =VLOOKUP($H10&$I$2,'4.2 产品详情原始数据'!$A:$BG,43,FALSE) -> 0.0294
A11: 2022-08-30 | B11: =VLOOKUP($A11&$B$2,'4.2 产品详情原始数据'!$A:$BG,10,FALSE) -> 5 | C11: =VLOOKUP($A11&$B$2,'4.2 产品详情原始数据'!$A:$BG,37,FALSE) -> 78 | D11: =VLOOKUP($A11&$B$2,'4.2 产品详情原始数据'!$A:$BG,43,FALSE) -> 0.0641 | E11: =VLOOKUP($A11&$B$2,'4.2 产品详情原始数据'!$A:$BG,7,FALSE) -> 13.99 | H11: 2022-08-30 | I11: =VLOOKUP(H11&$I$2,'4.2 产品详情原始数据'!$A:$BG,10,FALSE) -> 5 | J11: =VLOOKUP($H11&$I$2,'4.2 产品详情原始数据'!$A:$BG,37,FALSE) -> 48 | K11: =VLOOKUP($H11&$I$2,'4.2 产品详情原始数据'!$A:$BG,43,FALSE) -> 0.1042
A12: 2022-08-31 | B12: =VLOOKUP($A12&$B$2,'4.2 产品详情原始数据'!$A:$BG,10,FALSE) -> 9 | C12: =VLOOKUP($A12&$B$2,'4.2 产品详情原始数据'!$A:$BG,37,FALSE) -> 71 | D12: =VLOOKUP($A12&$B$2,'4.2 产品详情原始数据'!$A:$BG,43,FALSE) -> 0.1268 | E12: =VLOOKUP($A12&$B$2,'4.2 产品详情原始数据'!$A:$BG,7,FALSE) -> 13.99 | H12: 2022-08-31 | I12: =VLOOKUP(H12&$I$2,'4.2 产品详情原始数据'!$A:$BG,10,FALSE) -> 3 | J12: =VLOOKUP($H12&$I$2,'4.2 产品详情原始数据'!$A:$BG,37,FALSE) -> 62 | K12: =VLOOKUP($H12&$I$2,'4.2 产品详情原始数据'!$A:$BG,43,FALSE) -> 0.0484
A13: 2022-09-01 | B13: =VLOOKUP($A13&$B$2,'4.2 产品详情原始数据'!$A:$BG,10,FALSE) -> 4 | C13: =VLOOKUP($A13&$B$2,'4.2 产品详情原始数据'!$A:$BG,37,FALSE) -> 85 | D13: =VLOOKUP($A13&$B$2,'4.2 产品详情原始数据'!$A:$BG,43,FALSE) -> 0.0471 | E13: =VLOOKUP($A13&$B$2,'4.2 产品详情原始数据'!$A:$BG,7,FALSE) -> 13.99 | H13: 2022-09-01 | I13: =VLOOKUP(H13&$I$2,'4.2 产品详情原始数据'!$A:$BG,10,FALSE) -> 5 | J13: =VLOOKUP($H13&$I$2,'4.2 产品详情原始数据'!$A:$BG,37,FALSE) -> 52 | K13: =VLOOKUP($H13&$I$2,'4.2 产品详情原始数据'!$A:$BG,43,FALSE) -> 0.0962
A14: 2022-09-02 | B14: =VLOOKUP($A14&$B$2,'4.2 产品详情原始数据'!$A:$BG,10,FALSE) -> 9 | C14: =VLOOKUP($A14&$B$2,'4.2 产品详情原始数据'!$A:$BG,37,FALSE) -> 94 | D14: =VLOOKUP($A14&$B$2,'4.2 产品详情原始数据'!$A:$BG,43,FALSE) -> 0.0957 | E14: =VLOOKUP($A14&$B$2,'4.2 产品详情原始数据'!$A:$BG,7,FALSE) -> 13.99 | H14: 2022-09-02 | I14: =VLOOKUP(H14&$I$2,'4.2 产品详情原始数据'!$A:$BG,10,FALSE) -> 3 | J14: =VLOOKUP($H14&$I$2,'4.2 产品详情原始数据'!$A:$BG,37,FALSE) -> 61 | K14: =VLOOKUP($H14&$I$2,'4.2 产品详情原始数据'!$A:$BG,43,FALSE) -> 0.0492
A15: 2022-09-03 | B15: =VLOOKUP($A15&$B$2,'4.2 产品详情原始数据'!$A:$BG,10,FALSE) -> 9 | C15: =VLOOKUP($A15&$B$2,'4.2 产品详情原始数据'!$A:$BG,37,FALSE) -> 124 | D15: =VLOOKUP($A15&$B$2,'4.2 产品详情原始数据'!$A:$BG,43,FALSE) -> 0.0726 | E15: =VLOOKUP($A15&$B$2,'4.2 产品详情原始数据'!$A:$BG,7,FALSE) -> 13.99 | H15: 2022-09-03 | I15: =VLOOKUP(H15&$I$2,'4.2 产品详情原始数据'!$A:$BG,10,FALSE) -> 2 | J15: =VLOOKUP($H15&$I$2,'4.2 产品详情原始数据'!$A:$BG,37,FALSE) -> 81 | K15: =VLOOKUP($H15&$I$2,'4.2 产品详情原始数据'!$A:$BG,43,FALSE) -> 0.0247
... A57: 2022-10-15 | B57: =VLOOKUP($A57&$B$2,'4.2 产品详情原始数据'!$A:$BG,10,FALSE) -> 0 | C57: =VLOOKUP($A57&$B$2,'4.2 产品详情原始数据'!$A:$BG,37,FALSE) -> 0 | D57: =VLOOKUP($A57&$B$2,'4.2 产品详情原始数据'!$A:$BG,43,FALSE) -> 0 | E57: =VLOOKUP($A57&$B$2,'4.2 产品详情原始数据'!$A:$BG,7,FALSE) -> 19.99 | H57: 2022-10-15 | I57: =VLOOKUP(H57&$I$2,'4.2 产品详情原始数据'!$A:$BG,10,FALSE) -> 0 | J57: =VLOOKUP($H57&$I$2,'4.2 产品详情原始数据'!$A:$BG,37,FALSE) -> 0 | K57: =VLOOKUP($H57&$I$2,'4.2 产品详情原始数据'!$A:$BG,43,FALSE) -> 0
AF69: 求和项:Sessions-Total | AG69: MSKU
AF70: 时间 | AG70: XXXX-111 | AH70: XXXX-222 | AI70: 总计
AF71: 2022-08-20 | AG71: 0 | AH71: 0 | AI71: 0
AF72: 2022-08-21 | AG72: 0 | AH72: 0 | AI72: 0
AF73: 2022-08-22 | AG73: 0 | AH73: 0 | AI73: 0
AF74: 2022-08-23 | AG74: 29 | AH74: 25 | AI74: 54
AF75: 2022-08-24 | AG75: 25 | AH75: 16 | AI75: 41
A76: 求和项:Sessions-Total | B76: MSKU | H76: 求和项:销量 | I76: MSKU | N76: 求和项:销量CVR | O76: MSKU | AF76: 2022-08-25 | AG76: 17 | AH76: 28 | AI76: 45
A77: 时间 | B77: XXXX-111 | C77: XXXX-222 | D77: 总计 | H77: 时间 | I77: XXXX-111 | J77: XXXX-222 | K77: 总计 | N77: 时间 | O77: XXXX-111 | P77: XXXX-222 | Q77: 总计 | AF77: 2022-08-26 | AG77: 32 | AH77: 37 | AI77: 69
A78: 2022-08-20 | B78: 0 | C78: 0 | D78: 0 | H78: 2022-08-20 | I78: 0 | J78: 0 | K78: 0 | N78: 2022-08-20 | O78: 0 | P78: 0 | Q78: 0 | AF78: 2022-08-27 | AG78: 40 | AH78: 47 | AI78: 87
A79: 2022-08-21 | B79: 0 | C79: 0 | D79: 0 | H79: 2022-08-21 | I79: 0 | J79: 0 | K79: 0 | N79: 2022-08-21 | O79: 0 | P79: 0 | Q79: 0 | AF79: 2022-08-28 | AG79: 54 | AH79: 50 | AI79: 104
A80: 2022-08-22 | B80: 0 | C80: 0 | D80: 0 | H80: 2022-08-22 | I80: 0 | J80: 0 | K80: 0 | N80: 2022-08-22 | O80: 0 | P80: 0 | Q80: 0 | AF80: 2022-08-29 | AG80: 46 | AH80: 34 | AI80: 80
A81: 2022-08-23 | B81: 29 | C81: 25 | D81: 54 | H81: 2022-08-23 | I81: 2 | J81: 1 | K81: 3 | N81: 2022-08-23 | O81: 0.069 | P81: 0.04 | Q81: 0.109 | AF81: 2022-08-30 | AG81: 78 | AH81: 48 | AI81: 126
A82: 2022-08-24 | B82: 25 | C82: 16 | D82: 41 | H82: 2022-08-24 | I82: 1 | J82: 0 | K82: 1 | N82: 2022-08-24 | O82: 0.04 | P82: 0 | Q82: 0.04 | AF82: 2022-08-31 | AG82: 71 | AH82: 62 | AI82: 133
A83: 2022-08-25 | B83: 17 | C83: 28 | D83: 45 | H83: 2022-08-25 | I83: 0 | J83: 1 | K83: 1 | N83: 2022-08-25 | O83: 0 | P83: 0.0357 | Q83: 0.0357 | AF83: 2022-09-01 | AG83: 85 | AH83: 52 | AI83: 137
A84: 2022-08-26 | B84: 32 | C84: 37 | D84: 69 | H84: 2022-08-26 | I84: 1 | J84: 5 | K84: 6 | N84: 2022-08-26 | O84: 0.0312 | P84: 0.1351 | Q84: 0.1663 | AF84: 2022-09-02 | AG84: 94 | AH84: 61 | AI84: 155
A85: 2022-08-27 | B85: 40 | C85: 47 | D85: 87 | H85: 2022-08-27 | I85: 3 | J85: 2 | K85: 5 | N85: 2022-08-27 | O85: 0.075 | P85: 0.0426 | Q85: 0.1176 | AF85: 2022-09-03 | AG85: 124 | AH85: 81 | AI85: 205
A86: 2022-08-28 | B86: 54 | C86: 50 | D86: 104 | H86: 2022-08-28 | I86: 3 | J86: 1 | K86: 4 | N86: 2022-08-28 | O86: 0.0556 | P86: 0.02 | Q86: 0.0756 | AF86: 2022-09-04 | AG86: 149 | AH86: 90 | AI86: 239
A87: 2022-08-29 | B87: 46 | C87: 34 | D87: 80 | H87: 2022-08-29 | I87: 9 | J87: 1 | K87: 10 | N87: 2022-08-29 | O87: 0.1957 | P87: 0.0294 | Q87: 0.2251 | AF87: 2022-09-05 | AG87: 203 | AH87: 129 | AI87: 332
A88: 2022-08-30 | B88: 78 | C88: 48 | D88: 126 | H88: 2022-08-30 | I88: 5 | J88: 5 | K88: 10 | N88: 2022-08-30 | O88: 0.0641 | P88: 0.1042 | Q88: 0.1683 | AF88: 2022-09-06 | AG88: 138 | AH88: 77 | AI88: 215
A89: 2022-08-31 | B89: 71 | C89: 62 | D89: 133 | H89: 2022-08-31 | I89: 9 | J89: 3 | K89: 12 | N89: 2022-08-31 | O89: 0.1268 | P89: 0.0484 | Q89: 0.1752 | AF89: 2022-09-07 | AG89: 142 | AH89: 62 | AI89: 204
... A93: 2022-09-04 | B93: 149 | C93: 90 | D93: 239 | H93: 2022-09-04 | I93: 8 | J93: 11 | K93: 19 | N93: 2022-09-04 | O93: 0.0537 | P93: 0.1222 | Q93: 0.1759 | AF93: 总计 | AG93: 1723 | AH93: 1085 | AI93: 2808
A94: 2022-09-05 | B94: 203 | C94: 129 | D94: 332 | H94: 2022-09-05 | I94: 23 | J94: 11 | K94: 34 | N94: 2022-09-05 | O94: 0.1133 | P94: 0.0853 | Q94: 0.1986
A95: 2022-09-06 | B95: 138 | C95: 77 | D95: 215 | H95: 2022-09-06 | I95: 17 | J95: 10 | K95: 27 | N95: 2022-09-06 | O95: 0.1232 | P95: 0.1299 | Q95: 0.2531
...

Sheet 3.2 关键词数据
B1: XXXX-111 | J1: XXXX-222 | S1: 辅助列
S2: 7 | T2: 8 | U2: 9 | V2: 10 | W2: 11 | X2: 12 | Y2: 13 | Z2: 14 | AA2: 15 | AB2: 16 | AC2: 17 | AD2: 18 | AE2: 19 | AF2: 20 | AG2: 21 | AH2: 22 | AI2: 23 | AJ2: 24 | AK2: 25 | AL2: 26 | AM2: 27 | AN2: 28 | AO2: 29 | AP2: 30 | AQ2: 31 | AR2: 32 | AS2: 33 | AT2: 34 | AU2: 35
B3: 关键词1 | D3: 关键词2 | F3: 关键词3 | H3: 关键词4 | J3: 关键词1 | L3: 关键词2 | N3: 关键词3 | P3: 关键词4
A4: 日期 | B4: 广告位 | C4: 自然位 | D4: 广告位 | E4: 自然位 | F4: 广告位 | G4: 自然位 | H4: 广告位 | I4: 自然位 | J4: 广告位 | K4: 自然位 | L4: 广告位 | M4: 自然位 | N4: 广告位 | O4: 自然位 | P4: 广告位 | Q4: 自然位
A5: 8月31日上午 | B5: =_xlfn.IFNA(IF(VLOOKUP($B$1&$A5,'4.1 关键词原始数据'!$A:$N,S$2,FALSE)=0," ",VLOOKUP($B$1&$A5,'4.1 关键词原始数据'!$A:$N,S$2,FALSE))," ") | C5: =_xlfn.IFNA(IF(VLOOKUP($B$1&$A5,'4.1 关键词原始数据'!$A:$N,T$2,FALSE)=0," ",VLOOKUP($B$1&$A5,'4.1 关键词原始数据'!$A:$N,T$2,FALSE))," ") -> 3-7-2 | D5: =_xlfn.IFNA(IF(VLOOKUP($B$1&$A5,'4.1 关键词原始数据'!$A:$N,U$2,FALSE)=0," ",VLOOKUP($B$1&$A5,'4.1 关键词原始数据'!$A:$N,U$2,FALSE))," ") | E5: =_xlfn.IFNA(IF(VLOOKUP($B$1&$A5,'4.1 关键词原始数据'!$A:$N,V$2,FALSE)=0," ",VLOOKUP($B$1&$A5,'4.1 关键词原始数据'!$A:$N,V$2,FALSE))," ") | F5: =_xlfn.IFNA(IF(VLOOKUP($B$1&$A5,'4.1 关键词原始数据'!$A:$N,W$2,FALSE)=0," ",VLOOKUP($B$1&$A5,'4.1 关键词原始数据'!$A:$N,W$2,FALSE))," ") | G5: =_xlfn.IFNA(IF(VLOOKUP($B$1&$A5,'4.1 关键词原始数据'!$A:$N,X$2,FALSE)=0," ",VLOOKUP($B$1&$A5,'4.1 关键词原始数据'!$A:$N,X$2,FALSE))," ") -> 1-17-1 | H5: =_xlfn.IFNA(IF(VLOOKUP($B$1&$A5,'4.1 关键词原始数据'!$A:$N,Y$2,FALSE)=0," ",VLOOKUP($B$1&$A5,'4.1 关键词原始数据'!$A:$N,Y$2,FALSE))," ") | I5: =_xlfn.IFNA(IF(VLOOKUP($B$1&$A5,'4.1 关键词原始数据'!$A:$N,Z$2,FALSE)=0," ",VLOOKUP($B$1&$A5,'4.1 关键词原始数据'!$A:$N,Z$2,FALSE))," ") | J5: =_xlfn.IFNA(IF(VLOOKUP($J$1&$A5,'4.1 关键词原始数据'!$A:$N,S$2,FALSE)=0," ",VLOOKUP($J$1&$A5,'4.1 关键词原始数据'!$A:$N,S$2,FALSE))," ") | K5: =_xlfn.IFNA(IF(VLOOKUP($J$1&$A5,'4.1 关键词原始数据'!$A:$N,T$2,FALSE)=0," ",VLOOKUP($J$1&$A5,'4.1 关键词原始数据'!$A:$N,T$2,FALSE))," ") | L5: =_xlfn.IFNA(IF(VLOOKUP($J$1&$A5,'4.1 关键词原始数据'!$A:$N,U$2,FALSE)=0," ",VLOOKUP($J$1&$A5,'4.1 关键词原始数据'!$A:$N,U$2,FALSE))," ") | M5: =_xlfn.IFNA(IF(VLOOKUP($J$1&$A5,'4.1 关键词原始数据'!$A:$N,V$2,FALSE)=0," ",VLOOKUP($J$1&$A5,'4.1 关键词原始数据'!$A:$N,V$2,FALSE))," ") | N5: =_xlfn.IFNA(IF(VLOOKUP($J$1&$A5,'4.1 关键词原始数据'!$A:$N,W$2,FALSE)=0," ",VLOOKUP($J$1&$A5,'4.1 关键词原始数据'!$A:$N,W$2,FALSE))," ") | O5: =_xlfn.IFNA(IF(VLOOKUP($J$1&$A5,'4.1 关键词原始数据'!$A:$N,X$2,FALSE)=0," ",VLOOKUP($J$1&$A5,'4.1 关键词原始数据'!$A:$N,X$2,FALSE))," ") | P5: =_xlfn.IFNA(IF(VLOOKUP($J$1&$A5,'4.1 关键词原始数据'!$A:$N,Y$2,FALSE)=0," ",VLOOKUP($J$1&$A5,'4.1 关键词原始数据'!$A:$N,Y$2,FALSE))," ") | Q5: =_xlfn.IFNA(IF(VLOOKUP($J$1&$A5,'4.1 关键词原始数据'!$A:$N,Z$2,FALSE)=0," ",VLOOKUP($J$1&$A5,'4.1 关键词原始数据'!$A:$N,Z$2,FALSE))," ")
A6: 8月31日晚上 | B6: =_xlfn.IFNA(IF(VLOOKUP($B$1&$A6,'4.1 关键词原始数据'!$A:$N,S$2,FALSE)=0," ",VLOOKUP($B$1&$A6,'4.1 关键词原始数据'!$A:$N,S$2,FALSE))," ") | C6: =_xlfn.IFNA(IF(VLOOKUP($B$1&$A6,'4.1 关键词原始数据'!$A:$N,T$2,FALSE)=0," ",VLOOKUP($B$1&$A6,'4.1 关键词原始数据'!$A:$N,T$2,FALSE))," ") | D6: =_xlfn.IFNA(IF(VLOOKUP($B$1&$A6,'4.1 关键词原始数据'!$A:$N,U$2,FALSE)=0," ",VLOOKUP($B$1&$A6,'4.1 关键词原始数据'!$A:$N,U$2,FALSE))," ") | E6: =_xlfn.IFNA(IF(VLOOKUP($B$1&$A6,'4.1 关键词原始数据'!$A:$N,V$2,FALSE)=0," ",VLOOKUP($B$1&$A6,'4.1 关键词原始数据'!$A:$N,V$2,FALSE))," ") | F6: =_xlfn.IFNA(IF(VLOOKUP($B$1&$A6,'4.1 关键词原始数据'!$A:$N,W$2,FALSE)=0," ",VLOOKUP($B$1&$A6,'4.1 关键词原始数据'!$A:$N,W$2,FALSE))," ") | G6: =_xlfn.IFNA(IF(VLOOKUP($B$1&$A6,'4.1 关键词原始数据'!$A:$N,X$2,FALSE)=0," ",VLOOKUP($B$1&$A6,'4.1 关键词原始数据'!$A:$N,X$2,FALSE))," ") | H6: =_xlfn.IFNA(IF(VLOOKUP($B$1&$A6,'4.1 关键词原始数据'!$A:$N,Y$2,FALSE)=0," ",VLOOKUP($B$1&$A6,'4.1 关键词原始数据'!$A:$N,Y$2,FALSE))," ") | I6: =_xlfn.IFNA(IF(VLOOKUP($B$1&$A6,'4.1 关键词原始数据'!$A:$N,Z$2,FALSE)=0," ",VLOOKUP($B$1&$A6,'4.1 关键词原始数据'!$A:$N,Z$2,FALSE))," ") | J6: =_xlfn.IFNA(IF(VLOOKUP($J$1&$A6,'4.1 关键词原始数据'!$A:$N,S$2,FALSE)=0," ",VLOOKUP($J$1&$A6,'4.1 关键词原始数据'!$A:$N,S$2,FALSE))," ") | K6: =_xlfn.IFNA(IF(VLOOKUP($J$1&$A6,'4.1 关键词原始数据'!$A:$N,T$2,FALSE)=0," ",VLOOKUP($J$1&$A6,'4.1 关键词原始数据'!$A:$N,T$2,FALSE))," ") | L6: =_xlfn.IFNA(IF(VLOOKUP($J$1&$A6,'4.1 关键词原始数据'!$A:$N,U$2,FALSE)=0," ",VLOOKUP($J$1&$A6,'4.1 关键词原始数据'!$A:$N,U$2,FALSE))," ") | M6: =_xlfn.IFNA(IF(VLOOKUP($J$1&$A6,'4.1 关键词原始数据'!$A:$N,V$2,FALSE)=0," ",VLOOKUP($J$1&$A6,'4.1 关键词原始数据'!$A:$N,V$2,FALSE))," ") | N6: =_xlfn.IFNA(IF(VLOOKUP($J$1&$A6,'4.1 关键词原始数据'!$A:$N,W$2,FALSE)=0," ",VLOOKUP($J$1&$A6,'4.1 关键词原始数据'!$A:$N,W$2,FALSE))," ") | O6: =_xlfn.IFNA(IF(VLOOKUP($J$1&$A6,'4.1 关键词原始数据'!$A:$N,X$2,FALSE)=0," ",VLOOKUP($J$1&$A6,'4.1 关键词原始数据'!$A:$N,X$2,FALSE))," ") | P6: =_xlfn.IFNA(IF(VLOOKUP($J$1&$A6,'4.1 关键词原始数据'!$A:$N,Y$2,FALSE)=0," ",VLOOKUP($J$1&$A6,'4.1 关键词原始数据'!$A:$N,Y$2,FALSE))," ") | Q6: =_xlfn.IFNA(IF(VLOOKUP($J$1&$A6,'4.1 关键词原始数据'!$A:$N,Z$2,FALSE)=0," ",VLOOKUP($J$1&$A6,'4.1 关键词原始数据'!$A:$N,Z$2,FALSE))," ")
A7: 9月1日上午 | B7: =_xlfn.IFNA(IF(VLOOKUP($B$1&$A7,'4.1 关键词原始数据'!$A:$N,S$2,FALSE)=0," ",VLOOKUP($B$1&$A7,'4.1 关键词原始数据'!$A:$N,S$2,FALSE))," ") | C7: =_xlfn.IFNA(IF(VLOOKUP($B$1&$A7,'4.1 关键词原始数据'!$A:$N,T$2,FALSE)=0," ",VLOOKUP($B$1&$A7,'4.1 关键词原始数据'!$A:$N,T$2,FALSE))," ") -> 2-12-4 | D7: =_xlfn.IFNA(IF(VLOOKUP($B$1&$A7,'4.1 关键词原始数据'!$A:$N,U$2,FALSE)=0," ",VLOOKUP($B$1&$A7,'4.1 关键词原始数据'!$A:$N,U$2,FALSE))," ") | E7: =_xlfn.IFNA(IF(VLOOKUP($B$1&$A7,'4.1 关键词原始数据'!$A:$N,V$2,FALSE)=0," ",VLOOKUP($B$1&$A7,'4.1 关键词原始数据'!$A:$N,V$2,FALSE))," ") -> 2-4-4 | F7: =_xlfn.IFNA(IF(VLOOKUP($B$1&$A7,'4.1 关键词原始数据'!$A:$N,W$2,FALSE)=0," ",VLOOKUP($B$1&$A7,'4.1 关键词原始数据'!$A:$N,W$2,FALSE))," ") | G7: =_xlfn.IFNA(IF(VLOOKUP($B$1&$A7,'4.1 关键词原始数据'!$A:$N,X$2,FALSE)=0," ",VLOOKUP($B$1&$A7,'4.1 关键词原始数据'!$A:$N,X$2,FALSE))," ") | H7: =_xlfn.IFNA(IF(VLOOKUP($B$1&$A7,'4.1 关键词原始数据'!$A:$N,Y$2,FALSE)=0," ",VLOOKUP($B$1&$A7,'4.1 关键词原始数据'!$A:$N,Y$2,FALSE))," ") | I7: =_xlfn.IFNA(IF(VLOOKUP($B$1&$A7,'4.1 关键词原始数据'!$A:$N,Z$2,FALSE)=0," ",VLOOKUP($B$1&$A7,'4.1 关键词原始数据'!$A:$N,Z$2,FALSE))," ") | J7: =_xlfn.IFNA(IF(VLOOKUP($J$1&$A7,'4.1 关键词原始数据'!$A:$N,S$2,FALSE)=0," ",VLOOKUP($J$1&$A7,'4.1 关键词原始数据'!$A:$N,S$2,FALSE))," ") | K7: =_xlfn.IFNA(IF(VLOOKUP($J$1&$A7,'4.1 关键词原始数据'!$A:$N,T$2,FALSE)=0," ",VLOOKUP($J$1&$A7,'4.1 关键词原始数据'!$A:$N,T$2,FALSE))," ") | L7: =_xlfn.IFNA(IF(VLOOKUP($J$1&$A7,'4.1 关键词原始数据'!$A:$N,U$2,FALSE)=0," ",VLOOKUP($J$1&$A7,'4.1 关键词原始数据'!$A:$N,U$2,FALSE))," ") | M7: =_xlfn.IFNA(IF(VLOOKUP($J$1&$A7,'4.1 关键词原始数据'!$A:$N,V$2,FALSE)=0," ",VLOOKUP($J$1&$A7,'4.1 关键词原始数据'!$A:$N,V$2,FALSE))," ") | N7: =_xlfn.IFNA(IF(VLOOKUP($J$1&$A7,'4.1 关键词原始数据'!$A:$N,W$2,FALSE)=0," ",VLOOKUP($J$1&$A7,'4.1 关键词原始数据'!$A:$N,W$2,FALSE))," ") | O7: =_xlfn.IFNA(IF(VLOOKUP($J$1&$A7,'4.1 关键词原始数据'!$A:$N,X$2,FALSE)=0," ",VLOOKUP($J$1&$A7,'4.1 关键词原始数据'!$A:$N,X$2,FALSE))," ") | P7: =_xlfn.IFNA(IF(VLOOKUP($J$1&$A7,'4.1 关键词原始数据'!$A:$N,Y$2,FALSE)=0," ",VLOOKUP($J$1&$A7,'4.1 关键词原始数据'!$A:$N,Y$2,FALSE))," ") | Q7: =_xlfn.IFNA(IF(VLOOKUP($J$1&$A7,'4.1 关键词原始数据'!$A:$N,Z$2,FALSE)=0," ",VLOOKUP($J$1&$A7,'4.1 关键词原始数据'!$A:$N,Z$2,FALSE))," ")
A8: 9月1日晚上 | B8: =_xlfn.IFNA(IF(VLOOKUP($B$1&$A8,'4.1 关键词原始数据'!$A:$N,S$2,FALSE)=0," ",VLOOKUP($B$1&$A8,'4.1 关键词原始数据'!$A:$N,S$2,FALSE))," ") | C8: =_xlfn.IFNA(IF(VLOOKUP($B$1&$A8,'4.1 关键词原始数据'!$A:$N,T$2,FALSE)=0," ",VLOOKUP($B$1&$A8,'4.1 关键词原始数据'!$A:$N,T$2,FALSE))," ") | D8: =_xlfn.IFNA(IF(VLOOKUP($B$1&$A8,'4.1 关键词原始数据'!$A:$N,U$2,FALSE)=0," ",VLOOKUP($B$1&$A8,'4.1 关键词原始数据'!$A:$N,U$2,FALSE))," ") | E8: =_xlfn.IFNA(IF(VLOOKUP($B$1&$A8,'4.1 关键词原始数据'!$A:$N,V$2,FALSE)=0," ",VLOOKUP($B$1&$A8,'4.1 关键词原始数据'!$A:$N,V$2,FALSE))," ") | F8: =_xlfn.IFNA(IF(VLOOKUP($B$1&$A8,'4.1 关键词原始数据'!$A:$N,W$2,FALSE)=0," ",VLOOKUP($B$1&$A8,'4.1 关键词原始数据'!$A:$N,W$2,FALSE))," ") | G8: =_xlfn.IFNA(IF(VLOOKUP($B$1&$A8,'4.1 关键词原始数据'!$A:$N,X$2,FALSE)=0," ",VLOOKUP($B$1&$A8,'4.1 关键词原始数据'!$A:$N,X$2,FALSE))," ") | H8: =_xlfn.IFNA(IF(VLOOKUP($B$1&$A8,'4.1 关键词原始数据'!$A:$N,Y$2,FALSE)=0," ",VLOOKUP($B$1&$A8,'4.1 关键词原始数据'!$A:$N,Y$2,FALSE))," ") | I8: =_xlfn.IFNA(IF(VLOOKUP($B$1&$A8,'4.1 关键词原始数据'!$A:$N,Z$2,FALSE)=0," ",VLOOKUP($B$1&$A8,'4.1 关键词原始数据'!$A:$N,Z$2,FALSE))," ") | J8: =_xlfn.IFNA(IF(VLOOKUP($J$1&$A8,'4.1 关键词原始数据'!$A:$N,S$2,FALSE)=0," ",VLOOKUP($J$1&$A8,'4.1 关键词原始数据'!$A:$N,S$2,FALSE))," ") | K8: =_xlfn.IFNA(IF(VLOOKUP($J$1&$A8,'4.1 关键词原始数据'!$A:$N,T$2,FALSE)=0," ",VLOOKUP($J$1&$A8,'4.1 关键词原始数据'!$A:$N,T$2,FALSE))," ") | L8: =_xlfn.IFNA(IF(VLOOKUP($J$1&$A8,'4.1 关键词原始数据'!$A:$N,U$2,FALSE)=0," ",VLOOKUP($J$1&$A8,'4.1 关键词原始数据'!$A:$N,U$2,FALSE))," ") | M8: =_xlfn.IFNA(IF(VLOOKUP($J$1&$A8,'4.1 关键词原始数据'!$A:$N,V$2,FALSE)=0," ",VLOOKUP($J$1&$A8,'4.1 关键词原始数据'!$A:$N,V$2,FALSE))," ") | N8: =_xlfn.IFNA(IF(VLOOKUP($J$1&$A8,'4.1 关键词原始数据'!$A:$N,W$2,FALSE)=0," ",VLOOKUP($J$1&$A8,'4.1 关键词原始数据'!$A:$N,W$2,FALSE))," ") | O8: =_xlfn.IFNA(IF(VLOOKUP($J$1&$A8,'4.1 关键词原始数据'!$A:$N,X$2,FALSE)=0," ",VLOOKUP($J$1&$A8,'4.1 关键词原始数据'!$A:$N,X$2,FALSE))," ") | P8: =_xlfn.IFNA(IF(VLOOKUP($J$1&$A8,'4.1 关键词原始数据'!$A:$N,Y$2,FALSE)=0," ",VLOOKUP($J$1&$A8,'4.1 关键词原始数据'!$A:$N,Y$2,FALSE))," ") | Q8: =_xlfn.IFNA(IF(VLOOKUP($J$1&$A8,'4.1 关键词原始数据'!$A:$N,Z$2,FALSE)=0," ",VLOOKUP($J$1&$A8,'4.1 关键词原始数据'!$A:$N,Z$2,FALSE))," ")
A9: 9月2日上午 | B9: =_xlfn.IFNA(IF(VLOOKUP($B$1&$A9,'4.1 关键词原始数据'!$A:$N,S$2,FALSE)=0," ",VLOOKUP($B$1&$A9,'4.1 关键词原始数据'!$A:$N,S$2,FALSE))," ") | C9: =_xlfn.IFNA(IF(VLOOKUP($B$1&$A9,'4.1 关键词原始数据'!$A:$N,T$2,FALSE)=0," ",VLOOKUP($B$1&$A9,'4.1 关键词原始数据'!$A:$N,T$2,FALSE))," ") -> 2-14-4 | D9: =_xlfn.IFNA(IF(VLOOKUP($B$1&$A9,'4.1 关键词原始数据'!$A:$N,U$2,FALSE)=0," ",VLOOKUP($B$1&$A9,'4.1 关键词原始数据'!$A:$N,U$2,FALSE))," ") | E9: =_xlfn.IFNA(IF(VLOOKUP($B$1&$A9,'4.1 关键词原始数据'!$A:$N,V$2,FALSE)=0," ",VLOOKUP($B$1&$A9,'4.1 关键词原始数据'!$A:$N,V$2,FALSE))," ") | F9: =_xlfn.IFNA(IF(VLOOKUP($B$1&$A9,'4.1 关键词原始数据'!$A:$N,W$2,FALSE)=0," ",VLOOKUP($B$1&$A9,'4.1 关键词原始数据'!$A:$N,W$2,FALSE))," ") | G9: =_xlfn.IFNA(IF(VLOOKUP($B$1&$A9,'4.1 关键词原始数据'!$A:$N,X$2,FALSE)=0," ",VLOOKUP($B$1&$A9,'4.1 关键词原始数据'!$A:$N,X$2,FALSE))," ") -> 2-7-4 | H9: =_xlfn.IFNA(IF(VLOOKUP($B$1&$A9,'4.1 关键词原始数据'!$A:$N,Y$2,FALSE)=0," ",VLOOKUP($B$1&$A9,'4.1 关键词原始数据'!$A:$N,Y$2,FALSE))," ") | I9: =_xlfn.IFNA(IF(VLOOKUP($B$1&$A9,'4.1 关键词原始数据'!$A:$N,Z$2,FALSE)=0," ",VLOOKUP($B$1&$A9,'4.1 关键词原始数据'!$A:$N,Z$2,FALSE))," ") | J9: =_xlfn.IFNA(IF(VLOOKUP($J$1&$A9,'4.1 关键词原始数据'!$A:$N,S$2,FALSE)=0," ",VLOOKUP($J$1&$A9,'4.1 关键词原始数据'!$A:$N,S$2,FALSE))," ") | K9: =_xlfn.IFNA(IF(VLOOKUP($J$1&$A9,'4.1 关键词原始数据'!$A:$N,T$2,FALSE)=0," ",VLOOKUP($J$1&$A9,'4.1 关键词原始数据'!$A:$N,T$2,FALSE))," ") | L9: =_xlfn.IFNA(IF(VLOOKUP($J$1&$A9,'4.1 关键词原始数据'!$A:$N,U$2,FALSE)=0," ",VLOOKUP($J$1&$A9,'4.1 关键词原始数据'!$A:$N,U$2,FALSE))," ") | M9: =_xlfn.IFNA(IF(VLOOKUP($J$1&$A9,'4.1 关键词原始数据'!$A:$N,V$2,FALSE)=0," ",VLOOKUP($J$1&$A9,'4.1 关键词原始数据'!$A:$N,V$2,FALSE))," ") -> 3-16-4 | N9: =_xlfn.IFNA(IF(VLOOKUP($J$1&$A9,'4.1 关键词原始数据'!$A:$N,W$2,FALSE)=0," ",VLOOKUP($J$1&$A9,'4.1 关键词原始数据'!$A:$N,W$2,FALSE))," ") | O9: =_xlfn.IFNA(IF(VLOOKUP($J$1&$A9,'4.1 关键词原始数据'!$A:$N,X$2,FALSE)=0," ",VLOOKUP($J$1&$A9,'4.1 关键词原始数据'!$A:$N,X$2,FALSE))," ") | P9: =_xlfn.IFNA(IF(VLOOKUP($J$1&$A9,'4.1 关键词原始数据'!$A:$N,Y$2,FALSE)=0," ",VLOOKUP($J$1&$A9,'4.1 关键词原始数据'!$A:$N,Y$2,FALSE))," ") | Q9: =_xlfn.IFNA(IF(VLOOKUP($J$1&$A9,'4.1 关键词原始数据'!$A:$N,Z$2,FALSE)=0," ",VLOOKUP($J$1&$A9,'4.1 关键词原始数据'!$A:$N,Z$2,FALSE))," ")
A10: 9月2日晚上 | B10: =_xlfn.IFNA(IF(VLOOKUP($B$1&$A10,'4.1 关键词原始数据'!$A:$N,S$2,FALSE)=0," ",VLOOKUP($B$1&$A10,'4.1 关键词原始数据'!$A:$N,S$2,FALSE))," ") | C10: =_xlfn.IFNA(IF(VLOOKUP($B$1&$A10,'4.1 关键词原始数据'!$A:$N,T$2,FALSE)=0," ",VLOOKUP($B$1&$A10,'4.1 关键词原始数据'!$A:$N,T$2,FALSE))," ") | D10: =_xlfn.IFNA(IF(VLOOKUP($B$1&$A10,'4.1 关键词原始数据'!$A:$N,U$2,FALSE)=0," ",VLOOKUP($B$1&$A10,'4.1 关键词原始数据'!$A:$N,U$2,FALSE))," ") | E10: =_xlfn.IFNA(IF(VLOOKUP($B$1&$A10,'4.1 关键词原始数据'!$A:$N,V$2,FALSE)=0," ",VLOOKUP($B$1&$A10,'4.1 关键词原始数据'!$A:$N,V$2,FALSE))," ") | F10: =_xlfn.IFNA(IF(VLOOKUP($B$1&$A10,'4.1 关键词原始数据'!$A:$N,W$2,FALSE)=0," ",VLOOKUP($B$1&$A10,'4.1 关键词原始数据'!$A:$N,W$2,FALSE))," ") | G10: =_xlfn.IFNA(IF(VLOOKUP($B$1&$A10,'4.1 关键词原始数据'!$A:$N,X$2,FALSE)=0," ",VLOOKUP($B$1&$A10,'4.1 关键词原始数据'!$A:$N,X$2,FALSE))," ") | H10: =_xlfn.IFNA(IF(VLOOKUP($B$1&$A10,'4.1 关键词原始数据'!$A:$N,Y$2,FALSE)=0," ",VLOOKUP($B$1&$A10,'4.1 关键词原始数据'!$A:$N,Y$2,FALSE))," ") | I10: =_xlfn.IFNA(IF(VLOOKUP($B$1&$A10,'4.1 关键词原始数据'!$A:$N,Z$2,FALSE)=0," ",VLOOKUP($B$1&$A10,'4.1 关键词原始数据'!$A:$N,Z$2,FALSE))," ") | J10: =_xlfn.IFNA(IF(VLOOKUP($J$1&$A10,'4.1 关键词原始数据'!$A:$N,S$2,FALSE)=0," ",VLOOKUP($J$1&$A10,'4.1 关键词原始数据'!$A:$N,S$2,FALSE))," ") | K10: =_xlfn.IFNA(IF(VLOOKUP($J$1&$A10,'4.1 关键词原始数据'!$A:$N,T$2,FALSE)=0," ",VLOOKUP($J$1&$A10,'4.1 关键词原始数据'!$A:$N,T$2,FALSE))," ") | L10: =_xlfn.IFNA(IF(VLOOKUP($J$1&$A10,'4.1 关键词原始数据'!$A:$N,U$2,FALSE)=0," ",VLOOKUP($J$1&$A10,'4.1 关键词原始数据'!$A:$N,U$2,FALSE))," ") | M10: =_xlfn.IFNA(IF(VLOOKUP($J$1&$A10,'4.1 关键词原始数据'!$A:$N,V$2,FALSE)=0," ",VLOOKUP($J$1&$A10,'4.1 关键词原始数据'!$A:$N,V$2,FALSE))," ") | N10: =_xlfn.IFNA(IF(VLOOKUP($J$1&$A10,'4.1 关键词原始数据'!$A:$N,W$2,FALSE)=0," ",VLOOKUP($J$1&$A10,'4.1 关键词原始数据'!$A:$N,W$2,FALSE))," ") | O10: =_xlfn.IFNA(IF(VLOOKUP($J$1&$A10,'4.1 关键词原始数据'!$A:$N,X$2,FALSE)=0," ",VLOOKUP($J$1&$A10,'4.1 关键词原始数据'!$A:$N,X$2,FALSE))," ") | P10: =_xlfn.IFNA(IF(VLOOKUP($J$1&$A10,'4.1 关键词原始数据'!$A:$N,Y$2,FALSE)=0," ",VLOOKUP($J$1&$A10,'4.1 关键词原始数据'!$A:$N,Y$2,FALSE))," ") | Q10: =_xlfn.IFNA(IF(VLOOKUP($J$1&$A10,'4.1 关键词原始数据'!$A:$N,Z$2,FALSE)=0," ",VLOOKUP($J$1&$A10,'4.1 关键词原始数据'!$A:$N,Z$2,FALSE))," ")
A11: 9月3日上午 | B11: =_xlfn.IFNA(IF(VLOOKUP($B$1&$A11,'4.1 关键词原始数据'!$A:$N,S$2,FALSE)=0," ",VLOOKUP($B$1&$A11,'4.1 关键词原始数据'!$A:$N,S$2,FALSE))," ") | C11: =_xlfn.IFNA(IF(VLOOKUP($B$1&$A11,'4.1 关键词原始数据'!$A:$N,T$2,FALSE)=0," ",VLOOKUP($B$1&$A11,'4.1 关键词原始数据'!$A:$N,T$2,FALSE))," ") -> 3-12-4 | D11: =_xlfn.IFNA(IF(VLOOKUP($B$1&$A11,'4.1 关键词原始数据'!$A:$N,U$2,FALSE)=0," ",VLOOKUP($B$1&$A11,'4.1 关键词原始数据'!$A:$N,U$2,FALSE))," ") | E11: =_xlfn.IFNA(IF(VLOOKUP($B$1&$A11,'4.1 关键词原始数据'!$A:$N,V$2,FALSE)=0," ",VLOOKUP($B$1&$A11,'4.1 关键词原始数据'!$A:$N,V$2,FALSE))," ") | F11: =_xlfn.IFNA(IF(VLOOKUP($B$1&$A11,'4.1 关键词原始数据'!$A:$N,W$2,FALSE)=0," ",VLOOKUP($B$1&$A11,'4.1 关键词原始数据'!$A:$N,W$2,FALSE))," ") | G11: =_xlfn.IFNA(IF(VLOOKUP($B$1&$A11,'4.1 关键词原始数据'!$A:$N,X$2,FALSE)=0," ",VLOOKUP($B$1&$A11,'4.1 关键词原始数据'!$A:$N,X$2,FALSE))," ") -> 1-16-4 | H11: =_xlfn.IFNA(IF(VLOOKUP($B$1&$A11,'4.1 关键词原始数据'!$A:$N,Y$2,FALSE)=0," ",VLOOKUP($B$1&$A11,'4.1 关键词原始数据'!$A:$N,Y$2,FALSE))," ") | I11: =_xlfn.IFNA(IF(VLOOKUP($B$1&$A11,'4.1 关键词原始数据'!$A:$N,Z$2,FALSE)=0," ",VLOOKUP($B$1&$A11,'4.1 关键词原始数据'!$A:$N,Z$2,FALSE))," ") | J11: =_xlfn.IFNA(IF(VLOOKUP($J$1&$A11,'4.1 关键词原始数据'!$A:$N,S$2,FALSE)=0," ",VLOOKUP($J$1&$A11,'4.1 关键词原始数据'!$A:$N,S$2,FALSE))," ") | K11: =_xlfn.IFNA(IF(VLOOKUP($J$1&$A11,'4.1 关键词原始数据'!$A:$N,T$2,FALSE)=0," ",VLOOKUP($J$1&$A11,'4.1 关键词原始数据'!$A:$N,T$2,FALSE))," ") | L11: =_xlfn.IFNA(IF(VLOOKUP($J$1&$A11,'4.1 关键词原始数据'!$A:$N,U$2,FALSE)=0," ",VLOOKUP($J$1&$A11,'4.1 关键词原始数据'!$A:$N,U$2,FALSE))," ") | M11: =_xlfn.IFNA(IF(VLOOKUP($J$1&$A11,'4.1 关键词原始数据'!$A:$N,V$2,FALSE)=0," ",VLOOKUP($J$1&$A11,'4.1 关键词原始数据'!$A:$N,V$2,FALSE))," ") -> 4-12-4 | N11: =_xlfn.IFNA(IF(VLOOKUP($J$1&$A11,'4.1 关键词原始数据'!$A:$N,W$2,FALSE)=0," ",VLOOKUP($J$1&$A11,'4.1 关键词原始数据'!$A:$N,W$2,FALSE))," ") | O11: =_xlfn.IFNA(IF(VLOOKUP($J$1&$A11,'4.1 关键词原始数据'!$A:$N,X$2,FALSE)=0," ",VLOOKUP($J$1&$A11,'4.1 关键词原始数据'!$A:$N,X$2,FALSE))," ") | P11: =_xlfn.IFNA(IF(VLOOKUP($J$1&$A11,'4.1 关键词原始数据'!$A:$N,Y$2,FALSE)=0," ",VLOOKUP($J$1&$A11,'4.1 关键词原始数据'!$A:$N,Y$2,FALSE))," ") | Q11: =_xlfn.IFNA(IF(VLOOKUP($J$1&$A11,'4.1 关键词原始数据'!$A:$N,Z$2,FALSE)=0," ",VLOOKUP($J$1&$A11,'4.1 关键词原始数据'!$A:$N,Z$2,FALSE))," ")
A12: 9月4日晚上 | B12: =_xlfn.IFNA(IF(VLOOKUP($B$1&$A12,'4.1 关键词原始数据'!$A:$N,S$2,FALSE)=0," ",VLOOKUP($B$1&$A12,'4.1 关键词原始数据'!$A:$N,S$2,FALSE))," ") | C12: =_xlfn.IFNA(IF(VLOOKUP($B$1&$A12,'4.1 关键词原始数据'!$A:$N,T$2,FALSE)=0," ",VLOOKUP($B$1&$A12,'4.1 关键词原始数据'!$A:$N,T$2,FALSE))," ") | D12: =_xlfn.IFNA(IF(VLOOKUP($B$1&$A12,'4.1 关键词原始数据'!$A:$N,U$2,FALSE)=0," ",VLOOKUP($B$1&$A12,'4.1 关键词原始数据'!$A:$N,U$2,FALSE))," ") | E12: =_xlfn.IFNA(IF(VLOOKUP($B$1&$A12,'4.1 关键词原始数据'!$A:$N,V$2,FALSE)=0," ",VLOOKUP($B$1&$A12,'4.1 关键词原始数据'!$A:$N,V$2,FALSE))," ") | F12: =_xlfn.IFNA(IF(VLOOKUP($B$1&$A12,'4.1 关键词原始数据'!$A:$N,W$2,FALSE)=0," ",VLOOKUP($B$1&$A12,'4.1 关键词原始数据'!$A:$N,W$2,FALSE))," ") | G12: =_xlfn.IFNA(IF(VLOOKUP($B$1&$A12,'4.1 关键词原始数据'!$A:$N,X$2,FALSE)=0," ",VLOOKUP($B$1&$A12,'4.1 关键词原始数据'!$A:$N,X$2,FALSE))," ") | H12: =_xlfn.IFNA(IF(VLOOKUP($B$1&$A12,'4.1 关键词原始数据'!$A:$N,Y$2,FALSE)=0," ",VLOOKUP($B$1&$A12,'4.1 关键词原始数据'!$A:$N,Y$2,FALSE))," ") | I12: =_xlfn.IFNA(IF(VLOOKUP($B$1&$A12,'4.1 关键词原始数据'!$A:$N,Z$2,FALSE)=0," ",VLOOKUP($B$1&$A12,'4.1 关键词原始数据'!$A:$N,Z$2,FALSE))," ") | J12: =_xlfn.IFNA(IF(VLOOKUP($J$1&$A12,'4.1 关键词原始数据'!$A:$N,S$2,FALSE)=0," ",VLOOKUP($J$1&$A12,'4.1 关键词原始数据'!$A:$N,S$2,FALSE))," ") | K12: =_xlfn.IFNA(IF(VLOOKUP($J$1&$A12,'4.1 关键词原始数据'!$A:$N,T$2,FALSE)=0," ",VLOOKUP($J$1&$A12,'4.1 关键词原始数据'!$A:$N,T$2,FALSE))," ") | L12: =_xlfn.IFNA(IF(VLOOKUP($J$1&$A12,'4.1 关键词原始数据'!$A:$N,U$2,FALSE)=0," ",VLOOKUP($J$1&$A12,'4.1 关键词原始数据'!$A:$N,U$2,FALSE))," ") | M12: =_xlfn.IFNA(IF(VLOOKUP($J$1&$A12,'4.1 关键词原始数据'!$A:$N,V$2,FALSE)=0," ",VLOOKUP($J$1&$A12,'4.1 关键词原始数据'!$A:$N,V$2,FALSE))," ") | N12: =_xlfn.IFNA(IF(VLOOKUP($J$1&$A12,'4.1 关键词原始数据'!$A:$N,W$2,FALSE)=0," ",VLOOKUP($J$1&$A12,'4.1 关键词原始数据'!$A:$N,W$2,FALSE))," ") | O12: =_xlfn.IFNA(IF(VLOOKUP($J$1&$A12,'4.1 关键词原始数据'!$A:$N,X$2,FALSE)=0," ",VLOOKUP($J$1&$A12,'4.1 关键词原始数据'!$A:$N,X$2,FALSE))," ") | P12: =_xlfn.IFNA(IF(VLOOKUP($J$1&$A12,'4.1 关键词原始数据'!$A:$N,Y$2,FALSE)=0," ",VLOOKUP($J$1&$A12,'4.1 关键词原始数据'!$A:$N,Y$2,FALSE))," ") | Q12: =_xlfn.IFNA(IF(VLOOKUP($J$1&$A12,'4.1 关键词原始数据'!$A:$N,Z$2,FALSE)=0," ",VLOOKUP($J$1&$A12,'4.1 关键词原始数据'!$A:$N,Z$2,FALSE))," ")
A13: 9月5日上午 | B13: =_xlfn.IFNA(IF(VLOOKUP($B$1&$A13,'4.1 关键词原始数据'!$A:$N,S$2,FALSE)=0," ",VLOOKUP($B$1&$A13,'4.1 关键词原始数据'!$A:$N,S$2,FALSE))," ") | C13: =_xlfn.IFNA(IF(VLOOKUP($B$1&$A13,'4.1 关键词原始数据'!$A:$N,T$2,FALSE)=0," ",VLOOKUP($B$1&$A13,'4.1 关键词原始数据'!$A:$N,T$2,FALSE))," ") -> 3-11-1 | D13: =_xlfn.IFNA(IF(VLOOKUP($B$1&$A13,'4.1 关键词原始数据'!$A:$N,U$2,FALSE)=0," ",VLOOKUP($B$1&$A13,'4.1 关键词原始数据'!$A:$N,U$2,FALSE))," ") | E13: =_xlfn.IFNA(IF(VLOOKUP($B$1&$A13,'4.1 关键词原始数据'!$A:$N,V$2,FALSE)=0," ",VLOOKUP($B$1&$A13,'4.1 关键词原始数据'!$A:$N,V$2,FALSE))," ") -> 5-11-2 | F13: =_xlfn.IFNA(IF(VLOOKUP($B$1&$A13,'4.1 关键词原始数据'!$A:$N,W$2,FALSE)=0," ",VLOOKUP($B$1&$A13,'4.1 关键词原始数据'!$A:$N,W$2,FALSE))," ") | G13: =_xlfn.IFNA(IF(VLOOKUP($B$1&$A13,'4.1 关键词原始数据'!$A:$N,X$2,FALSE)=0," ",VLOOKUP($B$1&$A13,'4.1 关键词原始数据'!$A:$N,X$2,FALSE))," ") -> 1-17-4 | H13: =_xlfn.IFNA(IF(VLOOKUP($B$1&$A13,'4.1 关键词原始数据'!$A:$N,Y$2,FALSE)=0," ",VLOOKUP($B$1&$A13,'4.1 关键词原始数据'!$A:$N,Y$2,FALSE))," ") | I13: =_xlfn.IFNA(IF(VLOOKUP($B$1&$A13,'4.1 关键词原始数据'!$A:$N,Z$2,FALSE)=0," ",VLOOKUP($B$1&$A13,'4.1 关键词原始数据'!$A:$N,Z$2,FALSE))," ") | J13: =_xlfn.IFNA(IF(VLOOKUP($J$1&$A13,'4.1 关键词原始数据'!$A:$N,S$2,FALSE)=0," ",VLOOKUP($J$1&$A13,'4.1 关键词原始数据'!$A:$N,S$2,FALSE))," ") | K13: =_xlfn.IFNA(IF(VLOOKUP($J$1&$A13,'4.1 关键词原始数据'!$A:$N,T$2,FALSE)=0," ",VLOOKUP($J$1&$A13,'4.1 关键词原始数据'!$A:$N,T$2,FALSE))," ") | L13: =_xlfn.IFNA(IF(VLOOKUP($J$1&$A13,'4.1 关键词原始数据'!$A:$N,U$2,FALSE)=0," ",VLOOKUP($J$1&$A13,'4.1 关键词原始数据'!$A:$N,U$2,FALSE))," ") | M13: =_xlfn.IFNA(IF(VLOOKUP($J$1&$A13,'4.1 关键词原始数据'!$A:$N,V$2,FALSE)=0," ",VLOOKUP($J$1&$A13,'4.1 关键词原始数据'!$A:$N,V$2,FALSE))," ") | N13: =_xlfn.IFNA(IF(VLOOKUP($J$1&$A13,'4.1 关键词原始数据'!$A:$N,W$2,FALSE)=0," ",VLOOKUP($J$1&$A13,'4.1 关键词原始数据'!$A:$N,W$2,FALSE))," ") | O13: =_xlfn.IFNA(IF(VLOOKUP($J$1&$A13,'4.1 关键词原始数据'!$A:$N,X$2,FALSE)=0," ",VLOOKUP($J$1&$A13,'4.1 关键词原始数据'!$A:$N,X$2,FALSE))," ") | P13: =_xlfn.IFNA(IF(VLOOKUP($J$1&$A13,'4.1 关键词原始数据'!$A:$N,Y$2,FALSE)=0," ",VLOOKUP($J$1&$A13,'4.1 关键词原始数据'!$A:$N,Y$2,FALSE))," ") | Q13: =_xlfn.IFNA(IF(VLOOKUP($J$1&$A13,'4.1 关键词原始数据'!$A:$N,Z$2,FALSE)=0," ",VLOOKUP($J$1&$A13,'4.1 关键词原始数据'!$A:$N,Z$2,FALSE))," ")
A14: 9月6日晚上 | B14: =_xlfn.IFNA(IF(VLOOKUP($B$1&$A14,'4.1 关键词原始数据'!$A:$N,S$2,FALSE)=0," ",VLOOKUP($B$1&$A14,'4.1 关键词原始数据'!$A:$N,S$2,FALSE))," ") | C14: =_xlfn.IFNA(IF(VLOOKUP($B$1&$A14,'4.1 关键词原始数据'!$A:$N,T$2,FALSE)=0," ",VLOOKUP($B$1&$A14,'4.1 关键词原始数据'!$A:$N,T$2,FALSE))," ") | D14: =_xlfn.IFNA(IF(VLOOKUP($B$1&$A14,'4.1 关键词原始数据'!$A:$N,U$2,FALSE)=0," ",VLOOKUP($B$1&$A14,'4.1 关键词原始数据'!$A:$N,U$2,FALSE))," ") | E14: =_xlfn.IFNA(IF(VLOOKUP($B$1&$A14,'4.1 关键词原始数据'!$A:$N,V$2,FALSE)=0," ",VLOOKUP($B$1&$A14,'4.1 关键词原始数据'!$A:$N,V$2,FALSE))," ") | F14: =_xlfn.IFNA(IF(VLOOKUP($B$1&$A14,'4.1 关键词原始数据'!$A:$N,W$2,FALSE)=0," ",VLOOKUP($B$1&$A14,'4.1 关键词原始数据'!$A:$N,W$2,FALSE))," ") | G14: =_xlfn.IFNA(IF(VLOOKUP($B$1&$A14,'4.1 关键词原始数据'!$A:$N,X$2,FALSE)=0," ",VLOOKUP($B$1&$A14,'4.1 关键词原始数据'!$A:$N,X$2,FALSE))," ") | H14: =_xlfn.IFNA(IF(VLOOKUP($B$1&$A14,'4.1 关键词原始数据'!$A:$N,Y$2,FALSE)=0," ",VLOOKUP($B$1&$A14,'4.1 关键词原始数据'!$A:$N,Y$2,FALSE))," ") | I14: =_xlfn.IFNA(IF(VLOOKUP($B$1&$A14,'4.1 关键词原始数据'!$A:$N,Z$2,FALSE)=0," ",VLOOKUP($B$1&$A14,'4.1 关键词原始数据'!$A:$N,Z$2,FALSE))," ") | J14: =_xlfn.IFNA(IF(VLOOKUP($J$1&$A14,'4.1 关键词原始数据'!$A:$N,S$2,FALSE)=0," ",VLOOKUP($J$1&$A14,'4.1 关键词原始数据'!$A:$N,S$2,FALSE))," ") | K14: =_xlfn.IFNA(IF(VLOOKUP($J$1&$A14,'4.1 关键词原始数据'!$A:$N,T$2,FALSE)=0," ",VLOOKUP($J$1&$A14,'4.1 关键词原始数据'!$A:$N,T$2,FALSE))," ") | L14: =_xlfn.IFNA(IF(VLOOKUP($J$1&$A14,'4.1 关键词原始数据'!$A:$N,U$2,FALSE)=0," ",VLOOKUP($J$1&$A14,'4.1 关键词原始数据'!$A:$N,U$2,FALSE))," ") | M14: =_xlfn.IFNA(IF(VLOOKUP($J$1&$A14,'4.1 关键词原始数据'!$A:$N,V$2,FALSE)=0," ",VLOOKUP($J$1&$A14,'4.1 关键词原始数据'!$A:$N,V$2,FALSE))," ") | N14: =_xlfn.IFNA(IF(VLOOKUP($J$1&$A14,'4.1 关键词原始数据'!$A:$N,W$2,FALSE)=0," ",VLOOKUP($J$1&$A14,'4.1 关键词原始数据'!$A:$N,W$2,FALSE))," ") | O14: =_xlfn.IFNA(IF(VLOOKUP($J$1&$A14,'4.1 关键词原始数据'!$A:$N,X$2,FALSE)=0," ",VLOOKUP($J$1&$A14,'4.1 关键词原始数据'!$A:$N,X$2,FALSE))," ") | P14: =_xlfn.IFNA(IF(VLOOKUP($J$1&$A14,'4.1 关键词原始数据'!$A:$N,Y$2,FALSE)=0," ",VLOOKUP($J$1&$A14,'4.1 关键词原始数据'!$A:$N,Y$2,FALSE))," ") | Q14: =_xlfn.IFNA(IF(VLOOKUP($J$1&$A14,'4.1 关键词原始数据'!$A:$N,Z$2,FALSE)=0," ",VLOOKUP($J$1&$A14,'4.1 关键词原始数据'!$A:$N,Z$2,FALSE))," ")
A15: 9月7日上午 | B15: =_xlfn.IFNA(IF(VLOOKUP($B$1&$A15,'4.1 关键词原始数据'!$A:$N,S$2,FALSE)=0," ",VLOOKUP($B$1&$A15,'4.1 关键词原始数据'!$A:$N,S$2,FALSE))," ") | C15: =_xlfn.IFNA(IF(VLOOKUP($B$1&$A15,'4.1 关键词原始数据'!$A:$N,T$2,FALSE)=0," ",VLOOKUP($B$1&$A15,'4.1 关键词原始数据'!$A:$N,T$2,FALSE))," ") -> 3-12-3 | D15: =_xlfn.IFNA(IF(VLOOKUP($B$1&$A15,'4.1 关键词原始数据'!$A:$N,U$2,FALSE)=0," ",VLOOKUP($B$1&$A15,'4.1 关键词原始数据'!$A:$N,U$2,FALSE))," ") | E15: =_xlfn.IFNA(IF(VLOOKUP($B$1&$A15,'4.1 关键词原始数据'!$A:$N,V$2,FALSE)=0," ",VLOOKUP($B$1&$A15,'4.1 关键词原始数据'!$A:$N,V$2,FALSE))," ") | F15: =_xlfn.IFNA(IF(VLOOKUP($B$1&$A15,'4.1 关键词原始数据'!$A:$N,W$2,FALSE)=0," ",VLOOKUP($B$1&$A15,'4.1 关键词原始数据'!$A:$N,W$2,FALSE))," ") | G15: =_xlfn.IFNA(IF(VLOOKUP($B$1&$A15,'4.1 关键词原始数据'!$A:$N,X$2,FALSE)=0," ",VLOOKUP($B$1&$A15,'4.1 关键词原始数据'!$A:$N,X$2,FALSE))," ") -> 2-3-1 | H15: =_xlfn.IFNA(IF(VLOOKUP($B$1&$A15,'4.1 关键词原始数据'!$A:$N,Y$2,FALSE)=0," ",VLOOKUP($B$1&$A15,'4.1 关键词原始数据'!$A:$N,Y$2,FALSE))," ") | I15: =_xlfn.IFNA(IF(VLOOKUP($B$1&$A15,'4.1 关键词原始数据'!$A:$N,Z$2,FALSE)=0," ",VLOOKUP($B$1&$A15,'4.1 关键词原始数据'!$A:$N,Z$2,FALSE))," ") | J15: =_xlfn.IFNA(IF(VLOOKUP($J$1&$A15,'4.1 关键词原始数据'!$A:$N,S$2,FALSE)=0," ",VLOOKUP($J$1&$A15,'4.1 关键词原始数据'!$A:$N,S$2,FALSE))," ") | K15: =_xlfn.IFNA(IF(VLOOKUP($J$1&$A15,'4.1 关键词原始数据'!$A:$N,T$2,FALSE)=0," ",VLOOKUP($J$1&$A15,'4.1 关键词原始数据'!$A:$N,T$2,FALSE))," ") | L15: =_xlfn.IFNA(IF(VLOOKUP($J$1&$A15,'4.1 关键词原始数据'!$A:$N,U$2,FALSE)=0," ",VLOOKUP($J$1&$A15,'4.1 关键词原始数据'!$A:$N,U$2,FALSE))," ") | M15: =_xlfn.IFNA(IF(VLOOKUP($J$1&$A15,'4.1 关键词原始数据'!$A:$N,V$2,FALSE)=0," ",VLOOKUP($J$1&$A15,'4.1 关键词原始数据'!$A:$N,V$2,FALSE))," ") -> 4-4-4 | N15: =_xlfn.IFNA(IF(VLOOKUP($J$1&$A15,'4.1 关键词原始数据'!$A:$N,W$2,FALSE)=0," ",VLOOKUP($J$1&$A15,'4.1 关键词原始数据'!$A:$N,W$2,FALSE))," ") | O15: =_xlfn.IFNA(IF(VLOOKUP($J$1&$A15,'4.1 关键词原始数据'!$A:$N,X$2,FALSE)=0," ",VLOOKUP($J$1&$A15,'4.1 关键词原始数据'!$A:$N,X$2,FALSE))," ") | P15: =_xlfn.IFNA(IF(VLOOKUP($J$1&$A15,'4.1 关键词原始数据'!$A:$N,Y$2,FALSE)=0," ",VLOOKUP($J$1&$A15,'4.1 关键词原始数据'!$A:$N,Y$2,FALSE))," ") | Q15: =_xlfn.IFNA(IF(VLOOKUP($J$1&$A15,'4.1 关键词原始数据'!$A:$N,Z$2,FALSE)=0," ",VLOOKUP($J$1&$A15,'4.1 关键词原始数据'!$A:$N,Z$2,FALSE))," ")
A16: 9月7日晚上 | B16: =_xlfn.IFNA(IF(VLOOKUP($B$1&$A16,'4.1 关键词原始数据'!$A:$N,S$2,FALSE)=0," ",VLOOKUP($B$1&$A16,'4.1 关键词原始数据'!$A:$N,S$2,FALSE))," ") | C16: =_xlfn.IFNA(IF(VLOOKUP($B$1&$A16,'4.1 关键词原始数据'!$A:$N,T$2,FALSE)=0," ",VLOOKUP($B$1&$A16,'4.1 关键词原始数据'!$A:$N,T$2,FALSE))," ") | D16: =_xlfn.IFNA(IF(VLOOKUP($B$1&$A16,'4.1 关键词原始数据'!$A:$N,U$2,FALSE)=0," ",VLOOKUP($B$1&$A16,'4.1 关键词原始数据'!$A:$N,U$2,FALSE))," ") | E16: =_xlfn.IFNA(IF(VLOOKUP($B$1&$A16,'4.1 关键词原始数据'!$A:$N,V$2,FALSE)=0," ",VLOOKUP($B$1&$A16,'4.1 关键词原始数据'!$A:$N,V$2,FALSE))," ") | F16: =_xlfn.IFNA(IF(VLOOKUP($B$1&$A16,'4.1 关键词原始数据'!$A:$N,W$2,FALSE)=0," ",VLOOKUP($B$1&$A16,'4.1 关键词原始数据'!$A:$N,W$2,FALSE))," ") | G16: =_xlfn.IFNA(IF(VLOOKUP($B$1&$A16,'4.1 关键词原始数据'!$A:$N,X$2,FALSE)=0," ",VLOOKUP($B$1&$A16,'4.1 关键词原始数据'!$A:$N,X$2,FALSE))," ") | H16: =_xlfn.IFNA(IF(VLOOKUP($B$1&$A16,'4.1 关键词原始数据'!$A:$N,Y$2,FALSE)=0," ",VLOOKUP($B$1&$A16,'4.1 关键词原始数据'!$A:$N,Y$2,FALSE))," ") | I16: =_xlfn.IFNA(IF(VLOOKUP($B$1&$A16,'4.1 关键词原始数据'!$A:$N,Z$2,FALSE)=0," ",VLOOKUP($B$1&$A16,'4.1 关键词原始数据'!$A:$N,Z$2,FALSE))," ") | J16: =_xlfn.IFNA(IF(VLOOKUP($J$1&$A16,'4.1 关键词原始数据'!$A:$N,S$2,FALSE)=0," ",VLOOKUP($J$1&$A16,'4.1 关键词原始数据'!$A:$N,S$2,FALSE))," ") | K16: =_xlfn.IFNA(IF(VLOOKUP($J$1&$A16,'4.1 关键词原始数据'!$A:$N,T$2,FALSE)=0," ",VLOOKUP($J$1&$A16,'4.1 关键词原始数据'!$A:$N,T$2,FALSE))," ") | L16: =_xlfn.IFNA(IF(VLOOKUP($J$1&$A16,'4.1 关键词原始数据'!$A:$N,U$2,FALSE)=0," ",VLOOKUP($J$1&$A16,'4.1 关键词原始数据'!$A:$N,U$2,FALSE))," ") | M16: =_xlfn.IFNA(IF(VLOOKUP($J$1&$A16,'4.1 关键词原始数据'!$A:$N,V$2,FALSE)=0," ",VLOOKUP($J$1&$A16,'4.1 关键词原始数据'!$A:$N,V$2,FALSE))," ") | N16: =_xlfn.IFNA(IF(VLOOKUP($J$1&$A16,'4.1 关键词原始数据'!$A:$N,W$2,FALSE)=0," ",VLOOKUP($J$1&$A16,'4.1 关键词原始数据'!$A:$N,W$2,FALSE))," ") | O16: =_xlfn.IFNA(IF(VLOOKUP($J$1&$A16,'4.1 关键词原始数据'!$A:$N,X$2,FALSE)=0," ",VLOOKUP($J$1&$A16,'4.1 关键词原始数据'!$A:$N,X$2,FALSE))," ") | P16: =_xlfn.IFNA(IF(VLOOKUP($J$1&$A16,'4.1 关键词原始数据'!$A:$N,Y$2,FALSE)=0," ",VLOOKUP($J$1&$A16,'4.1 关键词原始数据'!$A:$N,Y$2,FALSE))," ") | Q16: =_xlfn.IFNA(IF(VLOOKUP($J$1&$A16,'4.1 关键词原始数据'!$A:$N,Z$2,FALSE)=0," ",VLOOKUP($J$1&$A16,'4.1 关键词原始数据'!$A:$N,Z$2,FALSE))," ")
... A84: 10月15日上午 | B84: =_xlfn.IFNA(IF(VLOOKUP($B$1&$A84,'4.1 关键词原始数据'!$A:$N,S$2,FALSE)=0," ",VLOOKUP($B$1&$A84,'4.1 关键词原始数据'!$A:$N,S$2,FALSE))," ") | C84: =_xlfn.IFNA(IF(VLOOKUP($B$1&$A84,'4.1 关键词原始数据'!$A:$N,T$2,FALSE)=0," ",VLOOKUP($B$1&$A84,'4.1 关键词原始数据'!$A:$N,T$2,FALSE))," ") | D84: =_xlfn.IFNA(IF(VLOOKUP($B$1&$A84,'4.1 关键词原始数据'!$A:$N,U$2,FALSE)=0," ",VLOOKUP($B$1&$A84,'4.1 关键词原始数据'!$A:$N,U$2,FALSE))," ") | E84: =_xlfn.IFNA(IF(VLOOKUP($B$1&$A84,'4.1 关键词原始数据'!$A:$N,V$2,FALSE)=0," ",VLOOKUP($B$1&$A84,'4.1 关键词原始数据'!$A:$N,V$2,FALSE))," ") | F84: =_xlfn.IFNA(IF(VLOOKUP($B$1&$A84,'4.1 关键词原始数据'!$A:$N,W$2,FALSE)=0," ",VLOOKUP($B$1&$A84,'4.1 关键词原始数据'!$A:$N,W$2,FALSE))," ") | G84: =_xlfn.IFNA(IF(VLOOKUP($B$1&$A84,'4.1 关键词原始数据'!$A:$N,X$2,FALSE)=0," ",VLOOKUP($B$1&$A84,'4.1 关键词原始数据'!$A:$N,X$2,FALSE))," ") -> 5-3-1 | H84: =_xlfn.IFNA(IF(VLOOKUP($B$1&$A84,'4.1 关键词原始数据'!$A:$N,Y$2,FALSE)=0," ",VLOOKUP($B$1&$A84,'4.1 关键词原始数据'!$A:$N,Y$2,FALSE))," ") | I84: =_xlfn.IFNA(IF(VLOOKUP($B$1&$A84,'4.1 关键词原始数据'!$A:$N,Z$2,FALSE)=0," ",VLOOKUP($B$1&$A84,'4.1 关键词原始数据'!$A:$N,Z$2,FALSE))," ") | J84: =_xlfn.IFNA(IF(VLOOKUP($J$1&$A84,'4.1 关键词原始数据'!$A:$N,S$2,FALSE)=0," ",VLOOKUP($J$1&$A84,'4.1 关键词原始数据'!$A:$N,S$2,FALSE))," ") | K84: =_xlfn.IFNA(IF(VLOOKUP($J$1&$A84,'4.1 关键词原始数据'!$A:$N,T$2,FALSE)=0," ",VLOOKUP($J$1&$A84,'4.1 关键词原始数据'!$A:$N,T$2,FALSE))," ") | L84: =_xlfn.IFNA(IF(VLOOKUP($J$1&$A84,'4.1 关键词原始数据'!$A:$N,U$2,FALSE)=0," ",VLOOKUP($J$1&$A84,'4.1 关键词原始数据'!$A:$N,U$2,FALSE))," ") | M84: =_xlfn.IFNA(IF(VLOOKUP($J$1&$A84,'4.1 关键词原始数据'!$A:$N,V$2,FALSE)=0," ",VLOOKUP($J$1&$A84,'4.1 关键词原始数据'!$A:$N,V$2,FALSE))," ") -> 4-2-2 | N84: =_xlfn.IFNA(IF(VLOOKUP($J$1&$A84,'4.1 关键词原始数据'!$A:$N,W$2,FALSE)=0," ",VLOOKUP($J$1&$A84,'4.1 关键词原始数据'!$A:$N,W$2,FALSE))," ") -> 1-1-1 | O84: =_xlfn.IFNA(IF(VLOOKUP($J$1&$A84,'4.1 关键词原始数据'!$A:$N,X$2,FALSE)=0," ",VLOOKUP($J$1&$A84,'4.1 关键词原始数据'!$A:$N,X$2,FALSE))," ") | P84: =_xlfn.IFNA(IF(VLOOKUP($J$1&$A84,'4.1 关键词原始数据'!$A:$N,Y$2,FALSE)=0," ",VLOOKUP($J$1&$A84,'4.1 关键词原始数据'!$A:$N,Y$2,FALSE))," ") | Q84: =_xlfn.IFNA(IF(VLOOKUP($J$1&$A84,'4.1 关键词原始数据'!$A:$N,Z$2,FALSE)=0," ",VLOOKUP($J$1&$A84,'4.1 关键词原始数据'!$A:$N,Z$2,FALSE))," ")
A85: 10月15日晚上

Sheet 3.3 广告数据
A1: 分析指南 | B1: 1、发现问题：整体数据是否正常且符合预期，对主推SKU做重点分析，次推SKU做简要总结（花费、展示位置、搜索词、是否有特殊情况等） 2、业务优化：广告结构是否需要进行一定的优化？ 3、数据跟踪：后续应当关注哪些重点指标？（如关键词排序、曝光量、曝光位置等） 4、展示位、搜索词等辅助信息，在分析时如果需要再截取，不要每个SKU每个广告组都截
A2: 主推款SKU | B2: XXXX-111 | C2: ASIN | D2: ASIN1 | E2: 主图 | I2: 次推款SKU | J2: XXXX-222 | K2: ASIN | L2: ASIN2 | M2: 主图
A3: 日期 | B3: 广告总花费 | C3: 广告展示量 | D3: 广告点击量 | E3: 广告点击率 | F3: 广告订单量 | G3: 广告转化率 | I3: 日期 | J3: 广告总花费 | K3: 广告展示量 | L3: 广告点击量 | M3: 广告点击率 | N3: 广告订单量 | O3: 广告转化率
A4: 2022-08-23 | I4: 2022-08-23
A5: 2022-08-24 | I5: 2022-08-24
A6: 2022-08-25 | I6: 2022-08-25
A7: 2022-08-26 | I7: 2022-08-26
A8: 2022-08-27 | I8: 2022-08-27
A9: 2022-08-28 | I9: 2022-08-28
A222: MYTD-157

Sheet 4.1 关键词原始数据
B1: 品牌 | C1: 产品系列 | D1: 款式 | E1: SKU | G1: 关键词排序
G2: 关键词1 | I2: 关键词2 | K2: 关键词3 | M2: 关键词4
A3: 辅助标识 | F3: 日期 | G3: 广告位 | H3: 自然位 | I3: 广告位 | J3: 自然位 | K3: 广告位 | L3: 自然位 | M3: 广告位 | N3: 自然位
A4: =E4&F4 -> XXXX-1118月31日上午 | E4: XXXX-111 | F4: 8月31日上午 | H4: 3-7-2 | L4: 1-17-1
A5: =E5&F5 -> XXXX-2228月31日上午 | E5: XXXX-222 | F5: 8月31日上午
A6: =E6&F6 -> 8月31日上午 | F6: 8月31日上午
A7: =E7&F7 -> 8月31日上午 | F7: 8月31日上午 | J7: 6-12-3
A8: =E8&F8 -> 8月31日上午 | F8: 8月31日上午
A9: =E9&F9 -> 8月31日上午 | F9: 8月31日上午
A10: =E10&F10 -> 8月31日上午 | F10: 8月31日上午
A11: =E11&F11 | G11: 关键词排序
A12: =E12&F12 | G12: 关键词1 | I12: 关键词2 | K12: 关键词3 | M12: 关键词4
A13: =E13&F13 -> 日期 | F13: 日期 | G13: 广告位 | H13: 自然位 | I13: 广告位 | J13: 自然位 | K13: 广告位 | L13: 自然位 | M13: 广告位 | N13: 自然位
A14: =E14&F14 -> XXXX-1118月31日晚上 | E14: XXXX-111 | F14: 8月31日晚上
A15: =E15&F15 -> XXXX-2228月31日晚上 | E15: XXXX-222 | F15: 8月31日晚上
A16: =E16&F16 -> 8月31日晚上 | F16: 8月31日晚上
A17: =E17&F17 -> 8月31日晚上 | F17: 8月31日晚上
A18: =E18&F18 -> 8月31日晚上 | F18: 8月31日晚上
A19: =E19&F19 -> 8月31日晚上 | F19: 8月31日晚上
A20: =E20&F20 -> 8月31日晚上 | F20: 8月31日晚上
A22: =E22&F22
A23: =E23&F23
A24: =E24&F24 -> SKU | B24: 品牌 | C24: 产品系列 | D24: 款式 | E24: SKU | G24: 关键词排序
A25: =E25&F25 | G25: 关键词1 | I25: 关键词2 | K25: 关键词3 | M25: 关键词4
A26: =E26&F26 -> 日期 | F26: 日期 | G26: 广告位 | H26: 自然位 | I26: 广告位 | J26: 自然位 | K26: 广告位 | L26: 自然位 | M26: 广告位 | N26: 自然位
A27: =E27&F27 -> XXXX-1119月1日上午 | E27: XXXX-111 | F27: 9月1日上午 | H27: 2-12-4 | J27: 2-4-4
A28: =E28&F28 -> XXXX-2229月1日上午 | E28: XXXX-222 | F28: 9月1日上午
A29: =E29&F29 -> 9月1日上午 | F29: 9月1日上午 | J29: 6-5-1
A30: =E30&F30 -> 9月1日上午 | F30: 9月1日上午
A31: =E31&F31 -> 9月1日上午 | F31: 9月1日上午 | J31: 5-4-4
A32: =E32&F32 -> 9月1日上午 | F32: 9月1日上午
A33: =E33&F33 -> 9月1日上午 | F33: 9月1日上午
A34: =E34&F34 | G34: 关键词1 | I34: 关键词2 | K34: 关键词3 | M34: 关键词4
A35: =E35&F35 -> 日期 | F35: 日期 | G35: 广告位 | H35: 自然位 | I35: 广告位 | J35: 自然位 | K35: 广告位 | L35: 自然位 | M35: 广告位 | N35: 自然位
A36: =E36&F36 -> XXXX-1119月1日晚上 | E36: XXXX-111 | F36: 9月1日晚上
A37: =E37&F37 -> XXXX-2229月1日晚上 | E37: XXXX-222 | F37: 9月1日晚上
A38: =E38&F38 -> 9月1日晚上 | F38: 9月1日晚上
A39: =E39&F39 -> 9月1日晚上 | F39: 9月1日晚上
A40: =E40&F40 -> 9月1日晚上 | F40: 9月1日晚上
A41: =E41&F41 -> 9月1日晚上 | F41: 9月1日晚上
...

Sheet 4.2 产品详情原始数据
A1: 产品标识 | B1: 时间 | C1: ASIN | D1: 父ASIN | E1: MSKU | F1: 品名 | G1: 价格 | H1: FBA可售 | I1: FBM可售 | J1: 销量 | K1: 订单量 | L1: 销售额 | M1: 净销售额 | N1: B2B 销量 | O1: B2B 销售额 | P1: B2B 订单量 | Q1: 促销销量 | R1: 促销销售额 | S1: 促销订单量 | T1: 平均客单价 | U1: 平均销量 | V1: 大类排名 | W1: 小类排名 | X1: 退款量 | Y1: 退款率 | Z1: 评分 | AA1: 评论数 | AB1: 留评率 | AC1: 促销折扣 | AD1: 毛利润 | AE1: 毛利率 | AF1: ROI | AG1: 退货量 | AH1: 退货率 | AI1: Sessions-Browser | AJ1: Sessions-Mobile | AK1: Sessions-Total | AL1: PV-Browser | AM1: PV-Mobile | AN1: PV-Total | AO1: Buybox | AP1: CVR | AQ1: 销量CVR | AR1: CPC | AS1: CTR | AT1: 广告花费 | AU1: ROAS | AV1: ACOS | AW1: ACoAS | AX1: ASoAS | AY1: CPO | AZ1: CPM | BA1: 广告销售额 | BB1: 广告订单量 | BC1: 广告订单占比 | BD1: 广告CVR | BE1: 展示 | BF1: 点击 | BG1: 运营日志1
A2: =B2&E2 -> 2022-08-20XXXX-111 | B2: 2022-08-20 | C2: ASIN1 | E2: XXXX-111 | G2: 13.99 | H2: 199 | I2: 0 | J2: 0 | K2: 0 | L2: 0 | M2: 0 | N2: 0 | O2: 0 | P2: 0 | Q2: 0 | R2: 0 | S2: 0 | U2: 0 | X2: 0 | Y2: 0 | Z2: 0 | AA2: 0 | AB2: 0 | AC2: 0 | AD2: 0 | AE2: 0 | AF2: 0 | AG2: 0 | AH2: 0 | AI2: 0 | AJ2: 0 | AK2: 0 | AL2: 0 | AM2: 0 | AN2: 0 | AP2: 0 | AQ2: 0 | AS2: 0 | AT2: 0 | AU2: 0 | AV2: 0 | AW2: 0 | AX2: 0 | AZ2: 0 | BA2: 0 | BB2: 0 | BC2: 0 | BD2: 0 | BE2: 0 | BF2: 0
A3: =B3&E3 -> 2022-08-21XXXX-111 | B3: 2022-08-21 | C3: ASIN1 | E3: XXXX-111 | G3: 13.99 | H3: 259 | I3: 0 | J3: 0 | K3: 0 | L3: 0 | M3: 0 | N3: 0 | O3: 0 | P3: 0 | Q3: 0 | R3: 0 | S3: 0 | U3: 0 | X3: 0 | Y3: 0 | Z3: 0 | AA3: 0 | AB3: 0 | AC3: 0 | AD3: 0 | AE3: 0 | AF3: 0 | AG3: 0 | AH3: 0 | AI3: 0 | AJ3: 0 | AK3: 0 | AL3: 0 | AM3: 0 | AN3: 0 | AP3: 0 | AQ3: 0 | AS3: 0 | AT3: 0 | AU3: 0 | AV3: 0 | AW3: 0 | AX3: 0 | AZ3: 0 | BA3: 0 | BB3: 0 | BC3: 0 | BD3: 0 | BE3: 0 | BF3: 0
A4: =B4&E4 -> 2022-08-22XXXX-111 | B4: 2022-08-22 | C4: ASIN1 | E4: XXXX-111 | G4: 13.99 | H4: 319 | I4: 0 | J4: 0 | K4: 0 | L4: 0 | M4: 0 | N4: 0 | O4: 0 | P4: 0 | Q4: 0 | R4: 0 | S4: 0 | U4: 0 | X4: 0 | Y4: 0 | Z4: 0 | AA4: 0 | AB4: 0 | AC4: 0 | AD4: 0 | AE4: 0 | AF4: 0 | AG4: 0 | AH4: 0 | AI4: 0 | AJ4: 0 | AK4: 0 | AL4: 0 | AM4: 0 | AN4: 0 | AP4: 0 | AQ4: 0 | AS4: 0 | AT4: 0 | AU4: 0 | AV4: 0 | AW4: 0 | AX4: 0 | AZ4: 0 | BA4: 0 | BB4: 0 | BC4: 0 | BD4: 0 | BE4: 0 | BF4: 0
A5: =B5&E5 -> 2022-08-23XXXX-111 | B5: 2022-08-23 | C5: ASIN1 | E5: XXXX-111 | G5: 13.99 | H5: 340 | I5: 0 | J5: 2 | K5: 2 | L5: 27.98 | M5: 27.98 | N5: 0 | O5: 0 | P5: 0 | Q5: 0 | R5: 0 | S5: 0 | T5: 13.99 | U5: 0 | X5: 0 | Y5: 0 | Z5: 0 | AA5: 0 | AB5: 0 | AC5: 0 | AD5: -20.95 | AE5: 0 | AF5: 0.2452 | AG5: 0 | AH5: 0 | AI5: 9 | AJ5: 20 | AK5: 29 | AL5: 14 | AM5: 23 | AN5: 37 | AO5: 1 | AP5: 0.069 | AQ5: 0.069 | AR5: 0.91 | AS5: 0.002 | AT5: -20.95 | AU5: 2.67 | AV5: 0.3744 | AW5: 0.7487 | AX5: 2 | AY5: 5.24 | AZ5: 1.81 | BA5: 55.96 | BB5: 4 | BC5: 2 | BD5: 0.1739 | BE5: 11582 | BF5: 23
A6: =B6&E6 -> 2022-08-24XXXX-111 | B6: 2022-08-24 | C6: ASIN1 | E6: XXXX-111 | G6: 13.99 | H6: 337 | I6: 0 | J6: 1 | K6: 1 | L6: 13.99 | M6: 13.99 | N6: 0 | O6: 0 | P6: 0 | Q6: 0 | R6: 0 | S6: 0 | T6: 13.99 | U6: 0 | X6: 0 | Y6: 0 | Z6: 0 | AA6: 0 | AB6: 0 | AC6: 0 | AD6: -18.32 | AE6: 0 | AF6: -2.5339 | AG6: 0 | AH6: 0 | AI6: 9 | AJ6: 16 | AK6: 25 | AL6: 11 | AM6: 22 | AN6: 33 | AO6: 1 | AP6: 0.04 | AQ6: 0.04 | AR6: 0.92 | AS6: 0.0024 | AT6: -18.32 | AU6: 0 | AV6: 1 | AW6: 1.3095 | AX6: 0 | AZ6: 2.19 | BA6: 0 | BB6: 0 | BC6: 0 | BD6: 0 | BE6: 8355 | BF6: 20
A7: =B7&E7 -> 2022-08-25XXXX-111 | B7: 2022-08-25 | C7: ASIN1 | E7: XXXX-111 | G7: 13.99 | H7: 334 | I7: 0 | J7: 0 | K7: 0 | L7: 0 | M7: 0 | N7: 0 | O7: 0 | P7: 0 | Q7: 0 | R7: 0 | S7: 0 | U7: 0 | X7: 0 | Y7: 0 | Z7: 0 | AA7: 0 | AB7: 0 | AC7: 0 | AD7: -1.13 | AE7: -0.081 | AF7: 0 | AG7: 0 | AH7: 0 | AI7: 8 | AJ7: 9 | AK7: 17 | AL7: 8 | AM7: 15 | AN7: 23 | AO7: 0.83 | AP7: 0 | AQ7: 0 | AR7: 0.79 | AS7: 0.0017 | AT7: -4.72 | AU7: 0 | AV7: 1 | AW7: 1 | AX7: 0 | AZ7: 1.35 | BA7: 0 | BB7: 0 | BC7: 0 | BD7: 0 | BE7: 3488 | BF7: 6
A8: =B8&E8 -> 2022-08-26XXXX-111 | B8: 2022-08-26 | C8: ASIN1 | E8: XXXX-111 | G8: 13.99 | H8: 493 | I8: 0 | J8: 1 | K8: 1 | L8: 13.99 | M8: 13.99 | N8: 0 | O8: 0 | P8: 0 | Q8: 0 | R8: 0 | S8: 0 | T8: 13.99 | U8: 0 | X8: 0 | Y8: 0 | Z8: 0 | AA8: 0 | AB8: 0 | AC8: 0 | AD8: -20.26 | AE8: 0 | AF8: -3.2212 | AG8: 0 | AH8: 0 | AI8: 15 | AJ8: 17 | AK8: 32 | AL8: 23 | AM8: 19 | AN8: 42 | AO8: 0.88 | AP8: 0.0312 | AQ8: 0.0312 | AR8: 1.07 | AS8: 0.0019 | AT8: -20.26 | AU8: 1.38 | AV8: 0.7241 | AW8: 1.4482 | AX8: 2 | AY8: 10.13 | AZ8: 1.98 | BA8: 27.98 | BB8: 2 | BC8: 2 | BD8: 0.1053 | BE8: 10230 | BF8: 19
A9: =B9&E9 -> 2022-08-27XXXX-111 | B9: 2022-08-27 | C9: ASIN1 | E9: XXXX-111 | G9: 13.99 | H9: 513 | I9: 0 | J9: 3 | K9: 3 | L9: 41.97 | M9: 41.97 | N9: 0 | O9: 0 | P9: 0 | Q9: 0 | R9: 0 | S9: 0 | T9: 13.99 | U9: 0.1 | X9: 0 | Y9: 0 | Z9: 0 | AA9: 0 | AB9: 0 | AC9: 0 | AD9: -22.85 | AE9: -1.6335 | AF9: 0.8858 | AG9: 0 | AH9: 0 | AI9: 16 | AJ9: 24 | AK9: 40 | AL9: 18 | AM9: 37 | AN9: 55 | AO9: 0.96 | AP9: 0.075 | AQ9: 0.075 | AR9: 1.08 | AS9: 0.0027 | AT9: -26 | AU9: 0.54 | AV9: 1.8585 | AW9: 0.6195 | AX9: 0.3333 | AY9: 26 | AZ9: 2.97 | BA9: 13.99 | BB9: 1 | BC9: 0.3333 | BD9: 0.0417 | BE9: 8753 | BF9: 24
A10: =B10&E10 -> 2022-08-28XXXX-111 | B10: 2022-08-28 | C10: ASIN1 | E10: XXXX-111 | G10: 13.99 | H10: 526 | I10: 0 | J10: 3 | K10: 2 | L10: 41.97 | M10: 41.97 | N10: 0 | O10: 0 | P10: 0 | Q10: 0 | R10: 0 | S10: 0 | T10: 13.99 | U10: 0.1 | X10: 0 | Y10: 0 | Z10: 0 | AA10: 0 | AB10: 0 | AC10: 0 | AD10: -23.48 | AE10: 0 | AF10: 1.1834 | AG10: 0 | AH10: 0 | AI10: 17 | AJ10: 37 | AK10: 54 | AL10: 21 | AM10: 52 | AN10: 73 | AO10: 0.96 | AP10: 0.037 | AQ10: 0.0556 | AR10: 1.07 | AS10: 0.0013 | AT10: -23.48 | AU10: 1.79 | AV10: 0.5594 | AW10: 0.5594 | AX10: 1 | AY10: 7.83 | AZ10: 1.4 | BA10: 41.97 | BB10: 3 | BC10: 1.5 | BD10: 0.1364 | BE10: 16751 | BF10: 22
A11: =B11&E11 -> 2022-08-29XXXX-111 | B11: 2022-08-29 | C11: ASIN1 | E11: XXXX-111 | G11: 13.99 | H11: 524 | I11: 0 | J11: 9 | K11: 9 | L11: 125.91 | M11: 125.91 | N11: 0 | O11: 0 | P11: 0 | Q11: 0 | R11: 0 | S11: 0 | T11: 13.99 | U11: 0.2 | X11: 0 | Y11: 0 | Z11: 0 | AA11: 0 | AB11: 0 | AC11: 0 | AD11: -0.2 | AE11: -0.0029 | AF11: 3.1507 | AG11: 0 | AH11: 0 | AI11: 16 | AJ11: 30 | AK11: 46 | AL11: 19 | AM11: 34 | AN11: 53 | AO11: 0.96 | AP11: 0.1957 | AQ11: 0.1957 | AR11: 1.08 | AS11: 0.0014 | AT11: -20.61 | AU11: 1.36 | AV11: 0.7366 | AW11: 0.1637 | AX11: 0.2222 | AY11: 10.3 | AZ11: 1.51 | BA11: 27.98 | BB11: 2 | BC11: 0.2222 | BD11: 0.1053 | BE11: 13659 | BF11: 19
A12: =B12&E12 -> 2022-08-30XXXX-111 | B12: 2022-08-30 | C12: ASIN1 | E12: XXXX-111 | G12: 13.99 | H12: 555 | I12: 0 | J12: 5 | K12: 5 | L12: 69.95 | M12: 69.95 | N12: 0 | O12: 0 | P12: 0 | Q12: 0 | R12: 0 | S12: 0 | T12: 13.99 | U12: 0.1 | X12: 0 | Y12: 0 | Z12: 0 | AA12: 0 | AB12: 0 | AC12: 0 | AD12: 19.73 | AE12: 0.1409 | AF12: 2.5688 | AG12: 0 | AH12: 0 | AI12: 23 | AJ12: 55 | AK12: 78 | AL12: 32 | AM12: 64 | AN12: 96 | AO12: 0.98 | AP12: 0.0641 | AQ12: 0.0641 | AR12: 1.09 | AS12: 0.0014 | AT12: -19.58 | AU12: 3.57 | AV12: 0.2799 | AW12: 0.2799 | AX12: 1 | AY12: 3.92 | AZ12: 1.52 | BA12: 69.95 | BB12: 5 | BC12: 1 | BD12: 0.2778 | BE12: 12849 | BF12: 18
A13: =B13&E13 -> 2022-08-31XXXX-111 | B13: 2022-08-31 | C13: ASIN1 | E13: XXXX-111 | G13: 13.99 | H13: 613 | I13: 0 | J13: 9 | K13: 7 | L13: 125.91 | M13: 113.6 | N13: 0 | O13: 0 | P13: 0 | Q13: 0 | R13: 0 | S13: 0 | T13: 12.62 | U13: 0.2 | X13: 1 | Y13: 0.1111 | Z13: 0 | AA13: 0 | AB13: 0 | AC13: 0 | AD13: -0.9 | AE13: -0.0081 | AF13: 3.1539 | AG13: 0 | AH13: 0 | AI13: 25 | AJ13: 46 | AK13: 71 | AL13: 35 | AM13: 51 | AN13: 86 | AO13: 0.95 | AP13: 0.0986 | AQ13: 0.1268 | AR13: 1.13 | AS13: 0.0033 | AT13: -20.38 | AU13: 1.37 | AV13: 0.7284 | AW13: 0.1619 | AX13: 0.2222 | AY13: 10.19 | AZ13: 3.69 | BA13: 27.98 | BB13: 2 | BC13: 0.2857 | BD13: 0.1111 | BE13: 5518 | BF13: 18
A14: =B14&E14 -> 2022-09-01XXXX-111 | B14: 2022-09-01 | C14: ASIN1 | E14: XXXX-111 | G14: 13.99 | H14: 758 | I14: 0 | J14: 4 | K14: 4 | L14: 55.96 | M14: 55.96 | N14: 0 | O14: 0 | P14: 0 | Q14: 0 | R14: 0 | S14: 0 | T14: 13.99 | U14: 0.1 | X14: 0 | Y14: 0 | Z14: 0 | AA14: 0 | AB14: 0 | AC14: 0 | AD14: -5.41 | AE14: -0.0967 | AF14: 2.1582 | AG14: 0 | AH14: 0 | AI14: 24 | AJ14: 61 | AK14: 85 | AL14: 34 | AM14: 75 | AN14: 109 | AO14: 0.99 | AP14: 0.0471 | AQ14: 0.0471 | AR14: 1.19 | AS14: 0.0036 | AT14: -20.3 | AU14: 0.69 | AV14: 1.451 | AW14: 0.3628 | AX14: 0.25 | AY14: 20.3 | AZ14: 4.35 | BA14: 13.99 | BB14: 1 | BC14: 0.25 | BD14: 0.0588 | BE14: 4668 | BF14: 17
A15: =B15&E15 -> 2022-09-02XXXX-111 | B15: 2022-09-02 | C15: ASIN1 | E15: XXXX-111 | G15: 13.99 | H15: 812 | I15: 0 | J15: 9 | K15: 9 | L15: 125.91 | M15: 125.91 | N15: 0 | O15: 0 | P15: 0 | Q15: 0 | R15: 0 | S15: 0 | T15: 13.99 | U15: 0.2 | X15: 0 | Y15: 0 | Z15: 0 | AA15: 0 | AB15: 0 | AC15: 0 | AD15: 1.98 | AE15: 0.0236 | AF15: 3.1602 | AG15: 0 | AH15: 0 | AI15: 31 | AJ15: 63 | AK15: 94 | AL15: 44 | AM15: 84 | AN15: 128 | AO15: 0.98 | AP15: 0.0957 | AQ15: 0.0957 | AR15: 1.19 | AS15: 0.0043 | AT15: -20.22 | AU15: 2.08 | AV15: 0.4818 | AW15: 0.1606 | AX15: 0.3333 | AY15: 6.74 | AZ15: 5.13 | BA15: 41.97 | BB15: 3 | BC15: 0.3333 | BD15: 0.1765 | BE15: 3943 | BF15: 17
