Workbook

Sheet 运营推广计划表
B2: 亚马逊新品利润预算表 | J2: 单个头程计算表
B3: 料号 | C3: 17C | D3: SKU | E3: 9941 | F3: 产品排名目标 | G3: Top 50 | H3: Top20 | J3: 外箱尺寸（inch） | K3: =K4/2.54 -> 0 | L3: =L4/2.54 -> 0 | M3: =M4/2.54 -> 0
B4: 品名 | C4: 电动器 | D4: ASIN | E4: B0B | F4: 产品销量目标 | G4: 24单/天 | H4: 45单/天 | J4: 外箱尺寸（cm）
B5: 原币 | C5: 美元 | D5: 汇率 | E5: =_xlfn.IFS(C5="美元",K31,C5="欧元",K32,C5="英镑",K33) -> 7.1 | F5: 预计达成时间 | G5: 第2个月 | H5: 第4个月 | J5: 体积 | K5: =K4*L4*M4 -> 0
B6: 币别 | C6: 人民币（元） | J6: 重量（kg）
B7: 销售期间 | D7: 推广期 | F7: 盈利期 | G7: 总合计 | H7: 备注 | J7: 体积重 | K7: =K5/6000 -> 0 | L7: =K5/5000 -> 0 | M7: =K5/6000 -> 0
B8: 类目 产品链接 | D8: 第1月 | E8: 第2月 | F8: 第3月及以后 | J8: 物流价格/kg
B9: 收入 | C9: 刷单数量 | D9: 5 | E9: 5 | F9: 10 | G9: =SUM(D9:F9) -> 20 | H9: 预估刷单单量 | J9: 单个运费 | K9: =IF(K7>$K$6,K7*K8,$K$6*K8) -> 0 | L9: =IF(L7>$K$6,L7*L8,$K$6*L8) -> 0 | M9: =IF(M7>$K$6,M7*M8,$K$6*M8) -> 0
C10: 正常销量 | D10: =SUM(首批与返单囤货数量预测表!G3:G32) -> 177 | E10: =SUM(首批与返单囤货数量预测表!G33:G62) -> 295 | F10: =SUM(首批与返单囤货数量预测表!G63:G92) -> 504 | G10: =SUM(D10:F10) -> 976 | H10: 预估正常销量（不包含刷单单量），需要通过囤货计划中的销量预估，公式会自动汇总 | J10: 单项数量 | K10: 1
C11: 汇总销量 | D11: =D9+D10 -> 182 | E11: =E9+E10 -> 300 | F11: =F9+F10 -> 514 | G11: =SUM(D11:F11) -> 996 | H11: 预估销量（包含刷单单量） | J11: 单个头程 | K11: =K9/K10 -> 0 | L11: =L9/K10 -> 0 | M11: =M9/K10 -> 0
C12: 不含税售价（人民币） | D12: =D16/(1+D13) -> 283.787 | E12: =E16/(1+E13) -> 283.787 | F12: =F16/(1+F13) -> 283.787 | H12: product sales价格 | K12: 空运 | L12: 红单 | M12: 海运
C13: 销售税率 | D13: =IF($C$5="美元",0,20%) -> 0 | E13: =IF($C$5="美元",0,20%) -> 0 | F13: =IF($C$5="美元",0,20%) -> 0 | H13: product sales tax税率，欧洲站20%，美国站0% | J13: 产品包装信息
C14: 含税售价(美元或其他货币） | D14: 39.97 | E14: 39.97 | F14: 39.97 | H14: 亚马逊上的售价 | J14: 彩盒尺寸（cm)
C15: 汇率 | D15: =$E$5 -> 7.1 | E15: =$E$5 -> 7.1 | F15: =$E$5 -> 7.1 | J15: 包裹重量(KG) | K15: 0.76
C16: 含税售价（人民币） | D16: =D14*D15 -> 283.787 | E16: =E14*E15 -> 283.787 | F16: =F14*F15 -> 283.787
C17: 退款率 | D17: =毛利测算表!$C$29 -> 0.02 | E17: =毛利测算表!$C$29 -> 0.02 | F17: =毛利测算表!$C$29 -> 0.02 | H17: 预估退款率 | J17: 各费用占比
C18: 不含税销售额（人民币） | D18: =D11*D12 -> 51649.234 | E18: =E11*E12 -> 85136.1 | F18: =F11*F12 -> 145866.52 | G18: =SUM(D18:F18) -> 282651.85 | J18: 阶段 | K18: 第1月 | L18: 第2月 | M18: 第3月及以后
C19: 含税销售额（人民币） | D19: =D16*D11 -> 51649.234 | E19: =E16*E11 -> 85136.1 | F19: =F16*F11 -> 145866.52 | G19: =SUM(D19:F19) -> 282651.85 | J19: 营销占比 | K19: =D37 -> 0.2814611 | L19: =E37 -> 0.16012009 | M19: =F37 -> 0.087565674
B20: 成本 | C20: 产品成本单价（人民币） | D20: =毛利测算表!$C$19 -> 69 | E20: =毛利测算表!$C$19 -> 69 | F20: =毛利测算表!$C$19 -> 69 | J20: 站内促销营销比 | K20: =D29/D19 -> 0.20050788 | L20: =E29/E19 -> 0.13252439 | M20: =F29/F19 -> 0.075209286
C21: 总成本（人民币） | D21: =D11*D20 -> 12558 | E21: =E11*E20 -> 20700 | F21: =F11*F20 -> 35466 | G21: =SUM(D21:F21) -> 68724 | J21: 站外营销比 | K21: =(D47+D48)/D19 -> 0.018363201 | L21: =(E47+E48)/E19 -> 0.011140342 | M21: =(F47+F48)/F19 -> 0.01300429
B22: 毛利 | C22: 毛利额（人民币） | D22: =D18-D21 -> 39091.234 | E22: =E18-E21 -> 64436.1 | F22: =F18-F21 -> 110400.52 | G22: =SUM(D22:F22) -> 213927.85 | H22: 不含税销售额减去产品总成本 | J22: 成本比 | K22: =D21/D19 -> 0.2431401 | L22: =E21/E19 -> 0.2431401 | M22: =F21/F19 -> 0.2431401
C23: 毛利率 | D23: =D22/D18 -> 0.7568599 | E23: =E22/E18 -> 0.7568599 | F23: =F22/F18 -> 0.7568599 | G23: =SUM(D22:F22)/SUM(D18:F18) -> 0.7568599 | J23: 物流费用比例 | K23: =D45/D19 -> 0.13742701 | L23: =E45/E19 -> 0.13742701 | M23: =F45/F19 -> 0.13742701
B24: 站内促销费用 | C24: LD次数 | D24: 0 | E24: 0 | F24: 0 | H24: 每月预计秒杀次数 | J24: 佣金比 | K24: =D39 -> 0.15 | L24: =E39 -> 0.15 | M24: =F39 -> 0.15
C25: 7DD次数 | D25: 0 | E25: 1 | F25: 2 | H25: 每月预计7天促销次数 | J25: FBA配送费比 | K25: =D42/D19 -> 0.13785339 | L25: =E42/E19 -> 0.13785339 | M25: =F42/F19 -> 0.13785339
C26: Coupon | D26: 0.2 | E26: 0.2 | F26: 0.1 | H26: 优惠券的优惠金额数或者百分比 | J26: 其他费用 | K26: 0.02 | L26: 0.02 | M26: 0.02
C27: Coupon Rate（使用率） | D27: 0.7 | E27: 0.5 | F27: 0.4 | H27: 优惠券使用率=Coupon兑换数/总订单,第一次制作的时候需要预估，有两周的数据后可以实际计算； | J27: 退款 | K27: =D17 -> 0.02 | L27: =E17 -> 0.02 | M27: =F17 -> 0.02
C28: Prime Discount（折扣） | D28: 0.05 | E28: 0 | F28: 0 | H28: 会员专项折扣百分比 | J28: 净利率 | K28: =1-SUM(K19:K27) -> -0.20875268 | L28: =1-SUM(L19:L27) -> -0.012205331 | M28: =1-SUM(M19:M27) -> 0.11580024
C29: 总计（人民币） | D29: =IF(D26>0.8,(D24*$K$37+D25*$L$37+D26*D27*D11+D28*D14*D11+0.6*D11*D27)*D15,(D24*$K$37+D25*$L$37+D26*D14*D27*D11+D28*D14*D11+0.6*D11*D27)*D15) -> 10356.078 | E29: =IF(E26>0.8,(E24*$K$37+E25*$L$37+E26*E27*E11+E28*E14*E11+0.6*E11*E27)*E15,(E24*$K$37+E25*$L$37+E26*E14*E27*E11+E28*E14*E11+0.6*E11*E27)*E15) -> 11282.61 | F29: =IF(F26>0.8,(F24*$K$37+F25*$L$37+F26*F27*F11+F28*F14*F11+0.6*F11*F27)*F15,(F24*$K$37+F25*$L$37+F26*F14*F27*F11+F28*F14*F11+0.6*F11*F27)*F15) -> 10970.517 | G29: =SUM(D29:F29) -> 32609.205 | H29: 请注意修改个站点LD,7DD的价格，参考右下方的价格信息
B30: 站内预估数据 | C30: CPC（预估）(美元或其他货币） | D30: 1.8 | E30: 1.6 | F30: 1.4 | H30: 参考类似产品历史数据或者卖家精灵，对CPC值做预估 | J30: 汇率
C31: 转化率（预估） | D31: 0.08 | E31: 0.1 | F31: 0.12 | H31: 结合后台商品探测器的类目关键词转化率和产品本身，对产品做出转化率预估 | J31: US | K31: 7.1
C32: 广告订单成本（每单）(美元或其他货币） | D32: =D30/D31 -> 22.5 | E32: =E30/E31 -> 16 | F32: =F30/F31 -> 11.666667 | H32: 每个广告订单所需要的广告费 | J32: EU | K32: 7.3
C33: 广告订单占比（预估） | D33: 0.5 | E33: 0.4 | F33: 0.3 | H33: 整月广告订单占比的预估值 | J33: UK | K33: 8.4
C34: 广告订单营销比（Acos） | D34: =D32/D14 -> 0.56292219 | E34: =E32/E14 -> 0.40030023 | F34: =F32/F14 -> 0.29188558
B35: 费用 | C35: 站内推广费（人民币） | D35: =D16*D11*D37 -> 14537.25 | E35: =E16*E11*E37 -> 13632 | F35: =F16*F11*F37 -> 12772.9 | G35: =SUM(D35:F35) -> 40942.15 | J35: 站内促销费用明细（当地货币）
C36: 站内推广费（美金） | D36: =D35/$D$15 -> 2047.5 | E36: =E35/$D$15 -> 1920 | F36: =F35/$D$15 -> 1799 | G36: =SUM(D36:F36) -> 5766.5 | J36: 站点 | K36: LD | L36: 7DD
C37: 营销占比 | D37: =D34*D33 -> 0.2814611 | E37: =E34*E33 -> 0.16012009 | F37: =F34*F33 -> 0.087565674 | H37: 广告营销比=ACOS*广告订单占比 | J37: US | K37: 150 | L37: 300
C38: 平台佣金（人民币） | D38: =D16*D11*D39 -> 7747.3851 | E38: =E16*E11*E39 -> 12770.415 | F38: =F16*F11*F39 -> 21879.978 | G38: =SUM(D38:F38) -> 42397.778 | J38: DE | K38: 35 | L38: 70
C39: 平台佣金比例 | D39: 0.15 | E39: 0.15 | F39: 0.15 | J39: UK | K39: 25 | L39: 50
C40: FBA配送费（美元或其他货币） | D40: 5.51 | E40: =D40 -> 5.51 | F40: =E40 -> 5.51 | J40: IT/FR/ES | K40: 20 | L40: 40
C41: FBA配送费（人民币） | D41: =D40*D15 -> 39.121 | E41: =E40*E15 -> 39.121 | F41: =F40*F15 -> 39.121 | H41: 单个产品FBA配送费
...

Sheet 首批与返单囤货数量预测表
B2: 日期 | C2: 月份 | D2: 周 | E2: 天数 | F2: 客单价 | G2: 日总单量 （预计） | H2: 当前库存 | I2: 预计剩余库存 | J2: 到货库存 | L2: 13周销量计划
B3: 44875 | C3: 第一月 | D3: 第一周 | E3: 1 | F3: 39.97 | G3: =VLOOKUP(D3,L:N,3,0) -> 4 | H3: =M21 -> 200 | I3: =H3-G3 -> 196 | L3: 销售时间 | M3: 预计达到小排名 | N3: 日销 | O3: 下单总量
B4: 44876 | C4: 第一月 | D4: 第一周 | E4: 2 | F4: 39.97 | G4: =VLOOKUP(D4,L:N,3,0) -> 4 | H4: =IF(I3<0,0,I3) -> 196 | I4: =IF(H4-G4+J4<0,0,H4-G4+J4) -> 192 | L4: 第一周 | M4: 300 | N4: 4 | O4: =N4*7 -> 28
B5: 44877 | C5: 第一月 | D5: 第一周 | E5: 3 | F5: 39.97 | G5: =VLOOKUP(D5,L:N,3,0) -> 4 | H5: =IF(I4<0,0,I4) -> 192 | I5: =IF(H5-G5+J5<0,0,H5-G5+J5) -> 188 | L5: 第二周 | M5: 250 | N5: 5 | O5: =N5*7 -> 35
B6: 44878 | C6: 第一月 | D6: 第一周 | E6: 4 | F6: 39.97 | G6: =VLOOKUP(D6,L:N,3,0) -> 4 | H6: =IF(I5<0,0,I5) -> 188 | I6: =IF(H6-G6+J6<0,0,H6-G6+J6) -> 184 | L6: 第三周 | M6: 200 | N6: 7 | O6: =N6*7 -> 49
B7: 44879 | C7: 第一月 | D7: 第一周 | E7: 5 | F7: 39.97 | G7: =VLOOKUP(D7,L:N,3,0) -> 4 | H7: =IF(I6<0,0,I6) -> 184 | I7: =IF(H7-G7+J7<0,0,H7-G7+J7) -> 180 | L7: 第四周 | M7: 200 | N7: 7 | O7: =N7*7 -> 49
B8: 44880 | C8: 第一月 | D8: 第一周 | E8: 6 | F8: 39.97 | G8: =VLOOKUP(D8,L:N,3,0) -> 4 | H8: =IF(I7<0,0,I7) -> 180 | I8: =IF(H8-G8+J8<0,0,H8-G8+J8) -> 176 | L8: 第五周 | M8: 180 | N8: 8 | O8: =N8*7 -> 56
B9: 44881 | C9: 第一月 | D9: 第一周 | E9: 7 | F9: 39.97 | G9: =VLOOKUP(D9,L:N,3,0) -> 4 | H9: =IF(I8<0,0,I8) -> 176 | I9: =IF(H9-G9+J9<0,0,H9-G9+J9) -> 172 | L9: 第六周 | M9: 150 | N9: 9 | O9: =N9*7 -> 63
B10: 44882 | C10: 第一月 | D10: 第二周 | E10: 8 | F10: 39.97 | G10: =VLOOKUP(D10,L:N,3,0) -> 5 | H10: =IF(I9<0,0,I9) -> 172 | I10: =IF(H10-G10+J10<0,0,H10-G10+J10) -> 167 | L10: 第七周 | M10: 140 | N10: 9 | O10: =N10*7 -> 63
B11: 44883 | C11: 第一月 | D11: 第二周 | E11: 9 | F11: 39.97 | G11: =VLOOKUP(D11,L:N,3,0) -> 5 | H11: =IF(I10<0,0,I10) -> 167 | I11: =IF(H11-G11+J11<0,0,H11-G11+J11) -> 162 | L11: 第八周 | M11: 100 | N11: 11 | O11: =N11*7 -> 77
B12: 44884 | C12: 第一月 | D12: 第二周 | E12: 10 | F12: 39.97 | G12: =VLOOKUP(D12,L:N,3,0) -> 5 | H12: =IF(I11<0,0,I11) -> 162 | I12: =IF(H12-G12+J12<0,0,H12-G12+J12) -> 157 | L12: 第九周 | M12: 80 | N12: 13 | O12: =N12*7 -> 91
B13: 44885 | C13: 第一月 | D13: 第二周 | E13: 11 | F13: 39.97 | G13: =VLOOKUP(D13,L:N,3,0) -> 5 | H13: =IF(I12<0,0,I12) -> 157 | I13: =IF(H13-G13+J13<0,0,H13-G13+J13) -> 152 | L13: 第十周 | M13: 80 | N13: 13 | O13: =N13*7 -> 91
B14: 44886 | C14: 第一月 | D14: 第二周 | E14: 12 | F14: 39.97 | G14: =VLOOKUP(D14,L:N,3,0) -> 5 | H14: =IF(I13<0,0,I13) -> 152 | I14: =IF(H14-G14+J14<0,0,H14-G14+J14) -> 147 | L14: 第十一周 | M14: 60 | N14: 16 | O14: =N14*7 -> 112
B15: 44887 | C15: 第一月 | D15: 第二周 | E15: 13 | F15: 39.97 | G15: =VLOOKUP(D15,L:N,3,0) -> 5 | H15: =IF(I14<0,0,I14) -> 147 | I15: =IF(H15-G15+J15<0,0,H15-G15+J15) -> 142 | L15: 第十二周 | M15: 60 | N15: 16 | O15: =N15*7 -> 112
B16: 44888 | C16: 第一月 | D16: 第二周 | E16: 14 | F16: 39.97 | G16: =VLOOKUP(D16,L:N,3,0) -> 5 | H16: =IF(I15<0,0,I15) -> 142 | I16: =IF(H16-G16+J16<0,0,H16-G16+J16) -> 137 | L16: 第十三周 | M16: 50 | N16: 25 | O16: =N16*7 -> 175
B17: 44889 | C17: 第一月 | D17: 第三周 | E17: 15 | F17: 39.97 | G17: =VLOOKUP(D17,L:N,3,0) -> 7 | H17: =IF(I16<0,0,I16) -> 137 | I17: =IF(H17-G17+J17<0,0,H17-G17+J17) -> 130 | L17: 汇总 | O17: =SUM(O4:O16) -> 1001
B18: 44890 | C18: 第一月 | D18: 第三周 | E18: 16 | F18: 39.97 | G18: =VLOOKUP(D18,L:N,3,0) -> 7 | H18: =IF(I17<0,0,I17) -> 130 | I18: =IF(H18-G18+J18<0,0,H18-G18+J18) -> 123
B19: 44891 | C19: 第一月 | D19: 第三周 | E19: 17 | F19: 39.97 | G19: =VLOOKUP(D19,L:N,3,0) -> 7 | H19: =IF(I18<0,0,I18) -> 123 | I19: =IF(H19-G19+J19<0,0,H19-G19+J19) -> 116 | L19: 首批+返单下单计划
B20: 44892 | C20: 第一月 | D20: 第三周 | E20: 18 | F20: 39.97 | G20: =VLOOKUP(D20,L:N,3,0) -> 7 | H20: =IF(I19<0,0,I19) -> 116 | I20: =IF(H20-G20+J20<0,0,H20-G20+J20) -> 109 | L20: 批次 | M20: 下单量 | N20: 物流时效 | O20: 物流渠道 | P20: 产品交期 | Q20: 下单时间 | R20: 付款金额 | S20: 交货时间 | T20: 国内离港时间 | U20: 到货时间
B21: 44893 | C21: 第一月 | D21: 第三周 | E21: 19 | F21: 39.97 | G21: =VLOOKUP(D21,L:N,3,0) -> 7 | H21: =IF(I20<0,0,I20) -> 109 | I21: =IF(H21-G21+J21<0,0,H21-G21+J21) -> 102 | L21: 首批 | M21: 200 | N21: =_xlfn.IFS(O21=$L$29,$M$29,O21=$L$30,$M$30,O21=$L$31,$M$31,O21=$L$32,$M$32,O21=$L$33,$M$33) -> 20 | O21: 快递时效 | P21: =$M$27 -> 30 | Q21: 44818 | R21: =M21*$M$28 -> 13800 | S21: =P21+Q21 -> 44848 | T21: =S21+M35 -> 44855 | U21: =T21+N21 -> 44875
B22: 44894 | C22: 第一月 | D22: 第三周 | E22: 20 | F22: 39.97 | G22: =VLOOKUP(D22,L:N,3,0) -> 7 | H22: =IF(I21<0,0,I21) -> 102 | I22: =IF(H22-G22+J22<0,0,H22-G22+J22) -> 95 | L22: 返单 | M22: 480 | N22: =_xlfn.IFS(O22=$L$29,$M$29,O22=$L$30,$M$30,O22=$L$31,$M$31,O22=$L$32,$M$32,O22=$L$33,$M$33) -> 20 | O22: 快递时效 | P22: =$M$27 -> 30 | Q22: =S22-P22 -> 44847 | R22: =M22*$M$28 -> 33120 | S22: =T22-M35 -> 44877 | T22: =U22-N22 -> 44884 | U22: =B32 -> 44904
B23: 44895 | C23: 第一月 | D23: 第三周 | E23: 21 | F23: 39.97 | G23: =VLOOKUP(D23,L:N,3,0) -> 7 | H23: =IF(I22<0,0,I22) -> 95 | I23: =IF(H23-G23+J23<0,0,H23-G23+J23) -> 88 | L23: 第三批 | N23: =_xlfn.IFS(O23=$L$29,$M$29,O23=$L$30,$M$30,O23=$L$31,$M$31,O23=$L$32,$M$32,O23=$L$33,$M$33) -> 20 | O23: 空运时效 | P23: =$M$27 -> 30 | Q23: =S23-P23 -> -50 | R23: =M23*$M$28 -> 0 | S23: =T23-M38 -> -20 | T23: =U23-N23 -> -20
B24: 44896 | C24: 第一月 | D24: 第四周 | E24: 22 | F24: 39.97 | G24: =VLOOKUP(D24,L:N,3,0) -> 7 | H24: =IF(I23<0,0,I23) -> 88 | I24: =IF(H24-G24+J24<0,0,H24-G24+J24) -> 81 | L24: 第四批 | N24: =_xlfn.IFS(O24=$L$29,$M$29,O24=$L$30,$M$30,O24=$L$31,$M$31,O24=$L$32,$M$32,O24=$L$33,$M$33) -> 20 | O24: 快递时效 | P24: =$M$27 -> 30 | Q24: =S24-P24 -> -50 | R24: =M24*$M$28 -> 0 | S24: =T24-M39 -> -20 | T24: =U24-N24 -> -20
B25: 44897 | C25: 第一月 | D25: 第四周 | E25: 23 | F25: 39.97 | G25: =VLOOKUP(D25,L:N,3,0) -> 7 | H25: =IF(I24<0,0,I24) -> 81 | I25: =IF(H25-G25+J25<0,0,H25-G25+J25) -> 74
B26: 44898 | C26: 第一月 | D26: 第四周 | E26: 24 | F26: 39.97 | G26: =VLOOKUP(D26,L:N,3,0) -> 7 | H26: =IF(I25<0,0,I25) -> 74 | I26: =IF(H26-G26+J26<0,0,H26-G26+J26) -> 67 | L26: 基础信息
B27: 44899 | C27: 第一月 | D27: 第四周 | E27: 25 | F27: 39.97 | G27: =VLOOKUP(D27,L:N,3,0) -> 7 | H27: =IF(I26<0,0,I26) -> 67 | I27: =IF(H27-G27+J27<0,0,H27-G27+J27) -> 60 | L27: 产品交期/天 | M27: 30 | N27: 天
B28: 44900 | C28: 第一月 | D28: 第四周 | E28: 26 | F28: 39.97 | G28: =VLOOKUP(D28,L:N,3,0) -> 7 | H28: =IF(I27<0,0,I27) -> 60 | I28: =IF(H28-G28+J28<0,0,H28-G28+J28) -> 53 | L28: 成本 | M28: 69 | N28: 人民币
B29: 44901 | C29: 第一月 | D29: 第四周 | E29: 27 | F29: 39.97 | G29: =VLOOKUP(D29,L:N,3,0) -> 7 | H29: =IF(I28<0,0,I28) -> 53 | I29: =IF(H29-G29+J29<0,0,H29-G29+J29) -> 46 | L29: 快递时效 | M29: 20 | N29: 天
B30: 44902 | C30: 第一月 | D30: 第四周 | E30: 28 | F30: 39.97 | G30: =VLOOKUP(D30,L:N,3,0) -> 7 | H30: =IF(I29<0,0,I29) -> 46 | I30: =IF(H30-G30+J30<0,0,H30-G30+J30) -> 39 | L30: 快船时效 | M30: 30 | N30: 天
B31: 44903 | C31: 第一月 | D31: 第五周 | E31: 29 | F31: 39.97 | G31: =VLOOKUP(D31,L:N,3,0) -> 8 | H31: =IF(I30<0,0,I30) -> 39 | I31: =IF(H31-G31+J31<0,0,H31-G31+J31) -> 31 | L31: 慢船时效 | M31: 40 | N31: 天
B32: 44904 | C32: 第一月 | D32: 第五周 | E32: 30 | F32: 39.97 | G32: =VLOOKUP(D32,L:N,3,0) -> 8 | H32: =IF(I31<0,0,I31) -> 31 | I32: =IF(H32-G32+J32<0,0,H32-G32+J32) -> 23 | L32: 空运时效 | M32: 20 | N32: 天
B33: 44905 | C33: 第二月 | D33: 第五周 | E33: 31 | F33: 39.97 | G33: =VLOOKUP(D33,L:N,3,0) -> 8 | H33: =IF(I32<0,0,I32) -> 23 | I33: =IF(H33-G33+J33<0,0,H33-G33+J33) -> 15 | L33: 卡航 | M33: 40 | N33: 天
B34: 44906 | C34: 第二月 | D34: 第五周 | E34: 32 | F34: 39.97 | G34: =VLOOKUP(D34,L:N,3,0) -> 8 | H34: =IF(I33<0,0,I33) -> 15 | I34: =IF(H34-G34+J34<0,0,H34-G34+J34) -> 7 | L34: 单次补货维持天数 | M34: 60 | N34: 天
B35: 44907 | C35: 第二月 | D35: 第五周 | E35: 33 | F35: 39.97 | G35: =VLOOKUP(D35,L:N,3,0) -> 8 | H35: =IF(I34<0,0,I34) -> 7 | I35: =IF(H35-G35+J35<0,0,H35-G35+J35) -> 0 | L35: 交货后国内处理时间 | M35: 7 | N35: 天
B36: 44908 | C36: 第二月 | D36: 第五周 | E36: 34 | F36: 39.97 | G36: =VLOOKUP(D36,L:N,3,0) -> 8 | H36: =IF(I35<0,0,I35) -> 0 | I36: =IF(H36-G36+J36<0,0,H36-G36+J36) -> 0
B37: 44909 | C37: 第二月 | D37: 第五周 | E37: 35 | F37: 39.97 | G37: =VLOOKUP(D37,L:N,3,0) -> 8 | H37: =IF(I36<0,0,I36) -> 0 | I37: =IF(H37-G37+J37<0,0,H37-G37+J37) -> 0
B38: 44910 | C38: 第二月 | D38: 第六周 | E38: 36 | F38: 39.97 | G38: =VLOOKUP(D38,L:N,3,0) -> 9 | H38: =IF(I37<0,0,I37) -> 0 | I38: =IF(H38-G38+J38<0,0,H38-G38+J38) -> 0
B39: 44911 | C39: 第二月 | D39: 第六周 | E39: 37 | F39: 39.97 | G39: =VLOOKUP(D39,L:N,3,0) -> 9 | H39: =IF(I38<0,0,I38) -> 0 | I39: =IF(H39-G39+J39<0,0,H39-G39+J39) -> 0
B40: 44912 | C40: 第二月 | D40: 第六周 | E40: 38 | F40: 39.97 | G40: =VLOOKUP(D40,L:N,3,0) -> 9 | H40: =IF(I39<0,0,I39) -> 0 | I40: =IF(H40-G40+J40<0,0,H40-G40+J40) -> 0
B41: 44913 | C41: 第二月 | D41: 第六周 | E41: 39 | F41: 39.97 | G41: =VLOOKUP(D41,L:N,3,0) -> 9 | H41: =IF(I40<0,0,I40) -> 0 | I41: =IF(H41-G41+J41<0,0,H41-G41+J41) -> 0
...

Sheet 毛利测算表
B2: 1 | C2: 利润核算表（海运）
B3: 售价阶梯 | C3: 成本结构 | N3: 利润 | O3: 毛利率
C4: 采购成本 | D4: 采购占比 | E4: 头程运费 | F4: 头程占比 | G4: FBA费用 | H4: 交易佣金 | I4: 仓租（淡/旺） | J4: 广告费用 | K4: 汇率折损 | L4: 退款费用 | M4: VAT税
B5: =B6-$B$2 -> 35.97 | C5: =$E$19 -> 9.7279007 | D5: =C5/B5*100% -> 0.27044484 | E5: =$E$20 -> 1.2857747 | F5: =E5/B5*100% -> 0.035745752 | G5: =$C$36 -> 5.4 | H5: =B5*0.15 -> 5.3955 | I5: 0 | J5: 0 | K5: =B5*0.03 -> 1.0791 | L5: =B5*$C$29 -> 0.7194 | M5: 0 | N5: =B5-C5-E5-G5-H5-J5-K5-L5-I5-M5 -> 12.362325 | O5: =N5/B5 -> 0.34368431
B6: =B7-$B$2 -> 36.97 | C6: =$E$19 -> 9.7279007 | D6: =C6/B6*100% -> 0.26312958 | E6: =$E$20 -> 1.2857747 | F6: =E6/B6*100% -> 0.034778867 | G6: =$C$36 -> 5.4 | H6: =B6*0.15 -> 5.5455 | I6: 0 | J6: 0 | K6: =B6*0.03 -> 1.1091 | L6: =B6*$C$29 -> 0.7394 | M6: 0 | N6: =B6-C6-E6-G6-H6-J6-K6-L6-I6-M6 -> 13.162325 | O6: =N6/B6 -> 0.35602717
B7: =B8-$B$2 -> 37.97 | C7: =$E$19 -> 9.7279007 | D7: =C7/B7*100% -> 0.25619965 | E7: =$E$20 -> 1.2857747 | F7: =E7/B7*100% -> 0.03386291 | G7: =$C$36 -> 5.4 | H7: =B7*0.15 -> 5.6955 | I7: 0 | J7: 0 | K7: =B7*0.03 -> 1.1391 | L7: =B7*$C$29 -> 0.7594 | M7: 0 | N7: =B7-C7-E7-G7-H7-J7-K7-L7-I7-M7 -> 13.962325 | O7: =N7/B7 -> 0.3677199
B8: =B9-$B$2 -> 38.97 | C8: =$E$19 -> 9.7279007 | D8: =C8/B8*100% -> 0.24962537 | E8: =$E$20 -> 1.2857747 | F8: =E8/B8*100% -> 0.032993962 | G8: =$C$36 -> 5.4 | H8: =B8*0.15 -> 5.8455 | I8: 0 | J8: 0 | K8: =B8*0.03 -> 1.1691 | L8: =B8*$C$29 -> 0.7794 | M8: 0 | N8: =B8-C8-E8-G8-H8-J8-K8-L8-I8-M8 -> 14.762325 | O8: =N8/B8 -> 0.37881254
B9: =B17 -> 39.97 | C9: =$E$19 -> 9.7279007 | D9: =C9/B9*100% -> 0.24338005 | E9: =$E$20 -> 1.2857747 | F9: =E9/B9*100% -> 0.032168494 | G9: =$C$36 -> 5.4 | H9: =B9*0.15 -> 5.9955 | I9: 0 | J9: 0 | K9: =B9*0.03 -> 1.1991 | L9: =B9*$C$29 -> 0.7994 | M9: 0 | N9: =B9-C9-E9-G9-H9-J9-K9-L9-I9-M9 -> 15.562325 | O9: =N9/B9 -> 0.38935013
B10: =B9+$B$2 -> 40.97 | C10: =$E$19 -> 9.7279007 | D10: =C10/B10*100% -> 0.23743961 | E10: =$E$20 -> 1.2857747 | F10: =E10/B10*100% -> 0.031383322 | G10: =$C$36 -> 5.4 | H10: =B10*0.15 -> 6.1455 | I10: 0 | J10: 0 | K10: =B10*0.03 -> 1.2291 | L10: =B10*$C$29 -> 0.8194 | M10: 0 | N10: =B10-C10-E10-G10-H10-J10-K10-L10-I10-M10 -> 16.362325 | O10: =N10/B10 -> 0.39937331
B11: =B10+$B$2 -> 41.97 | C11: =$E$19 -> 9.7279007 | D11: =C11/B11*100% -> 0.23178224 | E11: =$E$20 -> 1.2857747 | F11: =E11/B11*100% -> 0.030635566 | G11: =$C$36 -> 5.4 | H11: =B11*0.15 -> 6.2955 | I11: 0 | J11: 0 | K11: =B11*0.03 -> 1.2591 | L11: =B11*$C$29 -> 0.8394 | M11: 0 | N11: =B11-C11-E11-G11-H11-J11-K11-L11-I11-M11 -> 17.162325 | O11: =N11/B11 -> 0.40891886
B12: =B11+$B$2 -> 42.97 | C12: =$E$19 -> 9.7279007 | D12: =C12/B12*100% -> 0.2263882 | E12: =$E$20 -> 1.2857747 | F12: =E12/B12*100% -> 0.029922614 | G12: =$C$36 -> 5.4 | H12: =B12*0.15 -> 6.4455 | I12: 0 | J12: 0 | K12: =B12*0.03 -> 1.2891 | L12: =B12*$C$29 -> 0.8594 | M12: 0 | N12: =B12-C12-E12-G12-H12-J12-K12-L12-I12-M12 -> 17.962325 | O12: =N12/B12 -> 0.41802012
B13: =B12+$B$2 -> 43.97 | C13: =$E$19 -> 9.7279007 | D13: =C13/B13*100% -> 0.2212395 | E13: =$E$20 -> 1.2857747 | F13: =E13/B13*100% -> 0.02924209 | G13: =$C$36 -> 5.4 | H13: =B13*0.15 -> 6.5955 | I13: 0 | J13: 0 | K13: =B13*0.03 -> 1.3191 | L13: =B13*$C$29 -> 0.8794 | M13: 0 | N13: =B13-C13-E13-G13-H13-J13-K13-L13-I13-M13 -> 18.762325 | O13: =N13/B13 -> 0.4267074
B14: =B13+$B$2 -> 44.97 | C14: =$E$19 -> 9.7279007 | D14: =C14/B14*100% -> 0.21631979 | E14: =$E$20 -> 1.2857747 | F14: =E14/B14*100% -> 0.028591832 | G14: =$C$36 -> 5.4 | H14: =B14*0.15 -> 6.7455 | I14: 0 | J14: 0 | K14: =B14*0.03 -> 1.3491 | L14: =B14*$C$29 -> 0.8994 | M14: 0 | N14: =B14-C14-E14-G14-H14-J14-K14-L14-I14-M14 -> 19.562325 | O14: =N14/B14 -> 0.43500833
B16: 设定售价 | H16: 利润核算表（空运）
B17: 39.97 | K17: 利润 | L17: 毛利率
C18: 人民币 | E18: 美金 | H18: 采购占比 | I18: 头程运费 | J18: 头程占比
B19: 采购成本 | C19: 69 | E19: =C19/$C$23 -> 9.7279007 | H19: =C5/B5*100% -> 0.27044484 | I19: =$E$21 -> 4.1787678 | J19: =I19/B5*100% -> 0.11617369 | K19: =B5-C5-I19-G5-H5--J5-K5-L5-I5-M5 -> 9.4693315 | L19: =K19/B5 -> 0.26325637
B20: 海运成本 | C20: =MAX(C28*C32,C27*C32) -> 9.12 | E20: =C20/$C$23 -> 1.2857747 | H20: =C6/B6*100% -> 0.26312958 | I20: =$E$21 -> 4.1787678 | J20: =I20/B6*100% -> 0.11303132 | K20: =B6-C6-I20-G6-H6--J6-K6-L6-I6-M6 -> 10.269331 | L20: =K20/B6 -> 0.27777472
B21: 空派成本 | C21: =MAX(C27*C33,C28*C33) -> 29.64 | E21: =C21/$C$23 -> 4.1787678 | H21: =C7/B7*100% -> 0.25619965 | I21: =$E$21 -> 4.1787678 | J21: =I21/B7*100% -> 0.11005446 | K21: =B7-C7-I21-G7-H7--J7-K7-L7-I7-M7 -> 11.069331 | L21: =K21/B7 -> 0.29152835
B22: DHL成本 | C22: =MAX(C34*C27,C34*C28) -> 34.2 | E22: =C22/$C$23 -> 4.8216552 | H22: =C8/B8*100% -> 0.24962537 | I22: =$E$21 -> 4.1787678 | J22: =I22/B8*100% -> 0.10723038 | K22: =B8-C8-I22-G8-H8--J8-K8-L8-I8-M8 -> 11.869331 | L22: =K22/B8 -> 0.30457612
B23: 汇率 | C23: 7.093 | H23: =C9/B9*100% -> 0.24338005 | I23: =$E$21 -> 4.1787678 | J23: =I23/B9*100% -> 0.10454761 | K23: =B9-C9-I23-G9-H9--J9-K9-L9-I9-M9 -> 12.669331 | L23: =K23/B9 -> 0.31697101
B24: 长 | C24: 6 | E24: 厘米 | H24: =C10/B10*100% -> 0.23743961 | I24: =$E$21 -> 4.1787678 | J24: =I24/B10*100% -> 0.1019958 | K24: =B10-C10-I24-G10-H10--J10-K10-L10-I10-M10 -> 13.469331 | L24: =K24/B10 -> 0.32876084
B25: 宽 | C25: 13 | E25: 厘米 | H25: =C11/B11*100% -> 0.23178224 | I25: =$E$21 -> 4.1787678 | J25: =I25/B11*100% -> 0.09956559 | K25: =B11-C11-I25-G11-H11--J11-K11-L11-I11-M11 -> 14.269331 | L25: =K25/B11 -> 0.33998884
B26: 高 | C26: 20 | E26: 厘米 | H26: =C12/B12*100% -> 0.2263882 | I26: =$E$21 -> 4.1787678 | J26: =I26/B12*100% -> 0.097248494 | K26: =B12-C12-I26-G12-H12--J12-K12-L12-I12-M12 -> 15.069331 | L26: =K26/B12 -> 0.35069424
B27: 产品实重 | C27: 0.76 | E27: 千克 | H27: =C13/B13*100% -> 0.2212395 | I27: =$E$21 -> 4.1787678 | J27: =I27/B13*100% -> 0.095036793 | K27: =B13-C13-I27-G13-H13--J13-K13-L13-I13-M13 -> 15.869331 | L27: =K27/B13 -> 0.3609127
B28: 海运体积重 | C28: =C24*C25*C26/6000 -> 0.26 | E28: 千克 | H28: =C14/B14*100% -> 0.21631979 | I28: =$E$21 -> 4.1787678 | J28: =I28/B14*100% -> 0.092923456 | K28: =B14-C14-I28-G14-H14--J14-K14-L14-I14-M14 -> 16.669331 | L28: =K28/B14 -> 0.37067671
B29: 预估退款率 | C29: 0.02
H30: 利润核算表（快递）
B31: 渠道 | C31: 实时价格 | K31: 利润 | L31: 毛利率
B32: 海运价格 | C32: 12 | E32: 元/KG | H32: 采购占比 | I32: 头程运输 | J32: 头程占比
B33: 空派价格 | C33: 39 | E33: 元/KG | H33: =C5/B5*100% -> 0.27044484 | I33: =$E$22 -> 4.8216552 | J33: =I33/B5*100% -> 0.13404657 | K33: =B5-C5-I33-G5-H5--J5-K5-L5-I5-M5 -> 8.8264441 | L33: =K33/B5 -> 0.24538349
B34: 快递价格 | C34: 45 | E34: 元/KG | H34: =C6/B6*100% -> 0.26312958 | I34: =$E$22 -> 4.8216552 | J34: =I34/B6*100% -> 0.13042075 | K34: =B6-C6-I34-G6-H6--J6-K6-L6-I6-M6 -> 9.6264441 | L34: =K34/B6 -> 0.26038529
H35: =C7/B7*100% -> 0.25619965 | I35: =$E$22 -> 4.8216552 | J35: =I35/B7*100% -> 0.12698591 | K35: =B7-C7-I35-G7-H7--J7-K7-L7-I7-M7 -> 10.426444 | L35: =K35/B7 -> 0.27459689
B36: FBA配送费 | C36: 5.4 | H36: =C8/B8*100% -> 0.24962537 | I36: =$E$22 -> 4.8216552 | J36: =I36/B8*100% -> 0.12372736 | K36: =B8-C8-I36-G8-H8--J8-K8-L8-I8-M8 -> 11.226444 | L36: =K36/B8 -> 0.28807914
H37: =C9/B9*100% -> 0.24338005 | I37: =$E$22 -> 4.8216552 | J37: =I37/B9*100% -> 0.12063185 | K37: =B9-C9-I37-G9-H9--J9-K9-L9-I9-M9 -> 12.026444 | L37: =K37/B9 -> 0.30088677
H38: =C10/B10*100% -> 0.23743961 | I38: =$E$22 -> 4.8216552 | J38: =I38/B10*100% -> 0.11768746 | K38: =B10-C10-I38-G10-H10--J10-K10-L10-I10-M10 -> 12.826444 | L38: =K38/B10 -> 0.31306918
H39: =C11/B11*100% -> 0.23178224 | I39: =$E$22 -> 4.8216552 | J39: =I39/B11*100% -> 0.11488337 | K39: =B11-C11-I39-G11-H11--J11-K11-L11-I11-M11 -> 13.626444 | L39: =K39/B11 -> 0.32467105
H40: =C12/B12*100% -> 0.2263882 | I40: =$E$22 -> 4.8216552 | J40: =I40/B12*100% -> 0.1122098 | K40: =B12-C12-I40-G12-H12--J12-K12-L12-I12-M12 -> 14.426444 | L40: =K40/B12 -> 0.33573293
H41: =C13/B13*100% -> 0.2212395 | I41: =$E$22 -> 4.8216552 | J41: =I41/B13*100% -> 0.10965784 | K41: =B13-C13-I41-G13-H13--J13-K13-L13-I13-M13 -> 15.226444 | L41: =K41/B13 -> 0.34629166
H42: =C14/B14*100% -> 0.21631979 | I42: =$E$22 -> 4.8216552 | J42: =I42/B14*100% -> 0.10721937 | K42: =B14-C14-I42-G14-H14--J14-K14-L14-I14-M14 -> 16.026444 | L42: =K42/B14 -> 0.35638079

Sheet 价格策略
B2: 成本(¥) | C2: 头程(¥) | D2: 配送费($） | E2: 汇率
B3: 69 | C3: 39 | D3: 5.83 | E3: 7.09
B5: 新品期价格
B6: 正常 | C6: 售价 | D6: 成本 | E6: 头程 | F6: 佣金 （美金）成交价的15% | G6: 配送费 （美金） | H6: 利润 | I6: 毛利润率 | J6: 总订单 | K6: 正常订单 | L6: 总销售额 | M6: 总毛利 | N6: 退款损失 | O6: 退款率
C7: 35.97 | D7: =B3/E3 -> 9.7320169 | E7: =C3/E3 -> 5.5007052 | F7: =C7*0.15 -> 5.3955 | G7: =D3 -> 5.83 | H7: =C7-D7-E7-F7-G7 -> 9.5117779 | I7: =H7/C7 -> 0.26443642 | J7: 15 | K7: =J7-M10 -> 4.95 | L7: =K7*C7 -> 178.0515 | M7: =H7*K7 -> 47.0833 | N7: =O7*L7 -> 3.56103 | O7: 0.02
B9: 优惠券使用利润 | C9: 售价 | D9: 成本 | E9: 头程 | F9: 优惠券/促销 | G9: 佣金 （美金） | H9: 配送费 （美金） | I9: 优惠券费用 | J9: 毛利 | K9: 毛利率 | L9: 优惠券使用率 | M9: 日均订单 | N9: 总销售额 | O9: 总毛利 | P9: 退款损失 | Q9: 退款率
C10: =C7-C7*F10 -> 25.179 | D10: =D7 -> 9.7320169 | E10: =E7 -> 5.5007052 | F10: 0.3 | G10: =C10*0.15 -> 3.77685 | H10: =G7 -> 5.83 | I10: 0.6 | J10: =C10-D10-E10-G10-H10-I10 -> -0.26057214 | K10: =J10/C10 -> -0.010348788 | L10: 0.67 | M10: =J7*L10 -> 10.05 | N10: =M10*C10 -> 253.04895 | O10: =M10*J10 -> -2.61875 | P10: =Q10*N10 -> 5.060979 | Q10: =O7 -> 0.02
B12: 周期 | C12: 总销售额 | D12: 总毛利 | E12: 广告费 | F12: 退款费 | G12: 净利 | H12: 净利率 | I12: 广销比
B13: 日 | C13: =L7+N10 -> 431.10045 | D13: =M7+O10 -> 44.46455 | E13: 210 | F13: =P10+N7 -> 8.622009 | G13: =D13-E13-F13 -> -174.15746 | H13: =G13/C13 -> -0.40398348 | I13: =E13/C13 -> 0.48712545
B14: 周 | C14: =C13*7 -> 3017.7031 | D14: =D13*7 -> 311.25185 | E14: =E13*7 -> 1470 | F14: =F13*7 -> 60.354063 | G14: =D14-E14-F14 -> -1219.1022 | H14: =G14/C14 -> -0.40398348 | I14: =E14/C14 -> 0.48712545
B15: 旬 | C15: =C13*10 -> 4311.0045 | D15: =D13*10 -> 444.6455 | E15: =E13*10 -> 2100 | F15: =F13*10 -> 86.22009 | G15: =D15-E15-F15 -> -1741.5746 | H15: =G15/C15 -> -0.40398348 | I15: =E15/C15 -> 0.48712545
B16: 半月 | C16: =C13*15 -> 6466.5067 | D16: =D13*15 -> 666.96826 | E16: =E13*15 -> 3150 | F16: =F13*15 -> 129.33014 | G16: =D16-E16-F16 -> -2612.3619 | H16: =G16/C16 -> -0.40398348 | I16: =E16/C16 -> 0.48712545
B17: 月 | C17: =C13*30 -> 12933.013 | D17: =D13*30 -> 1333.9365 | E17: =E13*30 -> 6300 | F17: =F13*30 -> 258.66027 | G17: =D17-E17-F17 -> -5224.7238 | H17: =G17/C17 -> -0.40398348 | I17: =E17/C17 -> 0.48712545
B19: 成熟期价格
B20: 正常 | C20: 售价 | D20: 成本 | E20: 头程 | F20: 佣金 （美金）成交价的15% | G20: 配送费 （美金） | H20: 利润 | I20: 毛利润率 | J20: 总订单 | K20: 正常订单 | L20: 总销售额 | M20: 总毛利 | N20: 退款损失 | O20: 退款率
C21: 39.97 | D21: =B3/E3 -> 9.7320169 | E21: =E7 -> 5.5007052 | F21: =C21*0.15 -> 5.9955 | G21: =D3 -> 5.83 | H21: =C21-D21-E21-F21-G21 -> 12.911778 | I21: =H21/C21 -> 0.32303672 | J21: 40 | K21: =J21-M24 -> 20 | L21: =K21*C21 -> 799.4 | M21: =H21*K21 -> 258.23556 | N21: =O21*L21 -> 15.988 | O21: 0.02
B23: 优惠券使用利润 | C23: 售价 | D23: 成本 | E23: 头程 | F23: 优惠券/促销 | G23: 佣金 （美金） | H23: 配送费 （美金） | I23: 优惠券费用 | J23: 毛利 | K23: 毛利率 | L23: 优惠券使用率 | M23: 日均订单 | N23: 总销售额 | O23: 总毛利 | P23: 退款损失 | Q23: 退款率
C24: =C21-C21*F24 -> 31.976 | D24: =D21 -> 9.7320169 | E24: =E21 -> 5.5007052 | F24: 0.2 | G24: =C24*0.15 -> 4.7964 | H24: =G21 -> 5.83 | I24: 0.6 | J24: =C24-D24-E24-G24-H24-I24 -> 5.5168779 | K24: =J24/C24 -> 0.17253183 | L24: 0.5 | M24: =J21*L24 -> 20 | N24: =M24*C24 -> 639.52 | O24: =M24*J24 -> 110.33756 | P24: =Q24*N24 -> 12.7904 | Q24: =O21 -> 0.02
B26: 周期 | C26: 总销售额 | D26: 总毛利 | E26: 广告费 | F26: 退款费 | G26: 净利 | H26: 净利率 | I26: 广销比
B27: 日 | C27: =L21+N24 -> 1438.92 | D27: =M21+O24 -> 368.57311 | E27: 150 | F27: =P24+N21 -> 28.7784 | G27: =D27-E27-F27 -> 189.79471 | H27: =G27/C27 -> 0.13190081 | I27: =E27/C27 -> 0.10424485
B28: 周 | C28: =C27*7 -> 10072.44 | D28: =D27*7 -> 2580.0118 | E28: =E27*7 -> 1050 | F28: =F27*7 -> 201.4488 | G28: =D28-E28-F28 -> 1328.563 | H28: =G28/C28 -> 0.13190081 | I28: =E28/C28 -> 0.10424485
B29: 旬 | C29: =C27*10 -> 14389.2 | D29: =D27*10 -> 3685.7311 | E29: =E27*10 -> 1500 | F29: =F27*10 -> 287.784 | G29: =D29-E29-F29 -> 1897.9471 | H29: =G29/C29 -> 0.13190081 | I29: =E29/C29 -> 0.10424485
B30: 半月 | C30: =C27*15 -> 21583.8 | D30: =D27*15 -> 5528.5967 | E30: =E27*15 -> 2250 | F30: =F27*15 -> 431.676 | G30: =D30-E30-F30 -> 2846.9207 | H30: =G30/C30 -> 0.13190081 | I30: =E30/C30 -> 0.10424485
B31: 月 | C31: =C27*30 -> 43167.6 | D31: =D27*30 -> 11057.193 | E31: =E27*30 -> 4500 | F31: =F27*30 -> 863.352 | G31: =D31-E31-F31 -> 5693.8414 | H31: =G31/C31 -> 0.13190081 | I31: =E31/C31 -> 0.10424485
