Workbook

Sheet 总体数据一览
A1: 日期 | B1: 曝光量 | C1: 点击数 | D1: 点击率 | E1: 平均点击花费 | F1: 总花费 | G1: 销售额 | H1: ACOS
A2: 43770 | B2: =IF(SUMIF(#REF!,总体数据一览!A2,#REF!)=0,"",SUMIF(#REF!,总体数据一览!A2,#REF!)) -> #REF! | C2: =IF(SUMIF(#REF!,总体数据一览!A2,#REF!)=0,"",SUMIF(#REF!,总体数据一览!A2,#REF!)) -> #REF! | D2: =IFERROR(ROUND(C2/B2,4),"") | E2: =IFERROR(ROUND(F2/C2,2),"") | F2: =IF(SUMIF(#REF!,总体数据一览!A2,#REF!)=0,"",SUMIF(#REF!,总体数据一览!A2,#REF!)) -> #REF! | G2: =IFERROR(IF(B2="","",SUMIF(#REF!,总体数据一览!A2,#REF!))+IF(B2="","",SUMIF(#REF!,总体数据一览!A2,#REF!)),"") | H2: =IFERROR(ROUND(F2/G2,2),"")
A3: 43771 | B3: =IF(SUMIF(#REF!,总体数据一览!A3,#REF!)=0,"",SUMIF(#REF!,总体数据一览!A3,#REF!)) -> #REF! | C3: =IF(SUMIF(#REF!,总体数据一览!A3,#REF!)=0,"",SUMIF(#REF!,总体数据一览!A3,#REF!)) -> #REF! | D3: =IFERROR(ROUND(C3/B3,4),"") | E3: =IFERROR(ROUND(F3/C3,2),"") | F3: =IF(SUMIF(#REF!,总体数据一览!A3,#REF!)=0,"",SUMIF(#REF!,总体数据一览!A3,#REF!)) -> #REF! | G3: =IFERROR(IF(B3="","",SUMIF(#REF!,总体数据一览!A3,#REF!))+IF(B3="","",SUMIF(#REF!,总体数据一览!A3,#REF!)),"") | H3: =IFERROR(ROUND(F3/G3,2),"")
A4: 43772 | B4: =IF(SUMIF(#REF!,总体数据一览!A4,#REF!)=0,"",SUMIF(#REF!,总体数据一览!A4,#REF!)) -> #REF! | C4: =IF(SUMIF(#REF!,总体数据一览!A4,#REF!)=0,"",SUMIF(#REF!,总体数据一览!A4,#REF!)) -> #REF! | D4: =IFERROR(ROUND(C4/B4,4),"") | E4: =IFERROR(ROUND(F4/C4,2),"") | F4: =IF(SUMIF(#REF!,总体数据一览!A4,#REF!)=0,"",SUMIF(#REF!,总体数据一览!A4,#REF!)) -> #REF! | G4: =IFERROR(IF(B4="","",SUMIF(#REF!,总体数据一览!A4,#REF!))+IF(B4="","",SUMIF(#REF!,总体数据一览!A4,#REF!)),"") | H4: =IFERROR(ROUND(F4/G4,2),"")
A5: 43773 | B5: =IF(SUMIF(#REF!,总体数据一览!A5,#REF!)=0,"",SUMIF(#REF!,总体数据一览!A5,#REF!)) -> #REF! | C5: =IF(SUMIF(#REF!,总体数据一览!A5,#REF!)=0,"",SUMIF(#REF!,总体数据一览!A5,#REF!)) -> #REF! | D5: =IFERROR(ROUND(C5/B5,4),"") | E5: =IFERROR(ROUND(F5/C5,2),"") | F5: =IF(SUMIF(#REF!,总体数据一览!A5,#REF!)=0,"",SUMIF(#REF!,总体数据一览!A5,#REF!)) -> #REF! | G5: =IFERROR(IF(B5="","",SUMIF(#REF!,总体数据一览!A5,#REF!))+IF(B5="","",SUMIF(#REF!,总体数据一览!A5,#REF!)),"") | H5: =IFERROR(ROUND(F5/G5,2),"")
A6: 43774 | B6: =IF(SUMIF(#REF!,总体数据一览!A6,#REF!)=0,"",SUMIF(#REF!,总体数据一览!A6,#REF!)) -> #REF! | C6: =IF(SUMIF(#REF!,总体数据一览!A6,#REF!)=0,"",SUMIF(#REF!,总体数据一览!A6,#REF!)) -> #REF! | D6: =IFERROR(ROUND(C6/B6,4),"") | E6: =IFERROR(ROUND(F6/C6,2),"") | F6: =IF(SUMIF(#REF!,总体数据一览!A6,#REF!)=0,"",SUMIF(#REF!,总体数据一览!A6,#REF!)) -> #REF! | G6: =IFERROR(IF(B6="","",SUMIF(#REF!,总体数据一览!A6,#REF!))+IF(B6="","",SUMIF(#REF!,总体数据一览!A6,#REF!)),"") | H6: =IFERROR(ROUND(F6/G6,2),"")
A7: 43775 | B7: =IF(SUMIF(#REF!,总体数据一览!A7,#REF!)=0,"",SUMIF(#REF!,总体数据一览!A7,#REF!)) -> #REF! | C7: =IF(SUMIF(#REF!,总体数据一览!A7,#REF!)=0,"",SUMIF(#REF!,总体数据一览!A7,#REF!)) -> #REF! | D7: =IFERROR(ROUND(C7/B7,4),"") | E7: =IFERROR(ROUND(F7/C7,2),"") | F7: =IF(SUMIF(#REF!,总体数据一览!A7,#REF!)=0,"",SUMIF(#REF!,总体数据一览!A7,#REF!)) -> #REF! | G7: =IFERROR(IF(B7="","",SUMIF(#REF!,总体数据一览!A7,#REF!))+IF(B7="","",SUMIF(#REF!,总体数据一览!A7,#REF!)),"") | H7: =IFERROR(ROUND(F7/G7,2),"")
A8: 43776 | B8: =IF(SUMIF(#REF!,总体数据一览!A8,#REF!)=0,"",SUMIF(#REF!,总体数据一览!A8,#REF!)) -> #REF! | C8: =IF(SUMIF(#REF!,总体数据一览!A8,#REF!)=0,"",SUMIF(#REF!,总体数据一览!A8,#REF!)) -> #REF! | D8: =IFERROR(ROUND(C8/B8,4),"") | E8: =IFERROR(ROUND(F8/C8,2),"") | F8: =IF(SUMIF(#REF!,总体数据一览!A8,#REF!)=0,"",SUMIF(#REF!,总体数据一览!A8,#REF!)) -> #REF! | G8: =IFERROR(IF(B8="","",SUMIF(#REF!,总体数据一览!A8,#REF!))+IF(B8="","",SUMIF(#REF!,总体数据一览!A8,#REF!)),"") | H8: =IFERROR(ROUND(F8/G8,2),"")
A9: 43777 | B9: =IF(SUMIF(#REF!,总体数据一览!A9,#REF!)=0,"",SUMIF(#REF!,总体数据一览!A9,#REF!)) -> #REF! | C9: =IF(SUMIF(#REF!,总体数据一览!A9,#REF!)=0,"",SUMIF(#REF!,总体数据一览!A9,#REF!)) -> #REF! | D9: =IFERROR(ROUND(C9/B9,4),"") | E9: =IFERROR(ROUND(F9/C9,2),"") | F9: =IF(SUMIF(#REF!,总体数据一览!A9,#REF!)=0,"",SUMIF(#REF!,总体数据一览!A9,#REF!)) -> #REF! | G9: =IFERROR(IF(B9="","",SUMIF(#REF!,总体数据一览!A9,#REF!))+IF(B9="","",SUMIF(#REF!,总体数据一览!A9,#REF!)),"") | H9: =IFERROR(ROUND(F9/G9,2),"")
A10: 43778 | B10: =IF(SUMIF(#REF!,总体数据一览!A10,#REF!)=0,"",SUMIF(#REF!,总体数据一览!A10,#REF!)) -> #REF! | C10: =IF(SUMIF(#REF!,总体数据一览!A10,#REF!)=0,"",SUMIF(#REF!,总体数据一览!A10,#REF!)) -> #REF! | D10: =IFERROR(ROUND(C10/B10,4),"") | E10: =IFERROR(ROUND(F10/C10,2),"") | F10: =IF(SUMIF(#REF!,总体数据一览!A10,#REF!)=0,"",SUMIF(#REF!,总体数据一览!A10,#REF!)) -> #REF! | G10: =IFERROR(IF(B10="","",SUMIF(#REF!,总体数据一览!A10,#REF!))+IF(B10="","",SUMIF(#REF!,总体数据一览!A10,#REF!)),"") | H10: =IFERROR(ROUND(F10/G10,2),"")
A11: 43779 | B11: =IF(SUMIF(#REF!,总体数据一览!A11,#REF!)=0,"",SUMIF(#REF!,总体数据一览!A11,#REF!)) -> #REF! | C11: =IF(SUMIF(#REF!,总体数据一览!A11,#REF!)=0,"",SUMIF(#REF!,总体数据一览!A11,#REF!)) -> #REF! | D11: =IFERROR(ROUND(C11/B11,4),"") | E11: =IFERROR(ROUND(F11/C11,2),"") | F11: =IF(SUMIF(#REF!,总体数据一览!A11,#REF!)=0,"",SUMIF(#REF!,总体数据一览!A11,#REF!)) -> #REF! | G11: =IFERROR(IF(B11="","",SUMIF(#REF!,总体数据一览!A11,#REF!))+IF(B11="","",SUMIF(#REF!,总体数据一览!A11,#REF!)),"") | H11: =IFERROR(ROUND(F11/G11,2),"")
A12: 43780 | B12: =IF(SUMIF(#REF!,总体数据一览!A12,#REF!)=0,"",SUMIF(#REF!,总体数据一览!A12,#REF!)) -> #REF! | C12: =IF(SUMIF(#REF!,总体数据一览!A12,#REF!)=0,"",SUMIF(#REF!,总体数据一览!A12,#REF!)) -> #REF! | D12: =IFERROR(ROUND(C12/B12,4),"") | E12: =IFERROR(ROUND(F12/C12,2),"") | F12: =IF(SUMIF(#REF!,总体数据一览!A12,#REF!)=0,"",SUMIF(#REF!,总体数据一览!A12,#REF!)) -> #REF! | G12: =IFERROR(IF(B12="","",SUMIF(#REF!,总体数据一览!A12,#REF!))+IF(B12="","",SUMIF(#REF!,总体数据一览!A12,#REF!)),"") | H12: =IFERROR(ROUND(F12/G12,2),"")
A13: 43781 | B13: =IF(SUMIF(#REF!,总体数据一览!A13,#REF!)=0,"",SUMIF(#REF!,总体数据一览!A13,#REF!)) -> #REF! | C13: =IF(SUMIF(#REF!,总体数据一览!A13,#REF!)=0,"",SUMIF(#REF!,总体数据一览!A13,#REF!)) -> #REF! | D13: =IFERROR(ROUND(C13/B13,4),"") | E13: =IFERROR(ROUND(F13/C13,2),"") | F13: =IF(SUMIF(#REF!,总体数据一览!A13,#REF!)=0,"",SUMIF(#REF!,总体数据一览!A13,#REF!)) -> #REF! | G13: =IFERROR(IF(B13="","",SUMIF(#REF!,总体数据一览!A13,#REF!))+IF(B13="","",SUMIF(#REF!,总体数据一览!A13,#REF!)),"") | H13: =IFERROR(ROUND(F13/G13,2),"")
... A34: 43802 | B34: =IF(SUMIF(#REF!,总体数据一览!A34,#REF!)=0,"",SUMIF(#REF!,总体数据一览!A34,#REF!)) -> #REF! | C34: =IF(SUMIF(#REF!,总体数据一览!A34,#REF!)=0,"",SUMIF(#REF!,总体数据一览!A34,#REF!)) -> #REF! | D34: =IFERROR(ROUND(C34/B34,4),"") | E34: =IFERROR(ROUND(F34/C34,2),"") | F34: =IF(SUMIF(#REF!,总体数据一览!A34,#REF!)=0,"",SUMIF(#REF!,总体数据一览!A34,#REF!)) -> #REF! | G34: =IFERROR(IF(B34="","",SUMIF(#REF!,总体数据一览!A34,#REF!))+IF(B34="","",SUMIF(#REF!,总体数据一览!A34,#REF!)),"") | H34: =IFERROR(ROUND(F34/G34,2),"")
B35: =IF(SUMIF(#REF!,总体数据一览!A35,#REF!)=0,"",SUMIF(#REF!,总体数据一览!A35,#REF!)) -> #REF! | C35: =IF(SUMIF(#REF!,总体数据一览!A35,#REF!)=0,"",SUMIF(#REF!,总体数据一览!A35,#REF!)) -> #REF! | D35: =IFERROR(ROUND(C35/B35,4),"") | E35: =IFERROR(ROUND(F35/C35,2),"") | F35: =IF(SUMIF(#REF!,总体数据一览!A35,#REF!)=0,"",SUMIF(#REF!,总体数据一览!A35,#REF!)) -> #REF! | G35: =IFERROR(IF(B35="","",SUMIF(#REF!,总体数据一览!A35,#REF!))+IF(B35="","",SUMIF(#REF!,总体数据一览!A35,#REF!)),"") | H35: =IFERROR(ROUND(F35/G35,2),"")
B36: =IF(SUMIF(#REF!,总体数据一览!A36,#REF!)=0,"",SUMIF(#REF!,总体数据一览!A36,#REF!)) -> #REF! | C36: =IF(SUMIF(#REF!,总体数据一览!A36,#REF!)=0,"",SUMIF(#REF!,总体数据一览!A36,#REF!)) -> #REF! | D36: =IFERROR(ROUND(C36/B36,4),"") | E36: =IFERROR(ROUND(F36/C36,2),"") | F36: =IF(SUMIF(#REF!,总体数据一览!A36,#REF!)=0,"",SUMIF(#REF!,总体数据一览!A36,#REF!)) -> #REF! | G36: =IFERROR(IF(B36="","",SUMIF(#REF!,总体数据一览!A36,#REF!))+IF(B36="","",SUMIF(#REF!,总体数据一览!A36,#REF!)),"") | H36: =IFERROR(ROUND(F36/G36,2),"")
B37: =IF(SUMIF(#REF!,总体数据一览!A37,#REF!)=0,"",SUMIF(#REF!,总体数据一览!A37,#REF!)) -> #REF! | C37: =IF(SUMIF(#REF!,总体数据一览!A37,#REF!)=0,"",SUMIF(#REF!,总体数据一览!A37,#REF!)) -> #REF! | D37: =IFERROR(ROUND(C37/B37,4),"") | E37: =IFERROR(ROUND(F37/C37,2),"") | F37: =IF(SUMIF(#REF!,总体数据一览!A37,#REF!)=0,"",SUMIF(#REF!,总体数据一览!A37,#REF!)) -> #REF! | G37: =IFERROR(IF(B37="","",SUMIF(#REF!,总体数据一览!A37,#REF!))+IF(B37="","",SUMIF(#REF!,总体数据一览!A37,#REF!)),"") | H37: =IFERROR(ROUND(F37/G37,2),"")
B38: =IF(SUMIF(#REF!,总体数据一览!A38,#REF!)=0,"",SUMIF(#REF!,总体数据一览!A38,#REF!)) -> #REF! | C38: =IF(SUMIF(#REF!,总体数据一览!A38,#REF!)=0,"",SUMIF(#REF!,总体数据一览!A38,#REF!)) -> #REF! | D38: =IFERROR(ROUND(C38/B38,4),"") | E38: =IFERROR(ROUND(F38/C38,2),"") | F38: =IF(SUMIF(#REF!,总体数据一览!A38,#REF!)=0,"",SUMIF(#REF!,总体数据一览!A38,#REF!)) -> #REF! | G38: =IFERROR(IF(B38="","",SUMIF(#REF!,总体数据一览!A38,#REF!))+IF(B38="","",SUMIF(#REF!,总体数据一览!A38,#REF!)),"") | H38: =IFERROR(ROUND(F38/G38,2),"")
B39: =IF(SUMIF(#REF!,总体数据一览!A39,#REF!)=0,"",SUMIF(#REF!,总体数据一览!A39,#REF!)) -> #REF! | C39: =IF(SUMIF(#REF!,总体数据一览!A39,#REF!)=0,"",SUMIF(#REF!,总体数据一览!A39,#REF!)) -> #REF! | D39: =IFERROR(ROUND(C39/B39,4),"") | E39: =IFERROR(ROUND(F39/C39,2),"") | F39: =IF(SUMIF(#REF!,总体数据一览!A39,#REF!)=0,"",SUMIF(#REF!,总体数据一览!A39,#REF!)) -> #REF! | G39: =IFERROR(IF(B39="","",SUMIF(#REF!,总体数据一览!A39,#REF!))+IF(B39="","",SUMIF(#REF!,总体数据一览!A39,#REF!)),"") | H39: =IFERROR(ROUND(F39/G39,2),"")
B40: =IF(SUMIF(#REF!,总体数据一览!A40,#REF!)=0,"",SUMIF(#REF!,总体数据一览!A40,#REF!)) -> #REF! | C40: =IF(SUMIF(#REF!,总体数据一览!A40,#REF!)=0,"",SUMIF(#REF!,总体数据一览!A40,#REF!)) -> #REF! | D40: =IFERROR(ROUND(C40/B40,4),"") | E40: =IFERROR(ROUND(F40/C40,2),"") | F40: =IF(SUMIF(#REF!,总体数据一览!A40,#REF!)=0,"",SUMIF(#REF!,总体数据一览!A40,#REF!)) -> #REF! | G40: =IFERROR(IF(B40="","",SUMIF(#REF!,总体数据一览!A40,#REF!))+IF(B40="","",SUMIF(#REF!,总体数据一览!A40,#REF!)),"") | H40: =IFERROR(ROUND(F40/G40,2),"")
B41: =IF(SUMIF(#REF!,总体数据一览!A41,#REF!)=0,"",SUMIF(#REF!,总体数据一览!A41,#REF!)) -> #REF! | C41: =IF(SUMIF(#REF!,总体数据一览!A41,#REF!)=0,"",SUMIF(#REF!,总体数据一览!A41,#REF!)) -> #REF! | D41: =IFERROR(ROUND(C41/B41,4),"") | E41: =IFERROR(ROUND(F41/C41,2),"") | F41: =IF(SUMIF(#REF!,总体数据一览!A41,#REF!)=0,"",SUMIF(#REF!,总体数据一览!A41,#REF!)) -> #REF! | G41: =IFERROR(IF(B41="","",SUMIF(#REF!,总体数据一览!A41,#REF!))+IF(B41="","",SUMIF(#REF!,总体数据一览!A41,#REF!)),"") | H41: =IFERROR(ROUND(F41/G41,2),"")
B42: =IF(SUMIF(#REF!,总体数据一览!A42,#REF!)=0,"",SUMIF(#REF!,总体数据一览!A42,#REF!)) -> #REF! | C42: =IF(SUMIF(#REF!,总体数据一览!A42,#REF!)=0,"",SUMIF(#REF!,总体数据一览!A42,#REF!)) -> #REF! | D42: =IFERROR(ROUND(C42/B42,4),"") | E42: =IFERROR(ROUND(F42/C42,2),"") | F42: =IF(SUMIF(#REF!,总体数据一览!A42,#REF!)=0,"",SUMIF(#REF!,总体数据一览!A42,#REF!)) -> #REF! | G42: =IFERROR(IF(B42="","",SUMIF(#REF!,总体数据一览!A42,#REF!))+IF(B42="","",SUMIF(#REF!,总体数据一览!A42,#REF!)),"") | H42: =IFERROR(ROUND(F42/G42,2),"")
B43: =IF(SUMIF(#REF!,总体数据一览!A43,#REF!)=0,"",SUMIF(#REF!,总体数据一览!A43,#REF!)) -> #REF! | C43: =IF(SUMIF(#REF!,总体数据一览!A43,#REF!)=0,"",SUMIF(#REF!,总体数据一览!A43,#REF!)) -> #REF! | D43: =IFERROR(ROUND(C43/B43,4),"") | E43: =IFERROR(ROUND(F43/C43,2),"") | F43: =IF(SUMIF(#REF!,总体数据一览!A43,#REF!)=0,"",SUMIF(#REF!,总体数据一览!A43,#REF!)) -> #REF! | G43: =IFERROR(IF(B43="","",SUMIF(#REF!,总体数据一览!A43,#REF!))+IF(B43="","",SUMIF(#REF!,总体数据一览!A43,#REF!)),"") | H43: =IFERROR(ROUND(F43/G43,2),"")
B44: =IF(SUMIF(#REF!,总体数据一览!A44,#REF!)=0,"",SUMIF(#REF!,总体数据一览!A44,#REF!)) -> #REF! | C44: =IF(SUMIF(#REF!,总体数据一览!A44,#REF!)=0,"",SUMIF(#REF!,总体数据一览!A44,#REF!)) -> #REF! | D44: =IFERROR(ROUND(C44/B44,4),"") | E44: =IFERROR(ROUND(F44/C44,2),"") | F44: =IF(SUMIF(#REF!,总体数据一览!A44,#REF!)=0,"",SUMIF(#REF!,总体数据一览!A44,#REF!)) -> #REF! | G44: =IFERROR(IF(B44="","",SUMIF(#REF!,总体数据一览!A44,#REF!))+IF(B44="","",SUMIF(#REF!,总体数据一览!A44,#REF!)),"") | H44: =IFERROR(ROUND(F44/G44,2),"")
B45: =IF(SUMIF(#REF!,总体数据一览!A45,#REF!)=0,"",SUMIF(#REF!,总体数据一览!A45,#REF!)) -> #REF! | C45: =IF(SUMIF(#REF!,总体数据一览!A45,#REF!)=0,"",SUMIF(#REF!,总体数据一览!A45,#REF!)) -> #REF! | D45: =IFERROR(ROUND(C45/B45,4),"") | E45: =IFERROR(ROUND(F45/C45,2),"") | F45: =IF(SUMIF(#REF!,总体数据一览!A45,#REF!)=0,"",SUMIF(#REF!,总体数据一览!A45,#REF!)) -> #REF! | G45: =IFERROR(IF(B45="","",SUMIF(#REF!,总体数据一览!A45,#REF!))+IF(B45="","",SUMIF(#REF!,总体数据一览!A45,#REF!)),"") | H45: =IFERROR(ROUND(F45/G45,2),"")
B46: =IF(SUMIF(#REF!,总体数据一览!A46,#REF!)=0,"",SUMIF(#REF!,总体数据一览!A46,#REF!)) -> #REF! | C46: =IF(SUMIF(#REF!,总体数据一览!A46,#REF!)=0,"",SUMIF(#REF!,总体数据一览!A46,#REF!)) -> #REF! | D46: =IFERROR(ROUND(C46/B46,4),"") | E46: =IFERROR(ROUND(F46/C46,2),"") | F46: =IF(SUMIF(#REF!,总体数据一览!A46,#REF!)=0,"",SUMIF(#REF!,总体数据一览!A46,#REF!)) -> #REF! | G46: =IFERROR(IF(B46="","",SUMIF(#REF!,总体数据一览!A46,#REF!))+IF(B46="","",SUMIF(#REF!,总体数据一览!A46,#REF!)),"") | H46: =IFERROR(ROUND(F46/G46,2),"")
... B921: =IF(SUMIF(#REF!,总体数据一览!A921,#REF!)=0,"",SUMIF(#REF!,总体数据一览!A921,#REF!)) -> #REF! | C921: =IF(SUMIF(#REF!,总体数据一览!A921,#REF!)=0,"",SUMIF(#REF!,总体数据一览!A921,#REF!)) -> #REF! | D921: =IFERROR(ROUND(C921/B921,4),"") | E921: =IFERROR(ROUND(F921/C921,2),"") | F921: =IF(SUMIF(#REF!,总体数据一览!A921,#REF!)=0,"",SUMIF(#REF!,总体数据一览!A921,#REF!)) -> #REF! | G921: =IFERROR(IF(B921="","",SUMIF(#REF!,总体数据一览!A921,#REF!))+IF(B921="","",SUMIF(#REF!,总体数据一览!A921,#REF!)),"") | H921: =IFERROR(ROUND(F921/G921,2),"")

Sheet 关键词词频统计
A1: 开始时间 | L1: 开始时间
A2: 44927 | L2: 43770
A3: 结束时间 | L3: 结束时间
A4: 45291 | L4: 43802
A5: 客户搜索词 | B5: 曝光量 | C5: 点击次数 | D5: 点击率 | E5: 转化率 | F5: 订单数 | G5: 销售额 | H5: 花费 | I5: ACOS | J5: 评级 | K5: 所属广告组 | L5: 客户搜索词 | M5: 曝光量 | N5: 点击次数 | O5: 点击率 | P5: 转化率 | Q5: 订单数 | R5: 销售额 | S5: 花费 | T5: ACOS | U5: 评级 | V5: 所属广告组
B6: {=SUM(IF(#REF!=A6,IF(#REF!>=关键词词频统计!$A$2,IF(#REF!<=关键词词频统计!$A$4,#REF!,0),0),0))} -> #REF! | C6: {=SUM(IF(#REF!=A6,IF(#REF!>=关键词词频统计!$A$2,IF(#REF!<=关键词词频统计!$A$4,#REF!,0),0),0))} -> #REF! | D6: =IFERROR(C6/B6,0) -> 0 | E6: =IFERROR(F6/C6,0) -> 0 | F6: {=SUM(IF(#REF!=A6,IF(#REF!>=关键词词频统计!$A$2,IF(#REF!<=关键词词频统计!$A$4,#REF!,0),0),0))} -> #REF! | G6: {=SUM(IF(#REF!=A6,IF(#REF!>=关键词词频统计!$A$2,IF(#REF!<=关键词词频统计!$A$4,#REF!,0),0),0))} -> #REF! | H6: {=SUM(IF(#REF!=A6,IF(#REF!>=关键词词频统计!$A$2,IF(#REF!<=关键词词频统计!$A$4,#REF!,0),0),0))} -> #REF! | I6: =IF(IFERROR(H6/G6,0)=0,"",IFERROR(H6/G6,0)) | J6: =IF(AND(C6>=10,E6<=0.05),"极差",IF(AND(C6>=10,0.05<E6,E6<=0.1),"差",IF(AND(C6>=10,0.1<E6,E6<=0.15),"良",IF(AND(C6>=10,E6>0.15),"优","点击次数少于10次没有参考性")))) -> #REF! | K6: =IFERROR(INDEX(#REF!,MATCH(关键词词频统计!A6,#REF!,0)),"") | M6: {=SUM(IF(#REF!=L6,IF(#REF!>=$L$2,IF(#REF!<=$L$4,#REF!,0),0),0))} -> #REF! | N6: {=SUM(IF(#REF!=L6,IF(#REF!>=$L$2,IF(#REF!<=$L$4,#REF!,0),0),0))} -> #REF! | O6: =IFERROR(N6/M6,0) -> 0 | P6: =IFERROR(Q6/N6,0) -> 0 | Q6: {=SUM(IF(#REF!=L6,IF(#REF!>=$L$2,IF(#REF!<=$L$4,#REF!,0),0),0))} -> #REF! | R6: {=SUM(IF(#REF!=L6,IF(#REF!>=$L$2,IF(#REF!<=$L$4,#REF!,0),0),0))} -> #REF! | S6: {=SUM(IF(#REF!=L6,IF(#REF!>=$L$2,IF(#REF!<=$L$4,#REF!,0),0),0))} -> #REF! | T6: =IF(IFERROR(S6/R6,0)=0,"",IFERROR(S6/R6,0)) | U6: =IF(AND(N6>=10,P6<=0.05),"极差",IF(AND(N6>=10,0.05<P6,P6<=0.1),"差",IF(AND(N6>=10,0.1<P6,P6<=0.15),"良",IF(AND(N6>=10,P6>0.15),"优","点击次数少于10次没有参考性")))) -> #REF! | V6: =IFERROR(INDEX(#REF!,MATCH(关键词词频统计!L6,#REF!,0)),"")
B7: {=SUM(IF(#REF!=A7,IF(#REF!>=关键词词频统计!$A$2,IF(#REF!<=关键词词频统计!$A$4,#REF!,0),0),0))} -> #REF! | C7: {=SUM(IF(#REF!=A7,IF(#REF!>=关键词词频统计!$A$2,IF(#REF!<=关键词词频统计!$A$4,#REF!,0),0),0))} -> #REF! | D7: =IFERROR(C7/B7,0) -> 0 | E7: =IFERROR(F7/C7,0) -> 0 | F7: {=SUM(IF(#REF!=A7,IF(#REF!>=关键词词频统计!$A$2,IF(#REF!<=关键词词频统计!$A$4,#REF!,0),0),0))} -> #REF! | G7: {=SUM(IF(#REF!=A7,IF(#REF!>=关键词词频统计!$A$2,IF(#REF!<=关键词词频统计!$A$4,#REF!,0),0),0))} -> #REF! | H7: {=SUM(IF(#REF!=A7,IF(#REF!>=关键词词频统计!$A$2,IF(#REF!<=关键词词频统计!$A$4,#REF!,0),0),0))} -> #REF! | I7: =IF(IFERROR(H7/G7,0)=0,"",IFERROR(H7/G7,0)) | J7: =IF(AND(C7>=10,E7<=0.05),"极差",IF(AND(C7>=10,0.05<E7,E7<=0.1),"差",IF(AND(C7>=10,0.1<E7,E7<=0.15),"良",IF(AND(C7>=10,E7>0.15),"优","点击次数少于10次没有参考性")))) -> #REF! | K7: =IFERROR(INDEX(#REF!,MATCH(关键词词频统计!A7,#REF!,0)),"") | M7: {=SUM(IF(#REF!=L7,IF(#REF!>=$L$2,IF(#REF!<=$L$4,#REF!,0),0),0))} -> #REF! | N7: {=SUM(IF(#REF!=L7,IF(#REF!>=$L$2,IF(#REF!<=$L$4,#REF!,0),0),0))} -> #REF! | O7: =IFERROR(N7/M7,0) -> 0 | P7: =IFERROR(Q7/N7,0) -> 0 | Q7: {=SUM(IF(#REF!=L7,IF(#REF!>=$L$2,IF(#REF!<=$L$4,#REF!,0),0),0))} -> #REF! | R7: {=SUM(IF(#REF!=L7,IF(#REF!>=$L$2,IF(#REF!<=$L$4,#REF!,0),0),0))} -> #REF! | S7: {=SUM(IF(#REF!=L7,IF(#REF!>=$L$2,IF(#REF!<=$L$4,#REF!,0),0),0))} -> #REF! | T7: =IF(IFERROR(S7/R7,0)=0,"",IFERROR(S7/R7,0)) | U7: =IF(AND(N7>=10,P7<=0.05),"极差",IF(AND(N7>=10,0.05<P7,P7<=0.1),"差",IF(AND(N7>=10,0.1<P7,P7<=0.15),"良",IF(AND(N7>=10,P7>0.15),"优","点击次数少于10次没有参考性")))) -> #REF! | V7: =IFERROR(INDEX(#REF!,MATCH(关键词词频统计!L7,#REF!,0)),"")
B8: {=SUM(IF(#REF!=A8,IF(#REF!>=关键词词频统计!$A$2,IF(#REF!<=关键词词频统计!$A$4,#REF!,0),0),0))} -> #REF! | C8: {=SUM(IF(#REF!=A8,IF(#REF!>=关键词词频统计!$A$2,IF(#REF!<=关键词词频统计!$A$4,#REF!,0),0),0))} -> #REF! | D8: =IFERROR(C8/B8,0) -> 0 | E8: =IFERROR(F8/C8,0) -> 0 | F8: {=SUM(IF(#REF!=A8,IF(#REF!>=关键词词频统计!$A$2,IF(#REF!<=关键词词频统计!$A$4,#REF!,0),0),0))} -> #REF! | G8: {=SUM(IF(#REF!=A8,IF(#REF!>=关键词词频统计!$A$2,IF(#REF!<=关键词词频统计!$A$4,#REF!,0),0),0))} -> #REF! | H8: {=SUM(IF(#REF!=A8,IF(#REF!>=关键词词频统计!$A$2,IF(#REF!<=关键词词频统计!$A$4,#REF!,0),0),0))} -> #REF! | I8: =IF(IFERROR(H8/G8,0)=0,"",IFERROR(H8/G8,0)) | J8: =IF(AND(C8>=10,E8<=0.05),"极差",IF(AND(C8>=10,0.05<E8,E8<=0.1),"差",IF(AND(C8>=10,0.1<E8,E8<=0.15),"良",IF(AND(C8>=10,E8>0.15),"优","点击次数少于10次没有参考性")))) -> #REF! | K8: =IFERROR(INDEX(#REF!,MATCH(关键词词频统计!A8,#REF!,0)),"") | M8: {=SUM(IF(#REF!=L8,IF(#REF!>=$L$2,IF(#REF!<=$L$4,#REF!,0),0),0))} -> #REF! | N8: {=SUM(IF(#REF!=L8,IF(#REF!>=$L$2,IF(#REF!<=$L$4,#REF!,0),0),0))} -> #REF! | O8: =IFERROR(N8/M8,0) -> 0 | P8: =IFERROR(Q8/N8,0) -> 0 | Q8: {=SUM(IF(#REF!=L8,IF(#REF!>=$L$2,IF(#REF!<=$L$4,#REF!,0),0),0))} -> #REF! | R8: {=SUM(IF(#REF!=L8,IF(#REF!>=$L$2,IF(#REF!<=$L$4,#REF!,0),0),0))} -> #REF! | S8: {=SUM(IF(#REF!=L8,IF(#REF!>=$L$2,IF(#REF!<=$L$4,#REF!,0),0),0))} -> #REF! | T8: =IF(IFERROR(S8/R8,0)=0,"",IFERROR(S8/R8,0)) | U8: =IF(AND(N8>=10,P8<=0.05),"极差",IF(AND(N8>=10,0.05<P8,P8<=0.1),"差",IF(AND(N8>=10,0.1<P8,P8<=0.15),"良",IF(AND(N8>=10,P8>0.15),"优","点击次数少于10次没有参考性")))) -> #REF! | V8: =IFERROR(INDEX(#REF!,MATCH(关键词词频统计!L8,#REF!,0)),"")
B9: {=SUM(IF(#REF!=A9,IF(#REF!>=关键词词频统计!$A$2,IF(#REF!<=关键词词频统计!$A$4,#REF!,0),0),0))} -> #REF! | C9: {=SUM(IF(#REF!=A9,IF(#REF!>=关键词词频统计!$A$2,IF(#REF!<=关键词词频统计!$A$4,#REF!,0),0),0))} -> #REF! | D9: =IFERROR(C9/B9,0) -> 0 | E9: =IFERROR(F9/C9,0) -> 0 | F9: {=SUM(IF(#REF!=A9,IF(#REF!>=关键词词频统计!$A$2,IF(#REF!<=关键词词频统计!$A$4,#REF!,0),0),0))} -> #REF! | G9: {=SUM(IF(#REF!=A9,IF(#REF!>=关键词词频统计!$A$2,IF(#REF!<=关键词词频统计!$A$4,#REF!,0),0),0))} -> #REF! | H9: {=SUM(IF(#REF!=A9,IF(#REF!>=关键词词频统计!$A$2,IF(#REF!<=关键词词频统计!$A$4,#REF!,0),0),0))} -> #REF! | I9: =IF(IFERROR(H9/G9,0)=0,"",IFERROR(H9/G9,0)) | J9: =IF(AND(C9>=10,E9<=0.05),"极差",IF(AND(C9>=10,0.05<E9,E9<=0.1),"差",IF(AND(C9>=10,0.1<E9,E9<=0.15),"良",IF(AND(C9>=10,E9>0.15),"优","点击次数少于10次没有参考性")))) -> #REF! | K9: =IFERROR(INDEX(#REF!,MATCH(关键词词频统计!A9,#REF!,0)),"") | M9: {=SUM(IF(#REF!=L9,IF(#REF!>=$L$2,IF(#REF!<=$L$4,#REF!,0),0),0))} -> #REF! | N9: {=SUM(IF(#REF!=L9,IF(#REF!>=$L$2,IF(#REF!<=$L$4,#REF!,0),0),0))} -> #REF! | O9: =IFERROR(N9/M9,0) -> 0 | P9: =IFERROR(Q9/N9,0) -> 0 | Q9: {=SUM(IF(#REF!=L9,IF(#REF!>=$L$2,IF(#REF!<=$L$4,#REF!,0),0),0))} -> #REF! | R9: {=SUM(IF(#REF!=L9,IF(#REF!>=$L$2,IF(#REF!<=$L$4,#REF!,0),0),0))} -> #REF! | S9: {=SUM(IF(#REF!=L9,IF(#REF!>=$L$2,IF(#REF!<=$L$4,#REF!,0),0),0))} -> #REF! | T9: =IF(IFERROR(S9/R9,0)=0,"",IFERROR(S9/R9,0)) | U9: =IF(AND(N9>=10,P9<=0.05),"极差",IF(AND(N9>=10,0.05<P9,P9<=0.1),"差",IF(AND(N9>=10,0.1<P9,P9<=0.15),"良",IF(AND(N9>=10,P9>0.15),"优","点击次数少于10次没有参考性")))) -> #REF! | V9: =IFERROR(INDEX(#REF!,MATCH(关键词词频统计!L9,#REF!,0)),"")
B10: {=SUM(IF(#REF!=A10,IF(#REF!>=关键词词频统计!$A$2,IF(#REF!<=关键词词频统计!$A$4,#REF!,0),0),0))} -> #REF! | C10: {=SUM(IF(#REF!=A10,IF(#REF!>=关键词词频统计!$A$2,IF(#REF!<=关键词词频统计!$A$4,#REF!,0),0),0))} -> #REF! | D10: =IFERROR(C10/B10,0) -> 0 | E10: =IFERROR(F10/C10,0) -> 0 | F10: {=SUM(IF(#REF!=A10,IF(#REF!>=关键词词频统计!$A$2,IF(#REF!<=关键词词频统计!$A$4,#REF!,0),0),0))} -> #REF! | G10: {=SUM(IF(#REF!=A10,IF(#REF!>=关键词词频统计!$A$2,IF(#REF!<=关键词词频统计!$A$4,#REF!,0),0),0))} -> #REF! | H10: {=SUM(IF(#REF!=A10,IF(#REF!>=关键词词频统计!$A$2,IF(#REF!<=关键词词频统计!$A$4,#REF!,0),0),0))} -> #REF! | I10: =IF(IFERROR(H10/G10,0)=0,"",IFERROR(H10/G10,0)) | J10: =IF(AND(C10>=10,E10<=0.05),"极差",IF(AND(C10>=10,0.05<E10,E10<=0.1),"差",IF(AND(C10>=10,0.1<E10,E10<=0.15),"良",IF(AND(C10>=10,E10>0.15),"优","点击次数少于10次没有参考性")))) -> #REF! | K10: =IFERROR(INDEX(#REF!,MATCH(关键词词频统计!A10,#REF!,0)),"") | M10: {=SUM(IF(#REF!=L10,IF(#REF!>=$L$2,IF(#REF!<=$L$4,#REF!,0),0),0))} -> #REF! | N10: {=SUM(IF(#REF!=L10,IF(#REF!>=$L$2,IF(#REF!<=$L$4,#REF!,0),0),0))} -> #REF! | O10: =IFERROR(N10/M10,0) -> 0 | P10: =IFERROR(Q10/N10,0) -> 0 | Q10: {=SUM(IF(#REF!=L10,IF(#REF!>=$L$2,IF(#REF!<=$L$4,#REF!,0),0),0))} -> #REF! | R10: {=SUM(IF(#REF!=L10,IF(#REF!>=$L$2,IF(#REF!<=$L$4,#REF!,0),0),0))} -> #REF! | S10: {=SUM(IF(#REF!=L10,IF(#REF!>=$L$2,IF(#REF!<=$L$4,#REF!,0),0),0))} -> #REF! | T10: =IF(IFERROR(S10/R10,0)=0,"",IFERROR(S10/R10,0)) | U10: =IF(AND(N10>=10,P10<=0.05),"极差",IF(AND(N10>=10,0.05<P10,P10<=0.1),"差",IF(AND(N10>=10,0.1<P10,P10<=0.15),"良",IF(AND(N10>=10,P10>0.15),"优","点击次数少于10次没有参考性")))) -> #REF! | V10: =IFERROR(INDEX(#REF!,MATCH(关键词词频统计!L10,#REF!,0)),"")
B11: {=SUM(IF(#REF!=A11,IF(#REF!>=关键词词频统计!$A$2,IF(#REF!<=关键词词频统计!$A$4,#REF!,0),0),0))} -> #REF! | C11: {=SUM(IF(#REF!=A11,IF(#REF!>=关键词词频统计!$A$2,IF(#REF!<=关键词词频统计!$A$4,#REF!,0),0),0))} -> #REF! | D11: =IFERROR(C11/B11,0) -> 0 | E11: =IFERROR(F11/C11,0) -> 0 | F11: {=SUM(IF(#REF!=A11,IF(#REF!>=关键词词频统计!$A$2,IF(#REF!<=关键词词频统计!$A$4,#REF!,0),0),0))} -> #REF! | G11: {=SUM(IF(#REF!=A11,IF(#REF!>=关键词词频统计!$A$2,IF(#REF!<=关键词词频统计!$A$4,#REF!,0),0),0))} -> #REF! | H11: {=SUM(IF(#REF!=A11,IF(#REF!>=关键词词频统计!$A$2,IF(#REF!<=关键词词频统计!$A$4,#REF!,0),0),0))} -> #REF! | I11: =IF(IFERROR(H11/G11,0)=0,"",IFERROR(H11/G11,0)) | J11: =IF(AND(C11>=10,E11<=0.05),"极差",IF(AND(C11>=10,0.05<E11,E11<=0.1),"差",IF(AND(C11>=10,0.1<E11,E11<=0.15),"良",IF(AND(C11>=10,E11>0.15),"优","点击次数少于10次没有参考性")))) -> #REF! | K11: =IFERROR(INDEX(#REF!,MATCH(关键词词频统计!A11,#REF!,0)),"") | M11: {=SUM(IF(#REF!=L11,IF(#REF!>=$L$2,IF(#REF!<=$L$4,#REF!,0),0),0))} -> #REF! | N11: {=SUM(IF(#REF!=L11,IF(#REF!>=$L$2,IF(#REF!<=$L$4,#REF!,0),0),0))} -> #REF! | O11: =IFERROR(N11/M11,0) -> 0 | P11: =IFERROR(Q11/N11,0) -> 0 | Q11: {=SUM(IF(#REF!=L11,IF(#REF!>=$L$2,IF(#REF!<=$L$4,#REF!,0),0),0))} -> #REF! | R11: {=SUM(IF(#REF!=L11,IF(#REF!>=$L$2,IF(#REF!<=$L$4,#REF!,0),0),0))} -> #REF! | S11: {=SUM(IF(#REF!=L11,IF(#REF!>=$L$2,IF(#REF!<=$L$4,#REF!,0),0),0))} -> #REF! | T11: =IF(IFERROR(S11/R11,0)=0,"",IFERROR(S11/R11,0)) | U11: =IF(AND(N11>=10,P11<=0.05),"极差",IF(AND(N11>=10,0.05<P11,P11<=0.1),"差",IF(AND(N11>=10,0.1<P11,P11<=0.15),"良",IF(AND(N11>=10,P11>0.15),"优","点击次数少于10次没有参考性")))) -> #REF! | V11: =IFERROR(INDEX(#REF!,MATCH(关键词词频统计!L11,#REF!,0)),"")
B12: {=SUM(IF(#REF!=A12,IF(#REF!>=关键词词频统计!$A$2,IF(#REF!<=关键词词频统计!$A$4,#REF!,0),0),0))} -> #REF! | C12: {=SUM(IF(#REF!=A12,IF(#REF!>=关键词词频统计!$A$2,IF(#REF!<=关键词词频统计!$A$4,#REF!,0),0),0))} -> #REF! | D12: =IFERROR(C12/B12,0) -> 0 | E12: =IFERROR(F12/C12,0) -> 0 | F12: {=SUM(IF(#REF!=A12,IF(#REF!>=关键词词频统计!$A$2,IF(#REF!<=关键词词频统计!$A$4,#REF!,0),0),0))} -> #REF! | G12: {=SUM(IF(#REF!=A12,IF(#REF!>=关键词词频统计!$A$2,IF(#REF!<=关键词词频统计!$A$4,#REF!,0),0),0))} -> #REF! | H12: {=SUM(IF(#REF!=A12,IF(#REF!>=关键词词频统计!$A$2,IF(#REF!<=关键词词频统计!$A$4,#REF!,0),0),0))} -> #REF! | I12: =IF(IFERROR(H12/G12,0)=0,"",IFERROR(H12/G12,0)) | J12: =IF(AND(C12>=10,E12<=0.05),"极差",IF(AND(C12>=10,0.05<E12,E12<=0.1),"差",IF(AND(C12>=10,0.1<E12,E12<=0.15),"良",IF(AND(C12>=10,E12>0.15),"优","点击次数少于10次没有参考性")))) -> #REF! | K12: =IFERROR(INDEX(#REF!,MATCH(关键词词频统计!A12,#REF!,0)),"") | M12: {=SUM(IF(#REF!=L12,IF(#REF!>=$L$2,IF(#REF!<=$L$4,#REF!,0),0),0))} -> #REF! | N12: {=SUM(IF(#REF!=L12,IF(#REF!>=$L$2,IF(#REF!<=$L$4,#REF!,0),0),0))} -> #REF! | O12: =IFERROR(N12/M12,0) -> 0 | P12: =IFERROR(Q12/N12,0) -> 0 | Q12: {=SUM(IF(#REF!=L12,IF(#REF!>=$L$2,IF(#REF!<=$L$4,#REF!,0),0),0))} -> #REF! | R12: {=SUM(IF(#REF!=L12,IF(#REF!>=$L$2,IF(#REF!<=$L$4,#REF!,0),0),0))} -> #REF! | S12: {=SUM(IF(#REF!=L12,IF(#REF!>=$L$2,IF(#REF!<=$L$4,#REF!,0),0),0))} -> #REF! | T12: =IF(IFERROR(S12/R12,0)=0,"",IFERROR(S12/R12,0)) | U12: =IF(AND(N12>=10,P12<=0.05),"极差",IF(AND(N12>=10,0.05<P12,P12<=0.1),"差",IF(AND(N12>=10,0.1<P12,P12<=0.15),"良",IF(AND(N12>=10,P12>0.15),"优","点击次数少于10次没有参考性")))) -> #REF! | V12: =IFERROR(INDEX(#REF!,MATCH(关键词词频统计!L12,#REF!,0)),"")
B13: {=SUM(IF(#REF!=A13,IF(#REF!>=关键词词频统计!$A$2,IF(#REF!<=关键词词频统计!$A$4,#REF!,0),0),0))} -> #REF! | C13: {=SUM(IF(#REF!=A13,IF(#REF!>=关键词词频统计!$A$2,IF(#REF!<=关键词词频统计!$A$4,#REF!,0),0),0))} -> #REF! | D13: =IFERROR(C13/B13,0) -> 0 | E13: =IFERROR(F13/C13,0) -> 0 | F13: {=SUM(IF(#REF!=A13,IF(#REF!>=关键词词频统计!$A$2,IF(#REF!<=关键词词频统计!$A$4,#REF!,0),0),0))} -> #REF! | G13: {=SUM(IF(#REF!=A13,IF(#REF!>=关键词词频统计!$A$2,IF(#REF!<=关键词词频统计!$A$4,#REF!,0),0),0))} -> #REF! | H13: {=SUM(IF(#REF!=A13,IF(#REF!>=关键词词频统计!$A$2,IF(#REF!<=关键词词频统计!$A$4,#REF!,0),0),0))} -> #REF! | I13: =IF(IFERROR(H13/G13,0)=0,"",IFERROR(H13/G13,0)) | J13: =IF(AND(C13>=10,E13<=0.05),"极差",IF(AND(C13>=10,0.05<E13,E13<=0.1),"差",IF(AND(C13>=10,0.1<E13,E13<=0.15),"良",IF(AND(C13>=10,E13>0.15),"优","点击次数少于10次没有参考性")))) -> #REF! | K13: =IFERROR(INDEX(#REF!,MATCH(关键词词频统计!A13,#REF!,0)),"") | M13: {=SUM(IF(#REF!=L13,IF(#REF!>=$L$2,IF(#REF!<=$L$4,#REF!,0),0),0))} -> #REF! | N13: {=SUM(IF(#REF!=L13,IF(#REF!>=$L$2,IF(#REF!<=$L$4,#REF!,0),0),0))} -> #REF! | O13: =IFERROR(N13/M13,0) -> 0 | P13: =IFERROR(Q13/N13,0) -> 0 | Q13: {=SUM(IF(#REF!=L13,IF(#REF!>=$L$2,IF(#REF!<=$L$4,#REF!,0),0),0))} -> #REF! | R13: {=SUM(IF(#REF!=L13,IF(#REF!>=$L$2,IF(#REF!<=$L$4,#REF!,0),0),0))} -> #REF! | S13: {=SUM(IF(#REF!=L13,IF(#REF!>=$L$2,IF(#REF!<=$L$4,#REF!,0),0),0))} -> #REF! | T13: =IF(IFERROR(S13/R13,0)=0,"",IFERROR(S13/R13,0)) | U13: =IF(AND(N13>=10,P13<=0.05),"极差",IF(AND(N13>=10,0.05<P13,P13<=0.1),"差",IF(AND(N13>=10,0.1<P13,P13<=0.15),"良",IF(AND(N13>=10,P13>0.15),"优","点击次数少于10次没有参考性")))) -> #REF! | V13: =IFERROR(INDEX(#REF!,MATCH(关键词词频统计!L13,#REF!,0)),"")
B14: {=SUM(IF(#REF!=A14,IF(#REF!>=关键词词频统计!$A$2,IF(#REF!<=关键词词频统计!$A$4,#REF!,0),0),0))} -> #REF! | C14: {=SUM(IF(#REF!=A14,IF(#REF!>=关键词词频统计!$A$2,IF(#REF!<=关键词词频统计!$A$4,#REF!,0),0),0))} -> #REF! | D14: =IFERROR(C14/B14,0) -> 0 | E14: =IFERROR(F14/C14,0) -> 0 | F14: {=SUM(IF(#REF!=A14,IF(#REF!>=关键词词频统计!$A$2,IF(#REF!<=关键词词频统计!$A$4,#REF!,0),0),0))} -> #REF! | G14: {=SUM(IF(#REF!=A14,IF(#REF!>=关键词词频统计!$A$2,IF(#REF!<=关键词词频统计!$A$4,#REF!,0),0),0))} -> #REF! | H14: =SUM(IF(#REF!=A14,IF(#REF!>=关键词词频统计!$A$2,IF(#REF!<=关键词词频统计!$A$4,#REF!,0),0),0)) -> #REF! | I14: =IF(IFERROR(H14/G14,0)=0,"",IFERROR(H14/G14,0)) | J14: =IF(AND(C14>=10,E14<=0.05),"极差",IF(AND(C14>=10,0.05<E14,E14<=0.1),"差",IF(AND(C14>=10,0.1<E14,E14<=0.15),"良",IF(AND(C14>=10,E14>0.15),"优","点击次数少于10次没有参考性")))) -> #REF! | K14: =IFERROR(INDEX(#REF!,MATCH(关键词词频统计!A14,#REF!,0)),"") | M14: {=SUM(IF(#REF!=L14,IF(#REF!>=$L$2,IF(#REF!<=$L$4,#REF!,0),0),0))} -> #REF! | N14: {=SUM(IF(#REF!=L14,IF(#REF!>=$L$2,IF(#REF!<=$L$4,#REF!,0),0),0))} -> #REF! | O14: =IFERROR(N14/M14,0) -> 0 | P14: =IFERROR(Q14/N14,0) -> 0 | Q14: {=SUM(IF(#REF!=L14,IF(#REF!>=$L$2,IF(#REF!<=$L$4,#REF!,0),0),0))} -> #REF! | R14: {=SUM(IF(#REF!=L14,IF(#REF!>=$L$2,IF(#REF!<=$L$4,#REF!,0),0),0))} -> #REF! | S14: {=SUM(IF(#REF!=L14,IF(#REF!>=$L$2,IF(#REF!<=$L$4,#REF!,0),0),0))} -> #REF! | T14: =IF(IFERROR(S14/R14,0)=0,"",IFERROR(S14/R14,0)) | U14: =IF(AND(N14>=10,P14<=0.05),"极差",IF(AND(N14>=10,0.05<P14,P14<=0.1),"差",IF(AND(N14>=10,0.1<P14,P14<=0.15),"良",IF(AND(N14>=10,P14>0.15),"优","点击次数少于10次没有参考性")))) -> #REF! | V14: =IFERROR(INDEX(#REF!,MATCH(关键词词频统计!L14,#REF!,0)),"")
B15: {=SUM(IF(#REF!=A15,IF(#REF!>=关键词词频统计!$A$2,IF(#REF!<=关键词词频统计!$A$4,#REF!,0),0),0))} -> #REF! | C15: {=SUM(IF(#REF!=A15,IF(#REF!>=关键词词频统计!$A$2,IF(#REF!<=关键词词频统计!$A$4,#REF!,0),0),0))} -> #REF! | D15: =IFERROR(C15/B15,0) -> 0 | E15: =IFERROR(F15/C15,0) -> 0 | F15: {=SUM(IF(#REF!=A15,IF(#REF!>=关键词词频统计!$A$2,IF(#REF!<=关键词词频统计!$A$4,#REF!,0),0),0))} -> #REF! | G15: {=SUM(IF(#REF!=A15,IF(#REF!>=关键词词频统计!$A$2,IF(#REF!<=关键词词频统计!$A$4,#REF!,0),0),0))} -> #REF! | H15: {=SUM(IF(#REF!=A15,IF(#REF!>=关键词词频统计!$A$2,IF(#REF!<=关键词词频统计!$A$4,#REF!,0),0),0))} -> #REF! | I15: =IF(IFERROR(H15/G15,0)=0,"",IFERROR(H15/G15,0)) | J15: =IF(AND(C15>=10,E15<=0.05),"极差",IF(AND(C15>=10,0.05<E15,E15<=0.1),"差",IF(AND(C15>=10,0.1<E15,E15<=0.15),"良",IF(AND(C15>=10,E15>0.15),"优","点击次数少于10次没有参考性")))) -> #REF! | K15: =IFERROR(INDEX(#REF!,MATCH(关键词词频统计!A15,#REF!,0)),"") | M15: {=SUM(IF(#REF!=L15,IF(#REF!>=$L$2,IF(#REF!<=$L$4,#REF!,0),0),0))} -> #REF! | N15: {=SUM(IF(#REF!=L15,IF(#REF!>=$L$2,IF(#REF!<=$L$4,#REF!,0),0),0))} -> #REF! | O15: =IFERROR(N15/M15,0) -> 0 | P15: =IFERROR(Q15/N15,0) -> 0 | Q15: {=SUM(IF(#REF!=L15,IF(#REF!>=$L$2,IF(#REF!<=$L$4,#REF!,0),0),0))} -> #REF! | R15: {=SUM(IF(#REF!=L15,IF(#REF!>=$L$2,IF(#REF!<=$L$4,#REF!,0),0),0))} -> #REF! | S15: {=SUM(IF(#REF!=L15,IF(#REF!>=$L$2,IF(#REF!<=$L$4,#REF!,0),0),0))} -> #REF! | T15: =IF(IFERROR(S15/R15,0)=0,"",IFERROR(S15/R15,0)) | U15: =IF(AND(N15>=10,P15<=0.05),"极差",IF(AND(N15>=10,0.05<P15,P15<=0.1),"差",IF(AND(N15>=10,0.1<P15,P15<=0.15),"良",IF(AND(N15>=10,P15>0.15),"优","点击次数少于10次没有参考性")))) -> #REF! | V15: =IFERROR(INDEX(#REF!,MATCH(关键词词频统计!L15,#REF!,0)),"")
B16: {=SUM(IF(#REF!=A16,IF(#REF!>=关键词词频统计!$A$2,IF(#REF!<=关键词词频统计!$A$4,#REF!,0),0),0))} -> #REF! | C16: {=SUM(IF(#REF!=A16,IF(#REF!>=关键词词频统计!$A$2,IF(#REF!<=关键词词频统计!$A$4,#REF!,0),0),0))} -> #REF! | D16: =IFERROR(C16/B16,0) -> 0 | E16: =IFERROR(F16/C16,0) -> 0 | F16: {=SUM(IF(#REF!=A16,IF(#REF!>=关键词词频统计!$A$2,IF(#REF!<=关键词词频统计!$A$4,#REF!,0),0),0))} -> #REF! | G16: {=SUM(IF(#REF!=A16,IF(#REF!>=关键词词频统计!$A$2,IF(#REF!<=关键词词频统计!$A$4,#REF!,0),0),0))} -> #REF! | H16: {=SUM(IF(#REF!=A16,IF(#REF!>=关键词词频统计!$A$2,IF(#REF!<=关键词词频统计!$A$4,#REF!,0),0),0))} -> #REF! | I16: =IF(IFERROR(H16/G16,0)=0,"",IFERROR(H16/G16,0)) | J16: =IF(AND(C16>=10,E16<=0.05),"极差",IF(AND(C16>=10,0.05<E16,E16<=0.1),"差",IF(AND(C16>=10,0.1<E16,E16<=0.15),"良",IF(AND(C16>=10,E16>0.15),"优","点击次数少于10次没有参考性")))) -> #REF! | K16: =IFERROR(INDEX(#REF!,MATCH(关键词词频统计!A16,#REF!,0)),"") | M16: {=SUM(IF(#REF!=L16,IF(#REF!>=$L$2,IF(#REF!<=$L$4,#REF!,0),0),0))} -> #REF! | N16: {=SUM(IF(#REF!=L16,IF(#REF!>=$L$2,IF(#REF!<=$L$4,#REF!,0),0),0))} -> #REF! | O16: =IFERROR(N16/M16,0) -> 0 | P16: =IFERROR(Q16/N16,0) -> 0 | Q16: {=SUM(IF(#REF!=L16,IF(#REF!>=$L$2,IF(#REF!<=$L$4,#REF!,0),0),0))} -> #REF! | R16: {=SUM(IF(#REF!=L16,IF(#REF!>=$L$2,IF(#REF!<=$L$4,#REF!,0),0),0))} -> #REF! | S16: {=SUM(IF(#REF!=L16,IF(#REF!>=$L$2,IF(#REF!<=$L$4,#REF!,0),0),0))} -> #REF! | T16: =IF(IFERROR(S16/R16,0)=0,"",IFERROR(S16/R16,0)) | U16: =IF(AND(N16>=10,P16<=0.05),"极差",IF(AND(N16>=10,0.05<P16,P16<=0.1),"差",IF(AND(N16>=10,0.1<P16,P16<=0.15),"良",IF(AND(N16>=10,P16>0.15),"优","点击次数少于10次没有参考性")))) -> #REF! | V16: =IFERROR(INDEX(#REF!,MATCH(关键词词频统计!L16,#REF!,0)),"")
B17: {=SUM(IF(#REF!=A17,IF(#REF!>=关键词词频统计!$A$2,IF(#REF!<=关键词词频统计!$A$4,#REF!,0),0),0))} -> #REF! | C17: {=SUM(IF(#REF!=A17,IF(#REF!>=关键词词频统计!$A$2,IF(#REF!<=关键词词频统计!$A$4,#REF!,0),0),0))} -> #REF! | D17: =IFERROR(C17/B17,0) -> 0 | E17: =IFERROR(F17/C17,0) -> 0 | F17: {=SUM(IF(#REF!=A17,IF(#REF!>=关键词词频统计!$A$2,IF(#REF!<=关键词词频统计!$A$4,#REF!,0),0),0))} -> #REF! | G17: {=SUM(IF(#REF!=A17,IF(#REF!>=关键词词频统计!$A$2,IF(#REF!<=关键词词频统计!$A$4,#REF!,0),0),0))} -> #REF! | H17: {=SUM(IF(#REF!=A17,IF(#REF!>=关键词词频统计!$A$2,IF(#REF!<=关键词词频统计!$A$4,#REF!,0),0),0))} -> #REF! | I17: =IF(IFERROR(H17/G17,0)=0,"",IFERROR(H17/G17,0)) | J17: =IF(AND(C17>=10,E17<=0.05),"极差",IF(AND(C17>=10,0.05<E17,E17<=0.1),"差",IF(AND(C17>=10,0.1<E17,E17<=0.15),"良",IF(AND(C17>=10,E17>0.15),"优","点击次数少于10次没有参考性")))) -> #REF! | K17: =IFERROR(INDEX(#REF!,MATCH(关键词词频统计!A17,#REF!,0)),"") | M17: {=SUM(IF(#REF!=L17,IF(#REF!>=$L$2,IF(#REF!<=$L$4,#REF!,0),0),0))} -> #REF! | N17: {=SUM(IF(#REF!=L17,IF(#REF!>=$L$2,IF(#REF!<=$L$4,#REF!,0),0),0))} -> #REF! | O17: =IFERROR(N17/M17,0) -> 0 | P17: =IFERROR(Q17/N17,0) -> 0 | Q17: {=SUM(IF(#REF!=L17,IF(#REF!>=$L$2,IF(#REF!<=$L$4,#REF!,0),0),0))} -> #REF! | R17: {=SUM(IF(#REF!=L17,IF(#REF!>=$L$2,IF(#REF!<=$L$4,#REF!,0),0),0))} -> #REF! | S17: {=SUM(IF(#REF!=L17,IF(#REF!>=$L$2,IF(#REF!<=$L$4,#REF!,0),0),0))} -> #REF! | T17: =IF(IFERROR(S17/R17,0)=0,"",IFERROR(S17/R17,0)) | U17: =IF(AND(N17>=10,P17<=0.05),"极差",IF(AND(N17>=10,0.05<P17,P17<=0.1),"差",IF(AND(N17>=10,0.1<P17,P17<=0.15),"良",IF(AND(N17>=10,P17>0.15),"优","点击次数少于10次没有参考性")))) -> #REF! | V17: =IFERROR(INDEX(#REF!,MATCH(关键词词频统计!L17,#REF!,0)),"")
B18: {=SUM(IF(#REF!=A18,IF(#REF!>=关键词词频统计!$A$2,IF(#REF!<=关键词词频统计!$A$4,#REF!,0),0),0))} -> #REF! | C18: {=SUM(IF(#REF!=A18,IF(#REF!>=关键词词频统计!$A$2,IF(#REF!<=关键词词频统计!$A$4,#REF!,0),0),0))} -> #REF! | D18: =IFERROR(C18/B18,0) -> 0 | E18: =IFERROR(F18/C18,0) -> 0 | F18: {=SUM(IF(#REF!=A18,IF(#REF!>=关键词词频统计!$A$2,IF(#REF!<=关键词词频统计!$A$4,#REF!,0),0),0))} -> #REF! | G18: {=SUM(IF(#REF!=A18,IF(#REF!>=关键词词频统计!$A$2,IF(#REF!<=关键词词频统计!$A$4,#REF!,0),0),0))} -> #REF! | H18: {=SUM(IF(#REF!=A18,IF(#REF!>=关键词词频统计!$A$2,IF(#REF!<=关键词词频统计!$A$4,#REF!,0),0),0))} -> #REF! | I18: =IF(IFERROR(H18/G18,0)=0,"",IFERROR(H18/G18,0)) | J18: =IF(AND(C18>=10,E18<=0.05),"极差",IF(AND(C18>=10,0.05<E18,E18<=0.1),"差",IF(AND(C18>=10,0.1<E18,E18<=0.15),"良",IF(AND(C18>=10,E18>0.15),"优","点击次数少于10次没有参考性")))) -> #REF! | K18: =IFERROR(INDEX(#REF!,MATCH(关键词词频统计!A18,#REF!,0)),"") | M18: {=SUM(IF(#REF!=L18,IF(#REF!>=$L$2,IF(#REF!<=$L$4,#REF!,0),0),0))} -> #REF! | N18: {=SUM(IF(#REF!=L18,IF(#REF!>=$L$2,IF(#REF!<=$L$4,#REF!,0),0),0))} -> #REF! | O18: =IFERROR(N18/M18,0) -> 0 | P18: =IFERROR(Q18/N18,0) -> 0 | Q18: {=SUM(IF(#REF!=L18,IF(#REF!>=$L$2,IF(#REF!<=$L$4,#REF!,0),0),0))} -> #REF! | R18: {=SUM(IF(#REF!=L18,IF(#REF!>=$L$2,IF(#REF!<=$L$4,#REF!,0),0),0))} -> #REF! | S18: {=SUM(IF(#REF!=L18,IF(#REF!>=$L$2,IF(#REF!<=$L$4,#REF!,0),0),0))} -> #REF! | T18: =IF(IFERROR(S18/R18,0)=0,"",IFERROR(S18/R18,0)) | U18: =IF(AND(N18>=10,P18<=0.05),"极差",IF(AND(N18>=10,0.05<P18,P18<=0.1),"差",IF(AND(N18>=10,0.1<P18,P18<=0.15),"良",IF(AND(N18>=10,P18>0.15),"优","点击次数少于10次没有参考性")))) -> #REF! | V18: =IFERROR(INDEX(#REF!,MATCH(关键词词频统计!L18,#REF!,0)),"")
B19: {=SUM(IF(#REF!=A19,IF(#REF!>=关键词词频统计!$A$2,IF(#REF!<=关键词词频统计!$A$4,#REF!,0),0),0))} -> #REF! | C19: {=SUM(IF(#REF!=A19,IF(#REF!>=关键词词频统计!$A$2,IF(#REF!<=关键词词频统计!$A$4,#REF!,0),0),0))} -> #REF! | D19: =IFERROR(C19/B19,0) -> 0 | E19: =IFERROR(F19/C19,0) -> 0 | F19: {=SUM(IF(#REF!=A19,IF(#REF!>=关键词词频统计!$A$2,IF(#REF!<=关键词词频统计!$A$4,#REF!,0),0),0))} -> #REF! | G19: {=SUM(IF(#REF!=A19,IF(#REF!>=关键词词频统计!$A$2,IF(#REF!<=关键词词频统计!$A$4,#REF!,0),0),0))} -> #REF! | H19: {=SUM(IF(#REF!=A19,IF(#REF!>=关键词词频统计!$A$2,IF(#REF!<=关键词词频统计!$A$4,#REF!,0),0),0))} -> #REF! | I19: =IF(IFERROR(H19/G19,0)=0,"",IFERROR(H19/G19,0)) | J19: =IF(AND(C19>=10,E19<=0.05),"极差",IF(AND(C19>=10,0.05<E19,E19<=0.1),"差",IF(AND(C19>=10,0.1<E19,E19<=0.15),"良",IF(AND(C19>=10,E19>0.15),"优","点击次数少于10次没有参考性")))) -> #REF! | K19: =IFERROR(INDEX(#REF!,MATCH(关键词词频统计!A19,#REF!,0)),"") | M19: {=SUM(IF(#REF!=L19,IF(#REF!>=$L$2,IF(#REF!<=$L$4,#REF!,0),0),0))} -> #REF! | N19: {=SUM(IF(#REF!=L19,IF(#REF!>=$L$2,IF(#REF!<=$L$4,#REF!,0),0),0))} -> #REF! | O19: =IFERROR(N19/M19,0) -> 0 | P19: =IFERROR(Q19/N19,0) -> 0 | Q19: {=SUM(IF(#REF!=L19,IF(#REF!>=$L$2,IF(#REF!<=$L$4,#REF!,0),0),0))} -> #REF! | R19: {=SUM(IF(#REF!=L19,IF(#REF!>=$L$2,IF(#REF!<=$L$4,#REF!,0),0),0))} -> #REF! | S19: {=SUM(IF(#REF!=L19,IF(#REF!>=$L$2,IF(#REF!<=$L$4,#REF!,0),0),0))} -> #REF! | T19: =IF(IFERROR(S19/R19,0)=0,"",IFERROR(S19/R19,0)) | U19: =IF(AND(N19>=10,P19<=0.05),"极差",IF(AND(N19>=10,0.05<P19,P19<=0.1),"差",IF(AND(N19>=10,0.1<P19,P19<=0.15),"良",IF(AND(N19>=10,P19>0.15),"优","点击次数少于10次没有参考性")))) -> #REF! | V19: =IFERROR(INDEX(#REF!,MATCH(关键词词频统计!L19,#REF!,0)),"")
B20: {=SUM(IF(#REF!=A20,IF(#REF!>=关键词词频统计!$A$2,IF(#REF!<=关键词词频统计!$A$4,#REF!,0),0),0))} -> #REF! | C20: {=SUM(IF(#REF!=A20,IF(#REF!>=关键词词频统计!$A$2,IF(#REF!<=关键词词频统计!$A$4,#REF!,0),0),0))} -> #REF! | D20: =IFERROR(C20/B20,0) -> 0 | E20: =IFERROR(F20/C20,0) -> 0 | F20: {=SUM(IF(#REF!=A20,IF(#REF!>=关键词词频统计!$A$2,IF(#REF!<=关键词词频统计!$A$4,#REF!,0),0),0))} -> #REF! | G20: {=SUM(IF(#REF!=A20,IF(#REF!>=关键词词频统计!$A$2,IF(#REF!<=关键词词频统计!$A$4,#REF!,0),0),0))} -> #REF! | H20: {=SUM(IF(#REF!=A20,IF(#REF!>=关键词词频统计!$A$2,IF(#REF!<=关键词词频统计!$A$4,#REF!,0),0),0))} -> #REF! | I20: =IF(IFERROR(H20/G20,0)=0,"",IFERROR(H20/G20,0)) | J20: =IF(AND(C20>=10,E20<=0.05),"极差",IF(AND(C20>=10,0.05<E20,E20<=0.1),"差",IF(AND(C20>=10,0.1<E20,E20<=0.15),"良",IF(AND(C20>=10,E20>0.15),"优","点击次数少于10次没有参考性")))) -> #REF! | K20: =IFERROR(INDEX(#REF!,MATCH(关键词词频统计!A20,#REF!,0)),"") | M20: {=SUM(IF(#REF!=L20,IF(#REF!>=$L$2,IF(#REF!<=$L$4,#REF!,0),0),0))} -> #REF! | N20: {=SUM(IF(#REF!=L20,IF(#REF!>=$L$2,IF(#REF!<=$L$4,#REF!,0),0),0))} -> #REF! | O20: =IFERROR(N20/M20,0) -> 0 | P20: =IFERROR(Q20/N20,0) -> 0 | Q20: {=SUM(IF(#REF!=L20,IF(#REF!>=$L$2,IF(#REF!<=$L$4,#REF!,0),0),0))} -> #REF! | R20: {=SUM(IF(#REF!=L20,IF(#REF!>=$L$2,IF(#REF!<=$L$4,#REF!,0),0),0))} -> #REF! | S20: {=SUM(IF(#REF!=L20,IF(#REF!>=$L$2,IF(#REF!<=$L$4,#REF!,0),0),0))} -> #REF! | T20: =IF(IFERROR(S20/R20,0)=0,"",IFERROR(S20/R20,0)) | U20: =IF(AND(N20>=10,P20<=0.05),"极差",IF(AND(N20>=10,0.05<P20,P20<=0.1),"差",IF(AND(N20>=10,0.1<P20,P20<=0.15),"良",IF(AND(N20>=10,P20>0.15),"优","点击次数少于10次没有参考性")))) -> #REF! | V20: =IFERROR(INDEX(#REF!,MATCH(关键词词频统计!L20,#REF!,0)),"")
B21: {=SUM(IF(#REF!=A21,IF(#REF!>=关键词词频统计!$A$2,IF(#REF!<=关键词词频统计!$A$4,#REF!,0),0),0))} -> #REF! | C21: {=SUM(IF(#REF!=A21,IF(#REF!>=关键词词频统计!$A$2,IF(#REF!<=关键词词频统计!$A$4,#REF!,0),0),0))} -> #REF! | D21: =IFERROR(C21/B21,0) -> 0 | E21: =IFERROR(F21/C21,0) -> 0 | F21: {=SUM(IF(#REF!=A21,IF(#REF!>=关键词词频统计!$A$2,IF(#REF!<=关键词词频统计!$A$4,#REF!,0),0),0))} -> #REF! | G21: {=SUM(IF(#REF!=A21,IF(#REF!>=关键词词频统计!$A$2,IF(#REF!<=关键词词频统计!$A$4,#REF!,0),0),0))} -> #REF! | H21: {=SUM(IF(#REF!=A21,IF(#REF!>=关键词词频统计!$A$2,IF(#REF!<=关键词词频统计!$A$4,#REF!,0),0),0))} -> #REF! | I21: =IF(IFERROR(H21/G21,0)=0,"",IFERROR(H21/G21,0)) | J21: =IF(AND(C21>=10,E21<=0.05),"极差",IF(AND(C21>=10,0.05<E21,E21<=0.1),"差",IF(AND(C21>=10,0.1<E21,E21<=0.15),"良",IF(AND(C21>=10,E21>0.15),"优","点击次数少于10次没有参考性")))) -> #REF! | K21: =IFERROR(INDEX(#REF!,MATCH(关键词词频统计!A21,#REF!,0)),"") | M21: {=SUM(IF(#REF!=L21,IF(#REF!>=$L$2,IF(#REF!<=$L$4,#REF!,0),0),0))} -> #REF! | N21: {=SUM(IF(#REF!=L21,IF(#REF!>=$L$2,IF(#REF!<=$L$4,#REF!,0),0),0))} -> #REF! | O21: =IFERROR(N21/M21,0) -> 0 | P21: =IFERROR(Q21/N21,0) -> 0 | Q21: {=SUM(IF(#REF!=L21,IF(#REF!>=$L$2,IF(#REF!<=$L$4,#REF!,0),0),0))} -> #REF! | R21: {=SUM(IF(#REF!=L21,IF(#REF!>=$L$2,IF(#REF!<=$L$4,#REF!,0),0),0))} -> #REF! | S21: {=SUM(IF(#REF!=L21,IF(#REF!>=$L$2,IF(#REF!<=$L$4,#REF!,0),0),0))} -> #REF! | T21: =IF(IFERROR(S21/R21,0)=0,"",IFERROR(S21/R21,0)) | U21: =IF(AND(N21>=10,P21<=0.05),"极差",IF(AND(N21>=10,0.05<P21,P21<=0.1),"差",IF(AND(N21>=10,0.1<P21,P21<=0.15),"良",IF(AND(N21>=10,P21>0.15),"优","点击次数少于10次没有参考性")))) -> #REF! | V21: =IFERROR(INDEX(#REF!,MATCH(关键词词频统计!L21,#REF!,0)),"")
B22: {=SUM(IF(#REF!=A22,IF(#REF!>=关键词词频统计!$A$2,IF(#REF!<=关键词词频统计!$A$4,#REF!,0),0),0))} -> #REF! | C22: {=SUM(IF(#REF!=A22,IF(#REF!>=关键词词频统计!$A$2,IF(#REF!<=关键词词频统计!$A$4,#REF!,0),0),0))} -> #REF! | D22: =IFERROR(C22/B22,0) -> 0 | E22: =IFERROR(F22/C22,0) -> 0 | F22: {=SUM(IF(#REF!=A22,IF(#REF!>=关键词词频统计!$A$2,IF(#REF!<=关键词词频统计!$A$4,#REF!,0),0),0))} -> #REF! | G22: {=SUM(IF(#REF!=A22,IF(#REF!>=关键词词频统计!$A$2,IF(#REF!<=关键词词频统计!$A$4,#REF!,0),0),0))} -> #REF! | H22: {=SUM(IF(#REF!=A22,IF(#REF!>=关键词词频统计!$A$2,IF(#REF!<=关键词词频统计!$A$4,#REF!,0),0),0))} -> #REF! | I22: =IF(IFERROR(H22/G22,0)=0,"",IFERROR(H22/G22,0)) | J22: =IF(AND(C22>=10,E22<=0.05),"极差",IF(AND(C22>=10,0.05<E22,E22<=0.1),"差",IF(AND(C22>=10,0.1<E22,E22<=0.15),"良",IF(AND(C22>=10,E22>0.15),"优","点击次数少于10次没有参考性")))) -> #REF! | K22: =IFERROR(INDEX(#REF!,MATCH(关键词词频统计!A22,#REF!,0)),"") | M22: {=SUM(IF(#REF!=L22,IF(#REF!>=$L$2,IF(#REF!<=$L$4,#REF!,0),0),0))} -> #REF! | N22: {=SUM(IF(#REF!=L22,IF(#REF!>=$L$2,IF(#REF!<=$L$4,#REF!,0),0),0))} -> #REF! | O22: =IFERROR(N22/M22,0) -> 0 | P22: =IFERROR(Q22/N22,0) -> 0 | Q22: {=SUM(IF(#REF!=L22,IF(#REF!>=$L$2,IF(#REF!<=$L$4,#REF!,0),0),0))} -> #REF! | R22: {=SUM(IF(#REF!=L22,IF(#REF!>=$L$2,IF(#REF!<=$L$4,#REF!,0),0),0))} -> #REF! | S22: {=SUM(IF(#REF!=L22,IF(#REF!>=$L$2,IF(#REF!<=$L$4,#REF!,0),0),0))} -> #REF! | T22: =IF(IFERROR(S22/R22,0)=0,"",IFERROR(S22/R22,0)) | U22: =IF(AND(N22>=10,P22<=0.05),"极差",IF(AND(N22>=10,0.05<P22,P22<=0.1),"差",IF(AND(N22>=10,0.1<P22,P22<=0.15),"良",IF(AND(N22>=10,P22>0.15),"优","点击次数少于10次没有参考性")))) -> #REF! | V22: =IFERROR(INDEX(#REF!,MATCH(关键词词频统计!L22,#REF!,0)),"")
B23: {=SUM(IF(#REF!=A23,IF(#REF!>=关键词词频统计!$A$2,IF(#REF!<=关键词词频统计!$A$4,#REF!,0),0),0))} -> #REF! | C23: {=SUM(IF(#REF!=A23,IF(#REF!>=关键词词频统计!$A$2,IF(#REF!<=关键词词频统计!$A$4,#REF!,0),0),0))} -> #REF! | D23: =IFERROR(C23/B23,0) -> 0 | E23: =IFERROR(F23/C23,0) -> 0 | F23: {=SUM(IF(#REF!=A23,IF(#REF!>=关键词词频统计!$A$2,IF(#REF!<=关键词词频统计!$A$4,#REF!,0),0),0))} -> #REF! | G23: {=SUM(IF(#REF!=A23,IF(#REF!>=关键词词频统计!$A$2,IF(#REF!<=关键词词频统计!$A$4,#REF!,0),0),0))} -> #REF! | H23: {=SUM(IF(#REF!=A23,IF(#REF!>=关键词词频统计!$A$2,IF(#REF!<=关键词词频统计!$A$4,#REF!,0),0),0))} -> #REF! | I23: =IF(IFERROR(H23/G23,0)=0,"",IFERROR(H23/G23,0)) | J23: =IF(AND(C23>=10,E23<=0.05),"极差",IF(AND(C23>=10,0.05<E23,E23<=0.1),"差",IF(AND(C23>=10,0.1<E23,E23<=0.15),"良",IF(AND(C23>=10,E23>0.15),"优","点击次数少于10次没有参考性")))) -> #REF! | K23: =IFERROR(INDEX(#REF!,MATCH(关键词词频统计!A23,#REF!,0)),"") | M23: {=SUM(IF(#REF!=L23,IF(#REF!>=$L$2,IF(#REF!<=$L$4,#REF!,0),0),0))} -> #REF! | N23: {=SUM(IF(#REF!=L23,IF(#REF!>=$L$2,IF(#REF!<=$L$4,#REF!,0),0),0))} -> #REF! | O23: =IFERROR(N23/M23,0) -> 0 | P23: =IFERROR(Q23/N23,0) -> 0 | Q23: {=SUM(IF(#REF!=L23,IF(#REF!>=$L$2,IF(#REF!<=$L$4,#REF!,0),0),0))} -> #REF! | R23: {=SUM(IF(#REF!=L23,IF(#REF!>=$L$2,IF(#REF!<=$L$4,#REF!,0),0),0))} -> #REF! | S23: {=SUM(IF(#REF!=L23,IF(#REF!>=$L$2,IF(#REF!<=$L$4,#REF!,0),0),0))} -> #REF! | T23: =IF(IFERROR(S23/R23,0)=0,"",IFERROR(S23/R23,0)) | U23: =IF(AND(N23>=10,P23<=0.05),"极差",IF(AND(N23>=10,0.05<P23,P23<=0.1),"差",IF(AND(N23>=10,0.1<P23,P23<=0.15),"良",IF(AND(N23>=10,P23>0.15),"优","点击次数少于10次没有参考性")))) -> #REF! | V23: =IFERROR(INDEX(#REF!,MATCH(关键词词频统计!L23,#REF!,0)),"")
B24: {=SUM(IF(#REF!=A24,IF(#REF!>=关键词词频统计!$A$2,IF(#REF!<=关键词词频统计!$A$4,#REF!,0),0),0))} -> #REF! | C24: {=SUM(IF(#REF!=A24,IF(#REF!>=关键词词频统计!$A$2,IF(#REF!<=关键词词频统计!$A$4,#REF!,0),0),0))} -> #REF! | D24: =IFERROR(C24/B24,0) -> 0 | E24: =IFERROR(F24/C24,0) -> 0 | F24: {=SUM(IF(#REF!=A24,IF(#REF!>=关键词词频统计!$A$2,IF(#REF!<=关键词词频统计!$A$4,#REF!,0),0),0))} -> #REF! | G24: {=SUM(IF(#REF!=A24,IF(#REF!>=关键词词频统计!$A$2,IF(#REF!<=关键词词频统计!$A$4,#REF!,0),0),0))} -> #REF! | H24: {=SUM(IF(#REF!=A24,IF(#REF!>=关键词词频统计!$A$2,IF(#REF!<=关键词词频统计!$A$4,#REF!,0),0),0))} -> #REF! | I24: =IF(IFERROR(H24/G24,0)=0,"",IFERROR(H24/G24,0)) | J24: =IF(AND(C24>=10,E24<=0.05),"极差",IF(AND(C24>=10,0.05<E24,E24<=0.1),"差",IF(AND(C24>=10,0.1<E24,E24<=0.15),"良",IF(AND(C24>=10,E24>0.15),"优","点击次数少于10次没有参考性")))) -> #REF! | K24: =IFERROR(INDEX(#REF!,MATCH(关键词词频统计!A24,#REF!,0)),"") | M24: {=SUM(IF(#REF!=L24,IF(#REF!>=$L$2,IF(#REF!<=$L$4,#REF!,0),0),0))} -> #REF! | N24: {=SUM(IF(#REF!=L24,IF(#REF!>=$L$2,IF(#REF!<=$L$4,#REF!,0),0),0))} -> #REF! | O24: =IFERROR(N24/M24,0) -> 0 | P24: =IFERROR(Q24/N24,0) -> 0 | Q24: {=SUM(IF(#REF!=L24,IF(#REF!>=$L$2,IF(#REF!<=$L$4,#REF!,0),0),0))} -> #REF! | R24: {=SUM(IF(#REF!=L24,IF(#REF!>=$L$2,IF(#REF!<=$L$4,#REF!,0),0),0))} -> #REF! | S24: {=SUM(IF(#REF!=L24,IF(#REF!>=$L$2,IF(#REF!<=$L$4,#REF!,0),0),0))} -> #REF! | T24: =IF(IFERROR(S24/R24,0)=0,"",IFERROR(S24/R24,0)) | U24: =IF(AND(N24>=10,P24<=0.05),"极差",IF(AND(N24>=10,0.05<P24,P24<=0.1),"差",IF(AND(N24>=10,0.1<P24,P24<=0.15),"良",IF(AND(N24>=10,P24>0.15),"优","点击次数少于10次没有参考性")))) -> #REF! | V24: =IFERROR(INDEX(#REF!,MATCH(关键词词频统计!L24,#REF!,0)),"")
B25: {=SUM(IF(#REF!=A25,IF(#REF!>=关键词词频统计!$A$2,IF(#REF!<=关键词词频统计!$A$4,#REF!,0),0),0))} -> #REF! | C25: {=SUM(IF(#REF!=A25,IF(#REF!>=关键词词频统计!$A$2,IF(#REF!<=关键词词频统计!$A$4,#REF!,0),0),0))} -> #REF! | D25: =IFERROR(C25/B25,0) -> 0 | E25: =IFERROR(F25/C25,0) -> 0 | F25: {=SUM(IF(#REF!=A25,IF(#REF!>=关键词词频统计!$A$2,IF(#REF!<=关键词词频统计!$A$4,#REF!,0),0),0))} -> #REF! | G25: {=SUM(IF(#REF!=A25,IF(#REF!>=关键词词频统计!$A$2,IF(#REF!<=关键词词频统计!$A$4,#REF!,0),0),0))} -> #REF! | H25: {=SUM(IF(#REF!=A25,IF(#REF!>=关键词词频统计!$A$2,IF(#REF!<=关键词词频统计!$A$4,#REF!,0),0),0))} -> #REF! | I25: =IF(IFERROR(H25/G25,0)=0,"",IFERROR(H25/G25,0)) | J25: =IF(AND(C25>=10,E25<=0.05),"极差",IF(AND(C25>=10,0.05<E25,E25<=0.1),"差",IF(AND(C25>=10,0.1<E25,E25<=0.15),"良",IF(AND(C25>=10,E25>0.15),"优","点击次数少于10次没有参考性")))) -> #REF! | K25: =IFERROR(INDEX(#REF!,MATCH(关键词词频统计!A25,#REF!,0)),"") | M25: {=SUM(IF(#REF!=L25,IF(#REF!>=$L$2,IF(#REF!<=$L$4,#REF!,0),0),0))} -> #REF! | N25: {=SUM(IF(#REF!=L25,IF(#REF!>=$L$2,IF(#REF!<=$L$4,#REF!,0),0),0))} -> #REF! | O25: =IFERROR(N25/M25,0) -> 0 | P25: =IFERROR(Q25/N25,0) -> 0 | Q25: {=SUM(IF(#REF!=L25,IF(#REF!>=$L$2,IF(#REF!<=$L$4,#REF!,0),0),0))} -> #REF! | R25: {=SUM(IF(#REF!=L25,IF(#REF!>=$L$2,IF(#REF!<=$L$4,#REF!,0),0),0))} -> #REF! | S25: {=SUM(IF(#REF!=L25,IF(#REF!>=$L$2,IF(#REF!<=$L$4,#REF!,0),0),0))} -> #REF! | T25: =IF(IFERROR(S25/R25,0)=0,"",IFERROR(S25/R25,0)) | U25: =IF(AND(N25>=10,P25<=0.05),"极差",IF(AND(N25>=10,0.05<P25,P25<=0.1),"差",IF(AND(N25>=10,0.1<P25,P25<=0.15),"良",IF(AND(N25>=10,P25>0.15),"优","点击次数少于10次没有参考性")))) -> #REF! | V25: =IFERROR(INDEX(#REF!,MATCH(关键词词频统计!L25,#REF!,0)),"")
B26: {=SUM(IF(#REF!=A26,IF(#REF!>=关键词词频统计!$A$2,IF(#REF!<=关键词词频统计!$A$4,#REF!,0),0),0))} -> #REF! | C26: {=SUM(IF(#REF!=A26,IF(#REF!>=关键词词频统计!$A$2,IF(#REF!<=关键词词频统计!$A$4,#REF!,0),0),0))} -> #REF! | D26: =IFERROR(C26/B26,0) -> 0 | E26: =IFERROR(F26/C26,0) -> 0 | F26: {=SUM(IF(#REF!=A26,IF(#REF!>=关键词词频统计!$A$2,IF(#REF!<=关键词词频统计!$A$4,#REF!,0),0),0))} -> #REF! | G26: {=SUM(IF(#REF!=A26,IF(#REF!>=关键词词频统计!$A$2,IF(#REF!<=关键词词频统计!$A$4,#REF!,0),0),0))} -> #REF! | H26: {=SUM(IF(#REF!=A26,IF(#REF!>=关键词词频统计!$A$2,IF(#REF!<=关键词词频统计!$A$4,#REF!,0),0),0))} -> #REF! | I26: =IF(IFERROR(H26/G26,0)=0,"",IFERROR(H26/G26,0)) | J26: =IF(AND(C26>=10,E26<=0.05),"极差",IF(AND(C26>=10,0.05<E26,E26<=0.1),"差",IF(AND(C26>=10,0.1<E26,E26<=0.15),"良",IF(AND(C26>=10,E26>0.15),"优","点击次数少于10次没有参考性")))) -> #REF! | K26: =IFERROR(INDEX(#REF!,MATCH(关键词词频统计!A26,#REF!,0)),"") | M26: {=SUM(IF(#REF!=L26,IF(#REF!>=$L$2,IF(#REF!<=$L$4,#REF!,0),0),0))} -> #REF! | N26: {=SUM(IF(#REF!=L26,IF(#REF!>=$L$2,IF(#REF!<=$L$4,#REF!,0),0),0))} -> #REF! | O26: =IFERROR(N26/M26,0) -> 0 | P26: =IFERROR(Q26/N26,0) -> 0 | Q26: {=SUM(IF(#REF!=L26,IF(#REF!>=$L$2,IF(#REF!<=$L$4,#REF!,0),0),0))} -> #REF! | R26: {=SUM(IF(#REF!=L26,IF(#REF!>=$L$2,IF(#REF!<=$L$4,#REF!,0),0),0))} -> #REF! | S26: {=SUM(IF(#REF!=L26,IF(#REF!>=$L$2,IF(#REF!<=$L$4,#REF!,0),0),0))} -> #REF! | T26: =IF(IFERROR(S26/R26,0)=0,"",IFERROR(S26/R26,0)) | U26: =IF(AND(N26>=10,P26<=0.05),"极差",IF(AND(N26>=10,0.05<P26,P26<=0.1),"差",IF(AND(N26>=10,0.1<P26,P26<=0.15),"良",IF(AND(N26>=10,P26>0.15),"优","点击次数少于10次没有参考性")))) -> #REF! | V26: =IFERROR(INDEX(#REF!,MATCH(关键词词频统计!L26,#REF!,0)),"")
... B389: {=SUM(IF(#REF!=A389,IF(#REF!>=关键词词频统计!$A$2,IF(#REF!<=关键词词频统计!$A$4,#REF!,0),0),0))} -> #REF! | C389: {=SUM(IF(#REF!=A389,IF(#REF!>=关键词词频统计!$A$2,IF(#REF!<=关键词词频统计!$A$4,#REF!,0),0),0))} -> #REF! | D389: =IFERROR(C389/B389,0) -> 0 | E389: =IFERROR(F389/C389,0) -> 0 | F389: {=SUM(IF(#REF!=A389,IF(#REF!>=关键词词频统计!$A$2,IF(#REF!<=关键词词频统计!$A$4,#REF!,0),0),0))} -> #REF! | G389: {=SUM(IF(#REF!=A389,IF(#REF!>=关键词词频统计!$A$2,IF(#REF!<=关键词词频统计!$A$4,#REF!,0),0),0))} -> #REF! | H389: {=SUM(IF(#REF!=A389,IF(#REF!>=关键词词频统计!$A$2,IF(#REF!<=关键词词频统计!$A$4,#REF!,0),0),0))} -> #REF! | I389: =IF(IFERROR(H389/G389,0)=0,"",IFERROR(H389/G389,0)) | J389: =IF(AND(C389>=10,E389<=0.05),"极差",IF(AND(C389>=10,0.05<E389,E389<=0.1),"差",IF(AND(C389>=10,0.1<E389,E389<=0.15),"良",IF(AND(C389>=10,E389>0.15),"优","点击次数少于10次没有参考性")))) -> #REF! | K389: =IFERROR(INDEX(#REF!,MATCH(关键词词频统计!A389,#REF!,0)),"") | M389: {=SUM(IF(#REF!=L389,IF(#REF!>=$L$2,IF(#REF!<=$L$4,#REF!,0),0),0))} -> #REF! | N389: {=SUM(IF(#REF!=L389,IF(#REF!>=$L$2,IF(#REF!<=$L$4,#REF!,0),0),0))} -> #REF! | O389: =IFERROR(N389/M389,0) -> 0 | P389: =IFERROR(Q389/N389,0) -> 0 | Q389: {=SUM(IF(#REF!=L389,IF(#REF!>=$L$2,IF(#REF!<=$L$4,#REF!,0),0),0))} -> #REF! | R389: {=SUM(IF(#REF!=L389,IF(#REF!>=$L$2,IF(#REF!<=$L$4,#REF!,0),0),0))} -> #REF! | S389: {=SUM(IF(#REF!=L389,IF(#REF!>=$L$2,IF(#REF!<=$L$4,#REF!,0),0),0))} -> #REF! | T389: =IF(IFERROR(S389/R389,0)=0,"",IFERROR(S389/R389,0)) | U389: =IF(AND(N389>=10,P389<=0.05),"极差",IF(AND(N389>=10,0.05<P389,P389<=0.1),"差",IF(AND(N389>=10,0.1<P389,P389<=0.15),"良",IF(AND(N389>=10,P389>0.15),"优","点击次数少于10次没有参考性")))) -> #REF! | V389: =IFERROR(INDEX(#REF!,MATCH(关键词词频统计!L389,#REF!,0)),"")
B390: {=SUM(IF(#REF!=A390,IF(#REF!>=关键词词频统计!$A$2,IF(#REF!<=关键词词频统计!$A$4,#REF!,0),0),0))} -> #REF! | C390: {=SUM(IF(#REF!=A390,IF(#REF!>=关键词词频统计!$A$2,IF(#REF!<=关键词词频统计!$A$4,#REF!,0),0),0))} -> #REF! | D390: =IFERROR(C390/B390,0) -> 0 | E390: =IFERROR(F390/C390,0) -> 0 | F390: {=SUM(IF(#REF!=A390,IF(#REF!>=关键词词频统计!$A$2,IF(#REF!<=关键词词频统计!$A$4,#REF!,0),0),0))} -> #REF! | G390: {=SUM(IF(#REF!=A390,IF(#REF!>=关键词词频统计!$A$2,IF(#REF!<=关键词词频统计!$A$4,#REF!,0),0),0))} -> #REF! | H390: {=SUM(IF(#REF!=A390,IF(#REF!>=关键词词频统计!$A$2,IF(#REF!<=关键词词频统计!$A$4,#REF!,0),0),0))} -> #REF! | I390: =IF(IFERROR(H390/G390,0)=0,"",IFERROR(H390/G390,0)) | J390: =IF(AND(C390>=10,E390<=0.05),"极差",IF(AND(C390>=10,0.05<E390,E390<=0.1),"差",IF(AND(C390>=10,0.1<E390,E390<=0.15),"良",IF(AND(C390>=10,E390>0.15),"优","点击次数少于10次没有参考性")))) -> #REF! | K390: =IFERROR(INDEX(#REF!,MATCH(关键词词频统计!A390,#REF!,0)),"") | V390: =IFERROR(INDEX(#REF!,MATCH(关键词词频统计!L390,#REF!,0)),"")
B391: {=SUM(IF(#REF!=A391,IF(#REF!>=关键词词频统计!$A$2,IF(#REF!<=关键词词频统计!$A$4,#REF!,0),0),0))} -> #REF! | C391: {=SUM(IF(#REF!=A391,IF(#REF!>=关键词词频统计!$A$2,IF(#REF!<=关键词词频统计!$A$4,#REF!,0),0),0))} -> #REF! | D391: =IFERROR(C391/B391,0) -> 0 | E391: =IFERROR(F391/C391,0) -> 0 | F391: {=SUM(IF(#REF!=A391,IF(#REF!>=关键词词频统计!$A$2,IF(#REF!<=关键词词频统计!$A$4,#REF!,0),0),0))} -> #REF! | G391: {=SUM(IF(#REF!=A391,IF(#REF!>=关键词词频统计!$A$2,IF(#REF!<=关键词词频统计!$A$4,#REF!,0),0),0))} -> #REF! | H391: {=SUM(IF(#REF!=A391,IF(#REF!>=关键词词频统计!$A$2,IF(#REF!<=关键词词频统计!$A$4,#REF!,0),0),0))} -> #REF! | I391: =IF(IFERROR(H391/G391,0)=0,"",IFERROR(H391/G391,0)) | J391: =IF(AND(C391>=10,E391<=0.05),"极差",IF(AND(C391>=10,0.05<E391,E391<=0.1),"差",IF(AND(C391>=10,0.1<E391,E391<=0.15),"良",IF(AND(C391>=10,E391>0.15),"优","点击次数少于10次没有参考性")))) -> #REF! | K391: =IFERROR(INDEX(#REF!,MATCH(关键词词频统计!A391,#REF!,0)),"") | V391: =IFERROR(INDEX(#REF!,MATCH(关键词词频统计!L391,#REF!,0)),"")
B392: {=SUM(IF(#REF!=A392,IF(#REF!>=关键词词频统计!$A$2,IF(#REF!<=关键词词频统计!$A$4,#REF!,0),0),0))} -> #REF! | C392: {=SUM(IF(#REF!=A392,IF(#REF!>=关键词词频统计!$A$2,IF(#REF!<=关键词词频统计!$A$4,#REF!,0),0),0))} -> #REF! | D392: =IFERROR(C392/B392,0) -> 0 | E392: =IFERROR(F392/C392,0) -> 0 | F392: {=SUM(IF(#REF!=A392,IF(#REF!>=关键词词频统计!$A$2,IF(#REF!<=关键词词频统计!$A$4,#REF!,0),0),0))} -> #REF! | G392: {=SUM(IF(#REF!=A392,IF(#REF!>=关键词词频统计!$A$2,IF(#REF!<=关键词词频统计!$A$4,#REF!,0),0),0))} -> #REF! | H392: {=SUM(IF(#REF!=A392,IF(#REF!>=关键词词频统计!$A$2,IF(#REF!<=关键词词频统计!$A$4,#REF!,0),0),0))} -> #REF! | I392: =IF(IFERROR(H392/G392,0)=0,"",IFERROR(H392/G392,0)) | J392: =IF(AND(C392>=10,E392<=0.05),"极差",IF(AND(C392>=10,0.05<E392,E392<=0.1),"差",IF(AND(C392>=10,0.1<E392,E392<=0.15),"良",IF(AND(C392>=10,E392>0.15),"优","点击次数少于10次没有参考性")))) -> #REF! | K392: =IFERROR(INDEX(#REF!,MATCH(关键词词频统计!A392,#REF!,0)),"") | V392: =IFERROR(INDEX(#REF!,MATCH(关键词词频统计!L392,#REF!,0)),"")
B393: {=SUM(IF(#REF!=A393,IF(#REF!>=关键词词频统计!$A$2,IF(#REF!<=关键词词频统计!$A$4,#REF!,0),0),0))} -> #REF! | C393: {=SUM(IF(#REF!=A393,IF(#REF!>=关键词词频统计!$A$2,IF(#REF!<=关键词词频统计!$A$4,#REF!,0),0),0))} -> #REF! | D393: =IFERROR(C393/B393,0) -> 0 | E393: =IFERROR(F393/C393,0) -> 0 | F393: {=SUM(IF(#REF!=A393,IF(#REF!>=关键词词频统计!$A$2,IF(#REF!<=关键词词频统计!$A$4,#REF!,0),0),0))} -> #REF! | G393: {=SUM(IF(#REF!=A393,IF(#REF!>=关键词词频统计!$A$2,IF(#REF!<=关键词词频统计!$A$4,#REF!,0),0),0))} -> #REF! | H393: {=SUM(IF(#REF!=A393,IF(#REF!>=关键词词频统计!$A$2,IF(#REF!<=关键词词频统计!$A$4,#REF!,0),0),0))} -> #REF! | I393: =IF(IFERROR(H393/G393,0)=0,"",IFERROR(H393/G393,0)) | J393: =IF(AND(C393>=10,E393<=0.05),"极差",IF(AND(C393>=10,0.05<E393,E393<=0.1),"差",IF(AND(C393>=10,0.1<E393,E393<=0.15),"良",IF(AND(C393>=10,E393>0.15),"优","点击次数少于10次没有参考性")))) -> #REF! | K393: =IFERROR(INDEX(#REF!,MATCH(关键词词频统计!A393,#REF!,0)),"") | V393: =IFERROR(INDEX(#REF!,MATCH(关键词词频统计!L393,#REF!,0)),"")
B394: {=SUM(IF(#REF!=A394,IF(#REF!>=关键词词频统计!$A$2,IF(#REF!<=关键词词频统计!$A$4,#REF!,0),0),0))} -> #REF! | C394: {=SUM(IF(#REF!=A394,IF(#REF!>=关键词词频统计!$A$2,IF(#REF!<=关键词词频统计!$A$4,#REF!,0),0),0))} -> #REF! | D394: =IFERROR(C394/B394,0) -> 0 | E394: =IFERROR(F394/C394,0) -> 0 | F394: {=SUM(IF(#REF!=A394,IF(#REF!>=关键词词频统计!$A$2,IF(#REF!<=关键词词频统计!$A$4,#REF!,0),0),0))} -> #REF! | G394: {=SUM(IF(#REF!=A394,IF(#REF!>=关键词词频统计!$A$2,IF(#REF!<=关键词词频统计!$A$4,#REF!,0),0),0))} -> #REF! | H394: {=SUM(IF(#REF!=A394,IF(#REF!>=关键词词频统计!$A$2,IF(#REF!<=关键词词频统计!$A$4,#REF!,0),0),0))} -> #REF! | I394: =IF(IFERROR(H394/G394,0)=0,"",IFERROR(H394/G394,0)) | J394: =IF(AND(C394>=10,E394<=0.05),"极差",IF(AND(C394>=10,0.05<E394,E394<=0.1),"差",IF(AND(C394>=10,0.1<E394,E394<=0.15),"良",IF(AND(C394>=10,E394>0.15),"优","点击次数少于10次没有参考性")))) -> #REF! | K394: =IFERROR(INDEX(#REF!,MATCH(关键词词频统计!A394,#REF!,0)),"") | V394: =IFERROR(INDEX(#REF!,MATCH(关键词词频统计!L394,#REF!,0)),"")
B395: {=SUM(IF(#REF!=A395,IF(#REF!>=关键词词频统计!$A$2,IF(#REF!<=关键词词频统计!$A$4,#REF!,0),0),0))} -> #REF! | C395: {=SUM(IF(#REF!=A395,IF(#REF!>=关键词词频统计!$A$2,IF(#REF!<=关键词词频统计!$A$4,#REF!,0),0),0))} -> #REF! | D395: =IFERROR(C395/B395,0) -> 0 | E395: =IFERROR(F395/C395,0) -> 0 | F395: {=SUM(IF(#REF!=A395,IF(#REF!>=关键词词频统计!$A$2,IF(#REF!<=关键词词频统计!$A$4,#REF!,0),0),0))} -> #REF! | G395: {=SUM(IF(#REF!=A395,IF(#REF!>=关键词词频统计!$A$2,IF(#REF!<=关键词词频统计!$A$4,#REF!,0),0),0))} -> #REF! | H395: {=SUM(IF(#REF!=A395,IF(#REF!>=关键词词频统计!$A$2,IF(#REF!<=关键词词频统计!$A$4,#REF!,0),0),0))} -> #REF! | I395: =IF(IFERROR(H395/G395,0)=0,"",IFERROR(H395/G395,0)) | J395: =IF(AND(C395>=10,E395<=0.05),"极差",IF(AND(C395>=10,0.05<E395,E395<=0.1),"差",IF(AND(C395>=10,0.1<E395,E395<=0.15),"良",IF(AND(C395>=10,E395>0.15),"优","点击次数少于10次没有参考性")))) -> #REF! | K395: =IFERROR(INDEX(#REF!,MATCH(关键词词频统计!A395,#REF!,0)),"") | V395: =IFERROR(INDEX(#REF!,MATCH(关键词词频统计!L395,#REF!,0)),"")
B396: {=SUM(IF(#REF!=A396,IF(#REF!>=关键词词频统计!$A$2,IF(#REF!<=关键词词频统计!$A$4,#REF!,0),0),0))} -> #REF! | C396: {=SUM(IF(#REF!=A396,IF(#REF!>=关键词词频统计!$A$2,IF(#REF!<=关键词词频统计!$A$4,#REF!,0),0),0))} -> #REF! | D396: =IFERROR(C396/B396,0) -> 0 | E396: =IFERROR(F396/C396,0) -> 0 | F396: {=SUM(IF(#REF!=A396,IF(#REF!>=关键词词频统计!$A$2,IF(#REF!<=关键词词频统计!$A$4,#REF!,0),0),0))} -> #REF! | G396: {=SUM(IF(#REF!=A396,IF(#REF!>=关键词词频统计!$A$2,IF(#REF!<=关键词词频统计!$A$4,#REF!,0),0),0))} -> #REF! | H396: {=SUM(IF(#REF!=A396,IF(#REF!>=关键词词频统计!$A$2,IF(#REF!<=关键词词频统计!$A$4,#REF!,0),0),0))} -> #REF! | I396: =IF(IFERROR(H396/G396,0)=0,"",IFERROR(H396/G396,0)) | J396: =IF(AND(C396>=10,E396<=0.05),"极差",IF(AND(C396>=10,0.05<E396,E396<=0.1),"差",IF(AND(C396>=10,0.1<E396,E396<=0.15),"良",IF(AND(C396>=10,E396>0.15),"优","点击次数少于10次没有参考性")))) -> #REF! | K396: =IFERROR(INDEX(#REF!,MATCH(关键词词频统计!A396,#REF!,0)),"") | V396: =IFERROR(INDEX(#REF!,MATCH(关键词词频统计!L396,#REF!,0)),"")
B397: {=SUM(IF(#REF!=A397,IF(#REF!>=关键词词频统计!$A$2,IF(#REF!<=关键词词频统计!$A$4,#REF!,0),0),0))} -> #REF! | C397: {=SUM(IF(#REF!=A397,IF(#REF!>=关键词词频统计!$A$2,IF(#REF!<=关键词词频统计!$A$4,#REF!,0),0),0))} -> #REF! | D397: =IFERROR(C397/B397,0) -> 0 | E397: =IFERROR(F397/C397,0) -> 0 | F397: {=SUM(IF(#REF!=A397,IF(#REF!>=关键词词频统计!$A$2,IF(#REF!<=关键词词频统计!$A$4,#REF!,0),0),0))} -> #REF! | G397: {=SUM(IF(#REF!=A397,IF(#REF!>=关键词词频统计!$A$2,IF(#REF!<=关键词词频统计!$A$4,#REF!,0),0),0))} -> #REF! | H397: {=SUM(IF(#REF!=A397,IF(#REF!>=关键词词频统计!$A$2,IF(#REF!<=关键词词频统计!$A$4,#REF!,0),0),0))} -> #REF! | I397: =IF(IFERROR(H397/G397,0)=0,"",IFERROR(H397/G397,0)) | J397: =IF(AND(C397>=10,E397<=0.05),"极差",IF(AND(C397>=10,0.05<E397,E397<=0.1),"差",IF(AND(C397>=10,0.1<E397,E397<=0.15),"良",IF(AND(C397>=10,E397>0.15),"优","点击次数少于10次没有参考性")))) -> #REF! | K397: =IFERROR(INDEX(#REF!,MATCH(关键词词频统计!A397,#REF!,0)),"") | V397: =IFERROR(INDEX(#REF!,MATCH(关键词词频统计!L397,#REF!,0)),"")
B398: {=SUM(IF(#REF!=A398,IF(#REF!>=关键词词频统计!$A$2,IF(#REF!<=关键词词频统计!$A$4,#REF!,0),0),0))} -> #REF! | C398: {=SUM(IF(#REF!=A398,IF(#REF!>=关键词词频统计!$A$2,IF(#REF!<=关键词词频统计!$A$4,#REF!,0),0),0))} -> #REF! | D398: =IFERROR(C398/B398,0) -> 0 | E398: =IFERROR(F398/C398,0) -> 0 | F398: {=SUM(IF(#REF!=A398,IF(#REF!>=关键词词频统计!$A$2,IF(#REF!<=关键词词频统计!$A$4,#REF!,0),0),0))} -> #REF! | G398: {=SUM(IF(#REF!=A398,IF(#REF!>=关键词词频统计!$A$2,IF(#REF!<=关键词词频统计!$A$4,#REF!,0),0),0))} -> #REF! | H398: {=SUM(IF(#REF!=A398,IF(#REF!>=关键词词频统计!$A$2,IF(#REF!<=关键词词频统计!$A$4,#REF!,0),0),0))} -> #REF! | I398: =IF(IFERROR(H398/G398,0)=0,"",IFERROR(H398/G398,0)) | J398: =IF(AND(C398>=10,E398<=0.05),"极差",IF(AND(C398>=10,0.05<E398,E398<=0.1),"差",IF(AND(C398>=10,0.1<E398,E398<=0.15),"良",IF(AND(C398>=10,E398>0.15),"优","点击次数少于10次没有参考性")))) -> #REF! | K398: =IFERROR(INDEX(#REF!,MATCH(关键词词频统计!A398,#REF!,0)),"") | V398: =IFERROR(INDEX(#REF!,MATCH(关键词词频统计!L398,#REF!,0)),"")
B399: {=SUM(IF(#REF!=A399,IF(#REF!>=关键词词频统计!$A$2,IF(#REF!<=关键词词频统计!$A$4,#REF!,0),0),0))} -> #REF! | C399: {=SUM(IF(#REF!=A399,IF(#REF!>=关键词词频统计!$A$2,IF(#REF!<=关键词词频统计!$A$4,#REF!,0),0),0))} -> #REF! | D399: =IFERROR(C399/B399,0) -> 0 | E399: =IFERROR(F399/C399,0) -> 0 | F399: {=SUM(IF(#REF!=A399,IF(#REF!>=关键词词频统计!$A$2,IF(#REF!<=关键词词频统计!$A$4,#REF!,0),0),0))} -> #REF! | G399: {=SUM(IF(#REF!=A399,IF(#REF!>=关键词词频统计!$A$2,IF(#REF!<=关键词词频统计!$A$4,#REF!,0),0),0))} -> #REF! | H399: {=SUM(IF(#REF!=A399,IF(#REF!>=关键词词频统计!$A$2,IF(#REF!<=关键词词频统计!$A$4,#REF!,0),0),0))} -> #REF! | I399: =IF(IFERROR(H399/G399,0)=0,"",IFERROR(H399/G399,0)) | J399: =IF(AND(C399>=10,E399<=0.05),"极差",IF(AND(C399>=10,0.05<E399,E399<=0.1),"差",IF(AND(C399>=10,0.1<E399,E399<=0.15),"良",IF(AND(C399>=10,E399>0.15),"优","点击次数少于10次没有参考性")))) -> #REF! | K399: =IFERROR(INDEX(#REF!,MATCH(关键词词频统计!A399,#REF!,0)),"") | V399: =IFERROR(INDEX(#REF!,MATCH(关键词词频统计!L399,#REF!,0)),"")
B400: {=SUM(IF(#REF!=A400,IF(#REF!>=关键词词频统计!$A$2,IF(#REF!<=关键词词频统计!$A$4,#REF!,0),0),0))} -> #REF! | C400: {=SUM(IF(#REF!=A400,IF(#REF!>=关键词词频统计!$A$2,IF(#REF!<=关键词词频统计!$A$4,#REF!,0),0),0))} -> #REF! | D400: =IFERROR(C400/B400,0) -> 0 | E400: =IFERROR(F400/C400,0) -> 0 | F400: {=SUM(IF(#REF!=A400,IF(#REF!>=关键词词频统计!$A$2,IF(#REF!<=关键词词频统计!$A$4,#REF!,0),0),0))} -> #REF! | G400: {=SUM(IF(#REF!=A400,IF(#REF!>=关键词词频统计!$A$2,IF(#REF!<=关键词词频统计!$A$4,#REF!,0),0),0))} -> #REF! | H400: {=SUM(IF(#REF!=A400,IF(#REF!>=关键词词频统计!$A$2,IF(#REF!<=关键词词频统计!$A$4,#REF!,0),0),0))} -> #REF! | I400: =IF(IFERROR(H400/G400,0)=0,"",IFERROR(H400/G400,0)) | J400: =IF(AND(C400>=10,E400<=0.05),"极差",IF(AND(C400>=10,0.05<E400,E400<=0.1),"差",IF(AND(C400>=10,0.1<E400,E400<=0.15),"良",IF(AND(C400>=10,E400>0.15),"优","点击次数少于10次没有参考性")))) -> #REF! | K400: =IFERROR(INDEX(#REF!,MATCH(关键词词频统计!A400,#REF!,0)),"") | V400: =IFERROR(INDEX(#REF!,MATCH(关键词词频统计!L400,#REF!,0)),"")
B401: {=SUM(IF(#REF!=A401,IF(#REF!>=关键词词频统计!$A$2,IF(#REF!<=关键词词频统计!$A$4,#REF!,0),0),0))} -> #REF! | C401: {=SUM(IF(#REF!=A401,IF(#REF!>=关键词词频统计!$A$2,IF(#REF!<=关键词词频统计!$A$4,#REF!,0),0),0))} -> #REF! | D401: =IFERROR(C401/B401,0) -> 0 | E401: =IFERROR(F401/C401,0) -> 0 | F401: {=SUM(IF(#REF!=A401,IF(#REF!>=关键词词频统计!$A$2,IF(#REF!<=关键词词频统计!$A$4,#REF!,0),0),0))} -> #REF! | G401: {=SUM(IF(#REF!=A401,IF(#REF!>=关键词词频统计!$A$2,IF(#REF!<=关键词词频统计!$A$4,#REF!,0),0),0))} -> #REF! | H401: {=SUM(IF(#REF!=A401,IF(#REF!>=关键词词频统计!$A$2,IF(#REF!<=关键词词频统计!$A$4,#REF!,0),0),0))} -> #REF! | I401: =IF(IFERROR(H401/G401,0)=0,"",IFERROR(H401/G401,0)) | J401: =IF(AND(C401>=10,E401<=0.05),"极差",IF(AND(C401>=10,0.05<E401,E401<=0.1),"差",IF(AND(C401>=10,0.1<E401,E401<=0.15),"良",IF(AND(C401>=10,E401>0.15),"优","点击次数少于10次没有参考性")))) -> #REF! | K401: =IFERROR(INDEX(#REF!,MATCH(关键词词频统计!A401,#REF!,0)),"") | V401: =IFERROR(INDEX(#REF!,MATCH(关键词词频统计!L401,#REF!,0)),"")
