Workbook
Name NativeTimeline_日期: #N/A
Name 切片器_广告活动: #N/A

Sheet 源数据
A1: 列1 | B1: 状态 | C1: 广告活动 | D1: 状态2 | E1: 类型 | F1: 投放 | G1: 广告活动的竞价策略 | H1: 开始日期 | I1: 结束日期 | J1: 广告组合 | K1: 预算(CNY) | L1: 曝光量 | M1: 点击次数 | N1: 点击率 (CTR)(%) | O1: 花费(CNY) | P1: 每次点击费用 (CPC)(CNY) | Q1: 订单 | R1: 销售额(CNY) | S1: 广告投入产出比 (ACOS)(%) | T1: 新买家订单数 | U1: 新买家订单比 | V1: 新买家销量 | W1: 新买家销量比
A2: 43678 | B2: ENABLED | C2: Bc-M-B | D2: CAMPAIGN_STATUS_ENABLED | E2: SP | F2: MANUAL | G2: LEGACY | H2: 43420 | K2: 5 | L2: 0 | M2: 0 | N2: 0 | O2: 0 | P2: 0 | Q2: 0 | R2: 0 | S2: 0 | T2: 0 | U2: 0 | V2: 0 | W2: 0
A3: 43678 | B3: ENABLED | C3: Cb-M-E | D3: CAMPAIGN_STATUS_ENABLED | E3: SP | F3: MANUAL | G3: LEGACY | H3: 43667 | K3: 10 | L3: 0 | M3: 0 | N3: 0 | O3: 0 | P3: 0 | Q3: 0 | R3: 0 | S3: 0 | T3: 0 | U3: 0 | V3: 0 | W3: 0
A4: 43678 | B4: ENABLED | C4: R-A | D4: CAMPAIGN_STATUS_ENABLED | E4: SP | F4: AUTOMATIC | G4: LEGACY | H4: 43388 | K4: 5 | L4: 0 | M4: 0 | N4: 0 | O4: 0 | P4: 0 | Q4: 0 | R4: 0 | S4: 0 | T4: 0 | U4: 0 | V4: 0 | W4: 0
A5: 43678 | B5: ENABLED | C5: 56BLACK-M-B | D5: CAMPAIGN_STATUS_ENABLED | E5: SP | F5: MANUAL | G5: LEGACY | H5: 43688 | K5: 10 | L5: 0 | M5: 0 | N5: 0 | O5: 0 | P5: 0 | Q5: 0 | R5: 0 | S5: 0 | T5: 0 | U5: 0 | V5: 0 | W5: 0
A6: 43678 | B6: ENABLED | C6: A-A | D6: CAMPAIGN_STATUS_ENABLED | E6: SP | F6: AUTOMATIC | G6: LEGACY | H6: 43387 | K6: 10 | L6: 635 | M6: 4 | N6: 0.6299 | O6: 0.18 | P6: 0.05 | Q6: 0 | R6: 0 | S6: 0 | T6: 0 | U6: 0 | V6: 0 | W6: 0
A7: 43678 | B7: ENABLED | C7: 87green-A | D7: CAMPAIGN_STATUS_ENABLED | E7: SP | F7: AUTOMATIC | G7: LEGACY | H7: 43676 | K7: 10 | L7: 14 | M7: 0 | N7: 0 | O7: 0 | P7: 0 | Q7: 0 | R7: 0 | S7: 0 | T7: 0 | U7: 0 | V7: 0 | W7: 0
A8: 43678 | B8: ENABLED | C8: A-M-E | D8: CAMPAIGN_STATUS_ENABLED | E8: SP | F8: MANUAL | G8: LEGACY | H8: 43661 | K8: 10 | L8: 6163 | M8: 41 | N8: 0.6653 | O8: 10.56 | P8: 0.26 | Q8: 0 | R8: 0 | S8: 0 | T8: 0 | U8: 0 | V8: 0 | W8: 0
A9: 43678 | B9: ENABLED | C9: 37hblueR-M-B | D9: CAMPAIGN_STATUS_ENABLED | E9: SP | F9: MANUAL | G9: LEGACY | H9: 43428 | K9: 10 | L9: 1047 | M9: 6 | N9: 0.5731 | O9: 3.59 | P9: 0.6 | Q9: 0 | R9: 0 | S9: 0 | T9: 0 | U9: 0 | V9: 0 | W9: 0
A10: 43678 | B10: ENABLED | C10: Bc-A | D10: CAMPAIGN_STATUS_ENABLED | E10: SP | F10: AUTOMATIC | G10: LEGACY | H10: 43387 | K10: 5 | L10: 0 | M10: 0 | N10: 0 | O10: 0 | P10: 0 | Q10: 0 | R10: 0 | S10: 0 | T10: 0 | U10: 0 | V10: 0 | W10: 0
A11: 43678 | B11: ENABLED | C11: hblueL-A | D11: CAMPAIGN_STATUS_ENABLED | E11: SP | F11: AUTOMATIC | G11: LEGACY | H11: 43388 | K11: 5 | L11: 5231 | M11: 9 | N11: 0.1721 | O11: 5.4 | P11: 0.6 | Q11: 0 | R11: 0 | S11: 0 | T11: 0 | U11: 0 | V11: 0 | W11: 0
A12: 43678 | B12: ENABLED | C12: Winter Products-Auto | D12: CAMPAIGN_STATUS_ENABLED | E12: SP | F12: AUTOMATIC | G12: LEGACY | H12: 43423 | K12: 3 | L12: 158 | M12: 1 | N12: 0.6329 | O12: 0.1 | P12: 0.1 | Q12: 0 | R12: 0 | S12: 0 | T12: 0 | U12: 0 | V12: 0 | W12: 0
A13: 43678 | B13: ENABLED | C13: 56BLACK-A | D13: CAMPAIGN_STATUS_ENABLED | E13: SP | F13: AUTOMATIC | G13: LEGACY | H13: 43647 | K13: 10 | L13: 1258 | M13: 6 | N13: 0.4769 | O13: 3.85 | P13: 0.64 | Q13: 0 | R13: 0 | S13: 0 | T13: 0 | U13: 0 | V13: 0 | W13: 0
... A23: 43678 | B23: ENABLED | C23: EEN-5-M-B | D23: CAMPAIGN_STATUS_ENABLED | E23: SP | F23: MANUAL | G23: LEGACY | H23: 43454 | K23: 20 | L23: 63 | M23: 3 | N23: 4.7619 | O23: 0.71 | P23: 0.24 | Q23: 1 | R23: 79.97 | S23: 0.8878 | T23: 0 | U23: 0 | V23: 0 | W23: 0
A24: 43678 | B24: ENABLED | C24: 品牌推广 | D24: RUNNING | E24: SB | F24: MANUAL | H24: 43671 | K24: 2 | L24: 722 | M24: 6 | N24: 0.831 | O24: 2.41 | P24: 0.4 | Q24: 1 | R24: 107.94 | S24: 2.2327 | T24: 1 | U24: 100 | V24: 107.94 | W24: 100
A25: 43678 | B25: ENABLED | C25: A-M-B | D25: CAMPAIGN_STATUS_ENABLED | E25: SP | F25: MANUAL | G25: LEGACY | H25: 43412 | K25: 10 | L25: 6566 | M25: 60 | N25: 0.9138 | O25: 17.96 | P25: 0.3 | Q25: 3 | R25: 161.91 | S25: 11.0926 | T25: 0 | U25: 0 | V25: 0 | W25: 0
A26: 43678 | B26: ENABLED | C26: 15382lanbai-M-E | D26: CAMPAIGN_STATUS_ENABLED | E26: SP | F26: MANUAL | G26: LEGACY | H26: 43663 | K26: 10 | L26: 1326 | M26: 7 | N26: 0.5279 | O26: 4.24 | P26: 0.61 | Q26: 2 | R26: 34.34 | S26: 12.3471 | T26: 0 | U26: 0 | V26: 0 | W26: 0
A27: 43678 | B27: ENABLED | C27: 1537hblueL-M-E | D27: CAMPAIGN_STATUS_ENABLED | E27: SP | F27: MANUAL | G27: LEGACY | H27: 43663 | K27: 10 | L27: 927 | M27: 14 | N27: 1.5102 | O27: 9.68 | P27: 0.69 | Q27: 2 | R27: 71.97 | S27: 13.45 | T27: 0 | U27: 0 | V27: 0 | W27: 0
A28: 43679 | B28: ENABLED | C28: Bc-M-B | D28: CAMPAIGN_STATUS_ENABLED | E28: SP | F28: MANUAL | G28: LEGACY | H28: 43420 | K28: 5 | L28: 0 | M28: 0 | N28: 0 | O28: 0 | P28: 0 | Q28: 0 | R28: 0 | S28: 0 | T28: 0 | U28: 0 | V28: 0 | W28: 0
A29: 43679 | B29: ENABLED | C29: Cb-M-E | D29: CAMPAIGN_STATUS_ENABLED | E29: SP | F29: MANUAL | G29: LEGACY | H29: 43667 | K29: 10 | L29: 0 | M29: 0 | N29: 0 | O29: 0 | P29: 0 | Q29: 0 | R29: 0 | S29: 0 | T29: 0 | U29: 0 | V29: 0 | W29: 0
A30: 43679 | B30: ENABLED | C30: R-A | D30: CAMPAIGN_STATUS_ENABLED | E30: SP | F30: AUTOMATIC | G30: LEGACY | H30: 43388 | K30: 5 | L30: 0 | M30: 0 | N30: 0 | O30: 0 | P30: 0 | Q30: 0 | R30: 0 | S30: 0 | T30: 0 | U30: 0 | V30: 0 | W30: 0
A31: 43679 | B31: ENABLED | C31: 1537hblueL-M-E | D31: CAMPAIGN_STATUS_ENABLED | E31: SP | F31: MANUAL | G31: LEGACY | H31: 43663 | K31: 10 | L31: 1154 | M31: 0 | N31: 0 | O31: 0 | P31: 0 | Q31: 0 | R31: 0 | S31: 0 | T31: 0 | U31: 0 | V31: 0 | W31: 0
A32: 43679 | B32: ENABLED | C32: 品牌推广 | D32: RUNNING | E32: SB | F32: MANUAL | H32: 43671 | K32: 2 | L32: 779 | M32: 6 | N32: 0.7702 | O32: 2.29 | P32: 0.38 | Q32: 0 | R32: 0 | S32: 0 | T32: 0 | U32: 0 | V32: 0 | W32: 0
A33: 43679 | B33: ENABLED | C33: 56BLACK-M-B | D33: CAMPAIGN_STATUS_ENABLED | E33: SP | F33: MANUAL | G33: LEGACY | H33: 43688 | K33: 10 | L33: 0 | M33: 0 | N33: 0 | O33: 0 | P33: 0 | Q33: 0 | R33: 0 | S33: 0 | T33: 0 | U33: 0 | V33: 0 | W33: 0
A34: 43679 | B34: ENABLED | C34: A-A | D34: CAMPAIGN_STATUS_ENABLED | E34: SP | F34: AUTOMATIC | G34: LEGACY | H34: 43387 | K34: 10 | L34: 426 | M34: 2 | N34: 0.4695 | O34: 0.04 | P34: 0.02 | Q34: 0 | R34: 0 | S34: 0 | T34: 0 | U34: 0 | V34: 0 | W34: 0
A35: 43679 | B35: ENABLED | C35: 87green-A | D35: CAMPAIGN_STATUS_ENABLED | E35: SP | F35: AUTOMATIC | G35: LEGACY | H35: 43676 | K35: 10 | L35: 12 | M35: 0 | N35: 0 | O35: 0 | P35: 0 | Q35: 0 | R35: 0 | S35: 0 | T35: 0 | U35: 0 | V35: 0 | W35: 0
A36: 43679 | B36: ENABLED | C36: A-M-E | D36: CAMPAIGN_STATUS_ENABLED | E36: SP | F36: MANUAL | G36: LEGACY | H36: 43661 | K36: 10 | L36: 6964 | M36: 42 | N36: 0.6031 | O36: 10.05 | P36: 0.24 | Q36: 0 | R36: 0 | S36: 0 | T36: 0 | U36: 0 | V36: 0 | W36: 0
A37: 43679 | B37: ENABLED | C37: 37hblueR-M-B | D37: CAMPAIGN_STATUS_ENABLED | E37: SP | F37: MANUAL | G37: LEGACY | H37: 43428 | K37: 10 | L37: 607 | M37: 2 | N37: 0.3295 | O37: 1 | P37: 0.5 | Q37: 0 | R37: 0 | S37: 0 | T37: 0 | U37: 0 | V37: 0 | W37: 0
A38: 43679 | B38: ENABLED | C38: Bc-A | D38: CAMPAIGN_STATUS_ENABLED | E38: SP | F38: AUTOMATIC | G38: LEGACY | H38: 43387 | K38: 5 | L38: 0 | M38: 0 | N38: 0 | O38: 0 | P38: 0 | Q38: 0 | R38: 0 | S38: 0 | T38: 0 | U38: 0 | V38: 0 | W38: 0
A39: 43679 | B39: ENABLED | C39: 15382lanbai-M-E | D39: CAMPAIGN_STATUS_ENABLED | E39: SP | F39: MANUAL | G39: LEGACY | H39: 43663 | K39: 10 | L39: 1566 | M39: 4 | N39: 0.2554 | O39: 2.39 | P39: 0.6 | Q39: 0 | R39: 0 | S39: 0 | T39: 0 | U39: 0 | V39: 0 | W39: 0
A40: 43679 | B40: ENABLED | C40: hblueL-A | D40: CAMPAIGN_STATUS_ENABLED | E40: SP | F40: AUTOMATIC | G40: LEGACY | H40: 43388 | K40: 5 | L40: 5232 | M40: 8 | N40: 0.1529 | O40: 4.86 | P40: 0.61 | Q40: 0 | R40: 0 | S40: 0 | T40: 0 | U40: 0 | V40: 0 | W40: 0
A41: 43679 | B41: ENABLED | C41: Winter Products-Auto | D41: CAMPAIGN_STATUS_ENABLED | E41: SP | F41: AUTOMATIC | G41: LEGACY | H41: 43423 | K41: 3 | L41: 133 | M41: 0 | N41: 0 | O41: 0 | P41: 0 | Q41: 0 | R41: 0 | S41: 0 | T41: 0 | U41: 0 | V41: 0 | W41: 0
A42: 43679 | B42: ENABLED | C42: 56BLACK-A | D42: CAMPAIGN_STATUS_ENABLED | E42: SP | F42: AUTOMATIC | G42: LEGACY | H42: 43647 | K42: 10 | L42: 605 | M42: 0 | N42: 0 | O42: 0 | P42: 0 | Q42: 0 | R42: 0 | S42: 0 | T42: 0 | U42: 0 | V42: 0 | W42: 0
A43: 43679 | B43: ENABLED | C43: 1772GREEN-M-B | D43: CAMPAIGN_STATUS_ENABLED | E43: SP | F43: MANUAL | G43: LEGACY | H43: 43678 | K43: 5 | L43: 316 | M43: 0 | N43: 0 | O43: 0 | P43: 0 | Q43: 0 | R43: 0 | S43: 0 | T43: 0 | U43: 0 | V43: 0 | W43: 0
A44: 43679 | B44: ENABLED | C44: 82lanbai-A | D44: CAMPAIGN_STATUS_ENABLED | E44: SP | F44: AUTOMATIC | G44: LEGACY | H44: 43387 | K44: 5 | L44: 5 | M44: 0 | N44: 0 | O44: 0 | P44: 0 | Q44: 0 | R44: 0 | S44: 0 | T44: 0 | U44: 0 | V44: 0 | W44: 0
... A57: 43680 | B57: ENABLED | C57: 1537hblueL-M-E | D57: CAMPAIGN_STATUS_ENABLED | E57: SP | F57: MANUAL | G57: LEGACY | H57: 43663 | K57: 10 | L57: 632 | M57: 1 | N57: 0.1582 | O57: 0.66 | P57: 0.66 | Q57: 0 | R57: 0 | S57: 0 | T57: 0 | U57: 0 | V57: 0 | W57: 0
A58: 43680 | B58: ENABLED | C58: 品牌推广 | D58: RUNNING | E58: SB | F58: MANUAL | H58: 43671 | K58: 2 | L58: 672 | M58: 6 | N58: 0.8929 | O58: 2.07 | P58: 0.35 | Q58: 0 | R58: 0 | S58: 0 | T58: 0 | U58: 0 | V58: 0 | W58: 0
A59: 43680 | B59: ENABLED | C59: 56BLACK-M-B | D59: CAMPAIGN_STATUS_ENABLED | E59: SP | F59: MANUAL | G59: LEGACY | H59: 43688 | K59: 10 | L59: 0 | M59: 0 | N59: 0 | O59: 0 | P59: 0 | Q59: 0 | R59: 0 | S59: 0 | T59: 0 | U59: 0 | V59: 0 | W59: 0
A60: 43680 | B60: ENABLED | C60: A-A | D60: CAMPAIGN_STATUS_ENABLED | E60: SP | F60: AUTOMATIC | G60: LEGACY | H60: 43387 | K60: 10 | L60: 551 | M60: 5 | N60: 0.9074 | O60: 0.2 | P60: 0.04 | Q60: 0 | R60: 0 | S60: 0 | T60: 0 | U60: 0 | V60: 0 | W60: 0
A61: 43680 | B61: ENABLED | C61: 87green-A | D61: CAMPAIGN_STATUS_ENABLED | E61: SP | F61: AUTOMATIC | G61: LEGACY | H61: 43676 | K61: 10 | L61: 14 | M61: 0 | N61: 0 | O61: 0 | P61: 0 | Q61: 0 | R61: 0 | S61: 0 | T61: 0 | U61: 0 | V61: 0 | W61: 0
...

Sheet query
A1: 日期 | B1: 广告活动 | C1: 预算(CNY) | D1: 曝光量 | E1: 点击次数 | F1: 点击率 (CTR)(%) | G1: 花费(CNY) | H1: 每次点击费用 (CPC)(CNY) | I1: 订单 | J1: 销售额(CNY) | K1: 广告投入产出比 (ACOS)(%) | L1: 新买家订单数 | M1: 新买家订单比 | N1: 新买家销量 | O1: 新买家销量比
A2: 43678 | B2: Bc-M-B | C2: 5 | D2: 0 | E2: 0 | F2: 0 | G2: 0 | H2: 0 | I2: 0 | J2: 0 | K2: 0 | L2: 0 | M2: 0 | N2: 0 | O2: 0
A3: 43678 | B3: Cb-M-E | C3: 10 | D3: 0 | E3: 0 | F3: 0 | G3: 0 | H3: 0 | I3: 0 | J3: 0 | K3: 0 | L3: 0 | M3: 0 | N3: 0 | O3: 0
A4: 43678 | B4: R-A | C4: 5 | D4: 0 | E4: 0 | F4: 0 | G4: 0 | H4: 0 | I4: 0 | J4: 0 | K4: 0 | L4: 0 | M4: 0 | N4: 0 | O4: 0
A5: 43678 | B5: 56BLACK-M-B | C5: 10 | D5: 0 | E5: 0 | F5: 0 | G5: 0 | H5: 0 | I5: 0 | J5: 0 | K5: 0 | L5: 0 | M5: 0 | N5: 0 | O5: 0
A6: 43678 | B6: A-A | C6: 10 | D6: 635 | E6: 4 | F6: 0.6299 | G6: 0.18 | H6: 0.05 | I6: 0 | J6: 0 | K6: 0 | L6: 0 | M6: 0 | N6: 0 | O6: 0
A7: 43678 | B7: 87green-A | C7: 10 | D7: 14 | E7: 0 | F7: 0 | G7: 0 | H7: 0 | I7: 0 | J7: 0 | K7: 0 | L7: 0 | M7: 0 | N7: 0 | O7: 0
A8: 43678 | B8: A-M-E | C8: 10 | D8: 6163 | E8: 41 | F8: 0.6653 | G8: 10.56 | H8: 0.26 | I8: 0 | J8: 0 | K8: 0 | L8: 0 | M8: 0 | N8: 0 | O8: 0
A9: 43678 | B9: 37hblueR-M-B | C9: 10 | D9: 1047 | E9: 6 | F9: 0.5731 | G9: 3.59 | H9: 0.6 | I9: 0 | J9: 0 | K9: 0 | L9: 0 | M9: 0 | N9: 0 | O9: 0
A10: 43678 | B10: Bc-A | C10: 5 | D10: 0 | E10: 0 | F10: 0 | G10: 0 | H10: 0 | I10: 0 | J10: 0 | K10: 0 | L10: 0 | M10: 0 | N10: 0 | O10: 0
A11: 43678 | B11: hblueL-A | C11: 5 | D11: 5231 | E11: 9 | F11: 0.1721 | G11: 5.4 | H11: 0.6 | I11: 0 | J11: 0 | K11: 0 | L11: 0 | M11: 0 | N11: 0 | O11: 0
A12: 43678 | B12: Winter Products-Auto | C12: 3 | D12: 158 | E12: 1 | F12: 0.6329 | G12: 0.1 | H12: 0.1 | I12: 0 | J12: 0 | K12: 0 | L12: 0 | M12: 0 | N12: 0 | O12: 0
A13: 43678 | B13: 56BLACK-A | C13: 10 | D13: 1258 | E13: 6 | F13: 0.4769 | G13: 3.85 | H13: 0.64 | I13: 0 | J13: 0 | K13: 0 | L13: 0 | M13: 0 | N13: 0 | O13: 0
... A651: 43702 | B651: 15382lanbai-M-E | C651: 10 | D651: 2133 | E651: 8 | F651: 0.3751 | G651: 4.66 | H651: 0.58 | I651: 1 | J651: 16.37 | K651: 28.4667 | L651: 0 | M651: 0 | N651: 0 | O651: 0

Sheet day_data
A3: 行标签 | B3: 求和项:预算(CNY) | C3: 求和项:曝光量 | D3: 求和项:点击次数 | E3: 求和项:花费(CNY) | F3: 求和项:点击率 (CTR)(%) | G3: 求和项:每次点击费用 (CPC)(CNY) | H3: 求和项:订单 | I3: 求和项:销售额(CNY) | J3: 求和项:广告投入产出比 (ACOS)(%) | K3: 求和项:新买家订单数 | L3: 求和项:新买家订单比 | M3: 求和项:新买家销量 | N3: 求和项:新买家销量比
A4: 43678 | B4: 242 | C4: 24674 | D4: 161 | E4: 59.61 | F4: 37.5237 | G4: 4.81 | H4: 9 | I4: 456.13 | J4: 40.0102 | K4: 1 | L4: 100 | M4: 107.94 | N4: 100
A5: 43679 | B5: 242 | C5: 23177 | D5: 119 | E5: 37.65 | F5: 4.0059 | G5: 3.16 | H5: 1 | I5: 53.97 | J5: 30.6096 | K5: 0 | L5: 0 | M5: 0 | N5: 0
A6: 43680 | B6: 242 | C6: 27328 | D6: 131 | E6: 41.63 | F6: 6.4124 | G6: 4.56 | H6: 7 | I6: 287.85 | J6: 22.6443 | K6: 0 | L6: 0 | M6: 0 | N6: 0
A7: 43681 | B7: 242 | C7: 24342 | D7: 183 | E7: 59.21 | F7: 9.0289 | G7: 3.93 | H7: 3 | I7: 112.33 | J7: 46.5871 | K7: 0 | L7: 0 | M7: 0 | N7: 0
A8: 43682 | B8: 242 | C8: 28761 | D8: 172 | E8: 71.32 | F8: 7.4391 | G8: 6.6 | H8: 6 | I8: 263.86 | J8: 68.4467 | K8: 0 | L8: 0 | M8: 0 | N8: 0
A9: 43683 | B9: 242 | C9: 33999 | D9: 152 | E9: 54.65 | F9: 6.0879 | G9: 5.98 | H9: 5 | I9: 114.81 | J9: 64.8654 | K9: 0 | L9: 0 | M9: 0 | N9: 0
A10: 43684 | B10: 242 | C10: 30780 | D10: 122 | E10: 42.79 | F10: 6.3242 | G10: 5.28 | H10: 3 | I10: 119.93 | J10: 49.3152 | K10: 0 | L10: 0 | M10: 0 | N10: 0
A11: 43685 | B11: 242 | C11: 24374 | D11: 155 | E11: 50.9 | F11: 7.92 | G11: 4.39 | H11: 2 | I11: 89.94 | J11: 33.8245 | K11: 0 | L11: 0 | M11: 0 | N11: 0
A12: 43686 | B12: 242 | C12: 20432 | D12: 129 | E12: 38.79 | F12: 7.8094 | G12: 4.59 | H12: 6 | I12: 243.88 | J12: 70.4651 | K12: 0 | L12: 0 | M12: 0 | N12: 0
A13: 43687 | B13: 242 | C13: 28183 | D13: 202 | E13: 55.22 | F13: 28.1567 | G13: 4.29 | H13: 5 | I13: 244.89 | J13: 44.3308 | K13: 1 | L13: 100 | M13: 53.97 | N13: 100
A14: 43688 | B14: 242 | C14: 27736 | D14: 202 | E14: 62.79 | F14: 11.666 | G14: 5.01 | H14: 10 | I14: 551.14 | J14: 48.204 | K14: 0 | L14: 0 | M14: 0 | N14: 0
A15: 43689 | B15: 242 | C15: 27941 | D15: 178 | E15: 59.94 | F15: 10.6841 | G15: 4.67 | H15: 7 | I15: 339.87 | J15: 67.7364 | K15: 0 | L15: 0 | M15: 0 | N15: 0
... A28: 43702 | B28: 242 | C28: 22873 | D28: 103 | E28: 34.18 | F28: 9.8738 | G28: 5.85 | H28: 4 | I28: 74.32 | J28: 68.5942 | K28: 0 | L28: 0 | M28: 0 | N28: 0
A29: 总计 | B29: 6050 | C29: 776869 | D29: 3979 | E29: 1391.45 | F29: 275.8182 | G29: 131.9 | H29: 138 | I29: 6207.39 | J29: 1388.6267 | K29: 3 | L29: 300 | M29: 239.88 | N29: 300

Sheet day_控件
A1: =SMALL(day_data!$A:$A,1) -> 43678 | B1: 0 | C1: 21 | E1: 日期 | F1: 1 | L1: 日期 | M1: 预算 | N1: 曝光量 | O1: 点击次数 | P1: 花费 | Q1: 点击率 | R1: cpc | S1: 订单 | T1: 销售额 | U1: ACOS | V1: 新买家订单数 | W1: 新买家订单比 | X1: 新买家销量 | Y1: 新买家销量比
E2: 广告活动 | L2: =A1+B1 -> 43678 | M2: =IF($F$3,IF($L2="","",IFERROR(VLOOKUP($L2,day_data!$A:$O,2,FALSE),0)),NA()) -> #N/A | N2: =IF($F$4,IF($L2="","",IFERROR(VLOOKUP($L2,day_data!$A:$O,3,FALSE),0)),NA()) -> 24674 | O2: =IF($F$5,IF($L2="","",IFERROR(VLOOKUP($L2,day_data!$A:$O,4,FALSE),0)),NA()) -> #N/A | P2: =IF($F$6,IF($L2="","",IFERROR(VLOOKUP($L2,day_data!$A:$O,5,FALSE),0)),NA()) -> #N/A | Q2: =IF($F$7,IF($L2="","",IFERROR(VLOOKUP($L2,day_data!$A:$O,6,FALSE),0)),NA()) -> #N/A | R2: =IF($F$8,IF($L2="","",IFERROR(VLOOKUP($L2,day_data!$A:$O,7,FALSE),0)),NA()) -> #N/A | S2: =IF($F$9,IF($L2="","",IFERROR(VLOOKUP($L2,day_data!$A:$O,8,FALSE),0)),NA()) -> #N/A | T2: =IF($F$10,IF($L2="","",IFERROR(VLOOKUP($L2,day_data!$A:$O,9,FALSE),0)),NA()) -> #N/A | U2: =IF($F$11,IF($L2="","",IFERROR(VLOOKUP($L2,day_data!$A:$O,10,FALSE),0)),NA()) -> #N/A | V2: =IF($F$12,IF($L2="","",IFERROR(VLOOKUP($L2,day_data!$A:$O,11,FALSE),0)),NA()) -> #N/A | W2: =IF($F$13,IF($L2="","",IFERROR(VLOOKUP($L2,day_data!$A:$O,12,FALSE),0)),NA()) -> #N/A | X2: =IF($F$14,IF($L2="","",IFERROR(VLOOKUP($L2,day_data!$A:$O,13,FALSE),0)),NA()) -> #N/A | Y2: =IF($F$15,IF($L2="","",IFERROR(VLOOKUP($L2,day_data!$A:$O,14,FALSE),0)),NA()) -> #N/A
E3: 预算 | F3: FALSE | L3: =IF(ROW(L3)-1>$C$1,"",L2+1) -> 43679 | M3: =IF($F$3,IF($L3="","",IFERROR(VLOOKUP($L3,day_data!$A:$O,2,FALSE),0)),NA()) -> #N/A | N3: =IF($F$4,IF($L3="","",IFERROR(VLOOKUP($L3,day_data!$A:$O,3,FALSE),0)),NA()) -> 23177 | O3: =IF($F$5,IF($L3="","",IFERROR(VLOOKUP($L3,day_data!$A:$O,4,FALSE),0)),NA()) -> #N/A | P3: =IF($F$6,IF($L3="","",IFERROR(VLOOKUP($L3,day_data!$A:$O,5,FALSE),0)),NA()) -> #N/A | Q3: =IF($F$7,IF($L3="","",IFERROR(VLOOKUP($L3,day_data!$A:$O,6,FALSE),0)),NA()) -> #N/A | R3: =IF($F$8,IF($L3="","",IFERROR(VLOOKUP($L3,day_data!$A:$O,7,FALSE),0)),NA()) -> #N/A | S3: =IF($F$9,IF($L3="","",IFERROR(VLOOKUP($L3,day_data!$A:$O,8,FALSE),0)),NA()) -> #N/A | T3: =IF($F$10,IF($L3="","",IFERROR(VLOOKUP($L3,day_data!$A:$O,9,FALSE),0)),NA()) -> #N/A | U3: =IF($F$11,IF($L3="","",IFERROR(VLOOKUP($L3,day_data!$A:$O,10,FALSE),0)),NA()) -> #N/A | V3: =IF($F$12,IF($L3="","",IFERROR(VLOOKUP($L3,day_data!$A:$O,11,FALSE),0)),NA()) -> #N/A | W3: =IF($F$13,IF($L3="","",IFERROR(VLOOKUP($L3,day_data!$A:$O,12,FALSE),0)),NA()) -> #N/A | X3: =IF($F$14,IF($L3="","",IFERROR(VLOOKUP($L3,day_data!$A:$O,13,FALSE),0)),NA()) -> #N/A | Y3: =IF($F$15,IF($L3="","",IFERROR(VLOOKUP($L3,day_data!$A:$O,14,FALSE),0)),NA()) -> #N/A
E4: 曝光量 | F4: TRUE | L4: =IF(ROW(L4)-1>$C$1,"",L3+1) -> 43680 | M4: =IF($F$3,IF($L4="","",IFERROR(VLOOKUP($L4,day_data!$A:$O,2,FALSE),0)),NA()) -> #N/A | N4: =IF($F$4,IF($L4="","",IFERROR(VLOOKUP($L4,day_data!$A:$O,3,FALSE),0)),NA()) -> 27328 | O4: =IF($F$5,IF($L4="","",IFERROR(VLOOKUP($L4,day_data!$A:$O,4,FALSE),0)),NA()) -> #N/A | P4: =IF($F$6,IF($L4="","",IFERROR(VLOOKUP($L4,day_data!$A:$O,5,FALSE),0)),NA()) -> #N/A | Q4: =IF($F$7,IF($L4="","",IFERROR(VLOOKUP($L4,day_data!$A:$O,6,FALSE),0)),NA()) -> #N/A | R4: =IF($F$8,IF($L4="","",IFERROR(VLOOKUP($L4,day_data!$A:$O,7,FALSE),0)),NA()) -> #N/A | S4: =IF($F$9,IF($L4="","",IFERROR(VLOOKUP($L4,day_data!$A:$O,8,FALSE),0)),NA()) -> #N/A | T4: =IF($F$10,IF($L4="","",IFERROR(VLOOKUP($L4,day_data!$A:$O,9,FALSE),0)),NA()) -> #N/A | U4: =IF($F$11,IF($L4="","",IFERROR(VLOOKUP($L4,day_data!$A:$O,10,FALSE),0)),NA()) -> #N/A | V4: =IF($F$12,IF($L4="","",IFERROR(VLOOKUP($L4,day_data!$A:$O,11,FALSE),0)),NA()) -> #N/A | W4: =IF($F$13,IF($L4="","",IFERROR(VLOOKUP($L4,day_data!$A:$O,12,FALSE),0)),NA()) -> #N/A | X4: =IF($F$14,IF($L4="","",IFERROR(VLOOKUP($L4,day_data!$A:$O,13,FALSE),0)),NA()) -> #N/A | Y4: =IF($F$15,IF($L4="","",IFERROR(VLOOKUP($L4,day_data!$A:$O,14,FALSE),0)),NA()) -> #N/A
E5: 点击次数 | F5: FALSE | L5: =IF(ROW(L5)-1>$C$1,"",L4+1) -> 43681 | M5: =IF($F$3,IF($L5="","",IFERROR(VLOOKUP($L5,day_data!$A:$O,2,FALSE),0)),NA()) -> #N/A | N5: =IF($F$4,IF($L5="","",IFERROR(VLOOKUP($L5,day_data!$A:$O,3,FALSE),0)),NA()) -> 24342 | O5: =IF($F$5,IF($L5="","",IFERROR(VLOOKUP($L5,day_data!$A:$O,4,FALSE),0)),NA()) -> #N/A | P5: =IF($F$6,IF($L5="","",IFERROR(VLOOKUP($L5,day_data!$A:$O,5,FALSE),0)),NA()) -> #N/A | Q5: =IF($F$7,IF($L5="","",IFERROR(VLOOKUP($L5,day_data!$A:$O,6,FALSE),0)),NA()) -> #N/A | R5: =IF($F$8,IF($L5="","",IFERROR(VLOOKUP($L5,day_data!$A:$O,7,FALSE),0)),NA()) -> #N/A | S5: =IF($F$9,IF($L5="","",IFERROR(VLOOKUP($L5,day_data!$A:$O,8,FALSE),0)),NA()) -> #N/A | T5: =IF($F$10,IF($L5="","",IFERROR(VLOOKUP($L5,day_data!$A:$O,9,FALSE),0)),NA()) -> #N/A | U5: =IF($F$11,IF($L5="","",IFERROR(VLOOKUP($L5,day_data!$A:$O,10,FALSE),0)),NA()) -> #N/A | V5: =IF($F$12,IF($L5="","",IFERROR(VLOOKUP($L5,day_data!$A:$O,11,FALSE),0)),NA()) -> #N/A | W5: =IF($F$13,IF($L5="","",IFERROR(VLOOKUP($L5,day_data!$A:$O,12,FALSE),0)),NA()) -> #N/A | X5: =IF($F$14,IF($L5="","",IFERROR(VLOOKUP($L5,day_data!$A:$O,13,FALSE),0)),NA()) -> #N/A | Y5: =IF($F$15,IF($L5="","",IFERROR(VLOOKUP($L5,day_data!$A:$O,14,FALSE),0)),NA()) -> #N/A
E6: 花费 | F6: FALSE | L6: =IF(ROW(L6)-1>$C$1,"",L5+1) -> 43682 | M6: =IF($F$3,IF($L6="","",IFERROR(VLOOKUP($L6,day_data!$A:$O,2,FALSE),0)),NA()) -> #N/A | N6: =IF($F$4,IF($L6="","",IFERROR(VLOOKUP($L6,day_data!$A:$O,3,FALSE),0)),NA()) -> 28761 | O6: =IF($F$5,IF($L6="","",IFERROR(VLOOKUP($L6,day_data!$A:$O,4,FALSE),0)),NA()) -> #N/A | P6: =IF($F$6,IF($L6="","",IFERROR(VLOOKUP($L6,day_data!$A:$O,5,FALSE),0)),NA()) -> #N/A | Q6: =IF($F$7,IF($L6="","",IFERROR(VLOOKUP($L6,day_data!$A:$O,6,FALSE),0)),NA()) -> #N/A | R6: =IF($F$8,IF($L6="","",IFERROR(VLOOKUP($L6,day_data!$A:$O,7,FALSE),0)),NA()) -> #N/A | S6: =IF($F$9,IF($L6="","",IFERROR(VLOOKUP($L6,day_data!$A:$O,8,FALSE),0)),NA()) -> #N/A | T6: =IF($F$10,IF($L6="","",IFERROR(VLOOKUP($L6,day_data!$A:$O,9,FALSE),0)),NA()) -> #N/A | U6: =IF($F$11,IF($L6="","",IFERROR(VLOOKUP($L6,day_data!$A:$O,10,FALSE),0)),NA()) -> #N/A | V6: =IF($F$12,IF($L6="","",IFERROR(VLOOKUP($L6,day_data!$A:$O,11,FALSE),0)),NA()) -> #N/A | W6: =IF($F$13,IF($L6="","",IFERROR(VLOOKUP($L6,day_data!$A:$O,12,FALSE),0)),NA()) -> #N/A | X6: =IF($F$14,IF($L6="","",IFERROR(VLOOKUP($L6,day_data!$A:$O,13,FALSE),0)),NA()) -> #N/A | Y6: =IF($F$15,IF($L6="","",IFERROR(VLOOKUP($L6,day_data!$A:$O,14,FALSE),0)),NA()) -> #N/A
E7: 点击率 | F7: FALSE | L7: =IF(ROW(L7)-1>$C$1,"",L6+1) -> 43683 | M7: =IF($F$3,IF($L7="","",IFERROR(VLOOKUP($L7,day_data!$A:$O,2,FALSE),0)),NA()) -> #N/A | N7: =IF($F$4,IF($L7="","",IFERROR(VLOOKUP($L7,day_data!$A:$O,3,FALSE),0)),NA()) -> 33999 | O7: =IF($F$5,IF($L7="","",IFERROR(VLOOKUP($L7,day_data!$A:$O,4,FALSE),0)),NA()) -> #N/A | P7: =IF($F$6,IF($L7="","",IFERROR(VLOOKUP($L7,day_data!$A:$O,5,FALSE),0)),NA()) -> #N/A | Q7: =IF($F$7,IF($L7="","",IFERROR(VLOOKUP($L7,day_data!$A:$O,6,FALSE),0)),NA()) -> #N/A | R7: =IF($F$8,IF($L7="","",IFERROR(VLOOKUP($L7,day_data!$A:$O,7,FALSE),0)),NA()) -> #N/A | S7: =IF($F$9,IF($L7="","",IFERROR(VLOOKUP($L7,day_data!$A:$O,8,FALSE),0)),NA()) -> #N/A | T7: =IF($F$10,IF($L7="","",IFERROR(VLOOKUP($L7,day_data!$A:$O,9,FALSE),0)),NA()) -> #N/A | U7: =IF($F$11,IF($L7="","",IFERROR(VLOOKUP($L7,day_data!$A:$O,10,FALSE),0)),NA()) -> #N/A | V7: =IF($F$12,IF($L7="","",IFERROR(VLOOKUP($L7,day_data!$A:$O,11,FALSE),0)),NA()) -> #N/A | W7: =IF($F$13,IF($L7="","",IFERROR(VLOOKUP($L7,day_data!$A:$O,12,FALSE),0)),NA()) -> #N/A | X7: =IF($F$14,IF($L7="","",IFERROR(VLOOKUP($L7,day_data!$A:$O,13,FALSE),0)),NA()) -> #N/A | Y7: =IF($F$15,IF($L7="","",IFERROR(VLOOKUP($L7,day_data!$A:$O,14,FALSE),0)),NA()) -> #N/A
E8: cpc | F8: FALSE | L8: =IF(ROW(L8)-1>$C$1,"",L7+1) -> 43684 | M8: =IF($F$3,IF($L8="","",IFERROR(VLOOKUP($L8,day_data!$A:$O,2,FALSE),0)),NA()) -> #N/A | N8: =IF($F$4,IF($L8="","",IFERROR(VLOOKUP($L8,day_data!$A:$O,3,FALSE),0)),NA()) -> 30780 | O8: =IF($F$5,IF($L8="","",IFERROR(VLOOKUP($L8,day_data!$A:$O,4,FALSE),0)),NA()) -> #N/A | P8: =IF($F$6,IF($L8="","",IFERROR(VLOOKUP($L8,day_data!$A:$O,5,FALSE),0)),NA()) -> #N/A | Q8: =IF($F$7,IF($L8="","",IFERROR(VLOOKUP($L8,day_data!$A:$O,6,FALSE),0)),NA()) -> #N/A | R8: =IF($F$8,IF($L8="","",IFERROR(VLOOKUP($L8,day_data!$A:$O,7,FALSE),0)),NA()) -> #N/A | S8: =IF($F$9,IF($L8="","",IFERROR(VLOOKUP($L8,day_data!$A:$O,8,FALSE),0)),NA()) -> #N/A | T8: =IF($F$10,IF($L8="","",IFERROR(VLOOKUP($L8,day_data!$A:$O,9,FALSE),0)),NA()) -> #N/A | U8: =IF($F$11,IF($L8="","",IFERROR(VLOOKUP($L8,day_data!$A:$O,10,FALSE),0)),NA()) -> #N/A | V8: =IF($F$12,IF($L8="","",IFERROR(VLOOKUP($L8,day_data!$A:$O,11,FALSE),0)),NA()) -> #N/A | W8: =IF($F$13,IF($L8="","",IFERROR(VLOOKUP($L8,day_data!$A:$O,12,FALSE),0)),NA()) -> #N/A | X8: =IF($F$14,IF($L8="","",IFERROR(VLOOKUP($L8,day_data!$A:$O,13,FALSE),0)),NA()) -> #N/A | Y8: =IF($F$15,IF($L8="","",IFERROR(VLOOKUP($L8,day_data!$A:$O,14,FALSE),0)),NA()) -> #N/A
E9: 订单 | F9: FALSE | L9: =IF(ROW(L9)-1>$C$1,"",L8+1) -> 43685 | M9: =IF($F$3,IF($L9="","",IFERROR(VLOOKUP($L9,day_data!$A:$O,2,FALSE),0)),NA()) -> #N/A | N9: =IF($F$4,IF($L9="","",IFERROR(VLOOKUP($L9,day_data!$A:$O,3,FALSE),0)),NA()) -> 24374 | O9: =IF($F$5,IF($L9="","",IFERROR(VLOOKUP($L9,day_data!$A:$O,4,FALSE),0)),NA()) -> #N/A | P9: =IF($F$6,IF($L9="","",IFERROR(VLOOKUP($L9,day_data!$A:$O,5,FALSE),0)),NA()) -> #N/A | Q9: =IF($F$7,IF($L9="","",IFERROR(VLOOKUP($L9,day_data!$A:$O,6,FALSE),0)),NA()) -> #N/A | R9: =IF($F$8,IF($L9="","",IFERROR(VLOOKUP($L9,day_data!$A:$O,7,FALSE),0)),NA()) -> #N/A | S9: =IF($F$9,IF($L9="","",IFERROR(VLOOKUP($L9,day_data!$A:$O,8,FALSE),0)),NA()) -> #N/A | T9: =IF($F$10,IF($L9="","",IFERROR(VLOOKUP($L9,day_data!$A:$O,9,FALSE),0)),NA()) -> #N/A | U9: =IF($F$11,IF($L9="","",IFERROR(VLOOKUP($L9,day_data!$A:$O,10,FALSE),0)),NA()) -> #N/A | V9: =IF($F$12,IF($L9="","",IFERROR(VLOOKUP($L9,day_data!$A:$O,11,FALSE),0)),NA()) -> #N/A | W9: =IF($F$13,IF($L9="","",IFERROR(VLOOKUP($L9,day_data!$A:$O,12,FALSE),0)),NA()) -> #N/A | X9: =IF($F$14,IF($L9="","",IFERROR(VLOOKUP($L9,day_data!$A:$O,13,FALSE),0)),NA()) -> #N/A | Y9: =IF($F$15,IF($L9="","",IFERROR(VLOOKUP($L9,day_data!$A:$O,14,FALSE),0)),NA()) -> #N/A
E10: 销售额 | F10: FALSE | L10: =IF(ROW(L10)-1>$C$1,"",L9+1) -> 43686 | M10: =IF($F$3,IF($L10="","",IFERROR(VLOOKUP($L10,day_data!$A:$O,2,FALSE),0)),NA()) -> #N/A | N10: =IF($F$4,IF($L10="","",IFERROR(VLOOKUP($L10,day_data!$A:$O,3,FALSE),0)),NA()) -> 20432 | O10: =IF($F$5,IF($L10="","",IFERROR(VLOOKUP($L10,day_data!$A:$O,4,FALSE),0)),NA()) -> #N/A | P10: =IF($F$6,IF($L10="","",IFERROR(VLOOKUP($L10,day_data!$A:$O,5,FALSE),0)),NA()) -> #N/A | Q10: =IF($F$7,IF($L10="","",IFERROR(VLOOKUP($L10,day_data!$A:$O,6,FALSE),0)),NA()) -> #N/A | R10: =IF($F$8,IF($L10="","",IFERROR(VLOOKUP($L10,day_data!$A:$O,7,FALSE),0)),NA()) -> #N/A | S10: =IF($F$9,IF($L10="","",IFERROR(VLOOKUP($L10,day_data!$A:$O,8,FALSE),0)),NA()) -> #N/A | T10: =IF($F$10,IF($L10="","",IFERROR(VLOOKUP($L10,day_data!$A:$O,9,FALSE),0)),NA()) -> #N/A | U10: =IF($F$11,IF($L10="","",IFERROR(VLOOKUP($L10,day_data!$A:$O,10,FALSE),0)),NA()) -> #N/A | V10: =IF($F$12,IF($L10="","",IFERROR(VLOOKUP($L10,day_data!$A:$O,11,FALSE),0)),NA()) -> #N/A | W10: =IF($F$13,IF($L10="","",IFERROR(VLOOKUP($L10,day_data!$A:$O,12,FALSE),0)),NA()) -> #N/A | X10: =IF($F$14,IF($L10="","",IFERROR(VLOOKUP($L10,day_data!$A:$O,13,FALSE),0)),NA()) -> #N/A | Y10: =IF($F$15,IF($L10="","",IFERROR(VLOOKUP($L10,day_data!$A:$O,14,FALSE),0)),NA()) -> #N/A
E11: ACOS | F11: FALSE | L11: =IF(ROW(L11)-1>$C$1,"",L10+1) -> 43687 | M11: =IF($F$3,IF($L11="","",IFERROR(VLOOKUP($L11,day_data!$A:$O,2,FALSE),0)),NA()) -> #N/A | N11: =IF($F$4,IF($L11="","",IFERROR(VLOOKUP($L11,day_data!$A:$O,3,FALSE),0)),NA()) -> 28183 | O11: =IF($F$5,IF($L11="","",IFERROR(VLOOKUP($L11,day_data!$A:$O,4,FALSE),0)),NA()) -> #N/A | P11: =IF($F$6,IF($L11="","",IFERROR(VLOOKUP($L11,day_data!$A:$O,5,FALSE),0)),NA()) -> #N/A | Q11: =IF($F$7,IF($L11="","",IFERROR(VLOOKUP($L11,day_data!$A:$O,6,FALSE),0)),NA()) -> #N/A | R11: =IF($F$8,IF($L11="","",IFERROR(VLOOKUP($L11,day_data!$A:$O,7,FALSE),0)),NA()) -> #N/A | S11: =IF($F$9,IF($L11="","",IFERROR(VLOOKUP($L11,day_data!$A:$O,8,FALSE),0)),NA()) -> #N/A | T11: =IF($F$10,IF($L11="","",IFERROR(VLOOKUP($L11,day_data!$A:$O,9,FALSE),0)),NA()) -> #N/A | U11: =IF($F$11,IF($L11="","",IFERROR(VLOOKUP($L11,day_data!$A:$O,10,FALSE),0)),NA()) -> #N/A | V11: =IF($F$12,IF($L11="","",IFERROR(VLOOKUP($L11,day_data!$A:$O,11,FALSE),0)),NA()) -> #N/A | W11: =IF($F$13,IF($L11="","",IFERROR(VLOOKUP($L11,day_data!$A:$O,12,FALSE),0)),NA()) -> #N/A | X11: =IF($F$14,IF($L11="","",IFERROR(VLOOKUP($L11,day_data!$A:$O,13,FALSE),0)),NA()) -> #N/A | Y11: =IF($F$15,IF($L11="","",IFERROR(VLOOKUP($L11,day_data!$A:$O,14,FALSE),0)),NA()) -> #N/A
E12: 新买家订单数 | F12: FALSE | L12: =IF(ROW(L12)-1>$C$1,"",L11+1) -> 43688 | M12: =IF($F$3,IF($L12="","",IFERROR(VLOOKUP($L12,day_data!$A:$O,2,FALSE),0)),NA()) -> #N/A | N12: =IF($F$4,IF($L12="","",IFERROR(VLOOKUP($L12,day_data!$A:$O,3,FALSE),0)),NA()) -> 27736 | O12: =IF($F$5,IF($L12="","",IFERROR(VLOOKUP($L12,day_data!$A:$O,4,FALSE),0)),NA()) -> #N/A | P12: =IF($F$6,IF($L12="","",IFERROR(VLOOKUP($L12,day_data!$A:$O,5,FALSE),0)),NA()) -> #N/A | Q12: =IF($F$7,IF($L12="","",IFERROR(VLOOKUP($L12,day_data!$A:$O,6,FALSE),0)),NA()) -> #N/A | R12: =IF($F$8,IF($L12="","",IFERROR(VLOOKUP($L12,day_data!$A:$O,7,FALSE),0)),NA()) -> #N/A | S12: =IF($F$9,IF($L12="","",IFERROR(VLOOKUP($L12,day_data!$A:$O,8,FALSE),0)),NA()) -> #N/A | T12: =IF($F$10,IF($L12="","",IFERROR(VLOOKUP($L12,day_data!$A:$O,9,FALSE),0)),NA()) -> #N/A | U12: =IF($F$11,IF($L12="","",IFERROR(VLOOKUP($L12,day_data!$A:$O,10,FALSE),0)),NA()) -> #N/A | V12: =IF($F$12,IF($L12="","",IFERROR(VLOOKUP($L12,day_data!$A:$O,11,FALSE),0)),NA()) -> #N/A | W12: =IF($F$13,IF($L12="","",IFERROR(VLOOKUP($L12,day_data!$A:$O,12,FALSE),0)),NA()) -> #N/A | X12: =IF($F$14,IF($L12="","",IFERROR(VLOOKUP($L12,day_data!$A:$O,13,FALSE),0)),NA()) -> #N/A | Y12: =IF($F$15,IF($L12="","",IFERROR(VLOOKUP($L12,day_data!$A:$O,14,FALSE),0)),NA()) -> #N/A
E13: 新买家订单比 | F13: FALSE | L13: =IF(ROW(L13)-1>$C$1,"",L12+1) -> 43689 | M13: =IF($F$3,IF($L13="","",IFERROR(VLOOKUP($L13,day_data!$A:$O,2,FALSE),0)),NA()) -> #N/A | N13: =IF($F$4,IF($L13="","",IFERROR(VLOOKUP($L13,day_data!$A:$O,3,FALSE),0)),NA()) -> 27941 | O13: =IF($F$5,IF($L13="","",IFERROR(VLOOKUP($L13,day_data!$A:$O,4,FALSE),0)),NA()) -> #N/A | P13: =IF($F$6,IF($L13="","",IFERROR(VLOOKUP($L13,day_data!$A:$O,5,FALSE),0)),NA()) -> #N/A | Q13: =IF($F$7,IF($L13="","",IFERROR(VLOOKUP($L13,day_data!$A:$O,6,FALSE),0)),NA()) -> #N/A | R13: =IF($F$8,IF($L13="","",IFERROR(VLOOKUP($L13,day_data!$A:$O,7,FALSE),0)),NA()) -> #N/A | S13: =IF($F$9,IF($L13="","",IFERROR(VLOOKUP($L13,day_data!$A:$O,8,FALSE),0)),NA()) -> #N/A | T13: =IF($F$10,IF($L13="","",IFERROR(VLOOKUP($L13,day_data!$A:$O,9,FALSE),0)),NA()) -> #N/A | U13: =IF($F$11,IF($L13="","",IFERROR(VLOOKUP($L13,day_data!$A:$O,10,FALSE),0)),NA()) -> #N/A | V13: =IF($F$12,IF($L13="","",IFERROR(VLOOKUP($L13,day_data!$A:$O,11,FALSE),0)),NA()) -> #N/A | W13: =IF($F$13,IF($L13="","",IFERROR(VLOOKUP($L13,day_data!$A:$O,12,FALSE),0)),NA()) -> #N/A | X13: =IF($F$14,IF($L13="","",IFERROR(VLOOKUP($L13,day_data!$A:$O,13,FALSE),0)),NA()) -> #N/A | Y13: =IF($F$15,IF($L13="","",IFERROR(VLOOKUP($L13,day_data!$A:$O,14,FALSE),0)),NA()) -> #N/A
E14: 新买家销量 | F14: FALSE | L14: =IF(ROW(L14)-1>$C$1,"",L13+1) -> 43690 | M14: =IF($F$3,IF($L14="","",IFERROR(VLOOKUP($L14,day_data!$A:$O,2,FALSE),0)),NA()) -> #N/A | N14: =IF($F$4,IF($L14="","",IFERROR(VLOOKUP($L14,day_data!$A:$O,3,FALSE),0)),NA()) -> 33405 | O14: =IF($F$5,IF($L14="","",IFERROR(VLOOKUP($L14,day_data!$A:$O,4,FALSE),0)),NA()) -> #N/A | P14: =IF($F$6,IF($L14="","",IFERROR(VLOOKUP($L14,day_data!$A:$O,5,FALSE),0)),NA()) -> #N/A | Q14: =IF($F$7,IF($L14="","",IFERROR(VLOOKUP($L14,day_data!$A:$O,6,FALSE),0)),NA()) -> #N/A | R14: =IF($F$8,IF($L14="","",IFERROR(VLOOKUP($L14,day_data!$A:$O,7,FALSE),0)),NA()) -> #N/A | S14: =IF($F$9,IF($L14="","",IFERROR(VLOOKUP($L14,day_data!$A:$O,8,FALSE),0)),NA()) -> #N/A | T14: =IF($F$10,IF($L14="","",IFERROR(VLOOKUP($L14,day_data!$A:$O,9,FALSE),0)),NA()) -> #N/A | U14: =IF($F$11,IF($L14="","",IFERROR(VLOOKUP($L14,day_data!$A:$O,10,FALSE),0)),NA()) -> #N/A | V14: =IF($F$12,IF($L14="","",IFERROR(VLOOKUP($L14,day_data!$A:$O,11,FALSE),0)),NA()) -> #N/A | W14: =IF($F$13,IF($L14="","",IFERROR(VLOOKUP($L14,day_data!$A:$O,12,FALSE),0)),NA()) -> #N/A | X14: =IF($F$14,IF($L14="","",IFERROR(VLOOKUP($L14,day_data!$A:$O,13,FALSE),0)),NA()) -> #N/A | Y14: =IF($F$15,IF($L14="","",IFERROR(VLOOKUP($L14,day_data!$A:$O,14,FALSE),0)),NA()) -> #N/A
E15: 新买家销售比 | F15: FALSE | L15: =IF(ROW(L15)-1>$C$1,"",L14+1) -> 43691 | M15: =IF($F$3,IF($L15="","",IFERROR(VLOOKUP($L15,day_data!$A:$O,2,FALSE),0)),NA()) -> #N/A | N15: =IF($F$4,IF($L15="","",IFERROR(VLOOKUP($L15,day_data!$A:$O,3,FALSE),0)),NA()) -> 34661 | O15: =IF($F$5,IF($L15="","",IFERROR(VLOOKUP($L15,day_data!$A:$O,4,FALSE),0)),NA()) -> #N/A | P15: =IF($F$6,IF($L15="","",IFERROR(VLOOKUP($L15,day_data!$A:$O,5,FALSE),0)),NA()) -> #N/A | Q15: =IF($F$7,IF($L15="","",IFERROR(VLOOKUP($L15,day_data!$A:$O,6,FALSE),0)),NA()) -> #N/A | R15: =IF($F$8,IF($L15="","",IFERROR(VLOOKUP($L15,day_data!$A:$O,7,FALSE),0)),NA()) -> #N/A | S15: =IF($F$9,IF($L15="","",IFERROR(VLOOKUP($L15,day_data!$A:$O,8,FALSE),0)),NA()) -> #N/A | T15: =IF($F$10,IF($L15="","",IFERROR(VLOOKUP($L15,day_data!$A:$O,9,FALSE),0)),NA()) -> #N/A | U15: =IF($F$11,IF($L15="","",IFERROR(VLOOKUP($L15,day_data!$A:$O,10,FALSE),0)),NA()) -> #N/A | V15: =IF($F$12,IF($L15="","",IFERROR(VLOOKUP($L15,day_data!$A:$O,11,FALSE),0)),NA()) -> #N/A | W15: =IF($F$13,IF($L15="","",IFERROR(VLOOKUP($L15,day_data!$A:$O,12,FALSE),0)),NA()) -> #N/A | X15: =IF($F$14,IF($L15="","",IFERROR(VLOOKUP($L15,day_data!$A:$O,13,FALSE),0)),NA()) -> #N/A | Y15: =IF($F$15,IF($L15="","",IFERROR(VLOOKUP($L15,day_data!$A:$O,14,FALSE),0)),NA()) -> #N/A
L16: =IF(ROW(L16)-1>$C$1,"",L15+1) -> 43692 | M16: =IF($F$3,IF($L16="","",IFERROR(VLOOKUP($L16,day_data!$A:$O,2,FALSE),0)),NA()) -> #N/A | N16: =IF($F$4,IF($L16="","",IFERROR(VLOOKUP($L16,day_data!$A:$O,3,FALSE),0)),NA()) -> 33467 | O16: =IF($F$5,IF($L16="","",IFERROR(VLOOKUP($L16,day_data!$A:$O,4,FALSE),0)),NA()) -> #N/A | P16: =IF($F$6,IF($L16="","",IFERROR(VLOOKUP($L16,day_data!$A:$O,5,FALSE),0)),NA()) -> #N/A | Q16: =IF($F$7,IF($L16="","",IFERROR(VLOOKUP($L16,day_data!$A:$O,6,FALSE),0)),NA()) -> #N/A | R16: =IF($F$8,IF($L16="","",IFERROR(VLOOKUP($L16,day_data!$A:$O,7,FALSE),0)),NA()) -> #N/A | S16: =IF($F$9,IF($L16="","",IFERROR(VLOOKUP($L16,day_data!$A:$O,8,FALSE),0)),NA()) -> #N/A | T16: =IF($F$10,IF($L16="","",IFERROR(VLOOKUP($L16,day_data!$A:$O,9,FALSE),0)),NA()) -> #N/A | U16: =IF($F$11,IF($L16="","",IFERROR(VLOOKUP($L16,day_data!$A:$O,10,FALSE),0)),NA()) -> #N/A | V16: =IF($F$12,IF($L16="","",IFERROR(VLOOKUP($L16,day_data!$A:$O,11,FALSE),0)),NA()) -> #N/A | W16: =IF($F$13,IF($L16="","",IFERROR(VLOOKUP($L16,day_data!$A:$O,12,FALSE),0)),NA()) -> #N/A | X16: =IF($F$14,IF($L16="","",IFERROR(VLOOKUP($L16,day_data!$A:$O,13,FALSE),0)),NA()) -> #N/A | Y16: =IF($F$15,IF($L16="","",IFERROR(VLOOKUP($L16,day_data!$A:$O,14,FALSE),0)),NA()) -> #N/A
L17: =IF(ROW(L17)-1>$C$1,"",L16+1) -> 43693 | M17: =IF($F$3,IF($L17="","",IFERROR(VLOOKUP($L17,day_data!$A:$O,2,FALSE),0)),NA()) -> #N/A | N17: =IF($F$4,IF($L17="","",IFERROR(VLOOKUP($L17,day_data!$A:$O,3,FALSE),0)),NA()) -> 25793 | O17: =IF($F$5,IF($L17="","",IFERROR(VLOOKUP($L17,day_data!$A:$O,4,FALSE),0)),NA()) -> #N/A | P17: =IF($F$6,IF($L17="","",IFERROR(VLOOKUP($L17,day_data!$A:$O,5,FALSE),0)),NA()) -> #N/A | Q17: =IF($F$7,IF($L17="","",IFERROR(VLOOKUP($L17,day_data!$A:$O,6,FALSE),0)),NA()) -> #N/A | R17: =IF($F$8,IF($L17="","",IFERROR(VLOOKUP($L17,day_data!$A:$O,7,FALSE),0)),NA()) -> #N/A | S17: =IF($F$9,IF($L17="","",IFERROR(VLOOKUP($L17,day_data!$A:$O,8,FALSE),0)),NA()) -> #N/A | T17: =IF($F$10,IF($L17="","",IFERROR(VLOOKUP($L17,day_data!$A:$O,9,FALSE),0)),NA()) -> #N/A | U17: =IF($F$11,IF($L17="","",IFERROR(VLOOKUP($L17,day_data!$A:$O,10,FALSE),0)),NA()) -> #N/A | V17: =IF($F$12,IF($L17="","",IFERROR(VLOOKUP($L17,day_data!$A:$O,11,FALSE),0)),NA()) -> #N/A | W17: =IF($F$13,IF($L17="","",IFERROR(VLOOKUP($L17,day_data!$A:$O,12,FALSE),0)),NA()) -> #N/A | X17: =IF($F$14,IF($L17="","",IFERROR(VLOOKUP($L17,day_data!$A:$O,13,FALSE),0)),NA()) -> #N/A | Y17: =IF($F$15,IF($L17="","",IFERROR(VLOOKUP($L17,day_data!$A:$O,14,FALSE),0)),NA()) -> #N/A
L18: =IF(ROW(L18)-1>$C$1,"",L17+1) -> 43694 | M18: =IF($F$3,IF($L18="","",IFERROR(VLOOKUP($L18,day_data!$A:$O,2,FALSE),0)),NA()) -> #N/A | N18: =IF($F$4,IF($L18="","",IFERROR(VLOOKUP($L18,day_data!$A:$O,3,FALSE),0)),NA()) -> 36457 | O18: =IF($F$5,IF($L18="","",IFERROR(VLOOKUP($L18,day_data!$A:$O,4,FALSE),0)),NA()) -> #N/A | P18: =IF($F$6,IF($L18="","",IFERROR(VLOOKUP($L18,day_data!$A:$O,5,FALSE),0)),NA()) -> #N/A | Q18: =IF($F$7,IF($L18="","",IFERROR(VLOOKUP($L18,day_data!$A:$O,6,FALSE),0)),NA()) -> #N/A | R18: =IF($F$8,IF($L18="","",IFERROR(VLOOKUP($L18,day_data!$A:$O,7,FALSE),0)),NA()) -> #N/A | S18: =IF($F$9,IF($L18="","",IFERROR(VLOOKUP($L18,day_data!$A:$O,8,FALSE),0)),NA()) -> #N/A | T18: =IF($F$10,IF($L18="","",IFERROR(VLOOKUP($L18,day_data!$A:$O,9,FALSE),0)),NA()) -> #N/A | U18: =IF($F$11,IF($L18="","",IFERROR(VLOOKUP($L18,day_data!$A:$O,10,FALSE),0)),NA()) -> #N/A | V18: =IF($F$12,IF($L18="","",IFERROR(VLOOKUP($L18,day_data!$A:$O,11,FALSE),0)),NA()) -> #N/A | W18: =IF($F$13,IF($L18="","",IFERROR(VLOOKUP($L18,day_data!$A:$O,12,FALSE),0)),NA()) -> #N/A | X18: =IF($F$14,IF($L18="","",IFERROR(VLOOKUP($L18,day_data!$A:$O,13,FALSE),0)),NA()) -> #N/A | Y18: =IF($F$15,IF($L18="","",IFERROR(VLOOKUP($L18,day_data!$A:$O,14,FALSE),0)),NA()) -> #N/A
L19: =IF(ROW(L19)-1>$C$1,"",L18+1) -> 43695 | M19: =IF($F$3,IF($L19="","",IFERROR(VLOOKUP($L19,day_data!$A:$O,2,FALSE),0)),NA()) -> #N/A | N19: =IF($F$4,IF($L19="","",IFERROR(VLOOKUP($L19,day_data!$A:$O,3,FALSE),0)),NA()) -> 38221 | O19: =IF($F$5,IF($L19="","",IFERROR(VLOOKUP($L19,day_data!$A:$O,4,FALSE),0)),NA()) -> #N/A | P19: =IF($F$6,IF($L19="","",IFERROR(VLOOKUP($L19,day_data!$A:$O,5,FALSE),0)),NA()) -> #N/A | Q19: =IF($F$7,IF($L19="","",IFERROR(VLOOKUP($L19,day_data!$A:$O,6,FALSE),0)),NA()) -> #N/A | R19: =IF($F$8,IF($L19="","",IFERROR(VLOOKUP($L19,day_data!$A:$O,7,FALSE),0)),NA()) -> #N/A | S19: =IF($F$9,IF($L19="","",IFERROR(VLOOKUP($L19,day_data!$A:$O,8,FALSE),0)),NA()) -> #N/A | T19: =IF($F$10,IF($L19="","",IFERROR(VLOOKUP($L19,day_data!$A:$O,9,FALSE),0)),NA()) -> #N/A | U19: =IF($F$11,IF($L19="","",IFERROR(VLOOKUP($L19,day_data!$A:$O,10,FALSE),0)),NA()) -> #N/A | V19: =IF($F$12,IF($L19="","",IFERROR(VLOOKUP($L19,day_data!$A:$O,11,FALSE),0)),NA()) -> #N/A | W19: =IF($F$13,IF($L19="","",IFERROR(VLOOKUP($L19,day_data!$A:$O,12,FALSE),0)),NA()) -> #N/A | X19: =IF($F$14,IF($L19="","",IFERROR(VLOOKUP($L19,day_data!$A:$O,13,FALSE),0)),NA()) -> #N/A | Y19: =IF($F$15,IF($L19="","",IFERROR(VLOOKUP($L19,day_data!$A:$O,14,FALSE),0)),NA()) -> #N/A
L20: =IF(ROW(L20)-1>$C$1,"",L19+1) -> 43696 | M20: =IF($F$3,IF($L20="","",IFERROR(VLOOKUP($L20,day_data!$A:$O,2,FALSE),0)),NA()) -> #N/A | N20: =IF($F$4,IF($L20="","",IFERROR(VLOOKUP($L20,day_data!$A:$O,3,FALSE),0)),NA()) -> 50587 | O20: =IF($F$5,IF($L20="","",IFERROR(VLOOKUP($L20,day_data!$A:$O,4,FALSE),0)),NA()) -> #N/A | P20: =IF($F$6,IF($L20="","",IFERROR(VLOOKUP($L20,day_data!$A:$O,5,FALSE),0)),NA()) -> #N/A | Q20: =IF($F$7,IF($L20="","",IFERROR(VLOOKUP($L20,day_data!$A:$O,6,FALSE),0)),NA()) -> #N/A | R20: =IF($F$8,IF($L20="","",IFERROR(VLOOKUP($L20,day_data!$A:$O,7,FALSE),0)),NA()) -> #N/A | S20: =IF($F$9,IF($L20="","",IFERROR(VLOOKUP($L20,day_data!$A:$O,8,FALSE),0)),NA()) -> #N/A | T20: =IF($F$10,IF($L20="","",IFERROR(VLOOKUP($L20,day_data!$A:$O,9,FALSE),0)),NA()) -> #N/A | U20: =IF($F$11,IF($L20="","",IFERROR(VLOOKUP($L20,day_data!$A:$O,10,FALSE),0)),NA()) -> #N/A | V20: =IF($F$12,IF($L20="","",IFERROR(VLOOKUP($L20,day_data!$A:$O,11,FALSE),0)),NA()) -> #N/A | W20: =IF($F$13,IF($L20="","",IFERROR(VLOOKUP($L20,day_data!$A:$O,12,FALSE),0)),NA()) -> #N/A | X20: =IF($F$14,IF($L20="","",IFERROR(VLOOKUP($L20,day_data!$A:$O,13,FALSE),0)),NA()) -> #N/A | Y20: =IF($F$15,IF($L20="","",IFERROR(VLOOKUP($L20,day_data!$A:$O,14,FALSE),0)),NA()) -> #N/A
L21: =IF(ROW(L21)-1>$C$1,"",L20+1) -> 43697 | M21: =IF($F$3,IF($L21="","",IFERROR(VLOOKUP($L21,day_data!$A:$O,2,FALSE),0)),NA()) -> #N/A | N21: =IF($F$4,IF($L21="","",IFERROR(VLOOKUP($L21,day_data!$A:$O,3,FALSE),0)),NA()) -> 48163 | O21: =IF($F$5,IF($L21="","",IFERROR(VLOOKUP($L21,day_data!$A:$O,4,FALSE),0)),NA()) -> #N/A | P21: =IF($F$6,IF($L21="","",IFERROR(VLOOKUP($L21,day_data!$A:$O,5,FALSE),0)),NA()) -> #N/A | Q21: =IF($F$7,IF($L21="","",IFERROR(VLOOKUP($L21,day_data!$A:$O,6,FALSE),0)),NA()) -> #N/A | R21: =IF($F$8,IF($L21="","",IFERROR(VLOOKUP($L21,day_data!$A:$O,7,FALSE),0)),NA()) -> #N/A | S21: =IF($F$9,IF($L21="","",IFERROR(VLOOKUP($L21,day_data!$A:$O,8,FALSE),0)),NA()) -> #N/A | T21: =IF($F$10,IF($L21="","",IFERROR(VLOOKUP($L21,day_data!$A:$O,9,FALSE),0)),NA()) -> #N/A | U21: =IF($F$11,IF($L21="","",IFERROR(VLOOKUP($L21,day_data!$A:$O,10,FALSE),0)),NA()) -> #N/A | V21: =IF($F$12,IF($L21="","",IFERROR(VLOOKUP($L21,day_data!$A:$O,11,FALSE),0)),NA()) -> #N/A | W21: =IF($F$13,IF($L21="","",IFERROR(VLOOKUP($L21,day_data!$A:$O,12,FALSE),0)),NA()) -> #N/A | X21: =IF($F$14,IF($L21="","",IFERROR(VLOOKUP($L21,day_data!$A:$O,13,FALSE),0)),NA()) -> #N/A | Y21: =IF($F$15,IF($L21="","",IFERROR(VLOOKUP($L21,day_data!$A:$O,14,FALSE),0)),NA()) -> #N/A
L22: =IF(ROW(L22)-1>$C$1,"",L21+1) -> 43698 | M22: =IF($F$3,IF($L22="","",IFERROR(VLOOKUP($L22,day_data!$A:$O,2,FALSE),0)),NA()) -> #N/A | N22: =IF($F$4,IF($L22="","",IFERROR(VLOOKUP($L22,day_data!$A:$O,3,FALSE),0)),NA()) -> 43115 | O22: =IF($F$5,IF($L22="","",IFERROR(VLOOKUP($L22,day_data!$A:$O,4,FALSE),0)),NA()) -> #N/A | P22: =IF($F$6,IF($L22="","",IFERROR(VLOOKUP($L22,day_data!$A:$O,5,FALSE),0)),NA()) -> #N/A | Q22: =IF($F$7,IF($L22="","",IFERROR(VLOOKUP($L22,day_data!$A:$O,6,FALSE),0)),NA()) -> #N/A | R22: =IF($F$8,IF($L22="","",IFERROR(VLOOKUP($L22,day_data!$A:$O,7,FALSE),0)),NA()) -> #N/A | S22: =IF($F$9,IF($L22="","",IFERROR(VLOOKUP($L22,day_data!$A:$O,8,FALSE),0)),NA()) -> #N/A | T22: =IF($F$10,IF($L22="","",IFERROR(VLOOKUP($L22,day_data!$A:$O,9,FALSE),0)),NA()) -> #N/A | U22: =IF($F$11,IF($L22="","",IFERROR(VLOOKUP($L22,day_data!$A:$O,10,FALSE),0)),NA()) -> #N/A | V22: =IF($F$12,IF($L22="","",IFERROR(VLOOKUP($L22,day_data!$A:$O,11,FALSE),0)),NA()) -> #N/A | W22: =IF($F$13,IF($L22="","",IFERROR(VLOOKUP($L22,day_data!$A:$O,12,FALSE),0)),NA()) -> #N/A | X22: =IF($F$14,IF($L22="","",IFERROR(VLOOKUP($L22,day_data!$A:$O,13,FALSE),0)),NA()) -> #N/A | Y22: =IF($F$15,IF($L22="","",IFERROR(VLOOKUP($L22,day_data!$A:$O,14,FALSE),0)),NA()) -> #N/A
L23: =IF(ROW(L23)-1>$C$1,"",L22+1) | M23: =IF($F$3,IF($L23="","",IFERROR(VLOOKUP($L23,day_data!$A:$O,2,FALSE),0)),NA()) -> #N/A | N23: =IF($F$4,IF($L23="","",IFERROR(VLOOKUP($L23,day_data!$A:$O,3,FALSE),0)),NA()) | O23: =IF($F$5,IF($L23="","",IFERROR(VLOOKUP($L23,day_data!$A:$O,4,FALSE),0)),NA()) -> #N/A | P23: =IF($F$6,IF($L23="","",IFERROR(VLOOKUP($L23,day_data!$A:$O,5,FALSE),0)),NA()) -> #N/A | Q23: =IF($F$7,IF($L23="","",IFERROR(VLOOKUP($L23,day_data!$A:$O,6,FALSE),0)),NA()) -> #N/A | R23: =IF($F$8,IF($L23="","",IFERROR(VLOOKUP($L23,day_data!$A:$O,7,FALSE),0)),NA()) -> #N/A | S23: =IF($F$9,IF($L23="","",IFERROR(VLOOKUP($L23,day_data!$A:$O,8,FALSE),0)),NA()) -> #N/A | T23: =IF($F$10,IF($L23="","",IFERROR(VLOOKUP($L23,day_data!$A:$O,9,FALSE),0)),NA()) -> #N/A | U23: =IF($F$11,IF($L23="","",IFERROR(VLOOKUP($L23,day_data!$A:$O,10,FALSE),0)),NA()) -> #N/A | V23: =IF($F$12,IF($L23="","",IFERROR(VLOOKUP($L23,day_data!$A:$O,11,FALSE),0)),NA()) -> #N/A | W23: =IF($F$13,IF($L23="","",IFERROR(VLOOKUP($L23,day_data!$A:$O,12,FALSE),0)),NA()) -> #N/A | X23: =IF($F$14,IF($L23="","",IFERROR(VLOOKUP($L23,day_data!$A:$O,13,FALSE),0)),NA()) -> #N/A | Y23: =IF($F$15,IF($L23="","",IFERROR(VLOOKUP($L23,day_data!$A:$O,14,FALSE),0)),NA()) -> #N/A
L24: =IF(ROW(L24)-1>$C$1,"",L23+1) | M24: =IF($F$3,IF($L24="","",IFERROR(VLOOKUP($L24,day_data!$A:$O,2,FALSE),0)),NA()) -> #N/A | N24: =IF($F$4,IF($L24="","",IFERROR(VLOOKUP($L24,day_data!$A:$O,3,FALSE),0)),NA()) | O24: =IF($F$5,IF($L24="","",IFERROR(VLOOKUP($L24,day_data!$A:$O,4,FALSE),0)),NA()) -> #N/A | P24: =IF($F$6,IF($L24="","",IFERROR(VLOOKUP($L24,day_data!$A:$O,5,FALSE),0)),NA()) -> #N/A | Q24: =IF($F$7,IF($L24="","",IFERROR(VLOOKUP($L24,day_data!$A:$O,6,FALSE),0)),NA()) -> #N/A | R24: =IF($F$8,IF($L24="","",IFERROR(VLOOKUP($L24,day_data!$A:$O,7,FALSE),0)),NA()) -> #N/A | S24: =IF($F$9,IF($L24="","",IFERROR(VLOOKUP($L24,day_data!$A:$O,8,FALSE),0)),NA()) -> #N/A | T24: =IF($F$10,IF($L24="","",IFERROR(VLOOKUP($L24,day_data!$A:$O,9,FALSE),0)),NA()) -> #N/A | U24: =IF($F$11,IF($L24="","",IFERROR(VLOOKUP($L24,day_data!$A:$O,10,FALSE),0)),NA()) -> #N/A | V24: =IF($F$12,IF($L24="","",IFERROR(VLOOKUP($L24,day_data!$A:$O,11,FALSE),0)),NA()) -> #N/A | W24: =IF($F$13,IF($L24="","",IFERROR(VLOOKUP($L24,day_data!$A:$O,12,FALSE),0)),NA()) -> #N/A | X24: =IF($F$14,IF($L24="","",IFERROR(VLOOKUP($L24,day_data!$A:$O,13,FALSE),0)),NA()) -> #N/A | Y24: =IF($F$15,IF($L24="","",IFERROR(VLOOKUP($L24,day_data!$A:$O,14,FALSE),0)),NA()) -> #N/A
L25: =IF(ROW(L25)-1>$C$1,"",L24+1) | M25: =IF($F$3,IF($L25="","",IFERROR(VLOOKUP($L25,day_data!$A:$O,2,FALSE),0)),NA()) -> #N/A | N25: =IF($F$4,IF($L25="","",IFERROR(VLOOKUP($L25,day_data!$A:$O,3,FALSE),0)),NA()) | O25: =IF($F$5,IF($L25="","",IFERROR(VLOOKUP($L25,day_data!$A:$O,4,FALSE),0)),NA()) -> #N/A | P25: =IF($F$6,IF($L25="","",IFERROR(VLOOKUP($L25,day_data!$A:$O,5,FALSE),0)),NA()) -> #N/A | Q25: =IF($F$7,IF($L25="","",IFERROR(VLOOKUP($L25,day_data!$A:$O,6,FALSE),0)),NA()) -> #N/A | R25: =IF($F$8,IF($L25="","",IFERROR(VLOOKUP($L25,day_data!$A:$O,7,FALSE),0)),NA()) -> #N/A | S25: =IF($F$9,IF($L25="","",IFERROR(VLOOKUP($L25,day_data!$A:$O,8,FALSE),0)),NA()) -> #N/A | T25: =IF($F$10,IF($L25="","",IFERROR(VLOOKUP($L25,day_data!$A:$O,9,FALSE),0)),NA()) -> #N/A | U25: =IF($F$11,IF($L25="","",IFERROR(VLOOKUP($L25,day_data!$A:$O,10,FALSE),0)),NA()) -> #N/A | V25: =IF($F$12,IF($L25="","",IFERROR(VLOOKUP($L25,day_data!$A:$O,11,FALSE),0)),NA()) -> #N/A | W25: =IF($F$13,IF($L25="","",IFERROR(VLOOKUP($L25,day_data!$A:$O,12,FALSE),0)),NA()) -> #N/A | X25: =IF($F$14,IF($L25="","",IFERROR(VLOOKUP($L25,day_data!$A:$O,13,FALSE),0)),NA()) -> #N/A | Y25: =IF($F$15,IF($L25="","",IFERROR(VLOOKUP($L25,day_data!$A:$O,14,FALSE),0)),NA()) -> #N/A
L26: =IF(ROW(L26)-1>$C$1,"",L25+1) | M26: =IF($F$3,IF($L26="","",IFERROR(VLOOKUP($L26,day_data!$A:$O,2,FALSE),0)),NA()) -> #N/A | N26: =IF($F$4,IF($L26="","",IFERROR(VLOOKUP($L26,day_data!$A:$O,3,FALSE),0)),NA()) | O26: =IF($F$5,IF($L26="","",IFERROR(VLOOKUP($L26,day_data!$A:$O,4,FALSE),0)),NA()) -> #N/A | P26: =IF($F$6,IF($L26="","",IFERROR(VLOOKUP($L26,day_data!$A:$O,5,FALSE),0)),NA()) -> #N/A | Q26: =IF($F$7,IF($L26="","",IFERROR(VLOOKUP($L26,day_data!$A:$O,6,FALSE),0)),NA()) -> #N/A | R26: =IF($F$8,IF($L26="","",IFERROR(VLOOKUP($L26,day_data!$A:$O,7,FALSE),0)),NA()) -> #N/A | S26: =IF($F$9,IF($L26="","",IFERROR(VLOOKUP($L26,day_data!$A:$O,8,FALSE),0)),NA()) -> #N/A | T26: =IF($F$10,IF($L26="","",IFERROR(VLOOKUP($L26,day_data!$A:$O,9,FALSE),0)),NA()) -> #N/A | U26: =IF($F$11,IF($L26="","",IFERROR(VLOOKUP($L26,day_data!$A:$O,10,FALSE),0)),NA()) -> #N/A | V26: =IF($F$12,IF($L26="","",IFERROR(VLOOKUP($L26,day_data!$A:$O,11,FALSE),0)),NA()) -> #N/A | W26: =IF($F$13,IF($L26="","",IFERROR(VLOOKUP($L26,day_data!$A:$O,12,FALSE),0)),NA()) -> #N/A | X26: =IF($F$14,IF($L26="","",IFERROR(VLOOKUP($L26,day_data!$A:$O,13,FALSE),0)),NA()) -> #N/A | Y26: =IF($F$15,IF($L26="","",IFERROR(VLOOKUP($L26,day_data!$A:$O,14,FALSE),0)),NA()) -> #N/A
L27: =IF(ROW(L27)-1>$C$1,"",L26+1) | M27: =IF($F$3,IF($L27="","",IFERROR(VLOOKUP($L27,day_data!$A:$O,2,FALSE),0)),NA()) -> #N/A | N27: =IF($F$4,IF($L27="","",IFERROR(VLOOKUP($L27,day_data!$A:$O,3,FALSE),0)),NA()) | O27: =IF($F$5,IF($L27="","",IFERROR(VLOOKUP($L27,day_data!$A:$O,4,FALSE),0)),NA()) -> #N/A | P27: =IF($F$6,IF($L27="","",IFERROR(VLOOKUP($L27,day_data!$A:$O,5,FALSE),0)),NA()) -> #N/A | Q27: =IF($F$7,IF($L27="","",IFERROR(VLOOKUP($L27,day_data!$A:$O,6,FALSE),0)),NA()) -> #N/A | R27: =IF($F$8,IF($L27="","",IFERROR(VLOOKUP($L27,day_data!$A:$O,7,FALSE),0)),NA()) -> #N/A | S27: =IF($F$9,IF($L27="","",IFERROR(VLOOKUP($L27,day_data!$A:$O,8,FALSE),0)),NA()) -> #N/A | T27: =IF($F$10,IF($L27="","",IFERROR(VLOOKUP($L27,day_data!$A:$O,9,FALSE),0)),NA()) -> #N/A | U27: =IF($F$11,IF($L27="","",IFERROR(VLOOKUP($L27,day_data!$A:$O,10,FALSE),0)),NA()) -> #N/A | V27: =IF($F$12,IF($L27="","",IFERROR(VLOOKUP($L27,day_data!$A:$O,11,FALSE),0)),NA()) -> #N/A | W27: =IF($F$13,IF($L27="","",IFERROR(VLOOKUP($L27,day_data!$A:$O,12,FALSE),0)),NA()) -> #N/A | X27: =IF($F$14,IF($L27="","",IFERROR(VLOOKUP($L27,day_data!$A:$O,13,FALSE),0)),NA()) -> #N/A | Y27: =IF($F$15,IF($L27="","",IFERROR(VLOOKUP($L27,day_data!$A:$O,14,FALSE),0)),NA()) -> #N/A
... L200: =IF(ROW(L200)-1>$C$1,"",L199+1) | M200: =IF($F$3,IF($L200="","",IFERROR(VLOOKUP($L200,day_data!$A:$O,2,FALSE),0)),NA()) -> #N/A | N200: =IF($F$4,IF($L200="","",IFERROR(VLOOKUP($L200,day_data!$A:$O,3,FALSE),0)),NA()) | O200: =IF($F$5,IF($L200="","",IFERROR(VLOOKUP($L200,day_data!$A:$O,4,FALSE),0)),NA()) -> #N/A | P200: =IF($F$6,IF($L200="","",IFERROR(VLOOKUP($L200,day_data!$A:$O,5,FALSE),0)),NA()) -> #N/A | Q200: =IF($F$7,IF($L200="","",IFERROR(VLOOKUP($L200,day_data!$A:$O,6,FALSE),0)),NA()) -> #N/A | R200: =IF($F$8,IF($L200="","",IFERROR(VLOOKUP($L200,day_data!$A:$O,7,FALSE),0)),NA()) -> #N/A | S200: =IF($F$9,IF($L200="","",IFERROR(VLOOKUP($L200,day_data!$A:$O,8,FALSE),0)),NA()) -> #N/A | T200: =IF($F$10,IF($L200="","",IFERROR(VLOOKUP($L200,day_data!$A:$O,9,FALSE),0)),NA()) -> #N/A | U200: =IF($F$11,IF($L200="","",IFERROR(VLOOKUP($L200,day_data!$A:$O,10,FALSE),0)),NA()) -> #N/A | V200: =IF($F$12,IF($L200="","",IFERROR(VLOOKUP($L200,day_data!$A:$O,11,FALSE),0)),NA()) -> #N/A | W200: =IF($F$13,IF($L200="","",IFERROR(VLOOKUP($L200,day_data!$A:$O,12,FALSE),0)),NA()) -> #N/A | X200: =IF($F$14,IF($L200="","",IFERROR(VLOOKUP($L200,day_data!$A:$O,13,FALSE),0)),NA()) -> #N/A | Y200: =IF($F$15,IF($L200="","",IFERROR(VLOOKUP($L200,day_data!$A:$O,14,FALSE),0)),NA()) -> #N/A

Sheet 广告分析表
M1: 开始日期 | N1: ： | O1: =MIN(day_控件!L2:L200) -> 43678
M3: 结束日期 | N3: ： | O3: =MAX(day_控件!L2:L200) -> 43698
