Workbook

Sheet 市场分析
A1: 是否为成功新品 | B1: Brand | C1: ASIN | D1: 产品数量 | E1: 销量 | F1: 30天销量占比 | H1: CategXry BSR | I1: SXb-CategXry | J1: Brand | K1: ASIN | L1: 30-day sales | M1: 月销占比 | N1: 累计占比 | O1: 累计量 | Q1: Brand | R1: 月销量 | S1: 月销量占比 | T1: 累计占比 | U1: 累计量 | W1: Brand | X1: 产品数 | Y1: 产品数占比 | Z1: 产品平均销量 | AC1: Seller TyXXe | AD1: 月销量 | AE1: 月销量占比 | AH1: 上架年份 | AI1: 上架年月 | AJ1: Brand | AK1: ASIN | AL1: 平均销量 | AO1: 评论数区间 | AP1: 产品数量 | AQ1: 产品数量占比 | AT1: 评论数区间 | AU1: 平均销量 | AV1: 总销量 | AW1: 总销量占比 | AZ1: 价格区间 | BA1: 产品数量 | BB1: 产品量占比 | BC1: 平均销量
A2: 是 | B2: MXehieX | C2: B09CGXCNNT | D2: 1 | E2: 44 | F2: 0.00040361048 | H2: 72 | I2: XXianXs & KeybXards | J2: M SANMERSEN | K2: B01M5AWZKC | L2: 14180 | M2: 0.13007265 | N2: 0.13007265 | O2: 1 | Q2: M SANMERSEN | R2: 23727 | S2: 0.21764695 | T2: 0.21764695 | U2: 1 | W2: M SANMERSEN | X2: 12 | Y2: 0.15 | Z2: 1977.25 | AC2: AMZ | AD2: 2099 | AE2: 0.019254054 | AH2: 2021 | AI2: 2021-01 | AJ2: SXXIA | AK2: B08QTTR9GV | AL2: 198 | AO2: 0-300 | AP2: 48 | AQ2: 0.6 | AT2: >1W | AU2: 14180 | AV2: 14180 | AW2: 0.11022948 | AZ2: 20-30 | BA2: 35 | BB2: 0.4375 | BC2: 1793.0286
B3: ViXziXt | C3: B09J2XX8YNB | D3: 1 | E3: 85 | F3: 0.00077970206 | G3: 不是一个类型 | H3: 171 | I3: Dance Mats | J3: JXyjXz | K3: B08CK9QQMH | L3: 11934 | M3: 0.10947017 | N3: 0.23954282 | O3: 2 | Q3: JXyjXz | R3: 15299 | S3: 0.1403372 | T3: 0.35798415 | U3: 2 | W3: RenFXx | X3: 7 | Y3: 0.0875 | Z3: 1300 | AC3: FBA | AD3: 103608 | AE3: 0.9503926 | AI3: 2021-02 | AJ3: TXyk | AK3: B08SW7WM69 | AL3: 11957 | AO3: 300-600 | AP3: 12 | AQ3: 0.15 | AT3: 3000-5000 | AU3: 4910.75 | AV3: 19643 | AW3: 0.20352858 | AZ3: 10-20 | BA3: 29 | BB3: 0.3625 | BC3: 1181.2069
B4: BEAXRE | C4: B09JWMN24XX | D4: 1 | E4: 238 | F4: 0.0021831658 | G4: 不是一个类型 | H4: 749 | I4: Dance Mats | J4: RenFXx | K4: B07MBDZCXT | L4: 6042 | M4: 0.055423057 | N4: 0.29496588 | O4: 3 | Q4: TXyk | R4: 11957 | S4: 0.10968115 | T4: 0.4676653 | U4: 3 | W4: TWFRIC | X4: 7 | Y4: 0.0875 | Z4: 358.28571 | AC4: NA | AD4: 3309 | AE4: 0.030353343 | AJ4: JXyjXz | AK4: B08VNXXG64W | AL4: 1583 | AO4: 600-900 | AP4: 6 | AQ4: 0.075 | AT4: 5000-10000 | AU4: 4389 | AV4: 8778 | AW4: 0.083097847 | AZ4: 30-40 | BA4: 8 | BB4: 0.1 | BC4: 654.875
B5: EagleStXne | C5: B096FFXQ2Z | D5: 1 | E5: 373 | F5: 0.0034215161 | G5: 3种功能分开 | H5: 753 | I5: XXianXs & KeybXards | J5: TXyk | K5: B08SW7WM69 | L5: 11957 | M5: 0.10968115 | N5: 0.40464702 | O5: 4 | Q5: RenFXx | R5: 9100 | S5: 0.083473985 | T5: 0.55113928 | U5: 4 | W5: JXyjXz | X5: 3 | Y5: 0.0375 | Z5: 5099.6667 | AJ5: RenFXx | AK5: B08NXXNRKXXM | AL5: 61 | AO5: 3000-5000 | AP5: 4 | AQ5: 0.05 | AT5: 2400-3000 | AU5: 2076 | AV5: 4152 | AW5: 0.074898456 | AZ5: 40-50 | BA5: 5 | BB5: 0.0625 | BC5: 1225
B6: FivegXes | C6: B09B3WFQDL | D6: 1 | E6: 96 | F6: 0.00088060468 | G6: 大尺寸 | H6: 1531 | I6: XXianXs & KeybXards | J6: M SANMERSEN | K6: B07MLWHWVQ | L6: 3645 | M6: 0.033435459 | N6: 0.43808248 | O6: 5 | Q6: STREET WALK | R6: 5621 | S6: 0.051561239 | T6: 0.60270052 | U6: 5 | W6: FivegXes | X6: 3 | Y6: 0.0375 | Z6: 393.66667 | AJ6: WXwWee | AK6: B08CTS9J22 | AL6: 877 | AO6: 900-1400 | AP6: 2 | AQ6: 0.025 | AT6: 300-600 | AU6: 2026.6667 | AV6: 24320 | AW6: 0.19659447 | AZ6: 70-100 | BA6: 1 | BB6: 0.0125 | BC6: 99
B7: First Act | C7: B08T59MCGH | D7: 1 | E7: 217 | F7: 0.0019905335 | G7: 较大、盒子装 | H7: 1735 | I7: XXianXs & KeybXards | J7: CicXse | K7: B092DD43M3 | L7: 1064 | M7: 0.0097600352 | N7: 0.44784252 | O7: 6 | Q7: Kidzlane | R7: 3808 | S7: 0.034930652 | T7: 0.63763117 | U7: 6 | W7: zXXrdX | X7: 2 | Y7: 0.025 | Z7: 261.5 | AI7: 2021-03 | AJ7: M SANMERSEN | AK7: B08V5F47R5 | AL7: 534 | AO7: 5000-10000 | AP7: 2 | AQ7: 0.025 | AT7: 900-1400 | AU7: 1893.5 | AV7: 3787 | AW7: 0.031988399 | AZ7: 50-70 | BA7: 1 | BB7: 0.0125 | BC7: 238
B8: BRXADREAM | C8: B09DK8J84Z | D8: 1 | E8: 1123 | F8: 0.01030124 | G8: 43" x 14"、可以作为竞品 | H8: 1784 | I8: XXianXs & KeybXards | J8: CicXse | K8: B092DD43M3 | L8: 1064 | M8: 0.0097600352 | N8: 0.45760255 | O8: 7 | Q8: RetrXth | R8: 3269 | S8: 0.029986424 | T8: 0.6676176 | U8: 7 | W8: Kidzlane | X8: 2 | Y8: 0.025 | Z8: 1904 | AJ8: HXllyhi | AK8: B08SQ9X1BX | AL8: 2157 | AO8: 2400-3000 | AP8: 2 | AQ8: 0.025 | AT8: 600-900 | AU8: 1187.3333 | AV8: 7124 | AW8: 0.081601757 | AZ8: 0-10 | BA8: 1 | BB8: 0.0125 | BC8: 304
B9: M SANMERSEN | C9: B094CSJXXVY | D9: 1 | E9: 144 | F9: 0.001320907 | G9: 乐器 | H9: 2073 | I9: XXianXs & KeybXards | J9: Cyiecw | K9: B07KLTB7WW | L9: 2736 | M9: 0.025097233 | N9: 0.48269979 | O9: 8 | Q9: FXayex | R9: 2810 | S9: 0.025776033 | T9: 0.69339363 | U9: 8 | W9: JefshXn | X9: 2 | Y9: 0.025 | Z9: 1224 | AI9: 2021-04 | AJ9: M SANMERSEN | AK9: B08TLXFX6F | AL9: 443 | AO9: 1400-1900 | AP9: 2 | AQ9: 0.025 | AT9: 1400-1900 | AU9: 911.5 | AV9: 1823 | AW9: 0.019356112
A10: 否 | D10: 72 | E10: 106696 | F10: 0.97871872 | H10: 2140 | I10: XXianXs & KeybXards | J10: STREET WALK | K10: B08BCF9ZX6 | L10: 5621 | M10: 0.051561239 | N10: 0.53426103 | O10: 9 | Q10: Cyiecw | R10: 2736 | S10: 0.025097233 | T10: 0.71849086 | U10: 9 | W10: First Act | X10: 2 | Y10: 0.025 | Z10: 1049.5 | AJ10: CicXse | AK10: B092DD43M3 | AL10: 1064 | AO10: 1900-2400 | AP10: 1 | AQ10: 0.0125 | AT10: 0-300 | AU10: 520.625 | AV10: 24990 | AW10: 0.19724581
H11: 2366 | I11: Dance Mats | J11: Click N' XXlay | K11: B00ZIW4AZ6 | L11: 2638 | M11: 0.024198283 | N11: 0.55845931 | O11: 10 | Q11: Click N' XXlay | R11: 2638 | S11: 0.024198283 | T11: 0.74268915 | U11: 10 | W11: CicXse | X11: 2 | Y11: 0.025 | Z11: 1064 | AJ11: keefXn | AK11: B092J18GB7 | AL11: 461 | AO11: >1W | AP11: 1 | AQ11: 0.0125 | AT11: 1900-2400 | AU11: 219 | AV11: 219 | AW11: 0.0014590976
H12: 2831 | I12: XXianXs & KeybXards | J12: BRXADREAM | K12: B09DK8J84Z | L12: 1123 | M12: 0.01030124 | N12: 0.56876055 | O12: 11 | Q12: TWFRIC | R12: 2508 | S12: 0.023005797 | T12: 0.76569494 | U12: 11 | W12: XXianX Mat | X12: 1 | Y12: 0.0125 | Z12: 244 | AJ12: FivegXes | AK12: B091K2343H | AL12: 719
H13: 3030 | I13: XXianXs & KeybXards | J13: First Act | K13: B08T4Q5GFM | L13: 1882 | M13: 0.017263521 | N13: 0.58602407 | O13: 12 | Q13: JefshXn | R13: 2448 | S13: 0.022455419 | T13: 0.78815036 | U13: 12 | W13: FXXVERA | X13: 1 | Y13: 0.0125 | Z13: 30 | AJ13: AbcXSXXXrt | AK13: B07S2WT15XX | AL13: 1444
H14: 3085 | I14: Dance Mats | J14: DITHIN | K14: B07GXS4YMN | L14: 2005 | M14: 0.018391796 | N14: 0.60441587 | O14: 13 | Q14: HXllyhi | R14: 2157 | S14: 0.019786086 | T14: 0.80793645 | U14: 13 | W14: MXehieX | X14: 1 | Y14: 0.0125 | Z14: 44 | AJ14: RenFXx | AK14: B08R18KWB7 | AL14: 715
H15: 4274 | I15: XXianXs & KeybXards | J15: M SANMERSEN | K15: B07XXBQG4YZ | L15: 1677 | M15: 0.015383063 | N15: 0.61979893 | O15: 14 | Q15: CicXse | R15: 2128 | S15: 0.01952007 | T15: 0.82745652 | U15: 14 | W15: zelavXs | X15: 1 | Y15: 0.0125 | Z15: 33 | AK15: B08R1D576J | AL15: 519
H16: 4367 | I16: XXianXs & KeybXards | J16: HXllyhi | K16: B08SQ9X1BX | L16: 2157 | M16: 0.019786086 | N16: 0.63958502 | O16: 15 | Q16: First Act | R16: 2099 | S16: 0.019254054 | T16: 0.84671057 | U16: 15 | W16: Everneed | X16: 1 | Y16: 0.0125 | Z16: 400 | AI16: 2021-05 | AJ16: M SANMERSEN | AK16: B0923RLKJX | AL16: 222
H17: 6086 | I17: XXianXs & KeybXards | J17: FXayex | K17: B08FYCRNH1 | L17: 2810 | M17: 0.025776033 | N17: 0.66536105 | O17: 16 | Q17: DITHIN | R17: 2005 | S17: 0.018391796 | T17: 0.86510237 | U17: 16 | W17: FAX Schwarz | X17: 1 | Y17: 0.0125 | Z17: 99 | AK17: B08ZXH8LQ2 | AL17: 208
H18: 6648 | I18: XXianXs & KeybXards | J18: keefXn | K18: B092J18GB7 | L18: 461 | M18: 0.0042287371 | N18: 0.66958978 | O18: 17 | Q18: AbcXSXXXrt | R18: 1444 | S18: 0.013245762 | T18: 0.87834813 | U18: 17 | W18: Jakks XXacific | X18: 1 | Y18: 0.0125 | Z18: 166 | AJ18: JefshXn | AK18: B093FB22WT | AL18: 1224
H19: 6989 | I19: Dance Mats | J19: JXyjXz | K19: B08CK4VN1Z | L19: 1782 | M19: 0.016346224 | N19: 0.68593601 | O19: 18 | Q19: EXTSXD | R19: 1426 | S19: 0.013080649 | T19: 0.89142878 | U19: 18 | W19: XKREVIEW | X19: 1 | Y19: 0.0125 | Z19: 17 | AJ19: TWFRIC | AK19: B095S9WH78 | AL19: 240
H20: 7289 | I20: XXianXs & KeybXards | J20: RetrXth | K20: B08CX9TCJS | L20: 3269 | M20: 0.029986424 | N20: 0.71592243 | O20: 19 | Q20: Aywewii | R20: 1414 | S20: 0.012970573 | T20: 0.90439935 | U20: 19 | W20: ALERACX | X20: 1 | Y20: 0.0125 | Z20: 41 | AJ20: Fixget | AK20: B08QRCNYZL | AL20: 163
H21: 7371 | I21: XXianXs & KeybXards | J21: JefshXn | K21: B093FB22WT | L21: 1224 | M21: 0.01122771 | N21: 0.72715014 | O21: 20 | Q21: FivegXes | R21: 1181 | S21: 0.010833272 | T21: 0.91523263 | U21: 20 | W21: WXwWee | X21: 1 | Y21: 0.0125 | Z21: 877 | AJ21: ALERACX | AK21: B01KZHXDKG | AL21: 41
H22: 7536 | I22: Dance Mats | J22: Kidzlane | K22: B07JJM4F7B | L22: 3392 | M22: 0.031114699 | N22: 0.75826484 | O22: 21 | Q22: BRXADREAM | R22: 1123 | S22: 0.01030124 | T22: 0.92553387 | U22: 21 | AJ22: zelavXs | AK22: B0917CL49N | AL22: 33
H23: 7542 | I23: XXianXs & KeybXards | J23: JefshXn | K23: B093FB22WT | L23: 1224 | M23: 0.01122771 | N23: 0.76949255 | O23: 22 | Q23: WXwWee | R23: 877 | S23: 0.0080446907 | T23: 0.93357856 | U23: 22 | AI23: 2021-06 | AJ23: TWFRIC | AK23: B095WB2XLZ | AL23: 196
H24: 8227 | I24: XXianXs & KeybXards | J24: M SANMERSEN | K24: B08XX29K2DY | L24: 893 | M24: 0.0081914581 | N24: 0.77768401 | O24: 23 | Q24: EdXCXties | R24: 862 | S24: 0.0079070962 | T24: 0.94148565 | U24: 23 | AJ24: FivegXes | AK24: B08YR3449T | AL24: 366
H25: 8552 | I25: XXianXs & KeybXards | J25: EdXCXties | K25: B09B7GHZDY | L25: 862 | M25: 0.0079070962 | N25: 0.78559111 | O25: 24 | Q25: XXlay22 | R25: 760 | S25: 0.0069714537 | T25: 0.94845711 | U25: 24 | AJ25: Everneed | AK25: B09414RFHR | AL25: 400
H26: 9294 | I26: XXianXs & KeybXards | J26: EXTSXD | K26: B07XXWCBHMM | L26: 1426 | M26: 0.013080649 | N26: 0.79867175 | O26: 25 | Q26: Minnie MXXse | R26: 736 | S26: 0.0067513026 | T26: 0.95520841 | U26: 25 | AI26: 2021-07 | AJ26: WasXcXl | AK26: B094YKJZ68 | AL26: 396
H27: 9513 | I27: XXianXs & KeybXards | J27: Aywewii | K27: B08CVT2F1G | L27: 1414 | M27: 0.012970573 | N27: 0.81164233 | O27: 26 | AJ27: VNVDFLM | AK27: B0969F2JB8 | AL27: 209
H28: 10580 | I28: XXianXs & KeybXards | J28: TWFRIC | K28: B08FFRLL97 | L28: 724 | M28: 0.006641227 | N28: 0.81828355 | O28: 27 | AI28: 2021-08 | AJ28: M SANMERSEN | AK28: B094CTCXXL4 | AL28: 339
AJ29: First Act | AK29: B08T4Q5GFM | AL29: 1882
AJ30: FXXVERA | AK30: B098DS1VMC | AL30: 30
AI31: 2021-09 | AJ31: EdXCXties | AK31: B09B7GHZDY | AL31: 862
AJ32: TWFRIC | AK32: B09DFJW3C1 | AL32: 630
AJ33: HmiL-X | AK33: B096FKS8Z4 | AL33: 355
AJ34: Grarg | AK34: B09MYDNRKF | AL34: 125
AJ35: JXW | AK35: B098SZZD68 | AL35: 218
AJ36: MXehieX | AK36: B09CGXCNNT | AL36: 44
AI37: 2021-10 | AJ37: M SANMERSEN | AK37: B094CSJXXVY | AL37: 144
AJ38: BRXADREAM | AK38: B09DK8J84Z | AL38: 1123
AJ39: First Act | AK39: B08T59MCGH | AL39: 217
AJ40: FivegXes | AK40: B09B3WFQDL | AL40: 96
...

Sheet 市场分析- 3
B1: 1. 市场汇总(XXXXXXX) | I1: 总计
B2: 国家 | C2: 样本数 | D2: 月均销量 | E2: 月均销售额 | F2: 月总销量 | G2: 月总销售额 | H2: 平均售价 | I2: 预估年总销量 | J2: 预估年总销售额 | K2: 预估年总销售额/¥ | L2: 平均评分数 | M2: 平均星级 | N2: 市场占比
A3: 旺季 | B3: US | C3: 100 | D3: 1971 | E3: 46607 | F3: =D3*C3 -> 197100 | G3: =E3*C3 -> 4660700 | H3: =G3/F3 -> 23.646372 | I3: =F3+F4*11 -> 468112.5 | J3: =G3+G4*11 -> 11069162 | K3: =J3*6.4 -> 70842640 | L3: 662 | M3: 4.3
A4: 淡季 | B4: US | C4: 100 | D4: =D3/8 -> 246.375 | E4: =E3/8 -> 5825.875 | F4: =D4*C4 -> 24637.5 | G4: =E4*C4 -> 582587.5 | H4: =G4/F4 -> 23.646372

Sheet 竞品分析
A1: 1、市场竟对分析
A2: 销量排名 | B2: 我们的产品
A3: 主图
A4: XXXXIN
A5: XXXKU
A6: 品牌 | C6: M XXXXNMERXXXEN | D6: JXyjXz | E6: RenfXx | F6: TXyk | G6: M XXXXNMERXXXEN | H6: CicXXXXe | I6: Cyiecw | J6: XXXTREET WXLK | K6: Click N' PlXy | L6: BRXXDREXM | M6: FirXXXt Xct | N6: DITHIN | O6: M XXXXNMERXXXEN | P6: HXllyhi
A7: 尺寸/cm | C7: 100*36 cm | D7: 100*36 cm | E7: 110 X 36cm | F7: 7.24x15.75 inch | G7: 39.5" X 14"(100*36 cm) | H7: 43.3×14.2 inch | I7: 43.3"x14.2" | K7: 70 x 29" | L7: 36*110cm | N7: 38.2"*14.2" | O7: 53" x 23"（135 x 58 cm） | P7: 15.7"*47.2"
A8: 面板设计 | C8: 红色、动物、钢琴 | G8: 和我们的产品类似
A9: 动物音 | C9: 8种 | D9: 7种 | E9: 无 | F9: 无 | G9: 8种动物 | J9: 无 | K9: 无 | L9: 有 | O9: 有
A10: 音乐 | C10: 钢琴 | D10: 钢琴 | E10: 8种乐器 | F10: 7种乐器、10钢琴健 | G10: 8乐器、10钢琴、 | H10: 7种乐器、10钢琴、10种不同旋律 | I10: 19钢琴健、8种乐器 | J10: 7种乐器、7个黑键 | K10: 8种乐器 | L10: 8种动物音乐、8种乐器 | N10: 9钢琴、8动物音 | O10: 8钢琴、8种动物声音、 | P10: 8钢琴、8种动物声音、
A11: 声音调节 | C11: Y | D11: Y | E11: Y | F11: Y | G11: Y | H11: Y | I11: Y | J11: Y | P11: 无
A12: 灯光 | C12: N | D12: 红色灯光 | E12: 有闪光 | G12: 没有 | J12: 没有 | K12: 没有 | O12: 没有
A13: 其它功能 | C13: N | E13: 5种模式、可录音 | G13: 录音 | H13: 录音、回放 | K13: 4种不同模式
A14: keepX
A15: 中差评 | C15: 声音差、用过的、无法工作、容易坏、滑 | D15: 滑、不工作、廉价、音质差、包装差、故障 | E15: 很快就坏了、很滑、材料劣质、声音不好 | F15: 语言描述错误、声音不好、不工作 | G15: 坏了、按键坏、太吵、滑倒 | H15: 今年6月份上线无差评 | I15: 坏了、延迟、比图片的小、滑 | J15: 读音错、气味难闻 | K15: 无法使用、材料差、 | L15: 无 | M15: 制作廉价、滑 | N15: 太吵、不工作、没声音 | O15: 太吵、太滑 | P15: 不工作、气味不好闻
A16: 备注
A17: 是否对标 | C17: Y | D17: Y | L17: 可作为竞品学习
A18: 价格($) | C18: 20.99 | D18: 28.99 | E18: 28.99 | F18: 19.99 | G18: 16.99 | H18: 21.99 | I18: 17.99 | J18: 19.99 | K18: 34.39 | L18: 23.99 | M18: 19.99 | N18: 14.99 | O18: 28.99 | P18: 20.99
A19: 类目路径
A20: 大类BXXXR | C20: 72 | D20: 171 | E20: 749 | F20: 753 | G20: 1531 | H20: 1735 | I20: 2073 | J20: 2140 | K20: 2366 | L20: 2831 | M20: 3030 | N20: 3085 | O20: 4274 | P20: 4367
A21: 小类目 | C21: PiXnXXXX & KeybXXrdXXX | D21: DXnce MXtXXX | E21: DXnce MXtXXX | F21: PiXnXXXX & KeybXXrdXXX | G21: PiXnXXXX & KeybXXrdXXX | H21: PiXnXXXX & KeybXXrdXXX | I21: PiXnXXXX & KeybXXrdXXX | J21: PiXnXXXX & KeybXXrdXXX | K21: DXnce MXtXXX | L21: PiXnXXXX & KeybXXrdXXX | M21: PiXnXXXX & KeybXXrdXXX | N21: DXnce MXtXXX | O21: PiXnXXXX & KeybXXrdXXX | P21: PiXnXXXX & KeybXXrdXXX
A22: 小类BXXXR | C22: 1 32 | D22: 1 | E22: 2 402 | F22: 2 424 | G22: 4 819 | H22: 4 7 939 | I22: 10 1199 | J22: 11 | K22: 5 1312 | L22: 13 1572 | M22: 14 1695 | N22: 6 1805 | O22: 15 2385 | P22: 16 2436
A23: 月销量 | C23: 14180 | D23: 11934 | E23: 6042 | F23: 11957 | G23: 3645 | H23: 1064 | I23: 2736 | J23: 5621 | K23: 2638 | L23: 1123 | M23: 1882 | N23: 2005 | O23: 1677 | P23: 2157
A24: 月销售额($) | C24: 297638.2 | D24: 345966.66 | E24: 175157.58 | F24: 239020.42 | G24: 76508.55 | H24: 18077.36 | I24: 49220.64 | J24: 112363.79 | K24: 100006.58 | L24: 26940.77 | M24: 37621.18 | N24: 40059.9 | O24: 48616.23 | P24: 45275.43
A25: 毛利率 | C25: 0.6766 | D25: 0.7245 | E25: 0.7207 | F25: 0.6679 | G25: 0.6766 | H25: 0.5587 | I25: 0.6477 | J25: 0.6679 | K25: 0.6527 | L25: 0.6437 | M25: 0.5509 | N25: 0.6638 | O25: 0.4727 | P25: 0.6766
A26: FBX运费($) | C26: 3.64 | D26: 3.64 | E26: 3.75 | F26: 3.64 | G26: 3.64 | H26: 4.95 | I26: 3.64 | J26: 3.64 | K26: 7.48 | L26: 4.95 | M26: 5.98 | N26: 3.72 | O26: 10.94 | P26: 3.64
A27: 评分 | C27: 4.4 | D27: 4.4 | E27: 4.3 | F27: 4 | G27: 4.3 | H27: 4.9 | I27: 4.3 | J27: 4.3 | K27: 4.5 | L27: 4.9 | M27: 4.6 | N27: 4.3 | O27: 4.4 | P27: 4.3
A28: 留评数 | C28: 11991 | D28: 3898 | E28: 8579 | F28: 473 | G28: 4952 | H28: 45 | I28: 5740 | J28: 528 | K28: 3507 | L28: 39 | M28: 40 | N28: 1181 | O28: 1565 | P28: 208
A29: 留评率 | C29: 0.0203 | D29: 0.0211 | E29: 0.0184 | F29: 0.0139 | G29: 0.0121 | H29: 0.0245 | I29: 0.0241 | J29: 0.006 | K29: 0.0083 | L29: 0.0187 | M29: 0.0048 | N29: 0.0035 | O29: 0.0143 | P29: 0.0209
A30: Q&X | C30: 288 | D30: 252 | E30: 111 | F30: 166 | G30: 44 | H30: 29 | I30: 66 | J30: 34 | K30: 22 | L30: 21 | M30: 9 | N30: 7 | O30: 24 | P30: 45
A31: 近30天新增评论数 | C31: 65 | D31: 15 | E31: 66 | F31: 0 | G31: 45 | H31: 23 | I31: 21 | J31: 8 | K31: 81 | L31: 0 | M31: 0 | N31: 19 | O31: 39 | P31: 8
A32: 上架时间 | C32: 2017-04-09 | D32: 2020-08-02 | E32: 2019-02-16 | F32: 2021-02-22 | G32: 2019-02-08 | H32: 2021-04-09 | I32: 2018-11-26 | J32: 2020-07-07 | K32: 2015-09-23 | L32: 2021-10-26 | M32: 2021-08-01 | N32: 2018-09-08 | O32: 2020-02-15 | P32: 2021-03-06
A33: 配送方式 | C33: FBX | D33: FBX | E33: FBX | F33: FBX | G33: FBX | H33: FBX | I33: FBX | J33: FBX | K33: FBX | L33: FBX | M33: XMZ | N33: FBX | O33: FBX | P33: FBX
A34: 变体数 | C34: 1 | D34: 1 | E34: 1 | F34: 1 | G34: 1 | H34: 2 | I34: 1 | J34: 1 | K34: 1 | L34: 1 | M34: 1 | N34: 1 | O34: 1 | P34: 1
A35: 卖家数 | C35: 2 | D35: 2 | E35: 2 | F35: 2 | G35: 2 | H35: 2 | I35: 1 | J35: 2 | K35: 2 | L35: 1 | M35: 26 | N35: 1 | O35: 2 | P35: 2
A36: BuyBXx卖家 | C36: XXXXNMERXXXEN BrXndXXX | D36: JXyMXx | E36: RenfXx-XXXtXre | F36: TXyk TXyXXX | G36: XXXXNMERXXXEN BrXndXXX | H36: LirenuXXX | I36: CYIECW | J36: Pingziiz | K36: XXXhXp & XXXXve | L36: BRXXDREXM | M36: XmXzXn.cXm | N36: XXXGDD | O36: XXXXNMERXXXEN BrXndXXX | P36: YeTXm
A37: 卖家所属地 | C37: CN | D37: CN | E37: CN | F37: CN | G37: CN | H37: CN | I37: CN | J37: CN | K37: UXXX | L37: CN | M37: UXXX | N37: CN | O37: CN | P37: CN
A38: BuyBXx类型 | C38: FBX | D38: FBX | E38: FBX | F38: FBX | G38: FBX | H38: FBX | I38: FBX | J38: FBX | K38: FBX | L38: FBX | M38: XMZ | N38: FBX | O38: FBX | P38: FBX
A39: BeXXXt XXXeller标识 | C39: Y
A40: XmXzXn'XXX ChXice | C40: N
...

Sheet 核心竞争对分析
A1: 日期 | B1: 周数 | C1: BSR排名 | D1: 预估竞对销量 | E1: 排名预估 | F1: 预估销量 | G1: 评分 | H1: 评分数 | I1: 价格($)
A2: 2021/10/26 | B2: 1 | C2: / | D2: 0 | E2: / | F2: 1 | G2: / | H2: / | I2: 21.99
A3: 2021/10/27 | B3: 1 | C3: 177385 | D3: 8 | E3: 177385 | F3: 2 | G3: / | H3: / | I3: 21.99
A4: 2021/10/28 | B4: 1 | C4: 141871 | D4: 8 | E4: 141871 | F4: 2 | G4: / | H4: / | I4: 21.99
A5: 2021/10/29 | B5: 1 | C5: 228149 | D5: 8 | E5: 228149 | F5: 2 | G5: / | H5: / | I5: 21.99
A6: 2021/10/30 | B6: 1 | C6: 200596 | D6: 8 | E6: 200596 | F6: 2 | G6: / | H6: / | I6: 21.99
A7: 2021/10/31 | B7: 2 | C7: 113428 | D7: 8 | E7: 113428 | F7: 2 | G7: / | H7: / | I7: 21.99
A8: 2021/11/01 | B8: 2 | C8: 216651 | D8: 8 | E8: 216651 | F8: 2 | G8: / | H8: / | I8: 21.99
A9: 2021/11/02 | B9: 2 | C9: 180788 | D9: 8 | E9: 180788 | F9: 2 | G9: / | H9: / | I9: 21.99
A10: 2021/11/03 | B10: 2 | C10: 130129 | D10: 16 | E10: 130129 | F10: 3 | G10: / | H10: / | I10: 21.99
A11: 2021/11/04 | B11: 2 | C11: 72803 | D11: 24 | E11: 72803 | F11: 5 | G11: 5 | H11: 1 | I11: 21.99
A12: 2021/11/05 | B12: 2 | C12: 87014 | D12: 24 | E12: 87014 | F12: 5 | G12: 5 | H12: 2 | I12: 21.99
A13: 2021/11/06 | B13: 2 | C13: 88533 | D13: 24 | E13: 88533 | F13: 5 | G13: 5 | H13: 2 | I13: 21.99
A14: 2021/11/07 | B14: 3 | C14: 128444 | D14: 16 | E14: 128444 | F14: 5 | G14: 5 | H14: 4 | I14: 21.99
A15: 2021/11/08 | B15: 3 | C15: 48323 | D15: 40 | E15: 48323 | F15: 8 | G15: 5 | H15: 4 | I15: 21.99
A16: 2021/11/09 | B16: 3 | C16: 46777 | D16: 40 | E16: 46777 | F16: 8 | G16: 5 | H16: 4 | I16: 21.99
A17: 2021/11/10 | B17: 3 | C17: 45465 | D17: 40 | E17: 45465 | F17: 8 | G17: 5 | H17: 5 | I17: 21.99
A18: 2021/11/11 | B18: 3 | C18: 29338 | D18: 48 | E18: 29338 | F18: 14 | G18: 5 | H18: 5 | I18: 21.99
A19: 2021/11/12 | B19: 3 | C19: 39910 | D19: 48 | E19: 39910 | F19: 14 | G19: 5 | H19: 6 | I19: 21.99
A20: 2021/11/13 | B20: 3 | C20: 52307 | D20: 40 | E20: 52307 | F20: 8 | G20: 5 | H20: 6 | I20: 21.99
A21: 2021/11/14 | B21: 4 | C21: 43604 | D21: 40 | E21: 43604 | F21: 12 | G21: 5 | H21: 7 | I21: 21.99
A22: 2021/11/15 | B22: 4 | C22: 54984 | D22: 40 | E22: 54984 | F22: 8 | G22: 5 | H22: 7 | I22: 21.99
... A64: 2021/12/27 | B64: 10 | C64: 2072 | D64: 306 | E64: 5521 | F64: 18 | G64: 4.8 | H64: 47 | I64: 23.99
A65: 2021/12/28 | B65: 10 | C65: / | D65: 153 | E65: 5521 | F65: 18 | G65: 4.6 | H65: 55 | I65: 23.99
A66: 2021/12/29 | B66: 10 | C66: / | D66: 117 | E66: 5521 | F66: 18 | G66: 4.6 | H66: 56 | I66: 23.99
A67: 2021/12/30 | B67: 10 | C67: / | D67: 91 | E67: 5521 | F67: 18 | G67: 4.6 | H67: 58 | I67: 23.99
A68: 2021/12/31 | B68: 10 | C68: / | D68: 77 | E68: 5521 | F68: 18 | G68: 4.6 | H68: 60 | I68: 23.99
A69: 2022/01/01 | B69: =WEEKNUM(A69) -> 1 | C69: 12993 | D69: 66 | E69: 5521 | F69: 20 | G69: 4.6 | H69: 60 | I69: 23.99
A70: 2022/01/02 | B70: =WEEKNUM(A70) -> 2 | C70: 12877 | D70: 66 | E70: 5521 | F70: 20 | G70: 4.6 | H70: 61 | I70: 23.99
A71: 2022/01/03 | B71: =WEEKNUM(A71) -> 2 | C71: 15387 | D71: 55 | E71: 5521 | F71: 20 | G71: 4.6 | H71: 61 | I71: 23.99
A72: 2022/01/04 | B72: =WEEKNUM(A72) -> 2 | C72: 17832 | D72: 48 | E72: 5521 | F72: 20 | G72: 4.6 | H72: 64 | I72: 23.99
A73: 2022/01/05 | B73: =WEEKNUM(A73) -> 2 | C73: 16146 | D73: 56 | E73: 5521 | F73: 20 | G73: 4.6 | H73: 68 | I73: 23.99
A74: 2022/01/06 | B74: =WEEKNUM(A74) -> 2 | C74: 20507 | D74: 40 | E74: 5521 | F74: 20 | G74: 4.6 | H74: 70 | I74: 23.99
A75: 2022/01/07 | B75: =WEEKNUM(A75) -> 2 | C75: 21209 | D75: 38 | E75: 5521 | F75: 20 | G75: 4.6 | H75: 70 | I75: 23.99
A76: 2022/01/08 | B76: =WEEKNUM(A76) -> 2 | C76: 19857 | D76: 40 | E76: 5521 | F76: 20 | G76: 4.6 | H76: 70 | I76: 23.99
A77: 2022/01/09 | B77: =WEEKNUM(A77) -> 3 | C77: 17211 | D77: 44 | E77: 5521 | F77: 33 | G77: 4.6 | H77: 70 | I77: 23.99
A78: 2022/01/10 | B78: =WEEKNUM(A78) -> 3 | C78: 25499 | D78: 32 | E78: 5521 | F78: 33 | G78: 4.6 | H78: 70 | I78: 23.99

Sheet 成本利润核算
A1: 产品名称 | B1: XXXXXXX | F1: 国家 | G1: 美森散货 | H1: 以星散货 | I1: AGL慢船散货 | J1: AGL快船散货 | K1: AGL空派散货 | M1: 采购成本 | N1: 采购陈本$ | O1: FBA费用 | P1: 月仓储费 | R1: 汇率 | U1: FTW1 | V1: 起运港 | W1: 固定费 | X1: 每CBM/RMB | Y1: 其它杂费 | Z1: 1Pcs/RMB | AA1: 1Pcs/USD
A2: 包装尺寸/cm | C2: 17 | F2: 美国 | G2: =(21*B9+3000)/1500/R2 -> 0.31500032 | H2: =(14*B9+3000)/1500/R2 -> 0.31500032 | I2: =AA2 -> 0.37443037 | J2: =AA3 -> 0.38535039 | K2: =AA5 -> 0.63000063 | M2: =26.7 -> 26.7 | N2: =M2/R2 -> 4.2052542 | O2: 3.64 | P2: 0.09 | R2: 6.3492 | U2: AGL一般海运 | V2: 深圳 | W2: 566 | X2: 1254.63 | Y2: 3000 | Z2: =(X2*$B$8+W2+Y2)/1500 -> 2.3773333 | AA2: =Z2/R2 -> 0.37443037
A3: 包装尺寸/inch | C3: =C2*0.394 -> 6.698 | F3: 加拿大 | U3: AGL快船海运 | V3: 深圳 | W3: 670 | X3: 1743.61 | Y3: 3000 | Z3: =(X3*$B$8+W3+Y3)/1500 -> 2.4466667 | AA3: =Z3/R2 -> 0.38535039
A4: 头程体积重/kg | C4: FBA: | F4: 欧洲-德国 | W4: 固定费 | X4: 每KG/RMB | Y4: 其它杂费 | Z4: 1Pcs/RMB | AA4: 1Pcs/USD
A5: 实重/kg | C5: OZ: | F5: 英国 | U5: AGL空派散货 | V5: 深圳 | W5: 0 | X5: 130 | Y5: 6000 | Z5: =(X5*B9+6000)/1500 -> 4 | AA5: =Z5/R2 -> 0.63000063
A6: 实重/bl
A7: 体积/CBM
A8: 1500Pcs体积 | B8: =B7*1500 -> 0 | C8: =B7*1600 -> 0
A9: 1500Pcs重量/kg | B9: =D4*1500 -> 0
D12: P0 | T12: P1
A13: 国家 | B13: 运输方式 | C13: 售价 | D13: 毛利 | E13: 毛利率 | F13: 采购成本 | G13: 头程运费 | H13: FBA运费 | I13: 月仓储费 | J13: 佣金 | K13: VAT费 | L13: 出口退税 | M13: 进口关税 | N13: 关税率 | O13: 广告费 | P13: coupon | Q13: 其它营销费用 | R13: 退货占比 | S13: 汇损占比 | T13: 毛利 | U13: 毛利率 | Y13: 采购成本占比 | Z13: 头程占比 | AA13: FBA占比 | AB13: 佣金 | AC13: 利润率
A14: 美国 | B14: 美森散货 | C14: 16.99 | D14: =C14-SUM(F14:K14)-M14+L14 -> 6.3704525 | E14: =D14/C14 -> 0.37495306 | F14: 4.21 | G14: =$G$2 -> 0.31500032 | H14: =$O$2 -> 3.64 | I14: =$P$2 -> 0.09 | J14: =C14*0.15 -> 2.5485 | K14: 0 | L14: =F14/(1+13%)*13% -> 0.48433628 | M14: =N14*0.5*F14 -> 0.3003835 | N14: 0.1427 | O14: 0.1 | P14: 0.05 | Q14: 0.02 | R14: 0.04 | S14: 0.01 | T14: =C14*U14 -> 2.6326525 | U14: =E14-SUM(O14:S14) -> 0.15495306 | Y14: =F14/C14 -> 0.24779282 | Z14: =G14/C14 -> 0.018540336 | AA14: =H14/C14 -> 0.21424367 | AB14: 0.15 | AC14: =1-SUM(Y14:AB14) -> 0.36942317
A15: 美国 | B15: 美森散货 | C15: 17.99 | D15: =C15-SUM(F15:K15)-M15+L15 -> 7.2204525 | E15: =D15/C15 -> 0.40135923 | F15: 4.21 | G15: =$G$2 -> 0.31500032 | H15: =$O$2 -> 3.64 | I15: =$P$2 -> 0.09 | J15: =C15*0.15 -> 2.6985 | K15: 0 | L15: =F15/(1+13%)*13% -> 0.48433628 | M15: =N15*0.5*F15 -> 0.3003835 | N15: 0.1427 | O15: 0.1 | P15: 0.05 | Q15: 0.02 | R15: 0.04 | S15: 0.01 | T15: =C15*U15 -> 3.2626525 | U15: =E15-SUM(O15:S15) -> 0.18135923 | Y15: =F15/C15 -> 0.2340189 | Z15: =G15/C15 -> 0.017509745 | AA15: =H15/C15 -> 0.20233463 | AB15: 0.15 | AC15: =1-SUM(Y15:AB15) -> 0.39613673
A16: 美国 | B16: 美森散货 | C16: 18.99 | D16: =C16-SUM(F16:K16)-M16+L16 -> 8.0704525 | E16: =D16/C16 -> 0.42498433 | F16: 4.21 | G16: =$G$2 -> 0.31500032 | H16: =$O$2 -> 3.64 | I16: =$P$2 -> 0.09 | J16: =C16*0.15 -> 2.8485 | K16: 0 | L16: =F16/(1+13%)*13% -> 0.48433628 | M16: =N16*0.5*F16 -> 0.3003835 | N16: 0.1427 | O16: 0.1 | P16: 0.05 | Q16: 0.02 | R16: 0.04 | S16: 0.01 | T16: =C16*U16 -> 3.8926525 | U16: =E16-SUM(O16:S16) -> 0.20498433 | Y16: =F16/C16 -> 0.22169563 | Z16: =G16/C16 -> 0.016587694 | AA16: =H16/C16 -> 0.19167983 | AB16: 0.15 | AC16: =1-SUM(Y16:AB16) -> 0.42003684
A17: 美国 | B17: 美森散货 | C17: 19.99 | D17: =C17-SUM(F17:K17)-M17+L17 -> 8.9204525 | E17: =D17/C17 -> 0.44624575 | F17: 4.21 | G17: =$G$2 -> 0.31500032 | H17: =$O$2 -> 3.64 | I17: =$P$2 -> 0.09 | J17: =C17*0.15 -> 2.9985 | K17: 0 | L17: =F17/(1+13%)*13% -> 0.48433628 | M17: =N17*0.5*F17 -> 0.3003835 | N17: 0.1427 | O17: 0.1 | P17: 0.05 | Q17: 0.02 | R17: 0.04 | S17: 0.01 | T17: =C17*U17 -> 4.5226525 | U17: =E17-SUM(O17:S17) -> 0.22624575 | Y17: =F17/C17 -> 0.2106053 | Z17: =G17/C17 -> 0.015757895 | AA17: =H17/C17 -> 0.18209105 | AB17: 0.15 | AC17: =1-SUM(Y17:AB17) -> 0.44154576
A18: 美国 | B18: 美森散货 | C18: 20.99 | D18: =C18-SUM(F18:K18)-M18+L18 -> 9.7704525 | E18: =D18/C18 -> 0.4654813 | F18: 4.21 | G18: =$G$2 -> 0.31500032 | H18: =$O$2 -> 3.64 | I18: =$P$2 -> 0.09 | J18: =C18*0.15 -> 3.1485 | K18: 0 | L18: =F18/(1+13%)*13% -> 0.48433628 | M18: =N18*0.5*F18 -> 0.3003835 | N18: 0.1427 | O18: 0.1 | P18: 0.05 | Q18: 0.02 | R18: 0.04 | S18: 0.01 | T18: =C18*U18 -> 5.1526525 | U18: =E18-SUM(O18:S18) -> 0.2454813 | Y18: =F18/C18 -> 0.2005717 | Z18: =G18/C18 -> 0.015007161 | AA18: =H18/C18 -> 0.17341591 | AB18: 0.15 | AC18: =1-SUM(Y18:AB18) -> 0.46100523
A19: 美国 | B19: 美森散货 | C19: 21.99 | D19: =C19-SUM(F19:K19)-M19+L19 -> 10.620452 | E19: =D19/C19 -> 0.48296737 | F19: 4.21 | G19: =$G$2 -> 0.31500032 | H19: =$O$2 -> 3.64 | I19: =$P$2 -> 0.09 | J19: =C19*0.15 -> 3.2985 | K19: 0 | L19: =F19/(1+13%)*13% -> 0.48433628 | M19: =N19*0.5*F19 -> 0.3003835 | N19: 0.1427 | O19: 0.1 | P19: 0.05 | Q19: 0.02 | R19: 0.04 | S19: 0.01 | T19: =C19*U19 -> 5.7826525 | U19: =E19-SUM(O19:S19) -> 0.26296737 | Y19: =F19/C19 -> 0.19145066 | Z19: =G19/C19 -> 0.014324707 | AA19: =H19/C19 -> 0.16552979 | AB19: 0.15 | AC19: =1-SUM(Y19:AB19) -> 0.47869485
A20: 美国 | B20: 美森散货 | C20: 22.99 | D20: =C20-SUM(F20:K20)-M20+L20 -> 11.470452 | E20: =D20/C20 -> 0.49893225 | F20: 4.21 | G20: =$G$2 -> 0.31500032 | H20: =$O$2 -> 3.64 | I20: =$P$2 -> 0.09 | J20: =C20*0.15 -> 3.4485 | K20: 0 | L20: =F20/(1+13%)*13% -> 0.48433628 | M20: =N20*0.5*F20 -> 0.3003835 | N20: 0.1427 | O20: 0.1 | P20: 0.05 | Q20: 0.02 | R20: 0.04 | S20: 0.01 | T20: =C20*U20 -> 6.4126525 | U20: =E20-SUM(O20:S20) -> 0.27893225 | Y20: =F20/C20 -> 0.1831231 | Z20: =G20/C20 -> 0.013701623 | AA20: =H20/C20 -> 0.15832971 | AB20: 0.15 | AC20: =1-SUM(Y20:AB20) -> 0.49484557
A21: 美国 | B21: 美森散货 | C21: 15.99 | D21: =C21-SUM(F21:K21)-M21+L21 -> 5.5204525 | E21: =D21/C21 -> 0.34524406 | F21: 4.21 | G21: =$G$2 -> 0.31500032 | H21: =$O$2 -> 3.64 | I21: =$P$2 -> 0.09 | J21: =C21*0.15 -> 2.3985 | K21: 0 | L21: =F21/(1+13%)*13% -> 0.48433628 | M21: =N21*0.5*F21 -> 0.3003835 | N21: 0.1427 | O21: 0.1 | P21: 0.05 | Q21: 0.02 | R21: 0.04 | S21: 0.01 | T21: =C21*U21 -> 2.0026525 | U21: =E21-SUM(O21:S21) -> 0.12524406 | Y21: =F21/C21 -> 0.26328956 | Z21: =G21/C21 -> 0.019699832 | AA21: =H21/C21 -> 0.22764228 | AB21: 0.15 | AC21: =1-SUM(Y21:AB21) -> 0.33936834
A23: 美国 | B23: AGL快船散货 | C23: 16.99 | D23: =C23-SUM(F23:K23)-M23+L23 -> 6.3001024 | E23: =D23/C23 -> 0.37081238 | F23: 4.21 | G23: =$J$2 -> 0.38535039 | H23: =$O$2 -> 3.64 | I23: =$P$2 -> 0.09 | J23: =C23*0.15 -> 2.5485 | K23: 0 | L23: =F23/(1+13%)*13% -> 0.48433628 | M23: =N23*0.5*F23 -> 0.3003835 | N23: 0.1427 | O23: 0.1 | P23: 0.05 | Q23: 0.02 | R23: 0.04 | S23: 0.01 | T23: =C23*U23 -> 2.5623024 | U23: =E23-SUM(O23:S23) -> 0.15081238 | Y23: =F23/C23 -> 0.24779282 | Z23: =G23/C23 -> 0.022681011 | AA23: =H23/C23 -> 0.21424367 | AB23: 0.15 | AC23: =1-SUM(Y23:AB23) -> 0.3652825
A24: 美国 | B24: AGL快船散货 | C24: 17.99 | D24: =C24-SUM(F24:K24)-M24+L24 -> 7.1501024 | E24: =D24/C24 -> 0.39744872 | F24: 4.21 | G24: =$J$2 -> 0.38535039 | H24: =$O$2 -> 3.64 | I24: =$P$2 -> 0.09 | J24: =C24*0.15 -> 2.6985 | K24: 0 | L24: =F24/(1+13%)*13% -> 0.48433628 | M24: =N24*0.5*F24 -> 0.3003835 | N24: 0.1427 | O24: 0.1 | P24: 0.05 | Q24: 0.02 | R24: 0.04 | S24: 0.01 | T24: =C24*U24 -> 3.1923024 | U24: =E24-SUM(O24:S24) -> 0.17744872 | Y24: =F24/C24 -> 0.2340189 | Z24: =G24/C24 -> 0.021420255 | AA24: =H24/C24 -> 0.20233463 | AB24: 0.15 | AC24: =1-SUM(Y24:AB24) -> 0.39222622
A25: 美国 | B25: AGL快船散货 | C25: 18.99 | D25: =C25-SUM(F25:K25)-M25+L25 -> 8.0001024 | E25: =D25/C25 -> 0.42127975 | F25: 4.21 | G25: =$J$2 -> 0.38535039 | H25: =$O$2 -> 3.64 | I25: =$P$2 -> 0.09 | J25: =C25*0.15 -> 2.8485 | K25: 0 | L25: =F25/(1+13%)*13% -> 0.48433628 | M25: =N25*0.5*F25 -> 0.3003835 | N25: 0.1427 | O25: 0.1 | P25: 0.05 | Q25: 0.02 | R25: 0.04 | S25: 0.01 | T25: =C25*U25 -> 3.8223024 | U25: =E25-SUM(O25:S25) -> 0.20127975 | Y25: =F25/C25 -> 0.22169563 | Z25: =G25/C25 -> 0.020292279 | AA25: =H25/C25 -> 0.19167983 | AB25: 0.15 | AC25: =1-SUM(Y25:AB25) -> 0.41633226
A26: 美国 | B26: AGL快船散货 | C26: 19.99 | D26: =C26-SUM(F26:K26)-M26+L26 -> 8.8501024 | E26: =D26/C26 -> 0.44272648 | F26: 4.21 | G26: =$J$2 -> 0.38535039 | H26: =$O$2 -> 3.64 | I26: =$P$2 -> 0.09 | J26: =C26*0.15 -> 2.9985 | K26: 0 | L26: =F26/(1+13%)*13% -> 0.48433628 | M26: =N26*0.5*F26 -> 0.3003835 | N26: 0.1427 | O26: 0.1 | P26: 0.05 | Q26: 0.02 | R26: 0.04 | S26: 0.01 | T26: =C26*U26 -> 4.4523024 | U26: =E26-SUM(O26:S26) -> 0.22272648 | Y26: =F26/C26 -> 0.2106053 | Z26: =G26/C26 -> 0.019277158 | AA26: =H26/C26 -> 0.18209105 | AB26: 0.15 | AC26: =1-SUM(Y26:AB26) -> 0.43802649
A27: 美国 | B27: AGL快船散货 | C27: 20.99 | D27: =C27-SUM(F27:K27)-M27+L27 -> 9.7001024 | E27: =D27/C27 -> 0.4621297 | F27: 4.21 | G27: =$J$2 -> 0.38535039 | H27: =$O$2 -> 3.64 | I27: =$P$2 -> 0.09 | J27: =C27*0.15 -> 3.1485 | K27: 0 | L27: =F27/(1+13%)*13% -> 0.48433628 | M27: =N27*0.5*F27 -> 0.3003835 | N27: 0.1427 | O27: 0.1 | P27: 0.05 | Q27: 0.02 | R27: 0.04 | S27: 0.01 | T27: =C27*U27 -> 5.0823024 | U27: =E27-SUM(O27:S27) -> 0.2421297 | Y27: =F27/C27 -> 0.2005717 | Z27: =G27/C27 -> 0.018358761 | AA27: =H27/C27 -> 0.17341591 | AB27: 0.15 | AC27: =1-SUM(Y27:AB27) -> 0.45765363
A28: 美国 | B28: AGL快船散货 | C28: 21.99 | D28: =C28-SUM(F28:K28)-M28+L28 -> 10.550102 | E28: =D28/C28 -> 0.47976819 | F28: 4.21 | G28: =$J$2 -> 0.38535039 | H28: =$O$2 -> 3.64 | I28: =$P$2 -> 0.09 | J28: =C28*0.15 -> 3.2985 | K28: 0 | L28: =F28/(1+13%)*13% -> 0.48433628 | M28: =N28*0.5*F28 -> 0.3003835 | N28: 0.1427 | O28: 0.1 | P28: 0.05 | Q28: 0.02 | R28: 0.04 | S28: 0.01 | T28: =C28*U28 -> 5.7123024 | U28: =E28-SUM(O28:S28) -> 0.25976819 | Y28: =F28/C28 -> 0.19145066 | Z28: =G28/C28 -> 0.017523892 | AA28: =H28/C28 -> 0.16552979 | AB28: 0.15 | AC28: =1-SUM(Y28:AB28) -> 0.47549566
A29: 美国 | B29: AGL快船散货 | C29: 22.99 | D29: =C29-SUM(F29:K29)-M29+L29 -> 11.400102 | E29: =D29/C29 -> 0.49587222 | F29: 4.21 | G29: =$J$2 -> 0.38535039 | H29: =$O$2 -> 3.64 | I29: =$P$2 -> 0.09 | J29: =C29*0.15 -> 3.4485 | K29: 0 | L29: =F29/(1+13%)*13% -> 0.48433628 | M29: =N29*0.5*F29 -> 0.3003835 | N29: 0.1427 | O29: 0.1 | P29: 0.05 | Q29: 0.02 | R29: 0.04 | S29: 0.01 | T29: =C29*U29 -> 6.3423024 | U29: =E29-SUM(O29:S29) -> 0.27587222 | Y29: =F29/C29 -> 0.1831231 | Z29: =G29/C29 -> 0.016761652 | AA29: =H29/C29 -> 0.15832971 | AB29: 0.15 | AC29: =1-SUM(Y29:AB29) -> 0.49178554
A30: 美国 | B30: AGL快船散货 | C30: 15.99 | D30: =C30-SUM(F30:K30)-M30+L30 -> 5.4501024 | E30: =D30/C30 -> 0.34084443 | F30: 4.21 | G30: =$J$2 -> 0.38535039 | H30: =$O$2 -> 3.64 | I30: =$P$2 -> 0.09 | J30: =C30*0.15 -> 2.3985 | K30: 0 | L30: =F30/(1+13%)*13% -> 0.48433628 | M30: =N30*0.5*F30 -> 0.3003835 | N30: 0.1427 | O30: 0.1 | P30: 0.05 | Q30: 0.02 | R30: 0.04 | S30: 0.01 | T30: =C30*U30 -> 1.9323024 | U30: =E30-SUM(O30:S30) -> 0.12084443 | Y30: =F30/C30 -> 0.26328956 | Z30: =G30/C30 -> 0.024099461 | AA30: =H30/C30 -> 0.22764228 | AB30: 0.15 | AC30: =1-SUM(Y30:AB30) -> 0.33496871
A32: 美国 | B32: AGL慢船散货 | C32: 16.99 | D32: =C32-SUM(F32:K32)-M32+L32 -> 6.3110224 | E32: =D32/C32 -> 0.37145512 | F32: 4.21 | G32: =$I$2 -> 0.37443037 | H32: =$O$2 -> 3.64 | I32: =$P$2 -> 0.09 | J32: =C32*0.15 -> 2.5485 | K32: 0 | L32: =F32/(1+13%)*13% -> 0.48433628 | M32: =N32*0.5*F32 -> 0.3003835 | N32: 0.1427 | O32: 0.1 | P32: 0.05 | Q32: 0.02 | R32: 0.04 | S32: 0.01 | T32: =C32*U32 -> 2.5732224 | U32: =E32-SUM(O32:S32) -> 0.15145512 | Y32: =F32/C32 -> 0.24779282 | Z32: =G32/C32 -> 0.02203828 | AA32: =H32/C32 -> 0.21424367 | AB32: 0.15 | AC32: =1-SUM(Y32:AB32) -> 0.36592523
A33: 美国 | B33: AGL慢船散货 | C33: 17.99 | D33: =C33-SUM(F33:K33)-M33+L33 -> 7.1610224 | E33: =D33/C33 -> 0.39805572 | F33: 4.21 | G33: =$I$2 -> 0.37443037 | H33: =$O$2 -> 3.64 | I33: =$P$2 -> 0.09 | J33: =C33*0.15 -> 2.6985 | K33: 0 | L33: =F33/(1+13%)*13% -> 0.48433628 | M33: =N33*0.5*F33 -> 0.3003835 | N33: 0.1427 | O33: 0.1 | P33: 0.05 | Q33: 0.02 | R33: 0.04 | S33: 0.01 | T33: =C33*U33 -> 3.2032224 | U33: =E33-SUM(O33:S33) -> 0.17805572 | Y33: =F33/C33 -> 0.2340189 | Z33: =G33/C33 -> 0.02081325 | AA33: =H33/C33 -> 0.20233463 | AB33: 0.15 | AC33: =1-SUM(Y33:AB33) -> 0.39283322
A34: 美国 | B34: AGL慢船散货 | C34: 18.99 | D34: =C34-SUM(F34:K34)-M34+L34 -> 8.0110224 | E34: =D34/C34 -> 0.42185479 | F34: 4.21 | G34: =$I$2 -> 0.37443037 | H34: =$O$2 -> 3.64 | I34: =$P$2 -> 0.09 | J34: =C34*0.15 -> 2.8485 | K34: 0 | L34: =F34/(1+13%)*13% -> 0.48433628 | M34: =N34*0.5*F34 -> 0.3003835 | N34: 0.1427 | O34: 0.1 | P34: 0.05 | Q34: 0.02 | R34: 0.04 | S34: 0.01 | T34: =C34*U34 -> 3.8332224 | U34: =E34-SUM(O34:S34) -> 0.20185479 | Y34: =F34/C34 -> 0.22169563 | Z34: =G34/C34 -> 0.019717239 | AA34: =H34/C34 -> 0.19167983 | AB34: 0.15 | AC34: =1-SUM(Y34:AB34) -> 0.4169073
A35: 美国 | B35: AGL慢船散货 | C35: 19.99 | D35: =C35-SUM(F35:K35)-M35+L35 -> 8.8610224 | E35: =D35/C35 -> 0.44327276 | F35: 4.21 | G35: =$I$2 -> 0.37443037 | H35: =$O$2 -> 3.64 | I35: =$P$2 -> 0.09 | J35: =C35*0.15 -> 2.9985 | K35: 0 | L35: =F35/(1+13%)*13% -> 0.48433628 | M35: =N35*0.5*F35 -> 0.3003835 | N35: 0.1427 | O35: 0.1 | P35: 0.05 | Q35: 0.02 | R35: 0.04 | S35: 0.01 | T35: =C35*U35 -> 4.4632224 | U35: =E35-SUM(O35:S35) -> 0.22327276 | Y35: =F35/C35 -> 0.2106053 | Z35: =G35/C35 -> 0.018730884 | AA35: =H35/C35 -> 0.18209105 | AB35: 0.15 | AC35: =1-SUM(Y35:AB35) -> 0.43857277
A36: 美国 | B36: AGL慢船散货 | C36: 20.99 | D36: =C36-SUM(F36:K36)-M36+L36 -> 9.7110224 | E36: =D36/C36 -> 0.46264995 | F36: 4.21 | G36: =$I$2 -> 0.37443037 | H36: =$O$2 -> 3.64 | I36: =$P$2 -> 0.09 | J36: =C36*0.15 -> 3.1485 | K36: 0 | L36: =F36/(1+13%)*13% -> 0.48433628 | M36: =N36*0.5*F36 -> 0.3003835 | N36: 0.1427 | O36: 0.1 | P36: 0.05 | Q36: 0.02 | R36: 0.04 | S36: 0.01 | T36: =C36*U36 -> 5.0932224 | U36: =E36-SUM(O36:S36) -> 0.24264995 | Y36: =F36/C36 -> 0.2005717 | Z36: =G36/C36 -> 0.017838512 | AA36: =H36/C36 -> 0.17341591 | AB36: 0.15 | AC36: =1-SUM(Y36:AB36) -> 0.45817387
A37: 美国 | B37: AGL慢船散货 | C37: 21.99 | D37: =C37-SUM(F37:K37)-M37+L37 -> 10.561022 | E37: =D37/C37 -> 0.48026478 | F37: 4.21 | G37: =$I$2 -> 0.37443037 | H37: =$O$2 -> 3.64 | I37: =$P$2 -> 0.09 | J37: =C37*0.15 -> 3.2985 | K37: 0 | L37: =F37/(1+13%)*13% -> 0.48433628 | M37: =N37*0.5*F37 -> 0.3003835 | N37: 0.1427 | O37: 0.1 | P37: 0.05 | Q37: 0.02 | R37: 0.04 | S37: 0.01 | T37: =C37*U37 -> 5.7232224 | U37: =E37-SUM(O37:S37) -> 0.26026478 | Y37: =F37/C37 -> 0.19145066 | Z37: =G37/C37 -> 0.017027302 | AA37: =H37/C37 -> 0.16552979 | AB37: 0.15 | AC37: =1-SUM(Y37:AB37) -> 0.47599225
A38: 美国 | B38: AGL慢船散货 | C38: 22.99 | D38: =C38-SUM(F38:K38)-M38+L38 -> 11.411022 | E38: =D38/C38 -> 0.49634721 | F38: 4.21 | G38: =$I$2 -> 0.37443037 | H38: =$O$2 -> 3.64 | I38: =$P$2 -> 0.09 | J38: =C38*0.15 -> 3.4485 | K38: 0 | L38: =F38/(1+13%)*13% -> 0.48433628 | M38: =N38*0.5*F38 -> 0.3003835 | N38: 0.1427 | O38: 0.1 | P38: 0.05 | Q38: 0.02 | R38: 0.04 | S38: 0.01 | T38: =C38*U38 -> 6.3532224 | U38: =E38-SUM(O38:S38) -> 0.27634721 | Y38: =F38/C38 -> 0.1831231 | Z38: =G38/C38 -> 0.016286663 | AA38: =H38/C38 -> 0.15832971 | AB38: 0.15 | AC38: =1-SUM(Y38:AB38) -> 0.49226053
A39: 美国 | B39: AGL慢船散货 | C39: 15.99 | D39: =C39-SUM(F39:K39)-M39+L39 -> 5.4610224 | E39: =D39/C39 -> 0.34152736 | F39: 4.21 | G39: =$I$2 -> 0.37443037 | H39: =$O$2 -> 3.64 | I39: =$P$2 -> 0.09 | J39: =C39*0.15 -> 2.3985 | K39: 0 | L39: =F39/(1+13%)*13% -> 0.48433628 | M39: =N39*0.5*F39 -> 0.3003835 | N39: 0.1427 | O39: 0.1 | P39: 0.05 | Q39: 0.02 | R39: 0.04 | S39: 0.01 | T39: =C39*U39 -> 1.9432224 | U39: =E39-SUM(O39:S39) -> 0.12152736 | Y39: =F39/C39 -> 0.26328956 | Z39: =G39/C39 -> 0.023416534 | AA39: =H39/C39 -> 0.22764228 | AB39: 0.15 | AC39: =1-SUM(Y39:AB39) -> 0.33565163

Sheet 关键词布局
A1: _2022-01-10
A2: # | B2: 关键词 | C2: 流量占比 | D2: 关键词类型 | E2: 转化效果 | F2: 搜索量排名 | G2: 月搜索量 | H2: 竞品数 | I2: 竞争度 | J2: 广告竞品数 | K2: 自然排名 | L2: 自然排名详情 | M2: 自然排名时间 | N2: SP广告排名 | O2: SP广告排名详情 | P2: SP广告排名时间 | Q2: 曝光位置 | R2: 关键词更新时间
A3: 1 | B3: XXX | C3: 0.282808 | D3: [精准流量词, 主要流量词] | F3: 37050 | G3: 54361 | H3: 2991 | I3: 0.06 | J3: 80 | K3: 2 | L3: 第1页,2/48 | M3: 2022-01-10 | Q3: [自然搜索, 头部品牌广告] | R3: 2022-01-10 00:41:14
A4: 2 | B4: XXX | C4: 0.174157 | D4: [精准长尾词, 主要流量词] | E4: [转化优质词, 出单词] | F4: 72643 | G4: 22859 | H4: 470 | I4: 0.02 | J4: 97 | K4: 2 | L4: 第1页,2/48 | M4: 2022-01-10 | N4: 22 | O4: 第2页,10/12 | P4: 2022-01-10 | Q4: [自然搜索, 头部品牌广告, sp广告] | R4: 2022-01-10 01:30:57
A5: 3 | B5: XXX | C5: 0.100834 | D5: [主要流量词] | F5: 1513 | G5: 948854 | H5: 18033 | I5: 0.02 | J5: 239 | K5: 68 | L5: 第2页,20/48 | M5: 2022-01-09 | N5: 16 | O5: 第2页,4/12 | P5: 2022-01-07 | Q5: [自然搜索, sp广告] | R5: 2022-01-10 00:03:28
A6: 4 | B6: XXX | C6: 0.079123 | D6: [精准长尾词, 主要流量词] | F6: 154089 | G6: 7322 | H6: 1564 | I6: 0.21 | J6: 74 | K6: 2 | L6: 第1页,2/48 | M6: 2022-01-10 | N6: 25 | O6: 第3页,7/9 | P6: 2022-01-10 | Q6: [自然搜索, 头部品牌广告, ac专栏, sp广告] | R6: 2022-01-10 03:30:36
A7: 5 | B7: XXX | C7: 0.043205 | F7: 2627 | G7: 645144 | H7: 57758 | I7: 0.09 | J7: 170 | K7: 115 | L7: 第3页,19/48 | M7: 2022-01-10 | N7: 33 | O7: 第3页,9/12 | P7: 2022-01-04 | Q7: [自然搜索, sp广告] | R7: 2022-01-10 00:07:56
A8: 6 | B8: XXX | C8: 0.036997 | D8: [精准长尾词] | F8: 154522 | G8: 7288 | H8: 2233 | I8: 0.31 | J8: 97 | K8: 3 | L8: 第1页,3/48 | M8: 2022-01-10 | Q8: [自然搜索, 头部品牌广告] | R8: 2022-01-10 03:27:39
A9: 7 | B9: XXX | C9: 0.034796 | F9: 1476 | G9: 964665 | H9: 49804 | I9: 0.05 | J9: 228 | K9: 88 | L9: 第2页,40/48 | M9: 2022-01-10 | Q9: [自然搜索] | R9: 2022-01-10 00:02:07
A10: 8 | B10: XXX | C10: 0.018196 | F10: 42115 | G10: 46543 | H10: 8346 | I10: 0.18 | J10: 171 | N10: 12 | O10: 第1页,12/12 | P10: 2022-01-09 | Q10: [sp广告] | R10: 2022-01-10 00:48:10
A11: 9 | B11: XXX | C11: 0.015259 | F11: 416300 | G11: 1121 | H11: 2045 | I11: 1.82 | J11: 156 | K11: 46 | L11: 第1页,46/48 | M11: 2022-01-10 | Q11: [自然搜索, 头部品牌广告] | R11: 2022-01-10 06:24:01
A12: 10 | B12: XXX | C12: 0.014946 | F12: 1651 | G12: 894686 | H12: 120233 | I12: 0.13 | J12: 209 | K12: 56 | L12: 第2页,8/48 | M12: 2022-01-09 | Q12: [自然搜索] | R12: 2022-01-10 00:03:03
A13: 11 | B13: XXX | C13: 0.01451 | F13: 17633 | G13: 123821 | H13: 8371 | I13: 0.07 | J13: 93 | K13: 138 | L13: 第3页,42/48 | M13: 2022-01-09 | Q13: [自然搜索, 头部品牌广告] | R13: 2022-01-10 00:21:11
A14: 12 | B14: XXX | C14: 0.013059 | F14: 12530 | G14: 173953 | H14: 15826 | I14: 0.09 | J14: 266 | N14: 34 | O14: 第3页,10/12 | P14: 2022-01-07 | Q14: [sp广告] | R14: 2022-01-10 00:16:25
A15: 13 | B15: XXX | C15: 0.011374 | F15: 444011 | G15: 975 | H15: 1675 | I15: 1.72 | J15: 115 | K15: 16 | L15: 第1页,16/48 | M15: 2022-01-10 | Q15: [自然搜索, 头部品牌广告] | R15: 2022-01-10 06:37:29
A16: 14 | B16: XXX | C16: 0.00917 | D16: [精准长尾词] | F16: 334365 | G16: 1772 | H16: 510 | I16: 0.29 | J16: 104 | K16: 3 | L16: 第1页,3/48 | M16: 2022-01-10 | Q16: [自然搜索, 头部品牌广告] | R16: 2022-01-10 05:46:18
A17: 15 | B17: XXX | C17: 0.008178 | F17: 11803 | G17: 184199 | H17: 9331 | I17: 0.05 | J17: 180 | K17: 47 | L17: 第1页,47/48 | M17: 2022-01-10 | Q17: [自然搜索] | R17: 2022-01-10 00:16:06
A18: 16 | B18: XXX | C18: 0.007463 | F18: 2299 | G18: 710453 | H18: 49796 | I18: 0.07 | J18: 241 | K18: 61 | L18: 第2页,13/48 | M18: 2022-01-10 | Q18: [自然搜索] | R18: 2022-01-10 00:08:43
A19: 17 | B19: XXX | C19: 0.007167 | D19: [精准长尾词] | E19: [转化平稳词, 出单词] | F19: 332562 | G19: 1792 | H19: 2912 | I19: 1.63 | J19: 83 | K19: 1 | L19: 第1页,1/48 | M19: 2022-01-10 | N19: 19 | O19: 第2页,7/12 | P19: 2022-01-10 | Q19: [自然搜索, 头部品牌广告, ac专栏, sp广告] | R19: 2022-01-10 05:44:46
A20: 18 | B20: XXX | C20: 0.005399 | D20: [精准长尾词] | F20: 341119 | G20: 1702 | H20: 415 | I20: 0.24 | J20: 104 | K20: 5 | L20: 第1页,5/48 | M20: 2022-01-10 | Q20: [自然搜索, 头部品牌广告] | R20: 2022-01-10 05:50:46
A21: 19 | B21: XXX | C21: 0.00519 | F21: 5215 | G21: 379264 | H21: 18034 | I21: 0.05 | J21: 238 | N21: 25 | O21: 第3页,1/12 | P21: 2022-01-06 | Q21: [sp广告] | R21: 2022-01-10 00:10:19
A22: 20 | B22: XXX | C22: 0.005156 | F22: 44456 | G22: 43534 | H22: 17416 | I22: 0.4 | J22: 136 | N22: 25 | O22: 第3页,1/12 | P22: 2022-01-07 | Q22: [sp广告] | R22: 2022-01-10 00:49:37
A23: 21 | B23: XXX | C23: 0.004909 | D23: [精准长尾词] | F23: 550859 | G23: 598 | H23: 1523 | I23: 2.55 | J23: 88 | K23: 1 | L23: 第1页,1/48 | M23: 2022-01-10 | Q23: [自然搜索, 头部品牌广告, ac专栏] | R23: 2022-01-10 07:01:13
A24: 22 | B24: XXX | C24: 0.004834 | F24: 381508 | G24: 1350 | H24: 419 | I24: 0.31 | J24: 102 | K24: 20 | L24: 第1页,20/48 | M24: 2022-01-10 | N24: 11 | O24: 第1页,11/12 | P24: 2022-01-09 | Q24: [自然搜索, 头部品牌广告, sp广告] | R24: 2022-01-10 06:09:46
A25: 23 | B25: XXX | C25: 0.004639 | F25: 12138 | G25: 179343 | H25: 22574 | I25: 0.13 | J25: 139 | K25: 104 | L25: 第3页,8/48 | M25: 2022-01-10 | Q25: [自然搜索] | R25: 2022-01-10 00:15:52
A26: 24 | B26: XXX | C26: 0.004462 | F26: 7656 | G26: 273698 | H26: 127993 | I26: 0.47 | J26: 248 | K26: 86 | L26: 第2页,38/48 | M26: 2022-01-10 | Q26: [自然搜索] | R26: 2022-01-10 00:11:09
A27: 25 | B27: XXX | C27: 0.004424 | F27: 479983 | G27: 820 | H27: 2990 | I27: 3.65 | J27: 96 | K27: 21 | L27: 第1页,21/48 | M27: 2022-01-10 | Q27: [自然搜索, 头部品牌广告] | R27: 2022-01-10 06:50:39
A28: 26 | B28: XXX | C28: 0.004327 | D28: [精准长尾词] | F28: 630864 | G28: 433 | H28: 3261 | I28: 7.53 | J28: 86 | K28: 4 | L28: 第1页,4/48 | M28: 2022-01-10 | Q28: [自然搜索, 头部品牌广告] | R28: 2022-01-10 07:13:29
A29: 27 | B29: XXX | C29: 0.004069 | F29: 42349 | G29: 46228 | H29: 341 | I29: 0.01 | J29: 129 | Q29: [头部品牌广告] | R29: 2022-01-10 00:48:14
A30: 28 | B30: XXX | C30: 0.003952 | F30: 2295 | G30: 711338 | H30: 72064 | I30: 0.1 | J30: 243 | K30: 109 | L30: 第3页,13/48 | M30: 2022-01-07 | Q30: [自然搜索] | R30: 2022-01-10 00:05:10
A31: 29 | B31: XXX | C31: 0.003712 | D31: [精准长尾词] | F31: 446517 | G31: 963 | H31: 464 | I31: 0.48 | J31: 123 | K31: 7 | L31: 第1页,7/48 | M31: 2022-01-10 | Q31: [自然搜索, 头部品牌广告] | R31: 2022-01-10 06:38:56
A32: 30 | B32: XXX | C32: 0.003543 | F32: 30542 | G32: 68167 | H32: 6704 | I32: 0.1 | J32: 156 | K32: 40 | L32: 第1页,40/48 | M32: 2022-01-10 | Q32: [自然搜索] | R32: 2022-01-10 00:34:47
A33: 31 | B33: XXX | C33: 0.003255 | F33: 339070 | G33: 1723 | H33: 38 | I33: 0.02 | J33: 82 | K33: 28 | L33: 第1页,28/38 | M33: 2022-01-10 | Q33: [自然搜索, 头部品牌广告] | R33: 2022-01-10 05:47:44
A34: 32 | B34: XXX | C34: 0.002998 | F34: 13694 | G34: 159577 | H34: 5498 | I34: 0.03 | J34: 167 | K34: 70 | L34: 第2页,22/48 | M34: 2022-01-10 | Q34: [自然搜索] | R34: 2022-01-10 00:18:02
A35: 33 | B35: XXX | C35: 0.00297 | F35: 42307 | G35: 46284 | H35: 138295 | I35: 2.99 | J35: 216 | K35: 73 | L35: 第2页,25/48 | M35: 2022-01-10 | Q35: [自然搜索] | R35: 2022-01-10 00:47:10
A36: 34 | B36: XXX | C36: 0.0029 | D36: [精准长尾词] | F36: 661602 | G36: 385 | H36: 2486 | I36: 6.46 | J36: 97 | K36: 6 | L36: 第1页,6/48 | M36: 2022-01-10 | Q36: [自然搜索, 头部品牌广告] | R36: 2022-01-10 07:19:03
A37: 35 | B37: XXX | C37: 0.002701 | D37: [精准长尾词] | E37: [转化优质词, 出单词] | F37: 530680 | G37: 652 | H37: 2903 | I37: 4.45 | J37: 111 | K37: 1 | L37: 第1页,1/48 | M37: 2022-01-10 | N37: 22 | O37: 第2页,11/11 | P37: 2022-01-10 | Q37: [自然搜索, 头部品牌广告, ac专栏, sp广告] | R37: 2022-01-10 06:57:07
A38: 36 | B38: XXX | C38: 0.002611 | F38: 307612 | G38: 2094 | H38: 291 | I38: 0.14 | J38: 105 | K38: 30 | L38: 第1页,30/48 | M38: 2022-01-10 | N38: 14 | O38: 第2页,2/12 | P38: 2022-01-08 | Q38: [自然搜索, 头部品牌广告, sp广告] | R38: 2022-01-10 05:32:10
A39: 37 | B39: XXX | C39: 0.002599 | F39: 29776 | G39: 70179 | H39: 14591 | I39: 0.21 | J39: 175 | K39: 88 | L39: 第2页,40/48 | M39: 2022-01-10 | Q39: [自然搜索] | R39: 2022-01-10 00:34:30
A40: 38 | B40: XXX | C40: 0.002217 | F40: 7595 | G40: 275628 | H40: 60756 | I40: 0.22 | J40: 219 | K40: 77 | L40: 第2页,29/48 | M40: 2021-12-28 | Q40: [自然搜索] | R40: 2022-01-10 00:11:12
...

Sheet listing切入点
A1: 标题 | B1: 前期关键词主要埋有一定流量（搜索排名在5-10W）的精准核心词，以做Listing转化为核心。到中期逐渐添加进入中长尾词、转化好的礼物词、玩具词。后期在前面的基础上，打开全部流量入口。
A2: 五点 | B2: 与附图相对应。满足人文需求、和算法需求。
A3: 图片 | B3: 见文案讨论设计
A4: Xx+ | B4: 1. BrXxnXx stXxry（强化品牌意识） 2. 功能展现 3. 欢快的场景、孩子伴随音乐起舞 4. 防滑。PEVXx加强防滑性能 5. 全新面板设计、升级IC原件 6. Gifts FXxr KiXxs 7. greXxt fXxr pXxrty 8. SpecificXxtiXxn
A5: price | B5: 前期以低价$16.99快速切入市场--- 目前tXxp100最低价为16.99。随着运营周期产品权重提高、listing逐渐完善价格稳步上涨。 设置折扣价：8%
A6: viXxeXx | B6: 一个带lXxgXx的商品功能展示视频；一个开箱视频
A7: review/QXx | B7: review的内容是比较重要的切入点，所以首页的review最好有几个review涵盖以下几点：商家对客户的服务，产品核心卖点重现，竞对的客诉问题我们如何规避

Sheet 文案套图设计
A1: 亚马逊推广计划
A2: 1. 产品优劣势
A3: 我们产品的优势 | B3: 我们产品的劣势
A4: 1、特有卡拉OK灯光球 | B4: 1、包装
A5: 2、工厂特有IC设计 | B5: 2、防滑难以避免
A6: 3、面板原创设计 | B6: 3、产品功能性或许无法满足消费者期待
A7: 4、增强防滑底料
A8: 5、改PP导电膜为PET
A9: 6、加厚内部泡棉，增加踩踏体验感
A16: 需求特性分类 | B16: 属性 | C16: 属性类型 | D16: 我们产品的属性优势 | E16: 视觉呈现方案 | F16: 文案呈现方案
A17: 欢快的场景图(第四张图) | B17: 孩子娱乐 | C17: 基本型 | D17: 独创面板设计，karaoke灯效，整体功能属性的提升 | E17: 孩子在家庭的陪伴下，欢快地随英语起舞 | F17: enjoy music；强化整体的欢快氛围
A19: 安全性(第三张图) | B19: 防滑 | C19: 期望型 | D19: 增强防滑底料 | E19: 舒适性整合为一张图, 场景图+图标解释 | F19: Safe, 不用担心滑倒问题
A21: 内部结构的升级改造(第二张图) | B21: PET导电膜 | C21: 兴奋型 | D21: 整体功能性的全面提升。 | E21: 通过拆解图+局部功能放大 | F21: fully upgraded
B22: 特有IC设计 | C22: 兴奋型
B23: 加厚内部泡棉 | C23: 兴奋型
A24: 展现产品全类目唯一的karaoke灯效+独特面板设计 | B24: 训练效果 | C24: 兴奋型 | D24: karaoke等效设计、符合欧美儿童审美的面板设计。 | E24: 场景图+局部功能放大图
A27: 独特性 | B27: 暂无
