Workbook

Sheet 销售日报表
A1: 销售日报表
A2: 日期 | B2: 单价 | C2: 自然订单 | D2: 广告订单 | E2: 日总订单 | F2: 测评订单 | G2: 实际订单 | H2: 刷单金额 | I2: 总销售额 | J2: 实际销售额 | K2: 销售总量 | L2: 实际销售量
A3: 44136 | C3: =E3-D3 -> 0 | D3: =单SKU总广告监控表!G12 -> 0 | E3: =业务报告!L3 -> 0 | G3: =E3-F3 -> 0 | H3: =F3*B3 -> 0 | I3: =业务报告!K3 -> 0 | J3: =I3-F3*B3 -> 0 | K3: =业务报告!I3 -> 0 | L3: =K3-F3 -> 0
A4: 44137 | C4: =E4-D4 -> 0 | D4: =单SKU总广告监控表!G13 -> 0 | E4: =业务报告!L4 -> 0 | G4: =E4-F4 -> 0 | H4: =F4*B4 -> 0 | I4: =业务报告!K4 -> 0 | J4: =I4-F4*B4 -> 0 | K4: =业务报告!I4 -> 0 | L4: =K4-F4 -> 0
A5: 44138 | C5: =E5-D5 -> 0 | D5: =单SKU总广告监控表!G14 -> 0 | E5: =业务报告!L5 -> 0 | G5: =E5-F5 -> 0 | H5: =F5*B5 -> 0 | I5: =业务报告!K5 -> 0 | J5: =I5-F5*B5 -> 0 | K5: =业务报告!I5 -> 0 | L5: =K5-F5 -> 0
A6: 44139 | C6: =E6-D6 -> 0 | D6: =单SKU总广告监控表!G15 -> 0 | E6: =业务报告!L6 -> 0 | G6: =E6-F6 -> 0 | H6: =F6*B6 -> 0 | I6: =业务报告!K6 -> 0 | J6: =I6-F6*B6 -> 0 | K6: =业务报告!I6 -> 0 | L6: =K6-F6 -> 0
A7: 44140 | C7: =E7-D7 -> 0 | D7: =单SKU总广告监控表!G16 -> 0 | E7: =业务报告!L7 -> 0 | G7: =E7-F7 -> 0 | H7: =F7*B7 -> 0 | I7: =业务报告!K7 -> 0 | J7: =I7-F7*B7 -> 0 | K7: =业务报告!I7 -> 0 | L7: =K7-F7 -> 0
A8: 44141 | C8: =E8-D8 -> 0 | D8: =单SKU总广告监控表!G17 -> 0 | E8: =业务报告!L8 -> 0 | G8: =E8-F8 -> 0 | H8: =F8*B8 -> 0 | I8: =业务报告!K8 -> 0 | J8: =I8-F8*B8 -> 0 | K8: =业务报告!I8 -> 0 | L8: =K8-F8 -> 0
A9: 44142 | C9: =E9-D9 -> 0 | D9: =单SKU总广告监控表!G18 -> 0 | E9: =业务报告!L9 -> 0 | G9: =E9-F9 -> 0 | H9: =F9*B9 -> 0 | I9: =业务报告!K9 -> 0 | J9: =I9-F9*B9 -> 0 | K9: =业务报告!I9 -> 0 | L9: =K9-F9 -> 0
A10: 44143 | C10: =E10-D10 -> 0 | D10: =单SKU总广告监控表!G19 -> 0 | E10: =业务报告!L10 -> 0 | G10: =E10-F10 -> 0 | H10: =F10*B10 -> 0 | I10: =业务报告!K10 -> 0 | J10: =I10-F10*B10 -> 0 | K10: =业务报告!I10 -> 0 | L10: =K10-F10 -> 0
A11: 44144 | C11: =E11-D11 -> 0 | D11: =单SKU总广告监控表!G20 -> 0 | E11: =业务报告!L11 -> 0 | G11: =E11-F11 -> 0 | H11: =F11*B11 -> 0 | I11: =业务报告!K11 -> 0 | J11: =I11-F11*B11 -> 0 | K11: =业务报告!I11 -> 0 | L11: =K11-F11 -> 0
A12: 44145 | C12: =E12-D12 -> 0 | D12: =单SKU总广告监控表!G21 -> 0 | E12: =业务报告!L12 -> 0 | G12: =E12-F12 -> 0 | H12: =F12*B12 -> 0 | I12: =业务报告!K12 -> 0 | J12: =I12-F12*B12 -> 0 | K12: =业务报告!I12 -> 0 | L12: =K12-F12 -> 0
A13: 44146 | C13: =E13-D13 -> 0 | D13: =单SKU总广告监控表!G22 -> 0 | E13: =业务报告!L13 -> 0 | G13: =E13-F13 -> 0 | H13: =F13*B13 -> 0 | I13: =业务报告!K13 -> 0 | J13: =I13-F13*B13 -> 0 | K13: =业务报告!I13 -> 0 | L13: =K13-F13 -> 0
A14: 44147 | C14: =E14-D14 -> 0 | D14: =单SKU总广告监控表!G23 -> 0 | E14: =业务报告!L14 -> 0 | G14: =E14-F14 -> 0 | H14: =F14*B14 -> 0 | I14: =业务报告!K14 -> 0 | J14: =I14-F14*B14 -> 0 | K14: =业务报告!I14 -> 0 | L14: =K14-F14 -> 0
... A32: 44165 | C32: =E32-D32 -> 0 | D32: =单SKU总广告监控表!G41 -> 0 | E32: =业务报告!L32 -> 0 | G32: =E32-F32 -> 0 | H32: =F32*B32 -> 0 | I32: =业务报告!K32 -> 0 | J32: =I32-F32*B32 -> 0 | K32: =业务报告!I32 -> 0 | L32: =K32-F32 -> 0
A33: 合计 | C33: =SUM(C3:C32) -> 0 | D33: =SUM(D3:D32) -> 0 | E33: =SUM(E3:E32) -> 0 | F33: =SUM(F3:F32) -> 0 | G33: =SUM(G3:G32) -> 0 | H33: =SUM(H3:H32) -> 0 | I33: =SUM(I3:I32) -> 0 | J33: =SUM(J3:J32) -> 0 | ... L33: =SUM(L3:L32) -> 0
A34: 日平均 | C34: =AVERAGE(C3:C32) -> 0 | D34: =AVERAGE(D3:D32) -> 0 | E34: =AVERAGE(E3:E32) -> 0 | G34: =AVERAGE(G3:G32) -> 0 | H34: =AVERAGE(H3:H32) -> 0 | I34: =AVERAGE(I3:I32) -> 0 | J34: =AVERAGE(J3:J32) -> 0 | K34: =AVERAGE(K3:K32) -> 0 | L34: =AVERAGE(L3:L32) -> 0

Sheet 业务报告
A1: 日期 | B1: ASIN | C1: 总买家访问次数 | D1: 买家访问 次数 | E1: 买家访问次数 百分比 | F1: 页面浏览 次数 | G1: 页面浏览次数 百分比 | H1: 购买按钮赢得率 | I1: 已订购商品数量 | J1: 订单商品数量转化率 | K1: 已订购商品销售额 | L1: 订单商品种类数 | M1: 总转化率 | N1: 自然订单 | O1: 自然转化率
A2: Date | B2: ASIN | D2: Sessions | E2: Session Percentage | F2: Page Views | G2: Page Views Percentage | H2: Buy Box Percentage | I2: Units Ordered | J2: Unit Session Percentage | K2: Ordered Product Sales | L2: Total Order Items
A3: 44136 | C3: =D3+单SKU总广告监控表!C12 -> 0 | M3: =L3/C3 -> #DIV/0! | N3: =销售日报表!C3 -> 0 | O3: =N3/D3 -> #DIV/0!
A4: 44137 | C4: =D4+单SKU总广告监控表!C13 -> 0 | M4: =L4/C4 -> #DIV/0! | N4: =销售日报表!C4 -> 0 | O4: =N4/D4 -> #DIV/0!
A5: 44138 | C5: =D5+单SKU总广告监控表!C14 -> 0 | M5: =L5/C5 -> #DIV/0! | N5: =销售日报表!C5 -> 0 | O5: =N5/D5 -> #DIV/0!
A6: 44139 | C6: =D6+单SKU总广告监控表!C15 -> 0 | M6: =L6/C6 -> #DIV/0! | N6: =销售日报表!C6 -> 0 | O6: =N6/D6 -> #DIV/0!
A7: 44140 | C7: =D7+单SKU总广告监控表!C16 -> 0 | M7: =L7/C7 -> #DIV/0! | N7: =销售日报表!C7 -> 0 | O7: =N7/D7 -> #DIV/0!
A8: 44141 | C8: =D8+单SKU总广告监控表!C17 -> 0 | M8: =L8/C8 -> #DIV/0! | N8: =销售日报表!C8 -> 0 | O8: =N8/D8 -> #DIV/0!
A9: 44142 | C9: =D9+单SKU总广告监控表!C18 -> 0 | M9: =L9/C9 -> #DIV/0! | N9: =销售日报表!C9 -> 0 | O9: =N9/D9 -> #DIV/0!
A10: 44143 | C10: =D10+单SKU总广告监控表!C19 -> 0 | M10: =L10/C10 -> #DIV/0! | N10: =销售日报表!C10 -> 0 | O10: =N10/D10 -> #DIV/0!
A11: 44144 | C11: =D11+单SKU总广告监控表!C20 -> 0 | M11: =L11/C11 -> #DIV/0! | N11: =销售日报表!C11 -> 0 | O11: =N11/D11 -> #DIV/0!
A12: 44145 | C12: =D12+单SKU总广告监控表!C21 -> 0 | M12: =L12/C12 -> #DIV/0! | N12: =销售日报表!C12 -> 0 | O12: =N12/D12 -> #DIV/0!
A13: 44146 | C13: =D13+单SKU总广告监控表!C22 -> 0 | M13: =L13/C13 -> #DIV/0! | N13: =销售日报表!C13 -> 0 | O13: =N13/D13 -> #DIV/0!
A14: 44147 | C14: =D14+单SKU总广告监控表!C23 -> 0 | M14: =L14/C14 -> #DIV/0! | N14: =销售日报表!C14 -> 0 | O14: =N14/D14 -> #DIV/0!
... A32: 44165 | C32: =D32+单SKU总广告监控表!C41 -> 0 | M32: =L32/C32 -> #DIV/0! | N32: =销售日报表!C32 -> 0 | O32: =N32/D32 -> #DIV/0!

Sheet 单SKU总广告监控表
A11: 日期 | B11: 曝光量 | C11: 点击 | D11: 点击率 | E11: 花费 | F11: 单次点击费用 | G11: Ad订单 | H11: 贡献销售 | I11: ACoS | J11: ROAS | K11: 广告转化率 | L11: AD销量 | M11: 客单价 | N11: 今日动作 | O11: 今日工作总结 | P11: 周总结
A12: 44136 | D12: =C12/B12 -> #DIV/0! | F12: =E12/C12 -> #DIV/0! | I12: =E12/H12 -> #DIV/0! | J12: =H12/E12 -> #DIV/0! | K12: =G12/C12 -> #DIV/0! | L12: =H12/M12 -> #DIV/0! | M12: =销售日报表!B3 -> 0
A13: 44137 | D13: =C13/B13 -> #DIV/0! | F13: =E13/C13 -> #DIV/0! | I13: =E13/H13 -> #DIV/0! | J13: =H13/E13 -> #DIV/0! | K13: =G13/C13 -> #DIV/0! | L13: =H13/M13 -> #DIV/0! | M13: =销售日报表!B4 -> 0
A14: 44138 | D14: =C14/B14 -> #DIV/0! | F14: =E14/C14 -> #DIV/0! | I14: =E14/H14 -> #DIV/0! | J14: =H14/E14 -> #DIV/0! | K14: =G14/C14 -> #DIV/0! | L14: =H14/M14 -> #DIV/0! | M14: =销售日报表!B5 -> 0
A15: 44139 | D15: =C15/B15 -> #DIV/0! | F15: =E15/C15 -> #DIV/0! | I15: =E15/H15 -> #DIV/0! | J15: =H15/E15 -> #DIV/0! | K15: =G15/C15 -> #DIV/0! | L15: =H15/M15 -> #DIV/0! | M15: =销售日报表!B6 -> 0
A16: 44140 | D16: =C16/B16 -> #DIV/0! | F16: =E16/C16 -> #DIV/0! | I16: =E16/H16 -> #DIV/0! | J16: =H16/E16 -> #DIV/0! | K16: =G16/C16 -> #DIV/0! | L16: =H16/M16 -> #DIV/0! | M16: =销售日报表!B7 -> 0
A17: 44141 | D17: =C17/B17 -> #DIV/0! | F17: =E17/C17 -> #DIV/0! | I17: =E17/H17 -> #DIV/0! | J17: =H17/E17 -> #DIV/0! | K17: =G17/C17 -> #DIV/0! | L17: =H17/M17 -> #DIV/0! | M17: =销售日报表!B8 -> 0
A18: 44142 | D18: =C18/B18 -> #DIV/0! | F18: =E18/C18 -> #DIV/0! | I18: =E18/H18 -> #DIV/0! | J18: =H18/E18 -> #DIV/0! | K18: =G18/C18 -> #DIV/0! | L18: =H18/M18 -> #DIV/0! | M18: =销售日报表!B9 -> 0
A19: 44143 | D19: =C19/B19 -> #DIV/0! | F19: =E19/C19 -> #DIV/0! | I19: =E19/H19 -> #DIV/0! | J19: =H19/E19 -> #DIV/0! | K19: =G19/C19 -> #DIV/0! | L19: =H19/M19 -> #DIV/0! | M19: =销售日报表!B10 -> 0
A20: 44144 | D20: =C20/B20 -> #DIV/0! | F20: =E20/C20 -> #DIV/0! | I20: =E20/H20 -> #DIV/0! | J20: =H20/E20 -> #DIV/0! | K20: =G20/C20 -> #DIV/0! | L20: =H20/M20 -> #DIV/0! | M20: =销售日报表!B11 -> 0
A21: 44145 | D21: =C21/B21 -> #DIV/0! | F21: =E21/C21 -> #DIV/0! | I21: =E21/H21 -> #DIV/0! | J21: =H21/E21 -> #DIV/0! | K21: =G21/C21 -> #DIV/0! | L21: =H21/M21 -> #DIV/0! | M21: =销售日报表!B12 -> 0
A22: 44146 | D22: =C22/B22 -> #DIV/0! | F22: =E22/C22 -> #DIV/0! | I22: =E22/H22 -> #DIV/0! | J22: =H22/E22 -> #DIV/0! | K22: =G22/C22 -> #DIV/0! | L22: =H22/M22 -> #DIV/0! | M22: =销售日报表!B13 -> 0
A23: 44147 | D23: =C23/B23 -> #DIV/0! | F23: =E23/C23 -> #DIV/0! | I23: =E23/H23 -> #DIV/0! | J23: =H23/E23 -> #DIV/0! | K23: =G23/C23 -> #DIV/0! | L23: =H23/M23 -> #DIV/0! | M23: =销售日报表!B14 -> 0
... A41: 44165 | D41: =C41/B41 -> #DIV/0! | F41: =E41/C41 -> #DIV/0! | I41: =E41/H41 -> #DIV/0! | J41: =H41/E41 -> #DIV/0! | K41: =G41/C41 -> #DIV/0! | L41: =H41/M41 -> #DIV/0! | M41: =销售日报表!B32 -> 0
A42: 总和 | E42: =SUM(E12:E41) -> 0 | F42: =SUM(F12:F41) -> #DIV/0! | G42: =SUM(G12:G41) -> 0 | H42: =SUM(H12:H41) -> 0 | L42: =SUM(L12:L41) -> #DIV/0!
A43: 日平均 | D43: =AVERAGE(D12:D41) -> #DIV/0! | E43: =AVERAGE(E12:E41) -> #DIV/0! | F43: =AVERAGE(F12:F41) -> #DIV/0! | G43: =AVERAGE(G12:G41) -> #DIV/0! | H43: =AVERAGE(H12:H41) -> #DIV/0! | I43: =AVERAGE(I12:I41) -> #DIV/0! | J43: =AVERAGE(J12:J41) -> #DIV/0! | K43: =AVERAGE(K12:K40) -> #DIV/0! | L43: =AVERAGE(L12:L41) -> #DIV/0!

Sheet 利润明细
B1: 汇率 | C1: 售价 | D1: 产品成本 | E1: 头程 | F1: FBA派送 | G1: 佣金 | H1: 利润 | I1: 毛利率 | J1: 投入 | K1: 测评手续费
B2: 6.62 | C2: 17.99 | D2: 5.57 | E2: 2.4 | F2: 6.94 | G2: =C2*0.15 -> 2.6985 | H2: =C2-D2-E2-F2-G2 -> 0.3815 | I2: =H2/C2 -> 0.021206226 | J2: =SUM(D2:D2:G2) -> 17.6085 | K2: =50/B$2 -> 7.5528701
C5: 日期 | D5: 单价 | E5: 实际商品数量 | F5: 实际销售额 | G5: 佣金 | H5: 投入 | I5: 产品净利润 | J5: 广告费 | K5: 广告占比 | L5: ROI | M5: 测评数量 | N5: 测评成本
C6: 44136 | D6: =销售日报表!B3 -> 0 | E6: =销售日报表!L3 -> 0 | F6: =销售日报表!J3 -> 0 | G6: =D6*0.15 -> 0 | H6: =($D$2+$E$2+$F$2+G6) -> 14.91 | I6: =F6-H6*E6-J6-N6 -> 0 | J6: =单SKU总广告监控表!E12 -> 0 | K6: =J6/F6 -> #DIV/0! | L6: =F6/(D$2+E$2+N6+J6) -> 0 | M6: =销售日报表!F3 -> 0 | N6: =(H6+K$2)*M6 -> 0
C7: 44137 | D7: =销售日报表!B4 -> 0 | E7: =销售日报表!L4 -> 0 | F7: =销售日报表!J4 -> 0 | G7: =D7*0.15 -> 0 | H7: =($D$2+$E$2+$F$2+G7) -> 14.91 | I7: =F7-H7*E7-J7-N7 -> 0 | J7: =单SKU总广告监控表!E13 -> 0 | K7: =J7/F7 -> #DIV/0! | L7: =F7/(D$2+E$2+N7+J7) -> 0 | M7: =销售日报表!F4 -> 0 | N7: =(H7+K$2)*M7 -> 0
C8: 44138 | D8: =销售日报表!B5 -> 0 | E8: =销售日报表!L5 -> 0 | F8: =销售日报表!J5 -> 0 | G8: =D8*0.15 -> 0 | H8: =($D$2+$E$2+$F$2+G8) -> 14.91 | I8: =F8-H8*E8-J8-N8 -> 0 | J8: =单SKU总广告监控表!E14 -> 0 | K8: =J8/F8 -> #DIV/0! | L8: =F8/(D$2+E$2+N8+J8) -> 0 | M8: =销售日报表!F5 -> 0 | N8: =(H8+K$2)*M8 -> 0
C9: 44139 | D9: =销售日报表!B6 -> 0 | E9: =销售日报表!L6 -> 0 | F9: =销售日报表!J6 -> 0 | G9: =D9*0.15 -> 0 | H9: =($D$2+$E$2+$F$2+G9) -> 14.91 | I9: =F9-H9*E9-J9-N9 -> 0 | J9: =单SKU总广告监控表!E15 -> 0 | K9: =J9/F9 -> #DIV/0! | L9: =F9/(D$2+E$2+N9+J9) -> 0 | M9: =销售日报表!F6 -> 0 | N9: =(H9+K$2)*M9 -> 0
C10: 44140 | D10: =销售日报表!B7 -> 0 | E10: =销售日报表!L7 -> 0 | F10: =销售日报表!J7 -> 0 | G10: =D10*0.15 -> 0 | H10: =($D$2+$E$2+$F$2+G10) -> 14.91 | I10: =F10-H10*E10-J10-N10 -> 0 | J10: =单SKU总广告监控表!E16 -> 0 | K10: =J10/F10 -> #DIV/0! | L10: =F10/(D$2+E$2+N10+J10) -> 0 | M10: =销售日报表!F7 -> 0 | N10: =(H10+K$2)*M10 -> 0
C11: 44141 | D11: =销售日报表!B8 -> 0 | E11: =销售日报表!L8 -> 0 | F11: =销售日报表!J8 -> 0 | G11: =D11*0.15 -> 0 | H11: =($D$2+$E$2+$F$2+G11) -> 14.91 | I11: =F11-H11*E11-J11-N11 -> 0 | J11: =单SKU总广告监控表!E17 -> 0 | K11: =J11/F11 -> #DIV/0! | L11: =F11/(D$2+E$2+N11+J11) -> 0 | M11: =销售日报表!F8 -> 0 | N11: =(H11+K$2)*M11 -> 0
C12: 44142 | D12: =销售日报表!B9 -> 0 | E12: =销售日报表!L9 -> 0 | F12: =销售日报表!J9 -> 0 | G12: =D12*0.15 -> 0 | H12: =($D$2+$E$2+$F$2+G12) -> 14.91 | I12: =F12-H12*E12-J12-N12 -> 0 | J12: =单SKU总广告监控表!E18 -> 0 | K12: =J12/F12 -> #DIV/0! | L12: =F12/(D$2+E$2+N12+J12) -> 0 | M12: =销售日报表!F9 -> 0 | N12: =(H12+K$2)*M12 -> 0
C13: 44143 | D13: =销售日报表!B10 -> 0 | E13: =销售日报表!L10 -> 0 | F13: =销售日报表!J10 -> 0 | G13: =D13*0.15 -> 0 | H13: =($D$2+$E$2+$F$2+G13) -> 14.91 | I13: =F13-H13*E13-J13-N13 -> 0 | J13: =单SKU总广告监控表!E19 -> 0 | K13: =J13/F13 -> #DIV/0! | L13: =F13/(D$2+E$2+N13+J13) -> 0 | M13: =销售日报表!F10 -> 0 | N13: =(H13+K$2)*M13 -> 0
C14: 44144 | D14: =销售日报表!B11 -> 0 | E14: =销售日报表!L11 -> 0 | F14: =销售日报表!J11 -> 0 | G14: =D14*0.15 -> 0 | H14: =($D$2+$E$2+$F$2+G14) -> 14.91 | I14: =F14-H14*E14-J14-N14 -> 0 | J14: =单SKU总广告监控表!E20 -> 0 | K14: =J14/F14 -> #DIV/0! | L14: =F14/(D$2+E$2+N14+J14) -> 0 | M14: =销售日报表!F11 -> 0 | N14: =(H14+K$2)*M14 -> 0
C15: 44145 | D15: =销售日报表!B12 -> 0 | E15: =销售日报表!L12 -> 0 | F15: =销售日报表!J12 -> 0 | G15: =D15*0.15 -> 0 | H15: =($D$2+$E$2+$F$2+G15) -> 14.91 | I15: =F15-H15*E15-J15-N15 -> 0 | J15: =单SKU总广告监控表!E21 -> 0 | K15: =J15/F15 -> #DIV/0! | L15: =F15/(D$2+E$2+N15+J15) -> 0 | M15: =销售日报表!F12 -> 0 | N15: =(H15+K$2)*M15 -> 0
C16: 44146 | D16: =销售日报表!B13 -> 0 | E16: =销售日报表!L13 -> 0 | F16: =销售日报表!J13 -> 0 | G16: =D16*0.15 -> 0 | H16: =($D$2+$E$2+$F$2+G16) -> 14.91 | I16: =F16-H16*E16-J16-N16 -> 0 | J16: =单SKU总广告监控表!E22 -> 0 | K16: =J16/F16 -> #DIV/0! | L16: =F16/(D$2+E$2+N16+J16) -> 0 | M16: =销售日报表!F13 -> 0 | N16: =(H16+K$2)*M16 -> 0
C17: 44147 | D17: =销售日报表!B14 -> 0 | E17: =销售日报表!L14 -> 0 | F17: =销售日报表!J14 -> 0 | G17: =D17*0.15 -> 0 | H17: =($D$2+$E$2+$F$2+G17) -> 14.91 | I17: =F17-H17*E17-J17-N17 -> 0 | J17: =单SKU总广告监控表!E23 -> 0 | K17: =J17/F17 -> #DIV/0! | L17: =F17/(D$2+E$2+N17+J17) -> 0 | M17: =销售日报表!F14 -> 0 | N17: =(H17+K$2)*M17 -> 0
... C35: 44165 | D35: =销售日报表!B32 -> 0 | E35: =销售日报表!L32 -> 0 | F35: =销售日报表!J32 -> 0 | G35: =D35*0.15 -> 0 | H35: =($D$2+$E$2+$F$2+G35) -> 14.91 | I35: =F35-H35*E35-J35-N35 -> 0 | J35: =单SKU总广告监控表!E41 -> 0 | K35: =J35/F35 -> #DIV/0! | L35: =F35/(D$2+E$2+N35+J35) -> 0 | M35: =销售日报表!F32 -> 0 | N35: =(H35+K$2)*M35 -> 0
C36: 合计 | E36: =SUM(E6:E35) -> 0 | F36: =SUM(F6:F35) -> 0 | H36: =SUM(H6:H35) -> 447.3 | I36: =SUM(I6:I35) -> 0 | J36: =SUM(J6:J35) -> 0 | M36: =SUM(M6:M35) -> 0 | N36: =SUM(N6:N35) -> 0

Sheet 排名追踪
A1: 排名追踪表
A2: 日期 | B2: Sport & Outdoor | C2: Sleeping Bags | D2: Review | E2: 星级 | F2: 订单量 | G2: 今日动作
G3: Listing | H3: 站外 | I3: 广告
A4: 44136 | F4: =销售日报表!E3 -> 0 | H4: =销售日报表!F3 -> 0
A5: 44137 | F5: =销售日报表!E4 -> 0 | H5: =销售日报表!F4 -> 0
A6: 44138 | F6: =销售日报表!E5 -> 0 | H6: =销售日报表!F5 -> 0
A7: 44139 | F7: =销售日报表!E6 -> 0 | H7: =销售日报表!F6 -> 0
A8: 44140 | F8: =销售日报表!E7 -> 0 | H8: =销售日报表!F7 -> 0
A9: 44141 | F9: =销售日报表!E8 -> 0 | H9: =销售日报表!F8 -> 0
A10: 44142 | F10: =销售日报表!E9 -> 0 | H10: =销售日报表!F9 -> 0
A11: 44143 | F11: =销售日报表!E10 -> 0 | H11: =销售日报表!F10 -> 0
A12: 44144 | F12: =销售日报表!E11 -> 0 | H12: =销售日报表!F11 -> 0
A13: 44145 | F13: =销售日报表!E12 -> 0 | H13: =销售日报表!F12 -> 0
A14: 44146 | F14: =销售日报表!E13 -> 0 | H14: =销售日报表!F13 -> 0
A15: 44147 | F15: =销售日报表!E14 -> 0 | H15: =销售日报表!F14 -> 0
... A33: 44165 | F33: =销售日报表!E32 -> 0 | H33: =销售日报表!F32 -> 0

Sheet 关键词排名
A1: 排名监控表
A2: 日期 | B2: 广告词排名 | G2: 自然排名
A4: 44105
A5: 44106
A6: 44107
A7: 44108
A8: 44109
A9: 44110
A10: 44111
A11: 44112
A12: 44113
A13: 44114
A14: 44115
A15: 44116
... A34: 44135

Sheet 竞品追踪
A1: 竞品追踪
A2: 日期
B3: 价格 | C3: rating | D3: 星级 | E3: 大类排名 | F3: 小类排名 | G3: 价格 | H3: rating | I3: 星级 | J3: 大类排名 | K3: 小类排名 | L3: 价格 | M3: rating | N3: 星级 | O3: 大类排名 | P3: 小类排名
A4: 44105
A5: 44106
A6: 44107
A7: 44108
A8: 44109
A9: 44110
A10: 44111
A11: 44112
A12: 44113
A13: 44114
A14: 44115
A15: 44116
... A64: 44165

Sheet 测评订单记录
A1: 类型 | B1: 时间 | C1: 订单号 | D1: 买家姓名 | E1: 状态 | F1: 价格 | G1: 购买时间 | H1: review情况 | I1: Amazon ID | J1: 留评时间
A2: 测评
A3: 放量
A4: 放量
A5: 放量
A6: 放量
A7: rating
A8: rating
A9: rating
A10: rating
A11: rating
A12: rating
A13: rating
A14: rating

Sheet 客户跟踪
B2: Name
B3: Email
B4: Order_ID
B5: Date
B6: Message
B7: Action

Sheet 库存监控
A2: 数量 | B2: 表格开始日期 | E2: 总计 | F2: 日期 | H2: 44095 | I2: 44096 | J2: 44097 | K2: 44098 | L2: 44099 | M2: 44100 | N2: 44101 | O2: 44102 | P2: 44103 | Q2: 44104
B3: 43158 | E3: 2020年9月 | F3: 单价 | J3: 16.99 | K3: 16.99
E4: 汇总 | F4: 价格变化 | J4: 无 | K4: 无
E5: =SUM(H5:Q5) -> 8 | F5: 自然订单 | K5: 8
F6: 刷单订单 | K6: 5
E7: =SUM(H7:Q7) -> 0 | F7: 测评订单
F8: 折扣订单
F9: 广告订单 | K9: 11
E10: =SUM(H10:Q10) -> 19 | F10: 日总订单 | H10: =H5+H7 -> 0 | I10: =I5+I7 -> 0 | J10: =J5+J7 -> 0 | K10: 19 | L10: =L5+L7 -> 0 | M10: =M5+M7 -> 0 | N10: =N5+N7 -> 0 | O10: =O5+O7 -> 0 | P10: =P5+P7 -> 0 | Q10: =Q5+Q7 -> 0
E11: =SUM(H11:Q11) -> 0 | F11: 退货订单
B12: 产品名称 | E12: LISTING情况 | F12: Review | J12: 12 | K12: 12
F13: 一星比例 | J13: 0 | K13: 0
F14: QA | J14: 0 | K14: 0
B15: ASIN | E15: 店铺情况 | F15: Feedback反馈 | K15: 2
F16: Feedback反馈差评率 | K16: 0
F17: 账户状况 | K17: 0
E18: 流量情况 | F18: 访问量
F19: 转化率
E20: =SUM(H20:Q20) -> 27.18 | F20: 广告 | G20: 花费 | K20: 27.18
G21: 日预算 | K21: 65
A22: 标签： | E22: =SUM(H22:Q22) -> 14386 | G22: 曝光 | K22: 14386
E23: =SUM(H23:Q23) -> 29 | G23: 点击 | K23: 29
G24: 点击单价 | K24: 0.77
G25: 点击率 | K25: 0.002
G26: 转化率 | K26: 0.3793
G27: 点击出价(Auto) | K27: 1.1
E28: =SUM(H28:Q28) -> 11 | G28: 出单量(通过广告） | K28: 11
G29: ACOS | K29: 10.07
F30: 手动广告（广泛1组） | G30: 花费
G31: 日预算
G32: 曝光
G33: 点击次数
G34: 点击单价
G35: 点击出价
G36: 出单量
G37: ACOS
G38: 花费
G39: 日预算
G40: 曝光
G41: 点击次数
...
