Workbook
Name 切片器_SKU名称: #N/A
Name 客户名称: OFFSET(SKU信息!$B$2,1,0,COUNTA(SKU信息!$B:$B)-1,1)

Sheet 数据分析
C3: SKU名称 | D3: 日期 | E3: 每日记录 | F3: 求和项:销量
C4: SKU1 | F4: 2521
D5: 44621 | F5: 60
E6: 做了什么？（促销，优化，测评，站外） | F6: 60
D7: 44622 | F7: 60
E8: 做了什么？（促销，优化，测评，站外） | F8: 60
D9: 44623 | F9: 60
E10: 做了什么？（促销，优化，测评，站外） | F10: 60
D11: 44624 | F11: 60
E12: 做了什么？（促销，优化，测评，站外） | F12: 60
D13: 44625 | F13: 60
E14: 做了什么？（促销，优化，测评，站外） | F14: 60
D15: 44626 | F15: 60
E16: 做了什么？（促销，优化，测评，站外） | F16: 60
D17: 44627 | F17: 60
E18: 做了什么？（促销，优化，测评，站外） | F18: 60
D19: 44628 | F19: 60
E20: 做了什么？（促销，优化，测评，站外） | F20: 60
D21: 44629 | F21: 60
E22: 做了什么？（促销，优化，测评，站外） | F22: 60
D23: 44630 | F23: 60
E24: 做了什么？（促销，优化，测评，站外） | F24: 60
D25: 44631 | F25: 60
E26: 做了什么？（促销，优化，测评，站外） | F26: 60
D27: 44632 | F27: 120
E28: 秒杀 | F28: 120
D29: 44633 | F29: 110
E30: 做了什么？（促销，优化，测评，站外） | F30: 110
D31: 44634 | F31: 100
E32: 做了什么？（促销，优化，测评，站外） | F32: 100
D33: 44635 | F33: 80
E34: 做了什么？（促销，优化，测评，站外） | F34: 80
D35: 44636 | F35: 75
E36: 做了什么？（促销，优化，测评，站外） | F36: 75
D37: 44637 | F37: 76
E38: 做了什么？（促销，优化，测评，站外） | F38: 76
D39: 44638 | F39: 77
E40: 做了什么？（促销，优化，测评，站外） | F40: 77
D41: 44639 | F41: 78
E42: 做了什么？（促销，优化，测评，站外） | F42: 78
...

Sheet 每日记录
B1: 日期 | C1: SKU名称 | D1: 每日记录 | E1: 备注 | F1: 销量 | G1: DATESKU
A2: =IF(C2="","",IF(C2=跟进查询!$B$2,1+A1,A1)) -> 1 | B2: 44621 | C2: SKU1 | D2: 做了什么？（促销，优化，测评，站外） | F2: =VLOOKUP(G2,源数据!A:K,11,FALSE) -> 60 | G2: =B2&C2 -> 44621SKU1
A3: =IF(C3="","",IF(C3=跟进查询!$B$2,1+A2,A2)) -> 2 | B3: 44622 | C3: SKU1 | D3: 做了什么？（促销，优化，测评，站外） | F3: =VLOOKUP(G3,源数据!A:K,11,FALSE) -> 60 | G3: =B3&C3 -> 44622SKU1
A4: =IF(C4="","",IF(C4=跟进查询!$B$2,1+A3,A3)) -> 3 | B4: 44623 | C4: SKU1 | D4: 做了什么？（促销，优化，测评，站外） | F4: =VLOOKUP(G4,源数据!A:K,11,FALSE) -> 60 | G4: =B4&C4 -> 44623SKU1
A5: =IF(C5="","",IF(C5=跟进查询!$B$2,1+A4,A4)) -> 4 | B5: 44624 | C5: SKU1 | D5: 做了什么？（促销，优化，测评，站外） | F5: =VLOOKUP(G5,源数据!A:K,11,FALSE) -> 60 | G5: =B5&C5 -> 44624SKU1
A6: =IF(C6="","",IF(C6=跟进查询!$B$2,1+A5,A5)) -> 5 | B6: 44625 | C6: SKU1 | D6: 做了什么？（促销，优化，测评，站外） | F6: =VLOOKUP(G6,源数据!A:K,11,FALSE) -> 60 | G6: =B6&C6 -> 44625SKU1
A7: =IF(C7="","",IF(C7=跟进查询!$B$2,1+A6,A6)) -> 6 | B7: 44626 | C7: SKU1 | D7: 做了什么？（促销，优化，测评，站外） | F7: =VLOOKUP(G7,源数据!A:K,11,FALSE) -> 60 | G7: =B7&C7 -> 44626SKU1
A8: =IF(C8="","",IF(C8=跟进查询!$B$2,1+A7,A7)) -> 7 | B8: 44627 | C8: SKU1 | D8: 做了什么？（促销，优化，测评，站外） | F8: =VLOOKUP(G8,源数据!A:K,11,FALSE) -> 60 | G8: =B8&C8 -> 44627SKU1
A9: =IF(C9="","",IF(C9=跟进查询!$B$2,1+A8,A8)) -> 8 | B9: 44628 | C9: SKU1 | D9: 做了什么？（促销，优化，测评，站外） | F9: =VLOOKUP(G9,源数据!A:K,11,FALSE) -> 60 | G9: =B9&C9 -> 44628SKU1
A10: =IF(C10="","",IF(C10=跟进查询!$B$2,1+A9,A9)) -> 9 | B10: 44629 | C10: SKU1 | D10: 做了什么？（促销，优化，测评，站外） | F10: =VLOOKUP(G10,源数据!A:K,11,FALSE) -> 60 | G10: =B10&C10 -> 44629SKU1
A11: =IF(C11="","",IF(C11=跟进查询!$B$2,1+A10,A10)) -> 10 | B11: 44630 | C11: SKU1 | D11: 做了什么？（促销，优化，测评，站外） | F11: =VLOOKUP(G11,源数据!A:K,11,FALSE) -> 60 | G11: =B11&C11 -> 44630SKU1
A12: =IF(C12="","",IF(C12=跟进查询!$B$2,1+A11,A11)) -> 11 | B12: 44631 | C12: SKU1 | D12: 做了什么？（促销，优化，测评，站外） | F12: =VLOOKUP(G12,源数据!A:K,11,FALSE) -> 60 | G12: =B12&C12 -> 44631SKU1
A13: =IF(C13="","",IF(C13=跟进查询!$B$2,1+A12,A12)) -> 12 | B13: 44632 | C13: SKU1 | D13: 秒杀 | F13: =VLOOKUP(G13,源数据!A:K,11,FALSE) -> 120 | G13: =B13&C13 -> 44632SKU1
... A16: =IF(C16="","",IF(C16=跟进查询!$B$2,1+A15,A15)) -> 15 | B16: 44635 | C16: SKU1 | D16: 做了什么？（促销，优化，测评，站外） | F16: =VLOOKUP(G16,源数据!A:K,11,FALSE) -> 80 | G16: =B16&C16 -> 44635SKU1
A17: =IF(C17="","",IF(C17=跟进查询!$B$2,1+#REF!,#REF!)) -> #REF! | B17: 44636 | C17: SKU1 | D17: 做了什么？（促销，优化，测评，站外） | F17: =VLOOKUP(G17,源数据!A:K,11,FALSE) -> 75 | G17: =B17&C17 -> 44636SKU1
A18: =IF(C18="","",IF(C18=跟进查询!$B$2,1+A17,A17)) -> #REF! | B18: 44637 | C18: SKU1 | D18: 做了什么？（促销，优化，测评，站外） | F18: =VLOOKUP(G18,源数据!A:K,11,FALSE) -> 76 | G18: =B18&C18 -> 44637SKU1
A19: =IF(C19="","",IF(C19=跟进查询!$B$2,1+A18,A18)) -> #REF! | B19: 44638 | C19: SKU1 | D19: 做了什么？（促销，优化，测评，站外） | F19: =VLOOKUP(G19,源数据!A:K,11,FALSE) -> 77 | G19: =B19&C19 -> 44638SKU1
A20: =IF(C20="","",IF(C20=跟进查询!$B$2,1+A19,A19)) -> #REF! | B20: 44639 | C20: SKU1 | D20: 做了什么？（促销，优化，测评，站外） | F20: =VLOOKUP(G20,源数据!A:K,11,FALSE) -> 78 | G20: =B20&C20 -> 44639SKU1
A21: =IF(C21="","",IF(C21=跟进查询!$B$2,1+A20,A20)) -> #REF! | B21: 44640 | C21: SKU1 | D21: 做了什么？（促销，优化，测评，站外） | F21: =VLOOKUP(G21,源数据!A:K,11,FALSE) -> 79 | G21: =B21&C21 -> 44640SKU1
A22: =IF(C22="","",IF(C22=跟进查询!$B$2,1+A21,A21)) -> #REF! | B22: 44641 | C22: SKU1 | D22: 站外 | F22: =VLOOKUP(G22,源数据!A:K,11,FALSE) -> 130 | G22: =B22&C22 -> 44641SKU1
A23: =IF(C23="","",IF(C23=跟进查询!$B$2,1+A22,A22)) -> #REF! | B23: 44642 | C23: SKU1 | D23: 做了什么？（促销，优化，测评，站外） | F23: =VLOOKUP(G23,源数据!A:K,11,FALSE) -> 120 | G23: =B23&C23 -> 44642SKU1
A24: =IF(C24="","",IF(C24=跟进查询!$B$2,1+A23,A23)) -> #REF! | B24: 44643 | C24: SKU1 | D24: 做了什么？（促销，优化，测评，站外） | F24: =VLOOKUP(G24,源数据!A:K,11,FALSE) -> 110 | G24: =B24&C24 -> 44643SKU1
A25: =IF(C25="","",IF(C25=跟进查询!$B$2,1+A24,A24)) -> #REF! | B25: 44644 | C25: SKU1 | D25: 做了什么？（促销，优化，测评，站外） | F25: =VLOOKUP(G25,源数据!A:K,11,FALSE) -> 90 | G25: =B25&C25 -> 44644SKU1
A26: =IF(C26="","",IF(C26=跟进查询!$B$2,1+A25,A25)) -> #REF! | B26: 44645 | C26: SKU1 | D26: 做了什么？（促销，优化，测评，站外） | F26: =VLOOKUP(G26,源数据!A:K,11,FALSE) -> 85 | G26: =B26&C26 -> 44645SKU1
A27: =IF(C27="","",IF(C27=跟进查询!$B$2,1+A26,A26)) -> #REF! | B27: 44646 | C27: SKU1 | D27: 做了什么？（促销，优化，测评，站外） | F27: =VLOOKUP(G27,源数据!A:K,11,FALSE) -> 86 | G27: =B27&C27 -> 44646SKU1
A28: =IF(C28="","",IF(C28=跟进查询!$B$2,1+A27,A27)) -> #REF! | B28: 44647 | C28: SKU1 | D28: 做了什么？（促销，优化，测评，站外） | F28: =VLOOKUP(G28,源数据!A:K,11,FALSE) -> 87 | G28: =B28&C28 -> 44647SKU1
A29: =IF(C29="","",IF(C29=跟进查询!$B$2,1+A28,A28)) -> #REF! | B29: 44648 | C29: SKU1 | D29: 做了什么？（促销，优化，测评，站外） | F29: =VLOOKUP(G29,源数据!A:K,11,FALSE) -> 88 | G29: =B29&C29 -> 44648SKU1
... A63: =IF(C63="","",IF(C63=跟进查询!$B$2,1+A62,A62)) -> #REF! | B63: 44651 | C63: SKU2 | D63: 做了什么？（促销，优化，测评，站外） | F63: =VLOOKUP(G63,源数据!A:K,11,FALSE) -> 71 | G63: =B63&C63 -> 44651SKU2
A64: =IF(C64="","",IF(C64=跟进查询!$B$2,1+A63,A63)) | F64: =VLOOKUP(G64,源数据!A:K,11,FALSE) -> #N/A | G64: =B64&C64
A65: =IF(C65="","",IF(C65=跟进查询!$B$2,1+A64,A64)) | F65: =VLOOKUP(G65,源数据!A:K,11,FALSE) -> #N/A | G65: =B65&C65
A66: =IF(C66="","",IF(C66=跟进查询!$B$2,1+A65,A65)) | F66: =VLOOKUP(G66,源数据!A:K,11,FALSE) -> #N/A | G66: =B66&C66
A67: =IF(C67="","",IF(C67=跟进查询!$B$2,1+A66,A66)) | F67: =VLOOKUP(G67,源数据!A:K,11,FALSE) -> #N/A | G67: =B67&C67
A68: =IF(C68="","",IF(C68=跟进查询!$B$2,1+A67,A67)) | F68: =VLOOKUP(G68,源数据!A:K,11,FALSE) -> #N/A | G68: =B68&C68
A69: =IF(C69="","",IF(C69=跟进查询!$B$2,1+A68,A68)) | F69: =VLOOKUP(G69,源数据!A:K,11,FALSE) -> #N/A | G69: =B69&C69
A70: =IF(C70="","",IF(C70=跟进查询!$B$2,1+A69,A69)) | F70: =VLOOKUP(G70,源数据!A:K,11,FALSE) -> #N/A | G70: =B70&C70
A71: =IF(C71="","",IF(C71=跟进查询!$B$2,1+A70,A70)) | F71: =VLOOKUP(G71,源数据!A:K,11,FALSE) -> #N/A | G71: =B71&C71
A72: =IF(C72="","",IF(C72=跟进查询!$B$2,1+A71,A71)) | F72: =VLOOKUP(G72,源数据!A:K,11,FALSE) -> #N/A | G72: =B72&C72
A73: =IF(C73="","",IF(C73=跟进查询!$B$2,1+A72,A72)) | F73: =VLOOKUP(G73,源数据!A:K,11,FALSE) -> #N/A | G73: =B73&C73
A74: =IF(C74="","",IF(C74=跟进查询!$B$2,1+A73,A73)) | F74: =VLOOKUP(G74,源数据!A:K,11,FALSE) -> #N/A | G74: =B74&C74
A75: =IF(C75="","",IF(C75=跟进查询!$B$2,1+A74,A74)) | F75: =VLOOKUP(G75,源数据!A:K,11,FALSE) -> #N/A | G75: =B75&C75
...

Sheet 跟进查询
A1: 跟进查询
A2: SKU名称 | B2: SKU1 | E2: 产品名称 | F2: =VLOOKUP(B2,SKU信息!$B:$H,2,0) -> XXX1
A3: 负责人 | B3: =VLOOKUP(B2,SKU信息!$B:$H,3,0) -> Cecilia | E3: ASIN | F3: =VLOOKUP(B2,SKU信息!$B:$H,4,0) -> Bxxxx1
A4: 站 点 | B4: =VLOOKUP(B2,SKU信息!$B:$H,5,0) -> US | E4: 货物类型 | F4: =VLOOKUP(B2,SKU信息!$B:$H,6,0) -> 普货
A5: 备 注 | B5: =VLOOKUP(B2,SKU信息!$B:$H,7,0) -> 0
A6: 最近一次更新 | B6: =IFERROR(LOOKUP(1,0/(每日记录!$C$2:C65533=跟进查询!$B$2),每日记录!$B$2:$B$65533),"") -> 44651
A8: 跟 进 日 期 | B8: 跟 进 情 况 | F8: 备 注
A9: =IFERROR(VLOOKUP(ROW()-8,每日记录!$A:$G,2,0),"") -> 44621 | B9: =IFERROR(VLOOKUP(ROW()-8,每日记录!$A:$G,4,0),"") -> 做了什么？（促销，优化，测评，站外） | F9: =IFERROR(VLOOKUP(ROW()-8,每日记录!$A:$G,5,0),"") -> 0
A10: =IFERROR(VLOOKUP(ROW()-8,每日记录!$A:$G,2,0),"") -> 44622 | B10: =IFERROR(VLOOKUP(ROW()-8,每日记录!$A:$G,4,0),"") -> 做了什么？（促销，优化，测评，站外） | F10: =IFERROR(VLOOKUP(ROW()-8,每日记录!$A:$G,5,0),"") -> 0
A11: =IFERROR(VLOOKUP(ROW()-8,每日记录!$A:$G,2,0),"") -> 44623 | B11: =IFERROR(VLOOKUP(ROW()-8,每日记录!$A:$G,4,0),"") -> 做了什么？（促销，优化，测评，站外） | F11: =IFERROR(VLOOKUP(ROW()-8,每日记录!$A:$G,5,0),"") -> 0
A12: =IFERROR(VLOOKUP(ROW()-8,每日记录!$A:$G,2,0),"") -> 44624 | B12: =IFERROR(VLOOKUP(ROW()-8,每日记录!$A:$G,4,0),"") -> 做了什么？（促销，优化，测评，站外） | F12: =IFERROR(VLOOKUP(ROW()-8,每日记录!$A:$G,5,0),"") -> 0
A13: =IFERROR(VLOOKUP(ROW()-8,每日记录!$A:$G,2,0),"") -> 44625 | B13: =IFERROR(VLOOKUP(ROW()-8,每日记录!$A:$G,4,0),"") -> 做了什么？（促销，优化，测评，站外） | F13: =IFERROR(VLOOKUP(ROW()-8,每日记录!$A:$G,5,0),"") -> 0
A14: =IFERROR(VLOOKUP(ROW()-8,每日记录!$A:$G,2,0),"") -> 44626 | B14: =IFERROR(VLOOKUP(ROW()-8,每日记录!$A:$G,4,0),"") -> 做了什么？（促销，优化，测评，站外） | F14: =IFERROR(VLOOKUP(ROW()-8,每日记录!$A:$G,5,0),"") -> 0
A15: =IFERROR(VLOOKUP(ROW()-8,每日记录!$A:$G,2,0),"") -> 44627 | B15: =IFERROR(VLOOKUP(ROW()-8,每日记录!$A:$G,4,0),"") -> 做了什么？（促销，优化，测评，站外） | F15: =IFERROR(VLOOKUP(ROW()-8,每日记录!$A:$G,5,0),"") -> 0
A16: =IFERROR(VLOOKUP(ROW()-8,每日记录!$A:$G,2,0),"") -> 44628 | B16: =IFERROR(VLOOKUP(ROW()-8,每日记录!$A:$G,4,0),"") -> 做了什么？（促销，优化，测评，站外） | F16: =IFERROR(VLOOKUP(ROW()-8,每日记录!$A:$G,5,0),"") -> 0
A17: =IFERROR(VLOOKUP(ROW()-8,每日记录!$A:$G,2,0),"") -> 44629 | B17: =IFERROR(VLOOKUP(ROW()-8,每日记录!$A:$G,4,0),"") -> 做了什么？（促销，优化，测评，站外） | F17: =IFERROR(VLOOKUP(ROW()-8,每日记录!$A:$G,5,0),"") -> 0
A18: =IFERROR(VLOOKUP(ROW()-8,每日记录!$A:$G,2,0),"") -> 44630 | B18: =IFERROR(VLOOKUP(ROW()-8,每日记录!$A:$G,4,0),"") -> 做了什么？（促销，优化，测评，站外） | F18: =IFERROR(VLOOKUP(ROW()-8,每日记录!$A:$G,5,0),"") -> 0
A19: =IFERROR(VLOOKUP(ROW()-8,每日记录!$A:$G,2,0),"") -> 44631 | B19: =IFERROR(VLOOKUP(ROW()-8,每日记录!$A:$G,4,0),"") -> 做了什么？（促销，优化，测评，站外） | F19: =IFERROR(VLOOKUP(ROW()-8,每日记录!$A:$G,5,0),"") -> 0
A20: =IFERROR(VLOOKUP(ROW()-8,每日记录!$A:$G,2,0),"") -> 44632 | B20: =IFERROR(VLOOKUP(ROW()-8,每日记录!$A:$G,4,0),"") -> 秒杀 | F20: =IFERROR(VLOOKUP(ROW()-8,每日记录!$A:$G,5,0),"") -> 0
... A237: =IFERROR(VLOOKUP(ROW()-8,每日记录!$A:$G,2,0),"") | B237: =IFERROR(VLOOKUP(ROW()-8,每日记录!$A:$G,4,0),"") | F237: =IFERROR(VLOOKUP(ROW()-8,每日记录!$A:$G,5,0),"")

Sheet SKU信息
B2: SKU名称 | C2: 产品名称 | D2: 负责人 | E2: ASIN | F2: 站点 | G2: 货物类型 | H2: 备注
B3: SKU1 | C3: XXX1 | D3: Cecilia | E3: Bxxxx1 | F3: US | G3: 普货
B4: SKU2 | C4: XXX2 | D4: Cecilia | E4: Bxxxx2 | F4: US | G4: 普货
B5: SKU3 | C5: XXX3 | D5: Kris | E5: Bxxxx3 | F5: US | G5: 轻小货
B6: SKU4 | C6: XXX4 | D6: Kris | E6: Bxxxx4 | F6: UK | G6: 普货
B7: SKU5 | C7: XXX5 | D7: Kris | E7: Bxxxx5 | F7: UK | G7: 普货
B8: SKU6 | C8: XXX6 | D8: Jessica | E8: Bxxxx6 | F8: UK | G8: 带电
B9: SKU7 | C9: XXX7 | D9: Jessica | E9: Bxxxx7 | F9: DE | G9: 带电
B10: SKU8 | C10: XXX8 | D10: Jessica | E10: Bxxxx8 | F10: DE | G10: 带电
B11: SKU9 | C11: XXX9 | D11: Lucas | E11: Bxxxx9 | F11: DE | G11: 大件
B12: SKU10 | C12: XXX10 | D12: Lucas | E12: Bxxxx10 | F12: UK | G12: 大件
B13: SKU11 | C13: XXX11 | D13: Lucas | E13: Bxxxx11 | F13: UK | G13: 普货
B14: SKU12 | C14: XXX12 | D14: Daniel | E14: Bxxxx12 | F14: UK | G14: 普货
B15: SKU13 | C15: XXX13 | D15: Daniel | E15: Bxxxx13 | F15: UK | G15: 普货

Sheet 源数据
A1: Same Data | B1: Date | C1: (Parent) ASIN | D1: (Child) ASIN | E1: Title | F1: Sessions | G1: Session Percentage | H1: Page Views | I1: Page Views Percentage | J1: Buy Box Percentage | K1: Units Ordered | L1: Units Ordered - B2B | M1: Unit Session Percentage | N1: Unit Session Percentage - B2B | O1: Ordered Product Sales | P1: Ordered Product Sales - B2B | Q1: Total Order Items | R1: Total Order Items - B2B | S1: SKU
A2: =B2&S2 -> 44621SKU1 | B2: 44621 | C2: Bxxxx1 | D2: Bxxxx1 | E2: A1 | K2: 60 | S2: =INDEX(SKU信息!B:B,MATCH(D2,SKU信息!E:E,0)) -> SKU1
A3: =B3&S3 -> 44622SKU1 | B3: 44622 | C3: Bxxxx1 | D3: Bxxxx1 | E3: A1 | K3: 60 | S3: =INDEX(SKU信息!B:B,MATCH(D3,SKU信息!E:E,0)) -> SKU1
A4: =B4&S4 -> 44623SKU1 | B4: 44623 | C4: Bxxxx1 | D4: Bxxxx1 | E4: A1 | K4: 60 | S4: =INDEX(SKU信息!B:B,MATCH(D4,SKU信息!E:E,0)) -> SKU1
A5: =B5&S5 -> 44624SKU1 | B5: 44624 | C5: Bxxxx1 | D5: Bxxxx1 | E5: A1 | K5: 60 | S5: =INDEX(SKU信息!B:B,MATCH(D5,SKU信息!E:E,0)) -> SKU1
A6: =B6&S6 -> 44625SKU1 | B6: 44625 | C6: Bxxxx1 | D6: Bxxxx1 | E6: A1 | K6: 60 | S6: =INDEX(SKU信息!B:B,MATCH(D6,SKU信息!E:E,0)) -> SKU1
A7: =B7&S7 -> 44626SKU1 | B7: 44626 | C7: Bxxxx1 | D7: Bxxxx1 | E7: A1 | K7: 60 | S7: =INDEX(SKU信息!B:B,MATCH(D7,SKU信息!E:E,0)) -> SKU1
A8: =B8&S8 -> 44627SKU1 | B8: 44627 | C8: Bxxxx1 | D8: Bxxxx1 | E8: A1 | K8: 60 | S8: =INDEX(SKU信息!B:B,MATCH(D8,SKU信息!E:E,0)) -> SKU1
A9: =B9&S9 -> 44628SKU1 | B9: 44628 | C9: Bxxxx1 | D9: Bxxxx1 | E9: A1 | K9: 60 | S9: =INDEX(SKU信息!B:B,MATCH(D9,SKU信息!E:E,0)) -> SKU1
A10: =B10&S10 -> 44629SKU1 | B10: 44629 | C10: Bxxxx1 | D10: Bxxxx1 | E10: A1 | K10: 60 | S10: =INDEX(SKU信息!B:B,MATCH(D10,SKU信息!E:E,0)) -> SKU1
A11: =B11&S11 -> 44630SKU1 | B11: 44630 | C11: Bxxxx1 | D11: Bxxxx1 | E11: A1 | K11: 60 | S11: =INDEX(SKU信息!B:B,MATCH(D11,SKU信息!E:E,0)) -> SKU1
A12: =B12&S12 -> 44631SKU1 | B12: 44631 | C12: Bxxxx1 | D12: Bxxxx1 | E12: A1 | K12: 60 | S12: =INDEX(SKU信息!B:B,MATCH(D12,SKU信息!E:E,0)) -> SKU1
A13: =B13&S13 -> 44632SKU1 | B13: 44632 | C13: Bxxxx1 | D13: Bxxxx1 | E13: A1 | K13: 120 | S13: =INDEX(SKU信息!B:B,MATCH(D13,SKU信息!E:E,0)) -> SKU1
... A63: =B63&S63 -> 44651SKU2 | B63: 44651 | C63: Bxxxx2 | D63: Bxxxx2 | E63: A2 | K63: 71 | S63: =INDEX(SKU信息!B:B,MATCH(D63,SKU信息!E:E,0)) -> SKU2

Sheet 使用说明
A2: 使用说明：
A3: 1、 | B3: SKU信息>>录入产品相关信息。
A4: 2、 | B4: 每日记录>>SKU名称下拉选择，其他项目手动录入，清除数据，可选中区域点击del，切勿直接删行。
A5: 3、 | B5: 跟进查询>>下拉选择SKU名称，自动显示明细记录。
A6: 4、 | B6: 凡有公式的地方都可以自动统计，无须改动，公式可以直接拖拉填充
