Workbook

Sheet 总表
A1: 表头 | B1: 整体数据 | K1: 广告数据 | T1: 操作记录
A2: 日期 | B2: 访客数 | C2: 销量 | D2: 订单数 | E2: 访客转化率 | F2: 转化率 | G2: 销售额 | H2: 总ACOS | I2: 广告销售比 | J2: 星期 | K2: Impressions | L2: Click | M2: CTR | N2: CPC | O2: Order | P2: Sales | Q2: CR | R2: Spend | S2: ACOS
A3: 44440 | B3: =SUMIFS(销售数据包!F:F,销售数据包!A:A,A3,销售数据包!C:C,Base!$F$2)+SUMIFS(销售数据包!F:F,销售数据包!A:A,A3,销售数据包!C:C,Base!$F$3)+SUMIFS(销售数据包!F:F,销售数据包!A:A,A3,销售数据包!C:C,Base!$F$4) -> 0 | C3: =SUMIFS(销售数据包!K:K,销售数据包!A:A,A3,销售数据包!C:C,Base!$F$2)+SUMIFS(销售数据包!K:K,销售数据包!A:A,A3,销售数据包!C:C,Base!$F$3)+SUMIFS(销售数据包!K:K,销售数据包!A:A,A3,销售数据包!C:C,Base!$F$4) -> 0 | D3: =SUMIFS(销售数据包!Q:Q,销售数据包!A:A,A3,销售数据包!C:C,Base!$F$2)+SUMIFS(销售数据包!Q:Q,销售数据包!A:A,A3,销售数据包!C:C,Base!$F$3)+SUMIFS(销售数据包!Q:Q,销售数据包!A:A,A3,销售数据包!C:C,Base!$F$4) -> 0 | E3: =IFERROR(D3/B3,0) -> 0 | F3: =IFERROR(C3/B3,0) -> 0 | G3: =SUMIFS(销售数据包!O:O,销售数据包!A:A,A3) -> 0 | H3: =IFERROR(R3/G3,0) -> 0 | I3: =IFERROR(P3/G3,0) -> 0 | J3: ="周"&WEEKDAY(A3,2) -> 周3 | K3: =SUMIFS(广告数据包!H:H,广告数据包!A:A,A3,广告数据包!G:G,Base!$F$2)+SUMIFS(广告数据包!H:H,广告数据包!A:A,A3,广告数据包!G:G,Base!$F$3)+SUMIFS(广告数据包!H:H,广告数据包!A:A,A3,广告数据包!G:G,Base!$F$4) -> 0 | L3: =SUMIFS(广告数据包!I:I,广告数据包!A:A,A3,广告数据包!G:G,Base!$F$2)+SUMIFS(广告数据包!I:I,广告数据包!A:A,A3,广告数据包!G:G,Base!$F$3)+SUMIFS(广告数据包!I:I,广告数据包!A:A,A3,广告数据包!G:G,Base!$F$4) -> 0 | M3: =IFERROR(L3/K3,0) -> 0 | N3: =IFERROR(R3/L3,0) -> 0 | O3: =SUMIFS(广告数据包!P:P,广告数据包!A:A,A3,广告数据包!G:G,Base!$F$2)+SUMIFS(广告数据包!P:P,广告数据包!A:A,A3,广告数据包!G:G,Base!$F$3)+SUMIFS(广告数据包!P:P,广告数据包!A:A,A3,广告数据包!G:G,Base!$F$4) -> 0 | P3: =SUMIFS(广告数据包!M:M,广告数据包!A:A,A3,广告数据包!G:G,Base!$F$2)+SUMIFS(广告数据包!M:M,广告数据包!A:A,A3,广告数据包!G:G,Base!$F$3)+SUMIFS(广告数据包!M:M,广告数据包!A:A,A3,广告数据包!G:G,Base!$F$4) -> 0 | Q3: =IFERROR(O3/L3,0) -> 0 | R3: =SUMIFS(广告数据包!L:L,广告数据包!A:A,A3,广告数据包!G:G,Base!$F$2)+SUMIFS(广告数据包!L:L,广告数据包!A:A,A3,广告数据包!G:G,Base!$F$3)+SUMIFS(广告数据包!L:L,广告数据包!A:A,A3,广告数据包!G:G,Base!$F$4) -> 0 | S3: =IFERROR(R3/P3,0) -> 0
A4: 44441 | B4: =SUMIFS(销售数据包!F:F,销售数据包!A:A,A4,销售数据包!C:C,Base!$F$2)+SUMIFS(销售数据包!F:F,销售数据包!A:A,A4,销售数据包!C:C,Base!$F$3)+SUMIFS(销售数据包!F:F,销售数据包!A:A,A4,销售数据包!C:C,Base!$F$4) -> 0 | C4: =SUMIFS(销售数据包!K:K,销售数据包!A:A,A4,销售数据包!C:C,Base!$F$2)+SUMIFS(销售数据包!K:K,销售数据包!A:A,A4,销售数据包!C:C,Base!$F$3)+SUMIFS(销售数据包!K:K,销售数据包!A:A,A4,销售数据包!C:C,Base!$F$4) -> 0 | D4: =SUMIFS(销售数据包!Q:Q,销售数据包!A:A,A4,销售数据包!C:C,Base!$F$2)+SUMIFS(销售数据包!Q:Q,销售数据包!A:A,A4,销售数据包!C:C,Base!$F$3)+SUMIFS(销售数据包!Q:Q,销售数据包!A:A,A4,销售数据包!C:C,Base!$F$4) -> 0 | E4: =IFERROR(D4/B4,0) -> 0 | F4: =IFERROR(C4/B4,0) -> 0 | G4: =SUMIFS(销售数据包!O:O,销售数据包!A:A,A4) -> 0 | H4: =IFERROR(R4/G4,0) -> 0 | I4: =IFERROR(P4/G4,0) -> 0 | J4: ="周"&WEEKDAY(A4,2) -> 周4 | K4: =SUMIFS(广告数据包!H:H,广告数据包!A:A,A4,广告数据包!G:G,Base!$F$2)+SUMIFS(广告数据包!H:H,广告数据包!A:A,A4,广告数据包!G:G,Base!$F$3)+SUMIFS(广告数据包!H:H,广告数据包!A:A,A4,广告数据包!G:G,Base!$F$4) -> 0 | L4: =SUMIFS(广告数据包!I:I,广告数据包!A:A,A4,广告数据包!G:G,Base!$F$2)+SUMIFS(广告数据包!I:I,广告数据包!A:A,A4,广告数据包!G:G,Base!$F$3)+SUMIFS(广告数据包!I:I,广告数据包!A:A,A4,广告数据包!G:G,Base!$F$4) -> 0 | M4: =IFERROR(L4/K4,0) -> 0 | N4: =IFERROR(R4/L4,0) -> 0 | O4: =SUMIFS(广告数据包!P:P,广告数据包!A:A,A4,广告数据包!G:G,Base!$F$2)+SUMIFS(广告数据包!P:P,广告数据包!A:A,A4,广告数据包!G:G,Base!$F$3)+SUMIFS(广告数据包!P:P,广告数据包!A:A,A4,广告数据包!G:G,Base!$F$4) -> 0 | P4: =SUMIFS(广告数据包!M:M,广告数据包!A:A,A4,广告数据包!G:G,Base!$F$2)+SUMIFS(广告数据包!M:M,广告数据包!A:A,A4,广告数据包!G:G,Base!$F$3)+SUMIFS(广告数据包!M:M,广告数据包!A:A,A4,广告数据包!G:G,Base!$F$4) -> 0 | Q4: =IFERROR(O4/L4,0) -> 0 | R4: =SUMIFS(广告数据包!L:L,广告数据包!A:A,A4,广告数据包!G:G,Base!$F$2)+SUMIFS(广告数据包!L:L,广告数据包!A:A,A4,广告数据包!G:G,Base!$F$3)+SUMIFS(广告数据包!L:L,广告数据包!A:A,A4,广告数据包!G:G,Base!$F$4) -> 0 | S4: =IFERROR(R4/P4,0) -> 0
A5: 44442 | B5: =SUMIFS(销售数据包!F:F,销售数据包!A:A,A5,销售数据包!C:C,Base!$F$2)+SUMIFS(销售数据包!F:F,销售数据包!A:A,A5,销售数据包!C:C,Base!$F$3)+SUMIFS(销售数据包!F:F,销售数据包!A:A,A5,销售数据包!C:C,Base!$F$4) -> 0 | C5: =SUMIFS(销售数据包!K:K,销售数据包!A:A,A5,销售数据包!C:C,Base!$F$2)+SUMIFS(销售数据包!K:K,销售数据包!A:A,A5,销售数据包!C:C,Base!$F$3)+SUMIFS(销售数据包!K:K,销售数据包!A:A,A5,销售数据包!C:C,Base!$F$4) -> 0 | D5: =SUMIFS(销售数据包!Q:Q,销售数据包!A:A,A5,销售数据包!C:C,Base!$F$2)+SUMIFS(销售数据包!Q:Q,销售数据包!A:A,A5,销售数据包!C:C,Base!$F$3)+SUMIFS(销售数据包!Q:Q,销售数据包!A:A,A5,销售数据包!C:C,Base!$F$4) -> 0 | E5: =IFERROR(D5/B5,0) -> 0 | F5: =IFERROR(C5/B5,0) -> 0 | G5: =SUMIFS(销售数据包!O:O,销售数据包!A:A,A5) -> 0 | H5: =IFERROR(R5/G5,0) -> 0 | I5: =IFERROR(P5/G5,0) -> 0 | J5: ="周"&WEEKDAY(A5,2) -> 周5 | K5: =SUMIFS(广告数据包!H:H,广告数据包!A:A,A5,广告数据包!G:G,Base!$F$2)+SUMIFS(广告数据包!H:H,广告数据包!A:A,A5,广告数据包!G:G,Base!$F$3)+SUMIFS(广告数据包!H:H,广告数据包!A:A,A5,广告数据包!G:G,Base!$F$4) -> 0 | L5: =SUMIFS(广告数据包!I:I,广告数据包!A:A,A5,广告数据包!G:G,Base!$F$2)+SUMIFS(广告数据包!I:I,广告数据包!A:A,A5,广告数据包!G:G,Base!$F$3)+SUMIFS(广告数据包!I:I,广告数据包!A:A,A5,广告数据包!G:G,Base!$F$4) -> 0 | M5: =IFERROR(L5/K5,0) -> 0 | N5: =IFERROR(R5/L5,0) -> 0 | O5: =SUMIFS(广告数据包!P:P,广告数据包!A:A,A5,广告数据包!G:G,Base!$F$2)+SUMIFS(广告数据包!P:P,广告数据包!A:A,A5,广告数据包!G:G,Base!$F$3)+SUMIFS(广告数据包!P:P,广告数据包!A:A,A5,广告数据包!G:G,Base!$F$4) -> 0 | P5: =SUMIFS(广告数据包!M:M,广告数据包!A:A,A5,广告数据包!G:G,Base!$F$2)+SUMIFS(广告数据包!M:M,广告数据包!A:A,A5,广告数据包!G:G,Base!$F$3)+SUMIFS(广告数据包!M:M,广告数据包!A:A,A5,广告数据包!G:G,Base!$F$4) -> 0 | Q5: =IFERROR(O5/L5,0) -> 0 | R5: =SUMIFS(广告数据包!L:L,广告数据包!A:A,A5,广告数据包!G:G,Base!$F$2)+SUMIFS(广告数据包!L:L,广告数据包!A:A,A5,广告数据包!G:G,Base!$F$3)+SUMIFS(广告数据包!L:L,广告数据包!A:A,A5,广告数据包!G:G,Base!$F$4) -> 0 | S5: =IFERROR(R5/P5,0) -> 0
A6: 44443 | B6: =SUMIFS(销售数据包!F:F,销售数据包!A:A,A6,销售数据包!C:C,Base!$F$2)+SUMIFS(销售数据包!F:F,销售数据包!A:A,A6,销售数据包!C:C,Base!$F$3)+SUMIFS(销售数据包!F:F,销售数据包!A:A,A6,销售数据包!C:C,Base!$F$4) -> 0 | C6: =SUMIFS(销售数据包!K:K,销售数据包!A:A,A6,销售数据包!C:C,Base!$F$2)+SUMIFS(销售数据包!K:K,销售数据包!A:A,A6,销售数据包!C:C,Base!$F$3)+SUMIFS(销售数据包!K:K,销售数据包!A:A,A6,销售数据包!C:C,Base!$F$4) -> 0 | D6: =SUMIFS(销售数据包!Q:Q,销售数据包!A:A,A6,销售数据包!C:C,Base!$F$2)+SUMIFS(销售数据包!Q:Q,销售数据包!A:A,A6,销售数据包!C:C,Base!$F$3)+SUMIFS(销售数据包!Q:Q,销售数据包!A:A,A6,销售数据包!C:C,Base!$F$4) -> 0 | E6: =IFERROR(D6/B6,0) -> 0 | F6: =IFERROR(C6/B6,0) -> 0 | G6: =SUMIFS(销售数据包!O:O,销售数据包!A:A,A6) -> 0 | H6: =IFERROR(R6/G6,0) -> 0 | I6: =IFERROR(P6/G6,0) -> 0 | J6: ="周"&WEEKDAY(A6,2) -> 周6 | K6: =SUMIFS(广告数据包!H:H,广告数据包!A:A,A6,广告数据包!G:G,Base!$F$2)+SUMIFS(广告数据包!H:H,广告数据包!A:A,A6,广告数据包!G:G,Base!$F$3)+SUMIFS(广告数据包!H:H,广告数据包!A:A,A6,广告数据包!G:G,Base!$F$4) -> 0 | L6: =SUMIFS(广告数据包!I:I,广告数据包!A:A,A6,广告数据包!G:G,Base!$F$2)+SUMIFS(广告数据包!I:I,广告数据包!A:A,A6,广告数据包!G:G,Base!$F$3)+SUMIFS(广告数据包!I:I,广告数据包!A:A,A6,广告数据包!G:G,Base!$F$4) -> 0 | M6: =IFERROR(L6/K6,0) -> 0 | N6: =IFERROR(R6/L6,0) -> 0 | O6: =SUMIFS(广告数据包!P:P,广告数据包!A:A,A6,广告数据包!G:G,Base!$F$2)+SUMIFS(广告数据包!P:P,广告数据包!A:A,A6,广告数据包!G:G,Base!$F$3)+SUMIFS(广告数据包!P:P,广告数据包!A:A,A6,广告数据包!G:G,Base!$F$4) -> 0 | P6: =SUMIFS(广告数据包!M:M,广告数据包!A:A,A6,广告数据包!G:G,Base!$F$2)+SUMIFS(广告数据包!M:M,广告数据包!A:A,A6,广告数据包!G:G,Base!$F$3)+SUMIFS(广告数据包!M:M,广告数据包!A:A,A6,广告数据包!G:G,Base!$F$4) -> 0 | Q6: =IFERROR(O6/L6,0) -> 0 | R6: =SUMIFS(广告数据包!L:L,广告数据包!A:A,A6,广告数据包!G:G,Base!$F$2)+SUMIFS(广告数据包!L:L,广告数据包!A:A,A6,广告数据包!G:G,Base!$F$3)+SUMIFS(广告数据包!L:L,广告数据包!A:A,A6,广告数据包!G:G,Base!$F$4) -> 0 | S6: =IFERROR(R6/P6,0) -> 0
A7: 44444 | B7: =SUMIFS(销售数据包!F:F,销售数据包!A:A,A7,销售数据包!C:C,Base!$F$2)+SUMIFS(销售数据包!F:F,销售数据包!A:A,A7,销售数据包!C:C,Base!$F$3)+SUMIFS(销售数据包!F:F,销售数据包!A:A,A7,销售数据包!C:C,Base!$F$4) -> 0 | C7: =SUMIFS(销售数据包!K:K,销售数据包!A:A,A7,销售数据包!C:C,Base!$F$2)+SUMIFS(销售数据包!K:K,销售数据包!A:A,A7,销售数据包!C:C,Base!$F$3)+SUMIFS(销售数据包!K:K,销售数据包!A:A,A7,销售数据包!C:C,Base!$F$4) -> 0 | D7: =SUMIFS(销售数据包!Q:Q,销售数据包!A:A,A7,销售数据包!C:C,Base!$F$2)+SUMIFS(销售数据包!Q:Q,销售数据包!A:A,A7,销售数据包!C:C,Base!$F$3)+SUMIFS(销售数据包!Q:Q,销售数据包!A:A,A7,销售数据包!C:C,Base!$F$4) -> 0 | E7: =IFERROR(D7/B7,0) -> 0 | F7: =IFERROR(C7/B7,0) -> 0 | G7: =SUMIFS(销售数据包!O:O,销售数据包!A:A,A7) -> 0 | H7: =IFERROR(R7/G7,0) -> 0 | I7: =IFERROR(P7/G7,0) -> 0 | J7: ="周"&WEEKDAY(A7,2) -> 周7 | K7: =SUMIFS(广告数据包!H:H,广告数据包!A:A,A7,广告数据包!G:G,Base!$F$2)+SUMIFS(广告数据包!H:H,广告数据包!A:A,A7,广告数据包!G:G,Base!$F$3)+SUMIFS(广告数据包!H:H,广告数据包!A:A,A7,广告数据包!G:G,Base!$F$4) -> 0 | L7: =SUMIFS(广告数据包!I:I,广告数据包!A:A,A7,广告数据包!G:G,Base!$F$2)+SUMIFS(广告数据包!I:I,广告数据包!A:A,A7,广告数据包!G:G,Base!$F$3)+SUMIFS(广告数据包!I:I,广告数据包!A:A,A7,广告数据包!G:G,Base!$F$4) -> 0 | M7: =IFERROR(L7/K7,0) -> 0 | N7: =IFERROR(R7/L7,0) -> 0 | O7: =SUMIFS(广告数据包!P:P,广告数据包!A:A,A7,广告数据包!G:G,Base!$F$2)+SUMIFS(广告数据包!P:P,广告数据包!A:A,A7,广告数据包!G:G,Base!$F$3)+SUMIFS(广告数据包!P:P,广告数据包!A:A,A7,广告数据包!G:G,Base!$F$4) -> 0 | P7: =SUMIFS(广告数据包!M:M,广告数据包!A:A,A7,广告数据包!G:G,Base!$F$2)+SUMIFS(广告数据包!M:M,广告数据包!A:A,A7,广告数据包!G:G,Base!$F$3)+SUMIFS(广告数据包!M:M,广告数据包!A:A,A7,广告数据包!G:G,Base!$F$4) -> 0 | Q7: =IFERROR(O7/L7,0) -> 0 | R7: =SUMIFS(广告数据包!L:L,广告数据包!A:A,A7,广告数据包!G:G,Base!$F$2)+SUMIFS(广告数据包!L:L,广告数据包!A:A,A7,广告数据包!G:G,Base!$F$3)+SUMIFS(广告数据包!L:L,广告数据包!A:A,A7,广告数据包!G:G,Base!$F$4) -> 0 | S7: =IFERROR(R7/P7,0) -> 0
A8: 44445 | B8: =SUMIFS(销售数据包!F:F,销售数据包!A:A,A8,销售数据包!C:C,Base!$F$2)+SUMIFS(销售数据包!F:F,销售数据包!A:A,A8,销售数据包!C:C,Base!$F$3)+SUMIFS(销售数据包!F:F,销售数据包!A:A,A8,销售数据包!C:C,Base!$F$4) -> 0 | C8: =SUMIFS(销售数据包!K:K,销售数据包!A:A,A8,销售数据包!C:C,Base!$F$2)+SUMIFS(销售数据包!K:K,销售数据包!A:A,A8,销售数据包!C:C,Base!$F$3)+SUMIFS(销售数据包!K:K,销售数据包!A:A,A8,销售数据包!C:C,Base!$F$4) -> 0 | D8: =SUMIFS(销售数据包!Q:Q,销售数据包!A:A,A8,销售数据包!C:C,Base!$F$2)+SUMIFS(销售数据包!Q:Q,销售数据包!A:A,A8,销售数据包!C:C,Base!$F$3)+SUMIFS(销售数据包!Q:Q,销售数据包!A:A,A8,销售数据包!C:C,Base!$F$4) -> 0 | E8: =IFERROR(D8/B8,0) -> 0 | F8: =IFERROR(C8/B8,0) -> 0 | G8: =SUMIFS(销售数据包!O:O,销售数据包!A:A,A8) -> 0 | H8: =IFERROR(R8/G8,0) -> 0 | I8: =IFERROR(P8/G8,0) -> 0 | J8: ="周"&WEEKDAY(A8,2) -> 周1 | K8: =SUMIFS(广告数据包!H:H,广告数据包!A:A,A8,广告数据包!G:G,Base!$F$2)+SUMIFS(广告数据包!H:H,广告数据包!A:A,A8,广告数据包!G:G,Base!$F$3)+SUMIFS(广告数据包!H:H,广告数据包!A:A,A8,广告数据包!G:G,Base!$F$4) -> 0 | L8: =SUMIFS(广告数据包!I:I,广告数据包!A:A,A8,广告数据包!G:G,Base!$F$2)+SUMIFS(广告数据包!I:I,广告数据包!A:A,A8,广告数据包!G:G,Base!$F$3)+SUMIFS(广告数据包!I:I,广告数据包!A:A,A8,广告数据包!G:G,Base!$F$4) -> 0 | M8: =IFERROR(L8/K8,0) -> 0 | N8: =IFERROR(R8/L8,0) -> 0 | O8: =SUMIFS(广告数据包!P:P,广告数据包!A:A,A8,广告数据包!G:G,Base!$F$2)+SUMIFS(广告数据包!P:P,广告数据包!A:A,A8,广告数据包!G:G,Base!$F$3)+SUMIFS(广告数据包!P:P,广告数据包!A:A,A8,广告数据包!G:G,Base!$F$4) -> 0 | P8: =SUMIFS(广告数据包!M:M,广告数据包!A:A,A8,广告数据包!G:G,Base!$F$2)+SUMIFS(广告数据包!M:M,广告数据包!A:A,A8,广告数据包!G:G,Base!$F$3)+SUMIFS(广告数据包!M:M,广告数据包!A:A,A8,广告数据包!G:G,Base!$F$4) -> 0 | Q8: =IFERROR(O8/L8,0) -> 0 | R8: =SUMIFS(广告数据包!L:L,广告数据包!A:A,A8,广告数据包!G:G,Base!$F$2)+SUMIFS(广告数据包!L:L,广告数据包!A:A,A8,广告数据包!G:G,Base!$F$3)+SUMIFS(广告数据包!L:L,广告数据包!A:A,A8,广告数据包!G:G,Base!$F$4) -> 0 | S8: =IFERROR(R8/P8,0) -> 0
A9: 44446 | B9: =SUMIFS(销售数据包!F:F,销售数据包!A:A,A9,销售数据包!C:C,Base!$F$2)+SUMIFS(销售数据包!F:F,销售数据包!A:A,A9,销售数据包!C:C,Base!$F$3)+SUMIFS(销售数据包!F:F,销售数据包!A:A,A9,销售数据包!C:C,Base!$F$4) -> 0 | C9: =SUMIFS(销售数据包!K:K,销售数据包!A:A,A9,销售数据包!C:C,Base!$F$2)+SUMIFS(销售数据包!K:K,销售数据包!A:A,A9,销售数据包!C:C,Base!$F$3)+SUMIFS(销售数据包!K:K,销售数据包!A:A,A9,销售数据包!C:C,Base!$F$4) -> 0 | D9: =SUMIFS(销售数据包!Q:Q,销售数据包!A:A,A9,销售数据包!C:C,Base!$F$2)+SUMIFS(销售数据包!Q:Q,销售数据包!A:A,A9,销售数据包!C:C,Base!$F$3)+SUMIFS(销售数据包!Q:Q,销售数据包!A:A,A9,销售数据包!C:C,Base!$F$4) -> 0 | E9: =IFERROR(D9/B9,0) -> 0 | F9: =IFERROR(C9/B9,0) -> 0 | G9: =SUMIFS(销售数据包!O:O,销售数据包!A:A,A9) -> 0 | H9: =IFERROR(R9/G9,0) -> 0 | I9: =IFERROR(P9/G9,0) -> 0 | J9: ="周"&WEEKDAY(A9,2) -> 周2 | K9: =SUMIFS(广告数据包!H:H,广告数据包!A:A,A9,广告数据包!G:G,Base!$F$2)+SUMIFS(广告数据包!H:H,广告数据包!A:A,A9,广告数据包!G:G,Base!$F$3)+SUMIFS(广告数据包!H:H,广告数据包!A:A,A9,广告数据包!G:G,Base!$F$4) -> 0 | L9: =SUMIFS(广告数据包!I:I,广告数据包!A:A,A9,广告数据包!G:G,Base!$F$2)+SUMIFS(广告数据包!I:I,广告数据包!A:A,A9,广告数据包!G:G,Base!$F$3)+SUMIFS(广告数据包!I:I,广告数据包!A:A,A9,广告数据包!G:G,Base!$F$4) -> 0 | M9: =IFERROR(L9/K9,0) -> 0 | N9: =IFERROR(R9/L9,0) -> 0 | O9: =SUMIFS(广告数据包!P:P,广告数据包!A:A,A9,广告数据包!G:G,Base!$F$2)+SUMIFS(广告数据包!P:P,广告数据包!A:A,A9,广告数据包!G:G,Base!$F$3)+SUMIFS(广告数据包!P:P,广告数据包!A:A,A9,广告数据包!G:G,Base!$F$4) -> 0 | P9: =SUMIFS(广告数据包!M:M,广告数据包!A:A,A9,广告数据包!G:G,Base!$F$2)+SUMIFS(广告数据包!M:M,广告数据包!A:A,A9,广告数据包!G:G,Base!$F$3)+SUMIFS(广告数据包!M:M,广告数据包!A:A,A9,广告数据包!G:G,Base!$F$4) -> 0 | Q9: =IFERROR(O9/L9,0) -> 0 | R9: =SUMIFS(广告数据包!L:L,广告数据包!A:A,A9,广告数据包!G:G,Base!$F$2)+SUMIFS(广告数据包!L:L,广告数据包!A:A,A9,广告数据包!G:G,Base!$F$3)+SUMIFS(广告数据包!L:L,广告数据包!A:A,A9,广告数据包!G:G,Base!$F$4) -> 0 | S9: =IFERROR(R9/P9,0) -> 0
A10: 44447 | B10: =SUMIFS(销售数据包!F:F,销售数据包!A:A,A10,销售数据包!C:C,Base!$F$2)+SUMIFS(销售数据包!F:F,销售数据包!A:A,A10,销售数据包!C:C,Base!$F$3)+SUMIFS(销售数据包!F:F,销售数据包!A:A,A10,销售数据包!C:C,Base!$F$4) -> 0 | C10: =SUMIFS(销售数据包!K:K,销售数据包!A:A,A10,销售数据包!C:C,Base!$F$2)+SUMIFS(销售数据包!K:K,销售数据包!A:A,A10,销售数据包!C:C,Base!$F$3)+SUMIFS(销售数据包!K:K,销售数据包!A:A,A10,销售数据包!C:C,Base!$F$4) -> 0 | D10: =SUMIFS(销售数据包!Q:Q,销售数据包!A:A,A10,销售数据包!C:C,Base!$F$2)+SUMIFS(销售数据包!Q:Q,销售数据包!A:A,A10,销售数据包!C:C,Base!$F$3)+SUMIFS(销售数据包!Q:Q,销售数据包!A:A,A10,销售数据包!C:C,Base!$F$4) -> 0 | E10: =IFERROR(D10/B10,0) -> 0 | F10: =IFERROR(C10/B10,0) -> 0 | G10: =SUMIFS(销售数据包!O:O,销售数据包!A:A,A10) -> 0 | H10: =IFERROR(R10/G10,0) -> 0 | I10: =IFERROR(P10/G10,0) -> 0 | J10: ="周"&WEEKDAY(A10,2) -> 周3 | K10: =SUMIFS(广告数据包!H:H,广告数据包!A:A,A10,广告数据包!G:G,Base!$F$2)+SUMIFS(广告数据包!H:H,广告数据包!A:A,A10,广告数据包!G:G,Base!$F$3)+SUMIFS(广告数据包!H:H,广告数据包!A:A,A10,广告数据包!G:G,Base!$F$4) -> 0 | L10: =SUMIFS(广告数据包!I:I,广告数据包!A:A,A10,广告数据包!G:G,Base!$F$2)+SUMIFS(广告数据包!I:I,广告数据包!A:A,A10,广告数据包!G:G,Base!$F$3)+SUMIFS(广告数据包!I:I,广告数据包!A:A,A10,广告数据包!G:G,Base!$F$4) -> 0 | M10: =IFERROR(L10/K10,0) -> 0 | N10: =IFERROR(R10/L10,0) -> 0 | O10: =SUMIFS(广告数据包!P:P,广告数据包!A:A,A10,广告数据包!G:G,Base!$F$2)+SUMIFS(广告数据包!P:P,广告数据包!A:A,A10,广告数据包!G:G,Base!$F$3)+SUMIFS(广告数据包!P:P,广告数据包!A:A,A10,广告数据包!G:G,Base!$F$4) -> 0 | P10: =SUMIFS(广告数据包!M:M,广告数据包!A:A,A10,广告数据包!G:G,Base!$F$2)+SUMIFS(广告数据包!M:M,广告数据包!A:A,A10,广告数据包!G:G,Base!$F$3)+SUMIFS(广告数据包!M:M,广告数据包!A:A,A10,广告数据包!G:G,Base!$F$4) -> 0 | Q10: =IFERROR(O10/L10,0) -> 0 | R10: =SUMIFS(广告数据包!L:L,广告数据包!A:A,A10,广告数据包!G:G,Base!$F$2)+SUMIFS(广告数据包!L:L,广告数据包!A:A,A10,广告数据包!G:G,Base!$F$3)+SUMIFS(广告数据包!L:L,广告数据包!A:A,A10,广告数据包!G:G,Base!$F$4) -> 0 | S10: =IFERROR(R10/P10,0) -> 0
A11: 44448 | B11: =SUMIFS(销售数据包!F:F,销售数据包!A:A,A11,销售数据包!C:C,Base!$F$2)+SUMIFS(销售数据包!F:F,销售数据包!A:A,A11,销售数据包!C:C,Base!$F$3)+SUMIFS(销售数据包!F:F,销售数据包!A:A,A11,销售数据包!C:C,Base!$F$4) -> 0 | C11: =SUMIFS(销售数据包!K:K,销售数据包!A:A,A11,销售数据包!C:C,Base!$F$2)+SUMIFS(销售数据包!K:K,销售数据包!A:A,A11,销售数据包!C:C,Base!$F$3)+SUMIFS(销售数据包!K:K,销售数据包!A:A,A11,销售数据包!C:C,Base!$F$4) -> 0 | D11: =SUMIFS(销售数据包!Q:Q,销售数据包!A:A,A11,销售数据包!C:C,Base!$F$2)+SUMIFS(销售数据包!Q:Q,销售数据包!A:A,A11,销售数据包!C:C,Base!$F$3)+SUMIFS(销售数据包!Q:Q,销售数据包!A:A,A11,销售数据包!C:C,Base!$F$4) -> 0 | E11: =IFERROR(D11/B11,0) -> 0 | F11: =IFERROR(C11/B11,0) -> 0 | G11: =SUMIFS(销售数据包!O:O,销售数据包!A:A,A11) -> 0 | H11: =IFERROR(R11/G11,0) -> 0 | I11: =IFERROR(P11/G11,0) -> 0 | J11: ="周"&WEEKDAY(A11,2) -> 周4 | K11: =SUMIFS(广告数据包!H:H,广告数据包!A:A,A11,广告数据包!G:G,Base!$F$2)+SUMIFS(广告数据包!H:H,广告数据包!A:A,A11,广告数据包!G:G,Base!$F$3)+SUMIFS(广告数据包!H:H,广告数据包!A:A,A11,广告数据包!G:G,Base!$F$4) -> 0 | L11: =SUMIFS(广告数据包!I:I,广告数据包!A:A,A11,广告数据包!G:G,Base!$F$2)+SUMIFS(广告数据包!I:I,广告数据包!A:A,A11,广告数据包!G:G,Base!$F$3)+SUMIFS(广告数据包!I:I,广告数据包!A:A,A11,广告数据包!G:G,Base!$F$4) -> 0 | M11: =IFERROR(L11/K11,0) -> 0 | N11: =IFERROR(R11/L11,0) -> 0 | O11: =SUMIFS(广告数据包!P:P,广告数据包!A:A,A11,广告数据包!G:G,Base!$F$2)+SUMIFS(广告数据包!P:P,广告数据包!A:A,A11,广告数据包!G:G,Base!$F$3)+SUMIFS(广告数据包!P:P,广告数据包!A:A,A11,广告数据包!G:G,Base!$F$4) -> 0 | P11: =SUMIFS(广告数据包!M:M,广告数据包!A:A,A11,广告数据包!G:G,Base!$F$2)+SUMIFS(广告数据包!M:M,广告数据包!A:A,A11,广告数据包!G:G,Base!$F$3)+SUMIFS(广告数据包!M:M,广告数据包!A:A,A11,广告数据包!G:G,Base!$F$4) -> 0 | Q11: =IFERROR(O11/L11,0) -> 0 | R11: =SUMIFS(广告数据包!L:L,广告数据包!A:A,A11,广告数据包!G:G,Base!$F$2)+SUMIFS(广告数据包!L:L,广告数据包!A:A,A11,广告数据包!G:G,Base!$F$3)+SUMIFS(广告数据包!L:L,广告数据包!A:A,A11,广告数据包!G:G,Base!$F$4) -> 0 | S11: =IFERROR(R11/P11,0) -> 0
A12: 44449 | B12: =SUMIFS(销售数据包!F:F,销售数据包!A:A,A12,销售数据包!C:C,Base!$F$2)+SUMIFS(销售数据包!F:F,销售数据包!A:A,A12,销售数据包!C:C,Base!$F$3)+SUMIFS(销售数据包!F:F,销售数据包!A:A,A12,销售数据包!C:C,Base!$F$4) -> 0 | C12: =SUMIFS(销售数据包!K:K,销售数据包!A:A,A12,销售数据包!C:C,Base!$F$2)+SUMIFS(销售数据包!K:K,销售数据包!A:A,A12,销售数据包!C:C,Base!$F$3)+SUMIFS(销售数据包!K:K,销售数据包!A:A,A12,销售数据包!C:C,Base!$F$4) -> 0 | D12: =SUMIFS(销售数据包!Q:Q,销售数据包!A:A,A12,销售数据包!C:C,Base!$F$2)+SUMIFS(销售数据包!Q:Q,销售数据包!A:A,A12,销售数据包!C:C,Base!$F$3)+SUMIFS(销售数据包!Q:Q,销售数据包!A:A,A12,销售数据包!C:C,Base!$F$4) -> 0 | E12: =IFERROR(D12/B12,0) -> 0 | F12: =IFERROR(C12/B12,0) -> 0 | G12: =SUMIFS(销售数据包!O:O,销售数据包!A:A,A12) -> 0 | H12: =IFERROR(R12/G12,0) -> 0 | I12: =IFERROR(P12/G12,0) -> 0 | J12: ="周"&WEEKDAY(A12,2) -> 周5 | K12: =SUMIFS(广告数据包!H:H,广告数据包!A:A,A12,广告数据包!G:G,Base!$F$2)+SUMIFS(广告数据包!H:H,广告数据包!A:A,A12,广告数据包!G:G,Base!$F$3)+SUMIFS(广告数据包!H:H,广告数据包!A:A,A12,广告数据包!G:G,Base!$F$4) -> 0 | L12: =SUMIFS(广告数据包!I:I,广告数据包!A:A,A12,广告数据包!G:G,Base!$F$2)+SUMIFS(广告数据包!I:I,广告数据包!A:A,A12,广告数据包!G:G,Base!$F$3)+SUMIFS(广告数据包!I:I,广告数据包!A:A,A12,广告数据包!G:G,Base!$F$4) -> 0 | M12: =IFERROR(L12/K12,0) -> 0 | N12: =IFERROR(R12/L12,0) -> 0 | O12: =SUMIFS(广告数据包!P:P,广告数据包!A:A,A12,广告数据包!G:G,Base!$F$2)+SUMIFS(广告数据包!P:P,广告数据包!A:A,A12,广告数据包!G:G,Base!$F$3)+SUMIFS(广告数据包!P:P,广告数据包!A:A,A12,广告数据包!G:G,Base!$F$4) -> 0 | P12: =SUMIFS(广告数据包!M:M,广告数据包!A:A,A12,广告数据包!G:G,Base!$F$2)+SUMIFS(广告数据包!M:M,广告数据包!A:A,A12,广告数据包!G:G,Base!$F$3)+SUMIFS(广告数据包!M:M,广告数据包!A:A,A12,广告数据包!G:G,Base!$F$4) -> 0 | Q12: =IFERROR(O12/L12,0) -> 0 | R12: =SUMIFS(广告数据包!L:L,广告数据包!A:A,A12,广告数据包!G:G,Base!$F$2)+SUMIFS(广告数据包!L:L,广告数据包!A:A,A12,广告数据包!G:G,Base!$F$3)+SUMIFS(广告数据包!L:L,广告数据包!A:A,A12,广告数据包!G:G,Base!$F$4) -> 0 | S12: =IFERROR(R12/P12,0) -> 0
A13: 44450 | B13: =SUMIFS(销售数据包!F:F,销售数据包!A:A,A13,销售数据包!C:C,Base!$F$2)+SUMIFS(销售数据包!F:F,销售数据包!A:A,A13,销售数据包!C:C,Base!$F$3)+SUMIFS(销售数据包!F:F,销售数据包!A:A,A13,销售数据包!C:C,Base!$F$4) -> 0 | C13: =SUMIFS(销售数据包!K:K,销售数据包!A:A,A13,销售数据包!C:C,Base!$F$2)+SUMIFS(销售数据包!K:K,销售数据包!A:A,A13,销售数据包!C:C,Base!$F$3)+SUMIFS(销售数据包!K:K,销售数据包!A:A,A13,销售数据包!C:C,Base!$F$4) -> 0 | D13: =SUMIFS(销售数据包!Q:Q,销售数据包!A:A,A13,销售数据包!C:C,Base!$F$2)+SUMIFS(销售数据包!Q:Q,销售数据包!A:A,A13,销售数据包!C:C,Base!$F$3)+SUMIFS(销售数据包!Q:Q,销售数据包!A:A,A13,销售数据包!C:C,Base!$F$4) -> 0 | E13: =IFERROR(D13/B13,0) -> 0 | F13: =IFERROR(C13/B13,0) -> 0 | G13: =SUMIFS(销售数据包!O:O,销售数据包!A:A,A13) -> 0 | H13: =IFERROR(R13/G13,0) -> 0 | I13: =IFERROR(P13/G13,0) -> 0 | J13: ="周"&WEEKDAY(A13,2) -> 周6 | K13: =SUMIFS(广告数据包!H:H,广告数据包!A:A,A13,广告数据包!G:G,Base!$F$2)+SUMIFS(广告数据包!H:H,广告数据包!A:A,A13,广告数据包!G:G,Base!$F$3)+SUMIFS(广告数据包!H:H,广告数据包!A:A,A13,广告数据包!G:G,Base!$F$4) -> 0 | L13: =SUMIFS(广告数据包!I:I,广告数据包!A:A,A13,广告数据包!G:G,Base!$F$2)+SUMIFS(广告数据包!I:I,广告数据包!A:A,A13,广告数据包!G:G,Base!$F$3)+SUMIFS(广告数据包!I:I,广告数据包!A:A,A13,广告数据包!G:G,Base!$F$4) -> 0 | M13: =IFERROR(L13/K13,0) -> 0 | N13: =IFERROR(R13/L13,0) -> 0 | O13: =SUMIFS(广告数据包!P:P,广告数据包!A:A,A13,广告数据包!G:G,Base!$F$2)+SUMIFS(广告数据包!P:P,广告数据包!A:A,A13,广告数据包!G:G,Base!$F$3)+SUMIFS(广告数据包!P:P,广告数据包!A:A,A13,广告数据包!G:G,Base!$F$4) -> 0 | P13: =SUMIFS(广告数据包!M:M,广告数据包!A:A,A13,广告数据包!G:G,Base!$F$2)+SUMIFS(广告数据包!M:M,广告数据包!A:A,A13,广告数据包!G:G,Base!$F$3)+SUMIFS(广告数据包!M:M,广告数据包!A:A,A13,广告数据包!G:G,Base!$F$4) -> 0 | Q13: =IFERROR(O13/L13,0) -> 0 | R13: =SUMIFS(广告数据包!L:L,广告数据包!A:A,A13,广告数据包!G:G,Base!$F$2)+SUMIFS(广告数据包!L:L,广告数据包!A:A,A13,广告数据包!G:G,Base!$F$3)+SUMIFS(广告数据包!L:L,广告数据包!A:A,A13,广告数据包!G:G,Base!$F$4) -> 0 | S13: =IFERROR(R13/P13,0) -> 0
A14: 44451 | B14: =SUMIFS(销售数据包!F:F,销售数据包!A:A,A14,销售数据包!C:C,Base!$F$2)+SUMIFS(销售数据包!F:F,销售数据包!A:A,A14,销售数据包!C:C,Base!$F$3)+SUMIFS(销售数据包!F:F,销售数据包!A:A,A14,销售数据包!C:C,Base!$F$4) -> 0 | C14: =SUMIFS(销售数据包!K:K,销售数据包!A:A,A14,销售数据包!C:C,Base!$F$2)+SUMIFS(销售数据包!K:K,销售数据包!A:A,A14,销售数据包!C:C,Base!$F$3)+SUMIFS(销售数据包!K:K,销售数据包!A:A,A14,销售数据包!C:C,Base!$F$4) -> 0 | D14: =SUMIFS(销售数据包!Q:Q,销售数据包!A:A,A14,销售数据包!C:C,Base!$F$2)+SUMIFS(销售数据包!Q:Q,销售数据包!A:A,A14,销售数据包!C:C,Base!$F$3)+SUMIFS(销售数据包!Q:Q,销售数据包!A:A,A14,销售数据包!C:C,Base!$F$4) -> 0 | E14: =IFERROR(D14/B14,0) -> 0 | F14: =IFERROR(C14/B14,0) -> 0 | G14: =SUMIFS(销售数据包!O:O,销售数据包!A:A,A14) -> 0 | H14: =IFERROR(R14/G14,0) -> 0 | I14: =IFERROR(P14/G14,0) -> 0 | J14: ="周"&WEEKDAY(A14,2) -> 周7 | K14: =SUMIFS(广告数据包!H:H,广告数据包!A:A,A14,广告数据包!G:G,Base!$F$2)+SUMIFS(广告数据包!H:H,广告数据包!A:A,A14,广告数据包!G:G,Base!$F$3)+SUMIFS(广告数据包!H:H,广告数据包!A:A,A14,广告数据包!G:G,Base!$F$4) -> 0 | L14: =SUMIFS(广告数据包!I:I,广告数据包!A:A,A14,广告数据包!G:G,Base!$F$2)+SUMIFS(广告数据包!I:I,广告数据包!A:A,A14,广告数据包!G:G,Base!$F$3)+SUMIFS(广告数据包!I:I,广告数据包!A:A,A14,广告数据包!G:G,Base!$F$4) -> 0 | M14: =IFERROR(L14/K14,0) -> 0 | N14: =IFERROR(R14/L14,0) -> 0 | O14: =SUMIFS(广告数据包!P:P,广告数据包!A:A,A14,广告数据包!G:G,Base!$F$2)+SUMIFS(广告数据包!P:P,广告数据包!A:A,A14,广告数据包!G:G,Base!$F$3)+SUMIFS(广告数据包!P:P,广告数据包!A:A,A14,广告数据包!G:G,Base!$F$4) -> 0 | P14: =SUMIFS(广告数据包!M:M,广告数据包!A:A,A14,广告数据包!G:G,Base!$F$2)+SUMIFS(广告数据包!M:M,广告数据包!A:A,A14,广告数据包!G:G,Base!$F$3)+SUMIFS(广告数据包!M:M,广告数据包!A:A,A14,广告数据包!G:G,Base!$F$4) -> 0 | Q14: =IFERROR(O14/L14,0) -> 0 | R14: =SUMIFS(广告数据包!L:L,广告数据包!A:A,A14,广告数据包!G:G,Base!$F$2)+SUMIFS(广告数据包!L:L,广告数据包!A:A,A14,广告数据包!G:G,Base!$F$3)+SUMIFS(广告数据包!L:L,广告数据包!A:A,A14,广告数据包!G:G,Base!$F$4) -> 0 | S14: =IFERROR(R14/P14,0) -> 0
... A305: 44742 | B305: =SUMIFS(销售数据包!F:F,销售数据包!A:A,A305,销售数据包!C:C,Base!$F$2)+SUMIFS(销售数据包!F:F,销售数据包!A:A,A305,销售数据包!C:C,Base!$F$3)+SUMIFS(销售数据包!F:F,销售数据包!A:A,A305,销售数据包!C:C,Base!$F$4) -> 0 | C305: =SUMIFS(销售数据包!K:K,销售数据包!A:A,A305,销售数据包!C:C,Base!$F$2)+SUMIFS(销售数据包!K:K,销售数据包!A:A,A305,销售数据包!C:C,Base!$F$3)+SUMIFS(销售数据包!K:K,销售数据包!A:A,A305,销售数据包!C:C,Base!$F$4) -> 0 | D305: =SUMIFS(销售数据包!Q:Q,销售数据包!A:A,A305,销售数据包!C:C,Base!$F$2)+SUMIFS(销售数据包!Q:Q,销售数据包!A:A,A305,销售数据包!C:C,Base!$F$3)+SUMIFS(销售数据包!Q:Q,销售数据包!A:A,A305,销售数据包!C:C,Base!$F$4) -> 0 | E305: =IFERROR(D305/B305,0) -> 0 | F305: =IFERROR(C305/B305,0) -> 0 | G305: =SUMIFS(销售数据包!O:O,销售数据包!A:A,A305) -> 0 | H305: =IFERROR(R305/G305,0) -> 0 | I305: =IFERROR(P305/G305,0) -> 0 | J305: ="周"&WEEKDAY(A305,2) -> 周4 | K305: =SUMIFS(广告数据包!H:H,广告数据包!A:A,A305,广告数据包!G:G,Base!$F$2)+SUMIFS(广告数据包!H:H,广告数据包!A:A,A305,广告数据包!G:G,Base!$F$3)+SUMIFS(广告数据包!H:H,广告数据包!A:A,A305,广告数据包!G:G,Base!$F$4) -> 0 | L305: =SUMIFS(广告数据包!I:I,广告数据包!A:A,A305,广告数据包!G:G,Base!$F$2)+SUMIFS(广告数据包!I:I,广告数据包!A:A,A305,广告数据包!G:G,Base!$F$3)+SUMIFS(广告数据包!I:I,广告数据包!A:A,A305,广告数据包!G:G,Base!$F$4) -> 0 | M305: =IFERROR(L305/K305,0) -> 0 | N305: =IFERROR(R305/L305,0) -> 0 | O305: =SUMIFS(广告数据包!P:P,广告数据包!A:A,A305,广告数据包!G:G,Base!$F$2)+SUMIFS(广告数据包!P:P,广告数据包!A:A,A305,广告数据包!G:G,Base!$F$3)+SUMIFS(广告数据包!P:P,广告数据包!A:A,A305,广告数据包!G:G,Base!$F$4) -> 0 | P305: =SUMIFS(广告数据包!M:M,广告数据包!A:A,A305,广告数据包!G:G,Base!$F$2)+SUMIFS(广告数据包!M:M,广告数据包!A:A,A305,广告数据包!G:G,Base!$F$3)+SUMIFS(广告数据包!M:M,广告数据包!A:A,A305,广告数据包!G:G,Base!$F$4) -> 0 | Q305: =IFERROR(O305/L305,0) -> 0 | R305: =SUMIFS(广告数据包!L:L,广告数据包!A:A,A305,广告数据包!G:G,Base!$F$2)+SUMIFS(广告数据包!L:L,广告数据包!A:A,A305,广告数据包!G:G,Base!$F$3)+SUMIFS(广告数据包!L:L,广告数据包!A:A,A305,广告数据包!G:G,Base!$F$4) -> 0 | S305: =IFERROR(R305/P305,0) -> 0

Sheet 父表 
A1: 年份 | B1: 2022 | C1: 月分析表-父表
A2: 月份 | B2: 1
A3: 整体数据 | K3: 广告数据
A4: 日期 | B4: 访客数 | C4: 销量 | D4: 订单数 | E4: 访客转化率 | F4: 转化率 | G4: 销售额 | H4: 总ACOS | I4: 广告销售比 | J4: 星期 | K4: Impressions | L4: Click | M4: CTR | N4: CPC | O4: Order | P4: Sales | Q4: CR | R4: Spend | S4: ACOS
A5: =DATE($B$1,$B$2,1) -> 44562 | B5: =SUMIFS(销售数据包!F:F,销售数据包!A:A,A5,销售数据包!C:C,Base!$F$2)+SUMIFS(销售数据包!F:F,销售数据包!A:A,A5,销售数据包!C:C,Base!$F$3)+SUMIFS(销售数据包!F:F,销售数据包!A:A,A5,销售数据包!C:C,Base!$F$4) -> 0 | C5: =SUMIFS(销售数据包!K:K,销售数据包!A:A,A5,销售数据包!C:C,Base!$F$2)+SUMIFS(销售数据包!K:K,销售数据包!A:A,A5,销售数据包!C:C,Base!$F$3)+SUMIFS(销售数据包!K:K,销售数据包!A:A,A5,销售数据包!C:C,Base!$F$4) -> 0 | D5: =SUMIFS(销售数据包!Q:Q,销售数据包!A:A,A5,销售数据包!C:C,Base!$F$2)+SUMIFS(销售数据包!Q:Q,销售数据包!A:A,A5,销售数据包!C:C,Base!$F$3)+SUMIFS(销售数据包!Q:Q,销售数据包!A:A,A5,销售数据包!C:C,Base!$F$4) -> 0 | E5: =IFERROR(D5/B5,0) -> 0 | F5: =IFERROR(C5/B5,0) -> 0 | G5: =SUMIFS(销售数据包!O:O,销售数据包!A:A,A5) -> 0 | H5: =IFERROR(R5/G5,0) -> 0 | I5: =IFERROR(P5/G5,0) -> 0 | J5: ="周"&WEEKDAY(A5,2) -> 周6 | K5: =SUMIFS(广告数据包!H:H,广告数据包!A:A,A5,广告数据包!G:G,Base!$F$2)+SUMIFS(广告数据包!H:H,广告数据包!A:A,A5,广告数据包!G:G,Base!$F$3)+SUMIFS(广告数据包!H:H,广告数据包!A:A,A5,广告数据包!G:G,Base!$F$4) -> 0 | L5: =SUMIFS(广告数据包!I:I,广告数据包!A:A,A5,广告数据包!G:G,Base!$F$2)+SUMIFS(广告数据包!I:I,广告数据包!A:A,A5,广告数据包!G:G,Base!$F$3)+SUMIFS(广告数据包!I:I,广告数据包!A:A,A5,广告数据包!G:G,Base!$F$4) -> 0 | M5: =IFERROR(L5/K5,0) -> 0 | N5: =IFERROR(R5/L5,0) -> 0 | O5: =SUMIFS(广告数据包!P:P,广告数据包!A:A,A5,广告数据包!G:G,Base!$F$2)+SUMIFS(广告数据包!P:P,广告数据包!A:A,A5,广告数据包!G:G,Base!$F$3)+SUMIFS(广告数据包!P:P,广告数据包!A:A,A5,广告数据包!G:G,Base!$F$4) -> 0 | P5: =SUMIFS(广告数据包!M:M,广告数据包!A:A,A5,广告数据包!G:G,Base!$F$2)+SUMIFS(广告数据包!M:M,广告数据包!A:A,A5,广告数据包!G:G,Base!$F$3)+SUMIFS(广告数据包!M:M,广告数据包!A:A,A5,广告数据包!G:G,Base!$F$4) -> 0 | Q5: =IFERROR(O5/L5,0) -> 0 | R5: =SUMIFS(广告数据包!L:L,广告数据包!A:A,A5,广告数据包!G:G,Base!$F$2)+SUMIFS(广告数据包!L:L,广告数据包!A:A,A5,广告数据包!G:G,Base!$F$3)+SUMIFS(广告数据包!L:L,广告数据包!A:A,A5,广告数据包!G:G,Base!$F$4) -> 0 | S5: =IFERROR(R5/P5,0) -> 0
A6: =DATE($B$1,$B$2,DAY(A5)+1) -> 44563 | B6: =SUMIFS(销售数据包!F:F,销售数据包!A:A,A6,销售数据包!C:C,Base!$F$2)+SUMIFS(销售数据包!F:F,销售数据包!A:A,A6,销售数据包!C:C,Base!$F$3)+SUMIFS(销售数据包!F:F,销售数据包!A:A,A6,销售数据包!C:C,Base!$F$4) -> 0 | C6: =SUMIFS(销售数据包!K:K,销售数据包!A:A,A6,销售数据包!C:C,Base!$F$2)+SUMIFS(销售数据包!K:K,销售数据包!A:A,A6,销售数据包!C:C,Base!$F$3)+SUMIFS(销售数据包!K:K,销售数据包!A:A,A6,销售数据包!C:C,Base!$F$4) -> 0 | D6: =SUMIFS(销售数据包!Q:Q,销售数据包!A:A,A6,销售数据包!C:C,Base!$F$2)+SUMIFS(销售数据包!Q:Q,销售数据包!A:A,A6,销售数据包!C:C,Base!$F$3)+SUMIFS(销售数据包!Q:Q,销售数据包!A:A,A6,销售数据包!C:C,Base!$F$4) -> 0 | E6: =IFERROR(D6/B6,0) -> 0 | F6: =IFERROR(C6/B6,0) -> 0 | G6: =SUMIFS(销售数据包!O:O,销售数据包!A:A,A6) -> 0 | H6: =IFERROR(R6/G6,0) -> 0 | I6: =IFERROR(P6/G6,0) -> 0 | J6: ="周"&WEEKDAY(A6,2) -> 周7 | K6: =SUMIFS(广告数据包!H:H,广告数据包!A:A,A6,广告数据包!G:G,Base!$F$2)+SUMIFS(广告数据包!H:H,广告数据包!A:A,A6,广告数据包!G:G,Base!$F$3)+SUMIFS(广告数据包!H:H,广告数据包!A:A,A6,广告数据包!G:G,Base!$F$4) -> 0 | L6: =SUMIFS(广告数据包!I:I,广告数据包!A:A,A6,广告数据包!G:G,Base!$F$2)+SUMIFS(广告数据包!I:I,广告数据包!A:A,A6,广告数据包!G:G,Base!$F$3)+SUMIFS(广告数据包!I:I,广告数据包!A:A,A6,广告数据包!G:G,Base!$F$4) -> 0 | M6: =IFERROR(L6/K6,0) -> 0 | N6: =IFERROR(R6/L6,0) -> 0 | O6: =SUMIFS(广告数据包!P:P,广告数据包!A:A,A6,广告数据包!G:G,Base!$F$2)+SUMIFS(广告数据包!P:P,广告数据包!A:A,A6,广告数据包!G:G,Base!$F$3)+SUMIFS(广告数据包!P:P,广告数据包!A:A,A6,广告数据包!G:G,Base!$F$4) -> 0 | P6: =SUMIFS(广告数据包!M:M,广告数据包!A:A,A6,广告数据包!G:G,Base!$F$2)+SUMIFS(广告数据包!M:M,广告数据包!A:A,A6,广告数据包!G:G,Base!$F$3)+SUMIFS(广告数据包!M:M,广告数据包!A:A,A6,广告数据包!G:G,Base!$F$4) -> 0 | Q6: =IFERROR(O6/L6,0) -> 0 | R6: =SUMIFS(广告数据包!L:L,广告数据包!A:A,A6,广告数据包!G:G,Base!$F$2)+SUMIFS(广告数据包!L:L,广告数据包!A:A,A6,广告数据包!G:G,Base!$F$3)+SUMIFS(广告数据包!L:L,广告数据包!A:A,A6,广告数据包!G:G,Base!$F$4) -> 0 | S6: =IFERROR(R6/P6,0) -> 0
A7: =DATE($B$1,$B$2,DAY(A6)+1) -> 44564 | B7: =SUMIFS(销售数据包!F:F,销售数据包!A:A,A7,销售数据包!C:C,Base!$F$2)+SUMIFS(销售数据包!F:F,销售数据包!A:A,A7,销售数据包!C:C,Base!$F$3)+SUMIFS(销售数据包!F:F,销售数据包!A:A,A7,销售数据包!C:C,Base!$F$4) -> 0 | C7: =SUMIFS(销售数据包!K:K,销售数据包!A:A,A7,销售数据包!C:C,Base!$F$2)+SUMIFS(销售数据包!K:K,销售数据包!A:A,A7,销售数据包!C:C,Base!$F$3)+SUMIFS(销售数据包!K:K,销售数据包!A:A,A7,销售数据包!C:C,Base!$F$4) -> 0 | D7: =SUMIFS(销售数据包!Q:Q,销售数据包!A:A,A7,销售数据包!C:C,Base!$F$2)+SUMIFS(销售数据包!Q:Q,销售数据包!A:A,A7,销售数据包!C:C,Base!$F$3)+SUMIFS(销售数据包!Q:Q,销售数据包!A:A,A7,销售数据包!C:C,Base!$F$4) -> 0 | E7: =IFERROR(D7/B7,0) -> 0 | F7: =IFERROR(C7/B7,0) -> 0 | G7: =SUMIFS(销售数据包!O:O,销售数据包!A:A,A7) -> 0 | H7: =IFERROR(R7/G7,0) -> 0 | I7: =IFERROR(P7/G7,0) -> 0 | J7: ="周"&WEEKDAY(A7,2) -> 周1 | K7: =SUMIFS(广告数据包!H:H,广告数据包!A:A,A7,广告数据包!G:G,Base!$F$2)+SUMIFS(广告数据包!H:H,广告数据包!A:A,A7,广告数据包!G:G,Base!$F$3)+SUMIFS(广告数据包!H:H,广告数据包!A:A,A7,广告数据包!G:G,Base!$F$4) -> 0 | L7: =SUMIFS(广告数据包!I:I,广告数据包!A:A,A7,广告数据包!G:G,Base!$F$2)+SUMIFS(广告数据包!I:I,广告数据包!A:A,A7,广告数据包!G:G,Base!$F$3)+SUMIFS(广告数据包!I:I,广告数据包!A:A,A7,广告数据包!G:G,Base!$F$4) -> 0 | M7: =IFERROR(L7/K7,0) -> 0 | N7: =IFERROR(R7/L7,0) -> 0 | O7: =SUMIFS(广告数据包!P:P,广告数据包!A:A,A7,广告数据包!G:G,Base!$F$2)+SUMIFS(广告数据包!P:P,广告数据包!A:A,A7,广告数据包!G:G,Base!$F$3)+SUMIFS(广告数据包!P:P,广告数据包!A:A,A7,广告数据包!G:G,Base!$F$4) -> 0 | P7: =SUMIFS(广告数据包!M:M,广告数据包!A:A,A7,广告数据包!G:G,Base!$F$2)+SUMIFS(广告数据包!M:M,广告数据包!A:A,A7,广告数据包!G:G,Base!$F$3)+SUMIFS(广告数据包!M:M,广告数据包!A:A,A7,广告数据包!G:G,Base!$F$4) -> 0 | Q7: =IFERROR(O7/L7,0) -> 0 | R7: =SUMIFS(广告数据包!L:L,广告数据包!A:A,A7,广告数据包!G:G,Base!$F$2)+SUMIFS(广告数据包!L:L,广告数据包!A:A,A7,广告数据包!G:G,Base!$F$3)+SUMIFS(广告数据包!L:L,广告数据包!A:A,A7,广告数据包!G:G,Base!$F$4) -> 0 | S7: =IFERROR(R7/P7,0) -> 0
A8: =DATE($B$1,$B$2,DAY(A7)+1) -> 44565 | B8: =SUMIFS(销售数据包!F:F,销售数据包!A:A,A8,销售数据包!C:C,Base!$F$2)+SUMIFS(销售数据包!F:F,销售数据包!A:A,A8,销售数据包!C:C,Base!$F$3)+SUMIFS(销售数据包!F:F,销售数据包!A:A,A8,销售数据包!C:C,Base!$F$4) -> 0 | C8: =SUMIFS(销售数据包!K:K,销售数据包!A:A,A8,销售数据包!C:C,Base!$F$2)+SUMIFS(销售数据包!K:K,销售数据包!A:A,A8,销售数据包!C:C,Base!$F$3)+SUMIFS(销售数据包!K:K,销售数据包!A:A,A8,销售数据包!C:C,Base!$F$4) -> 0 | D8: =SUMIFS(销售数据包!Q:Q,销售数据包!A:A,A8,销售数据包!C:C,Base!$F$2)+SUMIFS(销售数据包!Q:Q,销售数据包!A:A,A8,销售数据包!C:C,Base!$F$3)+SUMIFS(销售数据包!Q:Q,销售数据包!A:A,A8,销售数据包!C:C,Base!$F$4) -> 0 | E8: =IFERROR(D8/B8,0) -> 0 | F8: =IFERROR(C8/B8,0) -> 0 | G8: =SUMIFS(销售数据包!O:O,销售数据包!A:A,A8) -> 0 | H8: =IFERROR(R8/G8,0) -> 0 | I8: =IFERROR(P8/G8,0) -> 0 | J8: ="周"&WEEKDAY(A8,2) -> 周2 | K8: =SUMIFS(广告数据包!H:H,广告数据包!A:A,A8,广告数据包!G:G,Base!$F$2)+SUMIFS(广告数据包!H:H,广告数据包!A:A,A8,广告数据包!G:G,Base!$F$3)+SUMIFS(广告数据包!H:H,广告数据包!A:A,A8,广告数据包!G:G,Base!$F$4) -> 0 | L8: =SUMIFS(广告数据包!I:I,广告数据包!A:A,A8,广告数据包!G:G,Base!$F$2)+SUMIFS(广告数据包!I:I,广告数据包!A:A,A8,广告数据包!G:G,Base!$F$3)+SUMIFS(广告数据包!I:I,广告数据包!A:A,A8,广告数据包!G:G,Base!$F$4) -> 0 | M8: =IFERROR(L8/K8,0) -> 0 | N8: =IFERROR(R8/L8,0) -> 0 | O8: =SUMIFS(广告数据包!P:P,广告数据包!A:A,A8,广告数据包!G:G,Base!$F$2)+SUMIFS(广告数据包!P:P,广告数据包!A:A,A8,广告数据包!G:G,Base!$F$3)+SUMIFS(广告数据包!P:P,广告数据包!A:A,A8,广告数据包!G:G,Base!$F$4) -> 0 | P8: =SUMIFS(广告数据包!M:M,广告数据包!A:A,A8,广告数据包!G:G,Base!$F$2)+SUMIFS(广告数据包!M:M,广告数据包!A:A,A8,广告数据包!G:G,Base!$F$3)+SUMIFS(广告数据包!M:M,广告数据包!A:A,A8,广告数据包!G:G,Base!$F$4) -> 0 | Q8: =IFERROR(O8/L8,0) -> 0 | R8: =SUMIFS(广告数据包!L:L,广告数据包!A:A,A8,广告数据包!G:G,Base!$F$2)+SUMIFS(广告数据包!L:L,广告数据包!A:A,A8,广告数据包!G:G,Base!$F$3)+SUMIFS(广告数据包!L:L,广告数据包!A:A,A8,广告数据包!G:G,Base!$F$4) -> 0 | S8: =IFERROR(R8/P8,0) -> 0
A9: =DATE($B$1,$B$2,DAY(A8)+1) -> 44566 | B9: =SUMIFS(销售数据包!F:F,销售数据包!A:A,A9,销售数据包!C:C,Base!$F$2)+SUMIFS(销售数据包!F:F,销售数据包!A:A,A9,销售数据包!C:C,Base!$F$3)+SUMIFS(销售数据包!F:F,销售数据包!A:A,A9,销售数据包!C:C,Base!$F$4) -> 0 | C9: =SUMIFS(销售数据包!K:K,销售数据包!A:A,A9,销售数据包!C:C,Base!$F$2)+SUMIFS(销售数据包!K:K,销售数据包!A:A,A9,销售数据包!C:C,Base!$F$3)+SUMIFS(销售数据包!K:K,销售数据包!A:A,A9,销售数据包!C:C,Base!$F$4) -> 0 | D9: =SUMIFS(销售数据包!Q:Q,销售数据包!A:A,A9,销售数据包!C:C,Base!$F$2)+SUMIFS(销售数据包!Q:Q,销售数据包!A:A,A9,销售数据包!C:C,Base!$F$3)+SUMIFS(销售数据包!Q:Q,销售数据包!A:A,A9,销售数据包!C:C,Base!$F$4) -> 0 | E9: =IFERROR(D9/B9,0) -> 0 | F9: =IFERROR(C9/B9,0) -> 0 | G9: =SUMIFS(销售数据包!O:O,销售数据包!A:A,A9) -> 0 | H9: =IFERROR(R9/G9,0) -> 0 | I9: =IFERROR(P9/G9,0) -> 0 | J9: ="周"&WEEKDAY(A9,2) -> 周3 | K9: =SUMIFS(广告数据包!H:H,广告数据包!A:A,A9,广告数据包!G:G,Base!$F$2)+SUMIFS(广告数据包!H:H,广告数据包!A:A,A9,广告数据包!G:G,Base!$F$3)+SUMIFS(广告数据包!H:H,广告数据包!A:A,A9,广告数据包!G:G,Base!$F$4) -> 0 | L9: =SUMIFS(广告数据包!I:I,广告数据包!A:A,A9,广告数据包!G:G,Base!$F$2)+SUMIFS(广告数据包!I:I,广告数据包!A:A,A9,广告数据包!G:G,Base!$F$3)+SUMIFS(广告数据包!I:I,广告数据包!A:A,A9,广告数据包!G:G,Base!$F$4) -> 0 | M9: =IFERROR(L9/K9,0) -> 0 | N9: =IFERROR(R9/L9,0) -> 0 | O9: =SUMIFS(广告数据包!P:P,广告数据包!A:A,A9,广告数据包!G:G,Base!$F$2)+SUMIFS(广告数据包!P:P,广告数据包!A:A,A9,广告数据包!G:G,Base!$F$3)+SUMIFS(广告数据包!P:P,广告数据包!A:A,A9,广告数据包!G:G,Base!$F$4) -> 0 | P9: =SUMIFS(广告数据包!M:M,广告数据包!A:A,A9,广告数据包!G:G,Base!$F$2)+SUMIFS(广告数据包!M:M,广告数据包!A:A,A9,广告数据包!G:G,Base!$F$3)+SUMIFS(广告数据包!M:M,广告数据包!A:A,A9,广告数据包!G:G,Base!$F$4) -> 0 | Q9: =IFERROR(O9/L9,0) -> 0 | R9: =SUMIFS(广告数据包!L:L,广告数据包!A:A,A9,广告数据包!G:G,Base!$F$2)+SUMIFS(广告数据包!L:L,广告数据包!A:A,A9,广告数据包!G:G,Base!$F$3)+SUMIFS(广告数据包!L:L,广告数据包!A:A,A9,广告数据包!G:G,Base!$F$4) -> 0 | S9: =IFERROR(R9/P9,0) -> 0
A10: =DATE($B$1,$B$2,DAY(A9)+1) -> 44567 | B10: =SUMIFS(销售数据包!F:F,销售数据包!A:A,A10,销售数据包!C:C,Base!$F$2)+SUMIFS(销售数据包!F:F,销售数据包!A:A,A10,销售数据包!C:C,Base!$F$3)+SUMIFS(销售数据包!F:F,销售数据包!A:A,A10,销售数据包!C:C,Base!$F$4) -> 0 | C10: =SUMIFS(销售数据包!K:K,销售数据包!A:A,A10,销售数据包!C:C,Base!$F$2)+SUMIFS(销售数据包!K:K,销售数据包!A:A,A10,销售数据包!C:C,Base!$F$3)+SUMIFS(销售数据包!K:K,销售数据包!A:A,A10,销售数据包!C:C,Base!$F$4) -> 0 | D10: =SUMIFS(销售数据包!Q:Q,销售数据包!A:A,A10,销售数据包!C:C,Base!$F$2)+SUMIFS(销售数据包!Q:Q,销售数据包!A:A,A10,销售数据包!C:C,Base!$F$3)+SUMIFS(销售数据包!Q:Q,销售数据包!A:A,A10,销售数据包!C:C,Base!$F$4) -> 0 | E10: =IFERROR(D10/B10,0) -> 0 | F10: =IFERROR(C10/B10,0) -> 0 | G10: =SUMIFS(销售数据包!O:O,销售数据包!A:A,A10) -> 0 | H10: =IFERROR(R10/G10,0) -> 0 | I10: =IFERROR(P10/G10,0) -> 0 | J10: ="周"&WEEKDAY(A10,2) -> 周4 | K10: =SUMIFS(广告数据包!H:H,广告数据包!A:A,A10,广告数据包!G:G,Base!$F$2)+SUMIFS(广告数据包!H:H,广告数据包!A:A,A10,广告数据包!G:G,Base!$F$3)+SUMIFS(广告数据包!H:H,广告数据包!A:A,A10,广告数据包!G:G,Base!$F$4) -> 0 | L10: =SUMIFS(广告数据包!I:I,广告数据包!A:A,A10,广告数据包!G:G,Base!$F$2)+SUMIFS(广告数据包!I:I,广告数据包!A:A,A10,广告数据包!G:G,Base!$F$3)+SUMIFS(广告数据包!I:I,广告数据包!A:A,A10,广告数据包!G:G,Base!$F$4) -> 0 | M10: =IFERROR(L10/K10,0) -> 0 | N10: =IFERROR(R10/L10,0) -> 0 | O10: =SUMIFS(广告数据包!P:P,广告数据包!A:A,A10,广告数据包!G:G,Base!$F$2)+SUMIFS(广告数据包!P:P,广告数据包!A:A,A10,广告数据包!G:G,Base!$F$3)+SUMIFS(广告数据包!P:P,广告数据包!A:A,A10,广告数据包!G:G,Base!$F$4) -> 0 | P10: =SUMIFS(广告数据包!M:M,广告数据包!A:A,A10,广告数据包!G:G,Base!$F$2)+SUMIFS(广告数据包!M:M,广告数据包!A:A,A10,广告数据包!G:G,Base!$F$3)+SUMIFS(广告数据包!M:M,广告数据包!A:A,A10,广告数据包!G:G,Base!$F$4) -> 0 | Q10: =IFERROR(O10/L10,0) -> 0 | R10: =SUMIFS(广告数据包!L:L,广告数据包!A:A,A10,广告数据包!G:G,Base!$F$2)+SUMIFS(广告数据包!L:L,广告数据包!A:A,A10,广告数据包!G:G,Base!$F$3)+SUMIFS(广告数据包!L:L,广告数据包!A:A,A10,广告数据包!G:G,Base!$F$4) -> 0 | S10: =IFERROR(R10/P10,0) -> 0
A11: =DATE($B$1,$B$2,DAY(A10)+1) -> 44568 | B11: =SUMIFS(销售数据包!F:F,销售数据包!A:A,A11,销售数据包!C:C,Base!$F$2)+SUMIFS(销售数据包!F:F,销售数据包!A:A,A11,销售数据包!C:C,Base!$F$3)+SUMIFS(销售数据包!F:F,销售数据包!A:A,A11,销售数据包!C:C,Base!$F$4) -> 0 | C11: =SUMIFS(销售数据包!K:K,销售数据包!A:A,A11,销售数据包!C:C,Base!$F$2)+SUMIFS(销售数据包!K:K,销售数据包!A:A,A11,销售数据包!C:C,Base!$F$3)+SUMIFS(销售数据包!K:K,销售数据包!A:A,A11,销售数据包!C:C,Base!$F$4) -> 0 | D11: =SUMIFS(销售数据包!Q:Q,销售数据包!A:A,A11,销售数据包!C:C,Base!$F$2)+SUMIFS(销售数据包!Q:Q,销售数据包!A:A,A11,销售数据包!C:C,Base!$F$3)+SUMIFS(销售数据包!Q:Q,销售数据包!A:A,A11,销售数据包!C:C,Base!$F$4) -> 0 | E11: =IFERROR(D11/B11,0) -> 0 | F11: =IFERROR(C11/B11,0) -> 0 | G11: =SUMIFS(销售数据包!O:O,销售数据包!A:A,A11) -> 0 | H11: =IFERROR(R11/G11,0) -> 0 | I11: =IFERROR(P11/G11,0) -> 0 | J11: ="周"&WEEKDAY(A11,2) -> 周5 | K11: =SUMIFS(广告数据包!H:H,广告数据包!A:A,A11,广告数据包!G:G,Base!$F$2)+SUMIFS(广告数据包!H:H,广告数据包!A:A,A11,广告数据包!G:G,Base!$F$3)+SUMIFS(广告数据包!H:H,广告数据包!A:A,A11,广告数据包!G:G,Base!$F$4) -> 0 | L11: =SUMIFS(广告数据包!I:I,广告数据包!A:A,A11,广告数据包!G:G,Base!$F$2)+SUMIFS(广告数据包!I:I,广告数据包!A:A,A11,广告数据包!G:G,Base!$F$3)+SUMIFS(广告数据包!I:I,广告数据包!A:A,A11,广告数据包!G:G,Base!$F$4) -> 0 | M11: =IFERROR(L11/K11,0) -> 0 | N11: =IFERROR(R11/L11,0) -> 0 | O11: =SUMIFS(广告数据包!P:P,广告数据包!A:A,A11,广告数据包!G:G,Base!$F$2)+SUMIFS(广告数据包!P:P,广告数据包!A:A,A11,广告数据包!G:G,Base!$F$3)+SUMIFS(广告数据包!P:P,广告数据包!A:A,A11,广告数据包!G:G,Base!$F$4) -> 0 | P11: =SUMIFS(广告数据包!M:M,广告数据包!A:A,A11,广告数据包!G:G,Base!$F$2)+SUMIFS(广告数据包!M:M,广告数据包!A:A,A11,广告数据包!G:G,Base!$F$3)+SUMIFS(广告数据包!M:M,广告数据包!A:A,A11,广告数据包!G:G,Base!$F$4) -> 0 | Q11: =IFERROR(O11/L11,0) -> 0 | R11: =SUMIFS(广告数据包!L:L,广告数据包!A:A,A11,广告数据包!G:G,Base!$F$2)+SUMIFS(广告数据包!L:L,广告数据包!A:A,A11,广告数据包!G:G,Base!$F$3)+SUMIFS(广告数据包!L:L,广告数据包!A:A,A11,广告数据包!G:G,Base!$F$4) -> 0 | S11: =IFERROR(R11/P11,0) -> 0
A12: =DATE($B$1,$B$2,DAY(A11)+1) -> 44569 | B12: =SUMIFS(销售数据包!F:F,销售数据包!A:A,A12,销售数据包!C:C,Base!$F$2)+SUMIFS(销售数据包!F:F,销售数据包!A:A,A12,销售数据包!C:C,Base!$F$3)+SUMIFS(销售数据包!F:F,销售数据包!A:A,A12,销售数据包!C:C,Base!$F$4) -> 0 | C12: =SUMIFS(销售数据包!K:K,销售数据包!A:A,A12,销售数据包!C:C,Base!$F$2)+SUMIFS(销售数据包!K:K,销售数据包!A:A,A12,销售数据包!C:C,Base!$F$3)+SUMIFS(销售数据包!K:K,销售数据包!A:A,A12,销售数据包!C:C,Base!$F$4) -> 0 | D12: =SUMIFS(销售数据包!Q:Q,销售数据包!A:A,A12,销售数据包!C:C,Base!$F$2)+SUMIFS(销售数据包!Q:Q,销售数据包!A:A,A12,销售数据包!C:C,Base!$F$3)+SUMIFS(销售数据包!Q:Q,销售数据包!A:A,A12,销售数据包!C:C,Base!$F$4) -> 0 | E12: =IFERROR(D12/B12,0) -> 0 | F12: =IFERROR(C12/B12,0) -> 0 | G12: =SUMIFS(销售数据包!O:O,销售数据包!A:A,A12) -> 0 | H12: =IFERROR(R12/G12,0) -> 0 | I12: =IFERROR(P12/G12,0) -> 0 | J12: ="周"&WEEKDAY(A12,2) -> 周6 | K12: =SUMIFS(广告数据包!H:H,广告数据包!A:A,A12,广告数据包!G:G,Base!$F$2)+SUMIFS(广告数据包!H:H,广告数据包!A:A,A12,广告数据包!G:G,Base!$F$3)+SUMIFS(广告数据包!H:H,广告数据包!A:A,A12,广告数据包!G:G,Base!$F$4) -> 0 | L12: =SUMIFS(广告数据包!I:I,广告数据包!A:A,A12,广告数据包!G:G,Base!$F$2)+SUMIFS(广告数据包!I:I,广告数据包!A:A,A12,广告数据包!G:G,Base!$F$3)+SUMIFS(广告数据包!I:I,广告数据包!A:A,A12,广告数据包!G:G,Base!$F$4) -> 0 | M12: =IFERROR(L12/K12,0) -> 0 | N12: =IFERROR(R12/L12,0) -> 0 | O12: =SUMIFS(广告数据包!P:P,广告数据包!A:A,A12,广告数据包!G:G,Base!$F$2)+SUMIFS(广告数据包!P:P,广告数据包!A:A,A12,广告数据包!G:G,Base!$F$3)+SUMIFS(广告数据包!P:P,广告数据包!A:A,A12,广告数据包!G:G,Base!$F$4) -> 0 | P12: =SUMIFS(广告数据包!M:M,广告数据包!A:A,A12,广告数据包!G:G,Base!$F$2)+SUMIFS(广告数据包!M:M,广告数据包!A:A,A12,广告数据包!G:G,Base!$F$3)+SUMIFS(广告数据包!M:M,广告数据包!A:A,A12,广告数据包!G:G,Base!$F$4) -> 0 | Q12: =IFERROR(O12/L12,0) -> 0 | R12: =SUMIFS(广告数据包!L:L,广告数据包!A:A,A12,广告数据包!G:G,Base!$F$2)+SUMIFS(广告数据包!L:L,广告数据包!A:A,A12,广告数据包!G:G,Base!$F$3)+SUMIFS(广告数据包!L:L,广告数据包!A:A,A12,广告数据包!G:G,Base!$F$4) -> 0 | S12: =IFERROR(R12/P12,0) -> 0
A13: =DATE($B$1,$B$2,DAY(A12)+1) -> 44570 | B13: =SUMIFS(销售数据包!F:F,销售数据包!A:A,A13,销售数据包!C:C,Base!$F$2)+SUMIFS(销售数据包!F:F,销售数据包!A:A,A13,销售数据包!C:C,Base!$F$3)+SUMIFS(销售数据包!F:F,销售数据包!A:A,A13,销售数据包!C:C,Base!$F$4) -> 0 | C13: =SUMIFS(销售数据包!K:K,销售数据包!A:A,A13,销售数据包!C:C,Base!$F$2)+SUMIFS(销售数据包!K:K,销售数据包!A:A,A13,销售数据包!C:C,Base!$F$3)+SUMIFS(销售数据包!K:K,销售数据包!A:A,A13,销售数据包!C:C,Base!$F$4) -> 0 | D13: =SUMIFS(销售数据包!Q:Q,销售数据包!A:A,A13,销售数据包!C:C,Base!$F$2)+SUMIFS(销售数据包!Q:Q,销售数据包!A:A,A13,销售数据包!C:C,Base!$F$3)+SUMIFS(销售数据包!Q:Q,销售数据包!A:A,A13,销售数据包!C:C,Base!$F$4) -> 0 | E13: =IFERROR(D13/B13,0) -> 0 | F13: =IFERROR(C13/B13,0) -> 0 | G13: =SUMIFS(销售数据包!O:O,销售数据包!A:A,A13) -> 0 | H13: =IFERROR(R13/G13,0) -> 0 | I13: =IFERROR(P13/G13,0) -> 0 | J13: ="周"&WEEKDAY(A13,2) -> 周7 | K13: =SUMIFS(广告数据包!H:H,广告数据包!A:A,A13,广告数据包!G:G,Base!$F$2)+SUMIFS(广告数据包!H:H,广告数据包!A:A,A13,广告数据包!G:G,Base!$F$3)+SUMIFS(广告数据包!H:H,广告数据包!A:A,A13,广告数据包!G:G,Base!$F$4) -> 0 | L13: =SUMIFS(广告数据包!I:I,广告数据包!A:A,A13,广告数据包!G:G,Base!$F$2)+SUMIFS(广告数据包!I:I,广告数据包!A:A,A13,广告数据包!G:G,Base!$F$3)+SUMIFS(广告数据包!I:I,广告数据包!A:A,A13,广告数据包!G:G,Base!$F$4) -> 0 | M13: =IFERROR(L13/K13,0) -> 0 | N13: =IFERROR(R13/L13,0) -> 0 | O13: =SUMIFS(广告数据包!P:P,广告数据包!A:A,A13,广告数据包!G:G,Base!$F$2)+SUMIFS(广告数据包!P:P,广告数据包!A:A,A13,广告数据包!G:G,Base!$F$3)+SUMIFS(广告数据包!P:P,广告数据包!A:A,A13,广告数据包!G:G,Base!$F$4) -> 0 | P13: =SUMIFS(广告数据包!M:M,广告数据包!A:A,A13,广告数据包!G:G,Base!$F$2)+SUMIFS(广告数据包!M:M,广告数据包!A:A,A13,广告数据包!G:G,Base!$F$3)+SUMIFS(广告数据包!M:M,广告数据包!A:A,A13,广告数据包!G:G,Base!$F$4) -> 0 | Q13: =IFERROR(O13/L13,0) -> 0 | R13: =SUMIFS(广告数据包!L:L,广告数据包!A:A,A13,广告数据包!G:G,Base!$F$2)+SUMIFS(广告数据包!L:L,广告数据包!A:A,A13,广告数据包!G:G,Base!$F$3)+SUMIFS(广告数据包!L:L,广告数据包!A:A,A13,广告数据包!G:G,Base!$F$4) -> 0 | S13: =IFERROR(R13/P13,0) -> 0
A14: =DATE($B$1,$B$2,DAY(A13)+1) -> 44571 | B14: =SUMIFS(销售数据包!F:F,销售数据包!A:A,A14,销售数据包!C:C,Base!$F$2)+SUMIFS(销售数据包!F:F,销售数据包!A:A,A14,销售数据包!C:C,Base!$F$3)+SUMIFS(销售数据包!F:F,销售数据包!A:A,A14,销售数据包!C:C,Base!$F$4) -> 0 | C14: =SUMIFS(销售数据包!K:K,销售数据包!A:A,A14,销售数据包!C:C,Base!$F$2)+SUMIFS(销售数据包!K:K,销售数据包!A:A,A14,销售数据包!C:C,Base!$F$3)+SUMIFS(销售数据包!K:K,销售数据包!A:A,A14,销售数据包!C:C,Base!$F$4) -> 0 | D14: =SUMIFS(销售数据包!Q:Q,销售数据包!A:A,A14,销售数据包!C:C,Base!$F$2)+SUMIFS(销售数据包!Q:Q,销售数据包!A:A,A14,销售数据包!C:C,Base!$F$3)+SUMIFS(销售数据包!Q:Q,销售数据包!A:A,A14,销售数据包!C:C,Base!$F$4) -> 0 | E14: =IFERROR(D14/B14,0) -> 0 | F14: =IFERROR(C14/B14,0) -> 0 | G14: =SUMIFS(销售数据包!O:O,销售数据包!A:A,A14) -> 0 | H14: =IFERROR(R14/G14,0) -> 0 | I14: =IFERROR(P14/G14,0) -> 0 | J14: ="周"&WEEKDAY(A14,2) -> 周1 | K14: =SUMIFS(广告数据包!H:H,广告数据包!A:A,A14,广告数据包!G:G,Base!$F$2)+SUMIFS(广告数据包!H:H,广告数据包!A:A,A14,广告数据包!G:G,Base!$F$3)+SUMIFS(广告数据包!H:H,广告数据包!A:A,A14,广告数据包!G:G,Base!$F$4) -> 0 | L14: =SUMIFS(广告数据包!I:I,广告数据包!A:A,A14,广告数据包!G:G,Base!$F$2)+SUMIFS(广告数据包!I:I,广告数据包!A:A,A14,广告数据包!G:G,Base!$F$3)+SUMIFS(广告数据包!I:I,广告数据包!A:A,A14,广告数据包!G:G,Base!$F$4) -> 0 | M14: =IFERROR(L14/K14,0) -> 0 | N14: =IFERROR(R14/L14,0) -> 0 | O14: =SUMIFS(广告数据包!P:P,广告数据包!A:A,A14,广告数据包!G:G,Base!$F$2)+SUMIFS(广告数据包!P:P,广告数据包!A:A,A14,广告数据包!G:G,Base!$F$3)+SUMIFS(广告数据包!P:P,广告数据包!A:A,A14,广告数据包!G:G,Base!$F$4) -> 0 | P14: =SUMIFS(广告数据包!M:M,广告数据包!A:A,A14,广告数据包!G:G,Base!$F$2)+SUMIFS(广告数据包!M:M,广告数据包!A:A,A14,广告数据包!G:G,Base!$F$3)+SUMIFS(广告数据包!M:M,广告数据包!A:A,A14,广告数据包!G:G,Base!$F$4) -> 0 | Q14: =IFERROR(O14/L14,0) -> 0 | R14: =SUMIFS(广告数据包!L:L,广告数据包!A:A,A14,广告数据包!G:G,Base!$F$2)+SUMIFS(广告数据包!L:L,广告数据包!A:A,A14,广告数据包!G:G,Base!$F$3)+SUMIFS(广告数据包!L:L,广告数据包!A:A,A14,广告数据包!G:G,Base!$F$4) -> 0 | S14: =IFERROR(R14/P14,0) -> 0
A15: =DATE($B$1,$B$2,DAY(A14)+1) -> 44572 | B15: =SUMIFS(销售数据包!F:F,销售数据包!A:A,A15,销售数据包!C:C,Base!$F$2)+SUMIFS(销售数据包!F:F,销售数据包!A:A,A15,销售数据包!C:C,Base!$F$3)+SUMIFS(销售数据包!F:F,销售数据包!A:A,A15,销售数据包!C:C,Base!$F$4) -> 0 | C15: =SUMIFS(销售数据包!K:K,销售数据包!A:A,A15,销售数据包!C:C,Base!$F$2)+SUMIFS(销售数据包!K:K,销售数据包!A:A,A15,销售数据包!C:C,Base!$F$3)+SUMIFS(销售数据包!K:K,销售数据包!A:A,A15,销售数据包!C:C,Base!$F$4) -> 0 | D15: =SUMIFS(销售数据包!Q:Q,销售数据包!A:A,A15,销售数据包!C:C,Base!$F$2)+SUMIFS(销售数据包!Q:Q,销售数据包!A:A,A15,销售数据包!C:C,Base!$F$3)+SUMIFS(销售数据包!Q:Q,销售数据包!A:A,A15,销售数据包!C:C,Base!$F$4) -> 0 | E15: =IFERROR(D15/B15,0) -> 0 | F15: =IFERROR(C15/B15,0) -> 0 | G15: =SUMIFS(销售数据包!O:O,销售数据包!A:A,A15) -> 0 | H15: =IFERROR(R15/G15,0) -> 0 | I15: =IFERROR(P15/G15,0) -> 0 | J15: ="周"&WEEKDAY(A15,2) -> 周2 | K15: =SUMIFS(广告数据包!H:H,广告数据包!A:A,A15,广告数据包!G:G,Base!$F$2)+SUMIFS(广告数据包!H:H,广告数据包!A:A,A15,广告数据包!G:G,Base!$F$3)+SUMIFS(广告数据包!H:H,广告数据包!A:A,A15,广告数据包!G:G,Base!$F$4) -> 0 | L15: =SUMIFS(广告数据包!I:I,广告数据包!A:A,A15,广告数据包!G:G,Base!$F$2)+SUMIFS(广告数据包!I:I,广告数据包!A:A,A15,广告数据包!G:G,Base!$F$3)+SUMIFS(广告数据包!I:I,广告数据包!A:A,A15,广告数据包!G:G,Base!$F$4) -> 0 | M15: =IFERROR(L15/K15,0) -> 0 | N15: =IFERROR(R15/L15,0) -> 0 | O15: =SUMIFS(广告数据包!P:P,广告数据包!A:A,A15,广告数据包!G:G,Base!$F$2)+SUMIFS(广告数据包!P:P,广告数据包!A:A,A15,广告数据包!G:G,Base!$F$3)+SUMIFS(广告数据包!P:P,广告数据包!A:A,A15,广告数据包!G:G,Base!$F$4) -> 0 | P15: =SUMIFS(广告数据包!M:M,广告数据包!A:A,A15,广告数据包!G:G,Base!$F$2)+SUMIFS(广告数据包!M:M,广告数据包!A:A,A15,广告数据包!G:G,Base!$F$3)+SUMIFS(广告数据包!M:M,广告数据包!A:A,A15,广告数据包!G:G,Base!$F$4) -> 0 | Q15: =IFERROR(O15/L15,0) -> 0 | R15: =SUMIFS(广告数据包!L:L,广告数据包!A:A,A15,广告数据包!G:G,Base!$F$2)+SUMIFS(广告数据包!L:L,广告数据包!A:A,A15,广告数据包!G:G,Base!$F$3)+SUMIFS(广告数据包!L:L,广告数据包!A:A,A15,广告数据包!G:G,Base!$F$4) -> 0 | S15: =IFERROR(R15/P15,0) -> 0
A16: =DATE($B$1,$B$2,DAY(A15)+1) -> 44573 | B16: =SUMIFS(销售数据包!F:F,销售数据包!A:A,A16,销售数据包!C:C,Base!$F$2)+SUMIFS(销售数据包!F:F,销售数据包!A:A,A16,销售数据包!C:C,Base!$F$3)+SUMIFS(销售数据包!F:F,销售数据包!A:A,A16,销售数据包!C:C,Base!$F$4) -> 0 | C16: =SUMIFS(销售数据包!K:K,销售数据包!A:A,A16,销售数据包!C:C,Base!$F$2)+SUMIFS(销售数据包!K:K,销售数据包!A:A,A16,销售数据包!C:C,Base!$F$3)+SUMIFS(销售数据包!K:K,销售数据包!A:A,A16,销售数据包!C:C,Base!$F$4) -> 0 | D16: =SUMIFS(销售数据包!Q:Q,销售数据包!A:A,A16,销售数据包!C:C,Base!$F$2)+SUMIFS(销售数据包!Q:Q,销售数据包!A:A,A16,销售数据包!C:C,Base!$F$3)+SUMIFS(销售数据包!Q:Q,销售数据包!A:A,A16,销售数据包!C:C,Base!$F$4) -> 0 | E16: =IFERROR(D16/B16,0) -> 0 | F16: =IFERROR(C16/B16,0) -> 0 | G16: =SUMIFS(销售数据包!O:O,销售数据包!A:A,A16) -> 0 | H16: =IFERROR(R16/G16,0) -> 0 | I16: =IFERROR(P16/G16,0) -> 0 | J16: ="周"&WEEKDAY(A16,2) -> 周3 | K16: =SUMIFS(广告数据包!H:H,广告数据包!A:A,A16,广告数据包!G:G,Base!$F$2)+SUMIFS(广告数据包!H:H,广告数据包!A:A,A16,广告数据包!G:G,Base!$F$3)+SUMIFS(广告数据包!H:H,广告数据包!A:A,A16,广告数据包!G:G,Base!$F$4) -> 0 | L16: =SUMIFS(广告数据包!I:I,广告数据包!A:A,A16,广告数据包!G:G,Base!$F$2)+SUMIFS(广告数据包!I:I,广告数据包!A:A,A16,广告数据包!G:G,Base!$F$3)+SUMIFS(广告数据包!I:I,广告数据包!A:A,A16,广告数据包!G:G,Base!$F$4) -> 0 | M16: =IFERROR(L16/K16,0) -> 0 | N16: =IFERROR(R16/L16,0) -> 0 | O16: =SUMIFS(广告数据包!P:P,广告数据包!A:A,A16,广告数据包!G:G,Base!$F$2)+SUMIFS(广告数据包!P:P,广告数据包!A:A,A16,广告数据包!G:G,Base!$F$3)+SUMIFS(广告数据包!P:P,广告数据包!A:A,A16,广告数据包!G:G,Base!$F$4) -> 0 | P16: =SUMIFS(广告数据包!M:M,广告数据包!A:A,A16,广告数据包!G:G,Base!$F$2)+SUMIFS(广告数据包!M:M,广告数据包!A:A,A16,广告数据包!G:G,Base!$F$3)+SUMIFS(广告数据包!M:M,广告数据包!A:A,A16,广告数据包!G:G,Base!$F$4) -> 0 | Q16: =IFERROR(O16/L16,0) -> 0 | R16: =SUMIFS(广告数据包!L:L,广告数据包!A:A,A16,广告数据包!G:G,Base!$F$2)+SUMIFS(广告数据包!L:L,广告数据包!A:A,A16,广告数据包!G:G,Base!$F$3)+SUMIFS(广告数据包!L:L,广告数据包!A:A,A16,广告数据包!G:G,Base!$F$4) -> 0 | S16: =IFERROR(R16/P16,0) -> 0
A17: =DATE($B$1,$B$2,DAY(A16)+1) -> 44574 | B17: =SUMIFS(销售数据包!F:F,销售数据包!A:A,A17,销售数据包!C:C,Base!$F$2)+SUMIFS(销售数据包!F:F,销售数据包!A:A,A17,销售数据包!C:C,Base!$F$3)+SUMIFS(销售数据包!F:F,销售数据包!A:A,A17,销售数据包!C:C,Base!$F$4) -> 0 | C17: =SUMIFS(销售数据包!K:K,销售数据包!A:A,A17,销售数据包!C:C,Base!$F$2)+SUMIFS(销售数据包!K:K,销售数据包!A:A,A17,销售数据包!C:C,Base!$F$3)+SUMIFS(销售数据包!K:K,销售数据包!A:A,A17,销售数据包!C:C,Base!$F$4) -> 0 | D17: =SUMIFS(销售数据包!Q:Q,销售数据包!A:A,A17,销售数据包!C:C,Base!$F$2)+SUMIFS(销售数据包!Q:Q,销售数据包!A:A,A17,销售数据包!C:C,Base!$F$3)+SUMIFS(销售数据包!Q:Q,销售数据包!A:A,A17,销售数据包!C:C,Base!$F$4) -> 0 | E17: =IFERROR(D17/B17,0) -> 0 | F17: =IFERROR(C17/B17,0) -> 0 | G17: =SUMIFS(销售数据包!O:O,销售数据包!A:A,A17) -> 0 | H17: =IFERROR(R17/G17,0) -> 0 | I17: =IFERROR(P17/G17,0) -> 0 | J17: ="周"&WEEKDAY(A17,2) -> 周4 | K17: =SUMIFS(广告数据包!H:H,广告数据包!A:A,A17,广告数据包!G:G,Base!$F$2)+SUMIFS(广告数据包!H:H,广告数据包!A:A,A17,广告数据包!G:G,Base!$F$3)+SUMIFS(广告数据包!H:H,广告数据包!A:A,A17,广告数据包!G:G,Base!$F$4) -> 0 | L17: =SUMIFS(广告数据包!I:I,广告数据包!A:A,A17,广告数据包!G:G,Base!$F$2)+SUMIFS(广告数据包!I:I,广告数据包!A:A,A17,广告数据包!G:G,Base!$F$3)+SUMIFS(广告数据包!I:I,广告数据包!A:A,A17,广告数据包!G:G,Base!$F$4) -> 0 | M17: =IFERROR(L17/K17,0) -> 0 | N17: =IFERROR(R17/L17,0) -> 0 | O17: =SUMIFS(广告数据包!P:P,广告数据包!A:A,A17,广告数据包!G:G,Base!$F$2)+SUMIFS(广告数据包!P:P,广告数据包!A:A,A17,广告数据包!G:G,Base!$F$3)+SUMIFS(广告数据包!P:P,广告数据包!A:A,A17,广告数据包!G:G,Base!$F$4) -> 0 | P17: =SUMIFS(广告数据包!M:M,广告数据包!A:A,A17,广告数据包!G:G,Base!$F$2)+SUMIFS(广告数据包!M:M,广告数据包!A:A,A17,广告数据包!G:G,Base!$F$3)+SUMIFS(广告数据包!M:M,广告数据包!A:A,A17,广告数据包!G:G,Base!$F$4) -> 0 | Q17: =IFERROR(O17/L17,0) -> 0 | R17: =SUMIFS(广告数据包!L:L,广告数据包!A:A,A17,广告数据包!G:G,Base!$F$2)+SUMIFS(广告数据包!L:L,广告数据包!A:A,A17,广告数据包!G:G,Base!$F$3)+SUMIFS(广告数据包!L:L,广告数据包!A:A,A17,广告数据包!G:G,Base!$F$4) -> 0 | S17: =IFERROR(R17/P17,0) -> 0
... A32: =DATE($B$1,$B$2,DAY(A31)+1) -> 44589 | B32: =SUMIFS(销售数据包!F:F,销售数据包!A:A,A32,销售数据包!C:C,Base!$F$2)+SUMIFS(销售数据包!F:F,销售数据包!A:A,A32,销售数据包!C:C,Base!$F$3)+SUMIFS(销售数据包!F:F,销售数据包!A:A,A32,销售数据包!C:C,Base!$F$4) -> 0 | C32: =SUMIFS(销售数据包!K:K,销售数据包!A:A,A32,销售数据包!C:C,Base!$F$2)+SUMIFS(销售数据包!K:K,销售数据包!A:A,A32,销售数据包!C:C,Base!$F$3)+SUMIFS(销售数据包!K:K,销售数据包!A:A,A32,销售数据包!C:C,Base!$F$4) -> 0 | D32: =SUMIFS(销售数据包!Q:Q,销售数据包!A:A,A32,销售数据包!C:C,Base!$F$2)+SUMIFS(销售数据包!Q:Q,销售数据包!A:A,A32,销售数据包!C:C,Base!$F$3)+SUMIFS(销售数据包!Q:Q,销售数据包!A:A,A32,销售数据包!C:C,Base!$F$4) -> 0 | E32: =IFERROR(D32/B32,0) -> 0 | F32: =IFERROR(C32/B32,0) -> 0 | G32: =SUMIFS(销售数据包!O:O,销售数据包!A:A,A32) -> 0 | H32: =IFERROR(R32/G32,0) -> 0 | I32: =IFERROR(P32/G32,0) -> 0 | J32: ="周"&WEEKDAY(A32,2) -> 周5 | K32: =SUMIFS(广告数据包!H:H,广告数据包!A:A,A32,广告数据包!G:G,Base!$F$2)+SUMIFS(广告数据包!H:H,广告数据包!A:A,A32,广告数据包!G:G,Base!$F$3)+SUMIFS(广告数据包!H:H,广告数据包!A:A,A32,广告数据包!G:G,Base!$F$4) -> 0 | L32: =SUMIFS(广告数据包!I:I,广告数据包!A:A,A32,广告数据包!G:G,Base!$F$2)+SUMIFS(广告数据包!I:I,广告数据包!A:A,A32,广告数据包!G:G,Base!$F$3)+SUMIFS(广告数据包!I:I,广告数据包!A:A,A32,广告数据包!G:G,Base!$F$4) -> 0 | M32: =IFERROR(L32/K32,0) -> 0 | N32: =IFERROR(R32/L32,0) -> 0 | O32: =SUMIFS(广告数据包!P:P,广告数据包!A:A,A32,广告数据包!G:G,Base!$F$2)+SUMIFS(广告数据包!P:P,广告数据包!A:A,A32,广告数据包!G:G,Base!$F$3)+SUMIFS(广告数据包!P:P,广告数据包!A:A,A32,广告数据包!G:G,Base!$F$4) -> 0 | P32: =SUMIFS(广告数据包!M:M,广告数据包!A:A,A32,广告数据包!G:G,Base!$F$2)+SUMIFS(广告数据包!M:M,广告数据包!A:A,A32,广告数据包!G:G,Base!$F$3)+SUMIFS(广告数据包!M:M,广告数据包!A:A,A32,广告数据包!G:G,Base!$F$4) -> 0 | Q32: =IFERROR(O32/L32,0) -> 0 | R32: =SUMIFS(广告数据包!L:L,广告数据包!A:A,A32,广告数据包!G:G,Base!$F$2)+SUMIFS(广告数据包!L:L,广告数据包!A:A,A32,广告数据包!G:G,Base!$F$3)+SUMIFS(广告数据包!L:L,广告数据包!A:A,A32,广告数据包!G:G,Base!$F$4) -> 0 | S32: =IFERROR(R32/P32,0) -> 0
A33: =IFERROR(IF(MONTH(DATE($B$1,$B$2,DAY(A32)+1))=$B$2,DATE($B$1,$B$2,DAY(A32)+1),"-"),IFERROR(IF(FIND("-",A32,1)>0,"-",0),"其他")) -> 44590 | B33: =SUMIFS(销售数据包!F:F,销售数据包!A:A,A33,销售数据包!C:C,Base!$F$2)+SUMIFS(销售数据包!F:F,销售数据包!A:A,A33,销售数据包!C:C,Base!$F$3)+SUMIFS(销售数据包!F:F,销售数据包!A:A,A33,销售数据包!C:C,Base!$F$4) -> 0 | C33: =SUMIFS(销售数据包!K:K,销售数据包!A:A,A33,销售数据包!C:C,Base!$F$2)+SUMIFS(销售数据包!K:K,销售数据包!A:A,A33,销售数据包!C:C,Base!$F$3)+SUMIFS(销售数据包!K:K,销售数据包!A:A,A33,销售数据包!C:C,Base!$F$4) -> 0 | D33: =SUMIFS(销售数据包!Q:Q,销售数据包!A:A,A33,销售数据包!C:C,Base!$F$2)+SUMIFS(销售数据包!Q:Q,销售数据包!A:A,A33,销售数据包!C:C,Base!$F$3)+SUMIFS(销售数据包!Q:Q,销售数据包!A:A,A33,销售数据包!C:C,Base!$F$4) -> 0 | E33: =IFERROR(D33/B33,0) -> 0 | F33: =IFERROR(C33/B33,0) -> 0 | G33: =SUMIFS(销售数据包!O:O,销售数据包!A:A,A33) -> 0 | H33: =IFERROR(R33/G33,0) -> 0 | I33: =IFERROR(P33/G33,0) -> 0 | J33: =IFERROR("周"&WEEKDAY(A34,2),"-") -> 周7 | K33: =SUMIFS(广告数据包!H:H,广告数据包!A:A,A33,广告数据包!G:G,Base!$F$2)+SUMIFS(广告数据包!H:H,广告数据包!A:A,A33,广告数据包!G:G,Base!$F$3)+SUMIFS(广告数据包!H:H,广告数据包!A:A,A33,广告数据包!G:G,Base!$F$4) -> 0 | L33: =SUMIFS(广告数据包!I:I,广告数据包!A:A,A33,广告数据包!G:G,Base!$F$2)+SUMIFS(广告数据包!I:I,广告数据包!A:A,A33,广告数据包!G:G,Base!$F$3)+SUMIFS(广告数据包!I:I,广告数据包!A:A,A33,广告数据包!G:G,Base!$F$4) -> 0 | M33: =IFERROR(L33/K33,0) -> 0 | N33: =IFERROR(R33/L33,0) -> 0 | O33: =SUMIFS(广告数据包!P:P,广告数据包!A:A,A33,广告数据包!G:G,Base!$F$2)+SUMIFS(广告数据包!P:P,广告数据包!A:A,A33,广告数据包!G:G,Base!$F$3)+SUMIFS(广告数据包!P:P,广告数据包!A:A,A33,广告数据包!G:G,Base!$F$4) -> 0 | P33: =SUMIFS(广告数据包!M:M,广告数据包!A:A,A33,广告数据包!G:G,Base!$F$2)+SUMIFS(广告数据包!M:M,广告数据包!A:A,A33,广告数据包!G:G,Base!$F$3)+SUMIFS(广告数据包!M:M,广告数据包!A:A,A33,广告数据包!G:G,Base!$F$4) -> 0 | Q33: =IFERROR(O33/L33,0) -> 0 | R33: =SUMIFS(广告数据包!L:L,广告数据包!A:A,A33,广告数据包!G:G,Base!$F$2)+SUMIFS(广告数据包!L:L,广告数据包!A:A,A33,广告数据包!G:G,Base!$F$3)+SUMIFS(广告数据包!L:L,广告数据包!A:A,A33,广告数据包!G:G,Base!$F$4) -> 0 | S33: =IFERROR(R33/P33,0) -> 0
A34: =IFERROR(IF(MONTH(DATE($B$1,$B$2,DAY(A33)+1))=$B$2,DATE($B$1,$B$2,DAY(A33)+1),"-"),IFERROR(IF(FIND("-",A33,1)>0,"-",0),"其他")) -> 44591 | B34: =SUMIFS(销售数据包!F:F,销售数据包!A:A,A34,销售数据包!C:C,Base!$F$2)+SUMIFS(销售数据包!F:F,销售数据包!A:A,A34,销售数据包!C:C,Base!$F$3)+SUMIFS(销售数据包!F:F,销售数据包!A:A,A34,销售数据包!C:C,Base!$F$4) -> 0 | C34: =SUMIFS(销售数据包!K:K,销售数据包!A:A,A34,销售数据包!C:C,Base!$F$2)+SUMIFS(销售数据包!K:K,销售数据包!A:A,A34,销售数据包!C:C,Base!$F$3)+SUMIFS(销售数据包!K:K,销售数据包!A:A,A34,销售数据包!C:C,Base!$F$4) -> 0 | D34: =SUMIFS(销售数据包!Q:Q,销售数据包!A:A,A34,销售数据包!C:C,Base!$F$2)+SUMIFS(销售数据包!Q:Q,销售数据包!A:A,A34,销售数据包!C:C,Base!$F$3)+SUMIFS(销售数据包!Q:Q,销售数据包!A:A,A34,销售数据包!C:C,Base!$F$4) -> 0 | E34: =IFERROR(D34/B34,0) -> 0 | F34: =IFERROR(C34/B34,0) -> 0 | G34: =SUMIFS(销售数据包!O:O,销售数据包!A:A,A34) -> 0 | H34: =IFERROR(R34/G34,0) -> 0 | I34: =IFERROR(P34/G34,0) -> 0 | J34: =IFERROR("周"&WEEKDAY(A34,2),"-") -> 周7 | K34: =SUMIFS(广告数据包!H:H,广告数据包!A:A,A34,广告数据包!G:G,Base!$F$2)+SUMIFS(广告数据包!H:H,广告数据包!A:A,A34,广告数据包!G:G,Base!$F$3)+SUMIFS(广告数据包!H:H,广告数据包!A:A,A34,广告数据包!G:G,Base!$F$4) -> 0 | L34: =SUMIFS(广告数据包!I:I,广告数据包!A:A,A34,广告数据包!G:G,Base!$F$2)+SUMIFS(广告数据包!I:I,广告数据包!A:A,A34,广告数据包!G:G,Base!$F$3)+SUMIFS(广告数据包!I:I,广告数据包!A:A,A34,广告数据包!G:G,Base!$F$4) -> 0 | M34: =IFERROR(L34/K34,0) -> 0 | N34: =IFERROR(R34/L34,0) -> 0 | O34: =SUMIFS(广告数据包!P:P,广告数据包!A:A,A34,广告数据包!G:G,Base!$F$2)+SUMIFS(广告数据包!P:P,广告数据包!A:A,A34,广告数据包!G:G,Base!$F$3)+SUMIFS(广告数据包!P:P,广告数据包!A:A,A34,广告数据包!G:G,Base!$F$4) -> 0 | P34: =SUMIFS(广告数据包!M:M,广告数据包!A:A,A34,广告数据包!G:G,Base!$F$2)+SUMIFS(广告数据包!M:M,广告数据包!A:A,A34,广告数据包!G:G,Base!$F$3)+SUMIFS(广告数据包!M:M,广告数据包!A:A,A34,广告数据包!G:G,Base!$F$4) -> 0 | Q34: =IFERROR(O34/L34,0) -> 0 | R34: =SUMIFS(广告数据包!L:L,广告数据包!A:A,A34,广告数据包!G:G,Base!$F$2)+SUMIFS(广告数据包!L:L,广告数据包!A:A,A34,广告数据包!G:G,Base!$F$3)+SUMIFS(广告数据包!L:L,广告数据包!A:A,A34,广告数据包!G:G,Base!$F$4) -> 0 | S34: =IFERROR(R34/P34,0) -> 0
A35: =IFERROR(IF(MONTH(DATE($B$1,$B$2,DAY(A34)+1))=$B$2,DATE($B$1,$B$2,DAY(A34)+1),"-"),IFERROR(IF(FIND("-",A34,1)>0,"-",0),"其他")) -> 44592 | B35: =SUMIFS(销售数据包!F:F,销售数据包!A:A,A35,销售数据包!C:C,Base!$F$2)+SUMIFS(销售数据包!F:F,销售数据包!A:A,A35,销售数据包!C:C,Base!$F$3)+SUMIFS(销售数据包!F:F,销售数据包!A:A,A35,销售数据包!C:C,Base!$F$4) -> 0 | C35: =SUMIFS(销售数据包!K:K,销售数据包!A:A,A35,销售数据包!C:C,Base!$F$2)+SUMIFS(销售数据包!K:K,销售数据包!A:A,A35,销售数据包!C:C,Base!$F$3)+SUMIFS(销售数据包!K:K,销售数据包!A:A,A35,销售数据包!C:C,Base!$F$4) -> 0 | D35: =SUMIFS(销售数据包!Q:Q,销售数据包!A:A,A35,销售数据包!C:C,Base!$F$2)+SUMIFS(销售数据包!Q:Q,销售数据包!A:A,A35,销售数据包!C:C,Base!$F$3)+SUMIFS(销售数据包!Q:Q,销售数据包!A:A,A35,销售数据包!C:C,Base!$F$4) -> 0 | E35: =IFERROR(D35/B35,0) -> 0 | F35: =IFERROR(C35/B35,0) -> 0 | G35: =SUMIFS(销售数据包!O:O,销售数据包!A:A,A35) -> 0 | H35: =IFERROR(R35/G35,0) -> 0 | I35: =IFERROR(P35/G35,0) -> 0 | J35: =IFERROR("周"&WEEKDAY(A35,2),"-") -> 周1 | K35: =SUMIFS(广告数据包!H:H,广告数据包!A:A,A35,广告数据包!G:G,Base!$F$2)+SUMIFS(广告数据包!H:H,广告数据包!A:A,A35,广告数据包!G:G,Base!$F$3)+SUMIFS(广告数据包!H:H,广告数据包!A:A,A35,广告数据包!G:G,Base!$F$4) -> 0 | L35: =SUMIFS(广告数据包!I:I,广告数据包!A:A,A35,广告数据包!G:G,Base!$F$2)+SUMIFS(广告数据包!I:I,广告数据包!A:A,A35,广告数据包!G:G,Base!$F$3)+SUMIFS(广告数据包!I:I,广告数据包!A:A,A35,广告数据包!G:G,Base!$F$4) -> 0 | M35: =IFERROR(L35/K35,0) -> 0 | N35: =IFERROR(R35/L35,0) -> 0 | O35: =SUMIFS(广告数据包!P:P,广告数据包!A:A,A35,广告数据包!G:G,Base!$F$2)+SUMIFS(广告数据包!P:P,广告数据包!A:A,A35,广告数据包!G:G,Base!$F$3)+SUMIFS(广告数据包!P:P,广告数据包!A:A,A35,广告数据包!G:G,Base!$F$4) -> 0 | P35: =SUMIFS(广告数据包!M:M,广告数据包!A:A,A35,广告数据包!G:G,Base!$F$2)+SUMIFS(广告数据包!M:M,广告数据包!A:A,A35,广告数据包!G:G,Base!$F$3)+SUMIFS(广告数据包!M:M,广告数据包!A:A,A35,广告数据包!G:G,Base!$F$4) -> 0 | Q35: =IFERROR(O35/L35,0) -> 0 | R35: =SUMIFS(广告数据包!L:L,广告数据包!A:A,A35,广告数据包!G:G,Base!$F$2)+SUMIFS(广告数据包!L:L,广告数据包!A:A,A35,广告数据包!G:G,Base!$F$3)+SUMIFS(广告数据包!L:L,广告数据包!A:A,A35,广告数据包!G:G,Base!$F$4) -> 0 | S35: =IFERROR(R35/P35,0) -> 0
A36: =B2&"月份 汇总" -> 1月份 汇总 | B36: =SUM(B5:B35) -> 0 | C36: =SUM(C5:C35) -> 0 | D36: =SUM(D5:D35) -> 0 | E36: =IFERROR(D36/B36,0) -> 0 | F36: =IFERROR(C36/B36,0) -> 0 | G36: =SUM(G5:G35) -> 0 | H36: =IFERROR(R36/G36,0) -> 0 | I36: =IFERROR(P36/G36,0) -> 0 | J36: =IFERROR("周"&WEEKDAY(A36,2),"-") -> - | K36: =SUM(K5:K35) -> 0 | L36: =SUM(L5:L35) -> 0 | M36: =IFERROR(L36/K36,0) -> 0 | N36: =IFERROR(R36/L36,0) -> 0 | O36: =SUM(O5:O35) -> 0 | P36: =SUM(P5:P35) -> 0 | Q36: =IFERROR(O36/L36,0) -> 0 | R36: =SUM(R5:R35) -> 0 | S36: =IFERROR(R36/P36,0) -> 0

Sheet 子表
A1: 年份 | B1: 2022 | C1: ASIN | D1: 月分析表-子表
A2: 月份 | B2: 1 | C2: ASIN1
A3: 整体数据 | K3: 广告数据
A4: 日期 | B4: 访客数 | C4: 销量 | D4: 订单数 | E4: 访客转化率 | F4: 转化率 | G4: 销售额 | H4: 总ACOS | I4: 广告销售比 | J4: 星期 | K4: Impressions | L4: Click | M4: CTR | N4: CPC | O4: Order | P4: Sales | Q4: CR | R4: Spend | S4: ACOS
A5: =DATE($B$1,$B$2,1) -> 44562 | B5: =SUMIFS(销售数据包!F:F,销售数据包!A:A,A5,销售数据包!C:C,$C$2) -> 0 | C5: =SUMIFS(销售数据包!K:K,销售数据包!A:A,A5,销售数据包!C:C,$C$2) -> 0 | D5: =SUMIFS(销售数据包!Q:Q,销售数据包!A:A,A5,销售数据包!C:C,$C$2) -> 0 | E5: =IFERROR(D5/B5,0) -> 0 | F5: =IFERROR(C5/B5,0) -> 0 | G5: =SUMIFS(销售数据包!O:O,销售数据包!A:A,A5,销售数据包!C:C,$C$2) -> 0 | H5: =IFERROR(R5/G5,0) -> 0 | I5: =IFERROR(P5/G5,0) -> 0 | J5: ="周"&WEEKDAY(A5,2) -> 周6 | K5: =SUMIFS(广告数据包!H:H,广告数据包!A:A,A5,广告数据包!G:G,$C$2) -> 0 | L5: =SUMIFS(广告数据包!I:I,广告数据包!A:A,A5,广告数据包!G:G,$C$2) -> 0 | M5: =IFERROR(L5/K5,0) -> 0 | N5: =IFERROR(R5/L5,0) -> 0 | O5: =SUMIFS(广告数据包!P:P,广告数据包!A:A,A5,广告数据包!G:G,$C$2) -> 0 | P5: =SUMIFS(广告数据包!U:U,广告数据包!A:A,A5,广告数据包!G:G,$C$2) -> 0 | Q5: =IFERROR(O5/L5,0) -> 0 | R5: =SUMIFS(广告数据包!L:L,广告数据包!A:A,A5,广告数据包!G:G,$C$2) -> 0 | S5: =IFERROR(R5/P5,0) -> 0
A6: =DATE($B$1,$B$2,DAY(A5)+1) -> 44563 | B6: =SUMIFS(销售数据包!F:F,销售数据包!A:A,A6,销售数据包!C:C,$C$2) -> 0 | C6: =SUMIFS(销售数据包!K:K,销售数据包!A:A,A6,销售数据包!C:C,$C$2) -> 0 | D6: =SUMIFS(销售数据包!Q:Q,销售数据包!A:A,A6,销售数据包!C:C,$C$2) -> 0 | E6: =IFERROR(D6/B6,0) -> 0 | F6: =IFERROR(C6/B6,0) -> 0 | G6: =SUMIFS(销售数据包!O:O,销售数据包!A:A,A6,销售数据包!C:C,$C$2) -> 0 | H6: =IFERROR(R6/G6,0) -> 0 | I6: =IFERROR(P6/G6,0) -> 0 | J6: ="周"&WEEKDAY(A6,2) -> 周7 | K6: =SUMIFS(广告数据包!H:H,广告数据包!A:A,A6,广告数据包!G:G,$C$2) -> 0 | L6: =SUMIFS(广告数据包!I:I,广告数据包!A:A,A6,广告数据包!G:G,$C$2) -> 0 | M6: =IFERROR(L6/K6,0) -> 0 | N6: =IFERROR(R6/L6,0) -> 0 | O6: =SUMIFS(广告数据包!P:P,广告数据包!A:A,A6,广告数据包!G:G,$C$2) -> 0 | P6: =SUMIFS(广告数据包!U:U,广告数据包!A:A,A6,广告数据包!G:G,$C$2) -> 0 | Q6: =IFERROR(O6/L6,0) -> 0 | R6: =SUMIFS(广告数据包!L:L,广告数据包!A:A,A6,广告数据包!G:G,$C$2) -> 0 | S6: =IFERROR(R6/P6,0) -> 0
A7: =DATE($B$1,$B$2,DAY(A6)+1) -> 44564 | B7: =SUMIFS(销售数据包!F:F,销售数据包!A:A,A7,销售数据包!C:C,$C$2) -> 0 | C7: =SUMIFS(销售数据包!K:K,销售数据包!A:A,A7,销售数据包!C:C,$C$2) -> 0 | D7: =SUMIFS(销售数据包!Q:Q,销售数据包!A:A,A7,销售数据包!C:C,$C$2) -> 0 | E7: =IFERROR(D7/B7,0) -> 0 | F7: =IFERROR(C7/B7,0) -> 0 | G7: =SUMIFS(销售数据包!O:O,销售数据包!A:A,A7,销售数据包!C:C,$C$2) -> 0 | H7: =IFERROR(R7/G7,0) -> 0 | I7: =IFERROR(P7/G7,0) -> 0 | J7: ="周"&WEEKDAY(A7,2) -> 周1 | K7: =SUMIFS(广告数据包!H:H,广告数据包!A:A,A7,广告数据包!G:G,$C$2) -> 0 | L7: =SUMIFS(广告数据包!I:I,广告数据包!A:A,A7,广告数据包!G:G,$C$2) -> 0 | M7: =IFERROR(L7/K7,0) -> 0 | N7: =IFERROR(R7/L7,0) -> 0 | O7: =SUMIFS(广告数据包!P:P,广告数据包!A:A,A7,广告数据包!G:G,$C$2) -> 0 | P7: =SUMIFS(广告数据包!U:U,广告数据包!A:A,A7,广告数据包!G:G,$C$2) -> 0 | Q7: =IFERROR(O7/L7,0) -> 0 | R7: =SUMIFS(广告数据包!L:L,广告数据包!A:A,A7,广告数据包!G:G,$C$2) -> 0 | S7: =IFERROR(R7/P7,0) -> 0
A8: =DATE($B$1,$B$2,DAY(A7)+1) -> 44565 | B8: =SUMIFS(销售数据包!F:F,销售数据包!A:A,A8,销售数据包!C:C,$C$2) -> 0 | C8: =SUMIFS(销售数据包!K:K,销售数据包!A:A,A8,销售数据包!C:C,$C$2) -> 0 | D8: =SUMIFS(销售数据包!Q:Q,销售数据包!A:A,A8,销售数据包!C:C,$C$2) -> 0 | E8: =IFERROR(D8/B8,0) -> 0 | F8: =IFERROR(C8/B8,0) -> 0 | G8: =SUMIFS(销售数据包!O:O,销售数据包!A:A,A8,销售数据包!C:C,$C$2) -> 0 | H8: =IFERROR(R8/G8,0) -> 0 | I8: =IFERROR(P8/G8,0) -> 0 | J8: ="周"&WEEKDAY(A8,2) -> 周2 | K8: =SUMIFS(广告数据包!H:H,广告数据包!A:A,A8,广告数据包!G:G,$C$2) -> 0 | L8: =SUMIFS(广告数据包!I:I,广告数据包!A:A,A8,广告数据包!G:G,$C$2) -> 0 | M8: =IFERROR(L8/K8,0) -> 0 | N8: =IFERROR(R8/L8,0) -> 0 | O8: =SUMIFS(广告数据包!P:P,广告数据包!A:A,A8,广告数据包!G:G,$C$2) -> 0 | P8: =SUMIFS(广告数据包!U:U,广告数据包!A:A,A8,广告数据包!G:G,$C$2) -> 0 | Q8: =IFERROR(O8/L8,0) -> 0 | R8: =SUMIFS(广告数据包!L:L,广告数据包!A:A,A8,广告数据包!G:G,$C$2) -> 0 | S8: =IFERROR(R8/P8,0) -> 0
A9: =DATE($B$1,$B$2,DAY(A8)+1) -> 44566 | B9: =SUMIFS(销售数据包!F:F,销售数据包!A:A,A9,销售数据包!C:C,$C$2) -> 0 | C9: =SUMIFS(销售数据包!K:K,销售数据包!A:A,A9,销售数据包!C:C,$C$2) -> 0 | D9: =SUMIFS(销售数据包!Q:Q,销售数据包!A:A,A9,销售数据包!C:C,$C$2) -> 0 | E9: =IFERROR(D9/B9,0) -> 0 | F9: =IFERROR(C9/B9,0) -> 0 | G9: =SUMIFS(销售数据包!O:O,销售数据包!A:A,A9,销售数据包!C:C,$C$2) -> 0 | H9: =IFERROR(R9/G9,0) -> 0 | I9: =IFERROR(P9/G9,0) -> 0 | J9: ="周"&WEEKDAY(A9,2) -> 周3 | K9: =SUMIFS(广告数据包!H:H,广告数据包!A:A,A9,广告数据包!G:G,$C$2) -> 0 | L9: =SUMIFS(广告数据包!I:I,广告数据包!A:A,A9,广告数据包!G:G,$C$2) -> 0 | M9: =IFERROR(L9/K9,0) -> 0 | N9: =IFERROR(R9/L9,0) -> 0 | O9: =SUMIFS(广告数据包!P:P,广告数据包!A:A,A9,广告数据包!G:G,$C$2) -> 0 | P9: =SUMIFS(广告数据包!U:U,广告数据包!A:A,A9,广告数据包!G:G,$C$2) -> 0 | Q9: =IFERROR(O9/L9,0) -> 0 | R9: =SUMIFS(广告数据包!L:L,广告数据包!A:A,A9,广告数据包!G:G,$C$2) -> 0 | S9: =IFERROR(R9/P9,0) -> 0
A10: =DATE($B$1,$B$2,DAY(A9)+1) -> 44567 | B10: =SUMIFS(销售数据包!F:F,销售数据包!A:A,A10,销售数据包!C:C,$C$2) -> 0 | C10: =SUMIFS(销售数据包!K:K,销售数据包!A:A,A10,销售数据包!C:C,$C$2) -> 0 | D10: =SUMIFS(销售数据包!Q:Q,销售数据包!A:A,A10,销售数据包!C:C,$C$2) -> 0 | E10: =IFERROR(D10/B10,0) -> 0 | F10: =IFERROR(C10/B10,0) -> 0 | G10: =SUMIFS(销售数据包!O:O,销售数据包!A:A,A10,销售数据包!C:C,$C$2) -> 0 | H10: =IFERROR(R10/G10,0) -> 0 | I10: =IFERROR(P10/G10,0) -> 0 | J10: ="周"&WEEKDAY(A10,2) -> 周4 | K10: =SUMIFS(广告数据包!H:H,广告数据包!A:A,A10,广告数据包!G:G,$C$2) -> 0 | L10: =SUMIFS(广告数据包!I:I,广告数据包!A:A,A10,广告数据包!G:G,$C$2) -> 0 | M10: =IFERROR(L10/K10,0) -> 0 | N10: =IFERROR(R10/L10,0) -> 0 | O10: =SUMIFS(广告数据包!P:P,广告数据包!A:A,A10,广告数据包!G:G,$C$2) -> 0 | P10: =SUMIFS(广告数据包!U:U,广告数据包!A:A,A10,广告数据包!G:G,$C$2) -> 0 | Q10: =IFERROR(O10/L10,0) -> 0 | R10: =SUMIFS(广告数据包!L:L,广告数据包!A:A,A10,广告数据包!G:G,$C$2) -> 0 | S10: =IFERROR(R10/P10,0) -> 0
A11: =DATE($B$1,$B$2,DAY(A10)+1) -> 44568 | B11: =SUMIFS(销售数据包!F:F,销售数据包!A:A,A11,销售数据包!C:C,$C$2) -> 0 | C11: =SUMIFS(销售数据包!K:K,销售数据包!A:A,A11,销售数据包!C:C,$C$2) -> 0 | D11: =SUMIFS(销售数据包!Q:Q,销售数据包!A:A,A11,销售数据包!C:C,$C$2) -> 0 | E11: =IFERROR(D11/B11,0) -> 0 | F11: =IFERROR(C11/B11,0) -> 0 | G11: =SUMIFS(销售数据包!O:O,销售数据包!A:A,A11,销售数据包!C:C,$C$2) -> 0 | H11: =IFERROR(R11/G11,0) -> 0 | I11: =IFERROR(P11/G11,0) -> 0 | J11: ="周"&WEEKDAY(A11,2) -> 周5 | K11: =SUMIFS(广告数据包!H:H,广告数据包!A:A,A11,广告数据包!G:G,$C$2) -> 0 | L11: =SUMIFS(广告数据包!I:I,广告数据包!A:A,A11,广告数据包!G:G,$C$2) -> 0 | M11: =IFERROR(L11/K11,0) -> 0 | N11: =IFERROR(R11/L11,0) -> 0 | O11: =SUMIFS(广告数据包!P:P,广告数据包!A:A,A11,广告数据包!G:G,$C$2) -> 0 | P11: =SUMIFS(广告数据包!U:U,广告数据包!A:A,A11,广告数据包!G:G,$C$2) -> 0 | Q11: =IFERROR(O11/L11,0) -> 0 | R11: =SUMIFS(广告数据包!L:L,广告数据包!A:A,A11,广告数据包!G:G,$C$2) -> 0 | S11: =IFERROR(R11/P11,0) -> 0
A12: =DATE($B$1,$B$2,DAY(A11)+1) -> 44569 | B12: =SUMIFS(销售数据包!F:F,销售数据包!A:A,A12,销售数据包!C:C,$C$2) -> 0 | C12: =SUMIFS(销售数据包!K:K,销售数据包!A:A,A12,销售数据包!C:C,$C$2) -> 0 | D12: =SUMIFS(销售数据包!Q:Q,销售数据包!A:A,A12,销售数据包!C:C,$C$2) -> 0 | E12: =IFERROR(D12/B12,0) -> 0 | F12: =IFERROR(C12/B12,0) -> 0 | G12: =SUMIFS(销售数据包!O:O,销售数据包!A:A,A12,销售数据包!C:C,$C$2) -> 0 | H12: =IFERROR(R12/G12,0) -> 0 | I12: =IFERROR(P12/G12,0) -> 0 | J12: ="周"&WEEKDAY(A12,2) -> 周6 | K12: =SUMIFS(广告数据包!H:H,广告数据包!A:A,A12,广告数据包!G:G,$C$2) -> 0 | L12: =SUMIFS(广告数据包!I:I,广告数据包!A:A,A12,广告数据包!G:G,$C$2) -> 0 | M12: =IFERROR(L12/K12,0) -> 0 | N12: =IFERROR(R12/L12,0) -> 0 | O12: =SUMIFS(广告数据包!P:P,广告数据包!A:A,A12,广告数据包!G:G,$C$2) -> 0 | P12: =SUMIFS(广告数据包!U:U,广告数据包!A:A,A12,广告数据包!G:G,$C$2) -> 0 | Q12: =IFERROR(O12/L12,0) -> 0 | R12: =SUMIFS(广告数据包!L:L,广告数据包!A:A,A12,广告数据包!G:G,$C$2) -> 0 | S12: =IFERROR(R12/P12,0) -> 0
