Workbook

Sheet 1-关键词库
A1: # | B1: 关键词 | C1: 翻译 | D1: 相关性-自动百分比 | E1: 相关性-自动 | F1: 搜索量 | G1: 排名 | H1: 流量大小 | I1: 相关性-手动 | J1: 修饰词类型 | K1: 搜词转化率
A2: 1 | B2: posture corrector for women | C2: 女性姿势矫正器 | D2: 0.9052 | E2: 高相关 | F2: 70103 | G2: 1708 | H2: 大 | I2: =E2 -> 高相关 | J2: 受众词 | K2: =VLOOKUP(B2,'2-搜索转化率'!A:F,6,FALSE) -> 0.0286
A3: 2 | B3: back brace | C3: 背部支撑 | D3: 0.3243 | E3: 中相关 | F3: 58872 | G3: 2328 | H3: 大 | I3: =E3 -> 中相关 | J3: 产品词 | K3: =VLOOKUP(B3,'2-搜索转化率'!A:F,6,FALSE) -> 0.0232
A4: 3 | B4: posture corrector for men | C4: 男士矫正器 | D4: 0.9088 | E4: 高相关 | F4: 46139 | G4: 3639 | H4: 大 | I4: =E4 -> 高相关 | J4: 受众词 | K4: =VLOOKUP(B4,'2-搜索转化率'!A:F,6,FALSE) -> 0.0311 | M4: CPC、CVR
A5: 4 | B5: back brace for lower back pain women | C5: 女性腰痛用背撑 | D5: 0.1663 | E5: 低相关 | F5: 24030 | G5: 8656 | H5: 大 | I5: =E5 -> 低相关 | J5: 受众词 | K5: =VLOOKUP(B5,'2-搜索转化率'!A:F,6,FALSE) -> 0.023
A6: 5 | B6: posture corrector | C6: 姿势矫正器 | D6: 0.9173 | E6: 高相关 | F6: 18767 | G6: 12022 | H6: 大 | I6: =E6 -> 高相关 | K6: =VLOOKUP(B6,'2-搜索转化率'!A:F,6,FALSE) -> 0.0252
A7: 6 | B7: back brace for men lower back | C7: 男士下背部背带 | D7: 0.2428 | E7: 中相关 | F7: 12808 | G7: 19178 | H7: 大 | I7: =E7 -> 中相关 | K7: =VLOOKUP(B7,'2-搜索转化率'!A:F,6,FALSE) -> 0.0328
A8: 7 | B8: back support | C8: 背部支撑 | D8: 0.5262 | E8: 高相关 | F8: 10368 | G8: 24644 | H8: 中上 | I8: =E8 -> 高相关 | K8: =VLOOKUP(B8,'2-搜索转化率'!A:F,6,FALSE) -> 0.0127
A9: 8 | B9: back brace posture corrector | C9: 背部矫姿器 | D9: 0.9494 | E9: 高相关 | F9: 10085 | G9: 25412 | H9: 中上 | I9: =E9 -> 高相关 | K9: =VLOOKUP(B9,'2-搜索转化率'!A:F,6,FALSE) -> 0.0244
A10: 9 | B10: back | C10: 背部 | D10: 0.2015 | E10: 中相关 | F10: 9737 | G10: 26456 | H10: 中上 | I10: =E10 -> 中相关 | K10: =VLOOKUP(B10,'2-搜索转化率'!A:F,6,FALSE) -> #N/A
A11: 10 | B11: fajas para hombres | C11: Fajas para hombres | D11: 0.3679 | E11: 中相关 | F11: 9378 | G11: 27608 | H11: 中上 | I11: =E11 -> 中相关 | K11: =VLOOKUP(B11,'2-搜索转化率'!A:F,6,FALSE) -> #N/A
A12: 11 | B12: back straightener posture corrector | C12: 背部矫正器姿势矫正器 | D12: 0.971 | E12: 高相关 | F12: 9070 | G12: 28687 | H12: 中上 | I12: =E12 -> 高相关 | K12: =VLOOKUP(B12,'2-搜索转化率'!A:F,6,FALSE) -> 0.0311
A13: 12 | B13: back support brace | C13: 背部支撑器 | D13: 0.3346 | E13: 中相关 | F13: 8419 | G13: 31243 | H13: 中上 | I13: =E13 -> 中相关 | K13: =VLOOKUP(B13,'2-搜索转化率'!A:F,6,FALSE) -> 0.0193
A14: 13 | B14: posture corrector bra | C14: 矫姿胸罩 | D14: 0.3767 | E14: 中相关 | F14: 7939 | G14: 33496 | H14: 中上 | I14: =E14 -> 中相关 | K14: =VLOOKUP(B14,'2-搜索转化率'!A:F,6,FALSE) -> #N/A
A15: 14 | B15: back posture corrector women | C15: 女性背部矫正器 | D15: 0.9746 | E15: 高相关 | F15: 7909 | G15: 33646 | H15: 中上 | I15: =E15 -> 高相关 | K15: =VLOOKUP(B15,'2-搜索转化率'!A:F,6,FALSE) -> 0.0264
A16: 15 | B16: lower back pain relief | C16: 下背部疼痛缓解 | D16: 0.0149 | E16: 低相关 | F16: 7873 | G16: 33813 | H16: 中上 | I16: =E16 -> 低相关 | K16: =VLOOKUP(B16,'2-搜索转化率'!A:F,6,FALSE) -> #N/A
A17: 16 | B17: back pain | C17: 背痛 | D17: 0.0161 | E17: 低相关 | F17: 6227 | G17: 44046 | H17: 中上 | I17: =E17 -> 低相关 | K17: =VLOOKUP(B17,'2-搜索转化率'!A:F,6,FALSE) -> #N/A
... A49: 48 | B49: instant posture corrector | C49: 即时姿势矫正器 | D49: 0.9222 | E49: 高相关 | F49: 2449 | G49: 123361 | H49: 小 | I49: =E49 -> 高相关 | K49: =VLOOKUP(B49,'2-搜索转化率'!A:F,6,FALSE) -> #N/A
A50: 49 | B50: best posture bra | C50: 最佳姿势文胸 | D50: 0.1112 | E50: 低相关 | F50: 2227 | G50: 136503 | H50: 小 | I50: =E50 -> 低相关 | J50: X | K50: =VLOOKUP(B50,'2-搜索转化率'!A:F,6,FALSE) -> #N/A
A51: 50 | B51: posture bras for women | C51: 女性姿势胸罩 | D51: 0.059 | E51: 低相关 | F51: 2207 | G51: 137851 | H51: 小 | I51: =E51 -> 低相关 | K51: =VLOOKUP(B51,'2-搜索转化率'!A:F,6,FALSE) -> #N/A
A52: 51 | B52: corecorex | C52: corecorex | D52: 0.9226 | E52: 高相关 | F52: 2161 | G52: 140965 | H52: 小 | I52: =E52 -> 高相关 | K52: =VLOOKUP(B52,'2-搜索转化率'!A:F,6,FALSE) -> #N/A
A53: 52 | B53: back brace for lower back pain | C53: 腰痛背部支撑 | D53: 0.0887 | E53: 低相关 | F53: 2126 | G53: 143607 | H53: 小 | I53: =E53 -> 低相关 | K53: =VLOOKUP(B53,'2-搜索转化率'!A:F,6,FALSE) -> 0.0227
A54: 53 | B54: copper fit | C54: 铜贴 | D54: 0.1028 | E54: 低相关 | F54: 2035 | G54: 150377 | H54: 小 | I54: =E54 -> 低相关 | K54: =VLOOKUP(B54,'2-搜索转化率'!A:F,6,FALSE) -> #N/A
A55: 54 | B55: vistaro posture corrector | D55: 0.8713 | E55: 高相关 | F55: 2015 | G55: 152021 | H55: 小 | I55: =E55 -> 高相关 | K55: =VLOOKUP(B55,'2-搜索转化率'!A:F,6,FALSE) -> #N/A
A56: 55 | B56: posture brace for women | C56: 女性用姿势支具 | D56: 0.9484 | E56: 高相关 | F56: 1904 | G56: 161622 | H56: 小 | I56: =E56 -> 高相关 | K56: =VLOOKUP(B56,'2-搜索转化率'!A:F,6,FALSE) -> 0.0267
A57: 56 | B57: back support belt for men | C57: 男士背部支撑带 | D57: 0.4529 | E57: 中相关 | F57: 1888 | G57: 162945 | H57: 小 | I57: =E57 -> 中相关 | K57: =VLOOKUP(B57,'2-搜索转化率'!A:F,6,FALSE) -> 0.0258
A58: 57 | B58: shoulder support | C58: 肩膀支撑 | D58: 0.0386 | E58: 低相关 | F58: 1838 | G58: 167651 | H58: 小 | I58: =E58 -> 低相关 | K58: =VLOOKUP(B58,'2-搜索转化率'!A:F,6,FALSE) -> #N/A
A59: 58 | B59: upper back brace | C59: 上背部支撑 | D59: 0.9759 | E59: 高相关 | F59: 1823 | G59: 169102 | H59: 小 | I59: =E59 -> 高相关 | K59: =VLOOKUP(B59,'2-搜索转化率'!A:F,6,FALSE) -> 0.0232
A60: 59 | B60: forme science bra posture correcting | C60: forme science文胸姿势矫正 | D60: 0.3619 | E60: 中相关 | F60: 1813 | G60: 170061 | H60: 小 | I60: =E60 -> 中相关 | K60: =VLOOKUP(B60,'2-搜索转化率'!A:F,6,FALSE) -> #N/A
A61: 60 | B61: neck posture corrector | C61: 颈部姿势矫正器 | D61: 0.4054 | E61: 中相关 | F61: 1767 | G61: 174659 | H61: 小 | I61: =E61 -> 中相关 | K61: =VLOOKUP(B61,'2-搜索转化率'!A:F,6,FALSE) -> #N/A
A62: 61 | B62: spine decompressor | C62: 脊柱减压器 | D62: 0.0373 | E62: 低相关 | F62: 1742 | G62: 177191 | H62: 小 | I62: =E62 -> 低相关 | K62: =VLOOKUP(B62,'2-搜索转化率'!A:F,6,FALSE) -> #N/A
A63: 62 | B63: back belts for back pain | C63: 背痛用背带 | D63: 0.1386 | E63: 低相关 | F63: 1717 | G63: 179885 | H63: 小 | I63: =E63 -> 低相关 | K63: =VLOOKUP(B63,'2-搜索转化率'!A:F,6,FALSE) -> 0.0261
A64: 63 | B64: back posture correction | C64: 背部姿势矫正 | D64: 0.9372 | E64: 高相关 | F64: 1671 | G64: 185053 | H64: 小 | I64: =E64 -> 高相关 | K64: =VLOOKUP(B64,'2-搜索转化率'!A:F,6,FALSE) -> #N/A
A65: 64 | B65: back corrector for women | C65: 妇女用背部矫正器 | D65: 0.9356 | E65: 高相关 | F65: 1651 | G65: 187423 | H65: 小 | I65: =E65 -> 高相关 | K65: =VLOOKUP(B65,'2-搜索转化率'!A:F,6,FALSE) -> 0.0197
A66: 65 | B66: shoulder posture corrector | C66: 肩部姿势矫正器 | D66: 0.9602 | E66: 高相关 | F66: 1626 | G66: 190391 | H66: 小 | I66: =E66 -> 高相关 | K66: =VLOOKUP(B66,'2-搜索转化率'!A:F,6,FALSE) -> 0.0416
A67: 66 | B67: hunchback posture corrector | C67: 驼背矫正器 | D67: 0.8877 | E67: 高相关 | F67: 1580 | G67: 196122 | H67: 小 | I67: =E67 -> 高相关 | K67: =VLOOKUP(B67,'2-搜索转化率'!A:F,6,FALSE) -> #N/A
... A69: 68 | B69: tommie copper back support | C69: 汤米铜背托 | D69: 0.0411 | E69: 低相关 | F69: 1575 | G69: 196769 | H69: 小 | I69: =E69 -> 低相关 | K69: =VLOOKUP(B69,'2-搜索转化率'!A:F,6,FALSE) -> #N/A
A70: 69 | B70: backache relief | D70: 0.1137 | E70: 低相关 | F70: 1409 | G70: 221104 | H70: 小 | I70: =E70 -> 低相关 | K70: =VLOOKUP(B70,'2-搜索转化率'!A:F,6,FALSE) -> #N/A
A71: 70 | B71: faja para la postura de la espalda | D71: 0.9488 | E71: 高相关 | F71: 1388 | G71: 224541 | H71: 小 | I71: =E71 -> 高相关 | K71: =VLOOKUP(B71,'2-搜索转化率'!A:F,6,FALSE) -> #N/A
A72: 71 | B72: posture correcting bra | C72: 矫姿胸罩 | D72: 0.3327 | E72: 中相关 | F72: 1373 | G72: 227083 | H72: 小 | I72: =E72 -> 中相关 | K72: =VLOOKUP(B72,'2-搜索转化率'!A:F,6,FALSE) -> #N/A
...

Sheet 2-搜索转化率
A1: 搜索词 | B1: 搜索量（过去 360 天） | C1: 搜索量增长（过去 90 天） | D1: 搜索量增长（过去 180 天） | E1: 点击份额（过去 360 天） | F1: 搜索转化率（过去 360 天） | G1: 点击率最高的商品1（标题） | H1: 点击率最高的商品1 (ASIN) | I1: 点击率最高的商品2（标题） | J1: 点击率最高的商品2 (ASIN) | K1: 点击率最高的商品3（标题） | L1: 点击率最高的商品3 (ASIN)
A2: posture corrector for women | B2: 2391602 | C2: 0.0642 | D2: 0.4611 | E2: 0.4105 | F2: 0.0286 | G2: Fit Geno Back Brace Posture Corrector for Women and Men Shoulder Straightener Adjustable Full Back Support Upper and Lower Back Pain Relief - Scoliosis Hunchback Hump Thoracic Spine Corrector | H2: B09ZQ2QSXS | I2: ComfyBrace Posture Corrector-Back Brace for Men and Women- Fully Adjustable Straightener for Mid Upper Spine Support- Neck Shoulder Clavicle and Back Pain Relief-Breathable | J2: B07ZQPKTVV | K2: JMPOSE Posture Corrector for Women and Men Breathable Back Brace Adjustable Posture Corrector for Back Shoulder and Spine Pain Relief (Small/Medium) | L2: B0BYMMVKZF
A3: posture corrector for men | B3: 1255472 | C3: 0.2709 | D3: 0.3723 | E3: 0.2075 | F3: 0.0311 | G3: Fit Geno Back Brace Posture Corrector for Women and Men Shoulder Straightener Adjustable Full Back Support Upper and Lower Back Pain Relief - Scoliosis Hunchback Hump Thoracic Spine Corrector | H3: B09ZQ2QSXS | I3: Posture Corrector for Men and Women Adjustable Upper Back Brace Muscle Memory Support Straightener Providing Pain Relief from Neck Shoulder and Upper and Lower Back Large-X Large(37-47) | J3: B0B63LDVDD | K3: ComfyBrace Posture Corrector-Back Brace for Men and Women- Fully Adjustable Straightener for Mid Upper Spine Support- Neck Shoulder Clavicle and Back Pain Relief-Breathable | L3: B07ZQPKTVV
A4: posture corrector | B4: 902511 | C4: -0.0682 | D4: -0.2713 | E4: 0.0876 | F4: 0.0252 | G4: Posture Corrector for Women and Men Adjustable Upper Back Brace Breathable Back Support straightener Providing Pain Relief from Lumbar Neck Shoulder and Clavicle Back (Black) | H4: B0BWRHYZWJ | I4: Fit Geno Posture Corrector for Women and Men - Adjustable Back Brace & Straightener for Scoliosis Hunchback Correction Back Pain Spine Corrector Back Support and Posture Trainer | J4: B09ZQ192L3 | K4: ComfyBrace Posture Corrector-Back Brace for Men and Women- Fully Adjustable Straightener for Mid Upper Spine Support- Neck Shoulder Clavicle and Back Pain Relief-Breathable | L4: B07ZQPKTVV
A5: back brace posture corrector | B5: 238605 | C5: -0.0476 | D5: 3.4084 | E5: 0.0468 | F5: 0.0244 | G5: Fit Geno Back Brace Posture Corrector for Women and Men Shoulder Straightener Adjustable Full Back Support Upper and Lower Back Pain Relief - Scoliosis Hunchback Hump Thoracic Spine Corrector | H5: B09ZQ2QSXS | I5: Fit Geno Posture Corrector for Women and Men - Adjustable Back Brace & Straightener for Scoliosis Hunchback Correction Back Pain Spine Corrector Back Support and Posture Trainer | J5: B09ZQ192L3 | K5: ComfyBrace Posture Corrector-Back Brace for Men and Women- Fully Adjustable Straightener for Mid Upper Spine Support- Neck Shoulder Clavicle and Back Pain Relief-Breathable | L5: B07ZQPKTVV
A6: back posture corrector women | B6: 217560 | C6: 0.1891 | D6: 0.5644 | E6: 0.0408 | F6: 0.0264 | G6: Fit Geno Back Brace Posture Corrector for Women and Men Shoulder Straightener Adjustable Full Back Support Upper and Lower Back Pain Relief - Scoliosis Hunchback Hump Thoracic Spine Corrector | H6: B09ZQ2QSXS | I6: ComfyBrace Posture Corrector-Back Brace for Men and Women- Fully Adjustable Straightener for Mid Upper Spine Support- Neck Shoulder Clavicle and Back Pain Relief-Breathable | J6: B07ZQPKTVV | K6: JMPOSE Posture Corrector for Women and Men Breathable Back Brace Adjustable Posture Corrector for Back Shoulder and Spine Pain Relief (Small/Medium) | L6: B0BYMMVKZF
A7: back straightener posture corrector | B7: 210975 | C7: 0.132 | D7: 0.5342 | E7: 0.0355 | F7: 0.0311 | G7: Fit Geno Back Brace Posture Corrector for Women and Men Shoulder Straightener Adjustable Full Back Support Upper and Lower Back Pain Relief - Scoliosis Hunchback Hump Thoracic Spine Corrector | H7: B09ZQ2QSXS | I7: Posture Corrector for Women and Men Adjustable Upper Back Brace Breathable Back Support straightener Providing Pain Relief from Lumbar Neck Shoulder and Clavicle Back (Black) | J7: B0BWRHYZWJ | K7: ComfyBrace Posture Corrector-Back Brace for Men and Women- Fully Adjustable Straightener for Mid Upper Spine Support- Neck Shoulder Clavicle and Back Pain Relief-Breathable | L7: B07ZQPKTVV
A8: back posture corrector for men | B8: 111113 | C8: 0.399 | D8: 3.8317 | E8: 0.0266 | F8: 0.0348 | G8: Fit Geno Back Brace Posture Corrector for Women and Men Shoulder Straightener Adjustable Full Back Support Upper and Lower Back Pain Relief - Scoliosis Hunchback Hump Thoracic Spine Corrector | H8: B09ZQ2QSXS | I8: Posture Corrector for Men and Women Adjustable Upper Back Brace Muscle Memory Support Straightener Providing Pain Relief from Neck Shoulder and Upper and Lower Back Large-X Large(37-47) | J8: B0B63LDVDD | K8: ComfyBrace Posture Corrector-Back Brace for Men and Women- Fully Adjustable Straightener for Mid Upper Spine Support- Neck Shoulder Clavicle and Back Pain Relief-Breathable | L8: B07ZQPKTVV
A9: corrector de postura para mujer | B9: 158778 | C9: 0.031 | D9: 0.3299 | E9: 0.0224 | F9: 0.0079 | G9: Fit Geno Back Brace Posture Corrector for Women and Men Shoulder Straightener Adjustable Full Back Support Upper and Lower Back Pain Relief - Scoliosis Hunchback Hump Thoracic Spine Corrector | H9: B09ZQ2QSXS | I9: ComfyBrace Posture Corrector-Back Brace for Men and Women- Fully Adjustable Straightener for Mid Upper Spine Support- Neck Shoulder Clavicle and Back Pain Relief-Breathable | J9: B07ZQPKTVV | K9: Fit Geno Back Brace Posture Corrector for Women: Shoulder Straightener Adjustable Full Back Support Upper and Lower Back Pain Relief - Scoliosis Hunchback Hump Thoracic Spine Corrector Pink Medium | L9: B0BHF1DT5N
A10: corrector de postura para hombre | B10: 139582 | C10: 0.1094 | D10: 0.4308 | E10: 0.0188 | F10: 0.0084 | G10: Fit Geno Back Brace Posture Corrector for Women and Men Shoulder Straightener Adjustable Full Back Support Upper and Lower Back Pain Relief - Scoliosis Hunchback Hump Thoracic Spine Corrector | H10: B09ZQ2QSXS | I10: Posture Corrector for Men and Women Adjustable Upper Back Brace Muscle Memory Support Straightener Providing Pain Relief from Neck Shoulder and Upper and Lower Back Large-X Large(37-47) | J10: B0B63LDVDD | K10: Posture Corrector for Women Back Brace for Men Adjustable Posture Corrector Shoulder Brace Back Posture Corrector Women Back Pain Relief Posture Brace Back Straightener Upper Back Support | L10: B0CN77K249
A11: posture | B11: 164435 | C11: -0.0508 | D11: -0.2724 | E11: 0.0116 | F11: 0.0226 | G11: Fit Geno Back Brace Posture Corrector for Women and Men Shoulder Straightener Adjustable Full Back Support Upper and Lower Back Pain Relief - Scoliosis Hunchback Hump Thoracic Spine Corrector | H11: B09ZQ2QSXS | I11: Posture Corrector for Women and Men Adjustable Upper Back Brace Breathable Back Support straightener Providing Pain Relief from Lumbar Neck Shoulder and Clavicle Back (Black) | J11: B0BWRHYZWJ | K11: ComfyBrace Posture Corrector-Back Brace for Men and Women- Fully Adjustable Straightener for Mid Upper Spine Support- Neck Shoulder Clavicle and Back Pain Relief-Breathable | L11: B07ZQPKTVV
A12: back brace for posture | B12: 83299 | C12: 0.6172 | D12: 0.5444 | E12: 0.0162 | F12: 0.0232 | G12: Fit Geno Back Brace Posture Corrector for Women and Men Shoulder Straightener Adjustable Full Back Support Upper and Lower Back Pain Relief - Scoliosis Hunchback Hump Thoracic Spine Corrector | H12: B09ZQ2QSXS | I12: Fit Geno Posture Corrector for Women and Men - Adjustable Back Brace & Straightener for Scoliosis Hunchback Correction Back Pain Spine Corrector Back Support and Posture Trainer | J12: B09ZQ192L3 | K12: ComfyBrace Posture Corrector-Back Brace for Men and Women- Fully Adjustable Straightener for Mid Upper Spine Support- Neck Shoulder Clavicle and Back Pain Relief-Breathable | L12: B07ZQPKTVV
A13: posture brace | B13: 139370 | C13: -0.1429 | D13: -0.2513 | E13: 0.0156 | F13: 0.0287 | G13: Fit Geno Back Brace Posture Corrector for Women and Men Shoulder Straightener Adjustable Full Back Support Upper and Lower Back Pain Relief - Scoliosis Hunchback Hump Thoracic Spine Corrector | H13: B09ZQ2QSXS | I13: ComfyBrace Posture Corrector-Back Brace for Men and Women- Fully Adjustable Straightener for Mid Upper Spine Support- Neck Shoulder Clavicle and Back Pain Relief-Breathable | J13: B07ZQPKTVV | K13: NLNYCT Posture Corrector For Women Adjustable Back Brace For Posture Back Posture Corrector Providing Pain Relief From Lumbar Neck Shoulder And Clavicle Back (S/M Upper Waist 25-36 Inch) | L13: B0C6GK7B9X
... A41: back brace for lifting at work | B41: 56514 | C41: -0.4997 | D41: 1.1335 | E41: 0.0062 | F41: 0.0209 | G41: Ergodyne - 11103 ProFlex 1600 Back Support Brace 9 Extended Support High Cut Front For Mobility Medium Black | H41: B000H89YHU | I41: Sparthos Back Brace for Lower Back Pain - Immediate Relief from Sciatica Herniated Disc Scoliosis - Breathable Design With Lumbar Support Pad - For Home & Lifting At Work - For Men & Women - (Large) | J41: B071G33DC1 | K41: FEATOL Back Brace Support Belt-Lumbar Support Back Brace for Back Pain Sciatica Scoliosis Herniated Disc Adjustable Support Straps-Lower Back Brace with Removable Lumbar Pad for Men & Women | L41: B07WZZFL9T

Sheet 3-词频表
A1: 单词频统计 | H1: 双词频统计
A2: # | B2: 单词 | C2: 单词翻译 | D2: 词根分类 | E2: 出现次数词频 | F2: 搜索量加权词频(亚马逊官方方法) | H2: # | I2: 单词 | J2: 单词翻译 | K2: 词根分类 | L2: 出现次数词频 | M2: 搜索量加权词频(亚马逊官方方法)
A3: 1 | B3: posture | C3: 姿势 | D3: 产品词 | E3: 58 | F3: 1349.71 | H3: 1 | I3: posture corrector | J3: 姿势矫正器 | L3: 33 | M3: 1196.35
A4: 2 | B4: corrector | C4: 修正器 | D4: 产品词 | E4: 45 | F4: 1271.83 | H4: 2 | I4: back brace | J4: 背部支撑 | L4: 33 | M4: 795.06
A5: 3 | B5: back | C5: 背部 | D5: 产品词 | E5: 75 | F5: 1227.98 | H5: 3 | I5: lower back | J5: 下背部 | L5: 17 | M5: 283.77
A6: 4 | B6: brace | C6: 支架 | D6: 产品词 | E6: 48 | F6: 899.42 | H6: 4 | I6: back pain | J6: 背痛 | L6: 17 | M6: 234.69
A7: 5 | B7: women | C7: 女性 | D7: 受众群体 | E7: 24 | F7: 834.67 | H7: 5 | I7: back support | J7: 背部支撑 | L7: 11 | M7: 139.04
A8: 6 | B8: men | C8: 男人 | D8: 受众群体 | E8: 15 | F8: 404.42 | H8: 6 | I8: pain women | J8: 痛苦的女人 | L8: 1 | M8: 115.53
A9: 7 | B9: lower | C9: 降低 | D9: 功能词 | E9: 18 | F9: 286.24 | H9: 7 | I9: back posture | J9: 背部姿势 | L9: 8 | M9: 70.24
A10: 8 | B10: pain | C10: 疼痛 | D10: 属性词 | E10: 18 | F10: 236.81 | H10: 8 | I10: fajas para | J10: 法哈斯段落 | L10: 5 | M10: 67.55
A11: 9 | B11: support | C11: 支持 | D11: 产品词 | E11: 16 | F11: 164.62 | H11: 9 | I11: para hombres | J11: 帕拉霍姆布雷斯 | L11: 2 | M11: 53.62
A12: 10 | B12: para | C12: para | E12: 17 | F12: 155.1 | H12: 10 | I12: men lower | J12: 男子下半身 | L12: 1 | M12: 52.14
A13: 12 | B13: de | C13: de | E13: 11 | F13: 80.87 | H13: 11 | I13: faja para | J13: 法贾山 | L13: 7 | M13: 48.73
A14: 13 | B14: belt | C14: 腰带 | E14: 13 | F14: 75.38 | H14: 12 | I14: posture bra | J14: 矫正胸罩 | L14: 3 | M14: 44.38
A15: 14 | B15: fajas | C15: 腰带 | E15: 5 | F15: 67.55 | H15: 13 | I15: back straightener | J15: 背部矫正器 | L15: 2 | M15: 43.09
A16: 15 | B16: hombres | C16: 伙计们 | E16: 2 | F16: 53.62 | H16: 14 | I16: la espalda | J16: 拉埃斯帕尔达 | L16: 6 | M16: 42.2
A17: 16 | B17: copper | C17: 铜 | E17: 9 | F17: 53.26 | H17: 15 | I17: para hombre | J17: Para Hombre | L17: 7 | M17: 39.87
A18: 17 | B18: faja | C18: 腰带 | E18: 8 | F18: 50.91 | H18: 16 | I18: support belt | J18: 支撑带 | L18: 4 | M18: 39.65
A19: 18 | B19: espalda | C19: 背部 | E19: 7 | F19: 46.2 | H19: 17 | I19: brace posture | J19: 支撑姿势 | L19: 1 | M19: 39.35
A20: 19 | B20: postura | C20: 姿势 | E20: 5 | F20: 43.68 | H20: 18 | I20: para la | J20: 帕拉拉 | L20: 5 | M20: 39.11
A21: 20 | B21: straightener | C21: 矫直机 | E21: 2 | F21: 43.09 | H21: 19 | I21: corrector de | J21: 校正器 | L21: 3 | M21: 36.14
A22: 21 | B22: la | C22: 洛杉矶 | E22: 6 | F22: 42.2 | H22: 20 | I22: de postura | J22: 姿势 | L22: 3 | M22: 36.14
A23: 22 | B23: neck | C23: 颈部 | E23: 8 | F23: 41.35 | H23: 21 | I23: pain relief | J23: 缓解疼痛 | L23: 3 | M23: 35.72
... A28: 27 | B28: instant | C28: 即时 | E28: 6 | F28: 28.36 | H28: 26 | I28: postura para | J28: para姿势 | L28: 2 | M28: 31.8
A29: 28 | B29: tommie | C29: 汤米 | E29: 3 | F29: 24.93 | H29: 27 | I29: instant posture | L29: 6 | M29: 28.36
A30: 29 | B30: trabajo | C30: 特拉巴霍 | E30: 4 | F30: 24.55 | H30: 28 | I30: tommie copper | J30: 汤米·科珀 | L30: 3 | M30: 24.93
A31: 30 | B31: hero | C31: 英雄 | E31: 2 | F31: 23.39 | H31: 29 | I31: de trabajo | J31: 德特拉瓦霍 | L31: 4 | M31: 24.55
A32: 31 | B32: hump | C32: 驼峰 | E32: 4 | F32: 22.44 | H32: 30 | I32: back hero | J32: 背部英雄 | L32: 2 | M32: 23.39
A33: 32 | B33: fit | C33: 适合 | E33: 4 | F33: 21.57 | H33: 31 | I33: hump corrector | J33: 驼峰校正器 | L33: 4 | M33: 22.44
A34: 33 | B34: correction | C34: 改正 | E34: 5 | F34: 21.35 | H34: 32 | I34: posture brace | J34: 姿势支架 | L34: 4 | M34: 22.36
A35: 34 | B35: braces | C35: 牙套 | E35: 5 | F35: 20.96 | H35: 33 | I35: para mujer | J35: 准妇女 | L35: 2 | M35: 19.42
A36: 35 | B36: upper | C36: 上部 | E36: 5 | F36: 18.31 | H36: 34 | I36: copper fit | J36: 铜贴 | L36: 3 | M36: 18.66
A37: 36 | B37: pesado | C37: 佩萨多 | E37: 1 | F37: 17.4 | H37: 35 | I37: copper posture | L37: 1 | M37: 17.57
A38: 37 | B38: corecorex | C38: corecorex | E38: 2 | F38: 15.67 | H38: 36 | I38: hombres de | J38: hombres de | L38: 1 | M38: 17.4
A39: 38 | B39: & | C39: 和符号 | E39: 1 | F39: 14.52 | H39: 37 | I39: trabajo pesado | J39: 佩萨多工人 | L39: 1 | M39: 17.4
A40: 39 | B40: supports | C40: 支持 | E40: 1 | F40: 14.52 | H40: 38 | I40: back braces | J40: 背部支架 | L40: 3 | M40: 16.39
A41: 40 | B41: elastic | C41: 有弹性 | E41: 1 | F41: 14.52 | H41: 39 | I41: pain men | J41: 痛苦男人 | L41: 2 | M41: 16.26
A42: 41 | B42: scoliosis | C42: 脊柱侧凸 | E42: 3 | F42: 14.33 | H42: 40 | I42: correction belt | J42: 矫正带 | L42: 4 | M42: 15.94
A43: 42 | B43: bras | C43: 文胸 | E43: 3 | F43: 14.01 | H43: 41 | I43: upper back | J43: 上背部 | L43: 4 | M43: 15.2
A44: 43 | B44: correcting | C44: 校正 | E44: 3 | F44: 13.34 | H44: 42 | I44: neck hump | J44: 颈部隆起 | L44: 2 | M44: 14.52
...

Sheet 4-ASIN 表
A1: ASIN竞品表 | O1: 产品受众群体 | P1: 款式
A2: # | B2: ASIN | C2: 标题 | D2: 价格 | E2: 星级 | F2: 评论数 | G2: 特征 | H2: 流量来源 | I2: 全部流量词 | J2: 自然流量词 | K2: SP广告词 | L2: 品牌广告词 | M2: 视频广告词 | N2: AC推荐词
A3: 1 | B3: B000095SGT | C3: Ergodyne ProFlex 1650 Back Support Belt, 7.5" Elastic, Adjustable, Removeable Straps, Large | D3: 9.99 | E3: 4.5 | F3: 2988 | H3: {自然搜索=[]} | I3: 190 | J3: 190 | K3: 0 | L3: 0 | M3: 0 | N3: 0
A4: 2 | B4: B000H8716Q | C4: Ergodyne ProFlex 1600 Back Support Brace, 9" Extended Support, High Cut Front For Mobility, Large,Black | D4: 19.99 | E4: 4.5 | F4: 7965 | H4: {自然搜索=[]} | I4: 180 | J4: 180 | K4: 0 | L4: 0 | M4: 0 | N4: 0
A5: 3 | B5: B00BFPYZWS | C5: NeoTech Care Adjustable Back Brace Lumbar Support Belt with Suspenders, Black, Size M | D5: 25.27 | E5: 4.5 | F5: 7234 | H5: {自然搜索=[], PPC广告=[SP广告, 头部品牌广告]} | I5: 181 | J5: 132 | K5: 32 | L5: 36 | M5: 0 | N5: 0
A6: 4 | B6: B00HGECOCA | C6: BraceAbility Clavicle Support Brace - Figure 8 Upper Back Brace Posture Corrector for Women and Men, Shoulder Straightener, Kyphosis Relief, Sling for Injuries and Fractures (Medium) | D6: 25.49 | E6: 4 | F6: 1457 | H6: {自然搜索=[], PPC广告=[SP广告]} | I6: 160 | J6: 129 | K6: 54 | L6: 0 | M6: 0 | N6: 0
A7: 5 | B7: B00OB2JLSA | C7: BraceAbility Plus Size 3XL Bariatric Back Brace - XXXL Big and Tall Lumbar Support Girdle for Obesity Lower Back Pain in Extra Large, Heavy or Overweight Men and Women (Fits 55"-61") | D7: 39.99 | E7: 4 | F7: 2504 | H7: {自然搜索=[], PPC广告=[SP广告, 视频广告]} | I7: 131 | J7: 85 | K7: 45 | L7: 0 | M7: 25 | N7: 0
A8: 6 | B8: B00TM8R6QM | C8: Copper Fit Advanced Back Pro Belt Compression Brace, Large/X-Large | D8: 17.59 | E8: 4.5 | F8: 12558 | H8: {自然搜索=[], PPC广告=[SP广告, 头部品牌广告]} | I8: 428 | J8: 382 | K8: 33 | L8: 70 | M8: 0 | N8: 0
A9: 7 | B9: B00VR00ZY8 | C9: Posture Medic Dynamic Posture Brace for Neck, Upper and Lower Back - Long-Term Posture Correction Tool, Unlike Static Posture Correctors That Just Yank Shoulders Back, Large Plus Strength, Silver | D9: 39.95 | E9: 4 | F9: 1040 | H9: {自然搜索=[], PPC广告=[SP广告]} | I9: 48 | J9: 47 | K9: 2 | L9: 0 | M9: 0 | N9: 0
A10: 8 | B10: B00ZHTM1D8 | C10: Work Back Brace - Industrial Lower Back Pain Protection Belt for Men and Women, Construction, Moving, Warehouse Jobs - Removable Suspender Shoulder Straps for Heavy Lifting Safety (L) | D10: 59.99 | E10: 4.5 | F10: 2359 | H10: {自然搜索=[], PPC广告=[SP广告, 视频广告]} | I10: 95 | J10: 84 | K10: 2 | L10: 0 | M10: 11 | N10: 0
A11: 9 | B11: B00ZN0HZ78 | C11: BraceUP Back Support Belt for Men and Women - Breathable Waist Lumbar Support Lower Back Brace for Sciatica, Herniated Disc, Scoliosis Lower Back Pain Relief (L/XL 90-110 cm) | D11: 25.99 | E11: 4.5 | F11: 14180 | H11: {自然搜索=[], 官方推荐=[AC专栏], PPC广告=[SP广告, 头部品牌广告, 视频广告]} | I11: 601 | J11: 357 | K11: 433 | L11: 58 | M11: 15 | N11: 10
A12: 10 | B12: B016LLMKLS | C12: Copper Compression Lower Back Lumbar Support Brace, 1 Guaranteed Highest Copper Content, Great for All Activities! Infused Fit Wrap/Belt, Wear Anywhere! (Waist 28" - 38") | D12: 24.95 | E12: 4 | F12: 9291 | H12: {自然搜索=[], PPC广告=[SP广告, 头部品牌广告]} | I12: 191 | J12: 176 | K12: 2 | L12: 15 | M12: 0 | N12: 0
A13: 11 | B13: B01GEXE74Q | C13: FlexGuard Posture Corrector for Women and Men - Back Brace for Posture, Adjustable Back Support Straightener Shoulder Posture Support for Pain Relief, Body Correction, Large | D13: 20.75 | E13: 4 | F13: 12908 | H13: {自然搜索=[], PPC广告=[SP广告]} | I13: 250 | J13: 245 | K13: 13 | L13: 0 | M13: 0 | N13: 0
A14: 12 | B14: B075STLFP1 | C14: Back Support Belts Posture Corrector Back Brace Improves Posture and Provides For Lower and Upper Back Pain Men and Women -XXL | D14: 33.66 | E14: 4 | F14: 3666 | H14: {自然搜索=[], PPC广告=[SP广告]} | I14: 260 | J14: 248 | K14: 29 | L14: 0 | M14: 0 | N14: 0
... A76: 74 | B76: B0CXPJNPG4 | C76: Posture Corrector Upper Back Brace Neck Shoulder Back Support Brace Pain Relief Belt for Women Men Braces Spine Straightener Breathable - Adjustable | D76: 23.99 | E76: 4.5 | F76: 235 | H76: {自然搜索=[], 官方推荐=[AC专栏], PPC广告=[SP广告], Deal=[优惠券(Coupon)]} | I76: 725 | J76: 499 | K76: 463 | L76: 0 | M76: 0 | N76: 86
A77: 75 | B77: B0CXPPGCKM | C77: Posture Corrector for Men And Women Shoulder Straightener Posture Corrector, Adjustable Full Back Support, Upper and Lower Back Pain Relief - Scoliosis, Hunchback, Hump, Thoracic, Spine Corrector (M) | D77: 13.99 | H77: {自然搜索=[]} | I77: 12 | J77: 12 | K77: 0 | L77: 0 | M77: 0 | N77: 0
A78: 76 | B78: B0CY4H36MR | C78: Back Brace Posture Corrector for Men & Women: Adjustable Full Back Support, Shoulder Straightener, Upper & Lower Back Pain Relief - Scoliosis, Hunchback, Hump, Thoracic, Spine Corrector (Medium) | D78: 32.99 | E78: 5 | F78: 18 | H78: {自然搜索=[], PPC广告=[SP广告], Deal=[优惠券(Coupon)]} | I78: 440 | J78: 398 | K78: 205 | L78: 0 | M78: 0 | N78: 0
A79: 77 | B79: B0CY7X47JQ | C79: Posture Corrector for Men&Women - Back Brace for Lumbar Support and Upright - Breathable Back Straightener Back Corrector Posture Improve and Neck, Back, Shoulder Pain Relieve,(Large(33-37 Inch)) | D79: 34.99 | E79: 4.5 | F79: 47 | H79: {自然搜索=[], PPC广告=[SP广告]} | I79: 487 | J79: 342 | K79: 271 | L79: 0 | M79: 0 | N79: 0
A80: 78 | B80: B0CYLK9JV3 | C80: Posture Corrector for Women & Men,Adjustable Back Posture Corrector,Breathable-Invisible Upper Back Brace Support and Providing Pain Relief from Neck,Shoulder, and Clavicle, Back Posture Corrector | D80: 19.99 | E80: 5 | F80: 13192 | H80: {自然搜索=[], PPC广告=[SP广告], Deal=[优惠券(Coupon)]} | I80: 252 | J80: 233 | K80: 51 | L80: 0 | M80: 0 | N80: 0
A81: 79 | B81: B0CYX6F6HD | C81: 2024 NEW instant posture corrector,Posture Corrector for Women and Men,instant posture,Back Straightener Posture, Used for Middle and Upper Spine (2XL) | D81: 19.98 | E81: 2 | F81: 2 | H81: {自然搜索=[], PPC广告=[SP广告]} | I81: 13 | J81: 11 | K81: 2 | L81: 0 | M81: 0 | N81: 0
A82: 80 | B82: B0CZ6NNH6G | C82: Vistaro Posture Corrector for Women and Men, Instant Posture Corrector Adjustable Back Straightener (X-Large (147-191lb)) | D82: 24.99 | H82: {自然搜索=[]} | I82: 166 | J82: 166 | K82: 0 | L82: 0 | M82: 0 | N82: 0
A83: 81 | B83: B0D12PR8GX | C83: Back Brace Posture Corrector for Women and Men - Relief for Waist, Back and Shoulder Pain - Adjustable and Breathable Posture Back Brace - Improve Back Posture and Provide Lumbar Support L(33"-37") | D83: 34.99 | E83: 4.5 | F83: 116 | H83: {自然搜索=[], 官方推荐=[AC专栏], Deal=[优惠券(Coupon)]} | I83: 450 | J83: 450 | K83: 0 | L83: 0 | M83: 0 | N83: 3
A84: 82 | B84: B0D1QPY7NP | C84: Back Brace Posture Corrector for Women and Men - Adjustable Posture Back Brace for Upper and Lower Back Pain Relief - Improve Back Posture and Lumbar Support XXL(42"-48") | D84: 34.99 | E84: 4.5 | F84: 58 | H84: {自然搜索=[], PPC广告=[SP广告]} | I84: 44 | J84: 40 | K84: 5 | L84: 0 | M84: 0 | N84: 0

Sheet 5-后台ABA数据对照
A1: 搜索频率排名 | B1: 搜索词 | C1: 点击量最高的品牌 #1 | D1: 点击量最高的品牌 #2 | E1: 点击量最高的品牌 #3 | F1: 点击量最高的类别 #1 | G1: 点击量最高的类别 #2 | H1: 点击量最高的类别 #3 | I1: 点击量最高的商品 #1：ASIN | J1: 点击量最高的商品 #1：商品名称 | K1: 点击量最高的商品 #1：点击份额 | L1: 点击量最高的商品 #1：转化份额 | M1: 点击量最高的商品 #2：ASIN | N1: 点击量最高的商品 #2：商品名称 | O1: 点击量最高的商品 #2：点击份额 | P1: 点击量最高的商品 #2：转化份额 | Q1: 点击量最高的商品 #3：ASIN | R1: 点击量最高的商品 #3：商品名称 | S1: 点击量最高的商品 #3：点击份额 | T1: 点击量最高的商品 #3：转化份额 | U1: 报告日期
A2: 1708 | B2: posture corrector for women | C2: Fit Geno | D2: ComfyBrace | E2: JMPOSE | F2: Health & Personal Care | G2: Biss | H2: Apparel | I2: B07ZQPKTVV | J2: ComfyBrace Posture Corrector-Back Brace for Men and Women- Fully Adjustable Straightener for Mid, Upper Spine Support- Neck, Shoulder, Clavicle and Back Pain Relief-Breathable | K2: 14.45 | L2: 10.08 | M2: B0BYMMVKZF | N2: JMPOSE Posture Corrector for Women and Men, Breathable Back Brace, Adjustable Posture Corrector for Back, Shoulder and Spine Pain Relief (Small/Medium) | O2: 12.64 | P2: 9.4 | Q2: B09ZQ192L3 | R2: Fit Geno Posture Corrector for Women and Men - Adjustable Back Brace & Straightener for Scoliosis, Hunchback Correction, Back Pain, Spine Corrector, Back Support and Posture Trainer | S2: 8.96 | T2: 4.11 | U2: 45395
A3: 3639 | B3: posture corrector for men | C3: Fit Geno | D3: SHAPERKY | E3: Fitsupport | F3: Health & Personal Care | G3: Biss | H3: Sports | I3: B09ZQ192L3 | J3: Fit Geno Posture Corrector for Women and Men - Adjustable Back Brace & Straightener for Scoliosis, Hunchback Correction, Back Pain, Spine Corrector, Back Support and Posture Trainer | K3: 12.31 | L3: 2.88 | M3: B0B63KDFK7 | N3: Posture Corrector for Men and Women, Adjustable Upper Back Brace, Muscle Memory Support Straightener, Providing Pain Relief from Neck, Shoulder, and Upper and Lower Back, Small/Medium(27''-39'') | O3: 10.43 | P3: 4.25 | Q3: B07M7RQCQ5 | R3: Copper Compression Posture Corrector for Men & Women - Adjustable Copper Infused Orthopedic Brace for Pain Relief from Bad Posture, Slumping - Targets Upper Back, Shoulders, Neck, Clavicle | S3: 8.98 | T3: 3.52 | U3: 45395
A4: 12022 | B4: posture corrector | C4: Fit Geno | D4: ComfyBrace | E4: Ticoni | F4: Health & Personal Care | G4: Biss | H4: Sports | I4: B07ZQPKTVV | J4: ComfyBrace Posture Corrector-Back Brace for Men and Women- Fully Adjustable Straightener for Mid, Upper Spine Support- Neck, Shoulder, Clavicle and Back Pain Relief-Breathable | K4: 11.94 | L4: 10.87 | M4: B09ZQ192L3 | N4: Fit Geno Posture Corrector for Women and Men - Adjustable Back Brace & Straightener for Scoliosis, Hunchback Correction, Back Pain, Spine Corrector, Back Support and Posture Trainer | O4: 11.64 | P4: 4.5 | Q4: B0BWRHYZWJ | R4: Posture Corrector for Women and Men,Adjustable Upper Back Brace, Breathable Back Support straightener, Providing Pain Relief from Lumbar, Neck, Shoulder, and Clavicle, Back (Black) | S4: 8.02 | T4: 6.99 | U4: 45395
A5: 25412 | B5: back brace posture corrector | C5: Fit Geno | D5: SNUSIM | E5: ComfyBrace | F5: Health & Personal Care | G5: Biss | H5: Apparel | I5: B09ZQ2QSXS | J5: Fit Geno Back Brace Posture Corrector for Women and Men, Shoulder Straightener, Adjustable Full Back Support, Upper and Lower Back Pain Relief - Scoliosis, Hunchback, Hump, Thoracic, Spine Corrector | K5: 15.27 | L5: 7.71 | M5: B0CXPJNPG4 | N5: SNUSIM Posture Corrector Upper Back Brace Neck Shoulder Back Support Brace Pain Relief Belt for Women Men Braces Spine Straightener Breathable - Adjustable | O5: 11.02 | P5: 7.71 | Q5: B07ZQPKTVV | R5: ComfyBrace Posture Corrector-Back Brace for Men and Women- Fully Adjustable Straightener for Mid, Upper Spine Support- Neck, Shoulder, Clavicle and Back Pain Relief-Breathable | S5: 8.11 | T5: 5.67 | U5: 45395
A6: 28687 | B6: back straightener posture corrector | C6: Fit Geno | D6: ComfyBrace | E6: Ticoni | F6: Health & Personal Care | G6: Biss | H6: Home | I6: B09ZQ2QSXS | J6: Fit Geno Back Brace Posture Corrector for Women and Men, Shoulder Straightener, Adjustable Full Back Support, Upper and Lower Back Pain Relief - Scoliosis, Hunchback, Hump, Thoracic, Spine Corrector | K6: 17.43 | L6: 8.5 | M6: B07ZQPKTVV | N6: ComfyBrace Posture Corrector-Back Brace for Men and Women- Fully Adjustable Straightener for Mid, Upper Spine Support- Neck, Shoulder, Clavicle and Back Pain Relief-Breathable | O6: 14.42 | P6: 10.78 | Q6: B0BHF1DT5N | R6: Fit Geno Back Brace Posture Corrector for Women: Shoulder Straightener Adjustable Full Back Support Upper and Lower Back Pain Relief - Scoliosis Hunchback Hump Thoracic Spine Corrector Pink Medium | S6: 6.74 | T6: 0.98 | U6: 45395
A7: 33496 | B7: posture corrector bra | C7: Delimira | D7: IROCUE | E7: JMPOSE | F7: Apparel | G7: Health & Personal Care | H7: Sports | I7: B0CT7MVMV3 | J7: DELIMIRA Women's Front Closure Posture Wireless Back Support Full Coverage Bra | K7: 15.01 | L7: 0 | M7: B0CW33TPRS | N7: IROCUE Women's Front Closure Posture Corrector Bra Wireless Back Support Bras for Women Comfy Unlined with Nipple Covers | O7: 10.18 | P7: 0 | Q7: B0BYMMVKZF | R7: JMPOSE Posture Corrector for Women and Men, Breathable Back Brace, Adjustable Posture Corrector for Back, Shoulder and Spine Pain Relief (Small/Medium) | S7: 7.63 | T7: 4.89 | U7: 45395
A8: 33646 | B8: back posture corrector women | C8: Fit Geno | D8: ComfyBrace | E8: JMPOSE | F8: Health & Personal Care | G8: Apparel | H8: Biss | I8: B09ZQ2QSXS | J8: Fit Geno Back Brace Posture Corrector for Women and Men, Shoulder Straightener, Adjustable Full Back Support, Upper and Lower Back Pain Relief - Scoliosis, Hunchback, Hump, Thoracic, Spine Corrector | K8: 16.67 | L8: 6.86 | M8: B07ZQPKTVV | N8: ComfyBrace Posture Corrector-Back Brace for Men and Women- Fully Adjustable Straightener for Mid, Upper Spine Support- Neck, Shoulder, Clavicle and Back Pain Relief-Breathable | O8: 16.03 | P8: 11.44 | Q8: B0BYMMVKZF | R8: JMPOSE Posture Corrector for Women and Men, Breathable Back Brace, Adjustable Posture Corrector for Back, Shoulder and Spine Pain Relief (Small/Medium) | S8: 11.56 | T8: 9.8 | U8: 45395
A9: 45501 | B9: back posture corrector for men | C9: Fit Geno | D9: SNUSIM | E9: Fitsupport | F9: Health & Personal Care | G9: Biss | H9: Apparel | I9: B0CXPJNPG4 | J9: SNUSIM Posture Corrector Upper Back Brace Neck Shoulder Back Support Brace Pain Relief Belt for Women Men Braces Spine Straightener Breathable - Adjustable | K9: 13.17 | L9: 10.19 | M9: B09ZQ2QSXS | N9: Fit Geno Back Brace Posture Corrector for Women and Men, Shoulder Straightener, Adjustable Full Back Support, Upper and Lower Back Pain Relief - Scoliosis, Hunchback, Hump, Thoracic, Spine Corrector | O9: 13.08 | P9: 8.3 | Q9: B09ZQ192L3 | R9: Fit Geno Posture Corrector for Women and Men - Adjustable Back Brace & Straightener for Scoliosis, Hunchback Correction, Back Pain, Spine Corrector, Back Support and Posture Trainer | S9: 7.25 | T9: 1.51 | U9: 45395
A10: 51329 | B10: posture bra | C10: Delimira | D10: Bali | E10: HACI | F10: Apparel | G10: Health & Personal Care | H10: Sports | I10: B0CT7MVMV3 | J10: DELIMIRA Women's Front Closure Posture Wireless Back Support Full Coverage Bra | K10: 8.99 | L10: 0 | M10: B0CW1NXQ4D | N10: DELIMIRA Women's Full Coverage Front Closure Wire Free Back Support Posture Bra | O10: 6.49 | P10: 0 | Q10: B0C6GK7B9X | R10: NLNYCT Posture Corrector For Women, Adjustable Back Brace For Posture, Back Posture Corrector Providing Pain Relief From Lumbar, Neck, Shoulder, And Clavicle, Back (S/M Upper Waist 25-36 Inch) | S10: 6.39 | T10: 1.63 | U10: 45395
A11: 56923 | B11: tommie copper posture bra | C11: Tommie Copper | D11: Delimira | E11: HACI | F11: Apparel | G11: Sports | H11: Health & Personal Care | I11: B0BRTGXT5M | J11: Tommie Copper Shoulder Support Bra, Posture Corrector Bra for Women, Bra with Back Support, Posture Bra and Compression Bra for Women, Back and Shoulder Support Bra- White - XX-Large | K11: 13.53 | L11: 3.87 | M11: B0CT7MVMV3 | N11: DELIMIRA Women's Front Closure Posture Wireless Back Support Full Coverage Bra | O11: 6.61 | P11: 0 | Q11: B0BRTJTBVL | R11: Tommie Copper Shoulder Support Bra, Posture Corrector Bra for Women, Bra with Back Support, Posture Bra and Compression Bra for Women, Back and Shoulder Support Bra- White - Large | S11: 4.48 | T11: 0.65 | U11: 45395
A12: 60972 | B12: back brace for posture | C12: Fit Geno | D12: ComfyBrace | E12: Fitsupport | F12: Health & Personal Care | G12: Biss | H12: Tools | I12: B07ZQPKTVV | J12: ComfyBrace Posture Corrector-Back Brace for Men and Women- Fully Adjustable Straightener for Mid, Upper Spine Support- Neck, Shoulder, Clavicle and Back Pain Relief-Breathable | K12: 11.36 | L12: 8.14 | M12: B09ZQ192L3 | N12: Fit Geno Posture Corrector for Women and Men - Adjustable Back Brace & Straightener for Scoliosis, Hunchback Correction, Back Pain, Spine Corrector, Back Support and Posture Trainer | O12: 11.04 | P12: 2.91 | Q12: B07Q494CNM | R12: Back Brace Posture Corrector for Women and Men Back Lumbar Support Shoulder Posture Support for Improve Posture Provide and Back Pain Relief | S12: 6.71 | T12: 1.74 | U12: 45395
A13: 75242 | B13: hatmeo posture correcting bra | D13: WOWENY | E13: CATESILK | F13: Apparel | G13: Health & Personal Care | H13: Sports | I13: B0CS3B4THH | J13: Hatmeo Posture Correcting Bra, Wmbra Bra, Comfortable Full Back Cover Plus Size Bra (US, Alpha, Medium, Regular, Regular, Beige) | K13: 7.32 | L13: 0 | M13: B0CS3C6JZJ | N13: Hatmeo Posture Correcting Bra, Wmbra Bra, Comfortable Full Back Cover Plus Size Bra (US, Alpha, Large, Regular, Regular, Beige) | O13: 5.1 | P13: 2.38 | Q13: B0CS38J3MR | R13: Hatmeo Posture Correcting Bra, Wmbra Bra Comfortable Full Back Cover Plus Size Bras | S13: 4.71 | T13: 0 | U13: 45395
A14: 90758 | B14: posture | C14: Fit Geno | D14: ComfyBrace | E14: Ticoni | F14: Health & Personal Care | G14: Biss | H14: Sports | I14: B07ZQPKTVV | J14: ComfyBrace Posture Corrector-Back Brace for Men and Women- Fully Adjustable Straightener for Mid, Upper Spine Support- Neck, Shoulder, Clavicle and Back Pain Relief-Breathable | K14: 14.11 | L14: 12.37 | M14: B09ZQ2QSXS | N14: Fit Geno Back Brace Posture Corrector for Women and Men, Shoulder Straightener, Adjustable Full Back Support, Upper and Lower Back Pain Relief - Scoliosis, Hunchback, Hump, Thoracic, Spine Corrector | O14: 13.02 | P14: 9.28 | Q14: B0BWRHYZWJ | R14: Posture Corrector for Women and Men,Adjustable Upper Back Brace, Breathable Back Support straightener, Providing Pain Relief from Lumbar, Neck, Shoulder, and Clavicle, Back (Black) | S14: 10.08 | T14: 8.25 | U14: 45395
A15: 98032 | B15: posture brace | C15: Fit Geno | D15: ComfyBrace | E15: JMPOSE | F15: Health & Personal Care | G15: Biss | H15: Apparel | I15: B07ZQPKTVV | J15: ComfyBrace Posture Corrector-Back Brace for Men and Women- Fully Adjustable Straightener for Mid, Upper Spine Support- Neck, Shoulder, Clavicle and Back Pain Relief-Breathable | K15: 19.63 | L15: 10.4 | M15: B09ZQ2QSXS | N15: Fit Geno Back Brace Posture Corrector for Women and Men, Shoulder Straightener, Adjustable Full Back Support, Upper and Lower Back Pain Relief - Scoliosis, Hunchback, Hump, Thoracic, Spine Corrector | O15: 15.47 | P15: 6.4 | Q15: B0BYMMVKZF | R15: JMPOSE Posture Corrector for Women and Men, Breathable Back Brace, Adjustable Posture Corrector for Back, Shoulder and Spine Pain Relief (Small/Medium) | S15: 6.99 | T15: 1.6 | U15: 45395
A16: 115321 | B16: back hero posture corrector | C16: BITYEYE | D16: VOKOKOYA | E16: Fit Geno | F16: Health & Personal Care | G16: Biss | H16: Sports | I16: B0CHNNXLJD | J16: VOKOKOYA Posture Corrector for Women and Men, Adjustable Shoulder Posture Brace, Back Straightener Posture, Used for Middle and Upper Spine | K16: 22.09 | L16: 3.51 | M16: B0CXD5GPXW | N16: BITYEYE Instant Posture Corrector,2024 New Back Straightener Posture Corrector,Instant Posture Corrector Adjustable Back Straightener (1PCS-S) | O16: 19.38 | P16: 0 | Q16: B09ZQ2QSXS | R16: Fit Geno Back Brace Posture Corrector for Women and Men, Shoulder Straightener, Adjustable Full Back Support, Upper and Lower Back Pain Relief - Scoliosis, Hunchback, Hump, Thoracic, Spine Corrector | S16: 10.85 | T16: 1.75 | U16: 45395
A17: 116583 | B17: corecorex instant posture corrector | D17: Super Ergonomic | E17: Fit Geno | F17: Health & Personal Care | G17: Biss | I17: B0CSYX26PB | J17: Super Ergonomic Corecorex™ Instant Posture Corrector Adjustable Back Straightener (Medium(88-132lb)) | K17: 16.05 | L17: 5.81 | M17: B09ZQ2QSXS | N17: Fit Geno Back Brace Posture Corrector for Women and Men, Shoulder Straightener, Adjustable Full Back Support, Upper and Lower Back Pain Relief - Scoliosis, Hunchback, Hump, Thoracic, Spine Corrector | O17: 12.72 | P17: 8.14 | Q17: B0CYX6TV6H | R17: 2024 NEW instant posture corrector,Posture Corrector for Women and Men,instant posture,Back Straightener Posture, Used for Middle and Upper Spine (S) | S17: 9.39 | T17: 1.16 | U17: 45395
A18: 123361 | B18: instant posture corrector | D18: Fit Geno | E18: Fitsupport | F18: Health & Personal Care | G18: Biss | H18: Apparel | I18: B0CYX6TV6H | J18: 2024 NEW instant posture corrector,Posture Corrector for Women and Men,instant posture,Back Straightener Posture, Used for Middle and Upper Spine (S) | K18: 17.94 | L18: 1.49 | M18: B09ZQ2QSXS | N18: Fit Geno Back Brace Posture Corrector for Women and Men, Shoulder Straightener, Adjustable Full Back Support, Upper and Lower Back Pain Relief - Scoliosis, Hunchback, Hump, Thoracic, Spine Corrector | O18: 12.16 | P18: 1.49 | Q18: B0CYX49SBT | R18: 2024 NEW instant posture corrector,Posture Corrector for Women and Men,instant posture,Back Straightener Posture, Used for Middle and Upper Spine (XL) | S18: 8.45 | T18: 2.99 | U18: 45395
A19: 136503 | B19: best posture bra | C19: Delimira | E19: Tommie Copper | F19: Apparel | G19: Health & Personal Care | H19: Beauty | I19: B0CT7MVMV3 | J19: DELIMIRA Women's Front Closure Posture Wireless Back Support Full Coverage Bra | K19: 14.51 | L19: 0 | M19: B08QKR1M75 | N19: Bali Women's One Smooth U Posture Boost W/Eversmooth Back Underwire Bra | O19: 7.71 | P19: 0 | Q19: B0CS38J3MR | R19: Hatmeo Posture Correcting Bra, Wmbra Bra Comfortable Full Back Cover Plus Size Bras | S19: 5.44 | T19: 0 | U19: 45395
A20: 137851 | B20: posture bras for women | C20: Delimira | D20: HACI | E20: Bali | F20: Apparel | G20: Health & Personal Care | H20: Sports | I20: B0CT7MVMV3 | J20: DELIMIRA Women's Front Closure Posture Wireless Back Support Full Coverage Bra | K20: 9.84 | L20: 0 | M20: B0CT8LWDT3 | N20: HACI Front Closure Posture Bra Back Support Comfort Unlined Wireless Bras Support Everyday | O20: 7.78 | P20: 0 | Q20: B08QKR1M75 | R20: Bali Women's One Smooth U Posture Boost W/Eversmooth Back Underwire Bra | S20: 6.86 | T20: 0 | U20: 45395
A21: 152021 | B21: vistaro posture corrector | D21: Fit Geno | E21: BITYEYE | F21: Health & Personal Care | G21: Biss | H21: Apparel | I21: B0CZ6NNH6G | J21: Vistaro Posture Corrector for Women and Men, Instant Posture Corrector Adjustable Back Straightener (X-Large (147-191lb)) | K21: 43.86 | L21: 8.93 | M21: B09ZQ2QSXS | N21: Fit Geno Back Brace Posture Corrector for Women and Men, Shoulder Straightener, Adjustable Full Back Support, Upper and Lower Back Pain Relief - Scoliosis, Hunchback, Hump, Thoracic, Spine Corrector | O21: 8.52 | P21: 5.36 | Q21: B0CHNNXLJD | R21: VOKOKOYA Posture Corrector for Women and Men, Adjustable Shoulder Posture Brace, Back Straightener Posture, Used for Middle and Upper Spine | S21: 6.52 | T21: 3.57 | U21: 45395
A22: 158437 | B22: kama sutra posture book english | C22: Inner Traditions | D22: Fair Winds Press | F22: Books | G22: Digital_Ebook_Purchase | H22: Audible | I22: 892811382 | J22: The Complete Illustrated Kama Sutra | K22: 47.14 | L22: 48 | M22: 076039279X | N22: Press Here! Kama Sutra for Beginners: A Couples Guide to Sexual Fulfilment | O22: 25.78 | P22: 14 | Q22: 2487342005 | R22: The Sex Positions Challenge: Break the Routine and Connect with Your Partner | S22: 7.81 | T22: 4 | U22: 45395
A23: 161622 | B23: posture brace for women | C23: Fit Geno | D23: ComfyBrace | E23: JMPOSE | F23: Health & Personal Care | G23: Biss | H23: Apparel | I23: B07ZQPKTVV | J23: ComfyBrace Posture Corrector-Back Brace for Men and Women- Fully Adjustable Straightener for Mid, Upper Spine Support- Neck, Shoulder, Clavicle and Back Pain Relief-Breathable | K23: 16.71 | L23: 6.98 | M23: B09ZQ2QSXS | N23: Fit Geno Back Brace Posture Corrector for Women and Men, Shoulder Straightener, Adjustable Full Back Support, Upper and Lower Back Pain Relief - Scoliosis, Hunchback, Hump, Thoracic, Spine Corrector | O23: 15.65 | P23: 4.65 | Q23: B0BYMMVKZF | R23: JMPOSE Posture Corrector for Women and Men, Breathable Back Brace, Adjustable Posture Corrector for Back, Shoulder and Spine Pain Relief (Small/Medium) | S23: 9.02 | T23: 8.14 | U23: 45395
A24: 170061 | B24: forme science bra posture correcting | C24: Delimira | D24: RUNNING GIRL | E24: Tommie Copper | F24: Apparel | G24: Health & Personal Care | H24: Sports | I24: B0CT7MVMV3 | J24: DELIMIRA Women's Front Closure Posture Wireless Back Support Full Coverage Bra | K24: 9.75 | L24: 0 | M24: B0C6GK7B9X | N24: NLNYCT Posture Corrector For Women, Adjustable Back Brace For Posture, Back Posture Corrector Providing Pain Relief From Lumbar, Neck, Shoulder, And Clavicle, Back (S/M Upper Waist 25-36 Inch) | O24: 7.8 | P24: 0 | Q24: B07X7T9RP4 | R24: RUNNING GIRL Sports Bra for Women, Criss-Cross Back Padded Strappy Sports Bras Medium Support Yoga Bra with Removable Cups A-White | S24: 4.74 | T24: 2.86 | U24: 45395
A25: 174659 | B25: neck posture corrector | C25: RESTCLOUD | D25: HYUNLAI | E25: Ticoni | F25: Health & Personal Care | G25: Home | H25: Sports | I25: B07QSFJ8S2 | J25: RESTCLOUD Neck and Shoulder Relaxer, Cervical Traction Device for TMJ Pain Relief and Cervical Spine Alignment, Chiropractic Pillow Neck Stretcher (Blue) | K25: 13.14 | L25: 8.51 | M25: B0BZYX1MTQ | N25: HYUNLAI Neck Support Neck Stretcher Exerciser Cervical Neck Brace Neck Hump Corrector Trainer Correction for Spine Pressure Neck Pain Relief Improving Forward Neck Posture | O25: 10.29 | P25: 4.26 | Q25: B0BWRHYZWJ | R25: Posture Corrector for Women and Men,Adjustable Upper Back Brace, Breathable Back Support straightener, Providing Pain Relief from Lumbar, Neck, Shoulder, and Clavicle, Back (Black) | S25: 9.71 | T25: 10.64 | U25: 45395
A26: 185053 | B26: back posture correction | C26: Fit Geno | D26: ComfyBrace | E26: JMPOSE | F26: Health & Personal Care | G26: Biss | H26: Apparel | I26: B09ZQ2QSXS | J26: Fit Geno Back Brace Posture Corrector for Women and Men, Shoulder Straightener, Adjustable Full Back Support, Upper and Lower Back Pain Relief - Scoliosis, Hunchback, Hump, Thoracic, Spine Corrector | K26: 20.24 | L26: 13.89 | M26: B07ZQPKTVV | N26: ComfyBrace Posture Corrector-Back Brace for Men and Women- Fully Adjustable Straightener for Mid, Upper Spine Support- Neck, Shoulder, Clavicle and Back Pain Relief-Breathable | O26: 19.34 | P26: 2.78 | Q26: B0BYMMVKZF | R26: JMPOSE Posture Corrector for Women and Men, Breathable Back Brace, Adjustable Posture Corrector for Back, Shoulder and Spine Pain Relief (Small/Medium) | S26: 6.34 | T26: 2.78 | U26: 45395
A27: 190391 | B27: shoulder posture corrector | C27: Ticoni | D27: ComfyBrace | E27: Fit Geno | F27: Health & Personal Care | G27: Biss | H27: Sports | I27: B0BWRHYZWJ | J27: Posture Corrector for Women and Men,Adjustable Upper Back Brace, Breathable Back Support straightener, Providing Pain Relief from Lumbar, Neck, Shoulder, and Clavicle, Back (Black) | K27: 17.08 | L27: 14.46 | M27: B07ZQPKTVV | N27: ComfyBrace Posture Corrector-Back Brace for Men and Women- Fully Adjustable Straightener for Mid, Upper Spine Support- Neck, Shoulder, Clavicle and Back Pain Relief-Breathable | O27: 14.91 | P27: 18.07 | Q27: B09ZQ2QSXS | R27: Fit Geno Back Brace Posture Corrector for Women and Men, Shoulder Straightener, Adjustable Full Back Support, Upper and Lower Back Pain Relief - Scoliosis, Hunchback, Hump, Thoracic, Spine Corrector | S27: 9.32 | T27: 4.82 | U27: 45395
A28: 196122 | B28: hunchback posture corrector | C28: Fit Geno | D28: ComfyBrace | E28: SHAPERKY | F28: Health & Personal Care | G28: Biss | I28: B09ZQ2QSXS | J28: Fit Geno Back Brace Posture Corrector for Women and Men, Shoulder Straightener, Adjustable Full Back Support, Upper and Lower Back Pain Relief - Scoliosis, Hunchback, Hump, Thoracic, Spine Corrector | K28: 13.74 | L28: 7.89 | M28: B07ZQPKTVV | N28: ComfyBrace Posture Corrector-Back Brace for Men and Women- Fully Adjustable Straightener for Mid, Upper Spine Support- Neck, Shoulder, Clavicle and Back Pain Relief-Breathable | O28: 13.42 | P28: 10.53 | Q28: B0BWRHYZWJ | R28: Posture Corrector for Women and Men,Adjustable Upper Back Brace, Breathable Back Support straightener, Providing Pain Relief from Lumbar, Neck, Shoulder, and Clavicle, Back (Black) | S28: 6.71 | T28: 0 | U28: 45395
A29: 216166 | B29: vanto posture correcting bra | C29: vljsfkh | D29: danlein | E29: MSRXUP | F29: Apparel | G29: Health & Personal Care | I29: B0CZP6Y4PS | J29: Vanto Posture Correcting Bra, Zenchic Bra - Seamless Sexy Push up Wireless Bra, Lysine Charm Bra, Women Seamless Sexy Push up Wireless Posture Correcting Bra-Black+Beige||L | K29: 18.25 | L29: 4.88 | M29: B0CZRMDLJ7 | N29: Vanto Posture Correcting Bra, Bloom Miss Bra, Posture Corrector Bra for Women Posture Fix | O29: 10.88 | P29: 0 | Q29: B0CZP8CST6 | R29: Vanto Posture Correcting Bra, Zenchic Bra - Seamless Sexy Push up Wireless Bra, Lysine Charm Bra | S29: 7.37 | T29: 0 | U29: 45395
A30: 221104 | B30: kamasutra posture book english | C30: Inner Traditions | E30: Fair Winds Press | F30: Books | G30: Digital_Ebook_Purchase | H30: Audible | I30: 892811382 | J30: The Complete Illustrated Kama Sutra | K30: 30.82 | L30: 27.27 | M30: 076039279X | N30: Press Here! Kama Sutra for Beginners: A Couples Guide to Sexual Fulfilment | O30: 17.56 | P30: 4.55 | Q30: 2487342005 | R30: The Sex Positions Challenge: Break the Routine and Connect with Your Partner | S30: 9.32 | T30: 9.09 | U30: 45395
A31: 227083 | B31: posture correcting bra | C31: Delimira | E31: Bali | F31: Apparel | G31: Health & Personal Care | H31: Furniture | I31: B0CT7MVMV3 | J31: DELIMIRA Women's Front Closure Posture Wireless Back Support Full Coverage Bra | K31: 13.97 | L31: 0 | M31: B0CS38J3MR | N31: Hatmeo Posture Correcting Bra, Wmbra Bra Comfortable Full Back Cover Plus Size Bras | O31: 5.15 | P31: 0 | Q31: B08QKR1M75 | R31: Bali Women's One Smooth U Posture Boost W/Eversmooth Back Underwire Bra | S31: 4.78 | T31: 0 | U31: 45395
A32: 230552 | B32: back support bras for women posture | C32: Delimira | D32: newlashua | E32: DotVol | F32: Apparel | G32: Health & Personal Care | H32: Furniture | I32: B0CT7MVMV3 | J32: DELIMIRA Women's Front Closure Posture Wireless Back Support Full Coverage Bra | K32: 7.09 | L32: 0 | M32: B0C6GK7B9X | N32: NLNYCT Posture Corrector For Women, Adjustable Back Brace For Posture, Back Posture Corrector Providing Pain Relief From Lumbar, Neck, Shoulder, And Clavicle, Back (S/M Upper Waist 25-36 Inch) | O32: 6.72 | P32: 0 | Q32: B0CW33TPRS | R32: IROCUE Women's Front Closure Posture Corrector Bra Wireless Back Support Bras for Women Comfy Unlined with Nipple Covers | S32: 5.6 | T32: 0 | U32: 45395
A33: 242925 | B33: hydrolabs posture fix | C33: BITYEYE | D33: Fit Geno | F33: Health & Personal Care | G33: Sports | H33: Home | I33: B0CXCVKRCP | J33: BITYEYE Instant Posture Corrector,2024 New Back Straightener Posture Corrector,Instant Posture Corrector Adjustable Back Straightener (1PCS-M) | K33: 29.02 | L33: 4.35 | M33: B09ZQ2QSXS | N33: Fit Geno Back Brace Posture Corrector for Women and Men, Shoulder Straightener, Adjustable Full Back Support, Upper and Lower Back Pain Relief - Scoliosis, Hunchback, Hump, Thoracic, Spine Corrector | O33: 13.33 | P33: 17.39 | Q33: B0CYX6TV6H | R33: 2024 NEW instant posture corrector,Posture Corrector for Women and Men,instant posture,Back Straightener Posture, Used for Middle and Upper Spine (S) | S33: 6.67 | T33: 0 | U33: 45395
A34: 242925 | B34: instant posture corrector for men | D34: VOKOKOYA | E34: Fit Geno | F34: Health & Personal Care | G34: Biss | I34: B0C5BQ2WCS | J34: VOKOKOYA Posture Corrector for Women and Men, Adjustable Shoulder Posture Brace, Back Straightener Posture, Used for Middle and Upper Spine | K34: 17.65 | L34: 8.7 | M34: B0CYX6TV6H | N34: 2024 NEW instant posture corrector,Posture Corrector for Women and Men,instant posture,Back Straightener Posture, Used for Middle and Upper Spine (S) | O34: 12.55 | P34: 4.35 | Q34: B09ZQ2QSXS | R34: Fit Geno Back Brace Posture Corrector for Women and Men, Shoulder Straightener, Adjustable Full Back Support, Upper and Lower Back Pain Relief - Scoliosis, Hunchback, Hump, Thoracic, Spine Corrector | S34: 10.2 | T34: 6.52 | U34: 45395
A35: 245830 | B35: posture board | C35: Posture Guy Mike | D35: MUCITAGF | E35: STNFAREBI | F35: Sports | G35: Health & Personal Care | H35: Home | I35: B0B8DVKZLN | J35: Posture Guy Mike Posture Board Slant Board Professional Adjustable Wooden Incline Board Intended for Egoscue, Posture Exercises, Stretching, Workouts, Balance, Flexibility, Calf Stretcher | K35: 32.14 | L35: 13.64 | M35: B095K9ZGY5 | N35: MUCITAGF Professional Slant Board, Adjustable Incline Board and Calf Stretcher, Slant Board for Calf Stretching, Calf Stretch Board | O35: 28.97 | P35: 31.82 | Q35: B0BKWJMCSR | R35: Professional Wooden Slant Board, Calf Stretcher Slant Board, Adjustable Incline Board and Calf Stretcher,Slant Board for Calf Stretching | S35: 4.76 | T35: 4.55 | U35: 45395
A36: 249879 | B36: posture corrector bra for women | C36: Delimira | E36: DotVol | F36: Apparel | G36: Health & Personal Care | H36: Beauty | I36: B0CT7MVMV3 | J36: DELIMIRA Women's Front Closure Posture Wireless Back Support Full Coverage Bra | K36: 15.73 | L36: 0 | M36: B08QKR1M75 | N36: Bali Women's One Smooth U Posture Boost W/Eversmooth Back Underwire Bra | O36: 5.24 | P36: 0 | Q36: B0CW33TPRS | R36: IROCUE Women's Front Closure Posture Corrector Bra Wireless Back Support Bras for Women Comfy Unlined with Nipple Covers | S36: 5.24 | T36: 0 | U36: 45395
A37: 249879 | B37: posture pump | C37: POSTURE PUMP | D37: AllSett Health | E37: ECOGUN | F37: Health & Personal Care | G37: Home | I37: B00SA5IPK4 | J37: Posture Pump® Neck Exercising Dual Cervical Spine Disc Hydrator® Pump | Relieves Neck & Upper Back Pain Stiffness | Neck Shoulder Pain Relief Posture Control (Dual Air Cell Model 1400-D) | K37: 31.85 | L37: 17.24 | M37: B07GDZQ9SR | N37: AllSett Health Posture Neck Exercising Cervical Spine Hydrator Pump || Relief for Stiffness, Relieves Neck Pain | O37: 18.15 | P37: 20.69 | Q37: B01N5OGBMW | R37: Posture Pump® Dual Deluxe Neck & Back Exercising Cervical Spine Hydrator Pump | Relieves Neck, Upper Back, & Low Back Pain Stiffness | Tech Neck Relief Posture Control (Dual Full Spine Model 4100-D) | S37: 14.52 | T37: 0 | U37: 45395
A38: 284333 | B38: back posture corrector | C38: Fit Geno | D38: ComfyBrace | E38: Ticoni | F38: Health & Personal Care | G38: Biss | H38: Home | I38: B07ZQPKTVV | J38: ComfyBrace Posture Corrector-Back Brace for Men and Women- Fully Adjustable Straightener for Mid, Upper Spine Support- Neck, Shoulder, Clavicle and Back Pain Relief-Breathable | K38: 10.96 | L38: 11.63 | M38: B09ZQ192L3 | N38: Fit Geno Posture Corrector for Women and Men - Adjustable Back Brace & Straightener for Scoliosis, Hunchback Correction, Back Pain, Spine Corrector, Back Support and Posture Trainer | O38: 9.13 | P38: 2.33 | Q38: B0BWRHYZWJ | R38: Posture Corrector for Women and Men,Adjustable Upper Back Brace, Breathable Back Support straightener, Providing Pain Relief from Lumbar, Neck, Shoulder, and Clavicle, Back (Black) | S38: 8.68 | T38: 6.98 | U38: 45395
A39: 292495 | B39: back posture brace | C39: Fit Geno | D39: ComfyBrace | E39: SHAPERKY | F39: Health & Personal Care | G39: Biss | H39: Home | I39: B09ZQ2QSXS | J39: Fit Geno Back Brace Posture Corrector for Women and Men, Shoulder Straightener, Adjustable Full Back Support, Upper and Lower Back Pain Relief - Scoliosis, Hunchback, Hump, Thoracic, Spine Corrector | K39: 18.78 | L39: 8.82 | M39: B07ZQPKTVV | N39: ComfyBrace Posture Corrector-Back Brace for Men and Women- Fully Adjustable Straightener for Mid, Upper Spine Support- Neck, Shoulder, Clavicle and Back Pain Relief-Breathable | O39: 17.37 | P39: 14.71 | Q39: B0CN77K249 | R39: Posture Corrector for Women, Back Brace for Men, Adjustable Posture Corrector, Shoulder Brace, Back Posture Corrector Women, Back Pain Relief, Posture Brace, Back Straightener, Upper Back Support | S39: 6.1 | T39: 2.94 | U39: 45395
A40: 292495 | B40: posture corrector for shoulders | C40: Fit Geno | D40: ComfyBrace | E40: Fitsupport | F40: Health & Personal Care | G40: Biss | H40: Apparel | I40: B07ZQPKTVV | J40: ComfyBrace Posture Corrector-Back Brace for Men and Women- Fully Adjustable Straightener for Mid, Upper Spine Support- Neck, Shoulder, Clavicle and Back Pain Relief-Breathable | K40: 16.9 | L40: 20.69 | M40: B09ZQ2QSXS | N40: Fit Geno Back Brace Posture Corrector for Women and Men, Shoulder Straightener, Adjustable Full Back Support, Upper and Lower Back Pain Relief - Scoliosis, Hunchback, Hump, Thoracic, Spine Corrector | O40: 15.49 | P40: 6.9 | Q40: B0BWRHYZWJ | R40: Posture Corrector for Women and Men,Adjustable Upper Back Brace, Breathable Back Support straightener, Providing Pain Relief from Lumbar, Neck, Shoulder, and Clavicle, Back (Black) | S40: 8.45 | T40: 13.79 | U40: 45395
...
